package net.journey.dimension.overworld.gen;

import java.util.Random;
import net.minecraft.init.Blocks;
import net.minecraft.world.World;
import net.minecraft.world.gen.feature.WorldGenerator;

public class WorldGenFloatingIsland extends WorldGenerator {

	@Override
	public boolean generate(World world, Random rand, BlockPos p) {
		int i = p.getX(), j = p.getY(), k = p.getZ();
		world.setBlockState(new BlockPos(i + 0, j + 27, k + 11), Blocks.grass.getDefaultState());
		world.setBlockState(new BlockPos(i + 0, j + 27, k + 12), Blocks.grass.getDefaultState());
		world.setBlockState(new BlockPos(i + 1, j + 24, k + 10), Blocks.dirt.getDefaultState());
		world.setBlockState(new BlockPos(i + 1, j + 25, k + 10), Blocks.dirt.getDefaultState());
		world.setBlockState(new BlockPos(i + 1, j + 26, k + 10), Blocks.dirt.getDefaultState());
		world.setBlockState(new BlockPos(i + 1, j + 27, k + 10), Blocks.grass.getDefaultState());
		world.setBlockState(new BlockPos(i + 1, j + 27, k + 11), Blocks.grass.getDefaultState());
		world.setBlockState(new BlockPos(i + 1, j + 27, k + 12), Blocks.grass.getDefaultState());
		world.setBlockState(new BlockPos(i + 1, j + 27, k + 13), Blocks.grass.getDefaultState());
		world.setBlockState(new BlockPos(i + 1, j + 27, k + 14), Blocks.grass.getDefaultState());
		world.setBlockState(new BlockPos(i + 1, j + 27, k + 15), Blocks.grass.getDefaultState());
		world.setBlockState(new BlockPos(i + 1, j + 27, k + 16), Blocks.grass.getDefaultState());
		world.setBlockState(new BlockPos(i + 1, j + 27, k + 17), Blocks.grass.getDefaultState());
		world.setBlockState(new BlockPos(i + 2, j + 18, k + 10), Blocks.dirt.getDefaultState());
		world.setBlockState(new BlockPos(i + 2, j + 19, k + 10), Blocks.dirt.getDefaultState());
		world.setBlockState(new BlockPos(i + 2, j + 20, k + 10), Blocks.dirt.getDefaultState());
		world.setBlockState(new BlockPos(i + 2, j + 21, k + 10), Blocks.dirt.getDefaultState());
		world.setBlockState(new BlockPos(i + 2, j + 22, k + 10), Blocks.dirt.getDefaultState());
		world.setBlockState(new BlockPos(i + 2, j + 22, k + 11), Blocks.dirt.getDefaultState());
		world.setBlockState(new BlockPos(i + 2, j + 23, k + 10), Blocks.dirt.getDefaultState());
		world.setBlockState(new BlockPos(i + 2, j + 23, k + 11), Blocks.dirt.getDefaultState());
		world.setBlockState(new BlockPos(i + 2, j + 24, k + 10), Blocks.dirt.getDefaultState());
		world.setBlockState(new BlockPos(i + 2, j + 24, k + 11), Blocks.dirt.getDefaultState());
		world.setBlockState(new BlockPos(i + 2, j + 25, k + 10), Blocks.dirt.getDefaultState());
		world.setBlockState(new BlockPos(i + 2, j + 25, k + 11), Blocks.dirt.getDefaultState());
		world.setBlockState(new BlockPos(i + 2, j + 26, k + 10), Blocks.dirt.getDefaultState());
		world.setBlockState(new BlockPos(i + 2, j + 26, k + 11), Blocks.dirt.getDefaultState());
		world.setBlockState(new BlockPos(i + 2, j + 26, k + 12), Blocks.dirt.getDefaultState());
		world.setBlockState(new BlockPos(i + 2, j + 26, k + 16), Blocks.dirt.getDefaultState());
		world.setBlockState(new BlockPos(i + 2, j + 26, k + 17), Blocks.dirt.getDefaultState());
		world.setBlockState(new BlockPos(i + 2, j + 26, k + 18), Blocks.dirt.getDefaultState());
		world.setBlockState(new BlockPos(i + 2, j + 27, k + 9), Blocks.grass.getDefaultState());
		world.setBlockState(new BlockPos(i + 2, j + 27, k + 10), Blocks.grass.getDefaultState());
		world.setBlockState(new BlockPos(i + 2, j + 27, k + 11), Blocks.grass.getDefaultState());
		world.setBlockState(new BlockPos(i + 2, j + 27, k + 12), Blocks.grass.getDefaultState());
		world.setBlockState(new BlockPos(i + 2, j + 27, k + 13), Blocks.grass.getDefaultState());
		world.setBlockState(new BlockPos(i + 2, j + 27, k + 14), Blocks.grass.getDefaultState());
		world.setBlockState(new BlockPos(i + 2, j + 27, k + 15), Blocks.grass.getDefaultState());
		world.setBlockState(new BlockPos(i + 2, j + 27, k + 16), Blocks.grass.getDefaultState());
		world.setBlockState(new BlockPos(i + 2, j + 27, k + 17), Blocks.grass.getDefaultState());
		world.setBlockState(new BlockPos(i + 2, j + 27, k + 18), Blocks.grass.getDefaultState());
		world.setBlockState(new BlockPos(i + 3, j + 14, k + 10), Blocks.glowstone.getDefaultState());
		world.setBlockState(new BlockPos(i + 3, j + 15, k + 10), Blocks.dirt.getDefaultState());
		world.setBlockState(new BlockPos(i + 3, j + 16, k + 10), Blocks.dirt.getDefaultState());
		world.setBlockState(new BlockPos(i + 3, j + 17, k + 10), Blocks.dirt.getDefaultState());
		world.setBlockState(new BlockPos(i + 3, j + 18, k + 10), Blocks.dirt.getDefaultState());
		world.setBlockState(new BlockPos(i + 3, j + 19, k + 10), Blocks.dirt.getDefaultState());
		world.setBlockState(new BlockPos(i + 3, j + 20, k + 10), Blocks.dirt.getDefaultState());
		world.setBlockState(new BlockPos(i + 3, j + 21, k + 9), Blocks.dirt.getDefaultState());
		world.setBlockState(new BlockPos(i + 3, j + 21, k + 10), Blocks.dirt.getDefaultState());
		world.setBlockState(new BlockPos(i + 3, j + 22, k + 9), Blocks.dirt.getDefaultState());
		world.setBlockState(new BlockPos(i + 3, j + 22, k + 10), Blocks.dirt.getDefaultState());
		world.setBlockState(new BlockPos(i + 3, j + 23, k + 9), Blocks.dirt.getDefaultState());
		world.setBlockState(new BlockPos(i + 3, j + 23, k + 10), Blocks.dirt.getDefaultState());
		world.setBlockState(new BlockPos(i + 3, j + 24, k + 9), Blocks.dirt.getDefaultState());
		world.setBlockState(new BlockPos(i + 3, j + 24, k + 10), Blocks.dirt.getDefaultState());
		world.setBlockState(new BlockPos(i + 3, j + 25, k + 9), Blocks.dirt.getDefaultState());
		world.setBlockState(new BlockPos(i + 3, j + 25, k + 10), Blocks.dirt.getDefaultState());
		world.setBlockState(new BlockPos(i + 3, j + 26, k + 9), Blocks.dirt.getDefaultState());
		world.setBlockState(new BlockPos(i + 3, j + 26, k + 10), Blocks.dirt.getDefaultState());
		world.setBlockState(new BlockPos(i + 3, j + 26, k + 11), Blocks.dirt.getDefaultState());
		world.setBlockState(new BlockPos(i + 3, j + 26, k + 12), Blocks.dirt.getDefaultState());
		world.setBlockState(new BlockPos(i + 3, j + 26, k + 13), Blocks.dirt.getDefaultState());
		world.setBlockState(new BlockPos(i + 3, j + 26, k + 15), Blocks.dirt.getDefaultState());
		world.setBlockState(new BlockPos(i + 3, j + 26, k + 16), Blocks.dirt.getDefaultState());
		world.setBlockState(new BlockPos(i + 3, j + 26, k + 17), Blocks.dirt.getDefaultState());
		world.setBlockState(new BlockPos(i + 3, j + 26, k + 18), Blocks.dirt.getDefaultState());
		world.setBlockState(new BlockPos(i + 3, j + 27, k + 8), Blocks.dirt.getDefaultState());
		world.setBlockState(new BlockPos(i + 3, j + 27, k + 9), Blocks.dirt.getDefaultState());
		world.setBlockState(new BlockPos(i + 3, j + 27, k + 10), Blocks.dirt.getDefaultState());
		world.setBlockState(new BlockPos(i + 3, j + 27, k + 11), Blocks.dirt.getDefaultState());
		world.setBlockState(new BlockPos(i + 3, j + 27, k + 12), Blocks.dirt.getDefaultState());
		world.setBlockState(new BlockPos(i + 3, j + 27, k + 13), Blocks.dirt.getDefaultState());
		world.setBlockState(new BlockPos(i + 3, j + 27, k + 14), Blocks.dirt.getDefaultState());
		world.setBlockState(new BlockPos(i + 3, j + 27, k + 15), Blocks.dirt.getDefaultState());
		world.setBlockState(new BlockPos(i + 3, j + 27, k + 16), Blocks.dirt.getDefaultState());
		world.setBlockState(new BlockPos(i + 3, j + 27, k + 17), Blocks.dirt.getDefaultState());
		world.setBlockState(new BlockPos(i + 3, j + 27, k + 18), Blocks.grass.getDefaultState());
		world.setBlockState(new BlockPos(i + 3, j + 27, k + 19), Blocks.grass.getDefaultState());
		world.setBlockState(new BlockPos(i + 3, j + 28, k + 7), Blocks.grass.getDefaultState());
		world.setBlockState(new BlockPos(i + 3, j + 28, k + 8), Blocks.grass.getDefaultState());
		world.setBlockState(new BlockPos(i + 3, j + 28, k + 9), Blocks.grass.getDefaultState());
		world.setBlockState(new BlockPos(i + 3, j + 28, k + 10), Blocks.grass.getDefaultState());
		world.setBlockState(new BlockPos(i + 3, j + 28, k + 11), Blocks.grass.getDefaultState());
		world.setBlockState(new BlockPos(i + 3, j + 28, k + 12), Blocks.grass.getDefaultState());
		world.setBlockState(new BlockPos(i + 3, j + 28, k + 13), Blocks.grass.getDefaultState());
		world.setBlockState(new BlockPos(i + 3, j + 28, k + 14), Blocks.grass.getDefaultState());
		world.setBlockState(new BlockPos(i + 3, j + 28, k + 15), Blocks.grass.getDefaultState());
		world.setBlockState(new BlockPos(i + 3, j + 28, k + 16), Blocks.grass.getDefaultState());
		world.setBlockState(new BlockPos(i + 3, j + 28, k + 17), Blocks.grass.getDefaultState());
		world.setBlockState(new BlockPos(i + 4, j + 20, k + 10), Blocks.dirt.getDefaultState());
		world.setBlockState(new BlockPos(i + 4, j + 21, k + 10), Blocks.dirt.getDefaultState());
		world.setBlockState(new BlockPos(i + 4, j + 22, k + 10), Blocks.dirt.getDefaultState());
		world.setBlockState(new BlockPos(i + 4, j + 23, k + 10), Blocks.dirt.getDefaultState());
		world.setBlockState(new BlockPos(i + 4, j + 24, k + 10), Blocks.dirt.getDefaultState());
		world.setBlockState(new BlockPos(i + 4, j + 25, k + 10), Blocks.dirt.getDefaultState());
		world.setBlockState(new BlockPos(i + 4, j + 26, k + 10), Blocks.dirt.getDefaultState());
		world.setBlockState(new BlockPos(i + 4, j + 26, k + 11), Blocks.dirt.getDefaultState());
		world.setBlockState(new BlockPos(i + 4, j + 26, k + 12), Blocks.dirt.getDefaultState());
		world.setBlockState(new BlockPos(i + 4, j + 26, k + 13), Blocks.dirt.getDefaultState());
		world.setBlockState(new BlockPos(i + 4, j + 26, k + 14), Blocks.dirt.getDefaultState());
		world.setBlockState(new BlockPos(i + 4, j + 26, k + 15), Blocks.dirt.getDefaultState());
		world.setBlockState(new BlockPos(i + 4, j + 26, k + 16), Blocks.dirt.getDefaultState());
		world.setBlockState(new BlockPos(i + 4, j + 26, k + 17), Blocks.dirt.getDefaultState());
		world.setBlockState(new BlockPos(i + 4, j + 26, k + 18), Blocks.dirt.getDefaultState());
		world.setBlockState(new BlockPos(i + 4, j + 27, k + 7), Blocks.dirt.getDefaultState());
		world.setBlockState(new BlockPos(i + 4, j + 27, k + 8), Blocks.dirt.getDefaultState());
		world.setBlockState(new BlockPos(i + 4, j + 27, k + 9), Blocks.dirt.getDefaultState());
		world.setBlockState(new BlockPos(i + 4, j + 27, k + 10), Blocks.dirt.getDefaultState());
		world.setBlockState(new BlockPos(i + 4, j + 27, k + 11), Blocks.dirt.getDefaultState());
		world.setBlockState(new BlockPos(i + 4, j + 27, k + 12), Blocks.dirt.getDefaultState());
		world.setBlockState(new BlockPos(i + 4, j + 27, k + 13), Blocks.dirt.getDefaultState());
		world.setBlockState(new BlockPos(i + 4, j + 27, k + 14), Blocks.dirt.getDefaultState());
		world.setBlockState(new BlockPos(i + 4, j + 27, k + 15), Blocks.dirt.getDefaultState());
		world.setBlockState(new BlockPos(i + 4, j + 27, k + 16), Blocks.dirt.getDefaultState());
		world.setBlockState(new BlockPos(i + 4, j + 27, k + 17), Blocks.grass.getDefaultState());
		world.setBlockState(new BlockPos(i + 4, j + 27, k + 18), Blocks.grass.getDefaultState());
		world.setBlockState(new BlockPos(i + 4, j + 27, k + 19), Blocks.grass.getDefaultState());
		world.setBlockState(new BlockPos(i + 4, j + 27, k + 20), Blocks.grass.getDefaultState());
		world.setBlockState(new BlockPos(i + 4, j + 28, k + 6), Blocks.grass.getDefaultState());
		world.setBlockState(new BlockPos(i + 4, j + 28, k + 7), Blocks.grass.getDefaultState());
		world.setBlockState(new BlockPos(i + 4, j + 28, k + 8), Blocks.grass.getDefaultState());
		world.setBlockState(new BlockPos(i + 4, j + 28, k + 9), Blocks.grass.getDefaultState());
		world.setBlockState(new BlockPos(i + 4, j + 28, k + 10), Blocks.grass.getDefaultState());
		world.setBlockState(new BlockPos(i + 4, j + 28, k + 11), Blocks.grass.getDefaultState());
		world.setBlockState(new BlockPos(i + 4, j + 28, k + 12), Blocks.grass.getDefaultState());
		world.setBlockState(new BlockPos(i + 4, j + 28, k + 13), Blocks.grass.getDefaultState());
		world.setBlockState(new BlockPos(i + 4, j + 28, k + 14), Blocks.grass.getDefaultState());
		world.setBlockState(new BlockPos(i + 4, j + 28, k + 15), Blocks.grass.getDefaultState());
		world.setBlockState(new BlockPos(i + 4, j + 28, k + 16), Blocks.grass.getDefaultState());
		world.setBlockState(new BlockPos(i + 5, j + 12, k + 18), Blocks.grass.getDefaultState());
		world.setBlockState(new BlockPos(i + 5, j + 26, k + 9), Blocks.dirt.getDefaultState());
		world.setBlockState(new BlockPos(i + 5, j + 26, k + 10), Blocks.dirt.getDefaultState());
		world.setBlockState(new BlockPos(i + 5, j + 26, k + 11), Blocks.dirt.getDefaultState());
		world.setBlockState(new BlockPos(i + 5, j + 26, k + 12), Blocks.dirt.getDefaultState());
		world.setBlockState(new BlockPos(i + 5, j + 26, k + 13), Blocks.dirt.getDefaultState());
		world.setBlockState(new BlockPos(i + 5, j + 26, k + 14), Blocks.dirt.getDefaultState());
		world.setBlockState(new BlockPos(i + 5, j + 26, k + 15), Blocks.dirt.getDefaultState());
		world.setBlockState(new BlockPos(i + 5, j + 26, k + 16), Blocks.dirt.getDefaultState());
		world.setBlockState(new BlockPos(i + 5, j + 26, k + 17), Blocks.dirt.getDefaultState());
		world.setBlockState(new BlockPos(i + 5, j + 26, k + 18), Blocks.dirt.getDefaultState());
		world.setBlockState(new BlockPos(i + 5, j + 26, k + 19), Blocks.dirt.getDefaultState());
		world.setBlockState(new BlockPos(i + 5, j + 26, k + 20), Blocks.dirt.getDefaultState());
		world.setBlockState(new BlockPos(i + 5, j + 27, k + 6), Blocks.dirt.getDefaultState());
		world.setBlockState(new BlockPos(i + 5, j + 27, k + 7), Blocks.dirt.getDefaultState());
		world.setBlockState(new BlockPos(i + 5, j + 27, k + 8), Blocks.dirt.getDefaultState());
		world.setBlockState(new BlockPos(i + 5, j + 27, k + 9), Blocks.dirt.getDefaultState());
		world.setBlockState(new BlockPos(i + 5, j + 27, k + 10), Blocks.dirt.getDefaultState());
		world.setBlockState(new BlockPos(i + 5, j + 27, k + 11), Blocks.dirt.getDefaultState());
		world.setBlockState(new BlockPos(i + 5, j + 27, k + 12), Blocks.dirt.getDefaultState());
		world.setBlockState(new BlockPos(i + 5, j + 27, k + 13), Blocks.dirt.getDefaultState());
		world.setBlockState(new BlockPos(i + 5, j + 27, k + 14), Blocks.dirt.getDefaultState());
		world.setBlockState(new BlockPos(i + 5, j + 27, k + 15), Blocks.dirt.getDefaultState());
		world.setBlockState(new BlockPos(i + 5, j + 27, k + 16), Blocks.dirt.getDefaultState());
		world.setBlockState(new BlockPos(i + 5, j + 27, k + 17), Blocks.dirt.getDefaultState());
		world.setBlockState(new BlockPos(i + 5, j + 27, k + 18), Blocks.grass.getDefaultState());
		world.setBlockState(new BlockPos(i + 5, j + 27, k + 19), Blocks.grass.getDefaultState());
		world.setBlockState(new BlockPos(i + 5, j + 27, k + 20), Blocks.grass.getDefaultState());
		world.setBlockState(new BlockPos(i + 5, j + 28, k + 6), Blocks.grass.getDefaultState());
		world.setBlockState(new BlockPos(i + 5, j + 28, k + 7), Blocks.grass.getDefaultState());
		world.setBlockState(new BlockPos(i + 5, j + 28, k + 8), Blocks.dirt.getDefaultState());
		world.setBlockState(new BlockPos(i + 5, j + 28, k + 9), Blocks.dirt.getDefaultState());
		world.setBlockState(new BlockPos(i + 5, j + 28, k + 10), Blocks.dirt.getDefaultState());
		world.setBlockState(new BlockPos(i + 5, j + 28, k + 11), Blocks.dirt.getDefaultState());
		world.setBlockState(new BlockPos(i + 5, j + 28, k + 12), Blocks.dirt.getDefaultState());
		world.setBlockState(new BlockPos(i + 5, j + 28, k + 13), Blocks.dirt.getDefaultState());
		world.setBlockState(new BlockPos(i + 5, j + 28, k + 14), Blocks.grass.getDefaultState());
		world.setBlockState(new BlockPos(i + 5, j + 28, k + 15), Blocks.grass.getDefaultState());
		world.setBlockState(new BlockPos(i + 5, j + 28, k + 16), Blocks.grass.getDefaultState());
		world.setBlockState(new BlockPos(i + 5, j + 28, k + 17), Blocks.grass.getDefaultState());
		world.setBlockState(new BlockPos(i + 5, j + 29, k + 8), Blocks.grass.getDefaultState());
		world.setBlockState(new BlockPos(i + 5, j + 29, k + 9), Blocks.grass.getDefaultState());
		world.setBlockState(new BlockPos(i + 5, j + 29, k + 10), Blocks.grass.getDefaultState());
		world.setBlockState(new BlockPos(i + 5, j + 29, k + 11), Blocks.grass.getDefaultState());
		world.setBlockState(new BlockPos(i + 5, j + 29, k + 12), Blocks.grass.getDefaultState());
		world.setBlockState(new BlockPos(i + 5, j + 29, k + 13), Blocks.grass.getDefaultState());
		world.setBlockState(new BlockPos(i + 6, j + 12, k + 17), Blocks.grass.getDefaultState());
		world.setBlockState(new BlockPos(i + 6, j + 12, k + 18), Blocks.grass.getDefaultState());
		world.setBlockState(new BlockPos(i + 6, j + 25, k + 18), Blocks.dirt.getDefaultState());
		world.setBlockState(new BlockPos(i + 6, j + 26, k + 8), Blocks.dirt.getDefaultState());
		world.setBlockState(new BlockPos(i + 6, j + 26, k + 9), Blocks.dirt.getDefaultState());
		world.setBlockState(new BlockPos(i + 6, j + 26, k + 10), Blocks.dirt.getDefaultState());
		world.setBlockState(new BlockPos(i + 6, j + 26, k + 11), Blocks.dirt.getDefaultState());
		world.setBlockState(new BlockPos(i + 6, j + 26, k + 12), Blocks.dirt.getDefaultState());
		world.setBlockState(new BlockPos(i + 6, j + 26, k + 13), Blocks.dirt.getDefaultState());
		world.setBlockState(new BlockPos(i + 6, j + 26, k + 14), Blocks.dirt.getDefaultState());
		world.setBlockState(new BlockPos(i + 6, j + 26, k + 15), Blocks.dirt.getDefaultState());
		world.setBlockState(new BlockPos(i + 6, j + 26, k + 16), Blocks.dirt.getDefaultState());
		world.setBlockState(new BlockPos(i + 6, j + 26, k + 17), Blocks.dirt.getDefaultState());
		world.setBlockState(new BlockPos(i + 6, j + 26, k + 18), Blocks.dirt.getDefaultState());
		world.setBlockState(new BlockPos(i + 6, j + 26, k + 19), Blocks.dirt.getDefaultState());
		world.setBlockState(new BlockPos(i + 6, j + 26, k + 20), Blocks.dirt.getDefaultState());
		world.setBlockState(new BlockPos(i + 6, j + 27, k + 6), Blocks.dirt.getDefaultState());
		world.setBlockState(new BlockPos(i + 6, j + 27, k + 7), Blocks.dirt.getDefaultState());
		world.setBlockState(new BlockPos(i + 6, j + 27, k + 8), Blocks.dirt.getDefaultState());
		world.setBlockState(new BlockPos(i + 6, j + 27, k + 9), Blocks.dirt.getDefaultState());
		world.setBlockState(new BlockPos(i + 6, j + 27, k + 10), Blocks.dirt.getDefaultState());
		world.setBlockState(new BlockPos(i + 6, j + 27, k + 11), Blocks.dirt.getDefaultState());
		world.setBlockState(new BlockPos(i + 6, j + 27, k + 12), Blocks.dirt.getDefaultState());
		world.setBlockState(new BlockPos(i + 6, j + 27, k + 13), Blocks.dirt.getDefaultState());
		world.setBlockState(new BlockPos(i + 6, j + 27, k + 14), Blocks.dirt.getDefaultState());
		world.setBlockState(new BlockPos(i + 6, j + 27, k + 15), Blocks.dirt.getDefaultState());
		world.setBlockState(new BlockPos(i + 6, j + 27, k + 16), Blocks.dirt.getDefaultState());
		world.setBlockState(new BlockPos(i + 6, j + 27, k + 17), Blocks.dirt.getDefaultState());
		world.setBlockState(new BlockPos(i + 6, j + 27, k + 18), Blocks.dirt.getDefaultState());
		world.setBlockState(new BlockPos(i + 6, j + 27, k + 19), Blocks.dirt.getDefaultState());
		world.setBlockState(new BlockPos(i + 6, j + 27, k + 20), Blocks.grass.getDefaultState());
		world.setBlockState(new BlockPos(i + 6, j + 28, k + 6), Blocks.grass.getDefaultState());
		world.setBlockState(new BlockPos(i + 6, j + 28, k + 7), Blocks.dirt.getDefaultState());
		world.setBlockState(new BlockPos(i + 6, j + 28, k + 8), Blocks.dirt.getDefaultState());
		world.setBlockState(new BlockPos(i + 6, j + 28, k + 9), Blocks.dirt.getDefaultState());
		world.setBlockState(new BlockPos(i + 6, j + 28, k + 10), Blocks.dirt.getDefaultState());
		world.setBlockState(new BlockPos(i + 6, j + 28, k + 11), Blocks.dirt.getDefaultState());
		world.setBlockState(new BlockPos(i + 6, j + 28, k + 12), Blocks.dirt.getDefaultState());
		world.setBlockState(new BlockPos(i + 6, j + 28, k + 13), Blocks.dirt.getDefaultState());
		world.setBlockState(new BlockPos(i + 6, j + 28, k + 14), Blocks.dirt.getDefaultState());
		world.setBlockState(new BlockPos(i + 6, j + 28, k + 15), Blocks.dirt.getDefaultState());
		world.setBlockState(new BlockPos(i + 6, j + 28, k + 16), Blocks.dirt.getDefaultState());
		world.setBlockState(new BlockPos(i + 6, j + 28, k + 17), Blocks.grass.getDefaultState());
		world.setBlockState(new BlockPos(i + 6, j + 28, k + 18), Blocks.grass.getDefaultState());
		world.setBlockState(new BlockPos(i + 6, j + 28, k + 19), Blocks.grass.getDefaultState());
		world.setBlockState(new BlockPos(i + 6, j + 29, k + 7), Blocks.grass.getDefaultState());
		world.setBlockState(new BlockPos(i + 6, j + 29, k + 8), Blocks.grass.getDefaultState());
		world.setBlockState(new BlockPos(i + 6, j + 29, k + 9), Blocks.grass.getDefaultState());
		world.setBlockState(new BlockPos(i + 6, j + 29, k + 10), Blocks.grass.getDefaultState());
		world.setBlockState(new BlockPos(i + 6, j + 29, k + 11), Blocks.grass.getDefaultState());
		world.setBlockState(new BlockPos(i + 6, j + 29, k + 12), Blocks.grass.getDefaultState());
		world.setBlockState(new BlockPos(i + 6, j + 29, k + 13), Blocks.grass.getDefaultState());
		world.setBlockState(new BlockPos(i + 6, j + 29, k + 14), Blocks.grass.getDefaultState());
		world.setBlockState(new BlockPos(i + 6, j + 29, k + 15), Blocks.grass.getDefaultState());
		world.setBlockState(new BlockPos(i + 6, j + 29, k + 16), Blocks.grass.getDefaultState());
		world.setBlockState(new BlockPos(i + 7, j + 12, k + 16), Blocks.grass.getDefaultState());
		world.setBlockState(new BlockPos(i + 7, j + 12, k + 17), Blocks.grass.getDefaultState());
		world.setBlockState(new BlockPos(i + 7, j + 12, k + 18), Blocks.dirt.getDefaultState());
		world.setBlockState(new BlockPos(i + 7, j + 13, k + 18), Blocks.grass.getDefaultState());
		world.setBlockState(new BlockPos(i + 7, j + 25, k + 16), Blocks.dirt.getDefaultState());
		world.setBlockState(new BlockPos(i + 7, j + 25, k + 17), Blocks.dirt.getDefaultState());
		world.setBlockState(new BlockPos(i + 7, j + 25, k + 18), Blocks.dirt.getDefaultState());
		world.setBlockState(new BlockPos(i + 7, j + 26, k + 7), Blocks.dirt.getDefaultState());
		world.setBlockState(new BlockPos(i + 7, j + 26, k + 8), Blocks.dirt.getDefaultState());
		world.setBlockState(new BlockPos(i + 7, j + 26, k + 9), Blocks.dirt.getDefaultState());
		world.setBlockState(new BlockPos(i + 7, j + 26, k + 10), Blocks.dirt.getDefaultState());
		world.setBlockState(new BlockPos(i + 7, j + 26, k + 11), Blocks.dirt.getDefaultState());
		world.setBlockState(new BlockPos(i + 7, j + 26, k + 12), Blocks.dirt.getDefaultState());
		world.setBlockState(new BlockPos(i + 7, j + 26, k + 13), Blocks.dirt.getDefaultState());
		world.setBlockState(new BlockPos(i + 7, j + 26, k + 14), Blocks.dirt.getDefaultState());
		world.setBlockState(new BlockPos(i + 7, j + 26, k + 15), Blocks.dirt.getDefaultState());
		world.setBlockState(new BlockPos(i + 7, j + 26, k + 16), Blocks.dirt.getDefaultState());
		world.setBlockState(new BlockPos(i + 7, j + 26, k + 17), Blocks.dirt.getDefaultState());
		world.setBlockState(new BlockPos(i + 7, j + 26, k + 18), Blocks.dirt.getDefaultState());
		world.setBlockState(new BlockPos(i + 7, j + 26, k + 19), Blocks.dirt.getDefaultState());
		world.setBlockState(new BlockPos(i + 7, j + 26, k + 20), Blocks.dirt.getDefaultState());
		world.setBlockState(new BlockPos(i + 7, j + 26, k + 21), Blocks.grass.getDefaultState());
		world.setBlockState(new BlockPos(i + 7, j + 27, k + 6), Blocks.dirt.getDefaultState());
		world.setBlockState(new BlockPos(i + 7, j + 27, k + 7), Blocks.dirt.getDefaultState());
		world.setBlockState(new BlockPos(i + 7, j + 27, k + 8), Blocks.dirt.getDefaultState());
		world.setBlockState(new BlockPos(i + 7, j + 27, k + 9), Blocks.dirt.getDefaultState());
		world.setBlockState(new BlockPos(i + 7, j + 27, k + 10), Blocks.dirt.getDefaultState());
		world.setBlockState(new BlockPos(i + 7, j + 27, k + 11), Blocks.dirt.getDefaultState());
		world.setBlockState(new BlockPos(i + 7, j + 27, k + 12), Blocks.dirt.getDefaultState());
		world.setBlockState(new BlockPos(i + 7, j + 27, k + 13), Blocks.dirt.getDefaultState());
		world.setBlockState(new BlockPos(i + 7, j + 27, k + 14), Blocks.dirt.getDefaultState());
		world.setBlockState(new BlockPos(i + 7, j + 27, k + 15), Blocks.dirt.getDefaultState());
		world.setBlockState(new BlockPos(i + 7, j + 27, k + 16), Blocks.dirt.getDefaultState());
		world.setBlockState(new BlockPos(i + 7, j + 27, k + 17), Blocks.dirt.getDefaultState());
		world.setBlockState(new BlockPos(i + 7, j + 27, k + 18), Blocks.grass.getDefaultState());
		world.setBlockState(new BlockPos(i + 7, j + 27, k + 19), Blocks.grass.getDefaultState());
		world.setBlockState(new BlockPos(i + 7, j + 27, k + 20), Blocks.grass.getDefaultState());
		world.setBlockState(new BlockPos(i + 7, j + 28, k + 6), Blocks.grass.getDefaultState());
		world.setBlockState(new BlockPos(i + 7, j + 28, k + 7), Blocks.dirt.getDefaultState());
		world.setBlockState(new BlockPos(i + 7, j + 28, k + 8), Blocks.dirt.getDefaultState());
		world.setBlockState(new BlockPos(i + 7, j + 28, k + 9), Blocks.dirt.getDefaultState());
		world.setBlockState(new BlockPos(i + 7, j + 28, k + 10), Blocks.dirt.getDefaultState());
		world.setBlockState(new BlockPos(i + 7, j + 28, k + 11), Blocks.dirt.getDefaultState());
		world.setBlockState(new BlockPos(i + 7, j + 28, k + 12), Blocks.dirt.getDefaultState());
		world.setBlockState(new BlockPos(i + 7, j + 28, k + 13), Blocks.dirt.getDefaultState());
		world.setBlockState(new BlockPos(i + 7, j + 28, k + 14), Blocks.dirt.getDefaultState());
		world.setBlockState(new BlockPos(i + 7, j + 28, k + 15), Blocks.dirt.getDefaultState());
		world.setBlockState(new BlockPos(i + 7, j + 28, k + 16), Blocks.grass.getDefaultState());
		world.setBlockState(new BlockPos(i + 7, j + 28, k + 17), Blocks.grass.getDefaultState());
		world.setBlockState(new BlockPos(i + 7, j + 29, k + 7), Blocks.grass.getDefaultState());
		world.setBlockState(new BlockPos(i + 7, j + 29, k + 8), Blocks.grass.getDefaultState());
		world.setBlockState(new BlockPos(i + 7, j + 29, k + 9), Blocks.grass.getDefaultState());
		world.setBlockState(new BlockPos(i + 7, j + 29, k + 10), Blocks.grass.getDefaultState());
		world.setBlockState(new BlockPos(i + 7, j + 29, k + 11), Blocks.grass.getDefaultState());
		world.setBlockState(new BlockPos(i + 7, j + 29, k + 12), Blocks.grass.getDefaultState());
		world.setBlockState(new BlockPos(i + 7, j + 29, k + 13), Blocks.grass.getDefaultState());
		world.setBlockState(new BlockPos(i + 7, j + 29, k + 14), Blocks.grass.getDefaultState());
		world.setBlockState(new BlockPos(i + 7, j + 29, k + 15), Blocks.grass.getDefaultState());
		world.setBlockState(new BlockPos(i + 8, j + 12, k + 16), Blocks.grass.getDefaultState());
		world.setBlockState(new BlockPos(i + 8, j + 12, k + 17), Blocks.grass.getDefaultState());
		world.setBlockState(new BlockPos(i + 8, j + 12, k + 18), Blocks.dirt.getDefaultState());
		world.setBlockState(new BlockPos(i + 8, j + 12, k + 19), Blocks.grass.getDefaultState());
		world.setBlockState(new BlockPos(i + 8, j + 13, k + 18), Blocks.grass.getDefaultState());
		world.setBlockState(new BlockPos(i + 8, j + 25, k + 15), Blocks.dirt.getDefaultState());
		world.setBlockState(new BlockPos(i + 8, j + 25, k + 16), Blocks.dirt.getDefaultState());
		world.setBlockState(new BlockPos(i + 8, j + 25, k + 17), Blocks.dirt.getDefaultState());
		world.setBlockState(new BlockPos(i + 8, j + 25, k + 18), Blocks.dirt.getDefaultState());
		world.setBlockState(new BlockPos(i + 8, j + 26, k + 6), Blocks.dirt.getDefaultState());
		world.setBlockState(new BlockPos(i + 8, j + 26, k + 7), Blocks.dirt.getDefaultState());
		world.setBlockState(new BlockPos(i + 8, j + 26, k + 8), Blocks.dirt.getDefaultState());
		world.setBlockState(new BlockPos(i + 8, j + 26, k + 9), Blocks.dirt.getDefaultState());
		world.setBlockState(new BlockPos(i + 8, j + 26, k + 10), Blocks.dirt.getDefaultState());
		world.setBlockState(new BlockPos(i + 8, j + 26, k + 11), Blocks.dirt.getDefaultState());
		world.setBlockState(new BlockPos(i + 8, j + 26, k + 12), Blocks.dirt.getDefaultState());
		world.setBlockState(new BlockPos(i + 8, j + 26, k + 13), Blocks.dirt.getDefaultState());
		world.setBlockState(new BlockPos(i + 8, j + 26, k + 14), Blocks.dirt.getDefaultState());
		world.setBlockState(new BlockPos(i + 8, j + 26, k + 15), Blocks.dirt.getDefaultState());
		world.setBlockState(new BlockPos(i + 8, j + 26, k + 16), Blocks.dirt.getDefaultState());
		world.setBlockState(new BlockPos(i + 8, j + 26, k + 17), Blocks.dirt.getDefaultState());
		world.setBlockState(new BlockPos(i + 8, j + 26, k + 18), Blocks.dirt.getDefaultState());
		world.setBlockState(new BlockPos(i + 8, j + 26, k + 19), Blocks.dirt.getDefaultState());
		world.setBlockState(new BlockPos(i + 8, j + 26, k + 20), Blocks.dirt.getDefaultState());
		world.setBlockState(new BlockPos(i + 8, j + 26, k + 21), Blocks.grass.getDefaultState());
		world.setBlockState(new BlockPos(i + 8, j + 27, k + 6), Blocks.dirt.getDefaultState());
		world.setBlockState(new BlockPos(i + 8, j + 27, k + 7), Blocks.dirt.getDefaultState());
		world.setBlockState(new BlockPos(i + 8, j + 27, k + 8), Blocks.dirt.getDefaultState());
		world.setBlockState(new BlockPos(i + 8, j + 27, k + 9), Blocks.dirt.getDefaultState());
		world.setBlockState(new BlockPos(i + 8, j + 27, k + 10), Blocks.dirt.getDefaultState());
		world.setBlockState(new BlockPos(i + 8, j + 27, k + 11), Blocks.dirt.getDefaultState());
		world.setBlockState(new BlockPos(i + 8, j + 27, k + 12), Blocks.dirt.getDefaultState());
		world.setBlockState(new BlockPos(i + 8, j + 27, k + 13), Blocks.dirt.getDefaultState());
		world.setBlockState(new BlockPos(i + 8, j + 27, k + 14), Blocks.dirt.getDefaultState());
		world.setBlockState(new BlockPos(i + 8, j + 27, k + 15), Blocks.dirt.getDefaultState());
		world.setBlockState(new BlockPos(i + 8, j + 27, k + 16), Blocks.dirt.getDefaultState());
		world.setBlockState(new BlockPos(i + 8, j + 27, k + 17), Blocks.grass.getDefaultState());
		world.setBlockState(new BlockPos(i + 8, j + 27, k + 18), Blocks.grass.getDefaultState());
		world.setBlockState(new BlockPos(i + 8, j + 27, k + 19), Blocks.grass.getDefaultState());
		world.setBlockState(new BlockPos(i + 8, j + 27, k + 20), Blocks.grass.getDefaultState());
		world.setBlockState(new BlockPos(i + 8, j + 28, k + 6), Blocks.grass.getDefaultState());
		world.setBlockState(new BlockPos(i + 8, j + 28, k + 7), Blocks.dirt.getDefaultState());
		world.setBlockState(new BlockPos(i + 8, j + 28, k + 8), Blocks.dirt.getDefaultState());
		world.setBlockState(new BlockPos(i + 8, j + 28, k + 9), Blocks.dirt.getDefaultState());
		world.setBlockState(new BlockPos(i + 8, j + 28, k + 10), Blocks.dirt.getDefaultState());
		world.setBlockState(new BlockPos(i + 8, j + 28, k + 11), Blocks.dirt.getDefaultState());
		world.setBlockState(new BlockPos(i + 8, j + 28, k + 12), Blocks.dirt.getDefaultState());
		world.setBlockState(new BlockPos(i + 8, j + 28, k + 13), Blocks.dirt.getDefaultState());
		world.setBlockState(new BlockPos(i + 8, j + 28, k + 14), Blocks.dirt.getDefaultState());
		world.setBlockState(new BlockPos(i + 8, j + 28, k + 15), Blocks.dirt.getDefaultState());
		world.setBlockState(new BlockPos(i + 8, j + 28, k + 16), Blocks.grass.getDefaultState());
		world.setBlockState(new BlockPos(i + 8, j + 29, k + 7), Blocks.grass.getDefaultState());
		world.setBlockState(new BlockPos(i + 8, j + 29, k + 8), Blocks.grass.getDefaultState());
		world.setBlockState(new BlockPos(i + 8, j + 29, k + 9), Blocks.grass.getDefaultState());
		world.setBlockState(new BlockPos(i + 8, j + 29, k + 10), Blocks.grass.getDefaultState());
		world.setBlockState(new BlockPos(i + 8, j + 29, k + 11), Blocks.grass.getDefaultState());
		world.setBlockState(new BlockPos(i + 8, j + 29, k + 12), Blocks.grass.getDefaultState());
		world.setBlockState(new BlockPos(i + 8, j + 29, k + 13), Blocks.grass.getDefaultState());
		world.setBlockState(new BlockPos(i + 8, j + 29, k + 14), Blocks.grass.getDefaultState());
		world.setBlockState(new BlockPos(i + 8, j + 29, k + 15), Blocks.grass.getDefaultState());
		world.setBlockState(new BlockPos(i + 9, j + 12, k + 16), Blocks.grass.getDefaultState());
		world.setBlockState(new BlockPos(i + 9, j + 12, k + 17), Blocks.dirt.getDefaultState());
		world.setBlockState(new BlockPos(i + 9, j + 12, k + 18), Blocks.dirt.getDefaultState());
		world.setBlockState(new BlockPos(i + 9, j + 12, k + 19), Blocks.grass.getDefaultState());
		world.setBlockState(new BlockPos(i + 9, j + 13, k + 17), Blocks.grass.getDefaultState());
		world.setBlockState(new BlockPos(i + 9, j + 13, k + 18), Blocks.grass.getDefaultState());
		world.setBlockState(new BlockPos(i + 9, j + 20, k + 18), Blocks.dirt.getDefaultState());
		world.setBlockState(new BlockPos(i + 9, j + 21, k + 18), Blocks.dirt.getDefaultState());
		world.setBlockState(new BlockPos(i + 9, j + 22, k + 18), Blocks.dirt.getDefaultState());
		world.setBlockState(new BlockPos(i + 9, j + 23, k + 18), Blocks.dirt.getDefaultState());
		world.setBlockState(new BlockPos(i + 9, j + 24, k + 17), Blocks.dirt.getDefaultState());
		world.setBlockState(new BlockPos(i + 9, j + 24, k + 18), Blocks.dirt.getDefaultState());
		world.setBlockState(new BlockPos(i + 9, j + 25, k + 14), Blocks.dirt.getDefaultState());
		world.setBlockState(new BlockPos(i + 9, j + 25, k + 15), Blocks.dirt.getDefaultState());
		world.setBlockState(new BlockPos(i + 9, j + 25, k + 16), Blocks.dirt.getDefaultState());
		world.setBlockState(new BlockPos(i + 9, j + 25, k + 17), Blocks.dirt.getDefaultState());
		world.setBlockState(new BlockPos(i + 9, j + 25, k + 18), Blocks.dirt.getDefaultState());
		world.setBlockState(new BlockPos(i + 9, j + 26, k + 6), Blocks.dirt.getDefaultState());
		world.setBlockState(new BlockPos(i + 9, j + 26, k + 7), Blocks.dirt.getDefaultState());
		world.setBlockState(new BlockPos(i + 9, j + 26, k + 8), Blocks.dirt.getDefaultState());
		world.setBlockState(new BlockPos(i + 9, j + 26, k + 9), Blocks.dirt.getDefaultState());
		world.setBlockState(new BlockPos(i + 9, j + 26, k + 10), Blocks.dirt.getDefaultState());
		world.setBlockState(new BlockPos(i + 9, j + 26, k + 11), Blocks.dirt.getDefaultState());
		world.setBlockState(new BlockPos(i + 9, j + 26, k + 12), Blocks.dirt.getDefaultState());
		world.setBlockState(new BlockPos(i + 9, j + 26, k + 13), Blocks.dirt.getDefaultState());
		world.setBlockState(new BlockPos(i + 9, j + 26, k + 14), Blocks.dirt.getDefaultState());
		world.setBlockState(new BlockPos(i + 9, j + 26, k + 15), Blocks.dirt.getDefaultState());
		world.setBlockState(new BlockPos(i + 9, j + 26, k + 16), Blocks.dirt.getDefaultState());
		world.setBlockState(new BlockPos(i + 9, j + 26, k + 17), Blocks.dirt.getDefaultState());
		world.setBlockState(new BlockPos(i + 9, j + 26, k + 18), Blocks.dirt.getDefaultState());
		world.setBlockState(new BlockPos(i + 9, j + 26, k + 19), Blocks.dirt.getDefaultState());
		world.setBlockState(new BlockPos(i + 9, j + 26, k + 20), Blocks.dirt.getDefaultState());
		world.setBlockState(new BlockPos(i + 9, j + 26, k + 21), Blocks.grass.getDefaultState());
		world.setBlockState(new BlockPos(i + 9, j + 26, k + 22), Blocks.grass.getDefaultState());
		world.setBlockState(new BlockPos(i + 9, j + 27, k + 6), Blocks.dirt.getDefaultState());
		world.setBlockState(new BlockPos(i + 9, j + 27, k + 7), Blocks.dirt.getDefaultState());
		world.setBlockState(new BlockPos(i + 9, j + 27, k + 8), Blocks.dirt.getDefaultState());
		world.setBlockState(new BlockPos(i + 9, j + 27, k + 9), Blocks.dirt.getDefaultState());
		world.setBlockState(new BlockPos(i + 9, j + 27, k + 10), Blocks.dirt.getDefaultState());
		world.setBlockState(new BlockPos(i + 9, j + 27, k + 11), Blocks.dirt.getDefaultState());
		world.setBlockState(new BlockPos(i + 9, j + 27, k + 12), Blocks.dirt.getDefaultState());
		world.setBlockState(new BlockPos(i + 9, j + 27, k + 13), Blocks.dirt.getDefaultState());
		world.setBlockState(new BlockPos(i + 9, j + 27, k + 14), Blocks.dirt.getDefaultState());
		world.setBlockState(new BlockPos(i + 9, j + 27, k + 15), Blocks.dirt.getDefaultState());
		world.setBlockState(new BlockPos(i + 9, j + 27, k + 16), Blocks.dirt.getDefaultState());
		world.setBlockState(new BlockPos(i + 9, j + 27, k + 17), Blocks.dirt.getDefaultState());
		world.setBlockState(new BlockPos(i + 9, j + 27, k + 18), Blocks.grass.getDefaultState());
		world.setBlockState(new BlockPos(i + 9, j + 27, k + 19), Blocks.grass.getDefaultState());
		world.setBlockState(new BlockPos(i + 9, j + 27, k + 20), Blocks.grass.getDefaultState());
		world.setBlockState(new BlockPos(i + 9, j + 28, k + 6), Blocks.grass.getDefaultState());
		world.setBlockState(new BlockPos(i + 9, j + 28, k + 7), Blocks.dirt.getDefaultState());
		world.setBlockState(new BlockPos(i + 9, j + 28, k + 8), Blocks.dirt.getDefaultState());
		world.setBlockState(new BlockPos(i + 9, j + 28, k + 9), Blocks.dirt.getDefaultState());
		world.setBlockState(new BlockPos(i + 9, j + 28, k + 10), Blocks.dirt.getDefaultState());
		world.setBlockState(new BlockPos(i + 9, j + 28, k + 11), Blocks.dirt.getDefaultState());
		world.setBlockState(new BlockPos(i + 9, j + 28, k + 12), Blocks.dirt.getDefaultState());
		world.setBlockState(new BlockPos(i + 9, j + 28, k + 13), Blocks.dirt.getDefaultState());
		world.setBlockState(new BlockPos(i + 9, j + 28, k + 14), Blocks.dirt.getDefaultState());
		world.setBlockState(new BlockPos(i + 9, j + 28, k + 15), Blocks.grass.getDefaultState());
		world.setBlockState(new BlockPos(i + 9, j + 28, k + 16), Blocks.grass.getDefaultState());
		world.setBlockState(new BlockPos(i + 9, j + 28, k + 17), Blocks.grass.getDefaultState());
		world.setBlockState(new BlockPos(i + 9, j + 29, k + 7), Blocks.grass.getDefaultState());
		world.setBlockState(new BlockPos(i + 9, j + 29, k + 8), Blocks.grass.getDefaultState());
		world.setBlockState(new BlockPos(i + 9, j + 29, k + 9), Blocks.grass.getDefaultState());
		world.setBlockState(new BlockPos(i + 9, j + 29, k + 10), Blocks.grass.getDefaultState());
		world.setBlockState(new BlockPos(i + 9, j + 29, k + 11), Blocks.grass.getDefaultState());
		world.setBlockState(new BlockPos(i + 9, j + 29, k + 12), Blocks.grass.getDefaultState());
		world.setBlockState(new BlockPos(i + 9, j + 29, k + 13), Blocks.grass.getDefaultState());
		world.setBlockState(new BlockPos(i + 9, j + 29, k + 14), Blocks.grass.getDefaultState());
		world.setBlockState(new BlockPos(i + 9, j + 29, k + 15), Blocks.grass.getDefaultState());
		world.setBlockState(new BlockPos(i + 10, j + 12, k + 15), Blocks.grass.getDefaultState());
		world.setBlockState(new BlockPos(i + 10, j + 12, k + 16), Blocks.grass.getDefaultState());
		world.setBlockState(new BlockPos(i + 10, j + 12, k + 17), Blocks.dirt.getDefaultState());
		world.setBlockState(new BlockPos(i + 10, j + 12, k + 18), Blocks.dirt.getDefaultState());
		world.setBlockState(new BlockPos(i + 10, j + 12, k + 19), Blocks.grass.getDefaultState());
		world.setBlockState(new BlockPos(i + 10, j + 13, k + 17), Blocks.grass.getDefaultState());
		world.setBlockState(new BlockPos(i + 10, j + 13, k + 18), Blocks.grass.getDefaultState());
		world.setBlockState(new BlockPos(i + 10, j + 19, k + 18), Blocks.dirt.getDefaultState());
		world.setBlockState(new BlockPos(i + 10, j + 20, k + 17), Blocks.dirt.getDefaultState());
		world.setBlockState(new BlockPos(i + 10, j + 20, k + 18), Blocks.dirt.getDefaultState());
		world.setBlockState(new BlockPos(i + 10, j + 21, k + 17), Blocks.dirt.getDefaultState());
		world.setBlockState(new BlockPos(i + 10, j + 21, k + 18), Blocks.dirt.getDefaultState());
		world.setBlockState(new BlockPos(i + 10, j + 22, k + 17), Blocks.dirt.getDefaultState());
		world.setBlockState(new BlockPos(i + 10, j + 22, k + 18), Blocks.dirt.getDefaultState());
		world.setBlockState(new BlockPos(i + 10, j + 23, k + 17), Blocks.dirt.getDefaultState());
		world.setBlockState(new BlockPos(i + 10, j + 23, k + 18), Blocks.dirt.getDefaultState());
		world.setBlockState(new BlockPos(i + 10, j + 24, k + 16), Blocks.dirt.getDefaultState());
		world.setBlockState(new BlockPos(i + 10, j + 24, k + 17), Blocks.dirt.getDefaultState());
		world.setBlockState(new BlockPos(i + 10, j + 24, k + 18), Blocks.dirt.getDefaultState());
		world.setBlockState(new BlockPos(i + 10, j + 24, k + 19), Blocks.dirt.getDefaultState());
		world.setBlockState(new BlockPos(i + 10, j + 24, k + 20), Blocks.dirt.getDefaultState());
		world.setBlockState(new BlockPos(i + 10, j + 24, k + 21), Blocks.dirt.getDefaultState());
		world.setBlockState(new BlockPos(i + 10, j + 24, k + 22), Blocks.dirt.getDefaultState());
		world.setBlockState(new BlockPos(i + 10, j + 25, k + 14), Blocks.dirt.getDefaultState());
		world.setBlockState(new BlockPos(i + 10, j + 25, k + 15), Blocks.dirt.getDefaultState());
		world.setBlockState(new BlockPos(i + 10, j + 25, k + 16), Blocks.dirt.getDefaultState());
		world.setBlockState(new BlockPos(i + 10, j + 25, k + 17), Blocks.dirt.getDefaultState());
		world.setBlockState(new BlockPos(i + 10, j + 25, k + 18), Blocks.dirt.getDefaultState());
		world.setBlockState(new BlockPos(i + 10, j + 25, k + 19), Blocks.dirt.getDefaultState());
		world.setBlockState(new BlockPos(i + 10, j + 25, k + 20), Blocks.dirt.getDefaultState());
		world.setBlockState(new BlockPos(i + 10, j + 25, k + 21), Blocks.dirt.getDefaultState());
		world.setBlockState(new BlockPos(i + 10, j + 25, k + 22), Blocks.dirt.getDefaultState());
		world.setBlockState(new BlockPos(i + 10, j + 26, k + 6), Blocks.dirt.getDefaultState());
		world.setBlockState(new BlockPos(i + 10, j + 26, k + 7), Blocks.dirt.getDefaultState());
		world.setBlockState(new BlockPos(i + 10, j + 26, k + 8), Blocks.dirt.getDefaultState());
		world.setBlockState(new BlockPos(i + 10, j + 26, k + 9), Blocks.dirt.getDefaultState());
		world.setBlockState(new BlockPos(i + 10, j + 26, k + 10), Blocks.dirt.getDefaultState());
		world.setBlockState(new BlockPos(i + 10, j + 26, k + 11), Blocks.dirt.getDefaultState());
		world.setBlockState(new BlockPos(i + 10, j + 26, k + 12), Blocks.dirt.getDefaultState());
		world.setBlockState(new BlockPos(i + 10, j + 26, k + 13), Blocks.dirt.getDefaultState());
		world.setBlockState(new BlockPos(i + 10, j + 26, k + 14), Blocks.dirt.getDefaultState());
		world.setBlockState(new BlockPos(i + 10, j + 26, k + 15), Blocks.dirt.getDefaultState());
		world.setBlockState(new BlockPos(i + 10, j + 26, k + 16), Blocks.dirt.getDefaultState());
		world.setBlockState(new BlockPos(i + 10, j + 26, k + 17), Blocks.dirt.getDefaultState());
		world.setBlockState(new BlockPos(i + 10, j + 26, k + 18), Blocks.dirt.getDefaultState());
		world.setBlockState(new BlockPos(i + 10, j + 26, k + 19), Blocks.dirt.getDefaultState());
		world.setBlockState(new BlockPos(i + 10, j + 26, k + 20), Blocks.dirt.getDefaultState());
		world.setBlockState(new BlockPos(i + 10, j + 26, k + 21), Blocks.grass.getDefaultState());
		world.setBlockState(new BlockPos(i + 10, j + 26, k + 22), Blocks.grass.getDefaultState());
		world.setBlockState(new BlockPos(i + 10, j + 27, k + 6), Blocks.dirt.getDefaultState());
		world.setBlockState(new BlockPos(i + 10, j + 27, k + 7), Blocks.dirt.getDefaultState());
		world.setBlockState(new BlockPos(i + 10, j + 27, k + 8), Blocks.dirt.getDefaultState());
		world.setBlockState(new BlockPos(i + 10, j + 27, k + 9), Blocks.dirt.getDefaultState());
		world.setBlockState(new BlockPos(i + 10, j + 27, k + 10), Blocks.dirt.getDefaultState());
		world.setBlockState(new BlockPos(i + 10, j + 27, k + 11), Blocks.dirt.getDefaultState());
		world.setBlockState(new BlockPos(i + 10, j + 27, k + 12), Blocks.dirt.getDefaultState());
		world.setBlockState(new BlockPos(i + 10, j + 27, k + 13), Blocks.dirt.getDefaultState());
		world.setBlockState(new BlockPos(i + 10, j + 27, k + 14), Blocks.dirt.getDefaultState());
		world.setBlockState(new BlockPos(i + 10, j + 27, k + 15), Blocks.dirt.getDefaultState());
		world.setBlockState(new BlockPos(i + 10, j + 27, k + 16), Blocks.dirt.getDefaultState());
		world.setBlockState(new BlockPos(i + 10, j + 27, k + 17), Blocks.dirt.getDefaultState());
		world.setBlockState(new BlockPos(i + 10, j + 27, k + 18), Blocks.dirt.getDefaultState());
		world.setBlockState(new BlockPos(i + 10, j + 27, k + 19), Blocks.grass.getDefaultState());
		world.setBlockState(new BlockPos(i + 10, j + 27, k + 20), Blocks.grass.getDefaultState());
		world.setBlockState(new BlockPos(i + 10, j + 28, k + 6), Blocks.grass.getDefaultState());
		world.setBlockState(new BlockPos(i + 10, j + 28, k + 7), Blocks.dirt.getDefaultState());
		world.setBlockState(new BlockPos(i + 10, j + 28, k + 8), Blocks.dirt.getDefaultState());
		world.setBlockState(new BlockPos(i + 10, j + 28, k + 9), Blocks.dirt.getDefaultState());
		world.setBlockState(new BlockPos(i + 10, j + 28, k + 10), Blocks.dirt.getDefaultState());
		world.setBlockState(new BlockPos(i + 10, j + 28, k + 11), Blocks.dirt.getDefaultState());
		world.setBlockState(new BlockPos(i + 10, j + 28, k + 12), Blocks.dirt.getDefaultState());
		world.setBlockState(new BlockPos(i + 10, j + 28, k + 13), Blocks.dirt.getDefaultState());
		world.setBlockState(new BlockPos(i + 10, j + 28, k + 14), Blocks.dirt.getDefaultState());
		world.setBlockState(new BlockPos(i + 10, j + 28, k + 15), Blocks.dirt.getDefaultState());
		world.setBlockState(new BlockPos(i + 10, j + 28, k + 16), Blocks.dirt.getDefaultState());
		world.setBlockState(new BlockPos(i + 10, j + 28, k + 17), Blocks.grass.getDefaultState());
		world.setBlockState(new BlockPos(i + 10, j + 28, k + 18), Blocks.grass.getDefaultState());
		world.setBlockState(new BlockPos(i + 10, j + 29, k + 7), Blocks.grass.getDefaultState());
		world.setBlockState(new BlockPos(i + 10, j + 29, k + 8), Blocks.grass.getDefaultState());
		world.setBlockState(new BlockPos(i + 10, j + 29, k + 9), Blocks.grass.getDefaultState());
		world.setBlockState(new BlockPos(i + 10, j + 29, k + 10), Blocks.grass.getDefaultState());
		world.setBlockState(new BlockPos(i + 10, j + 29, k + 11), Blocks.grass.getDefaultState());
		world.setBlockState(new BlockPos(i + 10, j + 29, k + 12), Blocks.grass.getDefaultState());
		world.setBlockState(new BlockPos(i + 10, j + 29, k + 13), Blocks.grass.getDefaultState());
		world.setBlockState(new BlockPos(i + 10, j + 29, k + 14), Blocks.grass.getDefaultState());
		world.setBlockState(new BlockPos(i + 10, j + 29, k + 15), Blocks.grass.getDefaultState());
		world.setBlockState(new BlockPos(i + 10, j + 29, k + 16), Blocks.grass.getDefaultState());
		world.setBlockState(new BlockPos(i + 11, j + 12, k + 15), Blocks.grass.getDefaultState());
		world.setBlockState(new BlockPos(i + 11, j + 12, k + 16), Blocks.grass.getDefaultState());
		world.setBlockState(new BlockPos(i + 11, j + 12, k + 17), Blocks.dirt.getDefaultState());
		world.setBlockState(new BlockPos(i + 11, j + 12, k + 18), Blocks.dirt.getDefaultState());
		world.setBlockState(new BlockPos(i + 11, j + 12, k + 19), Blocks.grass.getDefaultState());
		world.setBlockState(new BlockPos(i + 11, j + 13, k + 17), Blocks.grass.getDefaultState());
		world.setBlockState(new BlockPos(i + 11, j + 13, k + 18), Blocks.dirt.getDefaultState());
		world.setBlockState(new BlockPos(i + 11, j + 14, k + 18), Blocks.grass.getDefaultState());
		world.setBlockState(new BlockPos(i + 11, j + 19, k + 18), Blocks.dirt.getDefaultState());
		world.setBlockState(new BlockPos(i + 11, j + 20, k + 17), Blocks.dirt.getDefaultState());
		world.setBlockState(new BlockPos(i + 11, j + 20, k + 18), Blocks.dirt.getDefaultState());
		world.setBlockState(new BlockPos(i + 11, j + 21, k + 16), Blocks.dirt.getDefaultState());
		world.setBlockState(new BlockPos(i + 11, j + 21, k + 17), Blocks.dirt.getDefaultState());
		world.setBlockState(new BlockPos(i + 11, j + 21, k + 18), Blocks.dirt.getDefaultState());
		world.setBlockState(new BlockPos(i + 11, j + 21, k + 19), Blocks.dirt.getDefaultState());
		world.setBlockState(new BlockPos(i + 11, j + 21, k + 20), Blocks.dirt.getDefaultState());
		world.setBlockState(new BlockPos(i + 11, j + 21, k + 21), Blocks.dirt.getDefaultState());
		world.setBlockState(new BlockPos(i + 11, j + 21, k + 22), Blocks.dirt.getDefaultState());
		world.setBlockState(new BlockPos(i + 11, j + 21, k + 23), Blocks.dirt.getDefaultState());
		world.setBlockState(new BlockPos(i + 11, j + 22, k + 16), Blocks.dirt.getDefaultState());
		world.setBlockState(new BlockPos(i + 11, j + 22, k + 17), Blocks.dirt.getDefaultState());
		world.setBlockState(new BlockPos(i + 11, j + 22, k + 18), Blocks.dirt.getDefaultState());
		world.setBlockState(new BlockPos(i + 11, j + 22, k + 19), Blocks.dirt.getDefaultState());
		world.setBlockState(new BlockPos(i + 11, j + 22, k + 20), Blocks.dirt.getDefaultState());
		world.setBlockState(new BlockPos(i + 11, j + 22, k + 21), Blocks.dirt.getDefaultState());
		world.setBlockState(new BlockPos(i + 11, j + 22, k + 22), Blocks.dirt.getDefaultState());
		world.setBlockState(new BlockPos(i + 11, j + 22, k + 23), Blocks.dirt.getDefaultState());
		world.setBlockState(new BlockPos(i + 11, j + 23, k + 16), Blocks.dirt.getDefaultState());
		world.setBlockState(new BlockPos(i + 11, j + 23, k + 17), Blocks.dirt.getDefaultState());
		world.setBlockState(new BlockPos(i + 11, j + 23, k + 18), Blocks.dirt.getDefaultState());
		world.setBlockState(new BlockPos(i + 11, j + 23, k + 19), Blocks.dirt.getDefaultState());
		world.setBlockState(new BlockPos(i + 11, j + 23, k + 20), Blocks.dirt.getDefaultState());
		world.setBlockState(new BlockPos(i + 11, j + 23, k + 21), Blocks.dirt.getDefaultState());
		world.setBlockState(new BlockPos(i + 11, j + 23, k + 22), Blocks.dirt.getDefaultState());
		world.setBlockState(new BlockPos(i + 11, j + 23, k + 23), Blocks.dirt.getDefaultState());
		world.setBlockState(new BlockPos(i + 11, j + 24, k + 16), Blocks.dirt.getDefaultState());
		world.setBlockState(new BlockPos(i + 11, j + 24, k + 17), Blocks.dirt.getDefaultState());
		world.setBlockState(new BlockPos(i + 11, j + 24, k + 18), Blocks.dirt.getDefaultState());
		world.setBlockState(new BlockPos(i + 11, j + 24, k + 19), Blocks.dirt.getDefaultState());
		world.setBlockState(new BlockPos(i + 11, j + 24, k + 20), Blocks.dirt.getDefaultState());
		world.setBlockState(new BlockPos(i + 11, j + 24, k + 21), Blocks.dirt.getDefaultState());
		world.setBlockState(new BlockPos(i + 11, j + 24, k + 22), Blocks.dirt.getDefaultState());
		world.setBlockState(new BlockPos(i + 11, j + 24, k + 23), Blocks.grass.getDefaultState());
		world.setBlockState(new BlockPos(i + 11, j + 25, k + 13), Blocks.dirt.getDefaultState());
		world.setBlockState(new BlockPos(i + 11, j + 25, k + 14), Blocks.dirt.getDefaultState());
		world.setBlockState(new BlockPos(i + 11, j + 25, k + 15), Blocks.dirt.getDefaultState());
		world.setBlockState(new BlockPos(i + 11, j + 25, k + 16), Blocks.dirt.getDefaultState());
		world.setBlockState(new BlockPos(i + 11, j + 25, k + 17), Blocks.dirt.getDefaultState());
		world.setBlockState(new BlockPos(i + 11, j + 25, k + 18), Blocks.dirt.getDefaultState());
		world.setBlockState(new BlockPos(i + 11, j + 25, k + 19), Blocks.dirt.getDefaultState());
		world.setBlockState(new BlockPos(i + 11, j + 25, k + 20), Blocks.dirt.getDefaultState());
		world.setBlockState(new BlockPos(i + 11, j + 25, k + 21), Blocks.dirt.getDefaultState());
		world.setBlockState(new BlockPos(i + 11, j + 25, k + 22), Blocks.dirt.getDefaultState());
		world.setBlockState(new BlockPos(i + 11, j + 26, k + 6), Blocks.dirt.getDefaultState());
		world.setBlockState(new BlockPos(i + 11, j + 26, k + 7), Blocks.dirt.getDefaultState());
		world.setBlockState(new BlockPos(i + 11, j + 26, k + 8), Blocks.dirt.getDefaultState());
		world.setBlockState(new BlockPos(i + 11, j + 26, k + 9), Blocks.dirt.getDefaultState());
		world.setBlockState(new BlockPos(i + 11, j + 26, k + 10), Blocks.dirt.getDefaultState());
		world.setBlockState(new BlockPos(i + 11, j + 26, k + 11), Blocks.dirt.getDefaultState());
		world.setBlockState(new BlockPos(i + 11, j + 26, k + 12), Blocks.dirt.getDefaultState());
		world.setBlockState(new BlockPos(i + 11, j + 26, k + 13), Blocks.dirt.getDefaultState());
		world.setBlockState(new BlockPos(i + 11, j + 26, k + 14), Blocks.dirt.getDefaultState());
		world.setBlockState(new BlockPos(i + 11, j + 26, k + 15), Blocks.dirt.getDefaultState());
		world.setBlockState(new BlockPos(i + 11, j + 26, k + 16), Blocks.dirt.getDefaultState());
		world.setBlockState(new BlockPos(i + 11, j + 26, k + 17), Blocks.dirt.getDefaultState());
		world.setBlockState(new BlockPos(i + 11, j + 26, k + 18), Blocks.dirt.getDefaultState());
		world.setBlockState(new BlockPos(i + 11, j + 26, k + 19), Blocks.dirt.getDefaultState());
		world.setBlockState(new BlockPos(i + 11, j + 26, k + 20), Blocks.dirt.getDefaultState());
		world.setBlockState(new BlockPos(i + 11, j + 26, k + 21), Blocks.grass.getDefaultState());
		world.setBlockState(new BlockPos(i + 11, j + 26, k + 22), Blocks.grass.getDefaultState());
		world.setBlockState(new BlockPos(i + 11, j + 27, k + 6), Blocks.dirt.getDefaultState());
		world.setBlockState(new BlockPos(i + 11, j + 27, k + 7), Blocks.dirt.getDefaultState());
		world.setBlockState(new BlockPos(i + 11, j + 27, k + 8), Blocks.dirt.getDefaultState());
		world.setBlockState(new BlockPos(i + 11, j + 27, k + 9), Blocks.dirt.getDefaultState());
		world.setBlockState(new BlockPos(i + 11, j + 27, k + 10), Blocks.dirt.getDefaultState());
		world.setBlockState(new BlockPos(i + 11, j + 27, k + 11), Blocks.dirt.getDefaultState());
		world.setBlockState(new BlockPos(i + 11, j + 27, k + 12), Blocks.dirt.getDefaultState());
		world.setBlockState(new BlockPos(i + 11, j + 27, k + 13), Blocks.dirt.getDefaultState());
		world.setBlockState(new BlockPos(i + 11, j + 27, k + 14), Blocks.dirt.getDefaultState());
		world.setBlockState(new BlockPos(i + 11, j + 27, k + 15), Blocks.dirt.getDefaultState());
		world.setBlockState(new BlockPos(i + 11, j + 27, k + 16), Blocks.dirt.getDefaultState());
		world.setBlockState(new BlockPos(i + 11, j + 27, k + 17), Blocks.dirt.getDefaultState());
		world.setBlockState(new BlockPos(i + 11, j + 27, k + 18), Blocks.dirt.getDefaultState());
		world.setBlockState(new BlockPos(i + 11, j + 27, k + 19), Blocks.dirt.getDefaultState());
		world.setBlockState(new BlockPos(i + 11, j + 27, k + 20), Blocks.grass.getDefaultState());
		world.setBlockState(new BlockPos(i + 11, j + 28, k + 6), Blocks.grass.getDefaultState());
		world.setBlockState(new BlockPos(i + 11, j + 28, k + 7), Blocks.dirt.getDefaultState());
		world.setBlockState(new BlockPos(i + 11, j + 28, k + 8), Blocks.dirt.getDefaultState());
		world.setBlockState(new BlockPos(i + 11, j + 28, k + 9), Blocks.dirt.getDefaultState());
		world.setBlockState(new BlockPos(i + 11, j + 28, k + 10), Blocks.dirt.getDefaultState());
		world.setBlockState(new BlockPos(i + 11, j + 28, k + 11), Blocks.dirt.getDefaultState());
		world.setBlockState(new BlockPos(i + 11, j + 28, k + 12), Blocks.dirt.getDefaultState());
		world.setBlockState(new BlockPos(i + 11, j + 28, k + 13), Blocks.dirt.getDefaultState());
		world.setBlockState(new BlockPos(i + 11, j + 28, k + 14), Blocks.dirt.getDefaultState());
		world.setBlockState(new BlockPos(i + 11, j + 28, k + 15), Blocks.dirt.getDefaultState());
		world.setBlockState(new BlockPos(i + 11, j + 28, k + 16), Blocks.dirt.getDefaultState());
		world.setBlockState(new BlockPos(i + 11, j + 28, k + 17), Blocks.dirt.getDefaultState());
		world.setBlockState(new BlockPos(i + 11, j + 28, k + 18), Blocks.grass.getDefaultState());
		world.setBlockState(new BlockPos(i + 11, j + 28, k + 19), Blocks.grass.getDefaultState());
		world.setBlockState(new BlockPos(i + 11, j + 29, k + 7), Blocks.grass.getDefaultState());
		world.setBlockState(new BlockPos(i + 11, j + 29, k + 8), Blocks.grass.getDefaultState());
		world.setBlockState(new BlockPos(i + 11, j + 29, k + 9), Blocks.grass.getDefaultState());
		world.setBlockState(new BlockPos(i + 11, j + 29, k + 10), Blocks.grass.getDefaultState());
		world.setBlockState(new BlockPos(i + 11, j + 29, k + 11), Blocks.grass.getDefaultState());
		world.setBlockState(new BlockPos(i + 11, j + 29, k + 12), Blocks.grass.getDefaultState());
		world.setBlockState(new BlockPos(i + 11, j + 29, k + 13), Blocks.grass.getDefaultState());
		world.setBlockState(new BlockPos(i + 11, j + 29, k + 14), Blocks.grass.getDefaultState());
		world.setBlockState(new BlockPos(i + 11, j + 29, k + 15), Blocks.grass.getDefaultState());
		world.setBlockState(new BlockPos(i + 11, j + 29, k + 16), Blocks.grass.getDefaultState());
		world.setBlockState(new BlockPos(i + 11, j + 29, k + 17), Blocks.grass.getDefaultState());
		world.setBlockState(new BlockPos(i + 12, j + 9, k + 17), Blocks.dirt.getDefaultState());
		world.setBlockState(new BlockPos(i + 12, j + 10, k + 16), Blocks.dirt.getDefaultState());
		world.setBlockState(new BlockPos(i + 12, j + 10, k + 17), Blocks.dirt.getDefaultState());
		world.setBlockState(new BlockPos(i + 12, j + 10, k + 18), Blocks.dirt.getDefaultState());
		world.setBlockState(new BlockPos(i + 12, j + 11, k + 16), Blocks.dirt.getDefaultState());
		world.setBlockState(new BlockPos(i + 12, j + 11, k + 17), Blocks.dirt.getDefaultState());
		world.setBlockState(new BlockPos(i + 12, j + 11, k + 18), Blocks.dirt.getDefaultState());
		world.setBlockState(new BlockPos(i + 12, j + 12, k + 15), Blocks.grass.getDefaultState());
		world.setBlockState(new BlockPos(i + 12, j + 12, k + 16), Blocks.dirt.getDefaultState());
		world.setBlockState(new BlockPos(i + 12, j + 12, k + 17), Blocks.dirt.getDefaultState());
		world.setBlockState(new BlockPos(i + 12, j + 12, k + 18), Blocks.dirt.getDefaultState());
		world.setBlockState(new BlockPos(i + 12, j + 12, k + 19), Blocks.dirt.getDefaultState());
		world.setBlockState(new BlockPos(i + 12, j + 13, k + 16), Blocks.grass.getDefaultState());
		world.setBlockState(new BlockPos(i + 12, j + 13, k + 17), Blocks.grass.getDefaultState());
		world.setBlockState(new BlockPos(i + 12, j + 13, k + 18), Blocks.dirt.getDefaultState());
		world.setBlockState(new BlockPos(i + 12, j + 13, k + 19), Blocks.grass.getDefaultState());
		world.setBlockState(new BlockPos(i + 12, j + 14, k + 18), Blocks.grass.getDefaultState());
		world.setBlockState(new BlockPos(i + 12, j + 18, k + 18), Blocks.dirt.getDefaultState());
		world.setBlockState(new BlockPos(i + 12, j + 19, k + 17), Blocks.dirt.getDefaultState());
		world.setBlockState(new BlockPos(i + 12, j + 19, k + 18), Blocks.dirt.getDefaultState());
		world.setBlockState(new BlockPos(i + 12, j + 20, k + 16), Blocks.dirt.getDefaultState());
		world.setBlockState(new BlockPos(i + 12, j + 20, k + 17), Blocks.dirt.getDefaultState());
		world.setBlockState(new BlockPos(i + 12, j + 20, k + 18), Blocks.dirt.getDefaultState());
		world.setBlockState(new BlockPos(i + 12, j + 21, k + 16), Blocks.dirt.getDefaultState());
		world.setBlockState(new BlockPos(i + 12, j + 21, k + 17), Blocks.dirt.getDefaultState());
		world.setBlockState(new BlockPos(i + 12, j + 21, k + 18), Blocks.dirt.getDefaultState());
		world.setBlockState(new BlockPos(i + 12, j + 21, k + 19), Blocks.dirt.getDefaultState());
		world.setBlockState(new BlockPos(i + 12, j + 21, k + 20), Blocks.dirt.getDefaultState());
		world.setBlockState(new BlockPos(i + 12, j + 21, k + 21), Blocks.dirt.getDefaultState());
		world.setBlockState(new BlockPos(i + 12, j + 21, k + 22), Blocks.dirt.getDefaultState());
		world.setBlockState(new BlockPos(i + 12, j + 21, k + 23), Blocks.dirt.getDefaultState());
		world.setBlockState(new BlockPos(i + 12, j + 22, k + 16), Blocks.dirt.getDefaultState());
		world.setBlockState(new BlockPos(i + 12, j + 22, k + 17), Blocks.dirt.getDefaultState());
		world.setBlockState(new BlockPos(i + 12, j + 22, k + 18), Blocks.dirt.getDefaultState());
		world.setBlockState(new BlockPos(i + 12, j + 22, k + 19), Blocks.dirt.getDefaultState());
		world.setBlockState(new BlockPos(i + 12, j + 22, k + 20), Blocks.dirt.getDefaultState());
		world.setBlockState(new BlockPos(i + 12, j + 22, k + 21), Blocks.dirt.getDefaultState());
		world.setBlockState(new BlockPos(i + 12, j + 22, k + 22), Blocks.dirt.getDefaultState());
		world.setBlockState(new BlockPos(i + 12, j + 22, k + 23), Blocks.dirt.getDefaultState());
		world.setBlockState(new BlockPos(i + 12, j + 22, k + 24), Blocks.dirt.getDefaultState());
		world.setBlockState(new BlockPos(i + 12, j + 23, k + 15), Blocks.dirt.getDefaultState());
		world.setBlockState(new BlockPos(i + 12, j + 23, k + 16), Blocks.dirt.getDefaultState());
		world.setBlockState(new BlockPos(i + 12, j + 23, k + 17), Blocks.dirt.getDefaultState());
		world.setBlockState(new BlockPos(i + 12, j + 23, k + 18), Blocks.dirt.getDefaultState());
		world.setBlockState(new BlockPos(i + 12, j + 23, k + 19), Blocks.dirt.getDefaultState());
		world.setBlockState(new BlockPos(i + 12, j + 23, k + 20), Blocks.dirt.getDefaultState());
		world.setBlockState(new BlockPos(i + 12, j + 23, k + 21), Blocks.dirt.getDefaultState());
		world.setBlockState(new BlockPos(i + 12, j + 23, k + 22), Blocks.dirt.getDefaultState());
		world.setBlockState(new BlockPos(i + 12, j + 23, k + 23), Blocks.dirt.getDefaultState());
		world.setBlockState(new BlockPos(i + 12, j + 23, k + 24), Blocks.grass.getDefaultState());
		world.setBlockState(new BlockPos(i + 12, j + 24, k + 15), Blocks.dirt.getDefaultState());
		world.setBlockState(new BlockPos(i + 12, j + 24, k + 16), Blocks.dirt.getDefaultState());
		world.setBlockState(new BlockPos(i + 12, j + 24, k + 17), Blocks.dirt.getDefaultState());
		world.setBlockState(new BlockPos(i + 12, j + 24, k + 18), Blocks.dirt.getDefaultState());
		world.setBlockState(new BlockPos(i + 12, j + 24, k + 19), Blocks.dirt.getDefaultState());
		world.setBlockState(new BlockPos(i + 12, j + 24, k + 20), Blocks.dirt.getDefaultState());
		world.setBlockState(new BlockPos(i + 12, j + 24, k + 21), Blocks.dirt.getDefaultState());
		world.setBlockState(new BlockPos(i + 12, j + 24, k + 22), Blocks.dirt.getDefaultState());
		world.setBlockState(new BlockPos(i + 12, j + 24, k + 23), Blocks.grass.getDefaultState());
		world.setBlockState(new BlockPos(i + 12, j + 25, k + 13), Blocks.dirt.getDefaultState());
		world.setBlockState(new BlockPos(i + 12, j + 25, k + 14), Blocks.dirt.getDefaultState());
		world.setBlockState(new BlockPos(i + 12, j + 25, k + 15), Blocks.dirt.getDefaultState());
		world.setBlockState(new BlockPos(i + 12, j + 25, k + 16), Blocks.dirt.getDefaultState());
		world.setBlockState(new BlockPos(i + 12, j + 25, k + 17), Blocks.dirt.getDefaultState());
		world.setBlockState(new BlockPos(i + 12, j + 25, k + 18), Blocks.dirt.getDefaultState());
		world.setBlockState(new BlockPos(i + 12, j + 25, k + 19), Blocks.dirt.getDefaultState());
		world.setBlockState(new BlockPos(i + 12, j + 25, k + 20), Blocks.dirt.getDefaultState());
		world.setBlockState(new BlockPos(i + 12, j + 25, k + 21), Blocks.dirt.getDefaultState());
		world.setBlockState(new BlockPos(i + 12, j + 25, k + 22), Blocks.dirt.getDefaultState());
		world.setBlockState(new BlockPos(i + 12, j + 26, k + 6), Blocks.dirt.getDefaultState());
		world.setBlockState(new BlockPos(i + 12, j + 26, k + 7), Blocks.dirt.getDefaultState());
		world.setBlockState(new BlockPos(i + 12, j + 26, k + 8), Blocks.dirt.getDefaultState());
		world.setBlockState(new BlockPos(i + 12, j + 26, k + 9), Blocks.dirt.getDefaultState());
		world.setBlockState(new BlockPos(i + 12, j + 26, k + 10), Blocks.dirt.getDefaultState());
		world.setBlockState(new BlockPos(i + 12, j + 26, k + 11), Blocks.dirt.getDefaultState());
		world.setBlockState(new BlockPos(i + 12, j + 26, k + 12), Blocks.dirt.getDefaultState());
		world.setBlockState(new BlockPos(i + 12, j + 26, k + 13), Blocks.dirt.getDefaultState());
		world.setBlockState(new BlockPos(i + 12, j + 26, k + 14), Blocks.dirt.getDefaultState());
		world.setBlockState(new BlockPos(i + 12, j + 26, k + 15), Blocks.dirt.getDefaultState());
		world.setBlockState(new BlockPos(i + 12, j + 26, k + 16), Blocks.dirt.getDefaultState());
		world.setBlockState(new BlockPos(i + 12, j + 26, k + 17), Blocks.dirt.getDefaultState());
		world.setBlockState(new BlockPos(i + 12, j + 26, k + 18), Blocks.dirt.getDefaultState());
		world.setBlockState(new BlockPos(i + 12, j + 26, k + 19), Blocks.dirt.getDefaultState());
		world.setBlockState(new BlockPos(i + 12, j + 26, k + 20), Blocks.dirt.getDefaultState());
		world.setBlockState(new BlockPos(i + 12, j + 26, k + 21), Blocks.grass.getDefaultState());
		world.setBlockState(new BlockPos(i + 12, j + 26, k + 22), Blocks.grass.getDefaultState());
		world.setBlockState(new BlockPos(i + 12, j + 27, k + 6), Blocks.dirt.getDefaultState());
		world.setBlockState(new BlockPos(i + 12, j + 27, k + 7), Blocks.dirt.getDefaultState());
		world.setBlockState(new BlockPos(i + 12, j + 27, k + 8), Blocks.dirt.getDefaultState());
		world.setBlockState(new BlockPos(i + 12, j + 27, k + 9), Blocks.dirt.getDefaultState());
		world.setBlockState(new BlockPos(i + 12, j + 27, k + 10), Blocks.dirt.getDefaultState());
		world.setBlockState(new BlockPos(i + 12, j + 27, k + 11), Blocks.dirt.getDefaultState());
		world.setBlockState(new BlockPos(i + 12, j + 27, k + 12), Blocks.dirt.getDefaultState());
		world.setBlockState(new BlockPos(i + 12, j + 27, k + 13), Blocks.dirt.getDefaultState());
		world.setBlockState(new BlockPos(i + 12, j + 27, k + 14), Blocks.dirt.getDefaultState());
		world.setBlockState(new BlockPos(i + 12, j + 27, k + 15), Blocks.dirt.getDefaultState());
		world.setBlockState(new BlockPos(i + 12, j + 27, k + 16), Blocks.dirt.getDefaultState());
		world.setBlockState(new BlockPos(i + 12, j + 27, k + 17), Blocks.dirt.getDefaultState());
		world.setBlockState(new BlockPos(i + 12, j + 27, k + 18), Blocks.dirt.getDefaultState());
		world.setBlockState(new BlockPos(i + 12, j + 27, k + 19), Blocks.grass.getDefaultState());
		world.setBlockState(new BlockPos(i + 12, j + 27, k + 20), Blocks.grass.getDefaultState());
		world.setBlockState(new BlockPos(i + 12, j + 28, k + 6), Blocks.grass.getDefaultState());
		world.setBlockState(new BlockPos(i + 12, j + 28, k + 7), Blocks.dirt.getDefaultState());
		world.setBlockState(new BlockPos(i + 12, j + 28, k + 8), Blocks.dirt.getDefaultState());
		world.setBlockState(new BlockPos(i + 12, j + 28, k + 9), Blocks.dirt.getDefaultState());
		world.setBlockState(new BlockPos(i + 12, j + 28, k + 10), Blocks.dirt.getDefaultState());
		world.setBlockState(new BlockPos(i + 12, j + 28, k + 11), Blocks.dirt.getDefaultState());
		world.setBlockState(new BlockPos(i + 12, j + 28, k + 12), Blocks.dirt.getDefaultState());
		world.setBlockState(new BlockPos(i + 12, j + 28, k + 13), Blocks.dirt.getDefaultState());
		world.setBlockState(new BlockPos(i + 12, j + 28, k + 14), Blocks.dirt.getDefaultState());
		world.setBlockState(new BlockPos(i + 12, j + 28, k + 15), Blocks.dirt.getDefaultState());
		world.setBlockState(new BlockPos(i + 12, j + 28, k + 16), Blocks.dirt.getDefaultState());
		world.setBlockState(new BlockPos(i + 12, j + 28, k + 17), Blocks.grass.getDefaultState());
		world.setBlockState(new BlockPos(i + 12, j + 28, k + 18), Blocks.grass.getDefaultState());
		world.setBlockState(new BlockPos(i + 12, j + 29, k + 7), Blocks.grass.getDefaultState());
		world.setBlockState(new BlockPos(i + 12, j + 29, k + 8), Blocks.grass.getDefaultState());
		world.setBlockState(new BlockPos(i + 12, j + 29, k + 9), Blocks.grass.getDefaultState());
		world.setBlockState(new BlockPos(i + 12, j + 29, k + 10), Blocks.grass.getDefaultState());
		world.setBlockState(new BlockPos(i + 12, j + 29, k + 11), Blocks.grass.getDefaultState());
		world.setBlockState(new BlockPos(i + 12, j + 29, k + 12), Blocks.grass.getDefaultState());
		world.setBlockState(new BlockPos(i + 12, j + 29, k + 13), Blocks.grass.getDefaultState());
		world.setBlockState(new BlockPos(i + 12, j + 29, k + 14), Blocks.grass.getDefaultState());
		world.setBlockState(new BlockPos(i + 12, j + 29, k + 15), Blocks.grass.getDefaultState());
		world.setBlockState(new BlockPos(i + 12, j + 29, k + 16), Blocks.grass.getDefaultState());
		world.setBlockState(new BlockPos(i + 13, j + 5, k + 17), Blocks.glowstone.getDefaultState());
		world.setBlockState(new BlockPos(i + 13, j + 6, k + 17), Blocks.dirt.getDefaultState());
		world.setBlockState(new BlockPos(i + 13, j + 7, k + 17), Blocks.dirt.getDefaultState());
		world.setBlockState(new BlockPos(i + 13, j + 8, k + 17), Blocks.dirt.getDefaultState());
		world.setBlockState(new BlockPos(i + 13, j + 9, k + 16), Blocks.dirt.getDefaultState());
		world.setBlockState(new BlockPos(i + 13, j + 9, k + 17), Blocks.dirt.getDefaultState());
		world.setBlockState(new BlockPos(i + 13, j + 9, k + 18), Blocks.dirt.getDefaultState());
		world.setBlockState(new BlockPos(i + 13, j + 10, k + 16), Blocks.dirt.getDefaultState());
		world.setBlockState(new BlockPos(i + 13, j + 10, k + 17), Blocks.dirt.getDefaultState());
		world.setBlockState(new BlockPos(i + 13, j + 10, k + 18), Blocks.dirt.getDefaultState());
		world.setBlockState(new BlockPos(i + 13, j + 11, k + 16), Blocks.dirt.getDefaultState());
		world.setBlockState(new BlockPos(i + 13, j + 11, k + 17), Blocks.dirt.getDefaultState());
		world.setBlockState(new BlockPos(i + 13, j + 11, k + 18), Blocks.dirt.getDefaultState());
		world.setBlockState(new BlockPos(i + 13, j + 12, k + 15), Blocks.grass.getDefaultState());
		world.setBlockState(new BlockPos(i + 13, j + 12, k + 16), Blocks.dirt.getDefaultState());
		world.setBlockState(new BlockPos(i + 13, j + 12, k + 17), Blocks.dirt.getDefaultState());
		world.setBlockState(new BlockPos(i + 13, j + 12, k + 18), Blocks.dirt.getDefaultState());
		world.setBlockState(new BlockPos(i + 13, j + 12, k + 19), Blocks.dirt.getDefaultState());
		world.setBlockState(new BlockPos(i + 13, j + 13, k + 16), Blocks.grass.getDefaultState());
		world.setBlockState(new BlockPos(i + 13, j + 13, k + 17), Blocks.grass.getDefaultState());
		world.setBlockState(new BlockPos(i + 13, j + 13, k + 18), Blocks.dirt.getDefaultState());
		world.setBlockState(new BlockPos(i + 13, j + 13, k + 19), Blocks.dirt.getDefaultState());
		world.setBlockState(new BlockPos(i + 13, j + 14, k + 18), Blocks.grass.getDefaultState());
		world.setBlockState(new BlockPos(i + 13, j + 18, k + 18), Blocks.dirt.getDefaultState());
		world.setBlockState(new BlockPos(i + 13, j + 19, k + 17), Blocks.dirt.getDefaultState());
		world.setBlockState(new BlockPos(i + 13, j + 19, k + 18), Blocks.dirt.getDefaultState());
		world.setBlockState(new BlockPos(i + 13, j + 20, k + 16), Blocks.dirt.getDefaultState());
		world.setBlockState(new BlockPos(i + 13, j + 20, k + 17), Blocks.dirt.getDefaultState());
		world.setBlockState(new BlockPos(i + 13, j + 20, k + 18), Blocks.dirt.getDefaultState());
		world.setBlockState(new BlockPos(i + 13, j + 20, k + 19), Blocks.dirt.getDefaultState());
		world.setBlockState(new BlockPos(i + 13, j + 20, k + 20), Blocks.dirt.getDefaultState());
		world.setBlockState(new BlockPos(i + 13, j + 20, k + 21), Blocks.dirt.getDefaultState());
		world.setBlockState(new BlockPos(i + 13, j + 20, k + 22), Blocks.dirt.getDefaultState());
		world.setBlockState(new BlockPos(i + 13, j + 20, k + 23), Blocks.dirt.getDefaultState());
		world.setBlockState(new BlockPos(i + 13, j + 21, k + 15), Blocks.dirt.getDefaultState());
		world.setBlockState(new BlockPos(i + 13, j + 21, k + 16), Blocks.dirt.getDefaultState());
		world.setBlockState(new BlockPos(i + 13, j + 21, k + 17), Blocks.dirt.getDefaultState());
		world.setBlockState(new BlockPos(i + 13, j + 21, k + 18), Blocks.dirt.getDefaultState());
		world.setBlockState(new BlockPos(i + 13, j + 21, k + 19), Blocks.dirt.getDefaultState());
		world.setBlockState(new BlockPos(i + 13, j + 21, k + 20), Blocks.dirt.getDefaultState());
		world.setBlockState(new BlockPos(i + 13, j + 21, k + 21), Blocks.dirt.getDefaultState());
		world.setBlockState(new BlockPos(i + 13, j + 21, k + 22), Blocks.dirt.getDefaultState());
		world.setBlockState(new BlockPos(i + 13, j + 21, k + 23), Blocks.dirt.getDefaultState());
		world.setBlockState(new BlockPos(i + 13, j + 22, k + 15), Blocks.dirt.getDefaultState());
		world.setBlockState(new BlockPos(i + 13, j + 22, k + 16), Blocks.dirt.getDefaultState());
		world.setBlockState(new BlockPos(i + 13, j + 22, k + 17), Blocks.dirt.getDefaultState());
		world.setBlockState(new BlockPos(i + 13, j + 22, k + 18), Blocks.dirt.getDefaultState());
		world.setBlockState(new BlockPos(i + 13, j + 22, k + 19), Blocks.dirt.getDefaultState());
		world.setBlockState(new BlockPos(i + 13, j + 22, k + 20), Blocks.dirt.getDefaultState());
		world.setBlockState(new BlockPos(i + 13, j + 22, k + 21), Blocks.dirt.getDefaultState());
		world.setBlockState(new BlockPos(i + 13, j + 22, k + 22), Blocks.dirt.getDefaultState());
		world.setBlockState(new BlockPos(i + 13, j + 22, k + 23), Blocks.dirt.getDefaultState());
		world.setBlockState(new BlockPos(i + 13, j + 22, k + 24), Blocks.dirt.getDefaultState());
		world.setBlockState(new BlockPos(i + 13, j + 23, k + 15), Blocks.dirt.getDefaultState());
		world.setBlockState(new BlockPos(i + 13, j + 23, k + 16), Blocks.dirt.getDefaultState());
		world.setBlockState(new BlockPos(i + 13, j + 23, k + 17), Blocks.dirt.getDefaultState());
		world.setBlockState(new BlockPos(i + 13, j + 23, k + 18), Blocks.dirt.getDefaultState());
		world.setBlockState(new BlockPos(i + 13, j + 23, k + 19), Blocks.dirt.getDefaultState());
		world.setBlockState(new BlockPos(i + 13, j + 23, k + 20), Blocks.dirt.getDefaultState());
		world.setBlockState(new BlockPos(i + 13, j + 23, k + 21), Blocks.dirt.getDefaultState());
		world.setBlockState(new BlockPos(i + 13, j + 23, k + 22), Blocks.dirt.getDefaultState());
		world.setBlockState(new BlockPos(i + 13, j + 23, k + 23), Blocks.dirt.getDefaultState());
		world.setBlockState(new BlockPos(i + 13, j + 23, k + 24), Blocks.grass.getDefaultState());
		world.setBlockState(new BlockPos(i + 13, j + 24, k + 15), Blocks.dirt.getDefaultState());
		world.setBlockState(new BlockPos(i + 13, j + 24, k + 16), Blocks.dirt.getDefaultState());
		world.setBlockState(new BlockPos(i + 13, j + 24, k + 17), Blocks.dirt.getDefaultState());
		world.setBlockState(new BlockPos(i + 13, j + 24, k + 18), Blocks.dirt.getDefaultState());
		world.setBlockState(new BlockPos(i + 13, j + 24, k + 19), Blocks.dirt.getDefaultState());
		world.setBlockState(new BlockPos(i + 13, j + 24, k + 20), Blocks.dirt.getDefaultState());
		world.setBlockState(new BlockPos(i + 13, j + 24, k + 21), Blocks.dirt.getDefaultState());
		world.setBlockState(new BlockPos(i + 13, j + 24, k + 22), Blocks.dirt.getDefaultState());
		world.setBlockState(new BlockPos(i + 13, j + 24, k + 23), Blocks.grass.getDefaultState());
		world.setBlockState(new BlockPos(i + 13, j + 25, k + 6), Blocks.dirt.getDefaultState());
		world.setBlockState(new BlockPos(i + 13, j + 25, k + 13), Blocks.dirt.getDefaultState());
		world.setBlockState(new BlockPos(i + 13, j + 25, k + 14), Blocks.dirt.getDefaultState());
		world.setBlockState(new BlockPos(i + 13, j + 25, k + 15), Blocks.dirt.getDefaultState());
		world.setBlockState(new BlockPos(i + 13, j + 25, k + 16), Blocks.dirt.getDefaultState());
		world.setBlockState(new BlockPos(i + 13, j + 25, k + 17), Blocks.dirt.getDefaultState());
		world.setBlockState(new BlockPos(i + 13, j + 25, k + 18), Blocks.dirt.getDefaultState());
		world.setBlockState(new BlockPos(i + 13, j + 25, k + 19), Blocks.dirt.getDefaultState());
		world.setBlockState(new BlockPos(i + 13, j + 25, k + 20), Blocks.dirt.getDefaultState());
		world.setBlockState(new BlockPos(i + 13, j + 25, k + 21), Blocks.dirt.getDefaultState());
		world.setBlockState(new BlockPos(i + 13, j + 25, k + 22), Blocks.dirt.getDefaultState());
		world.setBlockState(new BlockPos(i + 13, j + 26, k + 6), Blocks.dirt.getDefaultState());
		world.setBlockState(new BlockPos(i + 13, j + 26, k + 7), Blocks.dirt.getDefaultState());
		world.setBlockState(new BlockPos(i + 13, j + 26, k + 8), Blocks.dirt.getDefaultState());
		world.setBlockState(new BlockPos(i + 13, j + 26, k + 9), Blocks.dirt.getDefaultState());
		world.setBlockState(new BlockPos(i + 13, j + 26, k + 10), Blocks.dirt.getDefaultState());
		world.setBlockState(new BlockPos(i + 13, j + 26, k + 11), Blocks.dirt.getDefaultState());
		world.setBlockState(new BlockPos(i + 13, j + 26, k + 12), Blocks.dirt.getDefaultState());
		world.setBlockState(new BlockPos(i + 13, j + 26, k + 13), Blocks.dirt.getDefaultState());
		world.setBlockState(new BlockPos(i + 13, j + 26, k + 14), Blocks.dirt.getDefaultState());
		world.setBlockState(new BlockPos(i + 13, j + 26, k + 15), Blocks.dirt.getDefaultState());
		world.setBlockState(new BlockPos(i + 13, j + 26, k + 16), Blocks.dirt.getDefaultState());
		world.setBlockState(new BlockPos(i + 13, j + 26, k + 17), Blocks.dirt.getDefaultState());
		world.setBlockState(new BlockPos(i + 13, j + 26, k + 18), Blocks.dirt.getDefaultState());
		world.setBlockState(new BlockPos(i + 13, j + 26, k + 19), Blocks.dirt.getDefaultState());
		world.setBlockState(new BlockPos(i + 13, j + 26, k + 20), Blocks.grass.getDefaultState());
		world.setBlockState(new BlockPos(i + 13, j + 26, k + 21), Blocks.grass.getDefaultState());
		world.setBlockState(new BlockPos(i + 13, j + 26, k + 22), Blocks.grass.getDefaultState());
		world.setBlockState(new BlockPos(i + 13, j + 27, k + 5), Blocks.grass.getDefaultState());
		world.setBlockState(new BlockPos(i + 13, j + 27, k + 6), Blocks.dirt.getDefaultState());
		world.setBlockState(new BlockPos(i + 13, j + 27, k + 7), Blocks.dirt.getDefaultState());
		world.setBlockState(new BlockPos(i + 13, j + 27, k + 8), Blocks.dirt.getDefaultState());
		world.setBlockState(new BlockPos(i + 13, j + 27, k + 9), Blocks.dirt.getDefaultState());
		world.setBlockState(new BlockPos(i + 13, j + 27, k + 10), Blocks.dirt.getDefaultState());
		world.setBlockState(new BlockPos(i + 13, j + 27, k + 11), Blocks.dirt.getDefaultState());
		world.setBlockState(new BlockPos(i + 13, j + 27, k + 12), Blocks.dirt.getDefaultState());
		world.setBlockState(new BlockPos(i + 13, j + 27, k + 13), Blocks.dirt.getDefaultState());
		world.setBlockState(new BlockPos(i + 13, j + 27, k + 14), Blocks.dirt.getDefaultState());
		world.setBlockState(new BlockPos(i + 13, j + 27, k + 15), Blocks.dirt.getDefaultState());
		world.setBlockState(new BlockPos(i + 13, j + 27, k + 16), Blocks.dirt.getDefaultState());
		world.setBlockState(new BlockPos(i + 13, j + 27, k + 17), Blocks.dirt.getDefaultState());
		world.setBlockState(new BlockPos(i + 13, j + 27, k + 18), Blocks.grass.getDefaultState());
		world.setBlockState(new BlockPos(i + 13, j + 27, k + 19), Blocks.grass.getDefaultState());
		world.setBlockState(new BlockPos(i + 13, j + 28, k + 6), Blocks.grass.getDefaultState());
		world.setBlockState(new BlockPos(i + 13, j + 28, k + 7), Blocks.dirt.getDefaultState());
		world.setBlockState(new BlockPos(i + 13, j + 28, k + 8), Blocks.dirt.getDefaultState());
		world.setBlockState(new BlockPos(i + 13, j + 28, k + 9), Blocks.dirt.getDefaultState());
		world.setBlockState(new BlockPos(i + 13, j + 28, k + 10), Blocks.dirt.getDefaultState());
		world.setBlockState(new BlockPos(i + 13, j + 28, k + 11), Blocks.dirt.getDefaultState());
		world.setBlockState(new BlockPos(i + 13, j + 28, k + 12), Blocks.dirt.getDefaultState());
		world.setBlockState(new BlockPos(i + 13, j + 28, k + 13), Blocks.dirt.getDefaultState());
		world.setBlockState(new BlockPos(i + 13, j + 28, k + 14), Blocks.dirt.getDefaultState());
		world.setBlockState(new BlockPos(i + 13, j + 28, k + 15), Blocks.dirt.getDefaultState());
		world.setBlockState(new BlockPos(i + 13, j + 28, k + 16), Blocks.grass.getDefaultState());
		world.setBlockState(new BlockPos(i + 13, j + 28, k + 17), Blocks.grass.getDefaultState());
		world.setBlockState(new BlockPos(i + 13, j + 29, k + 7), Blocks.grass.getDefaultState());
		world.setBlockState(new BlockPos(i + 13, j + 29, k + 8), Blocks.grass.getDefaultState());
		world.setBlockState(new BlockPos(i + 13, j + 29, k + 9), Blocks.grass.getDefaultState());
		world.setBlockState(new BlockPos(i + 13, j + 29, k + 10), Blocks.grass.getDefaultState());
		world.setBlockState(new BlockPos(i + 13, j + 29, k + 11), Blocks.grass.getDefaultState());
		world.setBlockState(new BlockPos(i + 13, j + 29, k + 12), Blocks.grass.getDefaultState());
		world.setBlockState(new BlockPos(i + 13, j + 29, k + 13), Blocks.grass.getDefaultState());
		world.setBlockState(new BlockPos(i + 13, j + 29, k + 14), Blocks.grass.getDefaultState());
		world.setBlockState(new BlockPos(i + 13, j + 29, k + 15), Blocks.grass.getDefaultState());
		world.setBlockState(new BlockPos(i + 14, j + 9, k + 17), Blocks.dirt.getDefaultState());
		world.setBlockState(new BlockPos(i + 14, j + 10, k + 16), Blocks.dirt.getDefaultState());
		world.setBlockState(new BlockPos(i + 14, j + 10, k + 17), Blocks.dirt.getDefaultState());
		world.setBlockState(new BlockPos(i + 14, j + 10, k + 18), Blocks.dirt.getDefaultState());
		world.setBlockState(new BlockPos(i + 14, j + 11, k + 16), Blocks.dirt.getDefaultState());
		world.setBlockState(new BlockPos(i + 14, j + 11, k + 17), Blocks.dirt.getDefaultState());
		world.setBlockState(new BlockPos(i + 14, j + 11, k + 18), Blocks.dirt.getDefaultState());
		world.setBlockState(new BlockPos(i + 14, j + 12, k + 12), Blocks.dirt.getDefaultState());
		world.setBlockState(new BlockPos(i + 14, j + 12, k + 13), Blocks.dirt.getDefaultState());
		world.setBlockState(new BlockPos(i + 14, j + 12, k + 14), Blocks.dirt.getDefaultState());
		world.setBlockState(new BlockPos(i + 14, j + 12, k + 15), Blocks.dirt.getDefaultState());
		world.setBlockState(new BlockPos(i + 14, j + 12, k + 16), Blocks.dirt.getDefaultState());
		world.setBlockState(new BlockPos(i + 14, j + 12, k + 17), Blocks.dirt.getDefaultState());
		world.setBlockState(new BlockPos(i + 14, j + 12, k + 18), Blocks.dirt.getDefaultState());
		world.setBlockState(new BlockPos(i + 14, j + 13, k + 16), Blocks.grass.getDefaultState());
		world.setBlockState(new BlockPos(i + 14, j + 13, k + 17), Blocks.dirt.getDefaultState());
		world.setBlockState(new BlockPos(i + 14, j + 13, k + 18), Blocks.dirt.getDefaultState());
		world.setBlockState(new BlockPos(i + 14, j + 18, k + 18), Blocks.dirt.getDefaultState());
		world.setBlockState(new BlockPos(i + 14, j + 19, k + 17), Blocks.dirt.getDefaultState());
		world.setBlockState(new BlockPos(i + 14, j + 19, k + 18), Blocks.dirt.getDefaultState());
		world.setBlockState(new BlockPos(i + 14, j + 20, k + 16), Blocks.dirt.getDefaultState());
		world.setBlockState(new BlockPos(i + 14, j + 20, k + 17), Blocks.dirt.getDefaultState());
		world.setBlockState(new BlockPos(i + 14, j + 20, k + 18), Blocks.dirt.getDefaultState());
		world.setBlockState(new BlockPos(i + 14, j + 20, k + 19), Blocks.dirt.getDefaultState());
		world.setBlockState(new BlockPos(i + 14, j + 20, k + 20), Blocks.dirt.getDefaultState());
		world.setBlockState(new BlockPos(i + 14, j + 20, k + 21), Blocks.dirt.getDefaultState());
		world.setBlockState(new BlockPos(i + 14, j + 20, k + 22), Blocks.dirt.getDefaultState());
		world.setBlockState(new BlockPos(i + 14, j + 20, k + 23), Blocks.dirt.getDefaultState());
		world.setBlockState(new BlockPos(i + 14, j + 21, k + 16), Blocks.dirt.getDefaultState());
		world.setBlockState(new BlockPos(i + 14, j + 21, k + 17), Blocks.dirt.getDefaultState());
		world.setBlockState(new BlockPos(i + 14, j + 21, k + 18), Blocks.dirt.getDefaultState());
		world.setBlockState(new BlockPos(i + 14, j + 21, k + 19), Blocks.dirt.getDefaultState());
		world.setBlockState(new BlockPos(i + 14, j + 21, k + 20), Blocks.dirt.getDefaultState());
		world.setBlockState(new BlockPos(i + 14, j + 21, k + 21), Blocks.dirt.getDefaultState());
		world.setBlockState(new BlockPos(i + 14, j + 21, k + 22), Blocks.dirt.getDefaultState());
		world.setBlockState(new BlockPos(i + 14, j + 21, k + 23), Blocks.dirt.getDefaultState());
		world.setBlockState(new BlockPos(i + 14, j + 21, k + 24), Blocks.dirt.getDefaultState());
		world.setBlockState(new BlockPos(i + 14, j + 22, k + 15), Blocks.dirt.getDefaultState());
		world.setBlockState(new BlockPos(i + 14, j + 22, k + 16), Blocks.dirt.getDefaultState());
		world.setBlockState(new BlockPos(i + 14, j + 22, k + 17), Blocks.dirt.getDefaultState());
		world.setBlockState(new BlockPos(i + 14, j + 22, k + 18), Blocks.dirt.getDefaultState());
		world.setBlockState(new BlockPos(i + 14, j + 22, k + 19), Blocks.dirt.getDefaultState());
		world.setBlockState(new BlockPos(i + 14, j + 22, k + 20), Blocks.dirt.getDefaultState());
		world.setBlockState(new BlockPos(i + 14, j + 22, k + 21), Blocks.dirt.getDefaultState());
		world.setBlockState(new BlockPos(i + 14, j + 22, k + 22), Blocks.dirt.getDefaultState());
		world.setBlockState(new BlockPos(i + 14, j + 22, k + 23), Blocks.dirt.getDefaultState());
		world.setBlockState(new BlockPos(i + 14, j + 22, k + 24), Blocks.dirt.getDefaultState());
		world.setBlockState(new BlockPos(i + 14, j + 23, k + 15), Blocks.dirt.getDefaultState());
		world.setBlockState(new BlockPos(i + 14, j + 23, k + 16), Blocks.dirt.getDefaultState());
		world.setBlockState(new BlockPos(i + 14, j + 23, k + 17), Blocks.dirt.getDefaultState());
		world.setBlockState(new BlockPos(i + 14, j + 23, k + 18), Blocks.dirt.getDefaultState());
		world.setBlockState(new BlockPos(i + 14, j + 23, k + 19), Blocks.dirt.getDefaultState());
		world.setBlockState(new BlockPos(i + 14, j + 23, k + 20), Blocks.dirt.getDefaultState());
		world.setBlockState(new BlockPos(i + 14, j + 23, k + 21), Blocks.dirt.getDefaultState());
		world.setBlockState(new BlockPos(i + 14, j + 23, k + 22), Blocks.dirt.getDefaultState());
		world.setBlockState(new BlockPos(i + 14, j + 23, k + 23), Blocks.dirt.getDefaultState());
		world.setBlockState(new BlockPos(i + 14, j + 23, k + 24), Blocks.grass.getDefaultState());
		world.setBlockState(new BlockPos(i + 14, j + 24, k + 15), Blocks.dirt.getDefaultState());
		world.setBlockState(new BlockPos(i + 14, j + 24, k + 16), Blocks.dirt.getDefaultState());
		world.setBlockState(new BlockPos(i + 14, j + 24, k + 17), Blocks.dirt.getDefaultState());
		world.setBlockState(new BlockPos(i + 14, j + 24, k + 18), Blocks.dirt.getDefaultState());
		world.setBlockState(new BlockPos(i + 14, j + 24, k + 19), Blocks.dirt.getDefaultState());
		world.setBlockState(new BlockPos(i + 14, j + 24, k + 20), Blocks.dirt.getDefaultState());
		world.setBlockState(new BlockPos(i + 14, j + 24, k + 21), Blocks.dirt.getDefaultState());
		world.setBlockState(new BlockPos(i + 14, j + 24, k + 22), Blocks.dirt.getDefaultState());
		world.setBlockState(new BlockPos(i + 14, j + 24, k + 23), Blocks.grass.getDefaultState());
		world.setBlockState(new BlockPos(i + 14, j + 25, k + 6), Blocks.dirt.getDefaultState());
		world.setBlockState(new BlockPos(i + 14, j + 25, k + 7), Blocks.dirt.getDefaultState());
		world.setBlockState(new BlockPos(i + 14, j + 25, k + 8), Blocks.dirt.getDefaultState());
		world.setBlockState(new BlockPos(i + 14, j + 25, k + 13), Blocks.dirt.getDefaultState());
		world.setBlockState(new BlockPos(i + 14, j + 25, k + 14), Blocks.dirt.getDefaultState());
		world.setBlockState(new BlockPos(i + 14, j + 25, k + 15), Blocks.dirt.getDefaultState());
		world.setBlockState(new BlockPos(i + 14, j + 25, k + 16), Blocks.dirt.getDefaultState());
		world.setBlockState(new BlockPos(i + 14, j + 25, k + 17), Blocks.dirt.getDefaultState());
		world.setBlockState(new BlockPos(i + 14, j + 25, k + 18), Blocks.dirt.getDefaultState());
		world.setBlockState(new BlockPos(i + 14, j + 25, k + 19), Blocks.dirt.getDefaultState());
		world.setBlockState(new BlockPos(i + 14, j + 25, k + 20), Blocks.dirt.getDefaultState());
		world.setBlockState(new BlockPos(i + 14, j + 25, k + 21), Blocks.dirt.getDefaultState());
		world.setBlockState(new BlockPos(i + 14, j + 25, k + 22), Blocks.dirt.getDefaultState());
		world.setBlockState(new BlockPos(i + 14, j + 26, k + 5), Blocks.dirt.getDefaultState());
		world.setBlockState(new BlockPos(i + 14, j + 26, k + 6), Blocks.dirt.getDefaultState());
		world.setBlockState(new BlockPos(i + 14, j + 26, k + 7), Blocks.dirt.getDefaultState());
		world.setBlockState(new BlockPos(i + 14, j + 26, k + 8), Blocks.dirt.getDefaultState());
		world.setBlockState(new BlockPos(i + 14, j + 26, k + 9), Blocks.dirt.getDefaultState());
		world.setBlockState(new BlockPos(i + 14, j + 26, k + 10), Blocks.dirt.getDefaultState());
		world.setBlockState(new BlockPos(i + 14, j + 26, k + 11), Blocks.dirt.getDefaultState());
		world.setBlockState(new BlockPos(i + 14, j + 26, k + 12), Blocks.dirt.getDefaultState());
		world.setBlockState(new BlockPos(i + 14, j + 26, k + 13), Blocks.dirt.getDefaultState());
		world.setBlockState(new BlockPos(i + 14, j + 26, k + 14), Blocks.dirt.getDefaultState());
		world.setBlockState(new BlockPos(i + 14, j + 26, k + 15), Blocks.dirt.getDefaultState());
		world.setBlockState(new BlockPos(i + 14, j + 26, k + 16), Blocks.dirt.getDefaultState());
		world.setBlockState(new BlockPos(i + 14, j + 26, k + 17), Blocks.dirt.getDefaultState());
		world.setBlockState(new BlockPos(i + 14, j + 26, k + 18), Blocks.dirt.getDefaultState());
		world.setBlockState(new BlockPos(i + 14, j + 26, k + 19), Blocks.dirt.getDefaultState());
		world.setBlockState(new BlockPos(i + 14, j + 26, k + 20), Blocks.dirt.getDefaultState());
		world.setBlockState(new BlockPos(i + 14, j + 26, k + 21), Blocks.grass.getDefaultState());
		world.setBlockState(new BlockPos(i + 14, j + 26, k + 22), Blocks.grass.getDefaultState());
		world.setBlockState(new BlockPos(i + 14, j + 27, k + 5), Blocks.grass.getDefaultState());
		world.setBlockState(new BlockPos(i + 14, j + 27, k + 6), Blocks.dirt.getDefaultState());
		world.setBlockState(new BlockPos(i + 14, j + 27, k + 7), Blocks.dirt.getDefaultState());
		world.setBlockState(new BlockPos(i + 14, j + 27, k + 8), Blocks.dirt.getDefaultState());
		world.setBlockState(new BlockPos(i + 14, j + 27, k + 9), Blocks.dirt.getDefaultState());
		world.setBlockState(new BlockPos(i + 14, j + 27, k + 10), Blocks.dirt.getDefaultState());
		world.setBlockState(new BlockPos(i + 14, j + 27, k + 11), Blocks.dirt.getDefaultState());
		world.setBlockState(new BlockPos(i + 14, j + 27, k + 12), Blocks.dirt.getDefaultState());
		world.setBlockState(new BlockPos(i + 14, j + 27, k + 13), Blocks.dirt.getDefaultState());
		world.setBlockState(new BlockPos(i + 14, j + 27, k + 14), Blocks.dirt.getDefaultState());
		world.setBlockState(new BlockPos(i + 14, j + 27, k + 15), Blocks.dirt.getDefaultState());
		world.setBlockState(new BlockPos(i + 14, j + 27, k + 16), Blocks.dirt.getDefaultState());
		world.setBlockState(new BlockPos(i + 14, j + 27, k + 17), Blocks.grass.getDefaultState());
		world.setBlockState(new BlockPos(i + 14, j + 27, k + 18), Blocks.grass.getDefaultState());
		world.setBlockState(new BlockPos(i + 14, j + 27, k + 19), Blocks.grass.getDefaultState());
		world.setBlockState(new BlockPos(i + 14, j + 27, k + 20), Blocks.grass.getDefaultState());
		world.setBlockState(new BlockPos(i + 14, j + 28, k + 6), Blocks.grass.getDefaultState());
		world.setBlockState(new BlockPos(i + 14, j + 28, k + 7), Blocks.dirt.getDefaultState());
		world.setBlockState(new BlockPos(i + 14, j + 28, k + 8), Blocks.dirt.getDefaultState());
		world.setBlockState(new BlockPos(i + 14, j + 28, k + 9), Blocks.dirt.getDefaultState());
		world.setBlockState(new BlockPos(i + 14, j + 28, k + 10), Blocks.dirt.getDefaultState());
		world.setBlockState(new BlockPos(i + 14, j + 28, k + 11), Blocks.dirt.getDefaultState());
		world.setBlockState(new BlockPos(i + 14, j + 28, k + 12), Blocks.dirt.getDefaultState());
		world.setBlockState(new BlockPos(i + 14, j + 28, k + 13), Blocks.dirt.getDefaultState());
		world.setBlockState(new BlockPos(i + 14, j + 28, k + 14), Blocks.dirt.getDefaultState());
		world.setBlockState(new BlockPos(i + 14, j + 28, k + 15), Blocks.grass.getDefaultState());
		world.setBlockState(new BlockPos(i + 14, j + 28, k + 16), Blocks.grass.getDefaultState());
		world.setBlockState(new BlockPos(i + 14, j + 29, k + 7), Blocks.grass.getDefaultState());
		world.setBlockState(new BlockPos(i + 14, j + 29, k + 8), Blocks.grass.getDefaultState());
		world.setBlockState(new BlockPos(i + 14, j + 29, k + 9), Blocks.grass.getDefaultState());
		world.setBlockState(new BlockPos(i + 14, j + 29, k + 10), Blocks.grass.getDefaultState());
		world.setBlockState(new BlockPos(i + 14, j + 29, k + 11), Blocks.grass.getDefaultState());
		world.setBlockState(new BlockPos(i + 14, j + 29, k + 12), Blocks.grass.getDefaultState());
		world.setBlockState(new BlockPos(i + 14, j + 29, k + 13), Blocks.grass.getDefaultState());
		world.setBlockState(new BlockPos(i + 14, j + 29, k + 14), Blocks.grass.getDefaultState());
		world.setBlockState(new BlockPos(i + 15, j + 11, k + 16), Blocks.dirt.getDefaultState());
		world.setBlockState(new BlockPos(i + 15, j + 11, k + 17), Blocks.dirt.getDefaultState());
		world.setBlockState(new BlockPos(i + 15, j + 12, k + 11), Blocks.dirt.getDefaultState());
		world.setBlockState(new BlockPos(i + 15, j + 12, k + 12), Blocks.dirt.getDefaultState());
		world.setBlockState(new BlockPos(i + 15, j + 12, k + 13), Blocks.dirt.getDefaultState());
		world.setBlockState(new BlockPos(i + 15, j + 12, k + 14), Blocks.dirt.getDefaultState());
		world.setBlockState(new BlockPos(i + 15, j + 12, k + 15), Blocks.dirt.getDefaultState());
		world.setBlockState(new BlockPos(i + 15, j + 12, k + 16), Blocks.dirt.getDefaultState());
		world.setBlockState(new BlockPos(i + 15, j + 12, k + 17), Blocks.dirt.getDefaultState());
		world.setBlockState(new BlockPos(i + 15, j + 13, k + 12), Blocks.dirt.getDefaultState());
		world.setBlockState(new BlockPos(i + 15, j + 13, k + 13), Blocks.dirt.getDefaultState());
		world.setBlockState(new BlockPos(i + 15, j + 13, k + 14), Blocks.dirt.getDefaultState());
		world.setBlockState(new BlockPos(i + 15, j + 13, k + 15), Blocks.grass.getDefaultState());
		world.setBlockState(new BlockPos(i + 15, j + 13, k + 16), Blocks.dirt.getDefaultState());
		world.setBlockState(new BlockPos(i + 15, j + 13, k + 17), Blocks.dirt.getDefaultState());
		world.setBlockState(new BlockPos(i + 15, j + 14, k + 12), Blocks.dirt.getDefaultState());
		world.setBlockState(new BlockPos(i + 15, j + 14, k + 13), Blocks.dirt.getDefaultState());
		world.setBlockState(new BlockPos(i + 15, j + 14, k + 14), Blocks.grass.getDefaultState());
		world.setBlockState(new BlockPos(i + 15, j + 18, k + 18), Blocks.dirt.getDefaultState());
		world.setBlockState(new BlockPos(i + 15, j + 19, k + 17), Blocks.dirt.getDefaultState());
		world.setBlockState(new BlockPos(i + 15, j + 19, k + 18), Blocks.dirt.getDefaultState());
		world.setBlockState(new BlockPos(i + 15, j + 19, k + 19), Blocks.dirt.getDefaultState());
		world.setBlockState(new BlockPos(i + 15, j + 19, k + 20), Blocks.dirt.getDefaultState());
		world.setBlockState(new BlockPos(i + 15, j + 19, k + 21), Blocks.dirt.getDefaultState());
		world.setBlockState(new BlockPos(i + 15, j + 19, k + 22), Blocks.dirt.getDefaultState());
		world.setBlockState(new BlockPos(i + 15, j + 19, k + 23), Blocks.dirt.getDefaultState());
		world.setBlockState(new BlockPos(i + 15, j + 20, k + 16), Blocks.dirt.getDefaultState());
		world.setBlockState(new BlockPos(i + 15, j + 20, k + 17), Blocks.dirt.getDefaultState());
		world.setBlockState(new BlockPos(i + 15, j + 20, k + 18), Blocks.dirt.getDefaultState());
		world.setBlockState(new BlockPos(i + 15, j + 20, k + 19), Blocks.dirt.getDefaultState());
		world.setBlockState(new BlockPos(i + 15, j + 20, k + 20), Blocks.dirt.getDefaultState());
		world.setBlockState(new BlockPos(i + 15, j + 20, k + 21), Blocks.dirt.getDefaultState());
		world.setBlockState(new BlockPos(i + 15, j + 20, k + 22), Blocks.dirt.getDefaultState());
		world.setBlockState(new BlockPos(i + 15, j + 20, k + 23), Blocks.dirt.getDefaultState());
		world.setBlockState(new BlockPos(i + 15, j + 20, k + 24), Blocks.dirt.getDefaultState());
		world.setBlockState(new BlockPos(i + 15, j + 21, k + 16), Blocks.dirt.getDefaultState());
		world.setBlockState(new BlockPos(i + 15, j + 21, k + 17), Blocks.dirt.getDefaultState());
		world.setBlockState(new BlockPos(i + 15, j + 21, k + 18), Blocks.dirt.getDefaultState());
		world.setBlockState(new BlockPos(i + 15, j + 21, k + 19), Blocks.dirt.getDefaultState());
		world.setBlockState(new BlockPos(i + 15, j + 21, k + 20), Blocks.dirt.getDefaultState());
		world.setBlockState(new BlockPos(i + 15, j + 21, k + 21), Blocks.dirt.getDefaultState());
		world.setBlockState(new BlockPos(i + 15, j + 21, k + 22), Blocks.dirt.getDefaultState());
		world.setBlockState(new BlockPos(i + 15, j + 21, k + 23), Blocks.dirt.getDefaultState());
		world.setBlockState(new BlockPos(i + 15, j + 21, k + 24), Blocks.dirt.getDefaultState());
		world.setBlockState(new BlockPos(i + 15, j + 22, k + 16), Blocks.dirt.getDefaultState());
		world.setBlockState(new BlockPos(i + 15, j + 22, k + 17), Blocks.dirt.getDefaultState());
		world.setBlockState(new BlockPos(i + 15, j + 22, k + 18), Blocks.dirt.getDefaultState());
		world.setBlockState(new BlockPos(i + 15, j + 22, k + 19), Blocks.dirt.getDefaultState());
		world.setBlockState(new BlockPos(i + 15, j + 22, k + 20), Blocks.dirt.getDefaultState());
		world.setBlockState(new BlockPos(i + 15, j + 22, k + 21), Blocks.dirt.getDefaultState());
		world.setBlockState(new BlockPos(i + 15, j + 22, k + 22), Blocks.dirt.getDefaultState());
		world.setBlockState(new BlockPos(i + 15, j + 22, k + 23), Blocks.dirt.getDefaultState());
		world.setBlockState(new BlockPos(i + 15, j + 22, k + 24), Blocks.grass.getDefaultState());
		world.setBlockState(new BlockPos(i + 15, j + 23, k + 15), Blocks.dirt.getDefaultState());
		world.setBlockState(new BlockPos(i + 15, j + 23, k + 16), Blocks.dirt.getDefaultState());
		world.setBlockState(new BlockPos(i + 15, j + 23, k + 17), Blocks.dirt.getDefaultState());
		world.setBlockState(new BlockPos(i + 15, j + 23, k + 18), Blocks.dirt.getDefaultState());
		world.setBlockState(new BlockPos(i + 15, j + 23, k + 19), Blocks.dirt.getDefaultState());
		world.setBlockState(new BlockPos(i + 15, j + 23, k + 20), Blocks.dirt.getDefaultState());
		world.setBlockState(new BlockPos(i + 15, j + 23, k + 21), Blocks.dirt.getDefaultState());
		world.setBlockState(new BlockPos(i + 15, j + 23, k + 22), Blocks.dirt.getDefaultState());
		world.setBlockState(new BlockPos(i + 15, j + 23, k + 23), Blocks.dirt.getDefaultState());
		world.setBlockState(new BlockPos(i + 15, j + 24, k + 15), Blocks.dirt.getDefaultState());
		world.setBlockState(new BlockPos(i + 15, j + 24, k + 16), Blocks.dirt.getDefaultState());
		world.setBlockState(new BlockPos(i + 15, j + 24, k + 17), Blocks.dirt.getDefaultState());
		world.setBlockState(new BlockPos(i + 15, j + 24, k + 18), Blocks.dirt.getDefaultState());
		world.setBlockState(new BlockPos(i + 15, j + 24, k + 19), Blocks.dirt.getDefaultState());
		world.setBlockState(new BlockPos(i + 15, j + 24, k + 20), Blocks.dirt.getDefaultState());
		world.setBlockState(new BlockPos(i + 15, j + 24, k + 21), Blocks.dirt.getDefaultState());
		world.setBlockState(new BlockPos(i + 15, j + 24, k + 22), Blocks.dirt.getDefaultState());
		world.setBlockState(new BlockPos(i + 15, j + 24, k + 23), Blocks.grass.getDefaultState());
		world.setBlockState(new BlockPos(i + 15, j + 25, k + 6), Blocks.dirt.getDefaultState());
		world.setBlockState(new BlockPos(i + 15, j + 25, k + 7), Blocks.dirt.getDefaultState());
		world.setBlockState(new BlockPos(i + 15, j + 25, k + 8), Blocks.dirt.getDefaultState());
		world.setBlockState(new BlockPos(i + 15, j + 25, k + 9), Blocks.dirt.getDefaultState());
		world.setBlockState(new BlockPos(i + 15, j + 25, k + 10), Blocks.dirt.getDefaultState());
		world.setBlockState(new BlockPos(i + 15, j + 25, k + 13), Blocks.dirt.getDefaultState());
		world.setBlockState(new BlockPos(i + 15, j + 25, k + 14), Blocks.dirt.getDefaultState());
