package net.journey.dimension.frozen.gen;
import java.util.Random;

import net.journey.JourneyBlocks;
import net.minecraft.init.Blocks;
import net.minecraft.util.math.BlockPos;
import net.minecraft.world.World;
import net.minecraft.world.gen.feature.WorldGenerator;
import net.slayer.api.worldgen.WorldGenAPI;

public class WorldGenIceDungeon extends WorldGenerator {
	
	public boolean locationIsValidSpawn(World w, int x, int y, int z) {
		return WorldGenAPI.checkRadius(w, new BlockPos(x,y,z), 11, JourneyBlocks.brittleIce);
	}
	
	@Override
	public boolean generate(World world, Random r, BlockPos pos) {
		int i = pos.getX(), j = pos.getY() - 1, k = pos.getZ();
		if(locationIsValidSpawn(world, i, j, k)) return true;
		world.setBlockState(new BlockPos(i + 0, j + 0, k + 11), JourneyBlocks.frozenBrick.getDefaultState());
		world.setBlockState(new BlockPos(i + 0, j + 0, k + 12), JourneyBlocks.frozenBrick.getDefaultState());
		world.setBlockState(new BlockPos(i + 0, j + 0, k + 13), JourneyBlocks.frozenBrick.getDefaultState());
		world.setBlockState(new BlockPos(i + 0, j + 0, k + 14), JourneyBlocks.frozenBrick.getDefaultState());
		world.setBlockState(new BlockPos(i + 0, j + 0, k + 15), JourneyBlocks.frozenBrick.getDefaultState());
		world.setBlockState(new BlockPos(i + 0, j + 0, k + 16), JourneyBlocks.frozenBrick.getDefaultState());
		world.setBlockState(new BlockPos(i + 0, j + 1, k + 11), JourneyBlocks.frozenBrick.getDefaultState());
		world.setBlockState(new BlockPos(i + 0, j + 1, k + 12), JourneyBlocks.frozenBrick.getDefaultState());
		world.setBlockState(new BlockPos(i + 0, j + 1, k + 13), JourneyBlocks.frozenBrick.getDefaultState());
		world.setBlockState(new BlockPos(i + 0, j + 1, k + 14), JourneyBlocks.frozenBrick.getDefaultState());
		world.setBlockState(new BlockPos(i + 0, j + 1, k + 15), JourneyBlocks.frozenBrick.getDefaultState());
		world.setBlockState(new BlockPos(i + 0, j + 1, k + 16), JourneyBlocks.frozenBrick.getDefaultState());
		world.setBlockState(new BlockPos(i + 0, j + 2, k + 11), JourneyBlocks.frozenBrick.getDefaultState());
		world.setBlockState(new BlockPos(i + 0, j + 2, k + 12), JourneyBlocks.frozenBrick.getDefaultState());
		world.setBlockState(new BlockPos(i + 0, j + 2, k + 13), JourneyBlocks.frozenBrick.getDefaultState());
		world.setBlockState(new BlockPos(i + 0, j + 2, k + 14), JourneyBlocks.frozenBrick.getDefaultState());
		world.setBlockState(new BlockPos(i + 0, j + 2, k + 15), JourneyBlocks.frozenBrick.getDefaultState());
		world.setBlockState(new BlockPos(i + 0, j + 2, k + 16), JourneyBlocks.frozenBrick.getDefaultState());
		world.setBlockState(new BlockPos(i + 0, j + 3, k + 11), JourneyBlocks.frozenBrick.getDefaultState());
		world.setBlockState(new BlockPos(i + 0, j + 3, k + 12), JourneyBlocks.frozenBrick.getDefaultState());
		world.setBlockState(new BlockPos(i + 0, j + 3, k + 13), JourneyBlocks.frozenBrick.getDefaultState());
		world.setBlockState(new BlockPos(i + 0, j + 3, k + 14), JourneyBlocks.frozenBrick.getDefaultState());
		world.setBlockState(new BlockPos(i + 0, j + 3, k + 15), JourneyBlocks.frozenBrick.getDefaultState());
		world.setBlockState(new BlockPos(i + 0, j + 3, k + 16), JourneyBlocks.frozenBrick.getDefaultState());
		world.setBlockState(new BlockPos(i + 0, j + 4, k + 11), JourneyBlocks.frozenBrick.getDefaultState());
		world.setBlockState(new BlockPos(i + 0, j + 4, k + 12), JourneyBlocks.frozenBrick.getDefaultState());
		world.setBlockState(new BlockPos(i + 0, j + 4, k + 13), JourneyBlocks.frozenBrick.getDefaultState());
		world.setBlockState(new BlockPos(i + 0, j + 4, k + 14), JourneyBlocks.frozenBrick.getDefaultState());
		world.setBlockState(new BlockPos(i + 0, j + 4, k + 15), JourneyBlocks.frozenBrick.getDefaultState());
		world.setBlockState(new BlockPos(i + 0, j + 4, k + 16), JourneyBlocks.frozenBrick.getDefaultState());
		world.setBlockState(new BlockPos(i + 0, j + 5, k + 11), JourneyBlocks.frozenBrick.getDefaultState());
		world.setBlockState(new BlockPos(i + 0, j + 5, k + 12), JourneyBlocks.frozenBrick.getDefaultState());
		world.setBlockState(new BlockPos(i + 0, j + 5, k + 13), JourneyBlocks.frozenBrick.getDefaultState());
		world.setBlockState(new BlockPos(i + 0, j + 5, k + 14), JourneyBlocks.frozenBrick.getDefaultState());
		world.setBlockState(new BlockPos(i + 0, j + 5, k + 15), JourneyBlocks.frozenBrick.getDefaultState());
		world.setBlockState(new BlockPos(i + 0, j + 5, k + 16), JourneyBlocks.frozenBrick.getDefaultState());
		world.setBlockState(new BlockPos(i + 1, j + 0, k + 11), JourneyBlocks.frozenBrick.getDefaultState());
		world.setBlockState(new BlockPos(i + 1, j + 0, k + 12), JourneyBlocks.frozenBrick.getDefaultState());
		world.setBlockState(new BlockPos(i + 1, j + 0, k + 13), JourneyBlocks.frozenBrick.getDefaultState());
		world.setBlockState(new BlockPos(i + 1, j + 0, k + 14), JourneyBlocks.frozenBrick.getDefaultState());
		world.setBlockState(new BlockPos(i + 1, j + 0, k + 15), JourneyBlocks.frozenBrick.getDefaultState());
		world.setBlockState(new BlockPos(i + 1, j + 0, k + 16), JourneyBlocks.frozenBrick.getDefaultState());
		world.setBlockState(new BlockPos(i + 1, j + 1, k + 11), JourneyBlocks.frozenBrick.getDefaultState());
		world.setBlockState(new BlockPos(i + 1, j + 1, k + 13), JourneyBlocks.frostbiterSpawner.getDefaultState());
		world.setBlockState(new BlockPos(i + 1, j + 1, k + 14), JourneyBlocks.frostbiterSpawner.getDefaultState());
		world.setBlockState(new BlockPos(i + 1, j + 1, k + 16), JourneyBlocks.frozenBrick.getDefaultState());
		world.setBlockState(new BlockPos(i + 1, j + 2, k + 11), JourneyBlocks.frozenBrick.getDefaultState());
		world.setBlockState(new BlockPos(i + 1, j + 2, k + 16), JourneyBlocks.frozenBrick.getDefaultState());
		world.setBlockState(new BlockPos(i + 1, j + 3, k + 11), JourneyBlocks.frozenBrick.getDefaultState());
		world.setBlockState(new BlockPos(i + 1, j + 3, k + 16), JourneyBlocks.frozenBrick.getDefaultState());
		world.setBlockState(new BlockPos(i + 1, j + 4, k + 11), JourneyBlocks.frozenBrick.getDefaultState());
		world.setBlockState(new BlockPos(i + 1, j + 4, k + 12), JourneyBlocks.icicle.getDefaultState());
		world.setBlockState(new BlockPos(i + 1, j + 4, k + 13), JourneyBlocks.icicle.getDefaultState());
		world.setBlockState(new BlockPos(i + 1, j + 4, k + 16), JourneyBlocks.frozenBrick.getDefaultState());
		world.setBlockState(new BlockPos(i + 1, j + 5, k + 11), JourneyBlocks.frozenBrick.getDefaultState());
		world.setBlockState(new BlockPos(i + 1, j + 5, k + 12), JourneyBlocks.frozenBrick.getDefaultState());
		world.setBlockState(new BlockPos(i + 1, j + 5, k + 13), JourneyBlocks.frozenBrick.getDefaultState());
		world.setBlockState(new BlockPos(i + 1, j + 5, k + 14), JourneyBlocks.frozenBrick.getDefaultState());
		world.setBlockState(new BlockPos(i + 1, j + 5, k + 15), JourneyBlocks.frozenBrick.getDefaultState());
		world.setBlockState(new BlockPos(i + 1, j + 5, k + 16), JourneyBlocks.frozenBrick.getDefaultState());
		world.setBlockState(new BlockPos(i + 2, j + 0, k + 11), JourneyBlocks.frozenBrick.getDefaultState());
		world.setBlockState(new BlockPos(i + 2, j + 0, k + 12), JourneyBlocks.frozenBrick.getDefaultState());
		world.setBlockState(new BlockPos(i + 2, j + 0, k + 13), JourneyBlocks.frozenBrick.getDefaultState());
		world.setBlockState(new BlockPos(i + 2, j + 0, k + 14), JourneyBlocks.frozenBrick.getDefaultState());
		world.setBlockState(new BlockPos(i + 2, j + 0, k + 15), JourneyBlocks.frozenBrick.getDefaultState());
		world.setBlockState(new BlockPos(i + 2, j + 0, k + 16), JourneyBlocks.frozenBrick.getDefaultState());
		world.setBlockState(new BlockPos(i + 2, j + 1, k + 11), JourneyBlocks.frozenBrick.getDefaultState());
		world.setBlockState(new BlockPos(i + 2, j + 1, k + 16), JourneyBlocks.frozenBrick.getDefaultState());
		world.setBlockState(new BlockPos(i + 2, j + 2, k + 11), JourneyBlocks.frozenBrick.getDefaultState());
		world.setBlockState(new BlockPos(i + 2, j + 2, k + 16), JourneyBlocks.frozenBrick.getDefaultState());
		world.setBlockState(new BlockPos(i + 2, j + 3, k + 11), JourneyBlocks.frozenBrick.getDefaultState());
		world.setBlockState(new BlockPos(i + 2, j + 3, k + 16), JourneyBlocks.frozenBrick.getDefaultState());
		world.setBlockState(new BlockPos(i + 2, j + 4, k + 11), JourneyBlocks.frozenBrick.getDefaultState());
		world.setBlockState(new BlockPos(i + 2, j + 4, k + 16), JourneyBlocks.frozenBrick.getDefaultState());
		world.setBlockState(new BlockPos(i + 2, j + 5, k + 11), JourneyBlocks.frozenBrick.getDefaultState());
		world.setBlockState(new BlockPos(i + 2, j + 5, k + 12), JourneyBlocks.frozenBrick.getDefaultState());
		world.setBlockState(new BlockPos(i + 2, j + 5, k + 13), Blocks.ICE.getDefaultState());
		world.setBlockState(new BlockPos(i + 2, j + 5, k + 14), Blocks.ICE.getDefaultState());
		world.setBlockState(new BlockPos(i + 2, j + 5, k + 15), JourneyBlocks.frozenBrick.getDefaultState());
		world.setBlockState(new BlockPos(i + 2, j + 5, k + 16), JourneyBlocks.frozenBrick.getDefaultState());
		world.setBlockState(new BlockPos(i + 3, j + 0, k + 11), JourneyBlocks.frozenBrick.getDefaultState());
		world.setBlockState(new BlockPos(i + 3, j + 0, k + 12), JourneyBlocks.frozenBrick.getDefaultState());
		world.setBlockState(new BlockPos(i + 3, j + 0, k + 13), JourneyBlocks.frozenBrick.getDefaultState());
		world.setBlockState(new BlockPos(i + 3, j + 0, k + 14), JourneyBlocks.frozenBrick.getDefaultState());
		world.setBlockState(new BlockPos(i + 3, j + 0, k + 15), JourneyBlocks.frozenBrick.getDefaultState());
		world.setBlockState(new BlockPos(i + 3, j + 0, k + 16), JourneyBlocks.frozenBrick.getDefaultState());
		world.setBlockState(new BlockPos(i + 3, j + 1, k + 11), JourneyBlocks.frozenBrick.getDefaultState());
		world.setBlockState(new BlockPos(i + 3, j + 1, k + 16), JourneyBlocks.frozenBrick.getDefaultState());
		world.setBlockState(new BlockPos(i + 3, j + 2, k + 11), JourneyBlocks.frozenBrick.getDefaultState());
		world.setBlockState(new BlockPos(i + 3, j + 2, k + 16), JourneyBlocks.frozenBrick.getDefaultState());
		world.setBlockState(new BlockPos(i + 3, j + 3, k + 11), JourneyBlocks.frozenBrick.getDefaultState());
		world.setBlockState(new BlockPos(i + 3, j + 3, k + 16), JourneyBlocks.frozenBrick.getDefaultState());
		world.setBlockState(new BlockPos(i + 3, j + 4, k + 11), JourneyBlocks.frozenBrick.getDefaultState());
		world.setBlockState(new BlockPos(i + 3, j + 4, k + 12), JourneyBlocks.icicle.getDefaultState());
		world.setBlockState(new BlockPos(i + 3, j + 4, k + 15), JourneyBlocks.icicle.getDefaultState());
		world.setBlockState(new BlockPos(i + 3, j + 4, k + 16), JourneyBlocks.frozenBrick.getDefaultState());
		world.setBlockState(new BlockPos(i + 3, j + 5, k + 11), JourneyBlocks.frozenBrick.getDefaultState());
		world.setBlockState(new BlockPos(i + 3, j + 5, k + 12), JourneyBlocks.frozenBrick.getDefaultState());
		world.setBlockState(new BlockPos(i + 3, j + 5, k + 13), Blocks.ICE.getDefaultState());
		world.setBlockState(new BlockPos(i + 3, j + 5, k + 14), Blocks.ICE.getDefaultState());
		world.setBlockState(new BlockPos(i + 3, j + 5, k + 15), JourneyBlocks.frozenBrick.getDefaultState());
		world.setBlockState(new BlockPos(i + 3, j + 5, k + 16), JourneyBlocks.frozenBrick.getDefaultState());
		world.setBlockState(new BlockPos(i + 4, j + 0, k + 11), JourneyBlocks.frozenBrick.getDefaultState());
		world.setBlockState(new BlockPos(i + 4, j + 0, k + 12), JourneyBlocks.frozenBrick.getDefaultState());
		world.setBlockState(new BlockPos(i + 4, j + 0, k + 13), JourneyBlocks.frozenBrick.getDefaultState());
		world.setBlockState(new BlockPos(i + 4, j + 0, k + 14), JourneyBlocks.frozenBrick.getDefaultState());
		world.setBlockState(new BlockPos(i + 4, j + 0, k + 15), JourneyBlocks.frozenBrick.getDefaultState());
		world.setBlockState(new BlockPos(i + 4, j + 0, k + 16), JourneyBlocks.frozenBrick.getDefaultState());
		world.setBlockState(new BlockPos(i + 4, j + 1, k + 11), JourneyBlocks.frozenBrick.getDefaultState());
		world.setBlockState(new BlockPos(i + 4, j + 1, k + 16), JourneyBlocks.frozenBrick.getDefaultState());
		world.setBlockState(new BlockPos(i + 4, j + 2, k + 11), JourneyBlocks.frozenBrick.getDefaultState());
		world.setBlockState(new BlockPos(i + 4, j + 2, k + 16), JourneyBlocks.frozenBrick.getDefaultState());
		world.setBlockState(new BlockPos(i + 4, j + 3, k + 11), JourneyBlocks.frozenBrick.getDefaultState());
		world.setBlockState(new BlockPos(i + 4, j + 3, k + 16), JourneyBlocks.frozenBrick.getDefaultState());
		world.setBlockState(new BlockPos(i + 4, j + 4, k + 11), JourneyBlocks.frozenBrick.getDefaultState());
		world.setBlockState(new BlockPos(i + 4, j + 4, k + 12), JourneyBlocks.icicle.getDefaultState());
		world.setBlockState(new BlockPos(i + 4, j + 4, k + 14), JourneyBlocks.icicle.getDefaultState());
		world.setBlockState(new BlockPos(i + 4, j + 4, k + 15), JourneyBlocks.icicle.getDefaultState());
		world.setBlockState(new BlockPos(i + 4, j + 4, k + 16), JourneyBlocks.frozenBrick.getDefaultState());
		world.setBlockState(new BlockPos(i + 4, j + 5, k + 11), JourneyBlocks.frozenBrick.getDefaultState());
		world.setBlockState(new BlockPos(i + 4, j + 5, k + 12), JourneyBlocks.frozenBrick.getDefaultState());
		world.setBlockState(new BlockPos(i + 4, j + 5, k + 13), JourneyBlocks.frozenBrick.getDefaultState());
		world.setBlockState(new BlockPos(i + 4, j + 5, k + 14), JourneyBlocks.frozenBrick.getDefaultState());
		world.setBlockState(new BlockPos(i + 4, j + 5, k + 15), JourneyBlocks.frozenBrick.getDefaultState());
		world.setBlockState(new BlockPos(i + 4, j + 5, k + 16), JourneyBlocks.frozenBrick.getDefaultState());
		world.setBlockState(new BlockPos(i + 5, j + 0, k + 11), JourneyBlocks.frozenBrick.getDefaultState());
		world.setBlockState(new BlockPos(i + 5, j + 0, k + 12), JourneyBlocks.frozenBrick.getDefaultState());
		world.setBlockState(new BlockPos(i + 5, j + 0, k + 13), JourneyBlocks.frozenBrick.getDefaultState());
		world.setBlockState(new BlockPos(i + 5, j + 0, k + 14), JourneyBlocks.frozenBrick.getDefaultState());
		world.setBlockState(new BlockPos(i + 5, j + 0, k + 15), JourneyBlocks.frozenBrick.getDefaultState());
		world.setBlockState(new BlockPos(i + 5, j + 0, k + 16), JourneyBlocks.frozenBrick.getDefaultState());
		world.setBlockState(new BlockPos(i + 5, j + 1, k + 11), JourneyBlocks.frozenBrick.getDefaultState());
		world.setBlockState(new BlockPos(i + 5, j + 1, k + 16), JourneyBlocks.frozenBrick.getDefaultState());
		world.setBlockState(new BlockPos(i + 5, j + 2, k + 11), JourneyBlocks.frozenBrick.getDefaultState());
		world.setBlockState(new BlockPos(i + 5, j + 2, k + 16), JourneyBlocks.frozenBrick.getDefaultState());
		world.setBlockState(new BlockPos(i + 5, j + 3, k + 11), JourneyBlocks.frozenBrick.getDefaultState());
		world.setBlockState(new BlockPos(i + 5, j + 3, k + 16), JourneyBlocks.frozenBrick.getDefaultState());
		world.setBlockState(new BlockPos(i + 5, j + 4, k + 11), JourneyBlocks.frozenBrick.getDefaultState());
		world.setBlockState(new BlockPos(i + 5, j + 4, k + 16), JourneyBlocks.frozenBrick.getDefaultState());
		world.setBlockState(new BlockPos(i + 5, j + 5, k + 11), JourneyBlocks.frozenBrick.getDefaultState());
		world.setBlockState(new BlockPos(i + 5, j + 5, k + 12), JourneyBlocks.frozenBrick.getDefaultState());
		world.setBlockState(new BlockPos(i + 5, j + 5, k + 13), JourneyBlocks.frozenBrick.getDefaultState());
		world.setBlockState(new BlockPos(i + 5, j + 5, k + 14), JourneyBlocks.frozenBrick.getDefaultState());
		world.setBlockState(new BlockPos(i + 5, j + 5, k + 15), JourneyBlocks.frozenBrick.getDefaultState());
		world.setBlockState(new BlockPos(i + 5, j + 5, k + 16), JourneyBlocks.frozenBrick.getDefaultState());
		world.setBlockState(new BlockPos(i + 6, j + 0, k + 12), JourneyBlocks.frozenBrick.getDefaultState());
		world.setBlockState(new BlockPos(i + 6, j + 0, k + 13), JourneyBlocks.frozenBrick.getDefaultState());
		world.setBlockState(new BlockPos(i + 6, j + 0, k + 14), JourneyBlocks.frozenBrick.getDefaultState());
		world.setBlockState(new BlockPos(i + 6, j + 0, k + 15), JourneyBlocks.frozenBrick.getDefaultState());
		world.setBlockState(new BlockPos(i + 6, j + 1, k + 12), JourneyBlocks.frozenBrick.getDefaultState());
		world.setBlockState(new BlockPos(i + 6, j + 1, k + 15), JourneyBlocks.frozenBrick.getDefaultState());
		world.setBlockState(new BlockPos(i + 6, j + 2, k + 12), Blocks.ICE.getDefaultState());
		world.setBlockState(new BlockPos(i + 6, j + 2, k + 15), Blocks.ICE.getDefaultState());
		world.setBlockState(new BlockPos(i + 6, j + 3, k + 12), JourneyBlocks.frozenBrick.getDefaultState());
		world.setBlockState(new BlockPos(i + 6, j + 3, k + 15), JourneyBlocks.frozenBrick.getDefaultState());
		world.setBlockState(new BlockPos(i + 6, j + 4, k + 12), JourneyBlocks.frozenBrick.getDefaultState());
		world.setBlockState(new BlockPos(i + 6, j + 4, k + 13), JourneyBlocks.frozenBrick.getDefaultState());
		world.setBlockState(new BlockPos(i + 6, j + 4, k + 14), JourneyBlocks.frozenBrick.getDefaultState());
		world.setBlockState(new BlockPos(i + 6, j + 4, k + 15), JourneyBlocks.frozenBrick.getDefaultState());
		world.setBlockState(new BlockPos(i + 7, j + 0, k + 12), JourneyBlocks.frozenBrick.getDefaultState());
		world.setBlockState(new BlockPos(i + 7, j + 0, k + 13), JourneyBlocks.frozenBrick.getDefaultState());
		world.setBlockState(new BlockPos(i + 7, j + 0, k + 14), JourneyBlocks.frozenBrick.getDefaultState());
		world.setBlockState(new BlockPos(i + 7, j + 0, k + 15), JourneyBlocks.frozenBrick.getDefaultState());
		world.setBlockState(new BlockPos(i + 7, j + 1, k + 12), JourneyBlocks.frozenBrick.getDefaultState());
		world.setBlockState(new BlockPos(i + 7, j + 1, k + 15), JourneyBlocks.frozenBrick.getDefaultState());
		world.setBlockState(new BlockPos(i + 7, j + 2, k + 12), Blocks.ICE.getDefaultState());
		world.setBlockState(new BlockPos(i + 7, j + 2, k + 15), Blocks.ICE.getDefaultState());
		world.setBlockState(new BlockPos(i + 7, j + 3, k + 12), JourneyBlocks.frozenBrick.getDefaultState());
		world.setBlockState(new BlockPos(i + 7, j + 3, k + 14), JourneyBlocks.icicle.getDefaultState());
		world.setBlockState(new BlockPos(i + 7, j + 3, k + 15), JourneyBlocks.frozenBrick.getDefaultState());
		world.setBlockState(new BlockPos(i + 7, j + 4, k + 12), JourneyBlocks.frozenBrick.getDefaultState());
		world.setBlockState(new BlockPos(i + 7, j + 4, k + 13), JourneyBlocks.frozenBrick.getDefaultState());
		world.setBlockState(new BlockPos(i + 7, j + 4, k + 14), JourneyBlocks.frozenBrick.getDefaultState());
		world.setBlockState(new BlockPos(i + 7, j + 4, k + 15), JourneyBlocks.frozenBrick.getDefaultState());
		world.setBlockState(new BlockPos(i + 8, j + 0, k + 12), JourneyBlocks.frozenBrick.getDefaultState());
		world.setBlockState(new BlockPos(i + 8, j + 0, k + 13), JourneyBlocks.frozenBrick.getDefaultState());
		world.setBlockState(new BlockPos(i + 8, j + 0, k + 14), JourneyBlocks.frozenBrick.getDefaultState());
		world.setBlockState(new BlockPos(i + 8, j + 0, k + 15), JourneyBlocks.frozenBrick.getDefaultState());
		world.setBlockState(new BlockPos(i + 8, j + 1, k + 12), JourneyBlocks.frozenBrick.getDefaultState());
		world.setBlockState(new BlockPos(i + 8, j + 1, k + 15), JourneyBlocks.frozenBrick.getDefaultState());
		world.setBlockState(new BlockPos(i + 8, j + 2, k + 12), Blocks.ICE.getDefaultState());
		world.setBlockState(new BlockPos(i + 8, j + 2, k + 15), Blocks.ICE.getDefaultState());
		world.setBlockState(new BlockPos(i + 8, j + 3, k + 12), JourneyBlocks.frozenBrick.getDefaultState());
		world.setBlockState(new BlockPos(i + 8, j + 3, k + 15), JourneyBlocks.frozenBrick.getDefaultState());
		world.setBlockState(new BlockPos(i + 8, j + 4, k + 12), JourneyBlocks.frozenBrick.getDefaultState());
		world.setBlockState(new BlockPos(i + 8, j + 4, k + 13), JourneyBlocks.frozenBrick.getDefaultState());
		world.setBlockState(new BlockPos(i + 8, j + 4, k + 14), JourneyBlocks.frozenBrick.getDefaultState());
		world.setBlockState(new BlockPos(i + 8, j + 4, k + 15), JourneyBlocks.frozenBrick.getDefaultState());
		world.setBlockState(new BlockPos(i + 9, j + 0, k + 12), JourneyBlocks.frozenBrick.getDefaultState());
		world.setBlockState(new BlockPos(i + 9, j + 0, k + 13), JourneyBlocks.frozenBrick.getDefaultState());
		world.setBlockState(new BlockPos(i + 9, j + 0, k + 14), JourneyBlocks.frozenBrick.getDefaultState());
		world.setBlockState(new BlockPos(i + 9, j + 0, k + 15), JourneyBlocks.frozenBrick.getDefaultState());
		world.setBlockState(new BlockPos(i + 9, j + 1, k + 12), JourneyBlocks.frozenBrick.getDefaultState());
		world.setBlockState(new BlockPos(i + 9, j + 1, k + 15), JourneyBlocks.frozenBrick.getDefaultState());
		world.setBlockState(new BlockPos(i + 9, j + 2, k + 12), Blocks.ICE.getDefaultState());
		world.setBlockState(new BlockPos(i + 9, j + 2, k + 15), Blocks.ICE.getDefaultState());
		world.setBlockState(new BlockPos(i + 9, j + 3, k + 12), JourneyBlocks.frozenBrick.getDefaultState());
		world.setBlockState(new BlockPos(i + 9, j + 3, k + 13), JourneyBlocks.icicle.getDefaultState());
		world.setBlockState(new BlockPos(i + 9, j + 3, k + 14), JourneyBlocks.icicle.getDefaultState());
		world.setBlockState(new BlockPos(i + 9, j + 3, k + 15), JourneyBlocks.frozenBrick.getDefaultState());
		world.setBlockState(new BlockPos(i + 9, j + 4, k + 12), JourneyBlocks.frozenBrick.getDefaultState());
		world.setBlockState(new BlockPos(i + 9, j + 4, k + 13), JourneyBlocks.frozenBrick.getDefaultState());
		world.setBlockState(new BlockPos(i + 9, j + 4, k + 14), JourneyBlocks.frozenBrick.getDefaultState());
		world.setBlockState(new BlockPos(i + 9, j + 4, k + 15), JourneyBlocks.frozenBrick.getDefaultState());
		world.setBlockState(new BlockPos(i + 10, j + 0, k + 12), JourneyBlocks.frozenBrick.getDefaultState());
		world.setBlockState(new BlockPos(i + 10, j + 0, k + 13), JourneyBlocks.frozenBrick.getDefaultState());
		world.setBlockState(new BlockPos(i + 10, j + 0, k + 14), JourneyBlocks.frozenBrick.getDefaultState());
		world.setBlockState(new BlockPos(i + 10, j + 0, k + 15), JourneyBlocks.frozenBrick.getDefaultState());
		world.setBlockState(new BlockPos(i + 10, j + 1, k + 12), JourneyBlocks.frozenBrick.getDefaultState());
		world.setBlockState(new BlockPos(i + 10, j + 1, k + 15), JourneyBlocks.frozenBrick.getDefaultState());
		world.setBlockState(new BlockPos(i + 10, j + 2, k + 12), Blocks.ICE.getDefaultState());
		world.setBlockState(new BlockPos(i + 10, j + 2, k + 15), Blocks.ICE.getDefaultState());
		world.setBlockState(new BlockPos(i + 10, j + 3, k + 12), JourneyBlocks.frozenBrick.getDefaultState());
		world.setBlockState(new BlockPos(i + 10, j + 3, k + 15), JourneyBlocks.frozenBrick.getDefaultState());
		world.setBlockState(new BlockPos(i + 10, j + 4, k + 12), JourneyBlocks.frozenBrick.getDefaultState());
		world.setBlockState(new BlockPos(i + 10, j + 4, k + 13), JourneyBlocks.frozenBrick.getDefaultState());
		world.setBlockState(new BlockPos(i + 10, j + 4, k + 14), JourneyBlocks.frozenBrick.getDefaultState());
		world.setBlockState(new BlockPos(i + 10, j + 4, k + 15), JourneyBlocks.frozenBrick.getDefaultState());
		world.setBlockState(new BlockPos(i + 11, j + 0, k + 0), JourneyBlocks.frozenBrick.getDefaultState());
		world.setBlockState(new BlockPos(i + 11, j + 0, k + 1), JourneyBlocks.frozenBrick.getDefaultState());
		world.setBlockState(new BlockPos(i + 11, j + 0, k + 2), JourneyBlocks.frozenBrick.getDefaultState());
		world.setBlockState(new BlockPos(i + 11, j + 0, k + 3), JourneyBlocks.frozenBrick.getDefaultState());
		world.setBlockState(new BlockPos(i + 11, j + 0, k + 4), JourneyBlocks.frozenBrick.getDefaultState());
		world.setBlockState(new BlockPos(i + 11, j + 0, k + 5), JourneyBlocks.frozenBrick.getDefaultState());
		world.setBlockState(new BlockPos(i + 11, j + 0, k + 11), JourneyBlocks.frozenBrick.getDefaultState());
		world.setBlockState(new BlockPos(i + 11, j + 0, k + 12), JourneyBlocks.frozenBrick.getDefaultState());
		world.setBlockState(new BlockPos(i + 11, j + 0, k + 13), JourneyBlocks.frozenBrick.getDefaultState());
		world.setBlockState(new BlockPos(i + 11, j + 0, k + 14), JourneyBlocks.frozenBrick.getDefaultState());
		world.setBlockState(new BlockPos(i + 11, j + 0, k + 15), JourneyBlocks.frozenBrick.getDefaultState());
		world.setBlockState(new BlockPos(i + 11, j + 0, k + 16), JourneyBlocks.frozenBrick.getDefaultState());
		world.setBlockState(new BlockPos(i + 11, j + 1, k + 0), JourneyBlocks.frozenBrick.getDefaultState());
		world.setBlockState(new BlockPos(i + 11, j + 1, k + 1), JourneyBlocks.frozenBrick.getDefaultState());
		world.setBlockState(new BlockPos(i + 11, j + 1, k + 2), JourneyBlocks.frozenBrick.getDefaultState());
		world.setBlockState(new BlockPos(i + 11, j + 1, k + 3), JourneyBlocks.frozenBrick.getDefaultState());
		world.setBlockState(new BlockPos(i + 11, j + 1, k + 4), JourneyBlocks.frozenBrick.getDefaultState());
		world.setBlockState(new BlockPos(i + 11, j + 1, k + 5), JourneyBlocks.frozenBrick.getDefaultState());
		world.setBlockState(new BlockPos(i + 11, j + 1, k + 11), JourneyBlocks.frozenBrick.getDefaultState());
		world.setBlockState(new BlockPos(i + 11, j + 1, k + 16), JourneyBlocks.frozenBrick.getDefaultState());
		world.setBlockState(new BlockPos(i + 11, j + 2, k + 0), JourneyBlocks.frozenBrick.getDefaultState());
		world.setBlockState(new BlockPos(i + 11, j + 2, k + 1), JourneyBlocks.frozenBrick.getDefaultState());
		world.setBlockState(new BlockPos(i + 11, j + 2, k + 2), JourneyBlocks.frozenBrick.getDefaultState());
		world.setBlockState(new BlockPos(i + 11, j + 2, k + 3), JourneyBlocks.frozenBrick.getDefaultState());
		world.setBlockState(new BlockPos(i + 11, j + 2, k + 4), JourneyBlocks.frozenBrick.getDefaultState());
		world.setBlockState(new BlockPos(i + 11, j + 2, k + 5), JourneyBlocks.frozenBrick.getDefaultState());
		world.setBlockState(new BlockPos(i + 11, j + 2, k + 11), Blocks.ICE.getDefaultState());
		world.setBlockState(new BlockPos(i + 11, j + 2, k + 16), Blocks.ICE.getDefaultState());
		world.setBlockState(new BlockPos(i + 11, j + 3, k + 0), JourneyBlocks.frozenBrick.getDefaultState());
		world.setBlockState(new BlockPos(i + 11, j + 3, k + 1), JourneyBlocks.frozenBrick.getDefaultState());
		world.setBlockState(new BlockPos(i + 11, j + 3, k + 2), JourneyBlocks.frozenBrick.getDefaultState());
		world.setBlockState(new BlockPos(i + 11, j + 3, k + 3), JourneyBlocks.frozenBrick.getDefaultState());
		world.setBlockState(new BlockPos(i + 11, j + 3, k + 4), JourneyBlocks.frozenBrick.getDefaultState());
		world.setBlockState(new BlockPos(i + 11, j + 3, k + 5), JourneyBlocks.frozenBrick.getDefaultState());
		world.setBlockState(new BlockPos(i + 11, j + 3, k + 11), JourneyBlocks.frozenBrick.getDefaultState());
		world.setBlockState(new BlockPos(i + 11, j + 3, k + 16), JourneyBlocks.frozenBrick.getDefaultState());
		world.setBlockState(new BlockPos(i + 11, j + 4, k + 0), JourneyBlocks.frozenBrick.getDefaultState());
		world.setBlockState(new BlockPos(i + 11, j + 4, k + 1), JourneyBlocks.frozenBrick.getDefaultState());
		world.setBlockState(new BlockPos(i + 11, j + 4, k + 2), JourneyBlocks.frozenBrick.getDefaultState());
		world.setBlockState(new BlockPos(i + 11, j + 4, k + 3), JourneyBlocks.frozenBrick.getDefaultState());
		world.setBlockState(new BlockPos(i + 11, j + 4, k + 4), JourneyBlocks.frozenBrick.getDefaultState());
		world.setBlockState(new BlockPos(i + 11, j + 4, k + 5), JourneyBlocks.frozenBrick.getDefaultState());
		world.setBlockState(new BlockPos(i + 11, j + 4, k + 11), JourneyBlocks.frozenBrick.getDefaultState());
		world.setBlockState(new BlockPos(i + 11, j + 4, k + 14), JourneyBlocks.icicle.getDefaultState());
		world.setBlockState(new BlockPos(i + 11, j + 4, k + 16), JourneyBlocks.frozenBrick.getDefaultState());
		world.setBlockState(new BlockPos(i + 11, j + 5, k + 0), JourneyBlocks.frozenBrick.getDefaultState());
		world.setBlockState(new BlockPos(i + 11, j + 5, k + 1), JourneyBlocks.frozenBrick.getDefaultState());
		world.setBlockState(new BlockPos(i + 11, j + 5, k + 2), JourneyBlocks.frozenBrick.getDefaultState());
		world.setBlockState(new BlockPos(i + 11, j + 5, k + 3), JourneyBlocks.frozenBrick.getDefaultState());
		world.setBlockState(new BlockPos(i + 11, j + 5, k + 4), JourneyBlocks.frozenBrick.getDefaultState());
		world.setBlockState(new BlockPos(i + 11, j + 5, k + 5), JourneyBlocks.frozenBrick.getDefaultState());
		world.setBlockState(new BlockPos(i + 11, j + 5, k + 12), JourneyBlocks.frozenBrick.getDefaultState());
		world.setBlockState(new BlockPos(i + 11, j + 5, k + 13), JourneyBlocks.frozenBrick.getDefaultState());
		world.setBlockState(new BlockPos(i + 11, j + 5, k + 14), JourneyBlocks.frozenBrick.getDefaultState());
		world.setBlockState(new BlockPos(i + 11, j + 5, k + 15), JourneyBlocks.frozenBrick.getDefaultState());
		world.setBlockState(new BlockPos(i + 12, j + 0, k + 0), JourneyBlocks.frozenBrick.getDefaultState());
		world.setBlockState(new BlockPos(i + 12, j + 0, k + 1), JourneyBlocks.frozenBrick.getDefaultState());
		world.setBlockState(new BlockPos(i + 12, j + 0, k + 2), JourneyBlocks.frozenBrick.getDefaultState());
		world.setBlockState(new BlockPos(i + 12, j + 0, k + 3), JourneyBlocks.frozenBrick.getDefaultState());
		world.setBlockState(new BlockPos(i + 12, j + 0, k + 4), JourneyBlocks.frozenBrick.getDefaultState());
		world.setBlockState(new BlockPos(i + 12, j + 0, k + 5), JourneyBlocks.frozenBrick.getDefaultState());
		world.setBlockState(new BlockPos(i + 12, j + 0, k + 6), JourneyBlocks.frozenBrick.getDefaultState());
		world.setBlockState(new BlockPos(i + 12, j + 0, k + 7), JourneyBlocks.frozenBrick.getDefaultState());
		world.setBlockState(new BlockPos(i + 12, j + 0, k + 8), JourneyBlocks.frozenBrick.getDefaultState());
		world.setBlockState(new BlockPos(i + 12, j + 0, k + 9), JourneyBlocks.frozenBrick.getDefaultState());
		world.setBlockState(new BlockPos(i + 12, j + 0, k + 10), JourneyBlocks.frozenBrick.getDefaultState());
		world.setBlockState(new BlockPos(i + 12, j + 0, k + 11), JourneyBlocks.frozenBrick.getDefaultState());
		world.setBlockState(new BlockPos(i + 12, j + 0, k + 12), JourneyBlocks.frozenBrick.getDefaultState());
		world.setBlockState(new BlockPos(i + 12, j + 0, k + 13), JourneyBlocks.frozenBrick.getDefaultState());
		world.setBlockState(new BlockPos(i + 12, j + 0, k + 14), JourneyBlocks.frozenBrick.getDefaultState());
		world.setBlockState(new BlockPos(i + 12, j + 0, k + 15), JourneyBlocks.frozenBrick.getDefaultState());
		world.setBlockState(new BlockPos(i + 12, j + 0, k + 16), JourneyBlocks.frozenBrick.getDefaultState());
		world.setBlockState(new BlockPos(i + 12, j + 0, k + 17), JourneyBlocks.frozenBrick.getDefaultState());
		world.setBlockState(new BlockPos(i + 12, j + 1, k + 0), JourneyBlocks.frozenBrick.getDefaultState());
		world.setBlockState(new BlockPos(i + 12, j + 1, k + 6), JourneyBlocks.frozenBrick.getDefaultState());
		world.setBlockState(new BlockPos(i + 12, j + 1, k + 7), JourneyBlocks.frozenBrick.getDefaultState());
		world.setBlockState(new BlockPos(i + 12, j + 1, k + 8), JourneyBlocks.frozenBrick.getDefaultState());
		world.setBlockState(new BlockPos(i + 12, j + 1, k + 9), JourneyBlocks.frozenBrick.getDefaultState());
		world.setBlockState(new BlockPos(i + 12, j + 1, k + 10), JourneyBlocks.frozenBrick.getDefaultState());
		world.setBlockState(new BlockPos(i + 12, j + 1, k + 17), JourneyBlocks.frozenBrick.getDefaultState());
		world.setBlockState(new BlockPos(i + 12, j + 2, k + 0), JourneyBlocks.frozenBrick.getDefaultState());
		world.setBlockState(new BlockPos(i + 12, j + 2, k + 6), Blocks.ICE.getDefaultState());
		world.setBlockState(new BlockPos(i + 12, j + 2, k + 7), Blocks.ICE.getDefaultState());
		world.setBlockState(new BlockPos(i + 12, j + 2, k + 8), Blocks.ICE.getDefaultState());
		world.setBlockState(new BlockPos(i + 12, j + 2, k + 9), Blocks.ICE.getDefaultState());
		world.setBlockState(new BlockPos(i + 12, j + 2, k + 10), Blocks.ICE.getDefaultState());
		world.setBlockState(new BlockPos(i + 12, j + 2, k + 17), JourneyBlocks.frozenBrick.getDefaultState());
		world.setBlockState(new BlockPos(i + 12, j + 3, k + 0), JourneyBlocks.frozenBrick.getDefaultState());
		world.setBlockState(new BlockPos(i + 12, j + 3, k + 6), JourneyBlocks.frozenBrick.getDefaultState());
		world.setBlockState(new BlockPos(i + 12, j + 3, k + 7), JourneyBlocks.frozenBrick.getDefaultState());
		world.setBlockState(new BlockPos(i + 12, j + 3, k + 8), JourneyBlocks.frozenBrick.getDefaultState());
		world.setBlockState(new BlockPos(i + 12, j + 3, k + 9), JourneyBlocks.frozenBrick.getDefaultState());
		world.setBlockState(new BlockPos(i + 12, j + 3, k + 10), JourneyBlocks.frozenBrick.getDefaultState());
		world.setBlockState(new BlockPos(i + 12, j + 3, k + 17), JourneyBlocks.frozenBrick.getDefaultState());
		world.setBlockState(new BlockPos(i + 12, j + 4, k + 0), JourneyBlocks.frozenBrick.getDefaultState());
		world.setBlockState(new BlockPos(i + 12, j + 4, k + 3), JourneyBlocks.icicle.getDefaultState());
		world.setBlockState(new BlockPos(i + 12, j + 4, k + 4), JourneyBlocks.icicle.getDefaultState());
		world.setBlockState(new BlockPos(i + 12, j + 4, k + 6), JourneyBlocks.frozenBrick.getDefaultState());
		world.setBlockState(new BlockPos(i + 12, j + 4, k + 7), JourneyBlocks.frozenBrick.getDefaultState());
		world.setBlockState(new BlockPos(i + 12, j + 4, k + 8), JourneyBlocks.frozenBrick.getDefaultState());
		world.setBlockState(new BlockPos(i + 12, j + 4, k + 9), JourneyBlocks.frozenBrick.getDefaultState());
		world.setBlockState(new BlockPos(i + 12, j + 4, k + 10), JourneyBlocks.frozenBrick.getDefaultState());
		world.setBlockState(new BlockPos(i + 12, j + 4, k + 11), JourneyBlocks.icicle.getDefaultState());
		world.setBlockState(new BlockPos(i + 12, j + 4, k + 16), JourneyBlocks.icicle.getDefaultState());
		world.setBlockState(new BlockPos(i + 12, j + 4, k + 17), JourneyBlocks.frozenBrick.getDefaultState());
		world.setBlockState(new BlockPos(i + 12, j + 5, k + 0), JourneyBlocks.frozenBrick.getDefaultState());
		world.setBlockState(new BlockPos(i + 12, j + 5, k + 1), JourneyBlocks.frozenBrick.getDefaultState());
		world.setBlockState(new BlockPos(i + 12, j + 5, k + 2), JourneyBlocks.frozenBrick.getDefaultState());
		world.setBlockState(new BlockPos(i + 12, j + 5, k + 3), JourneyBlocks.frozenBrick.getDefaultState());
		world.setBlockState(new BlockPos(i + 12, j + 5, k + 4), JourneyBlocks.frozenBrick.getDefaultState());
		world.setBlockState(new BlockPos(i + 12, j + 5, k + 5), JourneyBlocks.frozenBrick.getDefaultState());
		world.setBlockState(new BlockPos(i + 12, j + 5, k + 11), JourneyBlocks.frozenBrick.getDefaultState());
		world.setBlockState(new BlockPos(i + 12, j + 5, k + 13), JourneyBlocks.icicle.getDefaultState());
		world.setBlockState(new BlockPos(i + 12, j + 5, k + 16), JourneyBlocks.frozenBrick.getDefaultState());
		world.setBlockState(new BlockPos(i + 12, j + 6, k + 12), JourneyBlocks.frozenBrick.getDefaultState());
		world.setBlockState(new BlockPos(i + 12, j + 6, k + 13), JourneyBlocks.frozenBrick.getDefaultState());
		world.setBlockState(new BlockPos(i + 12, j + 6, k + 14), JourneyBlocks.frozenBrick.getDefaultState());
		world.setBlockState(new BlockPos(i + 12, j + 6, k + 15), JourneyBlocks.frozenBrick.getDefaultState());
		world.setBlockState(new BlockPos(i + 13, j + 0, k + 0), JourneyBlocks.frozenBrick.getDefaultState());
		world.setBlockState(new BlockPos(i + 13, j + 0, k + 1), JourneyBlocks.frozenBrick.getDefaultState());
		world.setBlockState(new BlockPos(i + 13, j + 0, k + 2), JourneyBlocks.frozenBrick.getDefaultState());
		world.setBlockState(new BlockPos(i + 13, j + 0, k + 3), JourneyBlocks.frozenBrick.getDefaultState());
		world.setBlockState(new BlockPos(i + 13, j + 0, k + 4), JourneyBlocks.frozenBrick.getDefaultState());
		world.setBlockState(new BlockPos(i + 13, j + 0, k + 5), JourneyBlocks.frozenBrick.getDefaultState());
		world.setBlockState(new BlockPos(i + 13, j + 0, k + 6), JourneyBlocks.frozenBrick.getDefaultState());
		world.setBlockState(new BlockPos(i + 13, j + 0, k + 7), JourneyBlocks.frozenBrick.getDefaultState());
		world.setBlockState(new BlockPos(i + 13, j + 0, k + 8), JourneyBlocks.frozenBrick.getDefaultState());
		world.setBlockState(new BlockPos(i + 13, j + 0, k + 9), JourneyBlocks.frozenBrick.getDefaultState());
		world.setBlockState(new BlockPos(i + 13, j + 0, k + 10), JourneyBlocks.frozenBrick.getDefaultState());
		world.setBlockState(new BlockPos(i + 13, j + 0, k + 11), JourneyBlocks.frozenBrick.getDefaultState());
		world.setBlockState(new BlockPos(i + 13, j + 0, k + 12), JourneyBlocks.frozenBrick.getDefaultState());
		world.setBlockState(new BlockPos(i + 13, j + 0, k + 13), JourneyBlocks.frozenBrick.getDefaultState());
		world.setBlockState(new BlockPos(i + 13, j + 0, k + 14), JourneyBlocks.frozenBrick.getDefaultState());
		world.setBlockState(new BlockPos(i + 13, j + 0, k + 15), JourneyBlocks.frozenBrick.getDefaultState());
		world.setBlockState(new BlockPos(i + 13, j + 0, k + 16), JourneyBlocks.frozenBrick.getDefaultState());
		world.setBlockState(new BlockPos(i + 13, j + 0, k + 17), JourneyBlocks.frozenBrick.getDefaultState());
		world.setBlockState(new BlockPos(i + 13, j + 1, k + 0), JourneyBlocks.frozenBrick.getDefaultState());
		world.setBlockState(new BlockPos(i + 13, j + 1, k + 1), JourneyBlocks.frostbiterSpawner.getDefaultState());
		world.setBlockState(new BlockPos(i + 13, j + 2, k + 0), JourneyBlocks.frozenBrick.getDefaultState());
		world.setBlockState(new BlockPos(i + 13, j + 3, k + 0), JourneyBlocks.frozenBrick.getDefaultState());
		world.setBlockState(new BlockPos(i + 13, j + 3, k + 6), JourneyBlocks.icicle.getDefaultState());
		world.setBlockState(new BlockPos(i + 13, j + 3, k + 9), JourneyBlocks.icicle.getDefaultState());
		world.setBlockState(new BlockPos(i + 13, j + 3, k + 17), JourneyBlocks.frozenBrick.getDefaultState());
		world.setBlockState(new BlockPos(i + 13, j + 4, k + 0), JourneyBlocks.frozenBrick.getDefaultState());
		world.setBlockState(new BlockPos(i + 13, j + 4, k + 1), JourneyBlocks.icicle.getDefaultState());
		world.setBlockState(new BlockPos(i + 13, j + 4, k + 6), JourneyBlocks.frozenBrick.getDefaultState());
		world.setBlockState(new BlockPos(i + 13, j + 4, k + 7), JourneyBlocks.frozenBrick.getDefaultState());
		world.setBlockState(new BlockPos(i + 13, j + 4, k + 8), JourneyBlocks.frozenBrick.getDefaultState());
		world.setBlockState(new BlockPos(i + 13, j + 4, k + 9), JourneyBlocks.frozenBrick.getDefaultState());
		world.setBlockState(new BlockPos(i + 13, j + 4, k + 10), JourneyBlocks.frozenBrick.getDefaultState());
		world.setBlockState(new BlockPos(i + 13, j + 4, k + 17), JourneyBlocks.frozenBrick.getDefaultState());
		world.setBlockState(new BlockPos(i + 13, j + 5, k + 0), JourneyBlocks.frozenBrick.getDefaultState());
		world.setBlockState(new BlockPos(i + 13, j + 5, k + 1), JourneyBlocks.frozenBrick.getDefaultState());
		world.setBlockState(new BlockPos(i + 13, j + 5, k + 2), Blocks.ICE.getDefaultState());
		world.setBlockState(new BlockPos(i + 13, j + 5, k + 3), Blocks.ICE.getDefaultState());
		world.setBlockState(new BlockPos(i + 13, j + 5, k + 4), JourneyBlocks.frozenBrick.getDefaultState());
		world.setBlockState(new BlockPos(i + 13, j + 5, k + 5), JourneyBlocks.frozenBrick.getDefaultState());
		world.setBlockState(new BlockPos(i + 13, j + 5, k + 11), JourneyBlocks.frozenBrick.getDefaultState());
		world.setBlockState(new BlockPos(i + 13, j + 5, k + 13), JourneyBlocks.icicle.getDefaultState());
		world.setBlockState(new BlockPos(i + 13, j + 5, k + 15), JourneyBlocks.icicle.getDefaultState());
		world.setBlockState(new BlockPos(i + 13, j + 5, k + 16), JourneyBlocks.frozenBrick.getDefaultState());
		world.setBlockState(new BlockPos(i + 13, j + 6, k + 12), JourneyBlocks.frozenBrick.getDefaultState());
		world.setBlockState(new BlockPos(i + 13, j + 6, k + 13), JourneyBlocks.frozenLamp.getDefaultState());
		world.setBlockState(new BlockPos(i + 13, j + 6, k + 14), JourneyBlocks.frozenLamp.getDefaultState());
		world.setBlockState(new BlockPos(i + 13, j + 6, k + 15), JourneyBlocks.frozenBrick.getDefaultState());
		world.setBlockState(new BlockPos(i + 13, j + 7, k + 13), JourneyBlocks.frozenBrick.getDefaultState());
		world.setBlockState(new BlockPos(i + 13, j + 7, k + 14), JourneyBlocks.frozenBrick.getDefaultState());
		world.setBlockState(new BlockPos(i + 14, j + 0, k + 0), JourneyBlocks.frozenBrick.getDefaultState());
		world.setBlockState(new BlockPos(i + 14, j + 0, k + 1), JourneyBlocks.frozenBrick.getDefaultState());
		world.setBlockState(new BlockPos(i + 14, j + 0, k + 2), JourneyBlocks.frozenBrick.getDefaultState());
		world.setBlockState(new BlockPos(i + 14, j + 0, k + 3), JourneyBlocks.frozenBrick.getDefaultState());
		world.setBlockState(new BlockPos(i + 14, j + 0, k + 4), JourneyBlocks.frozenBrick.getDefaultState());
		world.setBlockState(new BlockPos(i + 14, j + 0, k + 5), JourneyBlocks.frozenBrick.getDefaultState());
		world.setBlockState(new BlockPos(i + 14, j + 0, k + 6), JourneyBlocks.frozenBrick.getDefaultState());
		world.setBlockState(new BlockPos(i + 14, j + 0, k + 7), JourneyBlocks.frozenBrick.getDefaultState());
		world.setBlockState(new BlockPos(i + 14, j + 0, k + 8), JourneyBlocks.frozenBrick.getDefaultState());
		world.setBlockState(new BlockPos(i + 14, j + 0, k + 9), JourneyBlocks.frozenBrick.getDefaultState());
		world.setBlockState(new BlockPos(i + 14, j + 0, k + 10), JourneyBlocks.frozenBrick.getDefaultState());
		world.setBlockState(new BlockPos(i + 14, j + 0, k + 11), JourneyBlocks.frozenBrick.getDefaultState());
		world.setBlockState(new BlockPos(i + 14, j + 0, k + 12), JourneyBlocks.frozenBrick.getDefaultState());
		world.setBlockState(new BlockPos(i + 14, j + 0, k + 13), JourneyBlocks.frozenBrick.getDefaultState());
		world.setBlockState(new BlockPos(i + 14, j + 0, k + 14), JourneyBlocks.frozenBrick.getDefaultState());
		world.setBlockState(new BlockPos(i + 14, j + 0, k + 15), JourneyBlocks.frozenBrick.getDefaultState());
		world.setBlockState(new BlockPos(i + 14, j + 0, k + 16), JourneyBlocks.frozenBrick.getDefaultState());
		world.setBlockState(new BlockPos(i + 14, j + 0, k + 17), JourneyBlocks.frozenBrick.getDefaultState());
		world.setBlockState(new BlockPos(i + 14, j + 1, k + 0), JourneyBlocks.frozenBrick.getDefaultState());
		world.setBlockState(new BlockPos(i + 14, j + 1, k + 1), JourneyBlocks.frostbiterSpawner.getDefaultState());
		world.setBlockState(new BlockPos(i + 14, j + 2, k + 0), JourneyBlocks.frozenBrick.getDefaultState());
		world.setBlockState(new BlockPos(i + 14, j + 3, k + 0), JourneyBlocks.frozenBrick.getDefaultState());
		world.setBlockState(new BlockPos(i + 14, j + 3, k + 8), JourneyBlocks.icicle.getDefaultState());
		world.setBlockState(new BlockPos(i + 14, j + 3, k + 9), JourneyBlocks.icicle.getDefaultState());
		world.setBlockState(new BlockPos(i + 14, j + 3, k + 17), JourneyBlocks.frozenBrick.getDefaultState());
		world.setBlockState(new BlockPos(i + 14, j + 4, k + 0), JourneyBlocks.frozenBrick.getDefaultState());
		world.setBlockState(new BlockPos(i + 14, j + 4, k + 4), JourneyBlocks.icicle.getDefaultState());
		world.setBlockState(new BlockPos(i + 14, j + 4, k + 6), JourneyBlocks.frozenBrick.getDefaultState());
		world.setBlockState(new BlockPos(i + 14, j + 4, k + 7), JourneyBlocks.frozenBrick.getDefaultState());
		world.setBlockState(new BlockPos(i + 14, j + 4, k + 8), JourneyBlocks.frozenBrick.getDefaultState());
		world.setBlockState(new BlockPos(i + 14, j + 4, k + 9), JourneyBlocks.frozenBrick.getDefaultState());
		world.setBlockState(new BlockPos(i + 14, j + 4, k + 10), JourneyBlocks.frozenBrick.getDefaultState());
		world.setBlockState(new BlockPos(i + 14, j + 4, k + 17), JourneyBlocks.frozenBrick.getDefaultState());
		world.setBlockState(new BlockPos(i + 14, j + 5, k + 0), JourneyBlocks.frozenBrick.getDefaultState());
		world.setBlockState(new BlockPos(i + 14, j + 5, k + 1), JourneyBlocks.frozenBrick.getDefaultState());
		world.setBlockState(new BlockPos(i + 14, j + 5, k + 2), Blocks.ICE.getDefaultState());
		world.setBlockState(new BlockPos(i + 14, j + 5, k + 3), Blocks.ICE.getDefaultState());
		world.setBlockState(new BlockPos(i + 14, j + 5, k + 4), JourneyBlocks.frozenBrick.getDefaultState());
		world.setBlockState(new BlockPos(i + 14, j + 5, k + 5), JourneyBlocks.frozenBrick.getDefaultState());
		world.setBlockState(new BlockPos(i + 14, j + 5, k + 11), JourneyBlocks.frozenBrick.getDefaultState());
		world.setBlockState(new BlockPos(i + 14, j + 5, k + 15), JourneyBlocks.icicle.getDefaultState());
		world.setBlockState(new BlockPos(i + 14, j + 5, k + 16), JourneyBlocks.frozenBrick.getDefaultState());
		world.setBlockState(new BlockPos(i + 14, j + 6, k + 12), JourneyBlocks.frozenBrick.getDefaultState());
		world.setBlockState(new BlockPos(i + 14, j + 6, k + 13), JourneyBlocks.frozenLamp.getDefaultState());
		world.setBlockState(new BlockPos(i + 14, j + 6, k + 14), JourneyBlocks.frozenLamp.getDefaultState());
		world.setBlockState(new BlockPos(i + 14, j + 6, k + 15), JourneyBlocks.frozenBrick.getDefaultState());
		world.setBlockState(new BlockPos(i + 14, j + 7, k + 13), JourneyBlocks.frozenBrick.getDefaultState());
		world.setBlockState(new BlockPos(i + 14, j + 7, k + 14), JourneyBlocks.frozenBrick.getDefaultState());
		world.setBlockState(new BlockPos(i + 15, j + 0, k + 0), JourneyBlocks.frozenBrick.getDefaultState());
		world.setBlockState(new BlockPos(i + 15, j + 0, k + 1), JourneyBlocks.frozenBrick.getDefaultState());
		world.setBlockState(new BlockPos(i + 15, j + 0, k + 2), JourneyBlocks.frozenBrick.getDefaultState());
		world.setBlockState(new BlockPos(i + 15, j + 0, k + 3), JourneyBlocks.frozenBrick.getDefaultState());
		world.setBlockState(new BlockPos(i + 15, j + 0, k + 4), JourneyBlocks.frozenBrick.getDefaultState());
		world.setBlockState(new BlockPos(i + 15, j + 0, k + 5), JourneyBlocks.frozenBrick.getDefaultState());
		world.setBlockState(new BlockPos(i + 15, j + 0, k + 6), JourneyBlocks.frozenBrick.getDefaultState());
		world.setBlockState(new BlockPos(i + 15, j + 0, k + 7), JourneyBlocks.frozenBrick.getDefaultState());
		world.setBlockState(new BlockPos(i + 15, j + 0, k + 8), JourneyBlocks.frozenBrick.getDefaultState());
		world.setBlockState(new BlockPos(i + 15, j + 0, k + 9), JourneyBlocks.frozenBrick.getDefaultState());
		world.setBlockState(new BlockPos(i + 15, j + 0, k + 10), JourneyBlocks.frozenBrick.getDefaultState());
		world.setBlockState(new BlockPos(i + 15, j + 0, k + 11), JourneyBlocks.frozenBrick.getDefaultState());
		world.setBlockState(new BlockPos(i + 15, j + 0, k + 12), JourneyBlocks.frozenBrick.getDefaultState());
		world.setBlockState(new BlockPos(i + 15, j + 0, k + 13), JourneyBlocks.frozenBrick.getDefaultState());
		world.setBlockState(new BlockPos(i + 15, j + 0, k + 14), JourneyBlocks.frozenBrick.getDefaultState());
		world.setBlockState(new BlockPos(i + 15, j + 0, k + 15), JourneyBlocks.frozenBrick.getDefaultState());
		world.setBlockState(new BlockPos(i + 15, j + 0, k + 16), JourneyBlocks.frozenBrick.getDefaultState());
		world.setBlockState(new BlockPos(i + 15, j + 0, k + 17), JourneyBlocks.frozenBrick.getDefaultState());
		world.setBlockState(new BlockPos(i + 15, j + 1, k + 0), JourneyBlocks.frozenBrick.getDefaultState());
		world.setBlockState(new BlockPos(i + 15, j + 1, k + 6), JourneyBlocks.frozenBrick.getDefaultState());
		world.setBlockState(new BlockPos(i + 15, j + 1, k + 7), JourneyBlocks.frozenBrick.getDefaultState());
		world.setBlockState(new BlockPos(i + 15, j + 1, k + 8), JourneyBlocks.frozenBrick.getDefaultState());
		world.setBlockState(new BlockPos(i + 15, j + 1, k + 9), JourneyBlocks.frozenBrick.getDefaultState());
		world.setBlockState(new BlockPos(i + 15, j + 1, k + 10), JourneyBlocks.frozenBrick.getDefaultState());
		world.setBlockState(new BlockPos(i + 15, j + 1, k + 17), JourneyBlocks.frozenBrick.getDefaultState());
		world.setBlockState(new BlockPos(i + 15, j + 2, k + 0), JourneyBlocks.frozenBrick.getDefaultState());
		world.setBlockState(new BlockPos(i + 15, j + 2, k + 6), Blocks.ICE.getDefaultState());
		world.setBlockState(new BlockPos(i + 15, j + 2, k + 7), Blocks.ICE.getDefaultState());
		world.setBlockState(new BlockPos(i + 15, j + 2, k + 8), Blocks.ICE.getDefaultState());
		world.setBlockState(new BlockPos(i + 15, j + 2, k + 9), Blocks.ICE.getDefaultState());
		world.setBlockState(new BlockPos(i + 15, j + 2, k + 10), Blocks.ICE.getDefaultState());
		world.setBlockState(new BlockPos(i + 15, j + 2, k + 17), JourneyBlocks.frozenBrick.getDefaultState());
		world.setBlockState(new BlockPos(i + 15, j + 3, k + 0), JourneyBlocks.frozenBrick.getDefaultState());
		world.setBlockState(new BlockPos(i + 15, j + 3, k + 6), JourneyBlocks.frozenBrick.getDefaultState());
		world.setBlockState(new BlockPos(i + 15, j + 3, k + 7), JourneyBlocks.frozenBrick.getDefaultState());
		world.setBlockState(new BlockPos(i + 15, j + 3, k + 8), JourneyBlocks.frozenBrick.getDefaultState());
		world.setBlockState(new BlockPos(i + 15, j + 3, k + 9), JourneyBlocks.frozenBrick.getDefaultState());
		world.setBlockState(new BlockPos(i + 15, j + 3, k + 10), JourneyBlocks.frozenBrick.getDefaultState());
		world.setBlockState(new BlockPos(i + 15, j + 3, k + 17), JourneyBlocks.frozenBrick.getDefaultState());
		world.setBlockState(new BlockPos(i + 15, j + 4, k + 0), JourneyBlocks.frozenBrick.getDefaultState());
		world.setBlockState(new BlockPos(i + 15, j + 4, k + 2), JourneyBlocks.icicle.getDefaultState());
		world.setBlockState(new BlockPos(i + 15, j + 4, k + 3), JourneyBlocks.icicle.getDefaultState());
		world.setBlockState(new BlockPos(i + 15, j + 4, k + 6), JourneyBlocks.frozenBrick.getDefaultState());
		world.setBlockState(new BlockPos(i + 15, j + 4, k + 7), JourneyBlocks.frozenBrick.getDefaultState());
		world.setBlockState(new BlockPos(i + 15, j + 4, k + 8), JourneyBlocks.frozenBrick.getDefaultState());
		world.setBlockState(new BlockPos(i + 15, j + 4, k + 9), JourneyBlocks.frozenBrick.getDefaultState());
		world.setBlockState(new BlockPos(i + 15, j + 4, k + 10), JourneyBlocks.frozenBrick.getDefaultState());
		world.setBlockState(new BlockPos(i + 15, j + 4, k + 17), JourneyBlocks.frozenBrick.getDefaultState());
		world.setBlockState(new BlockPos(i + 15, j + 5, k + 0), JourneyBlocks.frozenBrick.getDefaultState());
		world.setBlockState(new BlockPos(i + 15, j + 5, k + 1), JourneyBlocks.frozenBrick.getDefaultState());
		world.setBlockState(new BlockPos(i + 15, j + 5, k + 2), JourneyBlocks.frozenBrick.getDefaultState());
		world.setBlockState(new BlockPos(i + 15, j + 5, k + 3), JourneyBlocks.frozenBrick.getDefaultState());
		world.setBlockState(new BlockPos(i + 15, j + 5, k + 4), JourneyBlocks.frozenBrick.getDefaultState());
		world.setBlockState(new BlockPos(i + 15, j + 5, k + 5), JourneyBlocks.frozenBrick.getDefaultState());
		world.setBlockState(new BlockPos(i + 15, j + 5, k + 11), JourneyBlocks.frozenBrick.getDefaultState());
		world.setBlockState(new BlockPos(i + 15, j + 5, k + 12), JourneyBlocks.icicle.getDefaultState());
		world.setBlockState(new BlockPos(i + 15, j + 5, k + 13), JourneyBlocks.icicle.getDefaultState());
		world.setBlockState(new BlockPos(i + 15, j + 5, k + 16), JourneyBlocks.frozenBrick.getDefaultState());
		world.setBlockState(new BlockPos(i + 15, j + 6, k + 12), JourneyBlocks.frozenBrick.getDefaultState());
		world.setBlockState(new BlockPos(i + 15, j + 6, k + 13), JourneyBlocks.frozenBrick.getDefaultState());
		world.setBlockState(new BlockPos(i + 15, j + 6, k + 14), JourneyBlocks.frozenBrick.getDefaultState());
		world.setBlockState(new BlockPos(i + 15, j + 6, k + 15), JourneyBlocks.frozenBrick.getDefaultState());
		world.setBlockState(new BlockPos(i + 16, j + 0, k + 0), JourneyBlocks.frozenBrick.getDefaultState());
		world.setBlockState(new BlockPos(i + 16, j + 0, k + 1), JourneyBlocks.frozenBrick.getDefaultState());
		world.setBlockState(new BlockPos(i + 16, j + 0, k + 2), JourneyBlocks.frozenBrick.getDefaultState());
		world.setBlockState(new BlockPos(i + 16, j + 0, k + 3), JourneyBlocks.frozenBrick.getDefaultState());
		world.setBlockState(new BlockPos(i + 16, j + 0, k + 4), JourneyBlocks.frozenBrick.getDefaultState());
		world.setBlockState(new BlockPos(i + 16, j + 0, k + 5), JourneyBlocks.frozenBrick.getDefaultState());
		world.setBlockState(new BlockPos(i + 16, j + 0, k + 11), JourneyBlocks.frozenBrick.getDefaultState());
		world.setBlockState(new BlockPos(i + 16, j + 0, k + 12), JourneyBlocks.frozenBrick.getDefaultState());
		world.setBlockState(new BlockPos(i + 16, j + 0, k + 13), JourneyBlocks.frozenBrick.getDefaultState());
		world.setBlockState(new BlockPos(i + 16, j + 0, k + 14), JourneyBlocks.frozenBrick.getDefaultState());
		world.setBlockState(new BlockPos(i + 16, j + 0, k + 15), JourneyBlocks.frozenBrick.getDefaultState());
		world.setBlockState(new BlockPos(i + 16, j + 0, k + 16), JourneyBlocks.frozenBrick.getDefaultState());
		world.setBlockState(new BlockPos(i + 16, j + 1, k + 0), JourneyBlocks.frozenBrick.getDefaultState());
		world.setBlockState(new BlockPos(i + 16, j + 1, k + 1), JourneyBlocks.frozenBrick.getDefaultState());
		world.setBlockState(new BlockPos(i + 16, j + 1, k + 2), JourneyBlocks.frozenBrick.getDefaultState());
		world.setBlockState(new BlockPos(i + 16, j + 1, k + 3), JourneyBlocks.frozenBrick.getDefaultState());
		world.setBlockState(new BlockPos(i + 16, j + 1, k + 4), JourneyBlocks.frozenBrick.getDefaultState());
		world.setBlockState(new BlockPos(i + 16, j + 1, k + 5), JourneyBlocks.frozenBrick.getDefaultState());
		world.setBlockState(new BlockPos(i + 16, j + 1, k + 11), JourneyBlocks.frozenBrick.getDefaultState());
		world.setBlockState(new BlockPos(i + 16, j + 1, k + 16), JourneyBlocks.frozenBrick.getDefaultState());
		world.setBlockState(new BlockPos(i + 16, j + 2, k + 0), JourneyBlocks.frozenBrick.getDefaultState());
		world.setBlockState(new BlockPos(i + 16, j + 2, k + 1), JourneyBlocks.frozenBrick.getDefaultState());
		world.setBlockState(new BlockPos(i + 16, j + 2, k + 2), JourneyBlocks.frozenBrick.getDefaultState());
		world.setBlockState(new BlockPos(i + 16, j + 2, k + 3), JourneyBlocks.frozenBrick.getDefaultState());
		world.setBlockState(new BlockPos(i + 16, j + 2, k + 4), JourneyBlocks.frozenBrick.getDefaultState());
		world.setBlockState(new BlockPos(i + 16, j + 2, k + 5), JourneyBlocks.frozenBrick.getDefaultState());
		world.setBlockState(new BlockPos(i + 16, j + 2, k + 11), Blocks.ICE.getDefaultState());
		world.setBlockState(new BlockPos(i + 16, j + 2, k + 16), Blocks.ICE.getDefaultState());
		world.setBlockState(new BlockPos(i + 16, j + 3, k + 0), JourneyBlocks.frozenBrick.getDefaultState());
		world.setBlockState(new BlockPos(i + 16, j + 3, k + 1), JourneyBlocks.frozenBrick.getDefaultState());
		world.setBlockState(new BlockPos(i + 16, j + 3, k + 2), JourneyBlocks.frozenBrick.getDefaultState());
		world.setBlockState(new BlockPos(i + 16, j + 3, k + 3), JourneyBlocks.frozenBrick.getDefaultState());
		world.setBlockState(new BlockPos(i + 16, j + 3, k + 4), JourneyBlocks.frozenBrick.getDefaultState());
		world.setBlockState(new BlockPos(i + 16, j + 3, k + 5), JourneyBlocks.frozenBrick.getDefaultState());
		world.setBlockState(new BlockPos(i + 16, j + 3, k + 11), JourneyBlocks.frozenBrick.getDefaultState());
		world.setBlockState(new BlockPos(i + 16, j + 3, k + 16), JourneyBlocks.frozenBrick.getDefaultState());
		world.setBlockState(new BlockPos(i + 16, j + 4, k + 0), JourneyBlocks.frozenBrick.getDefaultState());
		world.setBlockState(new BlockPos(i + 16, j + 4, k + 1), JourneyBlocks.frozenBrick.getDefaultState());
		world.setBlockState(new BlockPos(i + 16, j + 4, k + 2), JourneyBlocks.frozenBrick.getDefaultState());
		world.setBlockState(new BlockPos(i + 16, j + 4, k + 3), JourneyBlocks.frozenBrick.getDefaultState());
		world.setBlockState(new BlockPos(i + 16, j + 4, k + 4), JourneyBlocks.frozenBrick.getDefaultState());
		world.setBlockState(new BlockPos(i + 16, j + 4, k + 5), JourneyBlocks.frozenBrick.getDefaultState());
		world.setBlockState(new BlockPos(i + 16, j + 4, k + 11), JourneyBlocks.frozenBrick.getDefaultState());
		world.setBlockState(new BlockPos(i + 16, j + 4, k + 14), JourneyBlocks.icicle.getDefaultState());
		world.setBlockState(new BlockPos(i + 16, j + 4, k + 16), JourneyBlocks.frozenBrick.getDefaultState());
		world.setBlockState(new BlockPos(i + 16, j + 5, k + 0), JourneyBlocks.frozenBrick.getDefaultState());
		world.setBlockState(new BlockPos(i + 16, j + 5, k + 1), JourneyBlocks.frozenBrick.getDefaultState());
		world.setBlockState(new BlockPos(i + 16, j + 5, k + 2), JourneyBlocks.frozenBrick.getDefaultState());
		world.setBlockState(new BlockPos(i + 16, j + 5, k + 3), JourneyBlocks.frozenBrick.getDefaultState());
		world.setBlockState(new BlockPos(i + 16, j + 5, k + 4), JourneyBlocks.frozenBrick.getDefaultState());
		world.setBlockState(new BlockPos(i + 16, j + 5, k + 5), JourneyBlocks.frozenBrick.getDefaultState());
		world.setBlockState(new BlockPos(i + 16, j + 5, k + 12), JourneyBlocks.frozenBrick.getDefaultState());
		world.setBlockState(new BlockPos(i + 16, j + 5, k + 13), JourneyBlocks.frozenBrick.getDefaultState());
		world.setBlockState(new BlockPos(i + 16, j + 5, k + 14), JourneyBlocks.frozenBrick.getDefaultState());
		world.setBlockState(new BlockPos(i + 16, j + 5, k + 15), JourneyBlocks.frozenBrick.getDefaultState());
		world.setBlockState(new BlockPos(i + 17, j + 0, k + 12), JourneyBlocks.frozenBrick.getDefaultState());
		world.setBlockState(new BlockPos(i + 17, j + 0, k + 13), JourneyBlocks.frozenBrick.getDefaultState());
		world.setBlockState(new BlockPos(i + 17, j + 0, k + 14), JourneyBlocks.frozenBrick.getDefaultState());
		world.setBlockState(new BlockPos(i + 17, j + 0, k + 15), JourneyBlocks.frozenBrick.getDefaultState());
		world.setBlockState(new BlockPos(i + 17, j + 1, k + 12), JourneyBlocks.frozenBrick.getDefaultState());
		world.setBlockState(new BlockPos(i + 17, j + 1, k + 15), JourneyBlocks.frozenBrick.getDefaultState());
		world.setBlockState(new BlockPos(i + 17, j + 2, k + 12), Blocks.ICE.getDefaultState());
		world.setBlockState(new BlockPos(i + 17, j + 2, k + 15), Blocks.ICE.getDefaultState());
		world.setBlockState(new BlockPos(i + 17, j + 3, k + 12), JourneyBlocks.frozenBrick.getDefaultState());
		world.setBlockState(new BlockPos(i + 17, j + 3, k + 14), JourneyBlocks.icicle.getDefaultState());
		world.setBlockState(new BlockPos(i + 17, j + 3, k + 15), JourneyBlocks.frozenBrick.getDefaultState());
		world.setBlockState(new BlockPos(i + 17, j + 4, k + 12), JourneyBlocks.frozenBrick.getDefaultState());
		world.setBlockState(new BlockPos(i + 17, j + 4, k + 13), JourneyBlocks.frozenBrick.getDefaultState());
		world.setBlockState(new BlockPos(i + 17, j + 4, k + 14), JourneyBlocks.frozenBrick.getDefaultState());
		world.setBlockState(new BlockPos(i + 17, j + 4, k + 15), JourneyBlocks.frozenBrick.getDefaultState());
		world.setBlockState(new BlockPos(i + 18, j + 0, k + 12), JourneyBlocks.frozenBrick.getDefaultState());
		world.setBlockState(new BlockPos(i + 18, j + 0, k + 13), JourneyBlocks.frozenBrick.getDefaultState());
		world.setBlockState(new BlockPos(i + 18, j + 0, k + 14), JourneyBlocks.frozenBrick.getDefaultState());
		world.setBlockState(new BlockPos(i + 18, j + 0, k + 15), JourneyBlocks.frozenBrick.getDefaultState());
		world.setBlockState(new BlockPos(i + 18, j + 1, k + 12), JourneyBlocks.frozenBrick.getDefaultState());
		world.setBlockState(new BlockPos(i + 18, j + 1, k + 15), JourneyBlocks.frozenBrick.getDefaultState());
		world.setBlockState(new BlockPos(i + 18, j + 2, k + 12), Blocks.ICE.getDefaultState());
		world.setBlockState(new BlockPos(i + 18, j + 2, k + 15), Blocks.ICE.getDefaultState());
		world.setBlockState(new BlockPos(i + 18, j + 3, k + 12), JourneyBlocks.frozenBrick.getDefaultState());
		world.setBlockState(new BlockPos(i + 18, j + 3, k + 14), JourneyBlocks.icicle.getDefaultState());
		world.setBlockState(new BlockPos(i + 18, j + 3, k + 15), JourneyBlocks.frozenBrick.getDefaultState());
		world.setBlockState(new BlockPos(i + 18, j + 4, k + 12), JourneyBlocks.frozenBrick.getDefaultState());
		world.setBlockState(new BlockPos(i + 18, j + 4, k + 13), JourneyBlocks.frozenBrick.getDefaultState());
		world.setBlockState(new BlockPos(i + 18, j + 4, k + 14), JourneyBlocks.frozenBrick.getDefaultState());
		world.setBlockState(new BlockPos(i + 18, j + 4, k + 15), JourneyBlocks.frozenBrick.getDefaultState());
		world.setBlockState(new BlockPos(i + 19, j + 0, k + 12), JourneyBlocks.frozenBrick.getDefaultState());
		world.setBlockState(new BlockPos(i + 19, j + 0, k + 13), JourneyBlocks.frozenBrick.getDefaultState());
		world.setBlockState(new BlockPos(i + 19, j + 0, k + 14), JourneyBlocks.frozenBrick.getDefaultState());
		world.setBlockState(new BlockPos(i + 19, j + 0, k + 15), JourneyBlocks.frozenBrick.getDefaultState());
		world.setBlockState(new BlockPos(i + 19, j + 1, k + 12), JourneyBlocks.frozenBrick.getDefaultState());
		world.setBlockState(new BlockPos(i + 19, j + 1, k + 15), JourneyBlocks.frozenBrick.getDefaultState());
		world.setBlockState(new BlockPos(i + 19, j + 2, k + 12), Blocks.ICE.getDefaultState());
		world.setBlockState(new BlockPos(i + 19, j + 2, k + 15), Blocks.ICE.getDefaultState());
		world.setBlockState(new BlockPos(i + 19, j + 3, k + 12), JourneyBlocks.frozenBrick.getDefaultState());
		world.setBlockState(new BlockPos(i + 19, j + 3, k + 13), JourneyBlocks.icicle.getDefaultState());
		world.setBlockState(new BlockPos(i + 19, j + 3, k + 15), JourneyBlocks.frozenBrick.getDefaultState());
		world.setBlockState(new BlockPos(i + 19, j + 4, k + 12), JourneyBlocks.frozenBrick.getDefaultState());
		world.setBlockState(new BlockPos(i + 19, j + 4, k + 13), JourneyBlocks.frozenBrick.getDefaultState());
		world.setBlockState(new BlockPos(i + 19, j + 4, k + 14), JourneyBlocks.frozenBrick.getDefaultState());
		world.setBlockState(new BlockPos(i + 19, j + 4, k + 15), JourneyBlocks.frozenBrick.getDefaultState());
		world.setBlockState(new BlockPos(i + 20, j + 0, k + 12), JourneyBlocks.frozenBrick.getDefaultState());
		world.setBlockState(new BlockPos(i + 20, j + 0, k + 13), JourneyBlocks.frozenBrick.getDefaultState());
		world.setBlockState(new BlockPos(i + 20, j + 0, k + 14), JourneyBlocks.frozenBrick.getDefaultState());
		world.setBlockState(new BlockPos(i + 20, j + 0, k + 15), JourneyBlocks.frozenBrick.getDefaultState());
		world.setBlockState(new BlockPos(i + 20, j + 1, k + 12), JourneyBlocks.frozenBrick.getDefaultState());
		world.setBlockState(new BlockPos(i + 20, j + 1, k + 15), JourneyBlocks.frozenBrick.getDefaultState());
		world.setBlockState(new BlockPos(i + 20, j + 2, k + 12), Blocks.ICE.getDefaultState());
		world.setBlockState(new BlockPos(i + 20, j + 2, k + 15), Blocks.ICE.getDefaultState());
		world.setBlockState(new BlockPos(i + 20, j + 3, k + 12), JourneyBlocks.frozenBrick.getDefaultState());
		world.setBlockState(new BlockPos(i + 20, j + 3, k + 15), JourneyBlocks.frozenBrick.getDefaultState());
		world.setBlockState(new BlockPos(i + 20, j + 4, k + 12), JourneyBlocks.frozenBrick.getDefaultState());
		world.setBlockState(new BlockPos(i + 20, j + 4, k + 13), JourneyBlocks.frozenBrick.getDefaultState());
		world.setBlockState(new BlockPos(i + 20, j + 4, k + 14), JourneyBlocks.frozenBrick.getDefaultState());
		world.setBlockState(new BlockPos(i + 20, j + 4, k + 15), JourneyBlocks.frozenBrick.getDefaultState());
		world.setBlockState(new BlockPos(i + 21, j + 0, k + 12), JourneyBlocks.frozenBrick.getDefaultState());
		world.setBlockState(new BlockPos(i + 21, j + 0, k + 13), JourneyBlocks.frozenBrick.getDefaultState());
		world.setBlockState(new BlockPos(i + 21, j + 0, k + 14), JourneyBlocks.frozenBrick.getDefaultState());
		world.setBlockState(new BlockPos(i + 21, j + 0, k + 15), JourneyBlocks.frozenBrick.getDefaultState());
		world.setBlockState(new BlockPos(i + 21, j + 1, k + 12), JourneyBlocks.frozenBrick.getDefaultState());
		world.setBlockState(new BlockPos(i + 21, j + 1, k + 15), JourneyBlocks.frozenBrick.getDefaultState());
		world.setBlockState(new BlockPos(i + 21, j + 2, k + 12), Blocks.ICE.getDefaultState());
		world.setBlockState(new BlockPos(i + 21, j + 2, k + 15), Blocks.ICE.getDefaultState());
		world.setBlockState(new BlockPos(i + 21, j + 3, k + 12), JourneyBlocks.frozenBrick.getDefaultState());
		world.setBlockState(new BlockPos(i + 21, j + 3, k + 13), JourneyBlocks.icicle.getDefaultState());
		world.setBlockState(new BlockPos(i + 21, j + 3, k + 15), JourneyBlocks.frozenBrick.getDefaultState());
		world.setBlockState(new BlockPos(i + 21, j + 4, k + 12), JourneyBlocks.frozenBrick.getDefaultState());
		world.setBlockState(new BlockPos(i + 21, j + 4, k + 13), JourneyBlocks.frozenBrick.getDefaultState());
		world.setBlockState(new BlockPos(i + 21, j + 4, k + 14), JourneyBlocks.frozenBrick.getDefaultState());
		world.setBlockState(new BlockPos(i + 21, j + 4, k + 15), JourneyBlocks.frozenBrick.getDefaultState());
		world.setBlockState(new BlockPos(i + 22, j + 0, k + 11), JourneyBlocks.frozenBrick.getDefaultState());
		world.setBlockState(new BlockPos(i + 22, j + 0, k + 12), JourneyBlocks.frozenBrick.getDefaultState());
		world.setBlockState(new BlockPos(i + 22, j + 0, k + 13), JourneyBlocks.frozenBrick.getDefaultState());
		world.setBlockState(new BlockPos(i + 22, j + 0, k + 14), JourneyBlocks.frozenBrick.getDefaultState());
		world.setBlockState(new BlockPos(i + 22, j + 0, k + 15), JourneyBlocks.frozenBrick.getDefaultState());
		world.setBlockState(new BlockPos(i + 22, j + 0, k + 16), JourneyBlocks.frozenBrick.getDefaultState());
		world.setBlockState(new BlockPos(i + 22, j + 1, k + 11), JourneyBlocks.frozenBrick.getDefaultState());
		world.setBlockState(new BlockPos(i + 22, j + 1, k + 16), JourneyBlocks.frozenBrick.getDefaultState());
		world.setBlockState(new BlockPos(i + 22, j + 2, k + 11), JourneyBlocks.frozenBrick.getDefaultState());
		world.setBlockState(new BlockPos(i + 22, j + 2, k + 16), JourneyBlocks.frozenBrick.getDefaultState());
		world.setBlockState(new BlockPos(i + 22, j + 3, k + 11), JourneyBlocks.frozenBrick.getDefaultState());
		world.setBlockState(new BlockPos(i + 22, j + 3, k + 16), JourneyBlocks.frozenBrick.getDefaultState());
		world.setBlockState(new BlockPos(i + 22, j + 4, k + 11), JourneyBlocks.frozenBrick.getDefaultState());
		world.setBlockState(new BlockPos(i + 22, j + 4, k + 15), JourneyBlocks.icicle.getDefaultState());
		world.setBlockState(new BlockPos(i + 22, j + 4, k + 16), JourneyBlocks.frozenBrick.getDefaultState());
		world.setBlockState(new BlockPos(i + 22, j + 5, k + 11), JourneyBlocks.frozenBrick.getDefaultState());
		world.setBlockState(new BlockPos(i + 22, j + 5, k + 12), JourneyBlocks.frozenBrick.getDefaultState());
		world.setBlockState(new BlockPos(i + 22, j + 5, k + 13), JourneyBlocks.frozenBrick.getDefaultState());
		world.setBlockState(new BlockPos(i + 22, j + 5, k + 14), JourneyBlocks.frozenBrick.getDefaultState());
		world.setBlockState(new BlockPos(i + 22, j + 5, k + 15), JourneyBlocks.frozenBrick.getDefaultState());
		world.setBlockState(new BlockPos(i + 22, j + 5, k + 16), JourneyBlocks.frozenBrick.getDefaultState());
		world.setBlockState(new BlockPos(i + 23, j + 0, k + 11), JourneyBlocks.frozenBrick.getDefaultState());
		world.setBlockState(new BlockPos(i + 23, j + 0, k + 12), JourneyBlocks.frozenBrick.getDefaultState());
		world.setBlockState(new BlockPos(i + 23, j + 0, k + 13), JourneyBlocks.frozenBrick.getDefaultState());
		world.setBlockState(new BlockPos(i + 23, j + 0, k + 14), JourneyBlocks.frozenBrick.getDefaultState());
		world.setBlockState(new BlockPos(i + 23, j + 0, k + 15), JourneyBlocks.frozenBrick.getDefaultState());
		world.setBlockState(new BlockPos(i + 23, j + 0, k + 16), JourneyBlocks.frozenBrick.getDefaultState());
		world.setBlockState(new BlockPos(i + 23, j + 1, k + 11), JourneyBlocks.frozenBrick.getDefaultState());
		world.setBlockState(new BlockPos(i + 23, j + 1, k + 16), JourneyBlocks.frozenBrick.getDefaultState());
		world.setBlockState(new BlockPos(i + 23, j + 2, k + 11), JourneyBlocks.frozenBrick.getDefaultState());
		world.setBlockState(new BlockPos(i + 23, j + 2, k + 16), JourneyBlocks.frozenBrick.getDefaultState());
		world.setBlockState(new BlockPos(i + 23, j + 3, k + 11), JourneyBlocks.frozenBrick.getDefaultState());
		world.setBlockState(new BlockPos(i + 23, j + 3, k + 16), JourneyBlocks.frozenBrick.getDefaultState());
		world.setBlockState(new BlockPos(i + 23, j + 4, k + 11), JourneyBlocks.frozenBrick.getDefaultState());
		world.setBlockState(new BlockPos(i + 23, j + 4, k + 12), JourneyBlocks.icicle.getDefaultState());
		world.setBlockState(new BlockPos(i + 23, j + 4, k + 13), JourneyBlocks.icicle.getDefaultState());
		world.setBlockState(new BlockPos(i + 23, j + 4, k + 16), JourneyBlocks.frozenBrick.getDefaultState());
		world.setBlockState(new BlockPos(i + 23, j + 5, k + 11), JourneyBlocks.frozenBrick.getDefaultState());
		world.setBlockState(new BlockPos(i + 23, j + 5, k + 12), JourneyBlocks.frozenBrick.getDefaultState());
		world.setBlockState(new BlockPos(i + 23, j + 5, k + 13), JourneyBlocks.frozenBrick.getDefaultState());
		world.setBlockState(new BlockPos(i + 23, j + 5, k + 14), JourneyBlocks.frozenBrick.getDefaultState());
		world.setBlockState(new BlockPos(i + 23, j + 5, k + 15), JourneyBlocks.frozenBrick.getDefaultState());
		world.setBlockState(new BlockPos(i + 23, j + 5, k + 16), JourneyBlocks.frozenBrick.getDefaultState());
		world.setBlockState(new BlockPos(i + 24, j + 0, k + 11), JourneyBlocks.frozenBrick.getDefaultState());
		world.setBlockState(new BlockPos(i + 24, j + 0, k + 12), JourneyBlocks.frozenBrick.getDefaultState());
		world.setBlockState(new BlockPos(i + 24, j + 0, k + 13), JourneyBlocks.frozenBrick.getDefaultState());
		world.setBlockState(new BlockPos(i + 24, j + 0, k + 14), JourneyBlocks.frozenBrick.getDefaultState());
		world.setBlockState(new BlockPos(i + 24, j + 0, k + 15), JourneyBlocks.frozenBrick.getDefaultState());
		world.setBlockState(new BlockPos(i + 24, j + 0, k + 16), JourneyBlocks.frozenBrick.getDefaultState());
		world.setBlockState(new BlockPos(i + 24, j + 1, k + 11), JourneyBlocks.frozenBrick.getDefaultState());
		world.setBlockState(new BlockPos(i + 24, j + 1, k + 16), JourneyBlocks.frozenBrick.getDefaultState());
		world.setBlockState(new BlockPos(i + 24, j + 2, k + 11), JourneyBlocks.frozenBrick.getDefaultState());
		world.setBlockState(new BlockPos(i + 24, j + 2, k + 16), JourneyBlocks.frozenBrick.getDefaultState());
		world.setBlockState(new BlockPos(i + 24, j + 3, k + 11), JourneyBlocks.frozenBrick.getDefaultState());
		world.setBlockState(new BlockPos(i + 24, j + 3, k + 16), JourneyBlocks.frozenBrick.getDefaultState());
		world.setBlockState(new BlockPos(i + 24, j + 4, k + 11), JourneyBlocks.frozenBrick.getDefaultState());
		world.setBlockState(new BlockPos(i + 24, j + 4, k + 15), JourneyBlocks.icicle.getDefaultState());
		world.setBlockState(new BlockPos(i + 24, j + 4, k + 16), JourneyBlocks.frozenBrick.getDefaultState());
		world.setBlockState(new BlockPos(i + 24, j + 5, k + 11), JourneyBlocks.frozenBrick.getDefaultState());
		world.setBlockState(new BlockPos(i + 24, j + 5, k + 12), JourneyBlocks.frozenBrick.getDefaultState());
		world.setBlockState(new BlockPos(i + 24, j + 5, k + 13), Blocks.ICE.getDefaultState());
		world.setBlockState(new BlockPos(i + 24, j + 5, k + 14), Blocks.ICE.getDefaultState());
		world.setBlockState(new BlockPos(i + 24, j + 5, k + 15), JourneyBlocks.frozenBrick.getDefaultState());
		world.setBlockState(new BlockPos(i + 24, j + 5, k + 16), JourneyBlocks.frozenBrick.getDefaultState());
		world.setBlockState(new BlockPos(i + 25, j + 0, k + 11), JourneyBlocks.frozenBrick.getDefaultState());
		world.setBlockState(new BlockPos(i + 25, j + 0, k + 12), JourneyBlocks.frozenBrick.getDefaultState());
		world.setBlockState(new BlockPos(i + 25, j + 0, k + 13), JourneyBlocks.frozenBrick.getDefaultState());
		world.setBlockState(new BlockPos(i + 25, j + 0, k + 14), JourneyBlocks.frozenBrick.getDefaultState());
		world.setBlockState(new BlockPos(i + 25, j + 0, k + 15), JourneyBlocks.frozenBrick.getDefaultState());
		world.setBlockState(new BlockPos(i + 25, j + 0, k + 16), JourneyBlocks.frozenBrick.getDefaultState());
		world.setBlockState(new BlockPos(i + 25, j + 1, k + 11), JourneyBlocks.frozenBrick.getDefaultState());
		world.setBlockState(new BlockPos(i + 25, j + 1, k + 16), JourneyBlocks.frozenBrick.getDefaultState());
		world.setBlockState(new BlockPos(i + 25, j + 2, k + 11), JourneyBlocks.frozenBrick.getDefaultState());
		world.setBlockState(new BlockPos(i + 25, j + 2, k + 16), JourneyBlocks.frozenBrick.getDefaultState());
		world.setBlockState(new BlockPos(i + 25, j + 3, k + 11), JourneyBlocks.frozenBrick.getDefaultState());
		world.setBlockState(new BlockPos(i + 25, j + 3, k + 16), JourneyBlocks.frozenBrick.getDefaultState());
		world.setBlockState(new BlockPos(i + 25, j + 4, k + 11), JourneyBlocks.frozenBrick.getDefaultState());
		world.setBlockState(new BlockPos(i + 25, j + 4, k + 14), JourneyBlocks.icicle.getDefaultState());
		world.setBlockState(new BlockPos(i + 25, j + 4, k + 16), JourneyBlocks.frozenBrick.getDefaultState());
		world.setBlockState(new BlockPos(i + 25, j + 5, k + 11), JourneyBlocks.frozenBrick.getDefaultState());
		world.setBlockState(new BlockPos(i + 25, j + 5, k + 12), JourneyBlocks.frozenBrick.getDefaultState());
		world.setBlockState(new BlockPos(i + 25, j + 5, k + 13), Blocks.ICE.getDefaultState());
		world.setBlockState(new BlockPos(i + 25, j + 5, k + 14), Blocks.ICE.getDefaultState());
		world.setBlockState(new BlockPos(i + 25, j + 5, k + 15), JourneyBlocks.frozenBrick.getDefaultState());
		world.setBlockState(new BlockPos(i + 25, j + 5, k + 16), JourneyBlocks.frozenBrick.getDefaultState());
		world.setBlockState(new BlockPos(i + 26, j + 0, k + 11), JourneyBlocks.frozenBrick.getDefaultState());
		world.setBlockState(new BlockPos(i + 26, j + 0, k + 12), JourneyBlocks.frozenBrick.getDefaultState());
		world.setBlockState(new BlockPos(i + 26, j + 0, k + 13), JourneyBlocks.frozenBrick.getDefaultState());
		world.setBlockState(new BlockPos(i + 26, j + 0, k + 14), JourneyBlocks.frozenBrick.getDefaultState());
		world.setBlockState(new BlockPos(i + 26, j + 0, k + 15), JourneyBlocks.frozenBrick.getDefaultState());
		world.setBlockState(new BlockPos(i + 26, j + 0, k + 16), JourneyBlocks.frozenBrick.getDefaultState());
		world.setBlockState(new BlockPos(i + 26, j + 1, k + 11), JourneyBlocks.frozenBrick.getDefaultState());
		world.setBlockState(new BlockPos(i + 26, j + 1, k + 13), JourneyBlocks.frostbiterSpawner.getDefaultState());
		world.setBlockState(new BlockPos(i + 26, j + 1, k + 14), JourneyBlocks.frostbiterSpawner.getDefaultState());
		world.setBlockState(new BlockPos(i + 26, j + 1, k + 16), JourneyBlocks.frozenBrick.getDefaultState());
		world.setBlockState(new BlockPos(i + 26, j + 2, k + 11), JourneyBlocks.frozenBrick.getDefaultState());
		world.setBlockState(new BlockPos(i + 26, j + 2, k + 16), JourneyBlocks.frozenBrick.getDefaultState());
		world.setBlockState(new BlockPos(i + 26, j + 3, k + 11), JourneyBlocks.frozenBrick.getDefaultState());
		world.setBlockState(new BlockPos(i + 26, j + 3, k + 16), JourneyBlocks.frozenBrick.getDefaultState());
		world.setBlockState(new BlockPos(i + 26, j + 4, k + 11), JourneyBlocks.frozenBrick.getDefaultState());
		world.setBlockState(new BlockPos(i + 26, j + 4, k + 16), JourneyBlocks.frozenBrick.getDefaultState());
		world.setBlockState(new BlockPos(i + 26, j + 5, k + 11), JourneyBlocks.frozenBrick.getDefaultState());
		world.setBlockState(new BlockPos(i + 26, j + 5, k + 12), JourneyBlocks.frozenBrick.getDefaultState());
		world.setBlockState(new BlockPos(i + 26, j + 5, k + 13), JourneyBlocks.frozenBrick.getDefaultState());
		world.setBlockState(new BlockPos(i + 26, j + 5, k + 14), JourneyBlocks.frozenBrick.getDefaultState());
		world.setBlockState(new BlockPos(i + 26, j + 5, k + 15), JourneyBlocks.frozenBrick.getDefaultState());
		world.setBlockState(new BlockPos(i + 26, j + 5, k + 16), JourneyBlocks.frozenBrick.getDefaultState());
		world.setBlockState(new BlockPos(i + 27, j + 0, k + 11), JourneyBlocks.frozenBrick.getDefaultState());
		world.setBlockState(new BlockPos(i + 27, j + 0, k + 12), JourneyBlocks.frozenBrick.getDefaultState());
		world.setBlockState(new BlockPos(i + 27, j + 0, k + 13), JourneyBlocks.frozenBrick.getDefaultState());
		world.setBlockState(new BlockPos(i + 27, j + 0, k + 14), JourneyBlocks.frozenBrick.getDefaultState());
		world.setBlockState(new BlockPos(i + 27, j + 0, k + 15), JourneyBlocks.frozenBrick.getDefaultState());
		world.setBlockState(new BlockPos(i + 27, j + 0, k + 16), JourneyBlocks.frozenBrick.getDefaultState());
		world.setBlockState(new BlockPos(i + 27, j + 1, k + 11), JourneyBlocks.frozenBrick.getDefaultState());
		world.setBlockState(new BlockPos(i + 27, j + 1, k + 12), JourneyBlocks.frozenBrick.getDefaultState());
		world.setBlockState(new BlockPos(i + 27, j + 1, k + 13), JourneyBlocks.frozenBrick.getDefaultState());
		world.setBlockState(new BlockPos(i + 27, j + 1, k + 14), JourneyBlocks.frozenBrick.getDefaultState());
		world.setBlockState(new BlockPos(i + 27, j + 1, k + 15), JourneyBlocks.frozenBrick.getDefaultState());
		world.setBlockState(new BlockPos(i + 27, j + 1, k + 16), JourneyBlocks.frozenBrick.getDefaultState());
		world.setBlockState(new BlockPos(i + 27, j + 2, k + 11), JourneyBlocks.frozenBrick.getDefaultState());
		world.setBlockState(new BlockPos(i + 27, j + 2, k + 12), JourneyBlocks.frozenBrick.getDefaultState());
		world.setBlockState(new BlockPos(i + 27, j + 2, k + 13), JourneyBlocks.frozenBrick.getDefaultState());
		world.setBlockState(new BlockPos(i + 27, j + 2, k + 14), JourneyBlocks.frozenBrick.getDefaultState());
		world.setBlockState(new BlockPos(i + 27, j + 2, k + 15), JourneyBlocks.frozenBrick.getDefaultState());
		world.setBlockState(new BlockPos(i + 27, j + 2, k + 16), JourneyBlocks.frozenBrick.getDefaultState());
		world.setBlockState(new BlockPos(i + 27, j + 3, k + 11), JourneyBlocks.frozenBrick.getDefaultState());
		world.setBlockState(new BlockPos(i + 27, j + 3, k + 12), JourneyBlocks.frozenBrick.getDefaultState());
		world.setBlockState(new BlockPos(i + 27, j + 3, k + 13), JourneyBlocks.frozenBrick.getDefaultState());
		world.setBlockState(new BlockPos(i + 27, j + 3, k + 14), JourneyBlocks.frozenBrick.getDefaultState());
		world.setBlockState(new BlockPos(i + 27, j + 3, k + 15), JourneyBlocks.frozenBrick.getDefaultState());
		world.setBlockState(new BlockPos(i + 27, j + 3, k + 16), JourneyBlocks.frozenBrick.getDefaultState());
		world.setBlockState(new BlockPos(i + 27, j + 4, k + 11), JourneyBlocks.frozenBrick.getDefaultState());
		world.setBlockState(new BlockPos(i + 27, j + 4, k + 12), JourneyBlocks.frozenBrick.getDefaultState());
		world.setBlockState(new BlockPos(i + 27, j + 4, k + 13), JourneyBlocks.frozenBrick.getDefaultState());
		world.setBlockState(new BlockPos(i + 27, j + 4, k + 14), JourneyBlocks.frozenBrick.getDefaultState());
		world.setBlockState(new BlockPos(i + 27, j + 4, k + 15), JourneyBlocks.frozenBrick.getDefaultState());
		world.setBlockState(new BlockPos(i + 27, j + 4, k + 16), JourneyBlocks.frozenBrick.getDefaultState());
		world.setBlockState(new BlockPos(i + 27, j + 5, k + 11), JourneyBlocks.frozenBrick.getDefaultState());
		world.setBlockState(new BlockPos(i + 27, j + 5, k + 12), JourneyBlocks.frozenBrick.getDefaultState());
		world.setBlockState(new BlockPos(i + 27, j + 5, k + 13), JourneyBlocks.frozenBrick.getDefaultState());
		world.setBlockState(new BlockPos(i + 27, j + 5, k + 14), JourneyBlocks.frozenBrick.getDefaultState());
		world.setBlockState(new BlockPos(i + 27, j + 5, k + 15), JourneyBlocks.frozenBrick.getDefaultState());
		world.setBlockState(new BlockPos(i + 27, j + 5, k + 16), JourneyBlocks.frozenBrick.getDefaultState());

		return true;
	}
}