package net.journey.dimension.frozen.gen;

import java.util.Random;

import com.google.common.collect.Lists;

import net.journey.JourneyBlocks;
import net.journey.JourneyItems;
import net.journey.blocks.tileentity.TileEntityJourneyChest;
import net.journey.entity.mob.frozen.npc.EntityFrozenMerchant;
import net.journey.util.JourneyLootTables;
import net.minecraft.init.Blocks;
import net.minecraft.tileentity.TileEntity;
import net.minecraft.util.math.BlockPos;
import net.minecraft.world.World;
import net.minecraft.world.gen.feature.WorldGenerator;
import net.slayer.api.worldgen.WorldGenAPI;

public class WorldGenMerchantHouse extends WorldGenerator {
	
	
	/*private static WeightedRandomChestContent[] loot = {
		new WeightedRandomChestContent(JourneyItems.frostGem, 0, 1, 5, 10), 
		new WeightedRandomChestContent(JourneyItems.crystalFlake, 0, 1, 10, 40)};*/
	

	public boolean locationIsValidSpawn(World w, int x, int y, int z) {
		return WorldGenAPI.checkRadius(w, new BlockPos(x,y,z), 11, JourneyBlocks.frozenGrass);
	}
	
	@Override
	public boolean generate(World w, Random r, BlockPos pos) {
		int x = pos.getX(), y = pos.getY() - 1, z = pos.getZ();
		if(locationIsValidSpawn(w, x, y, z)) return true;
		
		w.setBlockState(new BlockPos(x + 0, y + 5, z + 1), JourneyBlocks.frozenBrick.getDefaultState());
		w.setBlockState(new BlockPos(x + 0, y + 5, z + 2), JourneyBlocks.frozenBrick.getDefaultState());
		w.setBlockState(new BlockPos(x + 0, y + 5, z + 3), JourneyBlocks.frozenBrick.getDefaultState());
		w.setBlockState(new BlockPos(x + 0, y + 5, z + 4), JourneyBlocks.frozenBrick.getDefaultState());
		w.setBlockState(new BlockPos(x + 0, y + 5, z + 5), JourneyBlocks.frozenBrick.getDefaultState());
		w.setBlockState(new BlockPos(x + 0, y + 5, z + 6), JourneyBlocks.frozenBrick.getDefaultState());
		w.setBlockState(new BlockPos(x + 0, y + 5, z + 7), JourneyBlocks.frozenBrick.getDefaultState());
		w.setBlockState(new BlockPos(x + 0, y + 5, z + 8), JourneyBlocks.frozenBrick.getDefaultState());
		w.setBlockState(new BlockPos(x + 0, y + 5, z + 9), JourneyBlocks.frozenBrick.getDefaultState());
		w.setBlockState(new BlockPos(x + 0, y + 5, z + 10), JourneyBlocks.frozenBrick.getDefaultState());
		w.setBlockState(new BlockPos(x + 0, y + 5, z + 11), JourneyBlocks.frozenBrick.getDefaultState());
		w.setBlockState(new BlockPos(x + 1, y + 0, z + 2), JourneyBlocks.frozenBrick.getDefaultState());
		w.setBlockState(new BlockPos(x + 1, y + 0, z + 3), JourneyBlocks.frozenBrick.getDefaultState());
		w.setBlockState(new BlockPos(x + 1, y + 0, z + 4), JourneyBlocks.frozenBrick.getDefaultState());
		w.setBlockState(new BlockPos(x + 1, y + 0, z + 5), JourneyBlocks.frozenBrick.getDefaultState());
		w.setBlockState(new BlockPos(x + 1, y + 0, z + 6), JourneyBlocks.frozenBrick.getDefaultState());
		w.setBlockState(new BlockPos(x + 1, y + 0, z + 7), JourneyBlocks.frozenBrick.getDefaultState());
		w.setBlockState(new BlockPos(x + 1, y + 0, z + 8), JourneyBlocks.frozenBrick.getDefaultState());
		w.setBlockState(new BlockPos(x + 1, y + 0, z + 9), JourneyBlocks.frozenBrick.getDefaultState());
		w.setBlockState(new BlockPos(x + 1, y + 0, z + 10), JourneyBlocks.frozenBrick.getDefaultState());
		w.setBlockState(new BlockPos(x + 1, y + 1, z + 2), JourneyBlocks.frozenBrick.getDefaultState());
		w.setBlockState(new BlockPos(x + 1, y + 1, z + 3), JourneyBlocks.frozenBrick.getDefaultState());
		w.setBlockState(new BlockPos(x + 1, y + 1, z + 4), JourneyBlocks.frozenBrick.getDefaultState());
		w.setBlockState(new BlockPos(x + 1, y + 1, z + 5), JourneyBlocks.frozenBrick.getDefaultState());
		w.setBlockState(new BlockPos(x + 1, y + 1, z + 6), JourneyBlocks.frozenBrick.getDefaultState());
		w.setBlockState(new BlockPos(x + 1, y + 1, z + 7), JourneyBlocks.frozenBrick.getDefaultState());
		w.setBlockState(new BlockPos(x + 1, y + 1, z + 8), JourneyBlocks.frozenBrick.getDefaultState());
		w.setBlockState(new BlockPos(x + 1, y + 1, z + 9), JourneyBlocks.frozenBrick.getDefaultState());
		w.setBlockState(new BlockPos(x + 1, y + 1, z + 10), JourneyBlocks.frozenBrick.getDefaultState());
		w.setBlockState(new BlockPos(x + 1, y + 2, z + 2), JourneyBlocks.frozenBrick.getDefaultState());
		w.setBlockState(new BlockPos(x + 1, y + 2, z + 3), JourneyBlocks.frozenBrick.getDefaultState());
		w.setBlockState(new BlockPos(x + 1, y + 2, z + 4), Blocks.GLASS_PANE.getStateFromMeta(1));
		w.setBlockState(new BlockPos(x + 1, y + 2, z + 5), Blocks.GLASS_PANE.getStateFromMeta(1));
		w.setBlockState(new BlockPos(x + 1, y + 2, z + 6), JourneyBlocks.frozenBrick.getDefaultState());
		w.setBlockState(new BlockPos(x + 1, y + 2, z + 7), Blocks.GLASS_PANE.getStateFromMeta(1));
		w.setBlockState(new BlockPos(x + 1, y + 2, z + 8), Blocks.GLASS_PANE.getStateFromMeta(1));
		w.setBlockState(new BlockPos(x + 1, y + 2, z + 9), JourneyBlocks.frozenBrick.getDefaultState());
		w.setBlockState(new BlockPos(x + 1, y + 2, z + 10), JourneyBlocks.frozenBrick.getDefaultState());
		w.setBlockState(new BlockPos(x + 1, y + 3, z + 2), JourneyBlocks.frozenBrick.getDefaultState());
		w.setBlockState(new BlockPos(x + 1, y + 3, z + 3), JourneyBlocks.frozenBrick.getDefaultState());
		w.setBlockState(new BlockPos(x + 1, y + 3, z + 4), Blocks.GLASS_PANE.getStateFromMeta(1));
		w.setBlockState(new BlockPos(x + 1, y + 3, z + 5), Blocks.GLASS_PANE.getStateFromMeta(1));
		w.setBlockState(new BlockPos(x + 1, y + 3, z + 6), JourneyBlocks.frozenBrick.getDefaultState());
		w.setBlockState(new BlockPos(x + 1, y + 3, z + 7), Blocks.GLASS_PANE.getStateFromMeta(1));
		w.setBlockState(new BlockPos(x + 1, y + 3, z + 8), Blocks.GLASS_PANE.getStateFromMeta(1));
		w.setBlockState(new BlockPos(x + 1, y + 3, z + 9), JourneyBlocks.frozenBrick.getDefaultState());
		w.setBlockState(new BlockPos(x + 1, y + 3, z + 10), JourneyBlocks.frozenBrick.getDefaultState());
		w.setBlockState(new BlockPos(x + 1, y + 4, z + 2), JourneyBlocks.frozenBrick.getDefaultState());
		w.setBlockState(new BlockPos(x + 1, y + 4, z + 3), JourneyBlocks.frozenBrick.getDefaultState());
		w.setBlockState(new BlockPos(x + 1, y + 4, z + 4), JourneyBlocks.frozenBrick.getDefaultState());
		w.setBlockState(new BlockPos(x + 1, y + 4, z + 5), JourneyBlocks.frozenBrick.getDefaultState());
		w.setBlockState(new BlockPos(x + 1, y + 4, z + 6), JourneyBlocks.frozenBrick.getDefaultState());
		w.setBlockState(new BlockPos(x + 1, y + 4, z + 7), JourneyBlocks.frozenBrick.getDefaultState());
		w.setBlockState(new BlockPos(x + 1, y + 4, z + 8), JourneyBlocks.frozenBrick.getDefaultState());
		w.setBlockState(new BlockPos(x + 1, y + 4, z + 9), JourneyBlocks.frozenBrick.getDefaultState());
		w.setBlockState(new BlockPos(x + 1, y + 4, z + 10), JourneyBlocks.frozenBrick.getDefaultState());
		w.setBlockState(new BlockPos(x + 1, y + 5, z + 2), JourneyBlocks.frozenBrick.getDefaultState());
		w.setBlockState(new BlockPos(x + 1, y + 5, z + 3), JourneyBlocks.frozenBrick.getDefaultState());
		w.setBlockState(new BlockPos(x + 1, y + 5, z + 4), JourneyBlocks.frozenBrick.getDefaultState());
		w.setBlockState(new BlockPos(x + 1, y + 5, z + 5), JourneyBlocks.frozenBrick.getDefaultState());
		w.setBlockState(new BlockPos(x + 1, y + 5, z + 6), JourneyBlocks.frozenBrick.getDefaultState());
		w.setBlockState(new BlockPos(x + 1, y + 5, z + 7), JourneyBlocks.frozenBrick.getDefaultState());
		w.setBlockState(new BlockPos(x + 1, y + 5, z + 8), JourneyBlocks.frozenBrick.getDefaultState());
		w.setBlockState(new BlockPos(x + 1, y + 5, z + 9), JourneyBlocks.frozenBrick.getDefaultState());
		w.setBlockState(new BlockPos(x + 1, y + 5, z + 10), JourneyBlocks.frozenBrick.getDefaultState());
		w.setBlockState(new BlockPos(x + 1, y + 6, z + 1), JourneyBlocks.frozenBrick.getDefaultState());
		w.setBlockState(new BlockPos(x + 1, y + 6, z + 2), JourneyBlocks.frozenBrick.getDefaultState());
		w.setBlockState(new BlockPos(x + 1, y + 6, z + 3), JourneyBlocks.frozenBrick.getDefaultState());
		w.setBlockState(new BlockPos(x + 1, y + 6, z + 4), JourneyBlocks.frozenBrick.getDefaultState());
		w.setBlockState(new BlockPos(x + 1, y + 6, z + 5), JourneyBlocks.frozenBrick.getDefaultState());
		w.setBlockState(new BlockPos(x + 1, y + 6, z + 6), JourneyBlocks.frozenBrick.getDefaultState());
		w.setBlockState(new BlockPos(x + 1, y + 6, z + 7), JourneyBlocks.frozenBrick.getDefaultState());
		w.setBlockState(new BlockPos(x + 1, y + 6, z + 8), JourneyBlocks.frozenBrick.getDefaultState());
		w.setBlockState(new BlockPos(x + 1, y + 6, z + 9), JourneyBlocks.frozenBrick.getDefaultState());
		w.setBlockState(new BlockPos(x + 1, y + 6, z + 10), JourneyBlocks.frozenBrick.getDefaultState());
		w.setBlockState(new BlockPos(x + 1, y + 6, z + 11), JourneyBlocks.frozenBrick.getDefaultState());
		w.setBlockState(new BlockPos(x + 2, y + 0, z + 2), JourneyBlocks.frozenBrick.getDefaultState());
		w.setBlockState(new BlockPos(x + 2, y + 0, z + 3), JourneyBlocks.frozenPlanks.getDefaultState());
		w.setBlockState(new BlockPos(x + 2, y + 0, z + 4), JourneyBlocks.frozenPlanks.getDefaultState());
		w.setBlockState(new BlockPos(x + 2, y + 0, z + 5), JourneyBlocks.frozenPlanks.getDefaultState());
		w.setBlockState(new BlockPos(x + 2, y + 0, z + 6), JourneyBlocks.frozenPlanks.getDefaultState());
		w.setBlockState(new BlockPos(x + 2, y + 0, z + 7), JourneyBlocks.frozenPlanks.getDefaultState());
		w.setBlockState(new BlockPos(x + 2, y + 0, z + 8), JourneyBlocks.frozenPlanks.getDefaultState());
		w.setBlockState(new BlockPos(x + 2, y + 0, z + 9), JourneyBlocks.frozenPlanks.getDefaultState());
		w.setBlockState(new BlockPos(x + 2, y + 0, z + 10), JourneyBlocks.frozenBrick.getDefaultState());
		w.setBlockState(new BlockPos(x + 2, y + 1, z + 2), JourneyBlocks.frozenBrick.getDefaultState());
		w.setBlockState(new BlockPos(x + 2, y + 1, z + 5), JourneyBlocks.journeyChest.getStateFromMeta(3));
		
        TileEntity chest = w.getTileEntity(new BlockPos(x + 2, y + 1, z + 5));
		if (chest instanceof TileEntityJourneyChest) {
			((TileEntityJourneyChest) chest).setLootTable(JourneyLootTables.FROZEN_MERCH_CHEST, r.nextLong());
		}
		
		w.setBlockState(new BlockPos(x + 2, y + 1, z + 6), JourneyBlocks.journeyChest.getStateFromMeta(3));
		w.setBlockState(new BlockPos(x + 2, y + 1, z + 8), JourneyBlocks.frozenBrick.getDefaultState());
		w.setBlockState(new BlockPos(x + 2, y + 1, z + 9), JourneyBlocks.journeyChest.getStateFromMeta(3));
		
        TileEntity chest1 = w.getTileEntity(new BlockPos(x + 2, y + 1, z + 9));
		if (chest1 instanceof TileEntityJourneyChest) {
			((TileEntityJourneyChest) chest1).setLootTable(JourneyLootTables.FROZEN_MERCH_CHEST, r.nextLong());
		}
		
		w.setBlockState(new BlockPos(x + 2, y + 1, z + 10), JourneyBlocks.frozenBrick.getDefaultState());
		w.setBlockState(new BlockPos(x + 2, y + 2, z + 2), JourneyBlocks.frozenBrick.getDefaultState());
		w.setBlockState(new BlockPos(x + 2, y + 2, z + 10), JourneyBlocks.frozenBrick.getDefaultState());
		w.setBlockState(new BlockPos(x + 2, y + 3, z + 2), JourneyBlocks.frozenBrick.getDefaultState());
		w.setBlockState(new BlockPos(x + 2, y + 3, z + 8), JourneyBlocks.frozenBrick.getDefaultState());
		w.setBlockState(new BlockPos(x + 2, y + 3, z + 10), JourneyBlocks.frozenBrick.getDefaultState());
		w.setBlockState(new BlockPos(x + 2, y + 4, z + 2), JourneyBlocks.frozenBrick.getDefaultState());
		w.setBlockState(new BlockPos(x + 2, y + 4, z + 8), JourneyBlocks.frozenBrick.getDefaultState());
		w.setBlockState(new BlockPos(x + 2, y + 4, z + 10), JourneyBlocks.frozenBrick.getDefaultState());
		w.setBlockState(new BlockPos(x + 2, y + 5, z + 2), JourneyBlocks.frozenBrick.getDefaultState());
		w.setBlockState(new BlockPos(x + 2, y + 5, z + 3), JourneyBlocks.frozenBrick.getDefaultState());
		w.setBlockState(new BlockPos(x + 2, y + 5, z + 4), JourneyBlocks.frozenBrick.getDefaultState());
		w.setBlockState(new BlockPos(x + 2, y + 5, z + 5), JourneyBlocks.frozenBrick.getDefaultState());
		w.setBlockState(new BlockPos(x + 2, y + 5, z + 6), JourneyBlocks.frozenBrick.getDefaultState());
		w.setBlockState(new BlockPos(x + 2, y + 5, z + 7), JourneyBlocks.frozenBrick.getDefaultState());
		w.setBlockState(new BlockPos(x + 2, y + 5, z + 8), JourneyBlocks.frozenBrick.getDefaultState());
		w.setBlockState(new BlockPos(x + 2, y + 5, z + 9), JourneyBlocks.frozenBrick.getDefaultState());
		w.setBlockState(new BlockPos(x + 2, y + 5, z + 10), JourneyBlocks.frozenBrick.getDefaultState());
		w.setBlockState(new BlockPos(x + 2, y + 6, z + 2), JourneyBlocks.frozenBrick.getDefaultState());
		w.setBlockState(new BlockPos(x + 2, y + 6, z + 3), JourneyBlocks.frozenBrick.getDefaultState());
		w.setBlockState(new BlockPos(x + 2, y + 6, z + 4), JourneyBlocks.frozenBrick.getDefaultState());
		w.setBlockState(new BlockPos(x + 2, y + 6, z + 5), JourneyBlocks.frozenBrick.getDefaultState());
		w.setBlockState(new BlockPos(x + 2, y + 6, z + 6), JourneyBlocks.frozenBrick.getDefaultState());
		w.setBlockState(new BlockPos(x + 2, y + 6, z + 7), JourneyBlocks.frozenBrick.getDefaultState());
		w.setBlockState(new BlockPos(x + 2, y + 6, z + 8), JourneyBlocks.frozenBrick.getDefaultState());
		w.setBlockState(new BlockPos(x + 2, y + 6, z + 9), JourneyBlocks.frozenBrick.getDefaultState());
		w.setBlockState(new BlockPos(x + 2, y + 6, z + 10), JourneyBlocks.frozenBrick.getDefaultState());
		w.setBlockState(new BlockPos(x + 2, y + 7, z + 0), JourneyBlocks.frozenBrick.getDefaultState());
		w.setBlockState(new BlockPos(x + 2, y + 7, z + 1), JourneyBlocks.frozenBrick.getDefaultState());
		w.setBlockState(new BlockPos(x + 2, y + 7, z + 2), JourneyBlocks.frozenBrick.getDefaultState());
		w.setBlockState(new BlockPos(x + 2, y + 7, z + 3), JourneyBlocks.frozenBrick.getDefaultState());
		w.setBlockState(new BlockPos(x + 2, y + 7, z + 4), JourneyBlocks.frozenBrick.getDefaultState());
		w.setBlockState(new BlockPos(x + 2, y + 7, z + 5), JourneyBlocks.frozenBrick.getDefaultState());
		w.setBlockState(new BlockPos(x + 2, y + 7, z + 6), JourneyBlocks.frozenBrick.getDefaultState());
		w.setBlockState(new BlockPos(x + 2, y + 7, z + 7), JourneyBlocks.frozenBrick.getDefaultState());
		w.setBlockState(new BlockPos(x + 2, y + 7, z + 8), JourneyBlocks.frozenBrick.getDefaultState());
		w.setBlockState(new BlockPos(x + 2, y + 7, z + 9), JourneyBlocks.frozenBrick.getDefaultState());
		w.setBlockState(new BlockPos(x + 2, y + 7, z + 10), JourneyBlocks.frozenBrick.getDefaultState());
		w.setBlockState(new BlockPos(x + 2, y + 7, z + 11), JourneyBlocks.frozenBrick.getDefaultState());
		w.setBlockState(new BlockPos(x + 2, y + 7, z + 12), JourneyBlocks.frozenBrick.getDefaultState());
		w.setBlockState(new BlockPos(x + 3, y + 0, z + 2), JourneyBlocks.frozenBrick.getDefaultState());
		w.setBlockState(new BlockPos(x + 3, y + 0, z + 3), JourneyBlocks.frozenPlanks.getDefaultState());
		w.setBlockState(new BlockPos(x + 3, y + 0, z + 4), JourneyBlocks.frozenPlanks.getDefaultState());
		w.setBlockState(new BlockPos(x + 3, y + 0, z + 5), JourneyBlocks.frozenPlanks.getDefaultState());
		w.setBlockState(new BlockPos(x + 3, y + 0, z + 6), JourneyBlocks.frozenPlanks.getDefaultState());
		w.setBlockState(new BlockPos(x + 3, y + 0, z + 7), JourneyBlocks.frozenPlanks.getDefaultState());
		w.setBlockState(new BlockPos(x + 3, y + 0, z + 8), JourneyBlocks.frozenPlanks.getDefaultState());
		w.setBlockState(new BlockPos(x + 3, y + 0, z + 9), JourneyBlocks.frozenPlanks.getDefaultState());
		w.setBlockState(new BlockPos(x + 3, y + 0, z + 10), JourneyBlocks.frozenBrick.getDefaultState());
		w.setBlockState(new BlockPos(x + 3, y + 1, z + 2), JourneyBlocks.frozenBrick.getDefaultState());
		w.setBlockState(new BlockPos(x + 3, y + 1, z + 9), JourneyBlocks.frozenBrick.getDefaultState());
		w.setBlockState(new BlockPos(x + 3, y + 1, z + 10), JourneyBlocks.frozenBrick.getDefaultState());
		w.setBlockState(new BlockPos(x + 3, y + 2, z + 2), JourneyBlocks.frozenBrick.getStateFromMeta(1));
		w.setBlockState(new BlockPos(x + 3, y + 2, z + 10), JourneyBlocks.frozenBrick.getStateFromMeta(1));
		w.setBlockState(new BlockPos(x + 3, y + 3, z + 2), JourneyBlocks.frozenBrick.getStateFromMeta(1));
		w.setBlockState(new BlockPos(x + 3, y + 3, z + 9), JourneyBlocks.frozenBrick.getDefaultState());
		w.setBlockState(new BlockPos(x + 3, y + 3, z + 10), JourneyBlocks.frozenBrick.getStateFromMeta(1));
		w.setBlockState(new BlockPos(x + 3, y + 4, z + 2), JourneyBlocks.frozenBrick.getDefaultState());
		w.setBlockState(new BlockPos(x + 3, y + 4, z + 9), JourneyBlocks.frozenBrick.getDefaultState());
		w.setBlockState(new BlockPos(x + 3, y + 4, z + 10), JourneyBlocks.frozenBrick.getDefaultState());
		w.setBlockState(new BlockPos(x + 3, y + 5, z + 2), JourneyBlocks.frozenBrick.getDefaultState());
		w.setBlockState(new BlockPos(x + 3, y + 5, z + 3), JourneyBlocks.frozenBrick.getDefaultState());
		w.setBlockState(new BlockPos(x + 3, y + 5, z + 4), JourneyBlocks.frozenBrick.getDefaultState());
		w.setBlockState(new BlockPos(x + 3, y + 5, z + 5), JourneyBlocks.frozenBrick.getDefaultState());
		w.setBlockState(new BlockPos(x + 3, y + 5, z + 6), JourneyBlocks.frozenBrick.getDefaultState());
		w.setBlockState(new BlockPos(x + 3, y + 5, z + 7), JourneyBlocks.frozenBrick.getDefaultState());
		w.setBlockState(new BlockPos(x + 3, y + 5, z + 8), JourneyBlocks.frozenBrick.getDefaultState());
		w.setBlockState(new BlockPos(x + 3, y + 5, z + 9), JourneyBlocks.frozenBrick.getDefaultState());
		w.setBlockState(new BlockPos(x + 3, y + 5, z + 10), JourneyBlocks.frozenBrick.getDefaultState());
		w.setBlockState(new BlockPos(x + 3, y + 6, z + 2), JourneyBlocks.frozenBrick.getDefaultState());
		w.setBlockState(new BlockPos(x + 3, y + 6, z + 3), JourneyBlocks.frozenBrick.getDefaultState());
		w.setBlockState(new BlockPos(x + 3, y + 6, z + 4), JourneyBlocks.frozenBrick.getDefaultState());
		w.setBlockState(new BlockPos(x + 3, y + 6, z + 5), JourneyBlocks.frozenBrick.getDefaultState());
		w.setBlockState(new BlockPos(x + 3, y + 6, z + 6), JourneyBlocks.frozenBrick.getDefaultState());
		w.setBlockState(new BlockPos(x + 3, y + 6, z + 7), JourneyBlocks.frozenBrick.getDefaultState());
		w.setBlockState(new BlockPos(x + 3, y + 6, z + 8), JourneyBlocks.frozenBrick.getDefaultState());
		w.setBlockState(new BlockPos(x + 3, y + 6, z + 9), JourneyBlocks.frozenBrick.getDefaultState());
		w.setBlockState(new BlockPos(x + 3, y + 6, z + 10), JourneyBlocks.frozenBrick.getDefaultState());
		w.setBlockState(new BlockPos(x + 3, y + 7, z + 2), JourneyBlocks.frozenBrick.getDefaultState());
		w.setBlockState(new BlockPos(x + 3, y + 7, z + 3), JourneyBlocks.frozenBrick.getDefaultState());
		w.setBlockState(new BlockPos(x + 3, y + 7, z + 4), JourneyBlocks.frozenBrick.getDefaultState());
		w.setBlockState(new BlockPos(x + 3, y + 7, z + 5), JourneyBlocks.frozenBrick.getDefaultState());
		w.setBlockState(new BlockPos(x + 3, y + 7, z + 6), JourneyBlocks.frozenBrick.getDefaultState());
		w.setBlockState(new BlockPos(x + 3, y + 7, z + 7), JourneyBlocks.frozenBrick.getDefaultState());
		w.setBlockState(new BlockPos(x + 3, y + 7, z + 8), JourneyBlocks.frozenBrick.getDefaultState());
		w.setBlockState(new BlockPos(x + 3, y + 7, z + 9), JourneyBlocks.frozenBrick.getDefaultState());
		w.setBlockState(new BlockPos(x + 3, y + 7, z + 10), JourneyBlocks.frozenBrick.getDefaultState());
		w.setBlockState(new BlockPos(x + 3, y + 8, z + 0), JourneyBlocks.frozenBrick.getDefaultState());
		w.setBlockState(new BlockPos(x + 3, y + 8, z + 1), JourneyBlocks.frozenBrick.getDefaultState());
		w.setBlockState(new BlockPos(x + 3, y + 8, z + 2), JourneyBlocks.frozenBrick.getDefaultState());
		w.setBlockState(new BlockPos(x + 3, y + 8, z + 3), JourneyBlocks.frozenBrick.getDefaultState());
		w.setBlockState(new BlockPos(x + 3, y + 8, z + 4), JourneyBlocks.frozenBrick.getDefaultState());
		w.setBlockState(new BlockPos(x + 3, y + 8, z + 5), JourneyBlocks.frozenBrick.getDefaultState());
		w.setBlockState(new BlockPos(x + 3, y + 8, z + 6), JourneyBlocks.frozenBrick.getDefaultState());
		w.setBlockState(new BlockPos(x + 3, y + 8, z + 7), JourneyBlocks.frozenBrick.getDefaultState());
		w.setBlockState(new BlockPos(x + 3, y + 8, z + 8), JourneyBlocks.frozenBrick.getDefaultState());
		w.setBlockState(new BlockPos(x + 3, y + 8, z + 9), JourneyBlocks.frozenBrick.getDefaultState());
		w.setBlockState(new BlockPos(x + 3, y + 8, z + 10), JourneyBlocks.frozenBrick.getDefaultState());
		w.setBlockState(new BlockPos(x + 3, y + 8, z + 11), JourneyBlocks.frozenBrick.getDefaultState());
		w.setBlockState(new BlockPos(x + 3, y + 8, z + 12), JourneyBlocks.frozenBrick.getDefaultState());
		w.setBlockState(new BlockPos(x + 4, y + 0, z + 2), JourneyBlocks.frozenBrick.getDefaultState());
		w.setBlockState(new BlockPos(x + 4, y + 0, z + 3), JourneyBlocks.frozenPlanks.getDefaultState());
		w.setBlockState(new BlockPos(x + 4, y + 0, z + 4), JourneyBlocks.frozenPlanks.getDefaultState());
		w.setBlockState(new BlockPos(x + 4, y + 0, z + 5), JourneyBlocks.frozenPlanks.getDefaultState());
		w.setBlockState(new BlockPos(x + 4, y + 0, z + 6), JourneyBlocks.frozenPlanks.getDefaultState());
		w.setBlockState(new BlockPos(x + 4, y + 0, z + 7), JourneyBlocks.frozenPlanks.getDefaultState());
		w.setBlockState(new BlockPos(x + 4, y + 0, z + 8), JourneyBlocks.frozenPlanks.getDefaultState());
		w.setBlockState(new BlockPos(x + 4, y + 0, z + 9), JourneyBlocks.frozenPlanks.getDefaultState());
		w.setBlockState(new BlockPos(x + 4, y + 0, z + 10), JourneyBlocks.frozenBrick.getDefaultState());
		w.setBlockState(new BlockPos(x + 4, y + 1, z + 2), JourneyBlocks.frozenBrick.getDefaultState());
		w.setBlockState(new BlockPos(x + 4, y + 1, z + 10), JourneyBlocks.frozenBrick.getDefaultState());
		w.setBlockState(new BlockPos(x + 4, y + 2, z + 2), Blocks.GLASS_PANE.getStateFromMeta(1));
		w.setBlockState(new BlockPos(x + 4, y + 2, z + 10), Blocks.GLASS_PANE.getStateFromMeta(1));
		w.setBlockState(new BlockPos(x + 4, y + 3, z + 2), Blocks.GLASS_PANE.getStateFromMeta(1));
		w.setBlockState(new BlockPos(x + 4, y + 3, z + 10), Blocks.GLASS_PANE.getStateFromMeta(1));
		w.setBlockState(new BlockPos(x + 4, y + 4, z + 2), JourneyBlocks.frozenBrick.getDefaultState());
		w.setBlockState(new BlockPos(x + 4, y + 4, z + 10), JourneyBlocks.frozenBrick.getDefaultState());
		w.setBlockState(new BlockPos(x + 4, y + 5, z + 2), JourneyBlocks.frozenBrick.getDefaultState());
		w.setBlockState(new BlockPos(x + 4, y + 5, z + 3), JourneyBlocks.frozenBrick.getDefaultState());
		w.setBlockState(new BlockPos(x + 4, y + 5, z + 4), JourneyBlocks.frozenBrick.getDefaultState());
		w.setBlockState(new BlockPos(x + 4, y + 5, z + 5), JourneyBlocks.frozenBrick.getDefaultState());
		w.setBlockState(new BlockPos(x + 4, y + 5, z + 6), JourneyBlocks.frozenBrick.getDefaultState());
		w.setBlockState(new BlockPos(x + 4, y + 5, z + 7), JourneyBlocks.frozenBrick.getDefaultState());
		w.setBlockState(new BlockPos(x + 4, y + 5, z + 8), JourneyBlocks.frozenBrick.getDefaultState());
		w.setBlockState(new BlockPos(x + 4, y + 5, z + 9), JourneyBlocks.frozenBrick.getDefaultState());
		w.setBlockState(new BlockPos(x + 4, y + 5, z + 10), JourneyBlocks.frozenBrick.getDefaultState());
		w.setBlockState(new BlockPos(x + 4, y + 6, z + 2), JourneyBlocks.frozenBrick.getDefaultState());
		w.setBlockState(new BlockPos(x + 4, y + 6, z + 3), JourneyBlocks.frozenBrick.getDefaultState());
		w.setBlockState(new BlockPos(x + 4, y + 6, z + 4), JourneyBlocks.frozenBrick.getDefaultState());
		w.setBlockState(new BlockPos(x + 4, y + 6, z + 5), JourneyBlocks.frozenBrick.getDefaultState());
		w.setBlockState(new BlockPos(x + 4, y + 6, z + 6), JourneyBlocks.frozenBrick.getDefaultState());
		w.setBlockState(new BlockPos(x + 4, y + 6, z + 7), JourneyBlocks.frozenBrick.getDefaultState());
		w.setBlockState(new BlockPos(x + 4, y + 6, z + 8), JourneyBlocks.frozenBrick.getDefaultState());
		w.setBlockState(new BlockPos(x + 4, y + 6, z + 9), JourneyBlocks.frozenBrick.getDefaultState());
		w.setBlockState(new BlockPos(x + 4, y + 6, z + 10), JourneyBlocks.frozenBrick.getDefaultState());
		w.setBlockState(new BlockPos(x + 4, y + 7, z + 2), JourneyBlocks.frozenBrick.getDefaultState());
		w.setBlockState(new BlockPos(x + 4, y + 7, z + 3), JourneyBlocks.frozenBrick.getDefaultState());
		w.setBlockState(new BlockPos(x + 4, y + 7, z + 4), JourneyBlocks.frozenBrick.getDefaultState());
		w.setBlockState(new BlockPos(x + 4, y + 7, z + 5), JourneyBlocks.frozenBrick.getDefaultState());
		w.setBlockState(new BlockPos(x + 4, y + 7, z + 6), JourneyBlocks.frozenBrick.getDefaultState());
		w.setBlockState(new BlockPos(x + 4, y + 7, z + 7), JourneyBlocks.frozenBrick.getDefaultState());
		w.setBlockState(new BlockPos(x + 4, y + 7, z + 8), JourneyBlocks.frozenBrick.getDefaultState());
		w.setBlockState(new BlockPos(x + 4, y + 7, z + 9), JourneyBlocks.frozenBrick.getDefaultState());
		w.setBlockState(new BlockPos(x + 4, y + 7, z + 10), JourneyBlocks.frozenBrick.getDefaultState());
		w.setBlockState(new BlockPos(x + 4, y + 8, z + 0), JourneyBlocks.frozenBrick.getDefaultState());
		w.setBlockState(new BlockPos(x + 4, y + 8, z + 1), JourneyBlocks.frozenBrick.getDefaultState());
		w.setBlockState(new BlockPos(x + 4, y + 8, z + 2), JourneyBlocks.frozenBrick.getDefaultState());
		w.setBlockState(new BlockPos(x + 4, y + 8, z + 3), JourneyBlocks.frozenBrick.getDefaultState());
		w.setBlockState(new BlockPos(x + 4, y + 8, z + 4), JourneyBlocks.frozenBrick.getDefaultState());
		w.setBlockState(new BlockPos(x + 4, y + 8, z + 5), JourneyBlocks.frozenBrick.getDefaultState());
		w.setBlockState(new BlockPos(x + 4, y + 8, z + 6), JourneyBlocks.frozenBrick.getDefaultState());
		w.setBlockState(new BlockPos(x + 4, y + 8, z + 7), JourneyBlocks.frozenBrick.getDefaultState());
		w.setBlockState(new BlockPos(x + 4, y + 8, z + 8), JourneyBlocks.frozenBrick.getDefaultState());
		w.setBlockState(new BlockPos(x + 4, y + 8, z + 9), JourneyBlocks.frozenBrick.getDefaultState());
		w.setBlockState(new BlockPos(x + 4, y + 8, z + 10), JourneyBlocks.frozenBrick.getDefaultState());
		w.setBlockState(new BlockPos(x + 4, y + 8, z + 11), JourneyBlocks.frozenBrick.getDefaultState());
		w.setBlockState(new BlockPos(x + 4, y + 8, z + 12), JourneyBlocks.frozenBrick.getDefaultState());
		w.setBlockState(new BlockPos(x + 5, y + 0, z + 2), JourneyBlocks.frozenBrick.getDefaultState());
		w.setBlockState(new BlockPos(x + 5, y + 0, z + 3), JourneyBlocks.frozenPlanks.getDefaultState());
		w.setBlockState(new BlockPos(x + 5, y + 0, z + 4), JourneyBlocks.frozenPlanks.getDefaultState());
		w.setBlockState(new BlockPos(x + 5, y + 0, z + 5), JourneyBlocks.frozenPlanks.getDefaultState());
		w.setBlockState(new BlockPos(x + 5, y + 0, z + 6), JourneyBlocks.frozenPlanks.getDefaultState());
		w.setBlockState(new BlockPos(x + 5, y + 0, z + 7), JourneyBlocks.frozenPlanks.getDefaultState());
		w.setBlockState(new BlockPos(x + 5, y + 0, z + 8), JourneyBlocks.frozenPlanks.getDefaultState());
		w.setBlockState(new BlockPos(x + 5, y + 0, z + 9), JourneyBlocks.frozenPlanks.getDefaultState());
		w.setBlockState(new BlockPos(x + 5, y + 0, z + 10), JourneyBlocks.frozenBrick.getDefaultState());
		w.setBlockState(new BlockPos(x + 5, y + 1, z + 2), JourneyBlocks.frozenBrick.getDefaultState());
		w.setBlockState(new BlockPos(x + 5, y + 1, z + 10), JourneyBlocks.frozenBrick.getDefaultState());
		w.setBlockState(new BlockPos(x + 5, y + 2, z + 2), JourneyBlocks.frozenBrick.getDefaultState());
		w.setBlockState(new BlockPos(x + 5, y + 2, z + 10), JourneyBlocks.frozenBrick.getDefaultState());
		w.setBlockState(new BlockPos(x + 5, y + 3, z + 2), JourneyBlocks.frozenBrick.getDefaultState());
		w.setBlockState(new BlockPos(x + 5, y + 3, z + 10), JourneyBlocks.frozenBrick.getDefaultState());
		w.setBlockState(new BlockPos(x + 5, y + 4, z + 2), JourneyBlocks.frozenBrick.getDefaultState());
		w.setBlockState(new BlockPos(x + 5, y + 4, z + 3), JourneyBlocks.frozenBrick.getDefaultState());
		w.setBlockState(new BlockPos(x + 5, y + 4, z + 4), JourneyBlocks.frozenBrick.getDefaultState());
		w.setBlockState(new BlockPos(x + 5, y + 4, z + 5), JourneyBlocks.frozenBrick.getDefaultState());
		w.setBlockState(new BlockPos(x + 5, y + 4, z + 6), JourneyBlocks.frozenBrick.getDefaultState());
		w.setBlockState(new BlockPos(x + 5, y + 4, z + 7), JourneyBlocks.frozenBrick.getDefaultState());
		w.setBlockState(new BlockPos(x + 5, y + 4, z + 8), JourneyBlocks.frozenBrick.getDefaultState());
		w.setBlockState(new BlockPos(x + 5, y + 4, z + 9), JourneyBlocks.frozenBrick.getDefaultState());
		w.setBlockState(new BlockPos(x + 5, y + 4, z + 10), JourneyBlocks.frozenBrick.getDefaultState());
		w.setBlockState(new BlockPos(x + 5, y + 5, z + 2), JourneyBlocks.frozenBrick.getDefaultState());
		w.setBlockState(new BlockPos(x + 5, y + 5, z + 3), JourneyBlocks.frozenBrick.getDefaultState());
		w.setBlockState(new BlockPos(x + 5, y + 5, z + 4), JourneyBlocks.frozenBrick.getDefaultState());
		w.setBlockState(new BlockPos(x + 5, y + 5, z + 5), JourneyBlocks.frozenBrick.getDefaultState());
		w.setBlockState(new BlockPos(x + 5, y + 5, z + 6), JourneyBlocks.frozenBrick.getDefaultState());
		w.setBlockState(new BlockPos(x + 5, y + 5, z + 7), JourneyBlocks.frozenBrick.getDefaultState());
		w.setBlockState(new BlockPos(x + 5, y + 5, z + 8), JourneyBlocks.frozenBrick.getDefaultState());
		w.setBlockState(new BlockPos(x + 5, y + 5, z + 9), JourneyBlocks.frozenBrick.getDefaultState());
		w.setBlockState(new BlockPos(x + 5, y + 5, z + 10), JourneyBlocks.frozenBrick.getDefaultState());
		w.setBlockState(new BlockPos(x + 5, y + 6, z + 2), JourneyBlocks.frozenBrick.getDefaultState());
		w.setBlockState(new BlockPos(x + 5, y + 6, z + 3), JourneyBlocks.frozenBrick.getDefaultState());
		w.setBlockState(new BlockPos(x + 5, y + 6, z + 4), JourneyBlocks.frozenBrick.getDefaultState());
		w.setBlockState(new BlockPos(x + 5, y + 6, z + 5), JourneyBlocks.frozenBrick.getDefaultState());
		w.setBlockState(new BlockPos(x + 5, y + 6, z + 6), JourneyBlocks.frozenBrick.getDefaultState());
		w.setBlockState(new BlockPos(x + 5, y + 6, z + 7), JourneyBlocks.frozenBrick.getDefaultState());
		w.setBlockState(new BlockPos(x + 5, y + 6, z + 8), JourneyBlocks.frozenBrick.getDefaultState());
		w.setBlockState(new BlockPos(x + 5, y + 6, z + 9), JourneyBlocks.frozenBrick.getDefaultState());
		w.setBlockState(new BlockPos(x + 5, y + 6, z + 10), JourneyBlocks.frozenBrick.getDefaultState());
		w.setBlockState(new BlockPos(x + 5, y + 7, z + 0), JourneyBlocks.frozenBrick.getDefaultState());
		w.setBlockState(new BlockPos(x + 5, y + 7, z + 1), JourneyBlocks.frozenBrick.getDefaultState());
		w.setBlockState(new BlockPos(x + 5, y + 7, z + 2), JourneyBlocks.frozenBrick.getDefaultState());
		w.setBlockState(new BlockPos(x + 5, y + 7, z + 3), JourneyBlocks.frozenBrick.getDefaultState());
		w.setBlockState(new BlockPos(x + 5, y + 7, z + 4), JourneyBlocks.frozenBrick.getDefaultState());
		w.setBlockState(new BlockPos(x + 5, y + 7, z + 5), JourneyBlocks.frozenBrick.getDefaultState());
		w.setBlockState(new BlockPos(x + 5, y + 7, z + 6), JourneyBlocks.frozenBrick.getDefaultState());
		w.setBlockState(new BlockPos(x + 5, y + 7, z + 7), JourneyBlocks.frozenBrick.getDefaultState());
		w.setBlockState(new BlockPos(x + 5, y + 7, z + 8), JourneyBlocks.frozenBrick.getDefaultState());
		w.setBlockState(new BlockPos(x + 5, y + 7, z + 9), JourneyBlocks.frozenBrick.getDefaultState());
		w.setBlockState(new BlockPos(x + 5, y + 7, z + 10), JourneyBlocks.frozenBrick.getDefaultState());
		w.setBlockState(new BlockPos(x + 5, y + 7, z + 11), JourneyBlocks.frozenBrick.getDefaultState());
		w.setBlockState(new BlockPos(x + 5, y + 7, z + 12), JourneyBlocks.frozenBrick.getDefaultState());
		w.setBlockState(new BlockPos(x + 6, y + 0, z + 2), JourneyBlocks.frozenBrick.getDefaultState());
		w.setBlockState(new BlockPos(x + 6, y + 0, z + 3), JourneyBlocks.frozenPlanks.getDefaultState());
		w.setBlockState(new BlockPos(x + 6, y + 0, z + 4), JourneyBlocks.frozenBrick.getDefaultState());
		w.setBlockState(new BlockPos(x + 6, y + 0, z + 5), JourneyBlocks.frozenBrick.getDefaultState());
		w.setBlockState(new BlockPos(x + 6, y + 0, z + 6), JourneyBlocks.frozenBrick.getDefaultState());
		w.setBlockState(new BlockPos(x + 6, y + 0, z + 7), JourneyBlocks.frozenBrick.getDefaultState());
		w.setBlockState(new BlockPos(x + 6, y + 0, z + 8), JourneyBlocks.frozenBrick.getDefaultState());
		w.setBlockState(new BlockPos(x + 6, y + 0, z + 9), JourneyBlocks.frozenBrick.getDefaultState());
		w.setBlockState(new BlockPos(x + 6, y + 0, z + 10), JourneyBlocks.frozenBrick.getDefaultState());
		w.setBlockState(new BlockPos(x + 6, y + 1, z + 2), JourneyBlocks.frozenBrick.getDefaultState());
		w.setBlockState(new BlockPos(x + 6, y + 1, z + 4), JourneyBlocks.frozenBrick.getDefaultState());
		w.setBlockState(new BlockPos(x + 6, y + 1, z + 5), JourneyBlocks.frozenBrick.getDefaultState());
		w.setBlockState(new BlockPos(x + 6, y + 1, z + 6), JourneyBlocks.frozenBrick.getDefaultState());
		w.setBlockState(new BlockPos(x + 6, y + 1, z + 7), JourneyBlocks.frozenBrick.getDefaultState());
		w.setBlockState(new BlockPos(x + 6, y + 1, z + 8), JourneyBlocks.frozenBrick.getDefaultState());
		w.setBlockState(new BlockPos(x + 6, y + 1, z + 9), JourneyBlocks.frozenBrick.getDefaultState());
		w.setBlockState(new BlockPos(x + 6, y + 1, z + 10), JourneyBlocks.frozenBrick.getDefaultState());
		w.setBlockState(new BlockPos(x + 6, y + 2, z + 2), JourneyBlocks.frozenBrick.getDefaultState());
		w.setBlockState(new BlockPos(x + 6, y + 2, z + 4), JourneyBlocks.frozenBrick.getDefaultState());
		w.setBlockState(new BlockPos(x + 6, y + 2, z + 5), JourneyBlocks.frozenBrick.getDefaultState());
		w.setBlockState(new BlockPos(x + 6, y + 2, z + 6), Blocks.GLASS_PANE.getStateFromMeta(1));
		w.setBlockState(new BlockPos(x + 6, y + 2, z + 7), Blocks.GLASS_PANE.getStateFromMeta(1));
		w.setBlockState(new BlockPos(x + 6, y + 2, z + 8), Blocks.GLASS_PANE.getStateFromMeta(1));
		w.setBlockState(new BlockPos(x + 6, y + 2, z + 9), JourneyBlocks.frozenBrick.getDefaultState());
		w.setBlockState(new BlockPos(x + 6, y + 2, z + 10), JourneyBlocks.frozenBrick.getDefaultState());
		w.setBlockState(new BlockPos(x + 6, y + 3, z + 2), JourneyBlocks.frozenBrick.getDefaultState());
		w.setBlockState(new BlockPos(x + 6, y + 3, z + 3), JourneyBlocks.frozenBrick.getDefaultState());
		w.setBlockState(new BlockPos(x + 6, y + 3, z + 4), JourneyBlocks.frozenBrick.getDefaultState());
		w.setBlockState(new BlockPos(x + 6, y + 3, z + 5), JourneyBlocks.frozenBrick.getDefaultState());
		w.setBlockState(new BlockPos(x + 6, y + 3, z + 6), Blocks.GLASS_PANE.getStateFromMeta(1));
		w.setBlockState(new BlockPos(x + 6, y + 3, z + 7), Blocks.GLASS_PANE.getStateFromMeta(1));
		w.setBlockState(new BlockPos(x + 6, y + 3, z + 8), Blocks.GLASS_PANE.getStateFromMeta(1));
		w.setBlockState(new BlockPos(x + 6, y + 3, z + 9), JourneyBlocks.frozenBrick.getDefaultState());
		w.setBlockState(new BlockPos(x + 6, y + 3, z + 10), JourneyBlocks.frozenBrick.getDefaultState());
		w.setBlockState(new BlockPos(x + 6, y + 4, z + 2), JourneyBlocks.frozenBrick.getDefaultState());
		w.setBlockState(new BlockPos(x + 6, y + 4, z + 3), JourneyBlocks.frozenBrick.getDefaultState());
		w.setBlockState(new BlockPos(x + 6, y + 4, z + 4), JourneyBlocks.frozenBrick.getDefaultState());
		w.setBlockState(new BlockPos(x + 6, y + 4, z + 5), JourneyBlocks.frozenBrick.getDefaultState());
		w.setBlockState(new BlockPos(x + 6, y + 4, z + 6), JourneyBlocks.frozenBrick.getDefaultState());
		w.setBlockState(new BlockPos(x + 6, y + 4, z + 7), JourneyBlocks.frozenBrick.getDefaultState());
		w.setBlockState(new BlockPos(x + 6, y + 4, z + 8), JourneyBlocks.frozenBrick.getDefaultState());
		w.setBlockState(new BlockPos(x + 6, y + 4, z + 9), JourneyBlocks.frozenBrick.getDefaultState());
		w.setBlockState(new BlockPos(x + 6, y + 4, z + 10), JourneyBlocks.frozenBrick.getDefaultState());
		w.setBlockState(new BlockPos(x + 6, y + 5, z + 2), JourneyBlocks.frozenBrick.getDefaultState());
		w.setBlockState(new BlockPos(x + 6, y + 5, z + 3), JourneyBlocks.frozenBrick.getDefaultState());
		w.setBlockState(new BlockPos(x + 6, y + 5, z + 4), JourneyBlocks.frozenBrick.getDefaultState());
		w.setBlockState(new BlockPos(x + 6, y + 5, z + 5), JourneyBlocks.frozenBrick.getDefaultState());
		w.setBlockState(new BlockPos(x + 6, y + 5, z + 6), JourneyBlocks.frozenBrick.getDefaultState());
		w.setBlockState(new BlockPos(x + 6, y + 5, z + 7), JourneyBlocks.frozenBrick.getDefaultState());
		w.setBlockState(new BlockPos(x + 6, y + 5, z + 8), JourneyBlocks.frozenBrick.getDefaultState());
		w.setBlockState(new BlockPos(x + 6, y + 5, z + 9), JourneyBlocks.frozenBrick.getDefaultState());
		w.setBlockState(new BlockPos(x + 6, y + 5, z + 10), JourneyBlocks.frozenBrick.getDefaultState());
		w.setBlockState(new BlockPos(x + 6, y + 6, z + 1), JourneyBlocks.frozenBrick.getDefaultState());
		w.setBlockState(new BlockPos(x + 6, y + 6, z + 2), JourneyBlocks.frozenBrick.getDefaultState());
		w.setBlockState(new BlockPos(x + 6, y + 6, z + 3), JourneyBlocks.frozenBrick.getDefaultState());
		w.setBlockState(new BlockPos(x + 6, y + 6, z + 4), JourneyBlocks.frozenBrick.getDefaultState());
		w.setBlockState(new BlockPos(x + 6, y + 6, z + 5), JourneyBlocks.frozenBrick.getDefaultState());
		w.setBlockState(new BlockPos(x + 6, y + 6, z + 6), JourneyBlocks.frozenBrick.getDefaultState());
		w.setBlockState(new BlockPos(x + 6, y + 6, z + 7), JourneyBlocks.frozenBrick.getDefaultState());
		w.setBlockState(new BlockPos(x + 6, y + 6, z + 8), JourneyBlocks.frozenBrick.getDefaultState());
		w.setBlockState(new BlockPos(x + 6, y + 6, z + 9), JourneyBlocks.frozenBrick.getDefaultState());
		w.setBlockState(new BlockPos(x + 6, y + 6, z + 10), JourneyBlocks.frozenBrick.getDefaultState());
		w.setBlockState(new BlockPos(x + 6, y + 6, z + 11), JourneyBlocks.frozenBrick.getDefaultState());
		w.setBlockState(new BlockPos(x + 7, y + 5, z + 1), JourneyBlocks.frozenBrick.getDefaultState());
		w.setBlockState(new BlockPos(x + 7, y + 5, z + 2), JourneyBlocks.frozenBrick.getDefaultState());
		w.setBlockState(new BlockPos(x + 7, y + 5, z + 3), JourneyBlocks.frozenBrick.getDefaultState());
		w.setBlockState(new BlockPos(x + 7, y + 5, z + 4), JourneyBlocks.frozenBrick.getDefaultState());
		w.setBlockState(new BlockPos(x + 7, y + 5, z + 5), JourneyBlocks.frozenBrick.getDefaultState());
		w.setBlockState(new BlockPos(x + 7, y + 5, z + 6), JourneyBlocks.frozenBrick.getDefaultState());
		w.setBlockState(new BlockPos(x + 7, y + 5, z + 7), JourneyBlocks.frozenBrick.getDefaultState());
		w.setBlockState(new BlockPos(x + 7, y + 5, z + 8), JourneyBlocks.frozenBrick.getDefaultState());
		w.setBlockState(new BlockPos(x + 7, y + 5, z + 9), JourneyBlocks.frozenBrick.getDefaultState());
		w.setBlockState(new BlockPos(x + 7, y + 5, z + 10), JourneyBlocks.frozenBrick.getDefaultState());
		w.setBlockState(new BlockPos(x + 7, y + 5, z + 11), JourneyBlocks.frozenBrick.getDefaultState());

		if(!w.isRemote) {
			EntityFrozenMerchant smith = new EntityFrozenMerchant(w);
			smith.setLocationAndAngles(x + 4, y + 2, z + 4, 0.0F, 0.0F);
			w.spawnEntity(smith);
		}
		return false;
	}
}