package net.journey.dimension.frozen.gen;
import java.util.Random;

import net.journey.JourneyBlocks;
import net.minecraft.init.Blocks;
import net.minecraft.world.World;
import net.minecraft.world.gen.feature.WorldGenerator;

public class WorldGenIceCrystal2 extends WorldGenerator {

	public boolean generate(World world, Random rand, BlockPos pos) {
		int i = pos.getX(), j = pos.getY(), k = pos.getZ();
		world.setBlockState(new BlockPos(i + 0, j + 0, k + 3), JourneyBlocks.iceLeaves.getDefaultState());
		world.setBlockState(new BlockPos(i + 0, j + 1, k + 3), JourneyBlocks.iceLeaves.getDefaultState());
		world.setBlockState(new BlockPos(i + 0, j + 2, k + 3), JourneyBlocks.iceLeaves.getDefaultState());
		world.setBlockState(new BlockPos(i + 1, j + 0, k + 1), JourneyBlocks.iceLeaves.getDefaultState());
		world.setBlockState(new BlockPos(i + 1, j + 0, k + 2), JourneyBlocks.iceLeaves.getDefaultState());
		world.setBlockState(new BlockPos(i + 1, j + 0, k + 3), JourneyBlocks.iceLeaves.getDefaultState());
		world.setBlockState(new BlockPos(i + 1, j + 0, k + 4), JourneyBlocks.iceLeaves.getDefaultState());
		world.setBlockState(new BlockPos(i + 1, j + 1, k + 2), JourneyBlocks.iceLeaves.getDefaultState());
		world.setBlockState(new BlockPos(i + 1, j + 1, k + 3), JourneyBlocks.iceLeaves.getDefaultState());
		world.setBlockState(new BlockPos(i + 1, j + 1, k + 4), JourneyBlocks.iceLeaves.getDefaultState());
		world.setBlockState(new BlockPos(i + 1, j + 2, k + 2), JourneyBlocks.iceLeaves.getDefaultState());
		world.setBlockState(new BlockPos(i + 1, j + 2, k + 3), JourneyBlocks.iceLeaves.getDefaultState());
		world.setBlockState(new BlockPos(i + 1, j + 2, k + 4), JourneyBlocks.iceLeaves.getDefaultState());
		world.setBlockState(new BlockPos(i + 1, j + 3, k + 2), JourneyBlocks.iceLeaves.getDefaultState());
		world.setBlockState(new BlockPos(i + 1, j + 3, k + 3), JourneyBlocks.iceLeaves.getDefaultState());
		world.setBlockState(new BlockPos(i + 1, j + 3, k + 4), JourneyBlocks.iceLeaves.getDefaultState());
		world.setBlockState(new BlockPos(i + 1, j + 4, k + 2), JourneyBlocks.iceLeaves.getDefaultState());
		world.setBlockState(new BlockPos(i + 1, j + 4, k + 3), JourneyBlocks.iceLeaves.getDefaultState());
		world.setBlockState(new BlockPos(i + 1, j + 5, k + 2), JourneyBlocks.iceLeaves.getDefaultState());
		world.setBlockState(new BlockPos(i + 1, j + 6, k + 2), JourneyBlocks.iceLeaves.getDefaultState());
		world.setBlockState(new BlockPos(i + 2, j + 0, k + 0), JourneyBlocks.iceLeaves.getDefaultState());
		world.setBlockState(new BlockPos(i + 2, j + 0, k + 1), JourneyBlocks.iceLeaves.getDefaultState());
		world.setBlockState(new BlockPos(i + 2, j + 0, k + 2), JourneyBlocks.iceLeaves.getDefaultState());
		world.setBlockState(new BlockPos(i + 2, j + 0, k + 3), JourneyBlocks.iceLeaves.getDefaultState());
		world.setBlockState(new BlockPos(i + 2, j + 0, k + 4), JourneyBlocks.iceLeaves.getDefaultState());
		world.setBlockState(new BlockPos(i + 2, j + 0, k + 5), JourneyBlocks.iceLeaves.getDefaultState());
		world.setBlockState(new BlockPos(i + 2, j + 1, k + 0), JourneyBlocks.iceLeaves.getDefaultState());
		world.setBlockState(new BlockPos(i + 2, j + 1, k + 1), JourneyBlocks.iceLeaves.getDefaultState());
		world.setBlockState(new BlockPos(i + 2, j + 1, k + 2), JourneyBlocks.iceLeaves.getDefaultState());
		world.setBlockState(new BlockPos(i + 2, j + 1, k + 3), JourneyBlocks.iceLeaves.getDefaultState());
		world.setBlockState(new BlockPos(i + 2, j + 1, k + 4), JourneyBlocks.iceLeaves.getDefaultState());
		world.setBlockState(new BlockPos(i + 2, j + 1, k + 5), JourneyBlocks.iceLeaves.getDefaultState());
		world.setBlockState(new BlockPos(i + 2, j + 2, k + 1), JourneyBlocks.iceLeaves.getDefaultState());
		world.setBlockState(new BlockPos(i + 2, j + 2, k + 2), JourneyBlocks.iceLeaves.getDefaultState());
		world.setBlockState(new BlockPos(i + 2, j + 2, k + 3), JourneyBlocks.iceLeaves.getDefaultState());
		world.setBlockState(new BlockPos(i + 2, j + 2, k + 4), JourneyBlocks.iceLeaves.getDefaultState());
		world.setBlockState(new BlockPos(i + 2, j + 2, k + 5), JourneyBlocks.iceLeaves.getDefaultState());
		world.setBlockState(new BlockPos(i + 2, j + 3, k + 1), JourneyBlocks.iceLeaves.getDefaultState());
		world.setBlockState(new BlockPos(i + 2, j + 3, k + 2), JourneyBlocks.iceLeaves.getDefaultState());
		world.setBlockState(new BlockPos(i + 2, j + 3, k + 3), JourneyBlocks.iceLeaves.getDefaultState());
		world.setBlockState(new BlockPos(i + 2, j + 3, k + 4), JourneyBlocks.iceLeaves.getDefaultState());
		world.setBlockState(new BlockPos(i + 2, j + 4, k + 1), JourneyBlocks.iceLeaves.getDefaultState());
		world.setBlockState(new BlockPos(i + 2, j + 4, k + 2), JourneyBlocks.iceLeaves.getDefaultState());
		world.setBlockState(new BlockPos(i + 2, j + 4, k + 3), JourneyBlocks.iceLeaves.getDefaultState());
		world.setBlockState(new BlockPos(i + 2, j + 4, k + 4), JourneyBlocks.iceLeaves.getDefaultState());
		world.setBlockState(new BlockPos(i + 2, j + 5, k + 1), JourneyBlocks.iceLeaves.getDefaultState());
		world.setBlockState(new BlockPos(i + 2, j + 5, k + 2), JourneyBlocks.iceLeaves.getDefaultState());
		world.setBlockState(new BlockPos(i + 2, j + 5, k + 3), JourneyBlocks.iceLeaves.getDefaultState());
		world.setBlockState(new BlockPos(i + 2, j + 5, k + 4), JourneyBlocks.iceLeaves.getDefaultState());
		world.setBlockState(new BlockPos(i + 2, j + 6, k + 1), JourneyBlocks.iceLeaves.getDefaultState());
		world.setBlockState(new BlockPos(i + 2, j + 6, k + 2), JourneyBlocks.iceLeaves.getDefaultState());
		world.setBlockState(new BlockPos(i + 2, j + 6, k + 3), JourneyBlocks.iceLeaves.getDefaultState());
		world.setBlockState(new BlockPos(i + 2, j + 7, k + 1), JourneyBlocks.iceLeaves.getDefaultState());
		world.setBlockState(new BlockPos(i + 2, j + 7, k + 2), JourneyBlocks.iceLeaves.getDefaultState());
		world.setBlockState(new BlockPos(i + 2, j + 8, k + 1), JourneyBlocks.iceLeaves.getDefaultState());
		world.setBlockState(new BlockPos(i + 2, j + 9, k + 1), JourneyBlocks.iceLeaves.getDefaultState());
		world.setBlockState(new BlockPos(i + 2, j + 10, k + 1), JourneyBlocks.iceLeaves.getDefaultState());
		world.setBlockState(new BlockPos(i + 3, j + 0, k + 0), JourneyBlocks.iceLeaves.getDefaultState());
		world.setBlockState(new BlockPos(i + 3, j + 0, k + 1), JourneyBlocks.iceLeaves.getDefaultState());
		world.setBlockState(new BlockPos(i + 3, j + 0, k + 2), JourneyBlocks.iceLeaves.getDefaultState());
		world.setBlockState(new BlockPos(i + 3, j + 0, k + 3), JourneyBlocks.iceLeaves.getDefaultState());
		world.setBlockState(new BlockPos(i + 3, j + 0, k + 4), JourneyBlocks.iceLeaves.getDefaultState());
		world.setBlockState(new BlockPos(i + 3, j + 0, k + 5), JourneyBlocks.iceLeaves.getDefaultState());
		world.setBlockState(new BlockPos(i + 3, j + 1, k + 0), JourneyBlocks.iceLeaves.getDefaultState());
		world.setBlockState(new BlockPos(i + 3, j + 1, k + 1), JourneyBlocks.iceLeaves.getDefaultState());
		world.setBlockState(new BlockPos(i + 3, j + 1, k + 2), JourneyBlocks.iceLeaves.getDefaultState());
		world.setBlockState(new BlockPos(i + 3, j + 1, k + 3), JourneyBlocks.iceLeaves.getDefaultState());
		world.setBlockState(new BlockPos(i + 3, j + 1, k + 4), JourneyBlocks.iceLeaves.getDefaultState());
		world.setBlockState(new BlockPos(i + 3, j + 1, k + 5), JourneyBlocks.iceLeaves.getDefaultState());
		world.setBlockState(new BlockPos(i + 3, j + 2, k + 0), JourneyBlocks.iceLeaves.getDefaultState());
		world.setBlockState(new BlockPos(i + 3, j + 2, k + 1), JourneyBlocks.iceLeaves.getDefaultState());
		world.setBlockState(new BlockPos(i + 3, j + 2, k + 2), JourneyBlocks.iceLeaves.getDefaultState());
		world.setBlockState(new BlockPos(i + 3, j + 2, k + 3), JourneyBlocks.iceLeaves.getDefaultState());
		world.setBlockState(new BlockPos(i + 3, j + 2, k + 4), JourneyBlocks.iceLeaves.getDefaultState());
		world.setBlockState(new BlockPos(i + 3, j + 2, k + 5), JourneyBlocks.iceLeaves.getDefaultState());
		world.setBlockState(new BlockPos(i + 3, j + 3, k + 0), JourneyBlocks.iceLeaves.getDefaultState());
		world.setBlockState(new BlockPos(i + 3, j + 3, k + 1), JourneyBlocks.iceLeaves.getDefaultState());
		world.setBlockState(new BlockPos(i + 3, j + 3, k + 2), JourneyBlocks.iceLeaves.getDefaultState());
		world.setBlockState(new BlockPos(i + 3, j + 3, k + 3), JourneyBlocks.iceLeaves.getDefaultState());
		world.setBlockState(new BlockPos(i + 3, j + 3, k + 4), JourneyBlocks.iceLeaves.getDefaultState());
		world.setBlockState(new BlockPos(i + 3, j + 3, k + 5), JourneyBlocks.iceLeaves.getDefaultState());
		world.setBlockState(new BlockPos(i + 3, j + 4, k + 1), JourneyBlocks.iceLeaves.getDefaultState());
		world.setBlockState(new BlockPos(i + 3, j + 4, k + 2), JourneyBlocks.iceLeaves.getDefaultState());
		world.setBlockState(new BlockPos(i + 3, j + 4, k + 3), JourneyBlocks.iceLeaves.getDefaultState());
		world.setBlockState(new BlockPos(i + 3, j + 4, k + 4), JourneyBlocks.iceLeaves.getDefaultState());
		world.setBlockState(new BlockPos(i + 3, j + 5, k + 1), JourneyBlocks.iceLeaves.getDefaultState());
		world.setBlockState(new BlockPos(i + 3, j + 5, k + 2), JourneyBlocks.iceLeaves.getDefaultState());
		world.setBlockState(new BlockPos(i + 3, j + 5, k + 3), JourneyBlocks.iceLeaves.getDefaultState());
		world.setBlockState(new BlockPos(i + 3, j + 5, k + 4), JourneyBlocks.iceLeaves.getDefaultState());
		world.setBlockState(new BlockPos(i + 3, j + 6, k + 1), JourneyBlocks.iceLeaves.getDefaultState());
		world.setBlockState(new BlockPos(i + 3, j + 6, k + 2), JourneyBlocks.iceLeaves.getDefaultState());
		world.setBlockState(new BlockPos(i + 3, j + 6, k + 3), JourneyBlocks.iceLeaves.getDefaultState());
		world.setBlockState(new BlockPos(i + 3, j + 6, k + 4), JourneyBlocks.iceLeaves.getDefaultState());
		world.setBlockState(new BlockPos(i + 3, j + 7, k + 1), JourneyBlocks.iceLeaves.getDefaultState());
		world.setBlockState(new BlockPos(i + 3, j + 7, k + 2), JourneyBlocks.iceLeaves.getDefaultState());
		world.setBlockState(new BlockPos(i + 3, j + 7, k + 3), JourneyBlocks.iceLeaves.getDefaultState());
		world.setBlockState(new BlockPos(i + 3, j + 8, k + 2), JourneyBlocks.iceLeaves.getDefaultState());
		world.setBlockState(new BlockPos(i + 3, j + 8, k + 3), JourneyBlocks.iceLeaves.getDefaultState());
		world.setBlockState(new BlockPos(i + 3, j + 9, k + 2), JourneyBlocks.iceLeaves.getDefaultState());
		world.setBlockState(new BlockPos(i + 3, j + 10, k + 2), JourneyBlocks.iceLeaves.getDefaultState());
		world.setBlockState(new BlockPos(i + 3, j + 11, k + 2), JourneyBlocks.iceLeaves.getDefaultState());
		world.setBlockState(new BlockPos(i + 3, j + 12, k + 2), JourneyBlocks.iceLeaves.getDefaultState());
		world.setBlockState(new BlockPos(i + 4, j + 0, k + 0), JourneyBlocks.iceLeaves.getDefaultState());
		world.setBlockState(new BlockPos(i + 4, j + 0, k + 1), JourneyBlocks.iceLeaves.getDefaultState());
		world.setBlockState(new BlockPos(i + 4, j + 0, k + 2), JourneyBlocks.iceLeaves.getDefaultState());
		world.setBlockState(new BlockPos(i + 4, j + 0, k + 3), JourneyBlocks.iceLeaves.getDefaultState());
		world.setBlockState(new BlockPos(i + 4, j + 0, k + 4), JourneyBlocks.iceLeaves.getDefaultState());
		world.setBlockState(new BlockPos(i + 4, j + 0, k + 5), JourneyBlocks.iceLeaves.getDefaultState());
		world.setBlockState(new BlockPos(i + 4, j + 1, k + 0), JourneyBlocks.iceLeaves.getDefaultState());
		world.setBlockState(new BlockPos(i + 4, j + 1, k + 1), JourneyBlocks.iceLeaves.getDefaultState());
		world.setBlockState(new BlockPos(i + 4, j + 1, k + 2), JourneyBlocks.iceLeaves.getDefaultState());
		world.setBlockState(new BlockPos(i + 4, j + 1, k + 3), JourneyBlocks.iceLeaves.getDefaultState());
		world.setBlockState(new BlockPos(i + 4, j + 1, k + 4), JourneyBlocks.iceLeaves.getDefaultState());
		world.setBlockState(new BlockPos(i + 4, j + 1, k + 5), JourneyBlocks.iceLeaves.getDefaultState());
		world.setBlockState(new BlockPos(i + 4, j + 2, k + 0), JourneyBlocks.iceLeaves.getDefaultState());
		world.setBlockState(new BlockPos(i + 4, j + 2, k + 1), JourneyBlocks.iceLeaves.getDefaultState());
		world.setBlockState(new BlockPos(i + 4, j + 2, k + 2), JourneyBlocks.iceLeaves.getDefaultState());
		world.setBlockState(new BlockPos(i + 4, j + 2, k + 3), JourneyBlocks.iceLeaves.getDefaultState());
		world.setBlockState(new BlockPos(i + 4, j + 2, k + 4), JourneyBlocks.iceLeaves.getDefaultState());
		world.setBlockState(new BlockPos(i + 4, j + 3, k + 1), JourneyBlocks.iceLeaves.getDefaultState());
		world.setBlockState(new BlockPos(i + 4, j + 3, k + 2), JourneyBlocks.iceLeaves.getDefaultState());
		world.setBlockState(new BlockPos(i + 4, j + 3, k + 3), JourneyBlocks.iceLeaves.getDefaultState());
		world.setBlockState(new BlockPos(i + 4, j + 3, k + 4), JourneyBlocks.iceLeaves.getDefaultState());
		world.setBlockState(new BlockPos(i + 4, j + 4, k + 1), JourneyBlocks.iceLeaves.getDefaultState());
		world.setBlockState(new BlockPos(i + 4, j + 4, k + 2), JourneyBlocks.iceLeaves.getDefaultState());
		world.setBlockState(new BlockPos(i + 4, j + 4, k + 3), JourneyBlocks.iceLeaves.getDefaultState());
		world.setBlockState(new BlockPos(i + 4, j + 4, k + 4), JourneyBlocks.iceLeaves.getDefaultState());
		world.setBlockState(new BlockPos(i + 4, j + 5, k + 1), JourneyBlocks.iceLeaves.getDefaultState());
		world.setBlockState(new BlockPos(i + 4, j + 5, k + 2), JourneyBlocks.iceLeaves.getDefaultState());
		world.setBlockState(new BlockPos(i + 4, j + 5, k + 3), JourneyBlocks.iceLeaves.getDefaultState());
		world.setBlockState(new BlockPos(i + 4, j + 5, k + 4), JourneyBlocks.iceLeaves.getDefaultState());
		world.setBlockState(new BlockPos(i + 4, j + 6, k + 1), JourneyBlocks.iceLeaves.getDefaultState());
		world.setBlockState(new BlockPos(i + 4, j + 6, k + 2), JourneyBlocks.iceLeaves.getDefaultState());
		world.setBlockState(new BlockPos(i + 4, j + 6, k + 3), JourneyBlocks.iceLeaves.getDefaultState());
		world.setBlockState(new BlockPos(i + 4, j + 7, k + 1), JourneyBlocks.iceLeaves.getDefaultState());
		world.setBlockState(new BlockPos(i + 4, j + 7, k + 2), JourneyBlocks.iceLeaves.getDefaultState());
		world.setBlockState(new BlockPos(i + 4, j + 7, k + 3), JourneyBlocks.iceLeaves.getDefaultState());
		world.setBlockState(new BlockPos(i + 4, j + 8, k + 1), JourneyBlocks.iceLeaves.getDefaultState());
		world.setBlockState(new BlockPos(i + 4, j + 8, k + 2), JourneyBlocks.iceLeaves.getDefaultState());
		world.setBlockState(new BlockPos(i + 4, j + 8, k + 3), JourneyBlocks.iceLeaves.getDefaultState());
		world.setBlockState(new BlockPos(i + 4, j + 9, k + 2), JourneyBlocks.iceLeaves.getDefaultState());
		world.setBlockState(new BlockPos(i + 5, j + 0, k + 1), JourneyBlocks.iceLeaves.getDefaultState());
		world.setBlockState(new BlockPos(i + 5, j + 0, k + 2), JourneyBlocks.iceLeaves.getDefaultState());
		world.setBlockState(new BlockPos(i + 5, j + 0, k + 3), JourneyBlocks.iceLeaves.getDefaultState());
		world.setBlockState(new BlockPos(i + 5, j + 1, k + 1), JourneyBlocks.iceLeaves.getDefaultState());
		world.setBlockState(new BlockPos(i + 5, j + 1, k + 2), JourneyBlocks.iceLeaves.getDefaultState());
		world.setBlockState(new BlockPos(i + 5, j + 1, k + 3), JourneyBlocks.iceLeaves.getDefaultState());
		world.setBlockState(new BlockPos(i + 5, j + 2, k + 1), JourneyBlocks.iceLeaves.getDefaultState());
		world.setBlockState(new BlockPos(i + 5, j + 2, k + 2), JourneyBlocks.iceLeaves.getDefaultState());
		world.setBlockState(new BlockPos(i + 5, j + 2, k + 3), JourneyBlocks.iceLeaves.getDefaultState());
		world.setBlockState(new BlockPos(i + 5, j + 3, k + 1), JourneyBlocks.iceLeaves.getDefaultState());
		world.setBlockState(new BlockPos(i + 5, j + 3, k + 2), JourneyBlocks.iceLeaves.getDefaultState());
		world.setBlockState(new BlockPos(i + 5, j + 3, k + 3), JourneyBlocks.iceLeaves.getDefaultState());
		world.setBlockState(new BlockPos(i + 5, j + 4, k + 2), JourneyBlocks.iceLeaves.getDefaultState());
		world.setBlockState(new BlockPos(i + 5, j + 4, k + 3), JourneyBlocks.iceLeaves.getDefaultState());
		world.setBlockState(new BlockPos(i + 5, j + 5, k + 2), JourneyBlocks.iceLeaves.getDefaultState());
		world.setBlockState(new BlockPos(i + 5, j + 6, k + 2), JourneyBlocks.iceLeaves.getDefaultState());

		return true;
	}
}