/*
*** MADE BY MITHION'S .SCHEMATIC TO JAVA CONVERTING TOOL v1.6 ***
*/

package net.journey.dimension.wither.gen.trees;
import java.util.Random;

import net.journey.JourneyBlocks;
import net.minecraft.world.World;
import net.minecraft.world.gen.feature.WorldGenerator;

public class WorldGenWithanTree2 extends WorldGenerator {
	
	public WorldGenWithanTree2() { }

	@Override
	public boolean generate(World world, Random rand, BlockPos pos) {
		int i = pos.getX();
		int j = pos.getY();
		int k = pos.getZ();
		world.setBlockState(new BlockPos(i + 0, j + 3, k + 4), JourneyBlocks.withanLeaves.getDefaultState());
		world.setBlockState(new BlockPos(i + 0, j + 3, k + 5), JourneyBlocks.withanLeaves.getDefaultState());
		world.setBlockState(new BlockPos(i + 1, j + 1, k + 2), JourneyBlocks.withanLeaves.getDefaultState());
		world.setBlockState(new BlockPos(i + 1, j + 1, k + 4), JourneyBlocks.withanLeaves.getDefaultState());
		world.setBlockState(new BlockPos(i + 1, j + 3, k + 3), JourneyBlocks.withanLeaves.getDefaultState());
		world.setBlockState(new BlockPos(i + 1, j + 3, k + 4), JourneyBlocks.withanLeaves.getDefaultState());
		world.setBlockState(new BlockPos(i + 1, j + 3, k + 6), JourneyBlocks.withanLeaves.getDefaultState());
		world.setBlockState(new BlockPos(i + 1, j + 4, k + 2), JourneyBlocks.withanLeaves.getDefaultState());
		world.setBlockState(new BlockPos(i + 1, j + 4, k + 3), JourneyBlocks.withanLeaves.getDefaultState());
		world.setBlockState(new BlockPos(i + 1, j + 6, k + 2), JourneyBlocks.withanLeaves.getDefaultState());
		world.setBlockState(new BlockPos(i + 1, j + 6, k + 3), JourneyBlocks.withanLeaves.getDefaultState());
		world.setBlockState(new BlockPos(i + 1, j + 6, k + 4), JourneyBlocks.withanLeaves.getDefaultState());
		world.setBlockState(new BlockPos(i + 2, j + 1, k + 1), JourneyBlocks.withanLeaves.getDefaultState());
		world.setBlockState(new BlockPos(i + 2, j + 1, k + 2), JourneyBlocks.withanLeaves.getDefaultState());
		world.setBlockState(new BlockPos(i + 2, j + 1, k + 3), JourneyBlocks.withanLeaves.getDefaultState());
		world.setBlockState(new BlockPos(i + 2, j + 1, k + 4), JourneyBlocks.withanLeaves.getDefaultState());
		world.setBlockState(new BlockPos(i + 2, j + 1, k + 5), JourneyBlocks.withanLeaves.getDefaultState());
		world.setBlockState(new BlockPos(i + 2, j + 2, k + 3), JourneyBlocks.withanLeaves.getDefaultState());
		world.setBlockState(new BlockPos(i + 2, j + 3, k + 0), JourneyBlocks.withanLeaves.getDefaultState());
		world.setBlockState(new BlockPos(i + 2, j + 3, k + 1), JourneyBlocks.withanLeaves.getDefaultState());
		world.setBlockState(new BlockPos(i + 2, j + 3, k + 2), JourneyBlocks.withanLeaves.getDefaultState());
		world.setBlockState(new BlockPos(i + 2, j + 3, k + 3), JourneyBlocks.withanLeaves.getDefaultState());
		world.setBlockState(new BlockPos(i + 2, j + 3, k + 4), JourneyBlocks.withanLeaves.getDefaultState());
		world.setBlockState(new BlockPos(i + 2, j + 3, k + 5), JourneyBlocks.withanLeaves.getDefaultState());
		world.setBlockState(new BlockPos(i + 2, j + 4, k + 2), JourneyBlocks.withanLeaves.getDefaultState());
		world.setBlockState(new BlockPos(i + 2, j + 4, k + 3), JourneyBlocks.withanLeaves.getDefaultState());
		world.setBlockState(new BlockPos(i + 2, j + 4, k + 4), JourneyBlocks.withanLeaves.getDefaultState());
		world.setBlockState(new BlockPos(i + 2, j + 5, k + 3), JourneyBlocks.withanLeaves.getDefaultState());
		world.setBlockState(new BlockPos(i + 2, j + 6, k + 3), JourneyBlocks.withanLeaves.getDefaultState());
		world.setBlockState(new BlockPos(i + 2, j + 6, k + 4), JourneyBlocks.withanLeaves.getDefaultState());
		world.setBlockState(new BlockPos(i + 2, j + 6, k + 5), JourneyBlocks.withanLeaves.getDefaultState());
		world.setBlockState(new BlockPos(i + 2, j + 7, k + 3), JourneyBlocks.withanLeaves.getDefaultState());
		world.setBlockState(new BlockPos(i + 2, j + 9, k + 3), JourneyBlocks.withanLeaves.getDefaultState());
		world.setBlockState(new BlockPos(i + 3, j + 0, k + 3), JourneyBlocks.withanBark.getDefaultState());
		world.setBlockState(new BlockPos(i + 3, j + 1, k + 1), JourneyBlocks.withanLeaves.getDefaultState());
		world.setBlockState(new BlockPos(i + 3, j + 1, k + 2), JourneyBlocks.withanLeaves.getDefaultState());
		world.setBlockState(new BlockPos(i + 3, j + 1, k + 3), JourneyBlocks.withanBark.getDefaultState());
		world.setBlockState(new BlockPos(i + 3, j + 1, k + 4), JourneyBlocks.withanLeaves.getDefaultState());
		world.setBlockState(new BlockPos(i + 3, j + 1, k + 5), JourneyBlocks.withanLeaves.getDefaultState());
		world.setBlockState(new BlockPos(i + 3, j + 2, k + 2), JourneyBlocks.withanLeaves.getDefaultState());
		world.setBlockState(new BlockPos(i + 3, j + 2, k + 3), JourneyBlocks.withanBark.getDefaultState());
		world.setBlockState(new BlockPos(i + 3, j + 2, k + 4), JourneyBlocks.withanLeaves.getDefaultState());
		world.setBlockState(new BlockPos(i + 3, j + 3, k + 2), JourneyBlocks.withanLeaves.getDefaultState());
		world.setBlockState(new BlockPos(i + 3, j + 3, k + 3), JourneyBlocks.withanBark.getDefaultState());
		world.setBlockState(new BlockPos(i + 3, j + 3, k + 4), JourneyBlocks.withanLeaves.getDefaultState());
		world.setBlockState(new BlockPos(i + 3, j + 3, k + 5), JourneyBlocks.withanLeaves.getDefaultState());
		world.setBlockState(new BlockPos(i + 3, j + 4, k + 2), JourneyBlocks.withanLeaves.getDefaultState());
		world.setBlockState(new BlockPos(i + 3, j + 4, k + 3), JourneyBlocks.withanBark.getDefaultState());
		world.setBlockState(new BlockPos(i + 3, j + 4, k + 4), JourneyBlocks.withanLeaves.getDefaultState());
		world.setBlockState(new BlockPos(i + 3, j + 5, k + 2), JourneyBlocks.withanLeaves.getDefaultState());
		world.setBlockState(new BlockPos(i + 3, j + 5, k + 3), JourneyBlocks.withanBark.getDefaultState());
		world.setBlockState(new BlockPos(i + 3, j + 5, k + 4), JourneyBlocks.withanLeaves.getDefaultState());
		world.setBlockState(new BlockPos(i + 3, j + 6, k + 1), JourneyBlocks.withanLeaves.getDefaultState());
		world.setBlockState(new BlockPos(i + 3, j + 6, k + 2), JourneyBlocks.withanLeaves.getDefaultState());
		world.setBlockState(new BlockPos(i + 3, j + 6, k + 3), JourneyBlocks.withanBark.getDefaultState());
		world.setBlockState(new BlockPos(i + 3, j + 6, k + 4), JourneyBlocks.withanLeaves.getDefaultState());
		world.setBlockState(new BlockPos(i + 3, j + 6, k + 5), JourneyBlocks.withanLeaves.getDefaultState());
		world.setBlockState(new BlockPos(i + 3, j + 7, k + 2), JourneyBlocks.withanLeaves.getDefaultState());
		world.setBlockState(new BlockPos(i + 3, j + 7, k + 3), JourneyBlocks.withanBark.getDefaultState());
		world.setBlockState(new BlockPos(i + 3, j + 7, k + 4), JourneyBlocks.withanLeaves.getDefaultState());
		world.setBlockState(new BlockPos(i + 3, j + 8, k + 3), JourneyBlocks.withanBark.getDefaultState());
		world.setBlockState(new BlockPos(i + 3, j + 9, k + 2), JourneyBlocks.withanLeaves.getDefaultState());
		world.setBlockState(new BlockPos(i + 3, j + 9, k + 3), JourneyBlocks.withanBark.getDefaultState());
		world.setBlockState(new BlockPos(i + 3, j + 9, k + 4), JourneyBlocks.withanLeaves.getDefaultState());
		world.setBlockState(new BlockPos(i + 3, j + 10, k + 3), JourneyBlocks.withanBark.getDefaultState());
		world.setBlockState(new BlockPos(i + 4, j + 1, k + 1), JourneyBlocks.withanLeaves.getDefaultState());
		world.setBlockState(new BlockPos(i + 4, j + 1, k + 2), JourneyBlocks.withanLeaves.getDefaultState());
		world.setBlockState(new BlockPos(i + 4, j + 1, k + 3), JourneyBlocks.withanLeaves.getDefaultState());
		world.setBlockState(new BlockPos(i + 4, j + 1, k + 4), JourneyBlocks.withanLeaves.getDefaultState());
		world.setBlockState(new BlockPos(i + 4, j + 1, k + 5), JourneyBlocks.withanLeaves.getDefaultState());
		world.setBlockState(new BlockPos(i + 4, j + 2, k + 3), JourneyBlocks.withanLeaves.getDefaultState());
		world.setBlockState(new BlockPos(i + 4, j + 3, k + 0), JourneyBlocks.withanLeaves.getDefaultState());
		world.setBlockState(new BlockPos(i + 4, j + 3, k + 1), JourneyBlocks.withanLeaves.getDefaultState());
		world.setBlockState(new BlockPos(i + 4, j + 3, k + 2), JourneyBlocks.withanLeaves.getDefaultState());
		world.setBlockState(new BlockPos(i + 4, j + 3, k + 3), JourneyBlocks.withanLeaves.getDefaultState());
		world.setBlockState(new BlockPos(i + 4, j + 3, k + 4), JourneyBlocks.withanLeaves.getDefaultState());
		world.setBlockState(new BlockPos(i + 4, j + 3, k + 5), JourneyBlocks.withanLeaves.getDefaultState());
		world.setBlockState(new BlockPos(i + 4, j + 4, k + 1), JourneyBlocks.withanLeaves.getDefaultState());
		world.setBlockState(new BlockPos(i + 4, j + 4, k + 2), JourneyBlocks.withanLeaves.getDefaultState());
		world.setBlockState(new BlockPos(i + 4, j + 4, k + 3), JourneyBlocks.withanLeaves.getDefaultState());
		world.setBlockState(new BlockPos(i + 4, j + 4, k + 4), JourneyBlocks.withanLeaves.getDefaultState());
		world.setBlockState(new BlockPos(i + 4, j + 4, k + 5), JourneyBlocks.withanLeaves.getDefaultState());
		world.setBlockState(new BlockPos(i + 4, j + 5, k + 3), JourneyBlocks.withanLeaves.getDefaultState());
		world.setBlockState(new BlockPos(i + 4, j + 6, k + 1), JourneyBlocks.withanLeaves.getDefaultState());
		world.setBlockState(new BlockPos(i + 4, j + 6, k + 2), JourneyBlocks.withanLeaves.getDefaultState());
		world.setBlockState(new BlockPos(i + 4, j + 6, k + 3), JourneyBlocks.withanLeaves.getDefaultState());
		world.setBlockState(new BlockPos(i + 4, j + 6, k + 4), JourneyBlocks.withanLeaves.getDefaultState());
		world.setBlockState(new BlockPos(i + 4, j + 6, k + 5), JourneyBlocks.withanLeaves.getDefaultState());
		world.setBlockState(new BlockPos(i + 4, j + 7, k + 3), JourneyBlocks.withanLeaves.getDefaultState());
		world.setBlockState(new BlockPos(i + 4, j + 9, k + 3), JourneyBlocks.withanLeaves.getDefaultState());
		world.setBlockState(new BlockPos(i + 5, j + 1, k + 2), JourneyBlocks.withanLeaves.getDefaultState());
		world.setBlockState(new BlockPos(i + 5, j + 1, k + 3), JourneyBlocks.withanLeaves.getDefaultState());
		world.setBlockState(new BlockPos(i + 5, j + 1, k + 4), JourneyBlocks.withanLeaves.getDefaultState());
		world.setBlockState(new BlockPos(i + 5, j + 3, k + 0), JourneyBlocks.withanLeaves.getDefaultState());
		world.setBlockState(new BlockPos(i + 5, j + 3, k + 3), JourneyBlocks.withanLeaves.getDefaultState());
		world.setBlockState(new BlockPos(i + 5, j + 3, k + 4), JourneyBlocks.withanLeaves.getDefaultState());
		world.setBlockState(new BlockPos(i + 5, j + 3, k + 6), JourneyBlocks.withanLeaves.getDefaultState());
		world.setBlockState(new BlockPos(i + 5, j + 4, k + 3), JourneyBlocks.withanLeaves.getDefaultState());
		world.setBlockState(new BlockPos(i + 5, j + 4, k + 4), JourneyBlocks.withanLeaves.getDefaultState());
		world.setBlockState(new BlockPos(i + 5, j + 6, k + 2), JourneyBlocks.withanLeaves.getDefaultState());
		world.setBlockState(new BlockPos(i + 5, j + 6, k + 3), JourneyBlocks.withanLeaves.getDefaultState());
		world.setBlockState(new BlockPos(i + 5, j + 6, k + 4), JourneyBlocks.withanLeaves.getDefaultState());
		world.setBlockState(new BlockPos(i + 6, j + 3, k + 1), JourneyBlocks.withanLeaves.getDefaultState());
		world.setBlockState(new BlockPos(i + 6, j + 3, k + 2), JourneyBlocks.withanLeaves.getDefaultState());
		world.setBlockState(new BlockPos(i + 6, j + 3, k + 3), JourneyBlocks.withanLeaves.getDefaultState());
		world.setBlockState(new BlockPos(i + 6, j + 3, k + 5), JourneyBlocks.withanLeaves.getDefaultState());
		return true;
	}
}