package net.journey.dimension.terrania.gen;

import java.util.Random;

import net.journey.JourneyBlocks;
import net.journey.entity.mob.terrania.npc.EntityTerranianTrader;
import net.minecraft.block.Block;
import net.minecraft.block.state.IBlockState;
import net.minecraft.util.math.BlockPos;
import net.minecraft.world.World;
import net.minecraft.world.gen.feature.WorldGenerator;
import net.slayer.api.worldgen.WorldGenAPI;

public class WorldGenTallTree extends WorldGenerator {
	
	public boolean locationIsValidSpawn(World w, int x, int y, int z) {
		for(int i = 0; i < 11; i++) {
			for(int l = 0; l < 11; l++) {
				if(w.getBlockState(new BlockPos(x + i, y, z + l)) != JourneyBlocks.terranianGrass) {
					return false;
				}
			}
		}
		return true;
	}
	
	@Override
	public boolean generate(World world, Random rand, BlockPos pos) {
		Block post = JourneyBlocks.terranianPost;
		Block plank = JourneyBlocks.terranianPanels;
		int i = pos.getX(), j = pos.getY(), k = pos.getZ();
		if(locationIsValidSpawn(world, i, j, k)) return true;
		IBlockState leaves = WorldGenAPI.getTerraniaLeaves().getDefaultState(), log = WorldGenAPI.getTerranianLog().getDefaultState(), vine = WorldGenAPI.getTerraniaVine().getDefaultState();
		i-=5;
		k-=5;
		
		world.setBlockState(new BlockPos(i + 0, j + 23, k + 4), JourneyBlocks.terraniaLeaves.getDefaultState());
		world.setBlockState(new BlockPos(i + 0, j + 44, k + 5), JourneyBlocks.terraniaLeaves.getDefaultState());
		world.setBlockState(new BlockPos(i + 0, j + 44, k + 6), JourneyBlocks.terraniaLeaves.getDefaultState());
		world.setBlockState(new BlockPos(i + 1, j + 0, k + 6), JourneyBlocks.terranianLog.getDefaultState());
		world.setBlockState(new BlockPos(i + 1, j + 23, k + 3), JourneyBlocks.terraniaLeaves.getDefaultState());
		world.setBlockState(new BlockPos(i + 1, j + 23, k + 5), JourneyBlocks.terraniaLeaves.getDefaultState());
		world.setBlockState(new BlockPos(i + 1, j + 23, k + 6), JourneyBlocks.terraniaLeaves.getDefaultState());
		world.setBlockState(new BlockPos(i + 1, j + 23, k + 7), JourneyBlocks.terraniaLeaves.getDefaultState());
		world.setBlockState(new BlockPos(i + 1, j + 24, k + 5), JourneyBlocks.terraniaLeaves.getDefaultState());
		world.setBlockState(new BlockPos(i + 1, j + 44, k + 2), JourneyBlocks.terraniaLeaves.getDefaultState());
		world.setBlockState(new BlockPos(i + 1, j + 44, k + 3), JourneyBlocks.terraniaLeaves.getDefaultState());
		world.setBlockState(new BlockPos(i + 1, j + 44, k + 4), JourneyBlocks.terraniaLeaves.getDefaultState());
		world.setBlockState(new BlockPos(i + 1, j + 44, k + 5), JourneyBlocks.terraniaLeaves.getDefaultState());
		world.setBlockState(new BlockPos(i + 1, j + 44, k + 6), JourneyBlocks.terraniaLeaves.getDefaultState());
		world.setBlockState(new BlockPos(i + 1, j + 44, k + 7), JourneyBlocks.terraniaLeaves.getDefaultState());
		world.setBlockState(new BlockPos(i + 1, j + 44, k + 8), JourneyBlocks.terraniaLeaves.getDefaultState());
		world.setBlockState(new BlockPos(i + 1, j + 44, k + 9), JourneyBlocks.terraniaLeaves.getDefaultState());
		world.setBlockState(new BlockPos(i + 1, j + 45, k + 5), JourneyBlocks.terraniaLeaves.getDefaultState());
		world.setBlockState(new BlockPos(i + 1, j + 45, k + 6), JourneyBlocks.terraniaLeaves.getDefaultState());
		world.setBlockState(new BlockPos(i + 2, j + 0, k + 4), JourneyBlocks.terranianLog.getDefaultState());
		world.setBlockState(new BlockPos(i + 2, j + 0, k + 5), JourneyBlocks.terranianLog.getDefaultState());
		world.setBlockState(new BlockPos(i + 2, j + 0, k + 8), JourneyBlocks.terranianLog.getDefaultState());
		world.setBlockState(new BlockPos(i + 2, j + 14, k + 10), JourneyBlocks.terraniaLeaves.getDefaultState());
		world.setBlockState(new BlockPos(i + 2, j + 23, k + 2), JourneyBlocks.terraniaLeaves.getDefaultState());
		world.setBlockState(new BlockPos(i + 2, j + 23, k + 3), JourneyBlocks.terraniaLeaves.getDefaultState());
		world.setBlockState(new BlockPos(i + 2, j + 23, k + 4), JourneyBlocks.terraniaLeaves.getDefaultState());
		world.setBlockState(new BlockPos(i + 2, j + 23, k + 5), JourneyBlocks.terraniaLeaves.getDefaultState());
		world.setBlockState(new BlockPos(i + 2, j + 23, k + 6), JourneyBlocks.terraniaLeaves.getDefaultState());
		world.setBlockState(new BlockPos(i + 2, j + 23, k + 7), JourneyBlocks.terraniaLeaves.getDefaultState());
		world.setBlockState(new BlockPos(i + 2, j + 23, k + 9), JourneyBlocks.terraniaLeaves.getDefaultState());
		world.setBlockState(new BlockPos(i + 2, j + 24, k + 4), JourneyBlocks.terraniaLeaves.getDefaultState());
		world.setBlockState(new BlockPos(i + 2, j + 24, k + 5), JourneyBlocks.terraniaLeaves.getDefaultState());
		world.setBlockState(new BlockPos(i + 2, j + 24, k + 6), JourneyBlocks.terraniaLeaves.getDefaultState());
		world.setBlockState(new BlockPos(i + 2, j + 25, k + 5), JourneyBlocks.terraniaLeaves.getDefaultState());
		world.setBlockState(new BlockPos(i + 2, j + 25, k + 6), JourneyBlocks.terraniaLeaves.getDefaultState());
		world.setBlockState(new BlockPos(i + 2, j + 41, k + 3), JourneyBlocks.terraniaLeaves.getDefaultState());
		world.setBlockState(new BlockPos(i + 2, j + 44, k + 1), JourneyBlocks.terraniaLeaves.getDefaultState());
		world.setBlockState(new BlockPos(i + 2, j + 44, k + 2), JourneyBlocks.terraniaLeaves.getDefaultState());
		world.setBlockState(new BlockPos(i + 2, j + 44, k + 3), JourneyBlocks.terraniaLeaves.getDefaultState());
		world.setBlockState(new BlockPos(i + 2, j + 44, k + 4), JourneyBlocks.terraniaLeaves.getDefaultState());
		world.setBlockState(new BlockPos(i + 2, j + 44, k + 5), JourneyBlocks.terraniaLeaves.getDefaultState());
		world.setBlockState(new BlockPos(i + 2, j + 44, k + 6), JourneyBlocks.terraniaLeaves.getDefaultState());
		world.setBlockState(new BlockPos(i + 2, j + 44, k + 7), JourneyBlocks.terraniaLeaves.getDefaultState());
		world.setBlockState(new BlockPos(i + 2, j + 44, k + 8), JourneyBlocks.terraniaLeaves.getDefaultState());
		world.setBlockState(new BlockPos(i + 2, j + 44, k + 9), JourneyBlocks.terraniaLeaves.getDefaultState());
		world.setBlockState(new BlockPos(i + 2, j + 44, k + 10), JourneyBlocks.terraniaLeaves.getDefaultState());
		world.setBlockState(new BlockPos(i + 2, j + 45, k + 3), JourneyBlocks.terraniaLeaves.getDefaultState());
		world.setBlockState(new BlockPos(i + 2, j + 45, k + 4), JourneyBlocks.terraniaLeaves.getDefaultState());
		world.setBlockState(new BlockPos(i + 2, j + 45, k + 5), JourneyBlocks.terraniaLeaves.getDefaultState());
		world.setBlockState(new BlockPos(i + 2, j + 45, k + 6), JourneyBlocks.terraniaLeaves.getDefaultState());
		world.setBlockState(new BlockPos(i + 2, j + 45, k + 7), JourneyBlocks.terraniaLeaves.getDefaultState());
		world.setBlockState(new BlockPos(i + 2, j + 45, k + 8), JourneyBlocks.terraniaLeaves.getDefaultState());
		world.setBlockState(new BlockPos(i + 2, j + 46, k + 5), JourneyBlocks.terraniaLeaves.getDefaultState());
		world.setBlockState(new BlockPos(i + 2, j + 46, k + 6), JourneyBlocks.terraniaLeaves.getDefaultState());
		world.setBlockState(new BlockPos(i + 3, j + 0, k + 2), JourneyBlocks.terranianLog.getDefaultState());
		world.setBlockState(new BlockPos(i + 3, j + 0, k + 5), JourneyBlocks.terranianLog.getDefaultState());
		world.setBlockState(new BlockPos(i + 3, j + 0, k + 7), JourneyBlocks.terranianLog.getDefaultState());
		world.setBlockState(new BlockPos(i + 3, j + 1, k + 5), JourneyBlocks.terranianLog.getDefaultState());
		world.setBlockState(new BlockPos(i + 3, j + 12, k + 6), JourneyBlocks.terraniaLeaves.getDefaultState());
		world.setBlockState(new BlockPos(i + 3, j + 14, k + 8), JourneyBlocks.terraniaLeaves.getDefaultState());
		world.setBlockState(new BlockPos(i + 3, j + 14, k + 9), JourneyBlocks.terraniaLeaves.getDefaultState());
		world.setBlockState(new BlockPos(i + 3, j + 14, k + 10), JourneyBlocks.terraniaLeaves.getDefaultState());
		world.setBlockState(new BlockPos(i + 3, j + 14, k + 11), JourneyBlocks.terraniaLeaves.getDefaultState());
		world.setBlockState(new BlockPos(i + 3, j + 14, k + 12), JourneyBlocks.terraniaLeaves.getDefaultState());
		world.setBlockState(new BlockPos(i + 3, j + 15, k + 10), JourneyBlocks.terraniaLeaves.getDefaultState());
		world.setBlockState(new BlockPos(i + 3, j + 22, k + 5), JourneyBlocks.terraniaLeaves.getDefaultState());
		world.setBlockState(new BlockPos(i + 3, j + 23, k + 1), JourneyBlocks.terraniaLeaves.getDefaultState());
		world.setBlockState(new BlockPos(i + 3, j + 23, k + 2), JourneyBlocks.terraniaLeaves.getDefaultState());
		world.setBlockState(new BlockPos(i + 3, j + 23, k + 3), JourneyBlocks.terraniaLeaves.getDefaultState());
		world.setBlockState(new BlockPos(i + 3, j + 23, k + 4), JourneyBlocks.terraniaLeaves.getDefaultState());
		world.setBlockState(new BlockPos(i + 3, j + 23, k + 5), JourneyBlocks.terraniaLeaves.getDefaultState());
		world.setBlockState(new BlockPos(i + 3, j + 23, k + 6), JourneyBlocks.terraniaLeaves.getDefaultState());
		world.setBlockState(new BlockPos(i + 3, j + 23, k + 7), JourneyBlocks.terraniaLeaves.getDefaultState());
		world.setBlockState(new BlockPos(i + 3, j + 23, k + 8), JourneyBlocks.terraniaLeaves.getDefaultState());
		world.setBlockState(new BlockPos(i + 3, j + 23, k + 9), JourneyBlocks.terraniaLeaves.getDefaultState());
		world.setBlockState(new BlockPos(i + 3, j + 23, k + 10), JourneyBlocks.terraniaLeaves.getDefaultState());
		world.setBlockState(new BlockPos(i + 3, j + 24, k + 3), JourneyBlocks.terraniaLeaves.getDefaultState());
		world.setBlockState(new BlockPos(i + 3, j + 24, k + 4), JourneyBlocks.terraniaLeaves.getDefaultState());
		world.setBlockState(new BlockPos(i + 3, j + 24, k + 5), JourneyBlocks.terraniaLeaves.getDefaultState());
		world.setBlockState(new BlockPos(i + 3, j + 24, k + 6), JourneyBlocks.terraniaLeaves.getDefaultState());
		world.setBlockState(new BlockPos(i + 3, j + 24, k + 7), JourneyBlocks.terraniaLeaves.getDefaultState());
		world.setBlockState(new BlockPos(i + 3, j + 24, k + 8), JourneyBlocks.terraniaLeaves.getDefaultState());
		world.setBlockState(new BlockPos(i + 3, j + 24, k + 9), JourneyBlocks.terraniaLeaves.getDefaultState());
		world.setBlockState(new BlockPos(i + 3, j + 25, k + 4), JourneyBlocks.terraniaLeaves.getDefaultState());
		world.setBlockState(new BlockPos(i + 3, j + 25, k + 5), JourneyBlocks.terraniaLeaves.getDefaultState());
		world.setBlockState(new BlockPos(i + 3, j + 25, k + 6), JourneyBlocks.terraniaLeaves.getDefaultState());
		world.setBlockState(new BlockPos(i + 3, j + 25, k + 7), JourneyBlocks.terraniaLeaves.getDefaultState());
		world.setBlockState(new BlockPos(i + 3, j + 25, k + 8), JourneyBlocks.terraniaLeaves.getDefaultState());
		world.setBlockState(new BlockPos(i + 3, j + 30, k + 6), JourneyBlocks.terraniaLeaves.getDefaultState());
		world.setBlockState(new BlockPos(i + 3, j + 41, k + 1), JourneyBlocks.terraniaLeaves.getDefaultState());
		world.setBlockState(new BlockPos(i + 3, j + 41, k + 2), JourneyBlocks.terraniaLeaves.getDefaultState());
		world.setBlockState(new BlockPos(i + 3, j + 41, k + 3), JourneyBlocks.terraniaLeaves.getDefaultState());
		world.setBlockState(new BlockPos(i + 3, j + 41, k + 4), JourneyBlocks.terraniaLeaves.getDefaultState());
		world.setBlockState(new BlockPos(i + 3, j + 41, k + 5), JourneyBlocks.terraniaLeaves.getDefaultState());
		world.setBlockState(new BlockPos(i + 3, j + 42, k + 3), JourneyBlocks.terraniaLeaves.getDefaultState());
		world.setBlockState(new BlockPos(i + 3, j + 44, k + 1), JourneyBlocks.terraniaLeaves.getDefaultState());
		world.setBlockState(new BlockPos(i + 3, j + 44, k + 2), JourneyBlocks.terraniaLeaves.getDefaultState());
		world.setBlockState(new BlockPos(i + 3, j + 44, k + 3), JourneyBlocks.terraniaLeaves.getDefaultState());
		world.setBlockState(new BlockPos(i + 3, j + 44, k + 4), JourneyBlocks.terraniaLeaves.getDefaultState());
		world.setBlockState(new BlockPos(i + 3, j + 44, k + 5), JourneyBlocks.terraniaLeaves.getDefaultState());
		world.setBlockState(new BlockPos(i + 3, j + 44, k + 6), JourneyBlocks.terraniaLeaves.getDefaultState());
		world.setBlockState(new BlockPos(i + 3, j + 44, k + 7), JourneyBlocks.terraniaLeaves.getDefaultState());
		world.setBlockState(new BlockPos(i + 3, j + 44, k + 8), JourneyBlocks.terraniaLeaves.getDefaultState());
		world.setBlockState(new BlockPos(i + 3, j + 44, k + 9), JourneyBlocks.terraniaLeaves.getDefaultState());
		world.setBlockState(new BlockPos(i + 3, j + 44, k + 10), JourneyBlocks.terraniaLeaves.getDefaultState());
		world.setBlockState(new BlockPos(i + 3, j + 45, k + 2), JourneyBlocks.terraniaLeaves.getDefaultState());
		world.setBlockState(new BlockPos(i + 3, j + 45, k + 3), JourneyBlocks.terraniaLeaves.getDefaultState());
		world.setBlockState(new BlockPos(i + 3, j + 45, k + 4), JourneyBlocks.terraniaLeaves.getDefaultState());
		world.setBlockState(new BlockPos(i + 3, j + 45, k + 5), JourneyBlocks.terraniaLeaves.getDefaultState());
		world.setBlockState(new BlockPos(i + 3, j + 45, k + 6), JourneyBlocks.terraniaLeaves.getDefaultState());
		world.setBlockState(new BlockPos(i + 3, j + 45, k + 7), JourneyBlocks.terraniaLeaves.getDefaultState());
		world.setBlockState(new BlockPos(i + 3, j + 45, k + 8), JourneyBlocks.terraniaLeaves.getDefaultState());
		world.setBlockState(new BlockPos(i + 3, j + 45, k + 9), JourneyBlocks.terraniaLeaves.getDefaultState());
		world.setBlockState(new BlockPos(i + 3, j + 46, k + 3), JourneyBlocks.terraniaLeaves.getDefaultState());
		world.setBlockState(new BlockPos(i + 3, j + 46, k + 4), JourneyBlocks.terraniaLeaves.getDefaultState());
		world.setBlockState(new BlockPos(i + 3, j + 46, k + 5), JourneyBlocks.terraniaLeaves.getDefaultState());
		world.setBlockState(new BlockPos(i + 3, j + 46, k + 6), JourneyBlocks.terraniaLeaves.getDefaultState());
		world.setBlockState(new BlockPos(i + 3, j + 46, k + 7), JourneyBlocks.terraniaLeaves.getDefaultState());
		world.setBlockState(new BlockPos(i + 3, j + 46, k + 8), JourneyBlocks.terraniaLeaves.getDefaultState());
		world.setBlockState(new BlockPos(i + 4, j + 0, k + 5), JourneyBlocks.terranianLog.getDefaultState());
		world.setBlockState(new BlockPos(i + 4, j + 0, k + 6), JourneyBlocks.terranianLog.getDefaultState());
		world.setBlockState(new BlockPos(i + 4, j + 0, k + 7), JourneyBlocks.terranianLog.getDefaultState());
		world.setBlockState(new BlockPos(i + 4, j + 1, k + 5), JourneyBlocks.terranianLog.getDefaultState());
		world.setBlockState(new BlockPos(i + 4, j + 1, k + 6), JourneyBlocks.terranianLog.getDefaultState());
		world.setBlockState(new BlockPos(i + 4, j + 1, k + 7), JourneyBlocks.terranianLog.getDefaultState());
		world.setBlockState(new BlockPos(i + 4, j + 2, k + 6), JourneyBlocks.terranianLog.getDefaultState());
		world.setBlockState(new BlockPos(i + 4, j + 3, k + 6), JourneyBlocks.terranianLog.getDefaultState());
		world.setBlockState(new BlockPos(i + 4, j + 12, k + 6), JourneyBlocks.terraniaLeaves.getDefaultState());
		world.setBlockState(new BlockPos(i + 4, j + 13, k + 8), JourneyBlocks.terraniaLeaves.getDefaultState());
		world.setBlockState(new BlockPos(i + 4, j + 14, k + 6), JourneyBlocks.terraniaLeaves.getDefaultState());
		world.setBlockState(new BlockPos(i + 4, j + 14, k + 8), JourneyBlocks.terraniaLeaves.getDefaultState());
		world.setBlockState(new BlockPos(i + 4, j + 14, k + 9), JourneyBlocks.terraniaLeaves.getDefaultState());
		world.setBlockState(new BlockPos(i + 4, j + 14, k + 10), JourneyBlocks.terraniaLeaves.getDefaultState());
		world.setBlockState(new BlockPos(i + 4, j + 14, k + 11), JourneyBlocks.terraniaLeaves.getDefaultState());
		world.setBlockState(new BlockPos(i + 4, j + 14, k + 12), JourneyBlocks.terraniaLeaves.getDefaultState());
		world.setBlockState(new BlockPos(i + 4, j + 15, k + 9), JourneyBlocks.terraniaLeaves.getDefaultState());
		world.setBlockState(new BlockPos(i + 4, j + 15, k + 10), JourneyBlocks.terraniaLeaves.getDefaultState());
		world.setBlockState(new BlockPos(i + 4, j + 15, k + 11), JourneyBlocks.terraniaLeaves.getDefaultState());
		world.setBlockState(new BlockPos(i + 4, j + 16, k + 5), JourneyBlocks.terraniaLeaves.getDefaultState());
		world.setBlockState(new BlockPos(i + 4, j + 16, k + 10), JourneyBlocks.terraniaLeaves.getDefaultState());
		world.setBlockState(new BlockPos(i + 4, j + 20, k + 5), JourneyBlocks.terraniaLeaves.getDefaultState());
		world.setBlockState(new BlockPos(i + 4, j + 20, k + 6), JourneyBlocks.terraniaLeaves.getDefaultState());
		world.setBlockState(new BlockPos(i + 4, j + 21, k + 6), JourneyBlocks.terraniaLeaves.getDefaultState());
		world.setBlockState(new BlockPos(i + 4, j + 22, k + 5), JourneyBlocks.terraniaLeaves.getDefaultState());
		world.setBlockState(new BlockPos(i + 4, j + 23, k + 1), JourneyBlocks.terraniaLeaves.getDefaultState());
		world.setBlockState(new BlockPos(i + 4, j + 23, k + 2), JourneyBlocks.terraniaLeaves.getDefaultState());
		world.setBlockState(new BlockPos(i + 4, j + 23, k + 3), JourneyBlocks.terraniaLeaves.getDefaultState());
		world.setBlockState(new BlockPos(i + 4, j + 23, k + 4), JourneyBlocks.terraniaLeaves.getDefaultState());
		world.setBlockState(new BlockPos(i + 4, j + 23, k + 5), JourneyBlocks.terraniaLeaves.getDefaultState());
		world.setBlockState(new BlockPos(i + 4, j + 23, k + 6), JourneyBlocks.terraniaLeaves.getDefaultState());
		world.setBlockState(new BlockPos(i + 4, j + 23, k + 7), JourneyBlocks.terraniaLeaves.getDefaultState());
		world.setBlockState(new BlockPos(i + 4, j + 23, k + 8), JourneyBlocks.terraniaLeaves.getDefaultState());
		world.setBlockState(new BlockPos(i + 4, j + 23, k + 9), JourneyBlocks.terraniaLeaves.getDefaultState());
		world.setBlockState(new BlockPos(i + 4, j + 24, k + 2), JourneyBlocks.terraniaLeaves.getDefaultState());
		world.setBlockState(new BlockPos(i + 4, j + 24, k + 3), JourneyBlocks.terraniaLeaves.getDefaultState());
		world.setBlockState(new BlockPos(i + 4, j + 24, k + 4), JourneyBlocks.terraniaLeaves.getDefaultState());
		world.setBlockState(new BlockPos(i + 4, j + 24, k + 5), JourneyBlocks.terraniaLeaves.getDefaultState());
		world.setBlockState(new BlockPos(i + 4, j + 24, k + 6), JourneyBlocks.terraniaLeaves.getDefaultState());
		world.setBlockState(new BlockPos(i + 4, j + 24, k + 7), JourneyBlocks.terraniaLeaves.getDefaultState());
		world.setBlockState(new BlockPos(i + 4, j + 24, k + 8), JourneyBlocks.terraniaLeaves.getDefaultState());
		world.setBlockState(new BlockPos(i + 4, j + 24, k + 9), JourneyBlocks.terraniaLeaves.getDefaultState());
		world.setBlockState(new BlockPos(i + 4, j + 25, k + 3), JourneyBlocks.terraniaLeaves.getDefaultState());
		world.setBlockState(new BlockPos(i + 4, j + 25, k + 4), JourneyBlocks.terraniaLeaves.getDefaultState());
		world.setBlockState(new BlockPos(i + 4, j + 25, k + 5), JourneyBlocks.terraniaLeaves.getDefaultState());
		world.setBlockState(new BlockPos(i + 4, j + 25, k + 6), JourneyBlocks.terraniaLeaves.getDefaultState());
		world.setBlockState(new BlockPos(i + 4, j + 25, k + 7), JourneyBlocks.terraniaLeaves.getDefaultState());
		world.setBlockState(new BlockPos(i + 4, j + 25, k + 8), JourneyBlocks.terraniaLeaves.getDefaultState());
		world.setBlockState(new BlockPos(i + 4, j + 26, k + 5), JourneyBlocks.terraniaLeaves.getDefaultState());
		world.setBlockState(new BlockPos(i + 4, j + 26, k + 6), JourneyBlocks.terraniaLeaves.getDefaultState());
		world.setBlockState(new BlockPos(i + 4, j + 27, k + 5), JourneyBlocks.terraniaLeaves.getDefaultState());
		world.setBlockState(new BlockPos(i + 4, j + 27, k + 6), JourneyBlocks.terraniaLeaves.getDefaultState());
		world.setBlockState(new BlockPos(i + 4, j + 30, k + 5), JourneyBlocks.terraniaLeaves.getDefaultState());
		world.setBlockState(new BlockPos(i + 4, j + 30, k + 6), JourneyBlocks.terraniaLeaves.getDefaultState());
		world.setBlockState(new BlockPos(i + 4, j + 32, k + 5), JourneyBlocks.terraniaLeaves.getDefaultState());
		world.setBlockState(new BlockPos(i + 4, j + 34, k + 5), JourneyBlocks.terraniaLeaves.getDefaultState());
		world.setBlockState(new BlockPos(i + 4, j + 35, k + 6), JourneyBlocks.terraniaLeaves.getDefaultState());
		world.setBlockState(new BlockPos(i + 4, j + 38, k + 6), JourneyBlocks.terraniaLeaves.getDefaultState());
		world.setBlockState(new BlockPos(i + 4, j + 39, k + 5), JourneyBlocks.terraniaLeaves.getDefaultState());
		world.setBlockState(new BlockPos(i + 4, j + 39, k + 6), JourneyBlocks.terraniaLeaves.getDefaultState());
		world.setBlockState(new BlockPos(i + 4, j + 40, k + 6), JourneyBlocks.terraniaLeaves.getDefaultState());
		world.setBlockState(new BlockPos(i + 4, j + 40, k + 7), JourneyBlocks.terraniaLeaves.getDefaultState());
		world.setBlockState(new BlockPos(i + 4, j + 41, k + 1), JourneyBlocks.terraniaLeaves.getDefaultState());
		world.setBlockState(new BlockPos(i + 4, j + 41, k + 2), JourneyBlocks.terraniaLeaves.getDefaultState());
		world.setBlockState(new BlockPos(i + 4, j + 41, k + 3), JourneyBlocks.terraniaLeaves.getDefaultState());
		world.setBlockState(new BlockPos(i + 4, j + 41, k + 4), JourneyBlocks.terraniaLeaves.getDefaultState());
		world.setBlockState(new BlockPos(i + 4, j + 41, k + 5), JourneyBlocks.terraniaLeaves.getDefaultState());
		world.setBlockState(new BlockPos(i + 4, j + 42, k + 2), JourneyBlocks.terraniaLeaves.getDefaultState());
		world.setBlockState(new BlockPos(i + 4, j + 42, k + 3), JourneyBlocks.terraniaLeaves.getDefaultState());
		world.setBlockState(new BlockPos(i + 4, j + 42, k + 4), JourneyBlocks.terraniaLeaves.getDefaultState());
		world.setBlockState(new BlockPos(i + 4, j + 42, k + 5), JourneyBlocks.terraniaLeaves.getDefaultState());
		world.setBlockState(new BlockPos(i + 4, j + 43, k + 3), JourneyBlocks.terraniaLeaves.getDefaultState());
		world.setBlockState(new BlockPos(i + 4, j + 44, k + 1), JourneyBlocks.terraniaLeaves.getDefaultState());
		world.setBlockState(new BlockPos(i + 4, j + 44, k + 2), JourneyBlocks.terraniaLeaves.getDefaultState());
		world.setBlockState(new BlockPos(i + 4, j + 44, k + 3), JourneyBlocks.terraniaLeaves.getDefaultState());
		world.setBlockState(new BlockPos(i + 4, j + 44, k + 4), JourneyBlocks.terraniaLeaves.getDefaultState());
		world.setBlockState(new BlockPos(i + 4, j + 44, k + 5), JourneyBlocks.terraniaLeaves.getDefaultState());
		world.setBlockState(new BlockPos(i + 4, j + 44, k + 6), JourneyBlocks.terraniaLeaves.getDefaultState());
		world.setBlockState(new BlockPos(i + 4, j + 44, k + 7), JourneyBlocks.terraniaLeaves.getDefaultState());
		world.setBlockState(new BlockPos(i + 4, j + 44, k + 8), JourneyBlocks.terraniaLeaves.getDefaultState());
		world.setBlockState(new BlockPos(i + 4, j + 44, k + 9), JourneyBlocks.terraniaLeaves.getDefaultState());
		world.setBlockState(new BlockPos(i + 4, j + 44, k + 10), JourneyBlocks.terraniaLeaves.getDefaultState());
		world.setBlockState(new BlockPos(i + 4, j + 45, k + 2), JourneyBlocks.terraniaLeaves.getDefaultState());
		world.setBlockState(new BlockPos(i + 4, j + 45, k + 3), JourneyBlocks.terraniaLeaves.getDefaultState());
		world.setBlockState(new BlockPos(i + 4, j + 45, k + 4), JourneyBlocks.terraniaLeaves.getDefaultState());
		world.setBlockState(new BlockPos(i + 4, j + 45, k + 5), JourneyBlocks.terraniaLeaves.getDefaultState());
		world.setBlockState(new BlockPos(i + 4, j + 45, k + 6), JourneyBlocks.terraniaLeaves.getDefaultState());
		world.setBlockState(new BlockPos(i + 4, j + 45, k + 7), JourneyBlocks.terraniaLeaves.getDefaultState());
		world.setBlockState(new BlockPos(i + 4, j + 45, k + 8), JourneyBlocks.terraniaLeaves.getDefaultState());
		world.setBlockState(new BlockPos(i + 4, j + 45, k + 9), JourneyBlocks.terraniaLeaves.getDefaultState());
		world.setBlockState(new BlockPos(i + 4, j + 46, k + 3), JourneyBlocks.terraniaLeaves.getDefaultState());
		world.setBlockState(new BlockPos(i + 4, j + 46, k + 4), JourneyBlocks.terraniaLeaves.getDefaultState());
		world.setBlockState(new BlockPos(i + 4, j + 46, k + 5), JourneyBlocks.terraniaLeaves.getDefaultState());
		world.setBlockState(new BlockPos(i + 4, j + 46, k + 6), JourneyBlocks.terraniaLeaves.getDefaultState());
		world.setBlockState(new BlockPos(i + 4, j + 46, k + 7), JourneyBlocks.terraniaLeaves.getDefaultState());
		world.setBlockState(new BlockPos(i + 4, j + 46, k + 8), JourneyBlocks.terraniaLeaves.getDefaultState());
		world.setBlockState(new BlockPos(i + 5, j + 0, k + 2), JourneyBlocks.terranianLog.getDefaultState());
		world.setBlockState(new BlockPos(i + 5, j + 0, k + 3), JourneyBlocks.terranianLog.getDefaultState());
		world.setBlockState(new BlockPos(i + 5, j + 0, k + 4), JourneyBlocks.terranianLog.getDefaultState());
		world.setBlockState(new BlockPos(i + 5, j + 0, k + 5), JourneyBlocks.terranianLog.getDefaultState());
		world.setBlockState(new BlockPos(i + 5, j + 0, k + 6), JourneyBlocks.terranianLog.getDefaultState());
		world.setBlockState(new BlockPos(i + 5, j + 0, k + 7), JourneyBlocks.terranianLog.getDefaultState());
		world.setBlockState(new BlockPos(i + 5, j + 0, k + 8), JourneyBlocks.terranianLog.getDefaultState());
		world.setBlockState(new BlockPos(i + 5, j + 0, k + 9), JourneyBlocks.terranianLog.getDefaultState());
		world.setBlockState(new BlockPos(i + 5, j + 0, k + 10), JourneyBlocks.terranianLog.getDefaultState());
		world.setBlockState(new BlockPos(i + 5, j + 1, k + 3), JourneyBlocks.terranianLog.getDefaultState());
		world.setBlockState(new BlockPos(i + 5, j + 1, k + 5), JourneyBlocks.terranianLog.getDefaultState());
		world.setBlockState(new BlockPos(i + 5, j + 1, k + 6), JourneyBlocks.terranianLog.getDefaultState());
		world.setBlockState(new BlockPos(i + 5, j + 1, k + 7), JourneyBlocks.terranianLog.getDefaultState());
		world.setBlockState(new BlockPos(i + 5, j + 1, k + 8), JourneyBlocks.terranianLog.getDefaultState());
		world.setBlockState(new BlockPos(i + 5, j + 1, k + 9), JourneyBlocks.terranianLog.getDefaultState());
		world.setBlockState(new BlockPos(i + 5, j + 2, k + 5), JourneyBlocks.terranianLog.getDefaultState());
		world.setBlockState(new BlockPos(i + 5, j + 2, k + 6), JourneyBlocks.terranianLog.getDefaultState());
		world.setBlockState(new BlockPos(i + 5, j + 2, k + 7), JourneyBlocks.terranianLog.getDefaultState());
		world.setBlockState(new BlockPos(i + 5, j + 3, k + 5), JourneyBlocks.terranianLog.getDefaultState());
		world.setBlockState(new BlockPos(i + 5, j + 3, k + 6), JourneyBlocks.terranianLog.getDefaultState());
		world.setBlockState(new BlockPos(i + 5, j + 4, k + 5), JourneyBlocks.terranianLog.getDefaultState());
		world.setBlockState(new BlockPos(i + 5, j + 4, k + 6), JourneyBlocks.terranianLog.getDefaultState());
		world.setBlockState(new BlockPos(i + 5, j + 5, k + 5), JourneyBlocks.terranianLog.getDefaultState());
		world.setBlockState(new BlockPos(i + 5, j + 5, k + 6), JourneyBlocks.terranianLog.getDefaultState());
		world.setBlockState(new BlockPos(i + 5, j + 6, k + 5), JourneyBlocks.terranianLog.getDefaultState());
		world.setBlockState(new BlockPos(i + 5, j + 6, k + 6), JourneyBlocks.terranianLog.getDefaultState());
		world.setBlockState(new BlockPos(i + 5, j + 7, k + 5), JourneyBlocks.terranianLog.getDefaultState());
		world.setBlockState(new BlockPos(i + 5, j + 7, k + 6), JourneyBlocks.terranianLog.getDefaultState());
		world.setBlockState(new BlockPos(i + 5, j + 8, k + 5), JourneyBlocks.terranianLog.getDefaultState());
		world.setBlockState(new BlockPos(i + 5, j + 8, k + 6), JourneyBlocks.terranianLog.getDefaultState());
		world.setBlockState(new BlockPos(i + 5, j + 9, k + 5), JourneyBlocks.terranianLog.getDefaultState());
		world.setBlockState(new BlockPos(i + 5, j + 9, k + 6), JourneyBlocks.terranianLog.getDefaultState());
		world.setBlockState(new BlockPos(i + 5, j + 10, k + 5), JourneyBlocks.terranianLog.getDefaultState());
		world.setBlockState(new BlockPos(i + 5, j + 10, k + 6), JourneyBlocks.terranianLog.getDefaultState());
		world.setBlockState(new BlockPos(i + 5, j + 11, k + 5), JourneyBlocks.terranianLog.getDefaultState());
		world.setBlockState(new BlockPos(i + 5, j + 11, k + 6), JourneyBlocks.terranianLog.getDefaultState());
		world.setBlockState(new BlockPos(i + 5, j + 12, k + 5), JourneyBlocks.terranianLog.getDefaultState());
		world.setBlockState(new BlockPos(i + 5, j + 12, k + 6), JourneyBlocks.terranianLog.getDefaultState());
		world.setBlockState(new BlockPos(i + 5, j + 12, k + 7), JourneyBlocks.terraniaLeaves.getDefaultState());
		world.setBlockState(new BlockPos(i + 5, j + 13, k + 5), JourneyBlocks.terranianLog.getDefaultState());
		world.setBlockState(new BlockPos(i + 5, j + 13, k + 6), JourneyBlocks.terranianLog.getDefaultState());
		world.setBlockState(new BlockPos(i + 5, j + 13, k + 7), JourneyBlocks.terraniaLeaves.getDefaultState());
		world.setBlockState(new BlockPos(i + 5, j + 13, k + 8), JourneyBlocks.terraniaLeaves.getDefaultState());
		world.setBlockState(new BlockPos(i + 5, j + 14, k + 5), JourneyBlocks.terranianLog.getDefaultState());
		world.setBlockState(new BlockPos(i + 5, j + 14, k + 6), JourneyBlocks.terranianLog.getDefaultState());
		world.setBlockState(new BlockPos(i + 5, j + 14, k + 7), JourneyBlocks.terraniaLeaves.getDefaultState());
		world.setBlockState(new BlockPos(i + 5, j + 14, k + 8), JourneyBlocks.terranianLog.getDefaultState());
		world.setBlockState(new BlockPos(i + 5, j + 14, k + 9), JourneyBlocks.terranianLog.getDefaultState());
		world.setBlockState(new BlockPos(i + 5, j + 14, k + 10), JourneyBlocks.terraniaLeaves.getDefaultState());
		world.setBlockState(new BlockPos(i + 5, j + 14, k + 11), JourneyBlocks.terraniaLeaves.getDefaultState());
		world.setBlockState(new BlockPos(i + 5, j + 14, k + 12), JourneyBlocks.terraniaLeaves.getDefaultState());
		world.setBlockState(new BlockPos(i + 5, j + 14, k + 13), JourneyBlocks.terraniaLeaves.getDefaultState());
		world.setBlockState(new BlockPos(i + 5, j + 15, k + 5), JourneyBlocks.terranianLog.getDefaultState());
		world.setBlockState(new BlockPos(i + 5, j + 15, k + 6), JourneyBlocks.terranianLog.getDefaultState());
		world.setBlockState(new BlockPos(i + 5, j + 15, k + 8), JourneyBlocks.terraniaLeaves.getDefaultState());
		world.setBlockState(new BlockPos(i + 5, j + 15, k + 9), JourneyBlocks.terraniaLeaves.getDefaultState());
		world.setBlockState(new BlockPos(i + 5, j + 15, k + 10), JourneyBlocks.terranianLog.getDefaultState());
		world.setBlockState(new BlockPos(i + 5, j + 15, k + 11), JourneyBlocks.terraniaLeaves.getDefaultState());
		world.setBlockState(new BlockPos(i + 5, j + 15, k + 12), JourneyBlocks.terraniaLeaves.getDefaultState());
		world.setBlockState(new BlockPos(i + 5, j + 16, k + 5), JourneyBlocks.terranianLog.getDefaultState());
		world.setBlockState(new BlockPos(i + 5, j + 16, k + 6), JourneyBlocks.terranianLog.getDefaultState());
		world.setBlockState(new BlockPos(i + 5, j + 16, k + 9), JourneyBlocks.terraniaLeaves.getDefaultState());
		world.setBlockState(new BlockPos(i + 5, j + 16, k + 10), JourneyBlocks.terraniaLeaves.getDefaultState());
		world.setBlockState(new BlockPos(i + 5, j + 16, k + 11), JourneyBlocks.terraniaLeaves.getDefaultState());
		world.setBlockState(new BlockPos(i + 5, j + 17, k + 5), JourneyBlocks.terranianLog.getDefaultState());
		world.setBlockState(new BlockPos(i + 5, j + 17, k + 6), JourneyBlocks.terranianLog.getDefaultState());
		world.setBlockState(new BlockPos(i + 5, j + 18, k + 5), JourneyBlocks.terranianLog.getDefaultState());
		world.setBlockState(new BlockPos(i + 5, j + 18, k + 6), JourneyBlocks.terranianLog.getDefaultState());
		world.setBlockState(new BlockPos(i + 5, j + 19, k + 4), JourneyBlocks.terraniaLeaves.getDefaultState());
		world.setBlockState(new BlockPos(i + 5, j + 19, k + 5), JourneyBlocks.terranianLog.getDefaultState());
		world.setBlockState(new BlockPos(i + 5, j + 19, k + 6), JourneyBlocks.terranianLog.getDefaultState());
		world.setBlockState(new BlockPos(i + 5, j + 20, k + 5), JourneyBlocks.terranianLog.getDefaultState());
		world.setBlockState(new BlockPos(i + 5, j + 20, k + 6), JourneyBlocks.terranianLog.getDefaultState());
		world.setBlockState(new BlockPos(i + 5, j + 21, k + 5), JourneyBlocks.terranianLog.getDefaultState());
		world.setBlockState(new BlockPos(i + 5, j + 21, k + 6), JourneyBlocks.terranianLog.getDefaultState());
		world.setBlockState(new BlockPos(i + 5, j + 21, k + 7), JourneyBlocks.terraniaLeaves.getDefaultState());
		world.setBlockState(new BlockPos(i + 5, j + 22, k + 4), JourneyBlocks.terraniaLeaves.getDefaultState());
		world.setBlockState(new BlockPos(i + 5, j + 22, k + 5), JourneyBlocks.terranianLog.getDefaultState());
		world.setBlockState(new BlockPos(i + 5, j + 22, k + 6), JourneyBlocks.terranianLog.getDefaultState());
		world.setBlockState(new BlockPos(i + 5, j + 22, k + 7), JourneyBlocks.terraniaLeaves.getDefaultState());
		world.setBlockState(new BlockPos(i + 5, j + 23, k + 1), JourneyBlocks.terraniaLeaves.getDefaultState());
		world.setBlockState(new BlockPos(i + 5, j + 23, k + 2), JourneyBlocks.terraniaLeaves.getDefaultState());
		world.setBlockState(new BlockPos(i + 5, j + 23, k + 3), JourneyBlocks.terraniaLeaves.getDefaultState());
		world.setBlockState(new BlockPos(i + 5, j + 23, k + 4), JourneyBlocks.terraniaLeaves.getDefaultState());
		world.setBlockState(new BlockPos(i + 5, j + 23, k + 5), JourneyBlocks.terranianLog.getDefaultState());
		world.setBlockState(new BlockPos(i + 5, j + 23, k + 6), JourneyBlocks.terranianLog.getDefaultState());
		world.setBlockState(new BlockPos(i + 5, j + 23, k + 7), JourneyBlocks.terraniaLeaves.getDefaultState());
		world.setBlockState(new BlockPos(i + 5, j + 23, k + 8), JourneyBlocks.terraniaLeaves.getDefaultState());
		world.setBlockState(new BlockPos(i + 5, j + 23, k + 9), JourneyBlocks.terraniaLeaves.getDefaultState());
		world.setBlockState(new BlockPos(i + 5, j + 23, k + 10), JourneyBlocks.terraniaLeaves.getDefaultState());
		world.setBlockState(new BlockPos(i + 5, j + 24, k + 1), JourneyBlocks.terraniaLeaves.getDefaultState());
		world.setBlockState(new BlockPos(i + 5, j + 24, k + 2), JourneyBlocks.terraniaLeaves.getDefaultState());
		world.setBlockState(new BlockPos(i + 5, j + 24, k + 3), JourneyBlocks.terraniaLeaves.getDefaultState());
		world.setBlockState(new BlockPos(i + 5, j + 24, k + 4), JourneyBlocks.terraniaLeaves.getDefaultState());
		world.setBlockState(new BlockPos(i + 5, j + 24, k + 5), JourneyBlocks.terranianLog.getDefaultState());
		world.setBlockState(new BlockPos(i + 5, j + 24, k + 6), JourneyBlocks.terraniaLeaves.getDefaultState());
		world.setBlockState(new BlockPos(i + 5, j + 24, k + 7), JourneyBlocks.terraniaLeaves.getDefaultState());
		world.setBlockState(new BlockPos(i + 5, j + 24, k + 8), JourneyBlocks.terraniaLeaves.getDefaultState());
		world.setBlockState(new BlockPos(i + 5, j + 24, k + 9), JourneyBlocks.terraniaLeaves.getDefaultState());
		world.setBlockState(new BlockPos(i + 5, j + 25, k + 2), JourneyBlocks.terraniaLeaves.getDefaultState());
		world.setBlockState(new BlockPos(i + 5, j + 25, k + 3), JourneyBlocks.terraniaLeaves.getDefaultState());
		world.setBlockState(new BlockPos(i + 5, j + 25, k + 4), JourneyBlocks.terraniaLeaves.getDefaultState());
				world.setBlockState(new BlockPos(i + 5, j + 25, k + 5), JourneyBlocks.terranianLog.getDefaultState());
				world.setBlockState(new BlockPos(i + 5, j + 25, k + 6), JourneyBlocks.terranianLog.getDefaultState());
		world.setBlockState(new BlockPos(i + 5, j + 25, k + 7), JourneyBlocks.terraniaLeaves.getDefaultState());
		world.setBlockState(new BlockPos(i + 5, j + 25, k + 8), JourneyBlocks.terraniaLeaves.getDefaultState());
		world.setBlockState(new BlockPos(i + 5, j + 25, k + 9), JourneyBlocks.terraniaLeaves.getDefaultState());
		world.setBlockState(new BlockPos(i + 5, j + 25, k + 10), JourneyBlocks.terraniaLeaves.getDefaultState());
		world.setBlockState(new BlockPos(i + 5, j + 26, k + 5), JourneyBlocks.terranianLog.getDefaultState());
		world.setBlockState(new BlockPos(i + 5, j + 26, k + 6), JourneyBlocks.terranianLog.getDefaultState());
		world.setBlockState(new BlockPos(i + 5, j + 26, k + 7), JourneyBlocks.terraniaLeaves.getDefaultState());
		world.setBlockState(new BlockPos(i + 5, j + 27, k + 3), JourneyBlocks.terraniaLeaves.getDefaultState());
		world.setBlockState(new BlockPos(i + 5, j + 27, k + 4), JourneyBlocks.terraniaLeaves.getDefaultState());
		world.setBlockState(new BlockPos(i + 5, j + 27, k + 5), JourneyBlocks.terranianLog.getDefaultState());
		world.setBlockState(new BlockPos(i + 5, j + 27, k + 6), JourneyBlocks.terranianLog.getDefaultState());
		world.setBlockState(new BlockPos(i + 5, j + 27, k + 7), JourneyBlocks.terraniaLeaves.getDefaultState());
		world.setBlockState(new BlockPos(i + 5, j + 28, k + 4), JourneyBlocks.terraniaLeaves.getDefaultState());
		world.setBlockState(new BlockPos(i + 5, j + 28, k + 5), JourneyBlocks.terranianLog.getDefaultState());
		world.setBlockState(new BlockPos(i + 5, j + 28, k + 6), JourneyBlocks.terranianLog.getDefaultState());
		world.setBlockState(new BlockPos(i + 5, j + 28, k + 7), JourneyBlocks.terraniaLeaves.getDefaultState());
		world.setBlockState(new BlockPos(i + 5, j + 29, k + 5), JourneyBlocks.terranianLog.getDefaultState());
		world.setBlockState(new BlockPos(i + 5, j + 29, k + 6), JourneyBlocks.terranianLog.getDefaultState());
		world.setBlockState(new BlockPos(i + 5, j + 30, k + 5), JourneyBlocks.terranianLog.getDefaultState());
		world.setBlockState(new BlockPos(i + 5, j + 30, k + 6), JourneyBlocks.terranianLog.getDefaultState());
		world.setBlockState(new BlockPos(i + 5, j + 30, k + 7), JourneyBlocks.terraniaLeaves.getDefaultState());
		world.setBlockState(new BlockPos(i + 5, j + 31, k + 5), JourneyBlocks.terranianLog.getDefaultState());
		world.setBlockState(new BlockPos(i + 5, j + 31, k + 6), JourneyBlocks.terranianLog.getDefaultState());
		world.setBlockState(new BlockPos(i + 5, j + 32, k + 4), JourneyBlocks.terraniaLeaves.getDefaultState());
		world.setBlockState(new BlockPos(i + 5, j + 32, k + 5), JourneyBlocks.terranianLog.getDefaultState());
		world.setBlockState(new BlockPos(i + 5, j + 32, k + 6), JourneyBlocks.terranianLog.getDefaultState());
		world.setBlockState(new BlockPos(i + 5, j + 32, k + 7), JourneyBlocks.terraniaLeaves.getDefaultState());
		world.setBlockState(new BlockPos(i + 5, j + 33, k + 5), JourneyBlocks.terranianLog.getDefaultState());
		world.setBlockState(new BlockPos(i + 5, j + 33, k + 6), JourneyBlocks.terranianLog.getDefaultState());
		world.setBlockState(new BlockPos(i + 5, j + 33, k + 7), JourneyBlocks.terraniaLeaves.getDefaultState());
		world.setBlockState(new BlockPos(i + 5, j + 34, k + 5), JourneyBlocks.terranianLog.getDefaultState());
		world.setBlockState(new BlockPos(i + 5, j + 34, k + 6), JourneyBlocks.terranianLog.getDefaultState());
		world.setBlockState(new BlockPos(i + 5, j + 34, k + 7), JourneyBlocks.terraniaLeaves.getDefaultState());
		world.setBlockState(new BlockPos(i + 5, j + 35, k + 3), JourneyBlocks.terraniaLeaves.getDefaultState());
		world.setBlockState(new BlockPos(i + 5, j + 35, k + 4), JourneyBlocks.terraniaLeaves.getDefaultState());
		world.setBlockState(new BlockPos(i + 5, j + 35, k + 5), JourneyBlocks.terranianLog.getDefaultState());
		world.setBlockState(new BlockPos(i + 5, j + 35, k + 6), JourneyBlocks.terranianLog.getDefaultState());
		world.setBlockState(new BlockPos(i + 5, j + 36, k + 5), JourneyBlocks.terranianLog.getDefaultState());
		world.setBlockState(new BlockPos(i + 5, j + 36, k + 6), JourneyBlocks.terranianLog.getDefaultState());
		world.setBlockState(new BlockPos(i + 5, j + 37, k + 5), JourneyBlocks.terranianLog.getDefaultState());
		world.setBlockState(new BlockPos(i + 5, j + 37, k + 6), JourneyBlocks.terranianLog.getDefaultState());
		world.setBlockState(new BlockPos(i + 5, j + 38, k + 5), JourneyBlocks.terranianLog.getDefaultState());
		world.setBlockState(new BlockPos(i + 5, j + 38, k + 6), JourneyBlocks.terranianLog.getDefaultState());
		world.setBlockState(new BlockPos(i + 5, j + 39, k + 5), JourneyBlocks.terranianLog.getDefaultState());
		world.setBlockState(new BlockPos(i + 5, j + 39, k + 6), JourneyBlocks.terranianLog.getDefaultState());
		world.setBlockState(new BlockPos(i + 5, j + 39, k + 7), JourneyBlocks.terraniaLeaves.getDefaultState());
		world.setBlockState(new BlockPos(i + 5, j + 40, k + 5), JourneyBlocks.terranianLog.getDefaultState());
		world.setBlockState(new BlockPos(i + 5, j + 40, k + 6), JourneyBlocks.terranianLog.getDefaultState());
		world.setBlockState(new BlockPos(i + 5, j + 41, k + 0), JourneyBlocks.terraniaLeaves.getDefaultState());
		world.setBlockState(new BlockPos(i + 5, j + 41, k + 1), JourneyBlocks.terraniaLeaves.getDefaultState());
		world.setBlockState(new BlockPos(i + 5, j + 41, k + 2), JourneyBlocks.terraniaLeaves.getDefaultState());
		world.setBlockState(new BlockPos(i + 5, j + 41, k + 3), JourneyBlocks.terraniaLeaves.getDefaultState());
		world.setBlockState(new BlockPos(i + 5, j + 41, k + 4), JourneyBlocks.terranianLog.getDefaultState());
		world.setBlockState(new BlockPos(i + 5, j + 41, k + 5), JourneyBlocks.terranianLog.getDefaultState());
		world.setBlockState(new BlockPos(i + 5, j + 41, k + 6), JourneyBlocks.terranianLog.getDefaultState());
		world.setBlockState(new BlockPos(i + 5, j + 41, k + 7), JourneyBlocks.terraniaLeaves.getDefaultState());
		world.setBlockState(new BlockPos(i + 5, j + 42, k + 1), JourneyBlocks.terraniaLeaves.getDefaultState());
		world.setBlockState(new BlockPos(i + 5, j + 42, k + 2), JourneyBlocks.terraniaLeaves.getDefaultState());
		world.setBlockState(new BlockPos(i + 5, j + 42, k + 3), JourneyBlocks.terranianLog.getDefaultState());
		world.setBlockState(new BlockPos(i + 5, j + 42, k + 4), JourneyBlocks.terraniaLeaves.getDefaultState());
		world.setBlockState(new BlockPos(i + 5, j + 42, k + 5), JourneyBlocks.terranianLog.getDefaultState());
		world.setBlockState(new BlockPos(i + 5, j + 42, k + 6), JourneyBlocks.terranianLog.getDefaultState());
		world.setBlockState(new BlockPos(i + 5, j + 43, k + 2), JourneyBlocks.terraniaLeaves.getDefaultState());
		world.setBlockState(new BlockPos(i + 5, j + 43, k + 3), JourneyBlocks.terraniaLeaves.getDefaultState());
		world.setBlockState(new BlockPos(i + 5, j + 43, k + 4), JourneyBlocks.terraniaLeaves.getDefaultState());
		world.setBlockState(new BlockPos(i + 5, j + 43, k + 5), JourneyBlocks.terranianLog.getDefaultState());
		world.setBlockState(new BlockPos(i + 5, j + 43, k + 6), JourneyBlocks.terranianLog.getDefaultState());
		world.setBlockState(new BlockPos(i + 5, j + 44, k + 0), JourneyBlocks.terraniaLeaves.getDefaultState());
		world.setBlockState(new BlockPos(i + 5, j + 44, k + 1), JourneyBlocks.terraniaLeaves.getDefaultState());
		world.setBlockState(new BlockPos(i + 5, j + 44, k + 2), JourneyBlocks.terraniaLeaves.getDefaultState());
		world.setBlockState(new BlockPos(i + 5, j + 44, k + 3), JourneyBlocks.terraniaLeaves.getDefaultState());
		world.setBlockState(new BlockPos(i + 5, j + 44, k + 4), JourneyBlocks.terraniaLeaves.getDefaultState());
		world.setBlockState(new BlockPos(i + 5, j + 44, k + 5), JourneyBlocks.terranianLog.getDefaultState());
		world.setBlockState(new BlockPos(i + 5, j + 44, k + 6), JourneyBlocks.terranianLog.getDefaultState());
		world.setBlockState(new BlockPos(i + 5, j + 44, k + 7), JourneyBlocks.terraniaLeaves.getDefaultState());
		world.setBlockState(new BlockPos(i + 5, j + 44, k + 8), JourneyBlocks.terraniaLeaves.getDefaultState());
		world.setBlockState(new BlockPos(i + 5, j + 44, k + 9), JourneyBlocks.terraniaLeaves.getDefaultState());
		world.setBlockState(new BlockPos(i + 5, j + 44, k + 10), JourneyBlocks.terraniaLeaves.getDefaultState());
		world.setBlockState(new BlockPos(i + 5, j + 44, k + 11), JourneyBlocks.terraniaLeaves.getDefaultState());
		world.setBlockState(new BlockPos(i + 5, j + 45, k + 1), JourneyBlocks.terraniaLeaves.getDefaultState());
		world.setBlockState(new BlockPos(i + 5, j + 45, k + 2), JourneyBlocks.terraniaLeaves.getDefaultState());
		world.setBlockState(new BlockPos(i + 5, j + 45, k + 3), JourneyBlocks.terraniaLeaves.getDefaultState());
		world.setBlockState(new BlockPos(i + 5, j + 45, k + 4), JourneyBlocks.terraniaLeaves.getDefaultState());
		world.setBlockState(new BlockPos(i + 5, j + 45, k + 5), JourneyBlocks.terranianLog.getDefaultState());
		world.setBlockState(new BlockPos(i + 5, j + 45, k + 6), JourneyBlocks.terraniaLeaves.getDefaultState());
		world.setBlockState(new BlockPos(i + 5, j + 45, k + 7), JourneyBlocks.terraniaLeaves.getDefaultState());
		world.setBlockState(new BlockPos(i + 5, j + 45, k + 8), JourneyBlocks.terraniaLeaves.getDefaultState());
		world.setBlockState(new BlockPos(i + 5, j + 45, k + 9), JourneyBlocks.terraniaLeaves.getDefaultState());
		world.setBlockState(new BlockPos(i + 5, j + 45, k + 10), JourneyBlocks.terraniaLeaves.getDefaultState());
		world.setBlockState(new BlockPos(i + 5, j + 46, k + 2), JourneyBlocks.terraniaLeaves.getDefaultState());
		world.setBlockState(new BlockPos(i + 5, j + 46, k + 3), JourneyBlocks.terraniaLeaves.getDefaultState());
		world.setBlockState(new BlockPos(i + 5, j + 46, k + 4), JourneyBlocks.terraniaLeaves.getDefaultState());
		world.setBlockState(new BlockPos(i + 5, j + 46, k + 5), JourneyBlocks.terraniaLeaves.getDefaultState());
		world.setBlockState(new BlockPos(i + 5, j + 46, k + 6), JourneyBlocks.terraniaLeaves.getDefaultState());
		world.setBlockState(new BlockPos(i + 5, j + 46, k + 7), JourneyBlocks.terraniaLeaves.getDefaultState());
		world.setBlockState(new BlockPos(i + 5, j + 46, k + 8), JourneyBlocks.terraniaLeaves.getDefaultState());
		world.setBlockState(new BlockPos(i + 5, j + 46, k + 9), JourneyBlocks.terraniaLeaves.getDefaultState());
				world.setBlockState(new BlockPos(i + 5, j + 47, k + 5), JourneyBlocks.purplianSpawner.getDefaultState());
				world.setBlockState(new BlockPos(i + 5, j + 47, k + 6), JourneyBlocks.purplianSpawner.getDefaultState());
		world.setBlockState(new BlockPos(i + 6, j + 0, k + 0), JourneyBlocks.terranianLog.getDefaultState());
		world.setBlockState(new BlockPos(i + 6, j + 0, k + 3), JourneyBlocks.terranianLog.getDefaultState());
		world.setBlockState(new BlockPos(i + 6, j + 0, k + 5), JourneyBlocks.terranianLog.getDefaultState());
		world.setBlockState(new BlockPos(i + 6, j + 0, k + 6), JourneyBlocks.terranianLog.getDefaultState());
		world.setBlockState(new BlockPos(i + 6, j + 0, k + 8), JourneyBlocks.terranianLog.getDefaultState());
		world.setBlockState(new BlockPos(i + 6, j + 0, k + 10), JourneyBlocks.terranianLog.getDefaultState());
		world.setBlockState(new BlockPos(i + 6, j + 1, k + 5), JourneyBlocks.terranianLog.getDefaultState());
		world.setBlockState(new BlockPos(i + 6, j + 1, k + 6), JourneyBlocks.terranianLog.getDefaultState());
		world.setBlockState(new BlockPos(i + 6, j + 2, k + 5), JourneyBlocks.terranianLog.getDefaultState());
		world.setBlockState(new BlockPos(i + 6, j + 2, k + 6), JourneyBlocks.terranianLog.getDefaultState());
		world.setBlockState(new BlockPos(i + 6, j + 3, k + 5), JourneyBlocks.terranianLog.getDefaultState());
		world.setBlockState(new BlockPos(i + 6, j + 3, k + 6), JourneyBlocks.terranianLog.getDefaultState());
		world.setBlockState(new BlockPos(i + 6, j + 4, k + 5), JourneyBlocks.terranianLog.getDefaultState());
		world.setBlockState(new BlockPos(i + 6, j + 4, k + 6), JourneyBlocks.terranianLog.getDefaultState());
		world.setBlockState(new BlockPos(i + 6, j + 5, k + 5), JourneyBlocks.terranianLog.getDefaultState());
		world.setBlockState(new BlockPos(i + 6, j + 5, k + 6), JourneyBlocks.terranianLog.getDefaultState());
		world.setBlockState(new BlockPos(i + 6, j + 6, k + 5), JourneyBlocks.terranianLog.getDefaultState());
		world.setBlockState(new BlockPos(i + 6, j + 6, k + 6), JourneyBlocks.terranianLog.getDefaultState());
		world.setBlockState(new BlockPos(i + 6, j + 7, k + 5), JourneyBlocks.terranianLog.getDefaultState());
		world.setBlockState(new BlockPos(i + 6, j + 7, k + 6), JourneyBlocks.terranianLog.getDefaultState());
		world.setBlockState(new BlockPos(i + 6, j + 8, k + 5), JourneyBlocks.terranianLog.getDefaultState());
		world.setBlockState(new BlockPos(i + 6, j + 8, k + 6), JourneyBlocks.terranianLog.getDefaultState());
		world.setBlockState(new BlockPos(i + 6, j + 9, k + 5), JourneyBlocks.terranianLog.getDefaultState());
		world.setBlockState(new BlockPos(i + 6, j + 9, k + 6), JourneyBlocks.terranianLog.getDefaultState());
		world.setBlockState(new BlockPos(i + 6, j + 10, k + 5), JourneyBlocks.terranianLog.getDefaultState());
		world.setBlockState(new BlockPos(i + 6, j + 10, k + 6), JourneyBlocks.terranianLog.getDefaultState());
		world.setBlockState(new BlockPos(i + 6, j + 11, k + 5), JourneyBlocks.terranianLog.getDefaultState());
		world.setBlockState(new BlockPos(i + 6, j + 11, k + 6), JourneyBlocks.terranianLog.getDefaultState());
		world.setBlockState(new BlockPos(i + 6, j + 12, k + 5), JourneyBlocks.terranianLog.getDefaultState());
		world.setBlockState(new BlockPos(i + 6, j + 12, k + 6), JourneyBlocks.terranianLog.getDefaultState());
		world.setBlockState(new BlockPos(i + 6, j + 13, k + 5), JourneyBlocks.terranianLog.getDefaultState());
		world.setBlockState(new BlockPos(i + 6, j + 13, k + 6), JourneyBlocks.terranianLog.getDefaultState());
		world.setBlockState(new BlockPos(i + 6, j + 13, k + 7), JourneyBlocks.terranianLog.getDefaultState());
		world.setBlockState(new BlockPos(i + 6, j + 13, k + 9), JourneyBlocks.terraniaLeaves.getDefaultState());
		world.setBlockState(new BlockPos(i + 6, j + 14, k + 5), JourneyBlocks.terranianLog.getDefaultState());
		world.setBlockState(new BlockPos(i + 6, j + 14, k + 6), JourneyBlocks.terranianLog.getDefaultState());
		world.setBlockState(new BlockPos(i + 6, j + 14, k + 8), JourneyBlocks.terraniaLeaves.getDefaultState());
		world.setBlockState(new BlockPos(i + 6, j + 14, k + 9), JourneyBlocks.terraniaLeaves.getDefaultState());
		world.setBlockState(new BlockPos(i + 6, j + 14, k + 10), JourneyBlocks.terraniaLeaves.getDefaultState());
		world.setBlockState(new BlockPos(i + 6, j + 14, k + 11), JourneyBlocks.terraniaLeaves.getDefaultState());
		world.setBlockState(new BlockPos(i + 6, j + 14, k + 12), JourneyBlocks.terraniaLeaves.getDefaultState());
		world.setBlockState(new BlockPos(i + 6, j + 15, k + 5), JourneyBlocks.terranianLog.getDefaultState());
		world.setBlockState(new BlockPos(i + 6, j + 15, k + 6), JourneyBlocks.terranianLog.getDefaultState());
		world.setBlockState(new BlockPos(i + 6, j + 15, k + 9), JourneyBlocks.terraniaLeaves.getDefaultState());
		world.setBlockState(new BlockPos(i + 6, j + 15, k + 10), JourneyBlocks.terraniaLeaves.getDefaultState());
		world.setBlockState(new BlockPos(i + 6, j + 15, k + 11), JourneyBlocks.terraniaLeaves.getDefaultState());
		world.setBlockState(new BlockPos(i + 6, j + 16, k + 5), JourneyBlocks.terranianLog.getDefaultState());
		world.setBlockState(new BlockPos(i + 6, j + 16, k + 6), JourneyBlocks.terranianLog.getDefaultState());
		world.setBlockState(new BlockPos(i + 6, j + 16, k + 10), JourneyBlocks.terraniaLeaves.getDefaultState());
		world.setBlockState(new BlockPos(i + 6, j + 17, k + 5), JourneyBlocks.terranianLog.getDefaultState());
		world.setBlockState(new BlockPos(i + 6, j + 17, k + 6), JourneyBlocks.terranianLog.getDefaultState());
		world.setBlockState(new BlockPos(i + 6, j + 18, k + 4), JourneyBlocks.terraniaLeaves.getDefaultState());
		world.setBlockState(new BlockPos(i + 6, j + 18, k + 5), JourneyBlocks.terranianLog.getDefaultState());
		world.setBlockState(new BlockPos(i + 6, j + 18, k + 6), JourneyBlocks.terranianLog.getDefaultState());
		world.setBlockState(new BlockPos(i + 6, j + 19, k + 4), JourneyBlocks.terraniaLeaves.getDefaultState());
		world.setBlockState(new BlockPos(i + 6, j + 19, k + 5), JourneyBlocks.terranianLog.getDefaultState());
		world.setBlockState(new BlockPos(i + 6, j + 19, k + 6), JourneyBlocks.terranianLog.getDefaultState());
		world.setBlockState(new BlockPos(i + 6, j + 19, k + 7), JourneyBlocks.terraniaLeaves.getDefaultState());
		world.setBlockState(new BlockPos(i + 6, j + 20, k + 3), JourneyBlocks.terraniaLeaves.getDefaultState());
		world.setBlockState(new BlockPos(i + 6, j + 20, k + 5), JourneyBlocks.terranianLog.getDefaultState());
		world.setBlockState(new BlockPos(i + 6, j + 20, k + 6), JourneyBlocks.terranianLog.getDefaultState());
		world.setBlockState(new BlockPos(i + 6, j + 20, k + 7), JourneyBlocks.terraniaLeaves.getDefaultState());
		world.setBlockState(new BlockPos(i + 6, j + 21, k + 5), JourneyBlocks.terranianLog.getDefaultState());
		world.setBlockState(new BlockPos(i + 6, j + 21, k + 6), JourneyBlocks.terranianLog.getDefaultState());
		world.setBlockState(new BlockPos(i + 6, j + 22, k + 5), JourneyBlocks.terranianLog.getDefaultState());
		world.setBlockState(new BlockPos(i + 6, j + 22, k + 6), JourneyBlocks.terranianLog.getDefaultState());
		world.setBlockState(new BlockPos(i + 6, j + 23, k + 0), JourneyBlocks.terraniaLeaves.getDefaultState());
		world.setBlockState(new BlockPos(i + 6, j + 23, k + 1), JourneyBlocks.terraniaLeaves.getDefaultState());
		world.setBlockState(new BlockPos(i + 6, j + 23, k + 2), JourneyBlocks.terraniaLeaves.getDefaultState());
		world.setBlockState(new BlockPos(i + 6, j + 23, k + 3), JourneyBlocks.terraniaLeaves.getDefaultState());
		world.setBlockState(new BlockPos(i + 6, j + 23, k + 4), JourneyBlocks.terraniaLeaves.getDefaultState());
		world.setBlockState(new BlockPos(i + 6, j + 23, k + 5), JourneyBlocks.terranianLog.getDefaultState());
		world.setBlockState(new BlockPos(i + 6, j + 23, k + 6), JourneyBlocks.terranianLog.getDefaultState());
		world.setBlockState(new BlockPos(i + 6, j + 23, k + 7), JourneyBlocks.terraniaLeaves.getDefaultState());
		world.setBlockState(new BlockPos(i + 6, j + 23, k + 8), JourneyBlocks.terraniaLeaves.getDefaultState());
		world.setBlockState(new BlockPos(i + 6, j + 23, k + 9), JourneyBlocks.terraniaLeaves.getDefaultState());
		world.setBlockState(new BlockPos(i + 6, j + 23, k + 10), JourneyBlocks.terraniaLeaves.getDefaultState());
		world.setBlockState(new BlockPos(i + 6, j + 23, k + 11), JourneyBlocks.terraniaLeaves.getDefaultState());
		world.setBlockState(new BlockPos(i + 6, j + 24, k + 2), JourneyBlocks.terraniaLeaves.getDefaultState());
		world.setBlockState(new BlockPos(i + 6, j + 24, k + 3), JourneyBlocks.terraniaLeaves.getDefaultState());
		world.setBlockState(new BlockPos(i + 6, j + 24, k + 4), JourneyBlocks.terraniaLeaves.getDefaultState());
		world.setBlockState(new BlockPos(i + 6, j + 24, k + 5), JourneyBlocks.terraniaLeaves.getDefaultState());
		world.setBlockState(new BlockPos(i + 6, j + 24, k + 6), JourneyBlocks.terraniaLeaves.getDefaultState());
		world.setBlockState(new BlockPos(i + 6, j + 24, k + 7), JourneyBlocks.terraniaLeaves.getDefaultState());
		world.setBlockState(new BlockPos(i + 6, j + 24, k + 8), JourneyBlocks.terraniaLeaves.getDefaultState());
		world.setBlockState(new BlockPos(i + 6, j + 24, k + 9), JourneyBlocks.terraniaLeaves.getDefaultState());
		world.setBlockState(new BlockPos(i + 6, j + 25, k + 1), JourneyBlocks.terraniaLeaves.getDefaultState());
		world.setBlockState(new BlockPos(i + 6, j + 25, k + 2), JourneyBlocks.terraniaLeaves.getDefaultState());
		world.setBlockState(new BlockPos(i + 6, j + 25, k + 3), JourneyBlocks.terraniaLeaves.getDefaultState());
		world.setBlockState(new BlockPos(i + 6, j + 25, k + 4), JourneyBlocks.terraniaLeaves.getDefaultState());
		world.setBlockState(new BlockPos(i + 6, j + 25, k + 5), JourneyBlocks.terranianLog.getDefaultState());
		world.setBlockState(new BlockPos(i + 6, j + 25, k + 6), JourneyBlocks.terranianLog.getDefaultState());
		world.setBlockState(new BlockPos(i + 6, j + 25, k + 7), JourneyBlocks.terraniaLeaves.getDefaultState());
		world.setBlockState(new BlockPos(i + 6, j + 25, k + 8), JourneyBlocks.terraniaLeaves.getDefaultState());
		world.setBlockState(new BlockPos(i + 6, j + 25, k + 9), JourneyBlocks.terraniaLeaves.getDefaultState());
		world.setBlockState(new BlockPos(i + 6, j + 26, k + 4), JourneyBlocks.terraniaLeaves.getDefaultState());
		world.setBlockState(new BlockPos(i + 6, j + 26, k + 5), JourneyBlocks.terranianLog.getDefaultState());
		world.setBlockState(new BlockPos(i + 6, j + 26, k + 6), JourneyBlocks.terranianLog.getDefaultState());
		world.setBlockState(new BlockPos(i + 6, j + 26, k + 7), JourneyBlocks.terraniaLeaves.getDefaultState());
		world.setBlockState(new BlockPos(i + 6, j + 27, k + 4), JourneyBlocks.terraniaLeaves.getDefaultState());
		world.setBlockState(new BlockPos(i + 6, j + 27, k + 5), JourneyBlocks.terranianLog.getDefaultState());
		world.setBlockState(new BlockPos(i + 6, j + 27, k + 6), JourneyBlocks.terranianLog.getDefaultState());
		world.setBlockState(new BlockPos(i + 6, j + 27, k + 7), JourneyBlocks.terraniaLeaves.getDefaultState());
		world.setBlockState(new BlockPos(i + 6, j + 28, k + 5), JourneyBlocks.terranianLog.getDefaultState());
		world.setBlockState(new BlockPos(i + 6, j + 28, k + 6), JourneyBlocks.terranianLog.getDefaultState());
		world.setBlockState(new BlockPos(i + 6, j + 29, k + 4), JourneyBlocks.terraniaLeaves.getDefaultState());
		world.setBlockState(new BlockPos(i + 6, j + 29, k + 5), JourneyBlocks.terranianLog.getDefaultState());
		world.setBlockState(new BlockPos(i + 6, j + 29, k + 6), JourneyBlocks.terranianLog.getDefaultState());
		world.setBlockState(new BlockPos(i + 6, j + 29, k + 7), JourneyBlocks.terraniaLeaves.getDefaultState());
		world.setBlockState(new BlockPos(i + 6, j + 30, k + 5), JourneyBlocks.terranianLog.getDefaultState());
		world.setBlockState(new BlockPos(i + 6, j + 30, k + 6), JourneyBlocks.terranianLog.getDefaultState());
		world.setBlockState(new BlockPos(i + 6, j + 31, k + 5), JourneyBlocks.terranianLog.getDefaultState());
		world.setBlockState(new BlockPos(i + 6, j + 31, k + 6), JourneyBlocks.terranianLog.getDefaultState());
		world.setBlockState(new BlockPos(i + 6, j + 32, k + 4), JourneyBlocks.terraniaLeaves.getDefaultState());
		world.setBlockState(new BlockPos(i + 6, j + 32, k + 5), JourneyBlocks.terranianLog.getDefaultState());
		world.setBlockState(new BlockPos(i + 6, j + 32, k + 6), JourneyBlocks.terranianLog.getDefaultState());
		world.setBlockState(new BlockPos(i + 6, j + 33, k + 5), JourneyBlocks.terranianLog.getDefaultState());
		world.setBlockState(new BlockPos(i + 6, j + 33, k + 6), JourneyBlocks.terranianLog.getDefaultState());
		world.setBlockState(new BlockPos(i + 6, j + 33, k + 7), JourneyBlocks.terraniaLeaves.getDefaultState());
		world.setBlockState(new BlockPos(i + 6, j + 34, k + 5), JourneyBlocks.terranianLog.getDefaultState());
		world.setBlockState(new BlockPos(i + 6, j + 34, k + 6), JourneyBlocks.terranianLog.getDefaultState());
		world.setBlockState(new BlockPos(i + 6, j + 35, k + 5), JourneyBlocks.terranianLog.getDefaultState());
		world.setBlockState(new BlockPos(i + 6, j + 35, k + 6), JourneyBlocks.terranianLog.getDefaultState());
		world.setBlockState(new BlockPos(i + 6, j + 35, k + 7), JourneyBlocks.terraniaLeaves.getDefaultState());
		world.setBlockState(new BlockPos(i + 6, j + 36, k + 3), JourneyBlocks.terraniaLeaves.getDefaultState());
		world.setBlockState(new BlockPos(i + 6, j + 36, k + 4), JourneyBlocks.terraniaLeaves.getDefaultState());
		world.setBlockState(new BlockPos(i + 6, j + 36, k + 5), JourneyBlocks.terranianLog.getDefaultState());
		world.setBlockState(new BlockPos(i + 6, j + 36, k + 6), JourneyBlocks.terranianLog.getDefaultState());
		world.setBlockState(new BlockPos(i + 6, j + 37, k + 5), JourneyBlocks.terranianLog.getDefaultState());
		world.setBlockState(new BlockPos(i + 6, j + 37, k + 6), JourneyBlocks.terranianLog.getDefaultState());
		world.setBlockState(new BlockPos(i + 6, j + 38, k + 4), JourneyBlocks.terraniaLeaves.getDefaultState());
		world.setBlockState(new BlockPos(i + 6, j + 38, k + 5), JourneyBlocks.terranianLog.getDefaultState());
		world.setBlockState(new BlockPos(i + 6, j + 38, k + 6), JourneyBlocks.terranianLog.getDefaultState());
		world.setBlockState(new BlockPos(i + 6, j + 39, k + 4), JourneyBlocks.terraniaLeaves.getDefaultState());
		world.setBlockState(new BlockPos(i + 6, j + 39, k + 5), JourneyBlocks.terranianLog.getDefaultState());
		world.setBlockState(new BlockPos(i + 6, j + 39, k + 6), JourneyBlocks.terranianLog.getDefaultState());
		world.setBlockState(new BlockPos(i + 6, j + 40, k + 5), JourneyBlocks.terranianLog.getDefaultState());
		world.setBlockState(new BlockPos(i + 6, j + 40, k + 6), JourneyBlocks.terranianLog.getDefaultState());
		world.setBlockState(new BlockPos(i + 6, j + 40, k + 7), JourneyBlocks.terraniaLeaves.getDefaultState());
		world.setBlockState(new BlockPos(i + 6, j + 41, k + 1), JourneyBlocks.terraniaLeaves.getDefaultState());
		world.setBlockState(new BlockPos(i + 6, j + 41, k + 2), JourneyBlocks.terraniaLeaves.getDefaultState());
		world.setBlockState(new BlockPos(i + 6, j + 41, k + 3), JourneyBlocks.terraniaLeaves.getDefaultState());
		world.setBlockState(new BlockPos(i + 6, j + 41, k + 4), JourneyBlocks.terraniaLeaves.getDefaultState());
		world.setBlockState(new BlockPos(i + 6, j + 41, k + 5), JourneyBlocks.terranianLog.getDefaultState());
		world.setBlockState(new BlockPos(i + 6, j + 41, k + 6), JourneyBlocks.terranianLog.getDefaultState());
		world.setBlockState(new BlockPos(i + 6, j + 41, k + 7), JourneyBlocks.terraniaLeaves.getDefaultState());
		world.setBlockState(new BlockPos(i + 6, j + 42, k + 2), JourneyBlocks.terraniaLeaves.getDefaultState());
		world.setBlockState(new BlockPos(i + 6, j + 42, k + 3), JourneyBlocks.terraniaLeaves.getDefaultState());
		world.setBlockState(new BlockPos(i + 6, j + 42, k + 4), JourneyBlocks.terraniaLeaves.getDefaultState());
		world.setBlockState(new BlockPos(i + 6, j + 42, k + 5), JourneyBlocks.terranianLog.getDefaultState());
		world.setBlockState(new BlockPos(i + 6, j + 42, k + 6), JourneyBlocks.terranianLog.getDefaultState());
		world.setBlockState(new BlockPos(i + 6, j + 43, k + 3), JourneyBlocks.terraniaLeaves.getDefaultState());
		world.setBlockState(new BlockPos(i + 6, j + 43, k + 5), JourneyBlocks.terranianLog.getDefaultState());
		world.setBlockState(new BlockPos(i + 6, j + 43, k + 6), JourneyBlocks.terranianLog.getDefaultState());
		world.setBlockState(new BlockPos(i + 6, j + 44, k + 0), JourneyBlocks.terraniaLeaves.getDefaultState());
		world.setBlockState(new BlockPos(i + 6, j + 44, k + 1), JourneyBlocks.terraniaLeaves.getDefaultState());
		world.setBlockState(new BlockPos(i + 6, j + 44, k + 2), JourneyBlocks.terraniaLeaves.getDefaultState());
		world.setBlockState(new BlockPos(i + 6, j + 44, k + 3), JourneyBlocks.terraniaLeaves.getDefaultState());
		world.setBlockState(new BlockPos(i + 6, j + 44, k + 4), JourneyBlocks.terraniaLeaves.getDefaultState());
		world.setBlockState(new BlockPos(i + 6, j + 44, k + 5), JourneyBlocks.terranianLog.getDefaultState());
		world.setBlockState(new BlockPos(i + 6, j + 44, k + 6), JourneyBlocks.terranianLog.getDefaultState());
		world.setBlockState(new BlockPos(i + 6, j + 44, k + 7), JourneyBlocks.terraniaLeaves.getDefaultState());
		world.setBlockState(new BlockPos(i + 6, j + 44, k + 8), JourneyBlocks.terraniaLeaves.getDefaultState());
		world.setBlockState(new BlockPos(i + 6, j + 44, k + 9), JourneyBlocks.terraniaLeaves.getDefaultState());
		world.setBlockState(new BlockPos(i + 6, j + 44, k + 10), JourneyBlocks.terraniaLeaves.getDefaultState());
		world.setBlockState(new BlockPos(i + 6, j + 44, k + 11), JourneyBlocks.terraniaLeaves.getDefaultState());
		world.setBlockState(new BlockPos(i + 6, j + 45, k + 1), JourneyBlocks.terraniaLeaves.getDefaultState());
		world.setBlockState(new BlockPos(i + 6, j + 45, k + 2), JourneyBlocks.terraniaLeaves.getDefaultState());
		world.setBlockState(new BlockPos(i + 6, j + 45, k + 3), JourneyBlocks.terraniaLeaves.getDefaultState());
		world.setBlockState(new BlockPos(i + 6, j + 45, k + 4), JourneyBlocks.terraniaLeaves.getDefaultState());
		world.setBlockState(new BlockPos(i + 6, j + 45, k + 5), JourneyBlocks.terraniaLeaves.getDefaultState());
		world.setBlockState(new BlockPos(i + 6, j + 45, k + 6), JourneyBlocks.terraniaLeaves.getDefaultState());
		world.setBlockState(new BlockPos(i + 6, j + 45, k + 7), JourneyBlocks.terraniaLeaves.getDefaultState());
		world.setBlockState(new BlockPos(i + 6, j + 45, k + 8), JourneyBlocks.terraniaLeaves.getDefaultState());
		world.setBlockState(new BlockPos(i + 6, j + 45, k + 9), JourneyBlocks.terraniaLeaves.getDefaultState());
		world.setBlockState(new BlockPos(i + 6, j + 45, k + 10), JourneyBlocks.terraniaLeaves.getDefaultState());
		world.setBlockState(new BlockPos(i + 6, j + 46, k + 2), JourneyBlocks.terraniaLeaves.getDefaultState());
		world.setBlockState(new BlockPos(i + 6, j + 46, k + 3), JourneyBlocks.terraniaLeaves.getDefaultState());
		world.setBlockState(new BlockPos(i + 6, j + 46, k + 4), JourneyBlocks.terraniaLeaves.getDefaultState());
		world.setBlockState(new BlockPos(i + 6, j + 46, k + 5), JourneyBlocks.terraniaLeaves.getDefaultState());
		world.setBlockState(new BlockPos(i + 6, j + 46, k + 6), JourneyBlocks.terraniaLeaves.getDefaultState());
		world.setBlockState(new BlockPos(i + 6, j + 46, k + 7), JourneyBlocks.terraniaLeaves.getDefaultState());
		world.setBlockState(new BlockPos(i + 6, j + 46, k + 8), JourneyBlocks.terraniaLeaves.getDefaultState());
		world.setBlockState(new BlockPos(i + 6, j + 46, k + 9), JourneyBlocks.terraniaLeaves.getDefaultState());
		world.setBlockState(new BlockPos(i + 6, j + 47, k + 5), JourneyBlocks.purplianSpawner.getDefaultState());
		world.setBlockState(new BlockPos(i + 6, j + 47, k + 6), JourneyBlocks.purplianSpawner.getDefaultState());
		world.setBlockState(new BlockPos(i + 7, j + 0, k + 1), JourneyBlocks.terranianLog.getDefaultState());
		world.setBlockState(new BlockPos(i + 7, j + 0, k + 3), JourneyBlocks.terranianLog.getDefaultState());
		world.setBlockState(new BlockPos(i + 7, j + 0, k + 6), JourneyBlocks.terranianLog.getDefaultState());
		world.setBlockState(new BlockPos(i + 7, j + 0, k + 7), JourneyBlocks.terranianLog.getDefaultState());
		world.setBlockState(new BlockPos(i + 7, j + 0, k + 8), JourneyBlocks.terranianLog.getDefaultState());
		world.setBlockState(new BlockPos(i + 7, j + 0, k + 10), JourneyBlocks.terranianLog.getDefaultState());
		world.setBlockState(new BlockPos(i + 7, j + 1, k + 7), JourneyBlocks.terranianLog.getDefaultState());
		world.setBlockState(new BlockPos(i + 7, j + 13, k + 7), JourneyBlocks.terraniaLeaves.getDefaultState());
		world.setBlockState(new BlockPos(i + 7, j + 14, k + 8), JourneyBlocks.terraniaLeaves.getDefaultState());
		world.setBlockState(new BlockPos(i + 7, j + 14, k + 9), JourneyBlocks.terraniaLeaves.getDefaultState());
		world.setBlockState(new BlockPos(i + 7, j + 14, k + 10), JourneyBlocks.terraniaLeaves.getDefaultState());
		world.setBlockState(new BlockPos(i + 7, j + 14, k + 11), JourneyBlocks.terraniaLeaves.getDefaultState());
		world.setBlockState(new BlockPos(i + 7, j + 14, k + 12), JourneyBlocks.terraniaLeaves.getDefaultState());
		world.setBlockState(new BlockPos(i + 7, j + 15, k + 10), JourneyBlocks.terraniaLeaves.getDefaultState());
		world.setBlockState(new BlockPos(i + 7, j + 17, k + 6), JourneyBlocks.terraniaLeaves.getDefaultState());
		world.setBlockState(new BlockPos(i + 7, j + 18, k + 5), JourneyBlocks.terraniaLeaves.getDefaultState());
		world.setBlockState(new BlockPos(i + 7, j + 19, k + 3), JourneyBlocks.terraniaLeaves.getDefaultState());
		world.setBlockState(new BlockPos(i + 7, j + 19, k + 4), JourneyBlocks.terranianLog.getDefaultState());
		world.setBlockState(new BlockPos(i + 7, j + 19, k + 5), JourneyBlocks.terranianLog.getDefaultState());
		world.setBlockState(new BlockPos(i + 7, j + 19, k + 6), JourneyBlocks.terraniaLeaves.getDefaultState());
		world.setBlockState(new BlockPos(i + 7, j + 20, k + 2), JourneyBlocks.terraniaLeaves.getDefaultState());
		world.setBlockState(new BlockPos(i + 7, j + 20, k + 3), JourneyBlocks.terraniaLeaves.getDefaultState());
		world.setBlockState(new BlockPos(i + 7, j + 20, k + 4), JourneyBlocks.terraniaLeaves.getDefaultState());
		world.setBlockState(new BlockPos(i + 7, j + 21, k + 3), JourneyBlocks.terraniaLeaves.getDefaultState());
		world.setBlockState(new BlockPos(i + 7, j + 21, k + 6), JourneyBlocks.terraniaLeaves.getDefaultState());
		world.setBlockState(new BlockPos(i + 7, j + 22, k + 5), JourneyBlocks.terraniaLeaves.getDefaultState());
		world.setBlockState(new BlockPos(i + 7, j + 23, k + 1), JourneyBlocks.terraniaLeaves.getDefaultState());
		world.setBlockState(new BlockPos(i + 7, j + 23, k + 2), JourneyBlocks.terraniaLeaves.getDefaultState());
		world.setBlockState(new BlockPos(i + 7, j + 23, k + 3), JourneyBlocks.terraniaLeaves.getDefaultState());
		world.setBlockState(new BlockPos(i + 7, j + 23, k + 4), JourneyBlocks.terraniaLeaves.getDefaultState());
		world.setBlockState(new BlockPos(i + 7, j + 23, k + 5), JourneyBlocks.terraniaLeaves.getDefaultState());
		world.setBlockState(new BlockPos(i + 7, j + 23, k + 6), JourneyBlocks.terraniaLeaves.getDefaultState());
		world.setBlockState(new BlockPos(i + 7, j + 23, k + 7), JourneyBlocks.terraniaLeaves.getDefaultState());
		world.setBlockState(new BlockPos(i + 7, j + 23, k + 8), JourneyBlocks.terraniaLeaves.getDefaultState());
		world.setBlockState(new BlockPos(i + 7, j + 23, k + 9), JourneyBlocks.terraniaLeaves.getDefaultState());
		world.setBlockState(new BlockPos(i + 7, j + 23, k + 10), JourneyBlocks.terraniaLeaves.getDefaultState());
		world.setBlockState(new BlockPos(i + 7, j + 23, k + 11), JourneyBlocks.terraniaLeaves.getDefaultState());
		world.setBlockState(new BlockPos(i + 7, j + 24, k + 2), JourneyBlocks.terraniaLeaves.getDefaultState());
		world.setBlockState(new BlockPos(i + 7, j + 24, k + 3), JourneyBlocks.terraniaLeaves.getDefaultState());
		world.setBlockState(new BlockPos(i + 7, j + 24, k + 4), JourneyBlocks.terraniaLeaves.getDefaultState());
		world.setBlockState(new BlockPos(i + 7, j + 24, k + 5), JourneyBlocks.terraniaLeaves.getDefaultState());
		world.setBlockState(new BlockPos(i + 7, j + 24, k + 6), JourneyBlocks.terraniaLeaves.getDefaultState());
		world.setBlockState(new BlockPos(i + 7, j + 24, k + 7), JourneyBlocks.terraniaLeaves.getDefaultState());
		world.setBlockState(new BlockPos(i + 7, j + 24, k + 8), JourneyBlocks.terraniaLeaves.getDefaultState());
		world.setBlockState(new BlockPos(i + 7, j + 24, k + 10), JourneyBlocks.terraniaLeaves.getDefaultState());
		world.setBlockState(new BlockPos(i + 7, j + 25, k + 2), JourneyBlocks.terraniaLeaves.getDefaultState());
		world.setBlockState(new BlockPos(i + 7, j + 25, k + 3), JourneyBlocks.terraniaLeaves.getDefaultState());
		world.setBlockState(new BlockPos(i + 7, j + 25, k + 4), JourneyBlocks.terraniaLeaves.getDefaultState());
		world.setBlockState(new BlockPos(i + 7, j + 25, k + 5), JourneyBlocks.terraniaLeaves.getDefaultState());
		world.setBlockState(new BlockPos(i + 7, j + 25, k + 6), JourneyBlocks.terraniaLeaves.getDefaultState());
		world.setBlockState(new BlockPos(i + 7, j + 25, k + 7), JourneyBlocks.terraniaLeaves.getDefaultState());
		world.setBlockState(new BlockPos(i + 7, j + 25, k + 8), JourneyBlocks.terraniaLeaves.getDefaultState());
		world.setBlockState(new BlockPos(i + 7, j + 25, k + 9), JourneyBlocks.terraniaLeaves.getDefaultState());
		world.setBlockState(new BlockPos(i + 7, j + 27, k + 6), JourneyBlocks.terraniaLeaves.getDefaultState());
		world.setBlockState(new BlockPos(i + 7, j + 28, k + 6), JourneyBlocks.terraniaLeaves.getDefaultState());
		world.setBlockState(new BlockPos(i + 7, j + 28, k + 7), JourneyBlocks.terraniaLeaves.getDefaultState());
		world.setBlockState(new BlockPos(i + 7, j + 29, k + 6), JourneyBlocks.terraniaLeaves.getDefaultState());
		world.setBlockState(new BlockPos(i + 7, j + 31, k + 5), JourneyBlocks.terraniaLeaves.getDefaultState());
		world.setBlockState(new BlockPos(i + 7, j + 32, k + 6), JourneyBlocks.terraniaLeaves.getDefaultState());
		world.setBlockState(new BlockPos(i + 7, j + 33, k + 6), JourneyBlocks.terraniaLeaves.getDefaultState());
		world.setBlockState(new BlockPos(i + 7, j + 35, k + 6), JourneyBlocks.terranianLog.getDefaultState());
		world.setBlockState(new BlockPos(i + 7, j + 36, k + 7), JourneyBlocks.terraniaLeaves.getDefaultState());
		world.setBlockState(new BlockPos(i + 7, j + 37, k + 5), JourneyBlocks.terraniaLeaves.getDefaultState());
		world.setBlockState(new BlockPos(i + 7, j + 38, k + 6), JourneyBlocks.terraniaLeaves.getDefaultState());
		world.setBlockState(new BlockPos(i + 7, j + 40, k + 6), JourneyBlocks.terraniaLeaves.getDefaultState());
		world.setBlockState(new BlockPos(i + 7, j + 41, k + 1), JourneyBlocks.terraniaLeaves.getDefaultState());
		world.setBlockState(new BlockPos(i + 7, j + 41, k + 2), JourneyBlocks.terraniaLeaves.getDefaultState());
		world.setBlockState(new BlockPos(i + 7, j + 41, k + 3), JourneyBlocks.terraniaLeaves.getDefaultState());
		world.setBlockState(new BlockPos(i + 7, j + 41, k + 4), JourneyBlocks.terraniaLeaves.getDefaultState());
		world.setBlockState(new BlockPos(i + 7, j + 41, k + 5), JourneyBlocks.terraniaLeaves.getDefaultState());
		world.setBlockState(new BlockPos(i + 7, j + 42, k + 3), JourneyBlocks.terraniaLeaves.getDefaultState());
		world.setBlockState(new BlockPos(i + 7, j + 44, k + 1), JourneyBlocks.terraniaLeaves.getDefaultState());
		world.setBlockState(new BlockPos(i + 7, j + 44, k + 2), JourneyBlocks.terraniaLeaves.getDefaultState());
		world.setBlockState(new BlockPos(i + 7, j + 44, k + 3), JourneyBlocks.terraniaLeaves.getDefaultState());
		world.setBlockState(new BlockPos(i + 7, j + 44, k + 4), JourneyBlocks.terraniaLeaves.getDefaultState());
		world.setBlockState(new BlockPos(i + 7, j + 44, k + 5), JourneyBlocks.terraniaLeaves.getDefaultState());
		world.setBlockState(new BlockPos(i + 7, j + 44, k + 6), JourneyBlocks.terraniaLeaves.getDefaultState());
		world.setBlockState(new BlockPos(i + 7, j + 44, k + 7), JourneyBlocks.terraniaLeaves.getDefaultState());
		world.setBlockState(new BlockPos(i + 7, j + 44, k + 8), JourneyBlocks.terraniaLeaves.getDefaultState());
		world.setBlockState(new BlockPos(i + 7, j + 44, k + 9), JourneyBlocks.terraniaLeaves.getDefaultState());
		world.setBlockState(new BlockPos(i + 7, j + 44, k + 10), JourneyBlocks.terraniaLeaves.getDefaultState());
		world.setBlockState(new BlockPos(i + 7, j + 45, k + 2), JourneyBlocks.terraniaLeaves.getDefaultState());
		world.setBlockState(new BlockPos(i + 7, j + 45, k + 3), JourneyBlocks.terraniaLeaves.getDefaultState());
		world.setBlockState(new BlockPos(i + 7, j + 45, k + 4), JourneyBlocks.terraniaLeaves.getDefaultState());
		world.setBlockState(new BlockPos(i + 7, j + 45, k + 5), JourneyBlocks.terraniaLeaves.getDefaultState());
		world.setBlockState(new BlockPos(i + 7, j + 45, k + 6), JourneyBlocks.terraniaLeaves.getDefaultState());
		world.setBlockState(new BlockPos(i + 7, j + 45, k + 7), JourneyBlocks.terraniaLeaves.getDefaultState());
		world.setBlockState(new BlockPos(i + 7, j + 45, k + 8), JourneyBlocks.terraniaLeaves.getDefaultState());
		world.setBlockState(new BlockPos(i + 7, j + 45, k + 9), JourneyBlocks.terraniaLeaves.getDefaultState());
		world.setBlockState(new BlockPos(i + 7, j + 46, k + 3), JourneyBlocks.terraniaLeaves.getDefaultState());
		world.setBlockState(new BlockPos(i + 7, j + 46, k + 4), JourneyBlocks.terraniaLeaves.getDefaultState());
		world.setBlockState(new BlockPos(i + 7, j + 46, k + 5), JourneyBlocks.terraniaLeaves.getDefaultState());
		world.setBlockState(new BlockPos(i + 7, j + 46, k + 6), JourneyBlocks.terraniaLeaves.getDefaultState());
		world.setBlockState(new BlockPos(i + 7, j + 46, k + 7), JourneyBlocks.terraniaLeaves.getDefaultState());
		world.setBlockState(new BlockPos(i + 7, j + 46, k + 8), JourneyBlocks.terraniaLeaves.getDefaultState());
		world.setBlockState(new BlockPos(i + 8, j + 0, k + 3), JourneyBlocks.terranianLog.getDefaultState());
		world.setBlockState(new BlockPos(i + 8, j + 0, k + 5), JourneyBlocks.terranianLog.getDefaultState());
		world.setBlockState(new BlockPos(i + 8, j + 0, k + 6), JourneyBlocks.terranianLog.getDefaultState());
		world.setBlockState(new BlockPos(i + 8, j + 0, k + 9), JourneyBlocks.terranianLog.getDefaultState());
		world.setBlockState(new BlockPos(i + 8, j + 1, k + 5), JourneyBlocks.terranianLog.getDefaultState());
		world.setBlockState(new BlockPos(i + 8, j + 14, k + 10), JourneyBlocks.terraniaLeaves.getDefaultState());
		world.setBlockState(new BlockPos(i + 8, j + 19, k + 4), JourneyBlocks.terraniaLeaves.getDefaultState());
		world.setBlockState(new BlockPos(i + 8, j + 20, k + 1), JourneyBlocks.terraniaLeaves.getDefaultState());
		world.setBlockState(new BlockPos(i + 8, j + 20, k + 2), JourneyBlocks.terraniaLeaves.getDefaultState());
		world.setBlockState(new BlockPos(i + 8, j + 20, k + 3), JourneyBlocks.terranianLog.getDefaultState());
		world.setBlockState(new BlockPos(i + 8, j + 20, k + 4), JourneyBlocks.terraniaLeaves.getDefaultState());
		world.setBlockState(new BlockPos(i + 8, j + 20, k + 5), JourneyBlocks.terraniaLeaves.getDefaultState());
		world.setBlockState(new BlockPos(i + 8, j + 21, k + 2), JourneyBlocks.terraniaLeaves.getDefaultState());
		world.setBlockState(new BlockPos(i + 8, j + 21, k + 3), JourneyBlocks.terraniaLeaves.getDefaultState());
		world.setBlockState(new BlockPos(i + 8, j + 21, k + 4), JourneyBlocks.terraniaLeaves.getDefaultState());
		world.setBlockState(new BlockPos(i + 8, j + 23, k + 1), JourneyBlocks.terraniaLeaves.getDefaultState());
		world.setBlockState(new BlockPos(i + 8, j + 23, k + 2), JourneyBlocks.terraniaLeaves.getDefaultState());
		world.setBlockState(new BlockPos(i + 8, j + 23, k + 3), JourneyBlocks.terraniaLeaves.getDefaultState());
		world.setBlockState(new BlockPos(i + 8, j + 23, k + 4), JourneyBlocks.terraniaLeaves.getDefaultState());
		world.setBlockState(new BlockPos(i + 8, j + 23, k + 5), JourneyBlocks.terraniaLeaves.getDefaultState());
		world.setBlockState(new BlockPos(i + 8, j + 23, k + 6), JourneyBlocks.terraniaLeaves.getDefaultState());
		world.setBlockState(new BlockPos(i + 8, j + 23, k + 7), JourneyBlocks.terraniaLeaves.getDefaultState());
		world.setBlockState(new BlockPos(i + 8, j + 23, k + 8), JourneyBlocks.terraniaLeaves.getDefaultState());
		world.setBlockState(new BlockPos(i + 8, j + 23, k + 10), JourneyBlocks.terraniaLeaves.getDefaultState());
		world.setBlockState(new BlockPos(i + 8, j + 24, k + 2), JourneyBlocks.terraniaLeaves.getDefaultState());
		world.setBlockState(new BlockPos(i + 8, j + 24, k + 4), JourneyBlocks.terraniaLeaves.getDefaultState());
		world.setBlockState(new BlockPos(i + 8, j + 24, k + 5), JourneyBlocks.terraniaLeaves.getDefaultState());
		world.setBlockState(new BlockPos(i + 8, j + 24, k + 6), JourneyBlocks.terraniaLeaves.getDefaultState());
		world.setBlockState(new BlockPos(i + 8, j + 24, k + 7), JourneyBlocks.terraniaLeaves.getDefaultState());
		world.setBlockState(new BlockPos(i + 8, j + 24, k + 9), JourneyBlocks.terraniaLeaves.getDefaultState());
		world.setBlockState(new BlockPos(i + 8, j + 25, k + 3), JourneyBlocks.terraniaLeaves.getDefaultState());
		world.setBlockState(new BlockPos(i + 8, j + 25, k + 4), JourneyBlocks.terraniaLeaves.getDefaultState());
		world.setBlockState(new BlockPos(i + 8, j + 25, k + 5), JourneyBlocks.terraniaLeaves.getDefaultState());
		world.setBlockState(new BlockPos(i + 8, j + 25, k + 6), JourneyBlocks.terraniaLeaves.getDefaultState());
		world.setBlockState(new BlockPos(i + 8, j + 25, k + 7), JourneyBlocks.terraniaLeaves.getDefaultState());
		world.setBlockState(new BlockPos(i + 8, j + 25, k + 8), JourneyBlocks.terraniaLeaves.getDefaultState());
		world.setBlockState(new BlockPos(i + 8, j + 28, k + 6), JourneyBlocks.terraniaLeaves.getDefaultState());
		world.setBlockState(new BlockPos(i + 8, j + 28, k + 7), JourneyBlocks.terraniaLeaves.getDefaultState());
		world.setBlockState(new BlockPos(i + 8, j + 36, k + 5), JourneyBlocks.terraniaLeaves.getDefaultState());
		world.setBlockState(new BlockPos(i + 8, j + 36, k + 6), JourneyBlocks.terranianLog.getDefaultState());
		world.setBlockState(new BlockPos(i + 8, j + 36, k + 7), JourneyBlocks.terraniaLeaves.getDefaultState());
		world.setBlockState(new BlockPos(i + 8, j + 36, k + 8), JourneyBlocks.terraniaLeaves.getDefaultState());
		world.setBlockState(new BlockPos(i + 8, j + 36, k + 9), JourneyBlocks.terraniaLeaves.getDefaultState());
		world.setBlockState(new BlockPos(i + 8, j + 37, k + 7), JourneyBlocks.terraniaLeaves.getDefaultState());
		world.setBlockState(new BlockPos(i + 8, j + 41, k + 3), JourneyBlocks.terraniaLeaves.getDefaultState());
		world.setBlockState(new BlockPos(i + 8, j + 44, k + 1), JourneyBlocks.terraniaLeaves.getDefaultState());
		world.setBlockState(new BlockPos(i + 8, j + 44, k + 2), JourneyBlocks.terraniaLeaves.getDefaultState());
		world.setBlockState(new BlockPos(i + 8, j + 44, k + 3), JourneyBlocks.terraniaLeaves.getDefaultState());
		world.setBlockState(new BlockPos(i + 8, j + 44, k + 4), JourneyBlocks.terraniaLeaves.getDefaultState());
		world.setBlockState(new BlockPos(i + 8, j + 44, k + 5), JourneyBlocks.terraniaLeaves.getDefaultState());
		world.setBlockState(new BlockPos(i + 8, j + 44, k + 6), JourneyBlocks.terraniaLeaves.getDefaultState());
		world.setBlockState(new BlockPos(i + 8, j + 44, k + 7), JourneyBlocks.terraniaLeaves.getDefaultState());
		world.setBlockState(new BlockPos(i + 8, j + 44, k + 8), JourneyBlocks.terraniaLeaves.getDefaultState());
		world.setBlockState(new BlockPos(i + 8, j + 44, k + 9), JourneyBlocks.terraniaLeaves.getDefaultState());
		world.setBlockState(new BlockPos(i + 8, j + 44, k + 10), JourneyBlocks.terraniaLeaves.getDefaultState());
		world.setBlockState(new BlockPos(i + 8, j + 45, k + 2), JourneyBlocks.terraniaLeaves.getDefaultState());
		world.setBlockState(new BlockPos(i + 8, j + 45, k + 3), JourneyBlocks.terraniaLeaves.getDefaultState());
		world.setBlockState(new BlockPos(i + 8, j + 45, k + 4), JourneyBlocks.terraniaLeaves.getDefaultState());
		world.setBlockState(new BlockPos(i + 8, j + 45, k + 5), JourneyBlocks.terraniaLeaves.getDefaultState());
		world.setBlockState(new BlockPos(i + 8, j + 45, k + 6), JourneyBlocks.terraniaLeaves.getDefaultState());
		world.setBlockState(new BlockPos(i + 8, j + 45, k + 7), JourneyBlocks.terraniaLeaves.getDefaultState());
		world.setBlockState(new BlockPos(i + 8, j + 45, k + 8), JourneyBlocks.terraniaLeaves.getDefaultState());
		world.setBlockState(new BlockPos(i + 8, j + 45, k + 9), JourneyBlocks.terraniaLeaves.getDefaultState());
		world.setBlockState(new BlockPos(i + 8, j + 46, k + 3), JourneyBlocks.terraniaLeaves.getDefaultState());
		world.setBlockState(new BlockPos(i + 8, j + 46, k + 4), JourneyBlocks.terraniaLeaves.getDefaultState());
		world.setBlockState(new BlockPos(i + 8, j + 46, k + 5), JourneyBlocks.terraniaLeaves.getDefaultState());
		world.setBlockState(new BlockPos(i + 8, j + 46, k + 6), JourneyBlocks.terraniaLeaves.getDefaultState());
		world.setBlockState(new BlockPos(i + 8, j + 46, k + 7), JourneyBlocks.terraniaLeaves.getDefaultState());
		world.setBlockState(new BlockPos(i + 8, j + 46, k + 8), JourneyBlocks.terraniaLeaves.getDefaultState());
		world.setBlockState(new BlockPos(i + 9, j + 0, k + 4), JourneyBlocks.terranianLog.getDefaultState());
		world.setBlockState(new BlockPos(i + 9, j + 0, k + 5), JourneyBlocks.terranianLog.getDefaultState());
		world.setBlockState(new BlockPos(i + 9, j + 0, k + 8), JourneyBlocks.terranianLog.getDefaultState());
		world.setBlockState(new BlockPos(i + 9, j + 20, k + 2), JourneyBlocks.terraniaLeaves.getDefaultState());
		world.setBlockState(new BlockPos(i + 9, j + 20, k + 3), JourneyBlocks.terraniaLeaves.getDefaultState());
		world.setBlockState(new BlockPos(i + 9, j + 20, k + 4), JourneyBlocks.terraniaLeaves.getDefaultState());
		world.setBlockState(new BlockPos(i + 9, j + 21, k + 3), JourneyBlocks.terraniaLeaves.getDefaultState());
		world.setBlockState(new BlockPos(i + 9, j + 23, k + 1), JourneyBlocks.terraniaLeaves.getDefaultState());
		world.setBlockState(new BlockPos(i + 9, j + 23, k + 4), JourneyBlocks.terraniaLeaves.getDefaultState());
		world.setBlockState(new BlockPos(i + 9, j + 23, k + 5), JourneyBlocks.terraniaLeaves.getDefaultState());
		world.setBlockState(new BlockPos(i + 9, j + 23, k + 6), JourneyBlocks.terraniaLeaves.getDefaultState());
		world.setBlockState(new BlockPos(i + 9, j + 23, k + 7), JourneyBlocks.terraniaLeaves.getDefaultState());
		world.setBlockState(new BlockPos(i + 9, j + 23, k + 8), JourneyBlocks.terraniaLeaves.getDefaultState());
		world.setBlockState(new BlockPos(i + 9, j + 23, k + 9), JourneyBlocks.terraniaLeaves.getDefaultState());
		world.setBlockState(new BlockPos(i + 9, j + 24, k + 3), JourneyBlocks.terraniaLeaves.getDefaultState());
		world.setBlockState(new BlockPos(i + 9, j + 24, k + 5), JourneyBlocks.terraniaLeaves.getDefaultState());
		world.setBlockState(new BlockPos(i + 9, j + 24, k + 6), JourneyBlocks.terraniaLeaves.getDefaultState());
		world.setBlockState(new BlockPos(i + 9, j + 24, k + 9), JourneyBlocks.terraniaLeaves.getDefaultState());
		world.setBlockState(new BlockPos(i + 9, j + 25, k + 7), JourneyBlocks.terraniaLeaves.getDefaultState());
		world.setBlockState(new BlockPos(i + 9, j + 25, k + 9), JourneyBlocks.terraniaLeaves.getDefaultState());
		world.setBlockState(new BlockPos(i + 9, j + 36, k + 5), JourneyBlocks.terraniaLeaves.getDefaultState());
		world.setBlockState(new BlockPos(i + 9, j + 36, k + 6), JourneyBlocks.terranianLog.getDefaultState());
		world.setBlockState(new BlockPos(i + 9, j + 36, k + 7), JourneyBlocks.terraniaLeaves.getDefaultState());
		world.setBlockState(new BlockPos(i + 9, j + 36, k + 8), JourneyBlocks.terraniaLeaves.getDefaultState());
		world.setBlockState(new BlockPos(i + 9, j + 36, k + 9), JourneyBlocks.terraniaLeaves.getDefaultState());
		world.setBlockState(new BlockPos(i + 9, j + 37, k + 6), JourneyBlocks.terraniaLeaves.getDefaultState());
		world.setBlockState(new BlockPos(i + 9, j + 37, k + 7), JourneyBlocks.terraniaLeaves.getDefaultState());
		world.setBlockState(new BlockPos(i + 9, j + 37, k + 8), JourneyBlocks.terraniaLeaves.getDefaultState());
		world.setBlockState(new BlockPos(i + 9, j + 38, k + 7), JourneyBlocks.terraniaLeaves.getDefaultState());
		world.setBlockState(new BlockPos(i + 9, j + 44, k + 1), JourneyBlocks.terraniaLeaves.getDefaultState());
		world.setBlockState(new BlockPos(i + 9, j + 44, k + 2), JourneyBlocks.terraniaLeaves.getDefaultState());
		world.setBlockState(new BlockPos(i + 9, j + 44, k + 3), JourneyBlocks.terraniaLeaves.getDefaultState());
		world.setBlockState(new BlockPos(i + 9, j + 44, k + 4), JourneyBlocks.terraniaLeaves.getDefaultState());
		world.setBlockState(new BlockPos(i + 9, j + 44, k + 5), JourneyBlocks.terraniaLeaves.getDefaultState());
		world.setBlockState(new BlockPos(i + 9, j + 44, k + 6), JourneyBlocks.terraniaLeaves.getDefaultState());
		world.setBlockState(new BlockPos(i + 9, j + 44, k + 7), JourneyBlocks.terraniaLeaves.getDefaultState());
		world.setBlockState(new BlockPos(i + 9, j + 44, k + 8), JourneyBlocks.terraniaLeaves.getDefaultState());
		world.setBlockState(new BlockPos(i + 9, j + 44, k + 9), JourneyBlocks.terraniaLeaves.getDefaultState());
		world.setBlockState(new BlockPos(i + 9, j + 44, k + 10), JourneyBlocks.terraniaLeaves.getDefaultState());
		world.setBlockState(new BlockPos(i + 9, j + 45, k + 3), JourneyBlocks.terraniaLeaves.getDefaultState());
		world.setBlockState(new BlockPos(i + 9, j + 45, k + 4), JourneyBlocks.terraniaLeaves.getDefaultState());
		world.setBlockState(new BlockPos(i + 9, j + 45, k + 5), JourneyBlocks.terraniaLeaves.getDefaultState());
		world.setBlockState(new BlockPos(i + 9, j + 45, k + 6), JourneyBlocks.terraniaLeaves.getDefaultState());
		world.setBlockState(new BlockPos(i + 9, j + 45, k + 7), JourneyBlocks.terraniaLeaves.getDefaultState());
		world.setBlockState(new BlockPos(i + 9, j + 45, k + 8), JourneyBlocks.terraniaLeaves.getDefaultState());
		world.setBlockState(new BlockPos(i + 9, j + 46, k + 5), JourneyBlocks.terraniaLeaves.getDefaultState());
		world.setBlockState(new BlockPos(i + 9, j + 46, k + 6), JourneyBlocks.terraniaLeaves.getDefaultState());
		world.setBlockState(new BlockPos(i + 10, j + 0, k + 7), JourneyBlocks.terranianLog.getDefaultState());
		world.setBlockState(new BlockPos(i + 10, j + 20, k + 3), JourneyBlocks.terraniaLeaves.getDefaultState());
		world.setBlockState(new BlockPos(i + 10, j + 23, k + 4), JourneyBlocks.terraniaLeaves.getDefaultState());
		world.setBlockState(new BlockPos(i + 10, j + 23, k + 5), JourneyBlocks.terraniaLeaves.getDefaultState());
		world.setBlockState(new BlockPos(i + 10, j + 23, k + 6), JourneyBlocks.terraniaLeaves.getDefaultState());
		world.setBlockState(new BlockPos(i + 10, j + 23, k + 7), JourneyBlocks.terraniaLeaves.getDefaultState());
		world.setBlockState(new BlockPos(i + 10, j + 23, k + 8), JourneyBlocks.terraniaLeaves.getDefaultState());
		world.setBlockState(new BlockPos(i + 10, j + 24, k + 7), JourneyBlocks.terraniaLeaves.getDefaultState());
		world.setBlockState(new BlockPos(i + 10, j + 36, k + 4), JourneyBlocks.terraniaLeaves.getDefaultState());
		world.setBlockState(new BlockPos(i + 10, j + 36, k + 5), JourneyBlocks.terraniaLeaves.getDefaultState());
		world.setBlockState(new BlockPos(i + 10, j + 36, k + 6), JourneyBlocks.terraniaLeaves.getDefaultState());
		world.setBlockState(new BlockPos(i + 10, j + 36, k + 7), JourneyBlocks.terraniaLeaves.getDefaultState());
		world.setBlockState(new BlockPos(i + 10, j + 36, k + 8), JourneyBlocks.terraniaLeaves.getDefaultState());
		world.setBlockState(new BlockPos(i + 10, j + 36, k + 9), JourneyBlocks.terraniaLeaves.getDefaultState());
		world.setBlockState(new BlockPos(i + 10, j + 36, k + 10), JourneyBlocks.terraniaLeaves.getDefaultState());
		world.setBlockState(new BlockPos(i + 10, j + 37, k + 5), JourneyBlocks.terraniaLeaves.getDefaultState());
		world.setBlockState(new BlockPos(i + 10, j + 37, k + 6), JourneyBlocks.terraniaLeaves.getDefaultState());
		world.setBlockState(new BlockPos(i + 10, j + 37, k + 7), JourneyBlocks.terranianLog.getDefaultState());
		world.setBlockState(new BlockPos(i + 10, j + 37, k + 8), JourneyBlocks.terraniaLeaves.getDefaultState());
		world.setBlockState(new BlockPos(i + 10, j + 37, k + 9), JourneyBlocks.terraniaLeaves.getDefaultState());
		world.setBlockState(new BlockPos(i + 10, j + 38, k + 6), JourneyBlocks.terraniaLeaves.getDefaultState());
		world.setBlockState(new BlockPos(i + 10, j + 38, k + 7), JourneyBlocks.terraniaLeaves.getDefaultState());
		world.setBlockState(new BlockPos(i + 10, j + 38, k + 8), JourneyBlocks.terraniaLeaves.getDefaultState());
		world.setBlockState(new BlockPos(i + 10, j + 44, k + 2), JourneyBlocks.terraniaLeaves.getDefaultState());
		world.setBlockState(new BlockPos(i + 10, j + 44, k + 3), JourneyBlocks.terraniaLeaves.getDefaultState());
		world.setBlockState(new BlockPos(i + 10, j + 44, k + 4), JourneyBlocks.terraniaLeaves.getDefaultState());
		world.setBlockState(new BlockPos(i + 10, j + 44, k + 5), JourneyBlocks.terraniaLeaves.getDefaultState());
		world.setBlockState(new BlockPos(i + 10, j + 44, k + 6), JourneyBlocks.terraniaLeaves.getDefaultState());
		world.setBlockState(new BlockPos(i + 10, j + 44, k + 7), JourneyBlocks.terraniaLeaves.getDefaultState());
		world.setBlockState(new BlockPos(i + 10, j + 44, k + 8), JourneyBlocks.terraniaLeaves.getDefaultState());
		world.setBlockState(new BlockPos(i + 10, j + 44, k + 9), JourneyBlocks.terraniaLeaves.getDefaultState());
		world.setBlockState(new BlockPos(i + 10, j + 45, k + 5), JourneyBlocks.terraniaLeaves.getDefaultState());
		world.setBlockState(new BlockPos(i + 10, j + 45, k + 6), JourneyBlocks.terraniaLeaves.getDefaultState());
		world.setBlockState(new BlockPos(i + 11, j + 23, k + 4), JourneyBlocks.terraniaLeaves.getDefaultState());
		world.setBlockState(new BlockPos(i + 11, j + 23, k + 5), JourneyBlocks.terraniaLeaves.getDefaultState());
		world.setBlockState(new BlockPos(i + 11, j + 23, k + 6), JourneyBlocks.terraniaLeaves.getDefaultState());
		world.setBlockState(new BlockPos(i + 11, j + 23, k + 7), JourneyBlocks.terraniaLeaves.getDefaultState());
		world.setBlockState(new BlockPos(i + 11, j + 36, k + 5), JourneyBlocks.terraniaLeaves.getDefaultState());
		world.setBlockState(new BlockPos(i + 11, j + 36, k + 6), JourneyBlocks.terraniaLeaves.getDefaultState());
		world.setBlockState(new BlockPos(i + 11, j + 36, k + 7), JourneyBlocks.terraniaLeaves.getDefaultState());
		world.setBlockState(new BlockPos(i + 11, j + 36, k + 8), JourneyBlocks.terraniaLeaves.getDefaultState());
		world.setBlockState(new BlockPos(i + 11, j + 36, k + 9), JourneyBlocks.terraniaLeaves.getDefaultState());
		world.setBlockState(new BlockPos(i + 11, j + 37, k + 6), JourneyBlocks.terraniaLeaves.getDefaultState());
		world.setBlockState(new BlockPos(i + 11, j + 37, k + 7), JourneyBlocks.terraniaLeaves.getDefaultState());
		world.setBlockState(new BlockPos(i + 11, j + 37, k + 8), JourneyBlocks.terraniaLeaves.getDefaultState());
		world.setBlockState(new BlockPos(i + 11, j + 38, k + 7), JourneyBlocks.terraniaLeaves.getDefaultState());
		world.setBlockState(new BlockPos(i + 11, j + 44, k + 5), JourneyBlocks.terraniaLeaves.getDefaultState());
		world.setBlockState(new BlockPos(i + 11, j + 44, k + 6), JourneyBlocks.terraniaLeaves.getDefaultState());
		world.setBlockState(new BlockPos(i + 12, j + 36, k + 5), JourneyBlocks.terraniaLeaves.getDefaultState());
		world.setBlockState(new BlockPos(i + 12, j + 36, k + 6), JourneyBlocks.terraniaLeaves.getDefaultState());
		world.setBlockState(new BlockPos(i + 12, j + 36, k + 7), JourneyBlocks.terraniaLeaves.getDefaultState());
		world.setBlockState(new BlockPos(i + 12, j + 36, k + 8), JourneyBlocks.terraniaLeaves.getDefaultState());
		world.setBlockState(new BlockPos(i + 12, j + 36, k + 9), JourneyBlocks.terraniaLeaves.getDefaultState());
		world.setBlockState(new BlockPos(i + 12, j + 37, k + 7), JourneyBlocks.terraniaLeaves.getDefaultState());
		world.setBlockState(new BlockPos(i + 13, j + 36, k + 7), JourneyBlocks.terraniaLeaves.getDefaultState());
				world.setBlockState(new BlockPos(i + 4, j + 2, k + 5), JourneyBlocks.terraniaVine.getStateFromMeta(4));
				world.setBlockState(new BlockPos(i + 4, j + 4, k + 5), JourneyBlocks.terraniaVine.getStateFromMeta(4));
				world.setBlockState(new BlockPos(i + 4, j + 4, k + 6), JourneyBlocks.terraniaVine.getStateFromMeta(4));
				world.setBlockState(new BlockPos(i + 4, j + 5, k + 5), JourneyBlocks.terraniaVine.getStateFromMeta(4));
				world.setBlockState(new BlockPos(i + 4, j + 5, k + 6), JourneyBlocks.terraniaVine.getStateFromMeta(4));
				world.setBlockState(new BlockPos(i + 4, j + 6, k + 5), JourneyBlocks.terraniaVine.getStateFromMeta(4));
				world.setBlockState(new BlockPos(i + 4, j + 6, k + 6), JourneyBlocks.terraniaVine.getStateFromMeta(4));
				world.setBlockState(new BlockPos(i + 4, j + 7, k + 5), JourneyBlocks.terraniaVine.getStateFromMeta(4));
				world.setBlockState(new BlockPos(i + 4, j + 7, k + 6), JourneyBlocks.terraniaVine.getStateFromMeta(4));
				world.setBlockState(new BlockPos(i + 4, j + 8, k + 5), JourneyBlocks.terraniaVine.getStateFromMeta(4));
				world.setBlockState(new BlockPos(i + 4, j + 8, k + 6), JourneyBlocks.terraniaVine.getStateFromMeta(4));
				world.setBlockState(new BlockPos(i + 4, j + 9, k + 5), JourneyBlocks.terraniaVine.getStateFromMeta(4));
				world.setBlockState(new BlockPos(i + 4, j + 9, k + 6), JourneyBlocks.terraniaVine.getStateFromMeta(4));
				world.setBlockState(new BlockPos(i + 4, j + 10, k + 6), JourneyBlocks.terraniaVine.getStateFromMeta(4));
				world.setBlockState(new BlockPos(i + 4, j + 11, k + 6), JourneyBlocks.terraniaVine.getStateFromMeta(4));
				world.setBlockState(new BlockPos(i + 4, j + 13, k + 5), JourneyBlocks.terraniaVine.getStateFromMeta(4));
				world.setBlockState(new BlockPos(i + 4, j + 13, k + 6), JourneyBlocks.terraniaVine.getStateFromMeta(4));
				world.setBlockState(new BlockPos(i + 4, j + 14, k + 5), JourneyBlocks.terraniaVine.getStateFromMeta(4));
				world.setBlockState(new BlockPos(i + 4, j + 15, k + 5), JourneyBlocks.terraniaVine.getStateFromMeta(4));
				world.setBlockState(new BlockPos(i + 4, j + 15, k + 6), JourneyBlocks.terraniaVine.getStateFromMeta(4));
				world.setBlockState(new BlockPos(i + 4, j + 16, k + 6), JourneyBlocks.terraniaVine.getStateFromMeta(4));
				world.setBlockState(new BlockPos(i + 4, j + 17, k + 5), JourneyBlocks.terraniaVine.getStateFromMeta(4));
				world.setBlockState(new BlockPos(i + 4, j + 17, k + 6), JourneyBlocks.terraniaVine.getStateFromMeta(4));
				world.setBlockState(new BlockPos(i + 4, j + 18, k + 5), JourneyBlocks.terraniaVine.getStateFromMeta(4));
				world.setBlockState(new BlockPos(i + 4, j + 18, k + 6), JourneyBlocks.terraniaVine.getStateFromMeta(4));
				world.setBlockState(new BlockPos(i + 4, j + 19, k + 5), JourneyBlocks.terraniaVine.getStateFromMeta(4));
				world.setBlockState(new BlockPos(i + 4, j + 19, k + 6), JourneyBlocks.terraniaVine.getStateFromMeta(4));
				world.setBlockState(new BlockPos(i + 4, j + 21, k + 5), JourneyBlocks.terraniaVine.getStateFromMeta(4));
				world.setBlockState(new BlockPos(i + 4, j + 22, k + 6), JourneyBlocks.terraniaVine.getStateFromMeta(4));
				world.setBlockState(new BlockPos(i + 4, j + 28, k + 5), JourneyBlocks.terraniaVine.getStateFromMeta(4));
				world.setBlockState(new BlockPos(i + 4, j + 28, k + 6), JourneyBlocks.terraniaVine.getStateFromMeta(4));
				world.setBlockState(new BlockPos(i + 4, j + 31, k + 5), JourneyBlocks.terraniaVine.getStateFromMeta(4));
				world.setBlockState(new BlockPos(i + 4, j + 31, k + 6), JourneyBlocks.terraniaVine.getStateFromMeta(4));
				world.setBlockState(new BlockPos(i + 4, j + 32, k + 6), JourneyBlocks.terraniaVine.getStateFromMeta(4));
				world.setBlockState(new BlockPos(i + 4, j + 33, k + 5), JourneyBlocks.terraniaVine.getStateFromMeta(4));
				world.setBlockState(new BlockPos(i + 4, j + 34, k + 6), JourneyBlocks.terraniaVine.getStateFromMeta(4));
				world.setBlockState(new BlockPos(i + 4, j + 37, k + 5), JourneyBlocks.terraniaVine.getStateFromMeta(4));
				world.setBlockState(new BlockPos(i + 4, j + 37, k + 6), JourneyBlocks.terraniaVine.getStateFromMeta(4));
				world.setBlockState(new BlockPos(i + 4, j + 40, k + 5), JourneyBlocks.terraniaVine.getStateFromMeta(4));
				world.setBlockState(new BlockPos(i + 4, j + 41, k + 6), JourneyBlocks.terraniaVine.getStateFromMeta(4));
				world.setBlockState(new BlockPos(i + 4, j + 43, k + 5), JourneyBlocks.terraniaVine.getStateFromMeta(4));
				world.setBlockState(new BlockPos(i + 4, j + 43, k + 6), JourneyBlocks.terraniaVine.getStateFromMeta(4));
				world.setBlockState(new BlockPos(i + 5, j + 1, k + 4), JourneyBlocks.terraniaVine.getStateFromMeta(1));
				world.setBlockState(new BlockPos(i + 5, j + 2, k + 4), JourneyBlocks.terraniaVine.getStateFromMeta(1));
				world.setBlockState(new BlockPos(i + 5, j + 3, k + 7), JourneyBlocks.terraniaVine.getStateFromMeta(4));
				world.setBlockState(new BlockPos(i + 5, j + 4, k + 4), JourneyBlocks.terraniaVine.getStateFromMeta(1));
				world.setBlockState(new BlockPos(i + 5, j + 5, k + 4), JourneyBlocks.terraniaVine.getStateFromMeta(1));
				world.setBlockState(new BlockPos(i + 5, j + 5, k + 7), JourneyBlocks.terraniaVine.getStateFromMeta(4));
				world.setBlockState(new BlockPos(i + 5, j + 6, k + 4), JourneyBlocks.terraniaVine.getStateFromMeta(1));
				world.setBlockState(new BlockPos(i + 5, j + 6, k + 7), JourneyBlocks.terraniaVine.getStateFromMeta(4));
				world.setBlockState(new BlockPos(i + 5, j + 7, k + 4), JourneyBlocks.terraniaVine.getStateFromMeta(1));
				world.setBlockState(new BlockPos(i + 5, j + 7, k + 7), JourneyBlocks.terraniaVine.getStateFromMeta(4));
				world.setBlockState(new BlockPos(i + 5, j + 8, k + 4), JourneyBlocks.terraniaVine.getStateFromMeta(1));
				world.setBlockState(new BlockPos(i + 5, j + 8, k + 7), JourneyBlocks.terraniaVine.getStateFromMeta(4));
				world.setBlockState(new BlockPos(i + 5, j + 9, k + 4), JourneyBlocks.terraniaVine.getStateFromMeta(1));
				world.setBlockState(new BlockPos(i + 5, j + 9, k + 7), JourneyBlocks.terraniaVine.getStateFromMeta(4));
