package net.journey.dimension.terrania.gen;

import java.util.Random;

import net.journey.JourneyBlocks;
import net.journey.entity.mob.terrania.npc.EntityTerranianTrader;
import net.minecraft.block.Block;
import net.minecraft.block.state.IBlockState;
import net.minecraft.util.math.BlockPos;
import net.minecraft.world.World;
import net.minecraft.world.gen.feature.WorldGenerator;
import net.slayer.api.worldgen.WorldGenAPI;

public class WorldGenHollowTree extends WorldGenerator {
	@Override
	public boolean generate(World world, Random rand, BlockPos pos) {
		Block post = JourneyBlocks.terranianPost;
		Block plank = JourneyBlocks.terranianPanels;
		int i = pos.getX(), j = pos.getY(), k = pos.getZ();
		IBlockState leaves = WorldGenAPI.getTerraniaLeaves().getDefaultState(), log = WorldGenAPI.getTerranianLog(), vine = WorldGenAPI.getTerraniaVine().getDefaultState();
		i-=5;
		k-=5;
		world.setBlockState(new BlockPos(i + 1, j + 0, k + 5), JourneyBlocks.terranianDirt.getDefaultState());
		world.setBlockState(new BlockPos(i + 1, j + 1, k + 5), log);
		world.setBlockState(new BlockPos(i + 2, j + 0, k + 6), JourneyBlocks.terranianDirt.getDefaultState());
		world.setBlockState(new BlockPos(i + 2, j + 0, k + 9), log);
		world.setBlockState(new BlockPos(i + 2, j + 1, k + 6), log);
		world.setBlockState(new BlockPos(i + 2, j + 1, k + 9), log);
		world.setBlockState(new BlockPos(i + 2, j + 12, k + 7), JourneyBlocks.terraniaLeaves.getDefaultState());
		world.setBlockState(new BlockPos(i + 2, j + 22, k + 6), JourneyBlocks.terraniaLeaves.getDefaultState());
		world.setBlockState(new BlockPos(i + 2, j + 22, k + 7), JourneyBlocks.terraniaLeaves.getDefaultState());
		world.setBlockState(new BlockPos(i + 2, j + 22, k + 8), JourneyBlocks.terraniaLeaves.getDefaultState());
		world.setBlockState(new BlockPos(i + 2, j + 22, k + 9), JourneyBlocks.terraniaLeaves.getDefaultState());
		world.setBlockState(new BlockPos(i + 2, j + 23, k + 6), JourneyBlocks.terraniaLeaves.getDefaultState());
		world.setBlockState(new BlockPos(i + 2, j + 23, k + 7), JourneyBlocks.terraniaLeaves.getDefaultState());
		world.setBlockState(new BlockPos(i + 2, j + 23, k + 9), JourneyBlocks.terraniaLeaves.getDefaultState());
		world.setBlockState(new BlockPos(i + 2, j + 23, k + 10), JourneyBlocks.terraniaLeaves.getDefaultState());
		world.setBlockState(new BlockPos(i + 3, j + 0, k + 1), JourneyBlocks.terranianDirt.getDefaultState());
		world.setBlockState(new BlockPos(i + 3, j + 0, k + 6), JourneyBlocks.terranianDirt.getDefaultState());
		world.setBlockState(new BlockPos(i + 3, j + 0, k + 7), JourneyBlocks.terranianDirt.getDefaultState());
		world.setBlockState(new BlockPos(i + 3, j + 0, k + 8), JourneyBlocks.terranianDirt.getDefaultState());
		world.setBlockState(new BlockPos(i + 3, j + 1, k + 1), log);
		world.setBlockState(new BlockPos(i + 3, j + 1, k + 6), log);
		world.setBlockState(new BlockPos(i + 3, j + 1, k + 7), log);
		world.setBlockState(new BlockPos(i + 3, j + 1, k + 8), log);
		world.setBlockState(new BlockPos(i + 3, j + 2, k + 7), log);
		world.setBlockState(new BlockPos(i + 3, j + 12, k + 5), JourneyBlocks.terraniaLeaves.getDefaultState());
		world.setBlockState(new BlockPos(i + 3, j + 12, k + 6), JourneyBlocks.terraniaLeaves.getDefaultState());
		world.setBlockState(new BlockPos(i + 3, j + 12, k + 7), JourneyBlocks.terraniaLeaves.getDefaultState());
		world.setBlockState(new BlockPos(i + 3, j + 12, k + 8), JourneyBlocks.terraniaLeaves.getDefaultState());
		world.setBlockState(new BlockPos(i + 3, j + 12, k + 9), JourneyBlocks.terraniaLeaves.getDefaultState());
		world.setBlockState(new BlockPos(i + 3, j + 13, k + 7), JourneyBlocks.terraniaLeaves.getDefaultState());
		world.setBlockState(new BlockPos(i + 3, j + 22, k + 4), JourneyBlocks.terraniaLeaves.getDefaultState());
		world.setBlockState(new BlockPos(i + 3, j + 22, k + 5), JourneyBlocks.terraniaLeaves.getDefaultState());
		world.setBlockState(new BlockPos(i + 3, j + 22, k + 10), JourneyBlocks.terraniaLeaves.getDefaultState());
		world.setBlockState(new BlockPos(i + 3, j + 23, k + 6), JourneyBlocks.terraniaLeaves.getDefaultState());
		world.setBlockState(new BlockPos(i + 3, j + 23, k + 7), JourneyBlocks.terraniaLeaves.getDefaultState());
		world.setBlockState(new BlockPos(i + 3, j + 23, k + 8), JourneyBlocks.terraniaLeaves.getDefaultState());
		world.setBlockState(new BlockPos(i + 3, j + 23, k + 9), JourneyBlocks.terraniaLeaves.getDefaultState());
		world.setBlockState(new BlockPos(i + 3, j + 23, k + 10), JourneyBlocks.terraniaLeaves.getDefaultState());
		world.setBlockState(new BlockPos(i + 3, j + 24, k + 7), JourneyBlocks.terraniaLeaves.getDefaultState());
		world.setBlockState(new BlockPos(i + 4, j + 0, k + 2), JourneyBlocks.terranianDirt.getDefaultState());
		world.setBlockState(new BlockPos(i + 4, j + 0, k + 3), JourneyBlocks.terranianDirt.getDefaultState());
		world.setBlockState(new BlockPos(i + 4, j + 0, k + 5), JourneyBlocks.terranianDirt.getDefaultState());
		world.setBlockState(new BlockPos(i + 4, j + 0, k + 7), JourneyBlocks.terranianDirt.getDefaultState());
		world.setBlockState(new BlockPos(i + 4, j + 0, k + 12), JourneyBlocks.terranianDirt.getDefaultState());
		world.setBlockState(new BlockPos(i + 4, j + 1, k + 2), log);
		world.setBlockState(new BlockPos(i + 4, j + 1, k + 3), log);
		world.setBlockState(new BlockPos(i + 4, j + 1, k + 5), log);
		world.setBlockState(new BlockPos(i + 4, j + 1, k + 7), log);
		world.setBlockState(new BlockPos(i + 4, j + 1, k + 12), log);
		world.setBlockState(new BlockPos(i + 4, j + 2, k + 2), JourneyBlocks.terranianPost.getDefaultState());
		world.setBlockState(new BlockPos(i + 4, j + 2, k + 3), JourneyBlocks.terranianPost.getDefaultState());
		world.setBlockState(new BlockPos(i + 4, j + 12, k + 5), JourneyBlocks.terraniaLeaves.getDefaultState());
		world.setBlockState(new BlockPos(i + 4, j + 12, k + 6), JourneyBlocks.terraniaLeaves.getDefaultState());
		world.setBlockState(new BlockPos(i + 4, j + 12, k + 7), JourneyBlocks.terraniaLeaves.getDefaultState());
		world.setBlockState(new BlockPos(i + 4, j + 12, k + 8), JourneyBlocks.terraniaLeaves.getDefaultState());
		world.setBlockState(new BlockPos(i + 4, j + 12, k + 9), JourneyBlocks.terraniaLeaves.getDefaultState());
		world.setBlockState(new BlockPos(i + 4, j + 13, k + 6), JourneyBlocks.terraniaLeaves.getDefaultState());
		world.setBlockState(new BlockPos(i + 4, j + 13, k + 7), JourneyBlocks.terraniaLeaves.getDefaultState());
		world.setBlockState(new BlockPos(i + 4, j + 13, k + 8), JourneyBlocks.terraniaLeaves.getDefaultState());
		world.setBlockState(new BlockPos(i + 4, j + 14, k + 7), JourneyBlocks.terraniaLeaves.getDefaultState());
		world.setBlockState(new BlockPos(i + 4, j + 16, k + 11), JourneyBlocks.terraniaLeaves.getDefaultState());
		world.setBlockState(new BlockPos(i + 4, j + 22, k + 3), JourneyBlocks.terraniaLeaves.getDefaultState());
		world.setBlockState(new BlockPos(i + 4, j + 22, k + 11), JourneyBlocks.terraniaLeaves.getDefaultState());
		world.setBlockState(new BlockPos(i + 4, j + 23, k + 3), JourneyBlocks.terraniaLeaves.getDefaultState());
		world.setBlockState(new BlockPos(i + 4, j + 23, k + 4), JourneyBlocks.terraniaLeaves.getDefaultState());
		world.setBlockState(new BlockPos(i + 4, j + 23, k + 5), JourneyBlocks.terraniaLeaves.getDefaultState());
		world.setBlockState(new BlockPos(i + 4, j + 23, k + 6), JourneyBlocks.terraniaLeaves.getDefaultState());
		world.setBlockState(new BlockPos(i + 4, j + 23, k + 7), JourneyBlocks.terraniaLeaves.getDefaultState());
		world.setBlockState(new BlockPos(i + 4, j + 23, k + 8), JourneyBlocks.terraniaLeaves.getDefaultState());
		world.setBlockState(new BlockPos(i + 4, j + 23, k + 9), JourneyBlocks.terraniaLeaves.getDefaultState());
		world.setBlockState(new BlockPos(i + 4, j + 23, k + 10), JourneyBlocks.terraniaLeaves.getDefaultState());
		world.setBlockState(new BlockPos(i + 4, j + 23, k + 11), JourneyBlocks.terraniaLeaves.getDefaultState());
		world.setBlockState(new BlockPos(i + 4, j + 24, k + 6), JourneyBlocks.terraniaLeaves.getDefaultState());
		world.setBlockState(new BlockPos(i + 4, j + 24, k + 7), JourneyBlocks.terraniaLeaves.getDefaultState());
		world.setBlockState(new BlockPos(i + 4, j + 24, k + 8), JourneyBlocks.terraniaLeaves.getDefaultState());
		world.setBlockState(new BlockPos(i + 4, j + 24, k + 9), JourneyBlocks.terraniaLeaves.getDefaultState());
		world.setBlockState(new BlockPos(i + 4, j + 25, k + 7), JourneyBlocks.terraniaLeaves.getDefaultState());
		world.setBlockState(new BlockPos(i + 4, j + 25, k + 8), JourneyBlocks.terraniaLeaves.getDefaultState());
		world.setBlockState(new BlockPos(i + 4, j + 25, k + 9), JourneyBlocks.terraniaLeaves.getDefaultState());
		world.setBlockState(new BlockPos(i + 5, j + 0, k + 2), JourneyBlocks.terranianDirt.getDefaultState());
		world.setBlockState(new BlockPos(i + 5, j + 0, k + 4), JourneyBlocks.terranianDirt.getDefaultState());
		world.setBlockState(new BlockPos(i + 5, j + 0, k + 5), JourneyBlocks.terranianDirt.getDefaultState());
		world.setBlockState(new BlockPos(i + 5, j + 0, k + 6), JourneyBlocks.terranianDirt.getDefaultState());
		world.setBlockState(new BlockPos(i + 5, j + 0, k + 7), JourneyBlocks.terranianDirt.getDefaultState());
		world.setBlockState(new BlockPos(i + 5, j + 0, k + 8), JourneyBlocks.terranianDirt.getDefaultState());
		world.setBlockState(new BlockPos(i + 5, j + 0, k + 9), JourneyBlocks.terranianDirt.getDefaultState());
		world.setBlockState(new BlockPos(i + 5, j + 0, k + 10), JourneyBlocks.terranianDirt.getDefaultState());
		world.setBlockState(new BlockPos(i + 5, j + 0, k + 11), JourneyBlocks.terranianDirt.getDefaultState());
		world.setBlockState(new BlockPos(i + 5, j + 0, k + 13), JourneyBlocks.terranianDirt.getDefaultState());
		world.setBlockState(new BlockPos(i + 5, j + 1, k + 2), log);
		world.setBlockState(new BlockPos(i + 5, j + 1, k + 4), log);
		world.setBlockState(new BlockPos(i + 5, j + 1, k + 5), log);
		world.setBlockState(new BlockPos(i + 5, j + 1, k + 6), log);
		world.setBlockState(new BlockPos(i + 5, j + 1, k + 7), log);
		world.setBlockState(new BlockPos(i + 5, j + 1, k + 8), log);
		world.setBlockState(new BlockPos(i + 5, j + 1, k + 9), log);
		world.setBlockState(new BlockPos(i + 5, j + 1, k + 10), log);
		world.setBlockState(new BlockPos(i + 5, j + 1, k + 11), log);
		world.setBlockState(new BlockPos(i + 5, j + 1, k + 13), log);
		world.setBlockState(new BlockPos(i + 5, j + 2, k + 3), JourneyBlocks.terranianPost.getDefaultState());
		world.setBlockState(new BlockPos(i + 5, j + 2, k + 4), log);
		world.setBlockState(new BlockPos(i + 5, j + 2, k + 5), log);
		world.setBlockState(new BlockPos(i + 5, j + 2, k + 7), log);
		world.setBlockState(new BlockPos(i + 5, j + 2, k + 8), JourneyBlocks.terranianBars.getDefaultState());
		world.setBlockState(new BlockPos(i + 5, j + 2, k + 9), log);
		world.setBlockState(new BlockPos(i + 5, j + 2, k + 11), log);
		world.setBlockState(new BlockPos(i + 5, j + 3, k + 5), log);
		world.setBlockState(new BlockPos(i + 5, j + 3, k + 7), log);
		world.setBlockState(new BlockPos(i + 5, j + 3, k + 8), log);
		world.setBlockState(new BlockPos(i + 5, j + 4, k + 6), log);
		world.setBlockState(new BlockPos(i + 5, j + 12, k + 4), JourneyBlocks.terraniaLeaves.getDefaultState());
		world.setBlockState(new BlockPos(i + 5, j + 12, k + 5), JourneyBlocks.terraniaLeaves.getDefaultState());
		world.setBlockState(new BlockPos(i + 5, j + 12, k + 6), JourneyBlocks.terraniaLeaves.getDefaultState());
		world.setBlockState(new BlockPos(i + 5, j + 12, k + 7), JourneyBlocks.terraniaLeaves.getDefaultState());
		world.setBlockState(new BlockPos(i + 5, j + 12, k + 8), JourneyBlocks.terraniaLeaves.getDefaultState());
		world.setBlockState(new BlockPos(i + 5, j + 12, k + 9), JourneyBlocks.terraniaLeaves.getDefaultState());
		world.setBlockState(new BlockPos(i + 5, j + 12, k + 10), JourneyBlocks.terraniaLeaves.getDefaultState());
		world.setBlockState(new BlockPos(i + 5, j + 13, k + 5), JourneyBlocks.terraniaLeaves.getDefaultState());
		world.setBlockState(new BlockPos(i + 5, j + 13, k + 6), JourneyBlocks.terraniaLeaves.getDefaultState());
		world.setBlockState(new BlockPos(i + 5, j + 13, k + 7), log);
		world.setBlockState(new BlockPos(i + 5, j + 13, k + 8), JourneyBlocks.terraniaLeaves.getDefaultState());
		world.setBlockState(new BlockPos(i + 5, j + 13, k + 9), JourneyBlocks.terraniaLeaves.getDefaultState());
		world.setBlockState(new BlockPos(i + 5, j + 14, k + 6), JourneyBlocks.terraniaLeaves.getDefaultState());
		world.setBlockState(new BlockPos(i + 5, j + 14, k + 7), JourneyBlocks.terraniaLeaves.getDefaultState());
		world.setBlockState(new BlockPos(i + 5, j + 14, k + 8), JourneyBlocks.terraniaLeaves.getDefaultState());
		world.setBlockState(new BlockPos(i + 5, j + 16, k + 9), JourneyBlocks.terraniaLeaves.getDefaultState());
		world.setBlockState(new BlockPos(i + 5, j + 16, k + 10), JourneyBlocks.terraniaLeaves.getDefaultState());
		world.setBlockState(new BlockPos(i + 5, j + 16, k + 11), JourneyBlocks.terraniaLeaves.getDefaultState());
		world.setBlockState(new BlockPos(i + 5, j + 16, k + 12), JourneyBlocks.terraniaLeaves.getDefaultState());
		world.setBlockState(new BlockPos(i + 5, j + 17, k + 11), JourneyBlocks.terraniaLeaves.getDefaultState());
		world.setBlockState(new BlockPos(i + 5, j + 22, k + 2), JourneyBlocks.terraniaLeaves.getDefaultState());
		world.setBlockState(new BlockPos(i + 5, j + 22, k + 11), JourneyBlocks.terraniaLeaves.getDefaultState());
		world.setBlockState(new BlockPos(i + 5, j + 22, k + 12), JourneyBlocks.terraniaLeaves.getDefaultState());
		world.setBlockState(new BlockPos(i + 5, j + 23, k + 2), JourneyBlocks.terraniaLeaves.getDefaultState());
		world.setBlockState(new BlockPos(i + 5, j + 23, k + 3), JourneyBlocks.terraniaLeaves.getDefaultState());
		world.setBlockState(new BlockPos(i + 5, j + 23, k + 4), JourneyBlocks.terraniaLeaves.getDefaultState());
		world.setBlockState(new BlockPos(i + 5, j + 23, k + 5), JourneyBlocks.terraniaLeaves.getDefaultState());
		world.setBlockState(new BlockPos(i + 5, j + 23, k + 6), JourneyBlocks.terraniaLeaves.getDefaultState());
		world.setBlockState(new BlockPos(i + 5, j + 23, k + 7), JourneyBlocks.terraniaLeaves.getDefaultState());
		world.setBlockState(new BlockPos(i + 5, j + 23, k + 8), JourneyBlocks.terraniaLeaves.getDefaultState());
		world.setBlockState(new BlockPos(i + 5, j + 23, k + 9), JourneyBlocks.terraniaLeaves.getDefaultState());
		world.setBlockState(new BlockPos(i + 5, j + 23, k + 10), JourneyBlocks.terraniaLeaves.getDefaultState());
		world.setBlockState(new BlockPos(i + 5, j + 23, k + 11), JourneyBlocks.terraniaLeaves.getDefaultState());
		world.setBlockState(new BlockPos(i + 5, j + 24, k + 4), JourneyBlocks.terraniaLeaves.getDefaultState());
		world.setBlockState(new BlockPos(i + 5, j + 24, k + 5), JourneyBlocks.terraniaLeaves.getDefaultState());
		world.setBlockState(new BlockPos(i + 5, j + 24, k + 6), JourneyBlocks.terraniaLeaves.getDefaultState());
		world.setBlockState(new BlockPos(i + 5, j + 24, k + 7), JourneyBlocks.terraniaLeaves.getDefaultState());
		world.setBlockState(new BlockPos(i + 5, j + 24, k + 8), JourneyBlocks.terraniaLeaves.getDefaultState());
		world.setBlockState(new BlockPos(i + 5, j + 24, k + 9), JourneyBlocks.terraniaLeaves.getDefaultState());
		world.setBlockState(new BlockPos(i + 5, j + 25, k + 5), JourneyBlocks.terraniaLeaves.getDefaultState());
		world.setBlockState(new BlockPos(i + 5, j + 25, k + 6), JourneyBlocks.terraniaLeaves.getDefaultState());
		world.setBlockState(new BlockPos(i + 5, j + 25, k + 7), JourneyBlocks.terraniaLeaves.getDefaultState());
		world.setBlockState(new BlockPos(i + 5, j + 25, k + 8), JourneyBlocks.terraniaLeaves.getDefaultState());
		world.setBlockState(new BlockPos(i + 5, j + 25, k + 9), JourneyBlocks.terraniaLeaves.getDefaultState());
		world.setBlockState(new BlockPos(i + 5, j + 25, k + 10), JourneyBlocks.terraniaLeaves.getDefaultState());
		world.setBlockState(new BlockPos(i + 6, j + 0, k + 1), JourneyBlocks.terranianDirt.getDefaultState());
		world.setBlockState(new BlockPos(i + 6, j + 0, k + 2), JourneyBlocks.terranianDirt.getDefaultState());
		world.setBlockState(new BlockPos(i + 6, j + 0, k + 3), JourneyBlocks.terranianDirt.getDefaultState());
		world.setBlockState(new BlockPos(i + 6, j + 0, k + 4), JourneyBlocks.terranianDirt.getDefaultState());
		world.setBlockState(new BlockPos(i + 6, j + 0, k + 5), JourneyBlocks.terranianDirt.getDefaultState());
		world.setBlockState(new BlockPos(i + 6, j + 0, k + 6), JourneyBlocks.terranianDirt.getDefaultState());
		world.setBlockState(new BlockPos(i + 6, j + 0, k + 7), JourneyBlocks.terranianPanels.getDefaultState());
		world.setBlockState(new BlockPos(i + 6, j + 0, k + 8), JourneyBlocks.terranianPanels.getDefaultState());
		world.setBlockState(new BlockPos(i + 6, j + 0, k + 9), JourneyBlocks.terranianPanels.getDefaultState());
		world.setBlockState(new BlockPos(i + 6, j + 0, k + 10), JourneyBlocks.terranianDirt.getDefaultState());
		world.setBlockState(new BlockPos(i + 6, j + 0, k + 11), JourneyBlocks.terranianDirt.getDefaultState());
		world.setBlockState(new BlockPos(i + 6, j + 0, k + 12), JourneyBlocks.terranianDirt.getDefaultState());
		world.setBlockState(new BlockPos(i + 6, j + 0, k + 14), JourneyBlocks.terranianDirt.getDefaultState());
		world.setBlockState(new BlockPos(i + 6, j + 1, k + 1), log);
		world.setBlockState(new BlockPos(i + 6, j + 1, k + 2), log);
		world.setBlockState(new BlockPos(i + 6, j + 1, k + 3), log);
		world.setBlockState(new BlockPos(i + 6, j + 1, k + 4), log);
		world.setBlockState(new BlockPos(i + 6, j + 1, k + 5), log);
		world.setBlockState(new BlockPos(i + 6, j + 1, k + 6), log);
		world.setBlockState(new BlockPos(i + 6, j + 1, k + 10), log);
		world.setBlockState(new BlockPos(i + 6, j + 1, k + 11), log);
		world.setBlockState(new BlockPos(i + 6, j + 1, k + 12), log);
		world.setBlockState(new BlockPos(i + 6, j + 1, k + 14), log);
		world.setBlockState(new BlockPos(i + 6, j + 2, k + 2), log);
		world.setBlockState(new BlockPos(i + 6, j + 2, k + 3), JourneyBlocks.terranianPost.getDefaultState());
		world.setBlockState(new BlockPos(i + 6, j + 2, k + 4), log);
		world.setBlockState(new BlockPos(i + 6, j + 2, k + 5), log);
		world.setBlockState(new BlockPos(i + 6, j + 2, k + 6), log);
		world.setBlockState(new BlockPos(i + 6, j + 2, k + 10), log);
		world.setBlockState(new BlockPos(i + 6, j + 2, k + 11), log);
		world.setBlockState(new BlockPos(i + 6, j + 2, k + 12), log);
		world.setBlockState(new BlockPos(i + 6, j + 3, k + 3), JourneyBlocks.terranianPost.getDefaultState());
		world.setBlockState(new BlockPos(i + 6, j + 3, k + 4), log);
		world.setBlockState(new BlockPos(i + 6, j + 3, k + 5), log);
		world.setBlockState(new BlockPos(i + 6, j + 3, k + 6), log);
		world.setBlockState(new BlockPos(i + 6, j + 3, k + 8), log);
		world.setBlockState(new BlockPos(i + 6, j + 3, k + 9), log);
		world.setBlockState(new BlockPos(i + 6, j + 3, k + 10), log);
		world.setBlockState(new BlockPos(i + 6, j + 3, k + 11), log);
		world.setBlockState(new BlockPos(i + 6, j + 4, k + 3), JourneyBlocks.terranianPost.getDefaultState());
		world.setBlockState(new BlockPos(i + 6, j + 4, k + 4), JourneyBlocks.terranianPost.getDefaultState());
		world.setBlockState(new BlockPos(i + 6, j + 4, k + 5), log);
		world.setBlockState(new BlockPos(i + 6, j + 4, k + 6), log);
		world.setBlockState(new BlockPos(i + 6, j + 4, k + 7), log);
		world.setBlockState(new BlockPos(i + 6, j + 4, k + 8), log);
		world.setBlockState(new BlockPos(i + 6, j + 4, k + 10), log);
		world.setBlockState(new BlockPos(i + 6, j + 5, k + 6), log);
		world.setBlockState(new BlockPos(i + 6, j + 5, k + 8), log);
		world.setBlockState(new BlockPos(i + 6, j + 5, k + 9), log);
		world.setBlockState(new BlockPos(i + 6, j + 6, k + 8), log);
		world.setBlockState(new BlockPos(i + 6, j + 12, k + 5), JourneyBlocks.terraniaLeaves.getDefaultState());
		world.setBlockState(new BlockPos(i + 6, j + 12, k + 6), JourneyBlocks.terraniaLeaves.getDefaultState());
		world.setBlockState(new BlockPos(i + 6, j + 12, k + 7), log);
		world.setBlockState(new BlockPos(i + 6, j + 12, k + 8), JourneyBlocks.terraniaLeaves.getDefaultState());
		world.setBlockState(new BlockPos(i + 6, j + 12, k + 9), JourneyBlocks.terraniaLeaves.getDefaultState());
		world.setBlockState(new BlockPos(i + 6, j + 13, k + 6), JourneyBlocks.terraniaLeaves.getDefaultState());
		world.setBlockState(new BlockPos(i + 6, j + 13, k + 7), JourneyBlocks.terraniaLeaves.getDefaultState());
		world.setBlockState(new BlockPos(i + 6, j + 13, k + 8), JourneyBlocks.terraniaLeaves.getDefaultState());
		world.setBlockState(new BlockPos(i + 6, j + 14, k + 7), JourneyBlocks.terraniaLeaves.getDefaultState());
		world.setBlockState(new BlockPos(i + 6, j + 15, k + 9), log);
		world.setBlockState(new BlockPos(i + 6, j + 16, k + 9), JourneyBlocks.terraniaLeaves.getDefaultState());
		world.setBlockState(new BlockPos(i + 6, j + 16, k + 10), JourneyBlocks.terraniaLeaves.getDefaultState());
		world.setBlockState(new BlockPos(i + 6, j + 16, k + 11), JourneyBlocks.terraniaLeaves.getDefaultState());
		world.setBlockState(new BlockPos(i + 6, j + 16, k + 12), JourneyBlocks.terraniaLeaves.getDefaultState());
		world.setBlockState(new BlockPos(i + 6, j + 16, k + 13), JourneyBlocks.terraniaLeaves.getDefaultState());
		world.setBlockState(new BlockPos(i + 6, j + 17, k + 10), JourneyBlocks.terraniaLeaves.getDefaultState());
		world.setBlockState(new BlockPos(i + 6, j + 17, k + 11), JourneyBlocks.terraniaLeaves.getDefaultState());
		world.setBlockState(new BlockPos(i + 6, j + 17, k + 12), JourneyBlocks.terraniaLeaves.getDefaultState());
		world.setBlockState(new BlockPos(i + 6, j + 18, k + 11), JourneyBlocks.terraniaLeaves.getDefaultState());
		world.setBlockState(new BlockPos(i + 6, j + 20, k + 8), log);
		world.setBlockState(new BlockPos(i + 6, j + 21, k + 8), log);
		world.setBlockState(new BlockPos(i + 6, j + 22, k + 2), JourneyBlocks.terraniaLeaves.getDefaultState());
		world.setBlockState(new BlockPos(i + 6, j + 22, k + 8), log);
		world.setBlockState(new BlockPos(i + 6, j + 22, k + 12), JourneyBlocks.terraniaLeaves.getDefaultState());
		world.setBlockState(new BlockPos(i + 6, j + 22, k + 13), JourneyBlocks.terraniaLeaves.getDefaultState());
		world.setBlockState(new BlockPos(i + 6, j + 23, k + 2), JourneyBlocks.terraniaLeaves.getDefaultState());
		world.setBlockState(new BlockPos(i + 6, j + 23, k + 3), JourneyBlocks.terraniaLeaves.getDefaultState());
		world.setBlockState(new BlockPos(i + 6, j + 23, k + 4), JourneyBlocks.terraniaLeaves.getDefaultState());
		world.setBlockState(new BlockPos(i + 6, j + 23, k + 5), JourneyBlocks.terraniaLeaves.getDefaultState());
		world.setBlockState(new BlockPos(i + 6, j + 23, k + 6), JourneyBlocks.terraniaLeaves.getDefaultState());
		world.setBlockState(new BlockPos(i + 6, j + 23, k + 7), JourneyBlocks.terraniaLeaves.getDefaultState());
		world.setBlockState(new BlockPos(i + 6, j + 23, k + 8), JourneyBlocks.terraniaLeaves.getDefaultState());
		world.setBlockState(new BlockPos(i + 6, j + 23, k + 9), JourneyBlocks.terraniaLeaves.getDefaultState());
		world.setBlockState(new BlockPos(i + 6, j + 23, k + 10), JourneyBlocks.terraniaLeaves.getDefaultState());
		world.setBlockState(new BlockPos(i + 6, j + 23, k + 11), JourneyBlocks.terraniaLeaves.getDefaultState());
		world.setBlockState(new BlockPos(i + 6, j + 23, k + 12), JourneyBlocks.terraniaLeaves.getDefaultState());
		world.setBlockState(new BlockPos(i + 6, j + 23, k + 13), JourneyBlocks.terraniaLeaves.getDefaultState());
		world.setBlockState(new BlockPos(i + 6, j + 24, k + 4), JourneyBlocks.terraniaLeaves.getDefaultState());
		world.setBlockState(new BlockPos(i + 6, j + 24, k + 5), JourneyBlocks.terraniaLeaves.getDefaultState());
		world.setBlockState(new BlockPos(i + 6, j + 24, k + 6), JourneyBlocks.terraniaLeaves.getDefaultState());
		world.setBlockState(new BlockPos(i + 6, j + 24, k + 7), JourneyBlocks.terraniaLeaves.getDefaultState());
		world.setBlockState(new BlockPos(i + 6, j + 24, k + 8), JourneyBlocks.terraniaLeaves.getDefaultState());
		world.setBlockState(new BlockPos(i + 6, j + 24, k + 9), JourneyBlocks.terraniaLeaves.getDefaultState());
		world.setBlockState(new BlockPos(i + 6, j + 24, k + 10), JourneyBlocks.terraniaLeaves.getDefaultState());
		world.setBlockState(new BlockPos(i + 6, j + 24, k + 11), JourneyBlocks.terraniaLeaves.getDefaultState());
		world.setBlockState(new BlockPos(i + 6, j + 25, k + 5), JourneyBlocks.terraniaLeaves.getDefaultState());
		world.setBlockState(new BlockPos(i + 6, j + 25, k + 6), JourneyBlocks.terraniaLeaves.getDefaultState());
		world.setBlockState(new BlockPos(i + 6, j + 25, k + 7), JourneyBlocks.terraniaLeaves.getDefaultState());
		world.setBlockState(new BlockPos(i + 6, j + 25, k + 8), JourneyBlocks.terraniaLeaves.getDefaultState());
		world.setBlockState(new BlockPos(i + 6, j + 25, k + 9), JourneyBlocks.terraniaLeaves.getDefaultState());
		world.setBlockState(new BlockPos(i + 6, j + 25, k + 10), JourneyBlocks.terraniaLeaves.getDefaultState());
		world.setBlockState(new BlockPos(i + 6, j + 25, k + 11), JourneyBlocks.terraniaLeaves.getDefaultState());
		world.setBlockState(new BlockPos(i + 7, j + 0, k + 1), JourneyBlocks.terranianDirt.getDefaultState());
		world.setBlockState(new BlockPos(i + 7, j + 0, k + 3), JourneyBlocks.terranianDirt.getDefaultState());
		world.setBlockState(new BlockPos(i + 7, j + 0, k + 4), JourneyBlocks.terranianDirt.getDefaultState());
		world.setBlockState(new BlockPos(i + 7, j + 0, k + 5), JourneyBlocks.terranianPanels.getDefaultState());
		world.setBlockState(new BlockPos(i + 7, j + 0, k + 6), JourneyBlocks.terranianPanels.getDefaultState());
		world.setBlockState(new BlockPos(i + 7, j + 0, k + 7), JourneyBlocks.terranianPanels.getDefaultState());
		world.setBlockState(new BlockPos(i + 7, j + 0, k + 8), JourneyBlocks.terranianPanels.getDefaultState());
		world.setBlockState(new BlockPos(i + 7, j + 0, k + 9), JourneyBlocks.terranianPanels.getDefaultState());
		world.setBlockState(new BlockPos(i + 7, j + 0, k + 10), JourneyBlocks.terranianPanels.getDefaultState());
		world.setBlockState(new BlockPos(i + 7, j + 0, k + 11), JourneyBlocks.terranianDirt.getDefaultState());
		world.setBlockState(new BlockPos(i + 7, j + 1, k + 1), log);
		world.setBlockState(new BlockPos(i + 7, j + 1, k + 3), log);
		world.setBlockState(new BlockPos(i + 7, j + 1, k + 4), log);
		world.setBlockState(new BlockPos(i + 7, j + 1, k + 10), log);
		world.setBlockState(new BlockPos(i + 7, j + 1, k + 11), log);
		world.setBlockState(new BlockPos(i + 7, j + 2, k + 4), log);
		world.setBlockState(new BlockPos(i + 7, j + 2, k + 10), JourneyBlocks.terranianBars.getDefaultState());
		world.setBlockState(new BlockPos(i + 7, j + 3, k + 10), JourneyBlocks.terranianBars.getDefaultState());
		world.setBlockState(new BlockPos(i + 7, j + 4, k + 4), JourneyBlocks.terranianPost.getDefaultState());
		world.setBlockState(new BlockPos(i + 7, j + 4, k + 6), log);
		world.setBlockState(new BlockPos(i + 7, j + 4, k + 9), log);
		world.setBlockState(new BlockPos(i + 7, j + 4, k + 10), log);
		world.setBlockState(new BlockPos(i + 7, j + 5, k + 4), JourneyBlocks.terranianPost.getDefaultState());
		world.setBlockState(new BlockPos(i + 7, j + 5, k + 5), log);
		world.setBlockState(new BlockPos(i + 7, j + 5, k + 6), log);
		world.setBlockState(new BlockPos(i + 7, j + 5, k + 7), log);
		world.setBlockState(new BlockPos(i + 7, j + 5, k + 8), log);
		world.setBlockState(new BlockPos(i + 7, j + 5, k + 9), log);
		world.setBlockState(new BlockPos(i + 7, j + 5, k + 10), log);
		world.setBlockState(new BlockPos(i + 7, j + 6, k + 6), log);
		world.setBlockState(new BlockPos(i + 7, j + 6, k + 7), log);
		world.setBlockState(new BlockPos(i + 7, j + 6, k + 8), log);
		world.setBlockState(new BlockPos(i + 7, j + 7, k + 6), log);
		world.setBlockState(new BlockPos(i + 7, j + 7, k + 7), log);
		world.setBlockState(new BlockPos(i + 7, j + 7, k + 8), log);
		world.setBlockState(new BlockPos(i + 7, j + 8, k + 6), log);
		world.setBlockState(new BlockPos(i + 7, j + 8, k + 7), log);
		world.setBlockState(new BlockPos(i + 7, j + 8, k + 8), log);
		world.setBlockState(new BlockPos(i + 7, j + 9, k + 6), log);
		world.setBlockState(new BlockPos(i + 7, j + 9, k + 7), log);
		world.setBlockState(new BlockPos(i + 7, j + 9, k + 8), log);
		world.setBlockState(new BlockPos(i + 7, j + 10, k + 7), log);
		world.setBlockState(new BlockPos(i + 7, j + 10, k + 8), log);
		world.setBlockState(new BlockPos(i + 7, j + 11, k + 7), log);
		world.setBlockState(new BlockPos(i + 7, j + 11, k + 8), log);
		world.setBlockState(new BlockPos(i + 7, j + 12, k + 5), JourneyBlocks.terraniaLeaves.getDefaultState());
		world.setBlockState(new BlockPos(i + 7, j + 12, k + 6), JourneyBlocks.terraniaLeaves.getDefaultState());
		world.setBlockState(new BlockPos(i + 7, j + 12, k + 7), log);
		world.setBlockState(new BlockPos(i + 7, j + 12, k + 8), log);
		world.setBlockState(new BlockPos(i + 7, j + 12, k + 9), JourneyBlocks.terraniaLeaves.getDefaultState());
		world.setBlockState(new BlockPos(i + 7, j + 13, k + 7), log);
		world.setBlockState(new BlockPos(i + 7, j + 13, k + 8), log);
		world.setBlockState(new BlockPos(i + 7, j + 13, k + 9), log);
		world.setBlockState(new BlockPos(i + 7, j + 14, k + 7), log);
		world.setBlockState(new BlockPos(i + 7, j + 14, k + 8), log);
		world.setBlockState(new BlockPos(i + 7, j + 14, k + 9), log);
		world.setBlockState(new BlockPos(i + 7, j + 14, k + 10), log);
		world.setBlockState(new BlockPos(i + 7, j + 15, k + 7), log);
		world.setBlockState(new BlockPos(i + 7, j + 15, k + 8), log);
		world.setBlockState(new BlockPos(i + 7, j + 15, k + 9), log);
		world.setBlockState(new BlockPos(i + 7, j + 15, k + 10), log);
		world.setBlockState(new BlockPos(i + 7, j + 15, k + 11), log);
		world.setBlockState(new BlockPos(i + 7, j + 16, k + 7), log);
		world.setBlockState(new BlockPos(i + 7, j + 16, k + 8), log);
		world.setBlockState(new BlockPos(i + 7, j + 16, k + 9), JourneyBlocks.terraniaLeaves.getDefaultState());
		world.setBlockState(new BlockPos(i + 7, j + 16, k + 10), log);
		world.setBlockState(new BlockPos(i + 7, j + 16, k + 11), JourneyBlocks.terraniaLeaves.getDefaultState());
		world.setBlockState(new BlockPos(i + 7, j + 16, k + 12), JourneyBlocks.terraniaLeaves.getDefaultState());
		world.setBlockState(new BlockPos(i + 7, j + 16, k + 13), JourneyBlocks.terraniaLeaves.getDefaultState());
		world.setBlockState(new BlockPos(i + 7, j + 16, k + 14), JourneyBlocks.terraniaLeaves.getDefaultState());
		world.setBlockState(new BlockPos(i + 7, j + 17, k + 7), log);
		world.setBlockState(new BlockPos(i + 7, j + 17, k + 8), log);
		world.setBlockState(new BlockPos(i + 7, j + 17, k + 9), JourneyBlocks.terraniaLeaves.getDefaultState());
		world.setBlockState(new BlockPos(i + 7, j + 17, k + 10), JourneyBlocks.terraniaLeaves.getDefaultState());
		world.setBlockState(new BlockPos(i + 7, j + 17, k + 11), log);
		world.setBlockState(new BlockPos(i + 7, j + 17, k + 12), JourneyBlocks.terraniaLeaves.getDefaultState());
		world.setBlockState(new BlockPos(i + 7, j + 17, k + 13), JourneyBlocks.terraniaLeaves.getDefaultState());
		world.setBlockState(new BlockPos(i + 7, j + 18, k + 7), log);
		world.setBlockState(new BlockPos(i + 7, j + 18, k + 8), log);
		world.setBlockState(new BlockPos(i + 7, j + 18, k + 10), JourneyBlocks.terraniaLeaves.getDefaultState());
		world.setBlockState(new BlockPos(i + 7, j + 18, k + 11), JourneyBlocks.terraniaLeaves.getDefaultState());
		world.setBlockState(new BlockPos(i + 7, j + 18, k + 12), JourneyBlocks.terraniaLeaves.getDefaultState());
		world.setBlockState(new BlockPos(i + 7, j + 19, k + 7), log);
		world.setBlockState(new BlockPos(i + 7, j + 19, k + 8), log);
		world.setBlockState(new BlockPos(i + 7, j + 20, k + 7), log);
		world.setBlockState(new BlockPos(i + 7, j + 20, k + 8), log);
		world.setBlockState(new BlockPos(i + 7, j + 21, k + 7), log);
		world.setBlockState(new BlockPos(i + 7, j + 21, k + 8), log);
		world.setBlockState(new BlockPos(i + 7, j + 21, k + 9), log);
		world.setBlockState(new BlockPos(i + 7, j + 22, k + 2), JourneyBlocks.terraniaLeaves.getDefaultState());
		world.setBlockState(new BlockPos(i + 7, j + 22, k + 7), log);
		world.setBlockState(new BlockPos(i + 7, j + 22, k + 8), log);
		world.setBlockState(new BlockPos(i + 7, j + 22, k + 9), log);
		world.setBlockState(new BlockPos(i + 7, j + 22, k + 13), JourneyBlocks.terraniaLeaves.getDefaultState());
		world.setBlockState(new BlockPos(i + 7, j + 23, k + 3), JourneyBlocks.terraniaLeaves.getDefaultState());
		world.setBlockState(new BlockPos(i + 7, j + 23, k + 4), JourneyBlocks.terraniaLeaves.getDefaultState());
		world.setBlockState(new BlockPos(i + 7, j + 23, k + 5), JourneyBlocks.terraniaLeaves.getDefaultState());
		world.setBlockState(new BlockPos(i + 7, j + 23, k + 6), JourneyBlocks.terraniaLeaves.getDefaultState());
		world.setBlockState(new BlockPos(i + 7, j + 23, k + 7), log);
		world.setBlockState(new BlockPos(i + 7, j + 23, k + 8), log);
		world.setBlockState(new BlockPos(i + 7, j + 23, k + 9), JourneyBlocks.terraniaLeaves.getDefaultState());
		world.setBlockState(new BlockPos(i + 7, j + 23, k + 10), JourneyBlocks.terraniaLeaves.getDefaultState());
		world.setBlockState(new BlockPos(i + 7, j + 23, k + 11), JourneyBlocks.terraniaLeaves.getDefaultState());
		world.setBlockState(new BlockPos(i + 7, j + 23, k + 12), JourneyBlocks.terraniaLeaves.getDefaultState());
		world.setBlockState(new BlockPos(i + 7, j + 24, k + 3), JourneyBlocks.terraniaLeaves.getDefaultState());
		world.setBlockState(new BlockPos(i + 7, j + 24, k + 4), JourneyBlocks.terraniaLeaves.getDefaultState());
		world.setBlockState(new BlockPos(i + 7, j + 24, k + 5), JourneyBlocks.terraniaLeaves.getDefaultState());
		world.setBlockState(new BlockPos(i + 7, j + 24, k + 6), JourneyBlocks.terraniaLeaves.getDefaultState());
		world.setBlockState(new BlockPos(i + 7, j + 24, k + 7), log);
		world.setBlockState(new BlockPos(i + 7, j + 24, k + 8), JourneyBlocks.terraniaLeaves.getDefaultState());
		world.setBlockState(new BlockPos(i + 7, j + 24, k + 9), JourneyBlocks.terraniaLeaves.getDefaultState());
		world.setBlockState(new BlockPos(i + 7, j + 24, k + 10), JourneyBlocks.terraniaLeaves.getDefaultState());
		world.setBlockState(new BlockPos(i + 7, j + 24, k + 11), JourneyBlocks.terraniaLeaves.getDefaultState());
		world.setBlockState(new BlockPos(i + 7, j + 24, k + 12), JourneyBlocks.terraniaLeaves.getDefaultState());
		world.setBlockState(new BlockPos(i + 7, j + 25, k + 4), JourneyBlocks.terraniaLeaves.getDefaultState());
		world.setBlockState(new BlockPos(i + 7, j + 25, k + 5), JourneyBlocks.terraniaLeaves.getDefaultState());
		world.setBlockState(new BlockPos(i + 7, j + 25, k + 6), JourneyBlocks.terraniaLeaves.getDefaultState());
		world.setBlockState(new BlockPos(i + 7, j + 25, k + 7), JourneyBlocks.terraniaLeaves.getDefaultState());
		world.setBlockState(new BlockPos(i + 7, j + 25, k + 8), JourneyBlocks.terraniaLeaves.getDefaultState());
		world.setBlockState(new BlockPos(i + 7, j + 25, k + 9), JourneyBlocks.terraniaLeaves.getDefaultState());
		world.setBlockState(new BlockPos(i + 7, j + 25, k + 10), JourneyBlocks.terraniaLeaves.getDefaultState());
		world.setBlockState(new BlockPos(i + 8, j + 0, k + 0), JourneyBlocks.terranianDirt.getDefaultState());
		world.setBlockState(new BlockPos(i + 8, j + 0, k + 1), JourneyBlocks.terranianPanels.getDefaultState());
		world.setBlockState(new BlockPos(i + 8, j + 0, k + 3), JourneyBlocks.terranianPanels.getDefaultState());
		world.setBlockState(new BlockPos(i + 8, j + 0, k + 4), JourneyBlocks.terranianPanels.getDefaultState());
		world.setBlockState(new BlockPos(i + 8, j + 0, k + 5), JourneyBlocks.terranianPanels.getDefaultState());
		world.setBlockState(new BlockPos(i + 8, j + 0, k + 6), JourneyBlocks.terranianPanels.getDefaultState());
		world.setBlockState(new BlockPos(i + 8, j + 0, k + 7), JourneyBlocks.terranianPanels.getDefaultState());
		world.setBlockState(new BlockPos(i + 8, j + 0, k + 8), JourneyBlocks.terranianPanels.getDefaultState());
		world.setBlockState(new BlockPos(i + 8, j + 0, k + 9), JourneyBlocks.terranianPanels.getDefaultState());
		world.setBlockState(new BlockPos(i + 8, j + 0, k + 10), JourneyBlocks.terranianDirt.getDefaultState());
		world.setBlockState(new BlockPos(i + 8, j + 1, k + 0), log);
		world.setBlockState(new BlockPos(i + 8, j + 1, k + 10), log);
		world.setBlockState(new BlockPos(i + 8, j + 2, k + 10), log);
		world.setBlockState(new BlockPos(i + 8, j + 3, k + 10), log);
		world.setBlockState(new BlockPos(i + 8, j + 4, k + 9), log);
		world.setBlockState(new BlockPos(i + 8, j + 5, k + 4), JourneyBlocks.terranianPost.getDefaultState());
		world.setBlockState(new BlockPos(i + 8, j + 5, k + 5), log);
		world.setBlockState(new BlockPos(i + 8, j + 5, k + 6), log);
		world.setBlockState(new BlockPos(i + 8, j + 5, k + 7), log);
		world.setBlockState(new BlockPos(i + 8, j + 5, k + 8), log);
		world.setBlockState(new BlockPos(i + 8, j + 5, k + 9), log);
		world.setBlockState(new BlockPos(i + 8, j + 6, k + 4), JourneyBlocks.terraniaLamp.getDefaultState());
		world.setBlockState(new BlockPos(i + 8, j + 6, k + 6), log);
		world.setBlockState(new BlockPos(i + 8, j + 6, k + 7), log);
		world.setBlockState(new BlockPos(i + 8, j + 6, k + 8), log);
		world.setBlockState(new BlockPos(i + 8, j + 6, k + 9), log);
		world.setBlockState(new BlockPos(i + 8, j + 7, k + 6), log);
		world.setBlockState(new BlockPos(i + 8, j + 7, k + 7), log);
		world.setBlockState(new BlockPos(i + 8, j + 7, k + 8), log);
		world.setBlockState(new BlockPos(i + 8, j + 8, k + 6), log);
		world.setBlockState(new BlockPos(i + 8, j + 8, k + 7), log);
		world.setBlockState(new BlockPos(i + 8, j + 8, k + 8), log);
		world.setBlockState(new BlockPos(i + 8, j + 9, k + 7), log);
		world.setBlockState(new BlockPos(i + 8, j + 9, k + 8), log);
		world.setBlockState(new BlockPos(i + 8, j + 10, k + 7), log);
		world.setBlockState(new BlockPos(i + 8, j + 10, k + 8), log);
		world.setBlockState(new BlockPos(i + 8, j + 11, k + 7), log);
		world.setBlockState(new BlockPos(i + 8, j + 11, k + 8), log);
		world.setBlockState(new BlockPos(i + 8, j + 12, k + 7), log);
		world.setBlockState(new BlockPos(i + 8, j + 12, k + 8), log);
		world.setBlockState(new BlockPos(i + 8, j + 13, k + 7), log);
		world.setBlockState(new BlockPos(i + 8, j + 13, k + 8), log);
		world.setBlockState(new BlockPos(i + 8, j + 14, k + 7), log);
		world.setBlockState(new BlockPos(i + 8, j + 14, k + 8), log);
		world.setBlockState(new BlockPos(i + 8, j + 14, k + 9), log);
		world.setBlockState(new BlockPos(i + 8, j + 15, k + 7), log);
		world.setBlockState(new BlockPos(i + 8, j + 15, k + 8), log);
		world.setBlockState(new BlockPos(i + 8, j + 15, k + 9), log);
		world.setBlockState(new BlockPos(i + 8, j + 15, k + 10), log);
		world.setBlockState(new BlockPos(i + 8, j + 16, k + 7), log);
		world.setBlockState(new BlockPos(i + 8, j + 16, k + 8), log);
		world.setBlockState(new BlockPos(i + 8, j + 16, k + 9), JourneyBlocks.terraniaLeaves.getDefaultState());
		world.setBlockState(new BlockPos(i + 8, j + 16, k + 10), JourneyBlocks.terraniaLeaves.getDefaultState());
		world.setBlockState(new BlockPos(i + 8, j + 16, k + 11), JourneyBlocks.terraniaLeaves.getDefaultState());
		world.setBlockState(new BlockPos(i + 8, j + 16, k + 12), JourneyBlocks.terraniaLeaves.getDefaultState());
		world.setBlockState(new BlockPos(i + 8, j + 16, k + 13), JourneyBlocks.terraniaLeaves.getDefaultState());
		world.setBlockState(new BlockPos(i + 8, j + 17, k + 7), log);
		world.setBlockState(new BlockPos(i + 8, j + 17, k + 8), log);
		world.setBlockState(new BlockPos(i + 8, j + 17, k + 10), JourneyBlocks.terraniaLeaves.getDefaultState());
		world.setBlockState(new BlockPos(i + 8, j + 17, k + 11), JourneyBlocks.terraniaLeaves.getDefaultState());
		world.setBlockState(new BlockPos(i + 8, j + 17, k + 12), JourneyBlocks.terraniaLeaves.getDefaultState());
		world.setBlockState(new BlockPos(i + 8, j + 18, k + 6), log);
		world.setBlockState(new BlockPos(i + 8, j + 18, k + 7), log);
		world.setBlockState(new BlockPos(i + 8, j + 18, k + 8), log);
		world.setBlockState(new BlockPos(i + 8, j + 18, k + 11), JourneyBlocks.terraniaLeaves.getDefaultState());
		world.setBlockState(new BlockPos(i + 8, j + 19, k + 6), log);
		world.setBlockState(new BlockPos(i + 8, j + 19, k + 7), log);
		world.setBlockState(new BlockPos(i + 8, j + 19, k + 8), log);
		world.setBlockState(new BlockPos(i + 8, j + 19, k + 9), log);
		world.setBlockState(new BlockPos(i + 8, j + 20, k + 6), log);
		world.setBlockState(new BlockPos(i + 8, j + 20, k + 7), log);
		world.setBlockState(new BlockPos(i + 8, j + 20, k + 8), log);
		world.setBlockState(new BlockPos(i + 8, j + 20, k + 9), log);
		world.setBlockState(new BlockPos(i + 8, j + 21, k + 6), log);
		world.setBlockState(new BlockPos(i + 8, j + 21, k + 7), log);
		world.setBlockState(new BlockPos(i + 8, j + 21, k + 8), log);
		world.setBlockState(new BlockPos(i + 8, j + 21, k + 9), log);
		world.setBlockState(new BlockPos(i + 8, j + 22, k + 2), JourneyBlocks.terraniaLeaves.getDefaultState());
		world.setBlockState(new BlockPos(i + 8, j + 22, k + 3), JourneyBlocks.terraniaLeaves.getDefaultState());
		world.setBlockState(new BlockPos(i + 8, j + 22, k + 6), log);
		world.setBlockState(new BlockPos(i + 8, j + 22, k + 7), log);
		world.setBlockState(new BlockPos(i + 8, j + 22, k + 8), log);
		world.setBlockState(new BlockPos(i + 8, j + 22, k + 9), log);
		world.setBlockState(new BlockPos(i + 8, j + 22, k + 10), log);
		world.setBlockState(new BlockPos(i + 8, j + 22, k + 13), JourneyBlocks.terraniaLeaves.getDefaultState());
		world.setBlockState(new BlockPos(i + 8, j + 23, k + 3), JourneyBlocks.terraniaLeaves.getDefaultState());
		world.setBlockState(new BlockPos(i + 8, j + 23, k + 4), JourneyBlocks.terraniaLeaves.getDefaultState());
		world.setBlockState(new BlockPos(i + 8, j + 23, k + 5), JourneyBlocks.terraniaLeaves.getDefaultState());
		world.setBlockState(new BlockPos(i + 8, j + 23, k + 6), JourneyBlocks.terraniaLeaves.getDefaultState());
		world.setBlockState(new BlockPos(i + 8, j + 23, k + 7), log);
		world.setBlockState(new BlockPos(i + 8, j + 23, k + 8), log);
		world.setBlockState(new BlockPos(i + 8, j + 23, k + 9), JourneyBlocks.terraniaLeaves.getDefaultState());
		world.setBlockState(new BlockPos(i + 8, j + 23, k + 10), JourneyBlocks.terraniaLeaves.getDefaultState());
		world.setBlockState(new BlockPos(i + 8, j + 23, k + 11), JourneyBlocks.terraniaLeaves.getDefaultState());
		world.setBlockState(new BlockPos(i + 8, j + 23, k + 12), JourneyBlocks.terraniaLeaves.getDefaultState());
		world.setBlockState(new BlockPos(i + 8, j + 23, k + 13), JourneyBlocks.terraniaLeaves.getDefaultState());
		world.setBlockState(new BlockPos(i + 8, j + 24, k + 4), JourneyBlocks.terraniaLeaves.getDefaultState());
		world.setBlockState(new BlockPos(i + 8, j + 24, k + 5), JourneyBlocks.terraniaLeaves.getDefaultState());
		world.setBlockState(new BlockPos(i + 8, j + 24, k + 6), JourneyBlocks.terraniaLeaves.getDefaultState());
		world.setBlockState(new BlockPos(i + 8, j + 24, k + 7), JourneyBlocks.terraniaLeaves.getDefaultState());
		world.setBlockState(new BlockPos(i + 8, j + 24, k + 8), JourneyBlocks.terraniaLeaves.getDefaultState());
		world.setBlockState(new BlockPos(i + 8, j + 24, k + 9), JourneyBlocks.terraniaLeaves.getDefaultState());
		world.setBlockState(new BlockPos(i + 8, j + 24, k + 10), JourneyBlocks.terraniaLeaves.getDefaultState());
		world.setBlockState(new BlockPos(i + 8, j + 24, k + 11), JourneyBlocks.terraniaLeaves.getDefaultState());
		world.setBlockState(new BlockPos(i + 8, j + 24, k + 12), JourneyBlocks.terraniaLeaves.getDefaultState());
		world.setBlockState(new BlockPos(i + 8, j + 25, k + 4), JourneyBlocks.terraniaLeaves.getDefaultState());
		world.setBlockState(new BlockPos(i + 8, j + 25, k + 5), JourneyBlocks.terraniaLeaves.getDefaultState());
		world.setBlockState(new BlockPos(i + 8, j + 25, k + 6), JourneyBlocks.terraniaLeaves.getDefaultState());
		world.setBlockState(new BlockPos(i + 8, j + 25, k + 7), JourneyBlocks.terraniaLeaves.getDefaultState());
		world.setBlockState(new BlockPos(i + 8, j + 25, k + 8), JourneyBlocks.terraniaLeaves.getDefaultState());
		world.setBlockState(new BlockPos(i + 8, j + 25, k + 9), JourneyBlocks.terraniaLeaves.getDefaultState());
		world.setBlockState(new BlockPos(i + 8, j + 25, k + 10), JourneyBlocks.terraniaLeaves.getDefaultState());
		world.setBlockState(new BlockPos(i + 8, j + 25, k + 11), JourneyBlocks.terraniaLeaves.getDefaultState());
		world.setBlockState(new BlockPos(i + 9, j + 0, k + 2), JourneyBlocks.terranianPanels.getDefaultState());
		world.setBlockState(new BlockPos(i + 9, j + 0, k + 3), JourneyBlocks.terranianPanels.getDefaultState());
		world.setBlockState(new BlockPos(i + 9, j + 0, k + 4), JourneyBlocks.terranianPanels.getDefaultState());
		world.setBlockState(new BlockPos(i + 9, j + 0, k + 5), JourneyBlocks.terranianPanels.getDefaultState());
		world.setBlockState(new BlockPos(i + 9, j + 0, k + 6), JourneyBlocks.terranianPanels.getDefaultState());
		world.setBlockState(new BlockPos(i + 9, j + 0, k + 7), JourneyBlocks.terranianPanels.getDefaultState());
		world.setBlockState(new BlockPos(i + 9, j + 0, k + 8), JourneyBlocks.terranianPanels.getDefaultState());
		world.setBlockState(new BlockPos(i + 9, j + 0, k + 9), JourneyBlocks.terranianDirt.getDefaultState());
		world.setBlockState(new BlockPos(i + 9, j + 0, k + 10), JourneyBlocks.terranianDirt.getDefaultState());
		world.setBlockState(new BlockPos(i + 9, j + 0, k + 11), JourneyBlocks.terranianDirt.getDefaultState());
		world.setBlockState(new BlockPos(i + 9, j + 0, k + 14), JourneyBlocks.terranianDirt.getDefaultState());
		world.setBlockState(new BlockPos(i + 9, j + 1, k + 9), log);
		world.setBlockState(new BlockPos(i + 9, j + 1, k + 10), log);
		world.setBlockState(new BlockPos(i + 9, j + 1, k + 11), log);
		world.setBlockState(new BlockPos(i + 9, j + 1, k + 14), log);
		world.setBlockState(new BlockPos(i + 9, j + 2, k + 9), log);
		world.setBlockState(new BlockPos(i + 9, j + 2, k + 10), log);
		world.setBlockState(new BlockPos(i + 9, j + 3, k + 9), log);
		world.setBlockState(new BlockPos(i + 9, j + 4, k + 4), JourneyBlocks.terranianPost.getDefaultState());
		world.setBlockState(new BlockPos(i + 9, j + 4, k + 8), log);
		world.setBlockState(new BlockPos(i + 9, j + 4, k + 9), log);
		world.setBlockState(new BlockPos(i + 9, j + 5, k + 4), JourneyBlocks.terranianPost.getDefaultState());
		world.setBlockState(new BlockPos(i + 9, j + 5, k + 5), log);
		world.setBlockState(new BlockPos(i + 9, j + 5, k + 6), log);
		world.setBlockState(new BlockPos(i + 9, j + 5, k + 7), log);
		world.setBlockState(new BlockPos(i + 9, j + 5, k + 8), log);
		world.setBlockState(new BlockPos(i + 9, j + 5, k + 9), log);
		world.setBlockState(new BlockPos(i + 9, j + 6, k + 6), log);
		world.setBlockState(new BlockPos(i + 9, j + 6, k + 8), log);
		world.setBlockState(new BlockPos(i + 9, j + 7, k + 8), log);
		world.setBlockState(new BlockPos(i + 9, j + 16, k + 9), JourneyBlocks.terraniaLeaves.getDefaultState());
		world.setBlockState(new BlockPos(i + 9, j + 16, k + 10), JourneyBlocks.terraniaLeaves.getDefaultState());
		world.setBlockState(new BlockPos(i + 9, j + 16, k + 11), JourneyBlocks.terraniaLeaves.getDefaultState());
		world.setBlockState(new BlockPos(i + 9, j + 16, k + 12), JourneyBlocks.terraniaLeaves.getDefaultState());
		world.setBlockState(new BlockPos(i + 9, j + 17, k + 8), log);
		world.setBlockState(new BlockPos(i + 9, j + 17, k + 11), JourneyBlocks.terraniaLeaves.getDefaultState());
		world.setBlockState(new BlockPos(i + 9, j + 18, k + 8), log);
		world.setBlockState(new BlockPos(i + 9, j + 19, k + 8), log);
		world.setBlockState(new BlockPos(i + 9, j + 20, k + 7), log);
		world.setBlockState(new BlockPos(i + 9, j + 20, k + 8), log);
		world.setBlockState(new BlockPos(i + 9, j + 20, k + 9), log);
		world.setBlockState(new BlockPos(i + 9, j + 21, k + 7), log);
		world.setBlockState(new BlockPos(i + 9, j + 21, k + 8), log);
		world.setBlockState(new BlockPos(i + 9, j + 21, k + 9), log);
		world.setBlockState(new BlockPos(i + 9, j + 22, k + 3), JourneyBlocks.terraniaLeaves.getDefaultState());
		world.setBlockState(new BlockPos(i + 9, j + 22, k + 7), log);
		world.setBlockState(new BlockPos(i + 9, j + 22, k + 8), log);
		world.setBlockState(new BlockPos(i + 9, j + 22, k + 13), JourneyBlocks.terraniaLeaves.getDefaultState());
		world.setBlockState(new BlockPos(i + 9, j + 23, k + 4), JourneyBlocks.terraniaLeaves.getDefaultState());
		world.setBlockState(new BlockPos(i + 9, j + 23, k + 5), JourneyBlocks.terraniaLeaves.getDefaultState());
		world.setBlockState(new BlockPos(i + 9, j + 23, k + 6), JourneyBlocks.terraniaLeaves.getDefaultState());
		world.setBlockState(new BlockPos(i + 9, j + 23, k + 7), JourneyBlocks.terraniaLeaves.getDefaultState());
		world.setBlockState(new BlockPos(i + 9, j + 23, k + 8), JourneyBlocks.terraniaLeaves.getDefaultState());
		world.setBlockState(new BlockPos(i + 9, j + 23, k + 9), JourneyBlocks.terraniaLeaves.getDefaultState());
		world.setBlockState(new BlockPos(i + 9, j + 23, k + 10), JourneyBlocks.terraniaLeaves.getDefaultState());
		world.setBlockState(new BlockPos(i + 9, j + 23, k + 11), JourneyBlocks.terraniaLeaves.getDefaultState());
		world.setBlockState(new BlockPos(i + 9, j + 23, k + 12), JourneyBlocks.terraniaLeaves.getDefaultState());
		world.setBlockState(new BlockPos(i + 9, j + 23, k + 13), JourneyBlocks.terraniaLeaves.getDefaultState());
		world.setBlockState(new BlockPos(i + 9, j + 24, k + 4), JourneyBlocks.terraniaLeaves.getDefaultState());
		world.setBlockState(new BlockPos(i + 9, j + 24, k + 5), JourneyBlocks.terraniaLeaves.getDefaultState());
		world.setBlockState(new BlockPos(i + 9, j + 24, k + 6), JourneyBlocks.terraniaLeaves.getDefaultState());
		world.setBlockState(new BlockPos(i + 9, j + 24, k + 7), JourneyBlocks.terraniaLeaves.getDefaultState());
		world.setBlockState(new BlockPos(i + 9, j + 24, k + 8), JourneyBlocks.terraniaLeaves.getDefaultState());
		world.setBlockState(new BlockPos(i + 9, j + 24, k + 9), JourneyBlocks.terraniaLeaves.getDefaultState());
		world.setBlockState(new BlockPos(i + 9, j + 24, k + 10), JourneyBlocks.terraniaLeaves.getDefaultState());
		world.setBlockState(new BlockPos(i + 9, j + 24, k + 11), JourneyBlocks.terraniaLeaves.getDefaultState());
		world.setBlockState(new BlockPos(i + 9, j + 24, k + 12), JourneyBlocks.terraniaLeaves.getDefaultState());
		world.setBlockState(new BlockPos(i + 9, j + 25, k + 5), JourneyBlocks.terraniaLeaves.getDefaultState());
		world.setBlockState(new BlockPos(i + 9, j + 25, k + 6), JourneyBlocks.terraniaLeaves.getDefaultState());
		world.setBlockState(new BlockPos(i + 9, j + 25, k + 7), JourneyBlocks.terraniaLeaves.getDefaultState());
		world.setBlockState(new BlockPos(i + 9, j + 25, k + 8), JourneyBlocks.terraniaLeaves.getDefaultState());
		world.setBlockState(new BlockPos(i + 9, j + 25, k + 9), JourneyBlocks.terraniaLeaves.getDefaultState());
		world.setBlockState(new BlockPos(i + 9, j + 25, k + 10), JourneyBlocks.terraniaLeaves.getDefaultState());
		world.setBlockState(new BlockPos(i + 10, j + 0, k + 0), JourneyBlocks.terranianPanels.getDefaultState());
		world.setBlockState(new BlockPos(i + 10, j + 0, k + 2), JourneyBlocks.terranianPanels.getDefaultState());
		world.setBlockState(new BlockPos(i + 10, j + 0, k + 4), JourneyBlocks.terranianPanels.getDefaultState());
		world.setBlockState(new BlockPos(i + 10, j + 0, k + 5), JourneyBlocks.terranianPanels.getDefaultState());
		world.setBlockState(new BlockPos(i + 10, j + 0, k + 6), JourneyBlocks.terranianDirt.getDefaultState());
		world.setBlockState(new BlockPos(i + 10, j + 0, k + 7), JourneyBlocks.terranianDirt.getDefaultState());
		world.setBlockState(new BlockPos(i + 10, j + 0, k + 8), JourneyBlocks.terranianDirt.getDefaultState());
		world.setBlockState(new BlockPos(i + 10, j + 0, k + 12), JourneyBlocks.terranianDirt.getDefaultState());
		world.setBlockState(new BlockPos(i + 10, j + 0, k + 13), JourneyBlocks.terranianDirt.getDefaultState());
		world.setBlockState(new BlockPos(i + 10, j + 1, k + 6), log);
		world.setBlockState(new BlockPos(i + 10, j + 1, k + 7), log);
		world.setBlockState(new BlockPos(i + 10, j + 1, k + 8), log);
		world.setBlockState(new BlockPos(i + 10, j + 1, k + 12), log);
		world.setBlockState(new BlockPos(i + 10, j + 1, k + 13), log);
		world.setBlockState(new BlockPos(i + 10, j + 2, k + 6), log);
		world.setBlockState(new BlockPos(i + 10, j + 2, k + 7), JourneyBlocks.terranianBars.getDefaultState());
		world.setBlockState(new BlockPos(i + 10, j + 2, k + 8), log);
		world.setBlockState(new BlockPos(i + 10, j + 3, k + 3), JourneyBlocks.terranianPost.getDefaultState());
		world.setBlockState(new BlockPos(i + 10, j + 3, k + 4), log);
		world.setBlockState(new BlockPos(i + 10, j + 3, k + 5), log);
		world.setBlockState(new BlockPos(i + 10, j + 3, k + 6), log);
		world.setBlockState(new BlockPos(i + 10, j + 3, k + 7), log);
		world.setBlockState(new BlockPos(i + 10, j + 3, k + 8), log);
		world.setBlockState(new BlockPos(i + 10, j + 4, k + 3), JourneyBlocks.terranianPost.getDefaultState());
		world.setBlockState(new BlockPos(i + 10, j + 4, k + 4), JourneyBlocks.terranianPost.getDefaultState());
		world.setBlockState(new BlockPos(i + 10, j + 4, k + 5), log);
		world.setBlockState(new BlockPos(i + 10, j + 4, k + 6), log);
		world.setBlockState(new BlockPos(i + 10, j + 4, k + 7), log);
		world.setBlockState(new BlockPos(i + 10, j + 5, k + 6), log);
		world.setBlockState(new BlockPos(i + 10, j + 16, k + 11), JourneyBlocks.terraniaLeaves.getDefaultState());
		world.setBlockState(new BlockPos(i + 10, j + 20, k + 8), log);
		world.setBlockState(new BlockPos(i + 10, j + 21, k + 9), log);
		world.setBlockState(new BlockPos(i + 10, j + 22, k + 4), JourneyBlocks.terraniaLeaves.getDefaultState());
		world.setBlockState(new BlockPos(i + 10, j + 22, k + 9), JourneyBlocks.terraniaLeaves.getDefaultState());
		world.setBlockState(new BlockPos(i + 10, j + 22, k + 12), JourneyBlocks.terraniaLeaves.getDefaultState());
		world.setBlockState(new BlockPos(i + 10, j + 23, k + 5), JourneyBlocks.terraniaLeaves.getDefaultState());
		world.setBlockState(new BlockPos(i + 10, j + 23, k + 6), JourneyBlocks.terraniaLeaves.getDefaultState());
		world.setBlockState(new BlockPos(i + 10, j + 23, k + 7), JourneyBlocks.terraniaLeaves.getDefaultState());
		world.setBlockState(new BlockPos(i + 10, j + 23, k + 8), JourneyBlocks.terraniaLeaves.getDefaultState());
		world.setBlockState(new BlockPos(i + 10, j + 23, k + 9), JourneyBlocks.terraniaLeaves.getDefaultState());
		world.setBlockState(new BlockPos(i + 10, j + 23, k + 10), JourneyBlocks.terraniaLeaves.getDefaultState());
		world.setBlockState(new BlockPos(i + 10, j + 23, k + 11), JourneyBlocks.terraniaLeaves.getDefaultState());
		world.setBlockState(new BlockPos(i + 10, j + 23, k + 12), JourneyBlocks.terraniaLeaves.getDefaultState());
		world.setBlockState(new BlockPos(i + 10, j + 23, k + 13), JourneyBlocks.terraniaLeaves.getDefaultState());
		world.setBlockState(new BlockPos(i + 10, j + 24, k + 5), JourneyBlocks.terraniaLeaves.getDefaultState());
		world.setBlockState(new BlockPos(i + 10, j + 24, k + 6), JourneyBlocks.terraniaLeaves.getDefaultState());
		world.setBlockState(new BlockPos(i + 10, j + 24, k + 7), JourneyBlocks.terraniaLeaves.getDefaultState());
		world.setBlockState(new BlockPos(i + 10, j + 24, k + 8), JourneyBlocks.terraniaLeaves.getDefaultState());
		world.setBlockState(new BlockPos(i + 10, j + 24, k + 9), JourneyBlocks.terraniaLeaves.getDefaultState());
		world.setBlockState(new BlockPos(i + 10, j + 24, k + 10), JourneyBlocks.terraniaLeaves.getDefaultState());
		world.setBlockState(new BlockPos(i + 10, j + 24, k + 11), JourneyBlocks.terraniaLeaves.getDefaultState());
		world.setBlockState(new BlockPos(i + 10, j + 24, k + 12), JourneyBlocks.terraniaLeaves.getDefaultState());
		world.setBlockState(new BlockPos(i + 10, j + 25, k + 5), JourneyBlocks.terraniaLeaves.getDefaultState());
		world.setBlockState(new BlockPos(i + 10, j + 25, k + 7), JourneyBlocks.terraniaLeaves.getDefaultState());
		world.setBlockState(new BlockPos(i + 10, j + 25, k + 8), JourneyBlocks.terraniaLeaves.getDefaultState());
		world.setBlockState(new BlockPos(i + 10, j + 25, k + 9), JourneyBlocks.terraniaLeaves.getDefaultState());
		world.setBlockState(new BlockPos(i + 11, j + 0, k + 3), JourneyBlocks.terranianDirt.getDefaultState());
		world.setBlockState(new BlockPos(i + 11, j + 0, k + 4), JourneyBlocks.terranianDirt.getDefaultState());
		world.setBlockState(new BlockPos(i + 11, j + 0, k + 5), JourneyBlocks.terranianDirt.getDefaultState());
		world.setBlockState(new BlockPos(i + 11, j + 0, k + 7), JourneyBlocks.terranianDirt.getDefaultState());
		world.setBlockState(new BlockPos(i + 11, j + 0, k + 8), JourneyBlocks.terranianDirt.getDefaultState());
		world.setBlockState(new BlockPos(i + 11, j + 0, k + 9), JourneyBlocks.terranianDirt.getDefaultState());
		world.setBlockState(new BlockPos(i + 11, j + 0, k + 13), JourneyBlocks.terranianDirt.getDefaultState());
		world.setBlockState(new BlockPos(i + 11, j + 1, k + 3), log);
		world.setBlockState(new BlockPos(i + 11, j + 1, k + 4), log);
		world.setBlockState(new BlockPos(i + 11, j + 1, k + 5), log);
		world.setBlockState(new BlockPos(i + 11, j + 1, k + 7), log);
		world.setBlockState(new BlockPos(i + 11, j + 1, k + 8), log);
		world.setBlockState(new BlockPos(i + 11, j + 1, k + 9), log);
		world.setBlockState(new BlockPos(i + 11, j + 1, k + 13), log);
		world.setBlockState(new BlockPos(i + 11, j + 2, k + 3), JourneyBlocks.terranianPost.getDefaultState());
		world.setBlockState(new BlockPos(i + 11, j + 2, k + 4), log);
		world.setBlockState(new BlockPos(i + 11, j + 2, k + 5), log);
		world.setBlockState(new BlockPos(i + 11, j + 3, k + 3), JourneyBlocks.terranianPost.getDefaultState());
		world.setBlockState(new BlockPos(i + 11, j + 3, k + 7), log);
		world.setBlockState(new BlockPos(i + 11, j + 21, k + 9), log);
		world.setBlockState(new BlockPos(i + 11, j + 22, k + 4), JourneyBlocks.terraniaLeaves.getDefaultState());
		world.setBlockState(new BlockPos(i + 11, j + 22, k + 8), JourneyBlocks.terraniaLeaves.getDefaultState());
		world.setBlockState(new BlockPos(i + 11, j + 22, k + 9), JourneyBlocks.terraniaLeaves.getDefaultState());
		world.setBlockState(new BlockPos(i + 11, j + 22, k + 10), JourneyBlocks.terraniaLeaves.getDefaultState());
		world.setBlockState(new BlockPos(i + 11, j + 22, k + 11), JourneyBlocks.terraniaLeaves.getDefaultState());
		world.setBlockState(new BlockPos(i + 11, j + 23, k + 5), JourneyBlocks.terraniaLeaves.getDefaultState());
		world.setBlockState(new BlockPos(i + 11, j + 23, k + 6), JourneyBlocks.terraniaLeaves.getDefaultState());
		world.setBlockState(new BlockPos(i + 11, j + 23, k + 7), JourneyBlocks.terraniaLeaves.getDefaultState());
		world.setBlockState(new BlockPos(i + 11, j + 23, k + 8), JourneyBlocks.terraniaLeaves.getDefaultState());
		world.setBlockState(new BlockPos(i + 11, j + 23, k + 9), JourneyBlocks.terraniaLeaves.getDefaultState());
		world.setBlockState(new BlockPos(i + 11, j + 23, k + 10), JourneyBlocks.terraniaLeaves.getDefaultState());
		world.setBlockState(new BlockPos(i + 11, j + 23, k + 11), JourneyBlocks.terraniaLeaves.getDefaultState());
		world.setBlockState(new BlockPos(i + 11, j + 24, k + 5), JourneyBlocks.terraniaLeaves.getDefaultState());
		world.setBlockState(new BlockPos(i + 11, j + 24, k + 6), JourneyBlocks.terraniaLeaves.getDefaultState());
		world.setBlockState(new BlockPos(i + 11, j + 24, k + 7), JourneyBlocks.terraniaLeaves.getDefaultState());
		world.setBlockState(new BlockPos(i + 11, j + 24, k + 8), JourneyBlocks.terraniaLeaves.getDefaultState());
		world.setBlockState(new BlockPos(i + 11, j + 24, k + 9), JourneyBlocks.terraniaLeaves.getDefaultState());
		world.setBlockState(new BlockPos(i + 11, j + 24, k + 10), JourneyBlocks.terraniaLeaves.getDefaultState());
		world.setBlockState(new BlockPos(i + 11, j + 25, k + 7), JourneyBlocks.terraniaLeaves.getDefaultState());
		world.setBlockState(new BlockPos(i + 11, j + 25, k + 8), JourneyBlocks.terraniaLeaves.getDefaultState());
		world.setBlockState(new BlockPos(i + 12, j + 0, k + 1), JourneyBlocks.terranianPanels.getDefaultState());
		world.setBlockState(new BlockPos(i + 12, j + 0, k + 2), JourneyBlocks.terranianDirt.getDefaultState());
		world.setBlockState(new BlockPos(i + 12, j + 0, k + 5), JourneyBlocks.terranianDirt.getDefaultState());
		world.setBlockState(new BlockPos(i + 12, j + 0, k + 8), JourneyBlocks.terranianDirt.getDefaultState());
		world.setBlockState(new BlockPos(i + 12, j + 1, k + 2), log);
		world.setBlockState(new BlockPos(i + 12, j + 1, k + 5), log);
		world.setBlockState(new BlockPos(i + 12, j + 1, k + 8), log);
		world.setBlockState(new BlockPos(i + 12, j + 22, k + 5), JourneyBlocks.terraniaLeaves.getDefaultState());
		world.setBlockState(new BlockPos(i + 12, j + 22, k + 6), JourneyBlocks.terraniaLeaves.getDefaultState());
		world.setBlockState(new BlockPos(i + 12, j + 22, k + 7), JourneyBlocks.terraniaLeaves.getDefaultState());
		world.setBlockState(new BlockPos(i + 12, j + 22, k + 8), JourneyBlocks.terraniaLeaves.getDefaultState());
		world.setBlockState(new BlockPos(i + 12, j + 22, k + 9), log);
		world.setBlockState(new BlockPos(i + 12, j + 22, k + 10), JourneyBlocks.terraniaLeaves.getDefaultState());
		world.setBlockState(new BlockPos(i + 12, j + 22, k + 11), JourneyBlocks.terraniaLeaves.getDefaultState());
		world.setBlockState(new BlockPos(i + 12, j + 23, k + 6), JourneyBlocks.terraniaLeaves.getDefaultState());
		world.setBlockState(new BlockPos(i + 12, j + 23, k + 7), JourneyBlocks.terraniaLeaves.getDefaultState());
		world.setBlockState(new BlockPos(i + 12, j + 23, k + 8), JourneyBlocks.terraniaLeaves.getDefaultState());
		world.setBlockState(new BlockPos(i + 12, j + 23, k + 9), JourneyBlocks.terraniaLeaves.getDefaultState());
		world.setBlockState(new BlockPos(i + 12, j + 23, k + 10), JourneyBlocks.terraniaLeaves.getDefaultState());
		world.setBlockState(new BlockPos(i + 12, j + 23, k + 11), JourneyBlocks.terraniaLeaves.getDefaultState());
		world.setBlockState(new BlockPos(i + 12, j + 24, k + 7), JourneyBlocks.terraniaLeaves.getDefaultState());
		world.setBlockState(new BlockPos(i + 12, j + 24, k + 8), JourneyBlocks.terraniaLeaves.getDefaultState());
		world.setBlockState(new BlockPos(i + 13, j + 0, k + 9), JourneyBlocks.terranianDirt.getDefaultState());
		world.setBlockState(new BlockPos(i + 13, j + 1, k + 9), log);
		world.setBlockState(new BlockPos(i + 13, j + 22, k + 6), JourneyBlocks.terraniaLeaves.getDefaultState());
		world.setBlockState(new BlockPos(i + 13, j + 22, k + 7), JourneyBlocks.terraniaLeaves.getDefaultState());
		world.setBlockState(new BlockPos(i + 13, j + 22, k + 8), JourneyBlocks.terraniaLeaves.getDefaultState());
		world.setBlockState(new BlockPos(i + 13, j + 22, k + 9), JourneyBlocks.terraniaLeaves.getDefaultState());
		world.setBlockState(new BlockPos(i + 13, j + 22, k + 10), JourneyBlocks.terraniaLeaves.getDefaultState());
		world.setBlockState(new BlockPos(i + 13, j + 23, k + 7), JourneyBlocks.terraniaLeaves.getDefaultState());
		world.setBlockState(new BlockPos(i + 13, j + 23, k + 8), JourneyBlocks.terraniaLeaves.getDefaultState());
		world.setBlockState(new BlockPos(i + 13, j + 23, k + 9), JourneyBlocks.terraniaLeaves.getDefaultState());
		world.setBlockState(new BlockPos(i + 14, j + 0, k + 10), JourneyBlocks.terranianDirt.getDefaultState());
		world.setBlockState(new BlockPos(i + 14, j + 1, k + 10), log);
		world.setBlockState(new BlockPos(i + 14, j + 22, k + 7), JourneyBlocks.terraniaLeaves.getDefaultState());
		world.setBlockState(new BlockPos(i + 14, j + 22, k + 8), JourneyBlocks.terraniaLeaves.getDefaultState());
		world.setBlockState(new BlockPos(i + 14, j + 22, k + 9), JourneyBlocks.terraniaLeaves.getDefaultState());
		world.setBlockState(new BlockPos(i + 1, j + 10, k + 7), JourneyBlocks.terraniaVine.getStateFromMeta(8));
		world.setBlockState(new BlockPos(i + 1, j + 11, k + 7), JourneyBlocks.terraniaVine.getStateFromMeta(8));
		world.setBlockState(new BlockPos(i + 1, j + 12, k + 7), JourneyBlocks.terraniaVine.getStateFromMeta(8));
		world.setBlockState(new BlockPos(i + 1, j + 13, k + 7), JourneyBlocks.terraniaVine.getStateFromMeta(8));
		world.setBlockState(new BlockPos(i + 1, j + 14, k + 7), JourneyBlocks.terraniaVine.getStateFromMeta(8));
		world.setBlockState(new BlockPos(i + 1, j + 15, k + 7), JourneyBlocks.terraniaVine.getStateFromMeta(8));
		world.setBlockState(new BlockPos(i + 1, j + 16, k + 7), JourneyBlocks.terraniaVine.getStateFromMeta(8));
		world.setBlockState(new BlockPos(i + 1, j + 17, k + 7), JourneyBlocks.terraniaVine.getStateFromMeta(8));
		world.setBlockState(new BlockPos(i + 1, j + 18, k + 7), JourneyBlocks.terraniaVine.getStateFromMeta(8));
		world.setBlockState(new BlockPos(i + 1, j + 19, k + 7), JourneyBlocks.terraniaVine.getStateFromMeta(8));
		world.setBlockState(new BlockPos(i + 1, j + 20, k + 7), JourneyBlocks.terraniaVine.getStateFromMeta(8));
		world.setBlockState(new BlockPos(i + 1, j + 20, k + 9), JourneyBlocks.terraniaVine.getStateFromMeta(8));
		world.setBlockState(new BlockPos(i + 1, j + 21, k + 7), JourneyBlocks.terraniaVine.getStateFromMeta(8));
		world.setBlockState(new BlockPos(i + 1, j + 21, k + 9), JourneyBlocks.terraniaVine.getStateFromMeta(8));
		world.setBlockState(new BlockPos(i + 1, j + 22, k + 7), JourneyBlocks.terraniaVine.getStateFromMeta(8));
		world.setBlockState(new BlockPos(i + 1, j + 22, k + 9), JourneyBlocks.terraniaVine.getStateFromMeta(8));
		world.setBlockState(new BlockPos(i + 2, j + 22, k + 4), JourneyBlocks.terraniaVine.getStateFromMeta(8));
		world.setBlockState(new BlockPos(i + 5, j + 3, k + 11), JourneyBlocks.terraniaVine.getStateFromMeta(4));
		world.setBlockState(new BlockPos(i + 5, j + 4, k + 11), JourneyBlocks.terraniaVine.getStateFromMeta(4));
		world.setBlockState(new BlockPos(i + 5, j + 5, k + 11), JourneyBlocks.terraniaVine.getStateFromMeta(4));
		world.setBlockState(new BlockPos(i + 5, j + 6, k + 3), JourneyBlocks.terraniaVine.getStateFromMeta(1));
		world.setBlockState(new BlockPos(i + 5, j + 6, k + 11), JourneyBlocks.terraniaVine.getStateFromMeta(4));
		world.setBlockState(new BlockPos(i + 5, j + 7, k + 3), JourneyBlocks.terraniaVine.getStateFromMeta(1));
		world.setBlockState(new BlockPos(i + 5, j + 7, k + 11), JourneyBlocks.terraniaVine.getStateFromMeta(4));
		world.setBlockState(new BlockPos(i + 5, j + 8, k + 3), JourneyBlocks.terraniaVine.getStateFromMeta(1));
		world.setBlockState(new BlockPos(i + 5, j + 8, k + 11), JourneyBlocks.terraniaVine.getStateFromMeta(4));
		world.setBlockState(new BlockPos(i + 5, j + 9, k + 3), JourneyBlocks.terraniaVine.getStateFromMeta(1));
		world.setBlockState(new BlockPos(i + 5, j + 9, k + 11), JourneyBlocks.terraniaVine.getStateFromMeta(4));
		world.setBlockState(new BlockPos(i + 5, j + 10, k + 3), JourneyBlocks.terraniaVine.getStateFromMeta(1));
		world.setBlockState(new BlockPos(i + 5, j + 10, k + 11), JourneyBlocks.terraniaVine.getStateFromMeta(4));
		world.setBlockState(new BlockPos(i + 5, j + 11, k + 3), JourneyBlocks.terraniaVine.getStateFromMeta(1));
		world.setBlockState(new BlockPos(i + 5, j + 11, k + 11), JourneyBlocks.terraniaVine.getStateFromMeta(4));
		world.setBlockState(new BlockPos(i + 5, j + 12, k + 3), JourneyBlocks.terraniaVine.getStateFromMeta(1));
		world.setBlockState(new BlockPos(i + 5, j + 12, k + 11), JourneyBlocks.terraniaVine.getStateFromMeta(4));
		world.setBlockState(new BlockPos(i + 5, j + 14, k + 13), JourneyBlocks.terraniaVine.getStateFromMeta(4));
		world.setBlockState(new BlockPos(i + 5, j + 15, k + 13), JourneyBlocks.terraniaVine.getStateFromMeta(4));
		world.setBlockState(new BlockPos(i + 5, j + 16, k + 13), JourneyBlocks.terraniaVine.getStateFromMeta(4));
		world.setBlockState(new BlockPos(i + 5, j + 22, k + 7), JourneyBlocks.terraniaVine.getDefaultState());
		world.setBlockState(new BlockPos(i + 6, j + 4, k + 11), JourneyBlocks.terraniaVine.getStateFromMeta(4));
		world.setBlockState(new BlockPos(i + 6, j + 6, k + 7), JourneyBlocks.terraniaVine.getStateFromMeta(8));
		world.setBlockState(new BlockPos(i + 6, j + 6, k + 9), JourneyBlocks.terraniaVine.getStateFromMeta(4));
		world.setBlockState(new BlockPos(i + 6, j + 7, k + 7), JourneyBlocks.terraniaVine.getStateFromMeta(8));
		world.setBlockState(new BlockPos(i + 6, j + 7, k + 8), JourneyBlocks.terraniaVine.getStateFromMeta(8));
		world.setBlockState(new BlockPos(i + 6, j + 8, k + 7), JourneyBlocks.terraniaVine.getStateFromMeta(8));
		world.setBlockState(new BlockPos(i + 6, j + 8, k + 8), JourneyBlocks.terraniaVine.getStateFromMeta(8));
		world.setBlockState(new BlockPos(i + 6, j + 9, k + 7), JourneyBlocks.terraniaVine.getStateFromMeta(8));
		world.setBlockState(new BlockPos(i + 6, j + 9, k + 8), JourneyBlocks.terraniaVine.getStateFromMeta(8));
		world.setBlockState(new BlockPos(i + 6, j + 10, k + 7), JourneyBlocks.terraniaVine.getStateFromMeta(8));
		world.setBlockState(new BlockPos(i + 6, j + 11, k + 7), JourneyBlocks.terraniaVine.getStateFromMeta(8));
		world.setBlockState(new BlockPos(i + 6, j + 14, k + 8), JourneyBlocks.terraniaVine.getStateFromMeta(8));
		world.setBlockState(new BlockPos(i + 6, j + 15, k + 7), JourneyBlocks.terraniaVine.getStateFromMeta(8));
		world.setBlockState(new BlockPos(i + 6, j + 15, k + 8), JourneyBlocks.terraniaVine.getStateFromMeta(8));
		world.setBlockState(new BlockPos(i + 6, j + 16, k + 7), JourneyBlocks.terraniaVine.getStateFromMeta(8));
		world.setBlockState(new BlockPos(i + 6, j + 16, k + 8), JourneyBlocks.terraniaVine.getStateFromMeta(8));
		world.setBlockState(new BlockPos(i + 6, j + 17, k + 7), JourneyBlocks.terraniaVine.getStateFromMeta(8));
		world.setBlockState(new BlockPos(i + 6, j + 17, k + 8), JourneyBlocks.terraniaVine.getStateFromMeta(8));
		world.setBlockState(new BlockPos(i + 6, j + 18, k + 7), JourneyBlocks.terraniaVine.getStateFromMeta(8));
		world.setBlockState(new BlockPos(i + 6, j + 18, k + 8), JourneyBlocks.terraniaVine.getStateFromMeta(8));
		world.setBlockState(new BlockPos(i + 6, j + 19, k + 7), JourneyBlocks.terraniaVine.getStateFromMeta(8));
		world.setBlockState(new BlockPos(i + 6, j + 19, k + 8), JourneyBlocks.terraniaVine.getStateFromMeta(8));
		world.setBlockState(new BlockPos(i + 6, j + 20, k + 7), JourneyBlocks.terraniaVine.getStateFromMeta(8));
		world.setBlockState(new BlockPos(i + 6, j + 21, k + 7), JourneyBlocks.terraniaVine.getStateFromMeta(8));
		world.setBlockState(new BlockPos(i + 6, j + 22, k + 7), JourneyBlocks.terraniaVine.getStateFromMeta(8));
		world.setBlockState(new BlockPos(i + 7, j + 6, k + 5), JourneyBlocks.terraniaVine.getStateFromMeta(1));
		world.setBlockState(new BlockPos(i + 7, j + 6, k + 9), JourneyBlocks.terraniaVine.getStateFromMeta(4));
		world.setBlockState(new BlockPos(i + 7, j + 7, k + 5), JourneyBlocks.terraniaVine.getStateFromMeta(1));
		world.setBlockState(new BlockPos(i + 7, j + 7, k + 9), JourneyBlocks.terraniaVine.getStateFromMeta(4));
		world.setBlockState(new BlockPos(i + 7, j + 8, k + 4), JourneyBlocks.terraniaVine.getStateFromMeta(1));
		world.setBlockState(new BlockPos(i + 7, j + 8, k + 5), JourneyBlocks.terraniaVine.getStateFromMeta(1));
		world.setBlockState(new BlockPos(i + 7, j + 8, k + 9), JourneyBlocks.terraniaVine.getStateFromMeta(4));
		world.setBlockState(new BlockPos(i + 7, j + 8, k + 15), JourneyBlocks.terraniaVine.getStateFromMeta(4));
		world.setBlockState(new BlockPos(i + 7, j + 9, k + 4), JourneyBlocks.terraniaVine.getStateFromMeta(1));
		world.setBlockState(new BlockPos(i + 7, j + 9, k + 5), JourneyBlocks.terraniaVine.getStateFromMeta(1));
		world.setBlockState(new BlockPos(i + 7, j + 9, k + 9), JourneyBlocks.terraniaVine.getStateFromMeta(4));
		world.setBlockState(new BlockPos(i + 7, j + 9, k + 15), JourneyBlocks.terraniaVine.getStateFromMeta(4));
		world.setBlockState(new BlockPos(i + 7, j + 10, k + 4), JourneyBlocks.terraniaVine.getStateFromMeta(1));
		world.setBlockState(new BlockPos(i + 7, j + 10, k + 9), JourneyBlocks.terraniaVine.getStateFromMeta(4));
		world.setBlockState(new BlockPos(i + 7, j + 10, k + 15), JourneyBlocks.terraniaVine.getStateFromMeta(4));
		world.setBlockState(new BlockPos(i + 7, j + 11, k + 4), JourneyBlocks.terraniaVine.getStateFromMeta(1));
		world.setBlockState(new BlockPos(i + 7, j + 11, k + 15), JourneyBlocks.terraniaVine.getStateFromMeta(4));
		world.setBlockState(new BlockPos(i + 7, j + 12, k + 4), JourneyBlocks.terraniaVine.getStateFromMeta(1));
		world.setBlockState(new BlockPos(i + 7, j + 12, k + 15), JourneyBlocks.terraniaVine.getStateFromMeta(4));
		world.setBlockState(new BlockPos(i + 7, j + 13, k + 6), JourneyBlocks.terraniaVine.getStateFromMeta(1));
		world.setBlockState(new BlockPos(i + 7, j + 13, k + 15), JourneyBlocks.terraniaVine.getStateFromMeta(4));
		world.setBlockState(new BlockPos(i + 7, j + 14, k + 6), JourneyBlocks.terraniaVine.getStateFromMeta(1));
		world.setBlockState(new BlockPos(i + 7, j + 14, k + 15), JourneyBlocks.terraniaVine.getStateFromMeta(4));
		world.setBlockState(new BlockPos(i + 7, j + 15, k + 6), JourneyBlocks.terraniaVine.getStateFromMeta(1));
		world.setBlockState(new BlockPos(i + 7, j + 15, k + 15), JourneyBlocks.terraniaVine.getStateFromMeta(4));
		world.setBlockState(new BlockPos(i + 7, j + 16, k + 6), JourneyBlocks.terraniaVine.getStateFromMeta(1));
		world.setBlockState(new BlockPos(i + 7, j + 16, k + 15), JourneyBlocks.terraniaVine.getStateFromMeta(4));
		world.setBlockState(new BlockPos(i + 7, j + 17, k + 6), JourneyBlocks.terraniaVine.getStateFromMeta(1));
		world.setBlockState(new BlockPos(i + 7, j + 18, k + 6), JourneyBlocks.terraniaVine.getStateFromMeta(1));
		world.setBlockState(new BlockPos(i + 7, j + 19, k + 6), JourneyBlocks.terraniaVine.getStateFromMeta(1));
		world.setBlockState(new BlockPos(i + 7, j + 20, k + 6), JourneyBlocks.terraniaVine.getStateFromMeta(1));
		world.setBlockState(new BlockPos(i + 7, j + 21, k + 6), JourneyBlocks.terraniaVine.getStateFromMeta(1));
		world.setBlockState(new BlockPos(i + 7, j + 22, k + 6), JourneyBlocks.terraniaVine.getStateFromMeta(1));
		world.setBlockState(new BlockPos(i + 8, j + 5, k + 10), JourneyBlocks.terraniaVine.getStateFromMeta(4));
		world.setBlockState(new BlockPos(i + 8, j + 6, k + 10), JourneyBlocks.terraniaVine.getStateFromMeta(4));
		world.setBlockState(new BlockPos(i + 8, j + 7, k + 9), JourneyBlocks.terraniaVine.getStateFromMeta(4));
		world.setBlockState(new BlockPos(i + 8, j + 8, k + 9), JourneyBlocks.terraniaVine.getStateFromMeta(4));
		world.setBlockState(new BlockPos(i + 8, j + 9, k + 6), JourneyBlocks.terraniaVine.getStateFromMeta(1));
		world.setBlockState(new BlockPos(i + 8, j + 9, k + 9), JourneyBlocks.terraniaVine.getStateFromMeta(4));
		world.setBlockState(new BlockPos(i + 8, j + 10, k + 6), JourneyBlocks.terraniaVine.getStateFromMeta(1));
		world.setBlockState(new BlockPos(i + 8, j + 10, k + 9), JourneyBlocks.terraniaVine.getStateFromMeta(4));
		world.setBlockState(new BlockPos(i + 8, j + 11, k + 6), JourneyBlocks.terraniaVine.getStateFromMeta(1));
		world.setBlockState(new BlockPos(i + 8, j + 12, k + 6), JourneyBlocks.terraniaVine.getStateFromMeta(1));
		world.setBlockState(new BlockPos(i + 8, j + 13, k + 6), JourneyBlocks.terraniaVine.getStateFromMeta(1));
		world.setBlockState(new BlockPos(i + 8, j + 14, k + 6), JourneyBlocks.terraniaVine.getStateFromMeta(1));
		world.setBlockState(new BlockPos(i + 8, j + 15, k + 1), JourneyBlocks.terraniaVine.getStateFromMeta(1));
		world.setBlockState(new BlockPos(i + 8, j + 15, k + 6), JourneyBlocks.terraniaVine.getStateFromMeta(1));
		world.setBlockState(new BlockPos(i + 8, j + 16, k + 1), JourneyBlocks.terraniaVine.getStateFromMeta(1));
		world.setBlockState(new BlockPos(i + 8, j + 16, k + 6), JourneyBlocks.terraniaVine.getStateFromMeta(1));
		world.setBlockState(new BlockPos(i + 8, j + 17, k + 1), JourneyBlocks.terraniaVine.getStateFromMeta(1));
		world.setBlockState(new BlockPos(i + 8, j + 17, k + 6), JourneyBlocks.terraniaVine.getStateFromMeta(1));
		world.setBlockState(new BlockPos(i + 8, j + 17, k + 9), JourneyBlocks.terraniaVine.getStateFromMeta(4));
		world.setBlockState(new BlockPos(i + 8, j + 18, k + 1), JourneyBlocks.terraniaVine.getStateFromMeta(1));
		world.setBlockState(new BlockPos(i + 8, j + 18, k + 9), JourneyBlocks.terraniaVine.getStateFromMeta(4));
		world.setBlockState(new BlockPos(i + 8, j + 19, k + 1), JourneyBlocks.terraniaVine.getStateFromMeta(1));
		world.setBlockState(new BlockPos(i + 8, j + 20, k + 1), JourneyBlocks.terraniaVine.getStateFromMeta(1));
		world.setBlockState(new BlockPos(i + 8, j + 21, k + 1), JourneyBlocks.terraniaVine.getStateFromMeta(1));
		world.setBlockState(new BlockPos(i + 8, j + 22, k + 1), JourneyBlocks.terraniaVine.getStateFromMeta(1));
		world.setBlockState(new BlockPos(i + 8, j + 23, k + 2), JourneyBlocks.terraniaVine.getStateFromMeta(1));
		world.setBlockState(new BlockPos(i + 9, j + 6, k + 5), JourneyBlocks.terraniaVine.getStateFromMeta(1));
		world.setBlockState(new BlockPos(i + 9, j + 6, k + 7), JourneyBlocks.terraniaVine.getStateFromMeta(2));
		world.setBlockState(new BlockPos(i + 9, j + 7, k + 7), JourneyBlocks.terraniaVine.getStateFromMeta(2));
		world.setBlockState(new BlockPos(i + 9, j + 8, k + 7), JourneyBlocks.terraniaVine.getStateFromMeta(2));
		world.setBlockState(new BlockPos(i + 9, j + 8, k + 8), JourneyBlocks.terraniaVine.getStateFromMeta(2));
		world.setBlockState(new BlockPos(i + 9, j + 9, k + 7), JourneyBlocks.terraniaVine.getStateFromMeta(2));
		world.setBlockState(new BlockPos(i + 9, j + 9, k + 8), JourneyBlocks.terraniaVine.getStateFromMeta(2));
		world.setBlockState(new BlockPos(i + 9, j + 10, k + 7), JourneyBlocks.terraniaVine.getStateFromMeta(2));
		world.setBlockState(new BlockPos(i + 9, j + 10, k + 8), JourneyBlocks.terraniaVine.getStateFromMeta(2));
		world.setBlockState(new BlockPos(i + 9, j + 11, k + 7), JourneyBlocks.terraniaVine.getStateFromMeta(2));
		world.setBlockState(new BlockPos(i + 9, j + 11, k + 8), JourneyBlocks.terraniaVine.getStateFromMeta(2));
		world.setBlockState(new BlockPos(i + 9, j + 12, k + 7), JourneyBlocks.terraniaVine.getStateFromMeta(2));
		world.setBlockState(new BlockPos(i + 9, j + 12, k + 8), JourneyBlocks.terraniaVine.getStateFromMeta(2));
		world.setBlockState(new BlockPos(i + 9, j + 15, k + 7), JourneyBlocks.terraniaVine.getStateFromMeta(2));
		world.setBlockState(new BlockPos(i + 9, j + 16, k + 7), JourneyBlocks.terraniaVine.getStateFromMeta(2));
		world.setBlockState(new BlockPos(i + 9, j + 17, k + 7), JourneyBlocks.terraniaVine.getStateFromMeta(2));
		world.setBlockState(new BlockPos(i + 9, j + 18, k + 7), JourneyBlocks.terraniaVine.getStateFromMeta(2));
		world.setBlockState(new BlockPos(i + 9, j + 19, k + 7), JourneyBlocks.terraniaVine.getStateFromMeta(2));
		world.setBlockState(new BlockPos(i + 9, j + 23, k + 3), JourneyBlocks.terraniaVine.getStateFromMeta(2));
		world.setBlockState(new BlockPos(i + 11, j + 12, k + 3), JourneyBlocks.terraniaVine.getStateFromMeta(1));
		world.setBlockState(new BlockPos(i + 11, j + 13, k + 3), JourneyBlocks.terraniaVine.getStateFromMeta(1));
		world.setBlockState(new BlockPos(i + 11, j + 14, k + 3), JourneyBlocks.terraniaVine.getStateFromMeta(1));
		world.setBlockState(new BlockPos(i + 11, j + 15, k + 3), JourneyBlocks.terraniaVine.getStateFromMeta(1));
		world.setBlockState(new BlockPos(i + 11, j + 16, k + 3), JourneyBlocks.terraniaVine.getStateFromMeta(1));
		world.setBlockState(new BlockPos(i + 11, j + 17, k + 3), JourneyBlocks.terraniaVine.getStateFromMeta(1));
		world.setBlockState(new BlockPos(i + 11, j + 18, k + 3), JourneyBlocks.terraniaVine.getStateFromMeta(1));
		world.setBlockState(new BlockPos(i + 11, j + 19, k + 3), JourneyBlocks.terraniaVine.getStateFromMeta(1));
		world.setBlockState(new BlockPos(i + 11, j + 20, k + 3), JourneyBlocks.terraniaVine.getStateFromMeta(1));
		world.setBlockState(new BlockPos(i + 11, j + 21, k + 3), JourneyBlocks.terraniaVine.getStateFromMeta(1));
		world.setBlockState(new BlockPos(i + 11, j + 22, k + 3), JourneyBlocks.terraniaVine.getStateFromMeta(1));
		world.setBlockState(new BlockPos(i + 14, j + 18, k + 6), JourneyBlocks.terraniaVine.getStateFromMeta(1));
		world.setBlockState(new BlockPos(i + 14, j + 19, k + 6), JourneyBlocks.terraniaVine.getStateFromMeta(1));
		world.setBlockState(new BlockPos(i + 14, j + 20, k + 6), JourneyBlocks.terraniaVine.getStateFromMeta(1));
		world.setBlockState(new BlockPos(i + 14, j + 21, k + 6), JourneyBlocks.terraniaVine.getStateFromMeta(1));
		world.setBlockState(new BlockPos(i + 14, j + 22, k + 6), JourneyBlocks.terraniaVine.getStateFromMeta(1));
		world.setBlockState(new BlockPos(i + 15, j + 21, k + 7), JourneyBlocks.terraniaVine.getStateFromMeta(2));
		world.setBlockState(new BlockPos(i + 15, j + 22, k + 7), JourneyBlocks.terraniaVine.getStateFromMeta(2));

		if(!world.isRemote) {
			EntityTerranianTrader smith = new EntityTerranianTrader(world);
			smith.setLocationAndAngles(i + 6, j + 0, k + 9, 0.0F, 0.0F);
			world.spawnEntity(smith);
		}
		return true;
	}
}