package net.journey.dimension.terrania.gen.trees;

import java.util.Random;

import net.journey.JourneyBlocks;
import net.minecraft.block.Block;
import net.minecraft.block.state.IBlockState;
import net.minecraft.init.Blocks;
import net.minecraft.world.World;
import net.minecraft.world.gen.feature.WorldGenerator;
import net.slayer.api.worldgen.WorldGenAPI;

public class WorldGenTerraniaBigTree1 extends WorldGenerator {
	@Override
	public boolean generate(World world, Random rand, BlockPos pos) {
		int i = pos.getX(), j = pos.getY(), k = pos.getZ();
		IBlockState leaves = WorldGenAPI.getTerraniaLeaves().getDefaultState(), log = WorldGenAPI.getTerranianLog().getDefaultState(), vine = WorldGenAPI.getTerraniaVine().getDefaultState();
		i-=5;
		k-=5;
		world.setBlockState(new BlockPos(i + 0, j + 18, k + 5), leaves);
		world.setBlockState(new BlockPos(i + 0, j + 17, k + 5), leaves);
		world.setBlockState(new BlockPos(i + 1, j + 17, k + 3), leaves);
		world.setBlockState(new BlockPos(i + 1, j + 17, k + 4), leaves);
		world.setBlockState(new BlockPos(i + 1, j + 17, k + 5), leaves);
		world.setBlockState(new BlockPos(i + 1, j + 17, k + 6), leaves);
		world.setBlockState(new BlockPos(i + 1, j + 17, k + 8), leaves);
		world.setBlockState(new BlockPos(i + 1, j + 17, k + 9), leaves);
		world.setBlockState(new BlockPos(i + 1, j + 18, k + 5), leaves);
		world.setBlockState(new BlockPos(i + 2, j + 14, k + 10), leaves);
		world.setBlockState(new BlockPos(i + 2, j + 16, k + 1), leaves);
		world.setBlockState(new BlockPos(i + 2, j + 17, k + 2), leaves);
		world.setBlockState(new BlockPos(i + 2, j + 17, k + 3), leaves);
		world.setBlockState(new BlockPos(i + 2, j + 17, k + 4), leaves);
		world.setBlockState(new BlockPos(i + 2, j + 17, k + 5), leaves);
		world.setBlockState(new BlockPos(i + 2, j + 17, k + 6), leaves);
		world.setBlockState(new BlockPos(i + 2, j + 17, k + 7), leaves);
		world.setBlockState(new BlockPos(i + 2, j + 17, k + 8), leaves);
		world.setBlockState(new BlockPos(i + 2, j + 18, k + 4), leaves);
		world.setBlockState(new BlockPos(i + 2, j + 18, k + 5), leaves);
		world.setBlockState(new BlockPos(i + 2, j + 18, k + 6), leaves);
		world.setBlockState(new BlockPos(i + 2, j + 18, k + 7), leaves);
		world.setBlockState(new BlockPos(i + 2, j + 19, k + 5), leaves);
		world.setBlockState(new BlockPos(i + 2, j + 19, k + 6), leaves);
		world.setBlockState(new BlockPos(i + 3, j + 14, k + 8), leaves);
		world.setBlockState(new BlockPos(i + 3, j + 14, k + 9), leaves);
		world.setBlockState(new BlockPos(i + 3, j + 14, k + 10), leaves);
		world.setBlockState(new BlockPos(i + 3, j + 14, k + 11), leaves);
		world.setBlockState(new BlockPos(i + 3, j + 14, k + 12), leaves);
		world.setBlockState(new BlockPos(i + 3, j + 15, k + 10), leaves);
		world.setBlockState(new BlockPos(i + 3, j + 17, k + 1), leaves);
		world.setBlockState(new BlockPos(i + 3, j + 17, k + 2), leaves);
		world.setBlockState(new BlockPos(i + 3, j + 17, k + 3), leaves);
		world.setBlockState(new BlockPos(i + 3, j + 17, k + 4), leaves);
		world.setBlockState(new BlockPos(i + 3, j + 17, k + 5), leaves);
		world.setBlockState(new BlockPos(i + 3, j + 17, k + 6), leaves);
		world.setBlockState(new BlockPos(i + 3, j + 17, k + 7), leaves);
		world.setBlockState(new BlockPos(i + 3, j + 17, k + 8), leaves);
		world.setBlockState(new BlockPos(i + 3, j + 17, k + 9), leaves);
		world.setBlockState(new BlockPos(i + 3, j + 17, k + 10), leaves);
		world.setBlockState(new BlockPos(i + 3, j + 18, k + 3), leaves);
		world.setBlockState(new BlockPos(i + 3, j + 18, k + 4), leaves);
		world.setBlockState(new BlockPos(i + 3, j + 18, k + 5), leaves);
		world.setBlockState(new BlockPos(i + 3, j + 18, k + 6), leaves);
		world.setBlockState(new BlockPos(i + 3, j + 18, k + 7), leaves);
		world.setBlockState(new BlockPos(i + 3, j + 19, k + 4), leaves);
		world.setBlockState(new BlockPos(i + 3, j + 19, k + 5), leaves);
		world.setBlockState(new BlockPos(i + 3, j + 19, k + 6), leaves);
		world.setBlockState(new BlockPos(i + 3, j + 19, k + 7), leaves);
		world.setBlockState(new BlockPos(i + 3, j + 19, k + 8), leaves);
		world.setBlockState(new BlockPos(i + 4, j + 14, k + 8), leaves);
		world.setBlockState(new BlockPos(i + 4, j + 14, k + 9), leaves);
		world.setBlockState(new BlockPos(i + 4, j + 14, k + 10), leaves);
		world.setBlockState(new BlockPos(i + 4, j + 14, k + 11), leaves);
		world.setBlockState(new BlockPos(i + 4, j + 14, k + 12), leaves);
		world.setBlockState(new BlockPos(i + 4, j + 15, k + 9), leaves);
		world.setBlockState(new BlockPos(i + 4, j + 15, k + 10), leaves);
		world.setBlockState(new BlockPos(i + 4, j + 15, k + 11), leaves);
		world.setBlockState(new BlockPos(i + 4, j + 16, k + 10), leaves);
		world.setBlockState(new BlockPos(i + 4, j + 17, k + 2), leaves);
		world.setBlockState(new BlockPos(i + 4, j + 17, k + 3), leaves);
		world.setBlockState(new BlockPos(i + 4, j + 17, k + 4), leaves);
		world.setBlockState(new BlockPos(i + 4, j + 17, k + 5), leaves);
		world.setBlockState(new BlockPos(i + 4, j + 17, k + 6), leaves);
		world.setBlockState(new BlockPos(i + 4, j + 17, k + 7), leaves);
		world.setBlockState(new BlockPos(i + 4, j + 17, k + 8), leaves);
		world.setBlockState(new BlockPos(i + 4, j + 17, k + 9), leaves);
		world.setBlockState(new BlockPos(i + 4, j + 17, k + 10), leaves);
		world.setBlockState(new BlockPos(i + 4, j + 18, k + 2), leaves);
		world.setBlockState(new BlockPos(i + 4, j + 18, k + 3), leaves);
		world.setBlockState(new BlockPos(i + 4, j + 18, k + 4), leaves);
		world.setBlockState(new BlockPos(i + 4, j + 18, k + 5), leaves);
		world.setBlockState(new BlockPos(i + 4, j + 18, k + 6), leaves);
		world.setBlockState(new BlockPos(i + 4, j + 18, k + 7), leaves);
		world.setBlockState(new BlockPos(i + 4, j + 18, k + 8), leaves);
		world.setBlockState(new BlockPos(i + 4, j + 18, k + 9), leaves);
		world.setBlockState(new BlockPos(i + 4, j + 19, k + 3), leaves);
		world.setBlockState(new BlockPos(i + 4, j + 19, k + 4), leaves);
		world.setBlockState(new BlockPos(i + 4, j + 19, k + 5), leaves);
		world.setBlockState(new BlockPos(i + 4, j + 19, k + 6), leaves);
		world.setBlockState(new BlockPos(i + 4, j + 19, k + 7), leaves);
		world.setBlockState(new BlockPos(i + 4, j + 19, k + 8), leaves);
		world.setBlockState(new BlockPos(i + 5, j + 0, k + 5), log);
		world.setBlockState(new BlockPos(i + 5, j + 0, k + 6), log);
		world.setBlockState(new BlockPos(i + 5, j + 1, k + 5), log);
		world.setBlockState(new BlockPos(i + 5, j + 1, k + 6), log);
		world.setBlockState(new BlockPos(i + 5, j + 2, k + 5), log);
		world.setBlockState(new BlockPos(i + 5, j + 2, k + 6), log);
		world.setBlockState(new BlockPos(i + 5, j + 3, k + 5), log);
		world.setBlockState(new BlockPos(i + 5, j + 3, k + 6), log);
		world.setBlockState(new BlockPos(i + 5, j + 4, k + 5), log);
		world.setBlockState(new BlockPos(i + 5, j + 4, k + 6), log);
		world.setBlockState(new BlockPos(i + 5, j + 5, k + 5), log);
		world.setBlockState(new BlockPos(i + 5, j + 5, k + 6), log);
		world.setBlockState(new BlockPos(i + 5, j + 6, k + 5), log);
		world.setBlockState(new BlockPos(i + 5, j + 6, k + 6), log);
		world.setBlockState(new BlockPos(i + 5, j + 7, k + 5), log);
		world.setBlockState(new BlockPos(i + 5, j + 7, k + 6), log);
		world.setBlockState(new BlockPos(i + 5, j + 8, k + 5), log);
		world.setBlockState(new BlockPos(i + 5, j + 8, k + 6), log);
		world.setBlockState(new BlockPos(i + 5, j + 9, k + 5), log);
		world.setBlockState(new BlockPos(i + 5, j + 9, k + 6), log);
		world.setBlockState(new BlockPos(i + 5, j + 10, k + 5), log);
		world.setBlockState(new BlockPos(i + 5, j + 10, k + 6), log);
		world.setBlockState(new BlockPos(i + 5, j + 11, k + 5), log);
		world.setBlockState(new BlockPos(i + 5, j + 11, k + 6), log);
		world.setBlockState(new BlockPos(i + 5, j + 12, k + 5), log);
		world.setBlockState(new BlockPos(i + 5, j + 12, k + 6), log);
		world.setBlockState(new BlockPos(i + 5, j + 13, k + 5), log);
		world.setBlockState(new BlockPos(i + 5, j + 13, k + 6), log);
		world.setBlockState(new BlockPos(i + 5, j + 14, k + 5), log);
		world.setBlockState(new BlockPos(i + 5, j + 14, k + 6), log);
		world.setBlockState(new BlockPos(i + 5, j + 14, k + 7), leaves);
		world.setBlockState(new BlockPos(i + 5, j + 14, k + 8), log);
		world.setBlockState(new BlockPos(i + 5, j + 14, k + 9), log);
		world.setBlockState(new BlockPos(i + 5, j + 14, k + 10), leaves);
		world.setBlockState(new BlockPos(i + 5, j + 14, k + 11), leaves);
		world.setBlockState(new BlockPos(i + 5, j + 14, k + 12), leaves);
		world.setBlockState(new BlockPos(i + 5, j + 14, k + 13), leaves);
		world.setBlockState(new BlockPos(i + 5, j + 15, k + 5), log);
		world.setBlockState(new BlockPos(i + 5, j + 15, k + 6), log);
		world.setBlockState(new BlockPos(i + 5, j + 15, k + 8), leaves);
		world.setBlockState(new BlockPos(i + 5, j + 15, k + 9), leaves);
		world.setBlockState(new BlockPos(i + 5, j + 15, k + 10), log);
		world.setBlockState(new BlockPos(i + 5, j + 15, k + 11), leaves);
		world.setBlockState(new BlockPos(i + 5, j + 15, k + 12), leaves);
		world.setBlockState(new BlockPos(i + 5, j + 16, k + 5), log);
		world.setBlockState(new BlockPos(i + 5, j + 16, k + 6), log);
		world.setBlockState(new BlockPos(i + 5, j + 16, k + 9), leaves);
		world.setBlockState(new BlockPos(i + 5, j + 16, k + 10), leaves);
		world.setBlockState(new BlockPos(i + 5, j + 16, k + 11), leaves);
		world.setBlockState(new BlockPos(i + 5, j + 17, k + 1), leaves);
		world.setBlockState(new BlockPos(i + 5, j + 17, k + 2), leaves);
		world.setBlockState(new BlockPos(i + 5, j + 17, k + 3), leaves);
		world.setBlockState(new BlockPos(i + 5, j + 17, k + 4), leaves);
		world.setBlockState(new BlockPos(i + 5, j + 17, k + 5), log);
		world.setBlockState(new BlockPos(i + 5, j + 17, k + 6), log);
		world.setBlockState(new BlockPos(i + 5, j + 17, k + 7), leaves);
		world.setBlockState(new BlockPos(i + 5, j + 17, k + 8), leaves);
		world.setBlockState(new BlockPos(i + 5, j + 17, k + 9), leaves);
		world.setBlockState(new BlockPos(i + 5, j + 17, k + 10), leaves);
		world.setBlockState(new BlockPos(i + 5, j + 17, k + 11), leaves);
		world.setBlockState(new BlockPos(i + 5, j + 18, k + 1), leaves);
		world.setBlockState(new BlockPos(i + 5, j + 18, k + 2), leaves);
		world.setBlockState(new BlockPos(i + 5, j + 18, k + 3), leaves);
		world.setBlockState(new BlockPos(i + 5, j + 18, k + 4), leaves);
		world.setBlockState(new BlockPos(i + 5, j + 18, k + 5), log);
		world.setBlockState(new BlockPos(i + 5, j + 18, k + 6), leaves);
		world.setBlockState(new BlockPos(i + 5, j + 18, k + 7), leaves);
		world.setBlockState(new BlockPos(i + 5, j + 18, k + 8), leaves);
		world.setBlockState(new BlockPos(i + 5, j + 18, k + 9), leaves);
		world.setBlockState(new BlockPos(i + 5, j + 18, k + 10), leaves);
		world.setBlockState(new BlockPos(i + 5, j + 19, k + 2), leaves);
		world.setBlockState(new BlockPos(i + 5, j + 19, k + 3), leaves);
		world.setBlockState(new BlockPos(i + 5, j + 19, k + 4), leaves);
		world.setBlockState(new BlockPos(i + 5, j + 19, k + 5), leaves);
		world.setBlockState(new BlockPos(i + 5, j + 19, k + 6), leaves);
		world.setBlockState(new BlockPos(i + 5, j + 19, k + 7), leaves);
		world.setBlockState(new BlockPos(i + 5, j + 19, k + 8), leaves);
		world.setBlockState(new BlockPos(i + 5, j + 19, k + 9), leaves);
		world.setBlockState(new BlockPos(i + 6, j + 0, k + 5), log);
		world.setBlockState(new BlockPos(i + 6, j + 0, k + 6), log);
		world.setBlockState(new BlockPos(i + 6, j + 1, k + 5), log);
		world.setBlockState(new BlockPos(i + 6, j + 1, k + 6), log);
		world.setBlockState(new BlockPos(i + 6, j + 2, k + 5), log);
		world.setBlockState(new BlockPos(i + 6, j + 2, k + 6), log);
		world.setBlockState(new BlockPos(i + 6, j + 3, k + 5), log);
		world.setBlockState(new BlockPos(i + 6, j + 3, k + 6), log);
		world.setBlockState(new BlockPos(i + 6, j + 4, k + 5), log);
		world.setBlockState(new BlockPos(i + 6, j + 4, k + 6), log);
		world.setBlockState(new BlockPos(i + 6, j + 5, k + 5), log);
		world.setBlockState(new BlockPos(i + 6, j + 5, k + 6), log);
		world.setBlockState(new BlockPos(i + 6, j + 6, k + 5), log);
		world.setBlockState(new BlockPos(i + 6, j + 6, k + 6), log);
		world.setBlockState(new BlockPos(i + 6, j + 7, k + 5), log);
		world.setBlockState(new BlockPos(i + 6, j + 7, k + 6), log);
		world.setBlockState(new BlockPos(i + 6, j + 8, k + 5), log);
		world.setBlockState(new BlockPos(i + 6, j + 8, k + 6), log);
		world.setBlockState(new BlockPos(i + 6, j + 9, k + 5), log);
		world.setBlockState(new BlockPos(i + 6, j + 9, k + 6), log);
		world.setBlockState(new BlockPos(i + 6, j + 9, k + 9), leaves);
		world.setBlockState(new BlockPos(i + 6, j + 10, k + 5), log);
		world.setBlockState(new BlockPos(i + 6, j + 10, k + 6), log);
		world.setBlockState(new BlockPos(i + 6, j + 11, k + 5), log);
		world.setBlockState(new BlockPos(i + 6, j + 11, k + 6), log);
		world.setBlockState(new BlockPos(i + 6, j + 12, k + 4), leaves);
		world.setBlockState(new BlockPos(i + 6, j + 12, k + 5), log);
		world.setBlockState(new BlockPos(i + 6, j + 12, k + 6), log);
		world.setBlockState(new BlockPos(i + 6, j + 13, k + 5), log);
		world.setBlockState(new BlockPos(i + 6, j + 13, k + 6), log);
		world.setBlockState(new BlockPos(i + 6, j + 13, k + 7), log);
		world.setBlockState(new BlockPos(i + 6, j + 14, k + 5), log);
		world.setBlockState(new BlockPos(i + 6, j + 14, k + 6), log);
		world.setBlockState(new BlockPos(i + 6, j + 14, k + 8), leaves);
		world.setBlockState(new BlockPos(i + 6, j + 14, k + 9), leaves);
		world.setBlockState(new BlockPos(i + 6, j + 14, k + 10), leaves);
		world.setBlockState(new BlockPos(i + 6, j + 14, k + 11), leaves);
		world.setBlockState(new BlockPos(i + 6, j + 14, k + 12), leaves);
		world.setBlockState(new BlockPos(i + 6, j + 15, k + 5), log);
		world.setBlockState(new BlockPos(i + 6, j + 15, k + 6), log);
		world.setBlockState(new BlockPos(i + 6, j + 15, k + 9), leaves);
		world.setBlockState(new BlockPos(i + 6, j + 15, k + 10), leaves);
		world.setBlockState(new BlockPos(i + 6, j + 15, k + 11), leaves);
		world.setBlockState(new BlockPos(i + 6, j + 16, k + 5), log);
		world.setBlockState(new BlockPos(i + 6, j + 16, k + 6), log);
		world.setBlockState(new BlockPos(i + 6, j + 16, k + 10), leaves);
		world.setBlockState(new BlockPos(i + 6, j + 17, k + 1), leaves);
		world.setBlockState(new BlockPos(i + 6, j + 17, k + 2), leaves);
		world.setBlockState(new BlockPos(i + 6, j + 17, k + 3), leaves);
		world.setBlockState(new BlockPos(i + 6, j + 17, k + 4), leaves);
		world.setBlockState(new BlockPos(i + 6, j + 17, k + 5), log);
		world.setBlockState(new BlockPos(i + 6, j + 17, k + 6), log);
		world.setBlockState(new BlockPos(i + 6, j + 17, k + 7), leaves);
		world.setBlockState(new BlockPos(i + 6, j + 17, k + 8), leaves);
		world.setBlockState(new BlockPos(i + 6, j + 17, k + 9), leaves);
		world.setBlockState(new BlockPos(i + 6, j + 17, k + 10), leaves);
		world.setBlockState(new BlockPos(i + 6, j + 17, k + 11), leaves);
		world.setBlockState(new BlockPos(i + 6, j + 18, k + 2), leaves);
		world.setBlockState(new BlockPos(i + 6, j + 18, k + 3), leaves);
		world.setBlockState(new BlockPos(i + 6, j + 18, k + 4), leaves);
		world.setBlockState(new BlockPos(i + 6, j + 18, k + 5), leaves);
		world.setBlockState(new BlockPos(i + 6, j + 18, k + 6), leaves);
		world.setBlockState(new BlockPos(i + 6, j + 18, k + 7), leaves);
		world.setBlockState(new BlockPos(i + 6, j + 18, k + 8), leaves);
		world.setBlockState(new BlockPos(i + 6, j + 18, k + 9), leaves);
		world.setBlockState(new BlockPos(i + 6, j + 18, k + 10), leaves);
		world.setBlockState(new BlockPos(i + 6, j + 19, k + 2), leaves);
		world.setBlockState(new BlockPos(i + 6, j + 19, k + 3), leaves);
		world.setBlockState(new BlockPos(i + 6, j + 19, k + 4), leaves);
		world.setBlockState(new BlockPos(i + 6, j + 19, k + 5), leaves);
		world.setBlockState(new BlockPos(i + 6, j + 19, k + 6), leaves);
		world.setBlockState(new BlockPos(i + 6, j + 19, k + 7), leaves);
		world.setBlockState(new BlockPos(i + 6, j + 19, k + 8), leaves);
		world.setBlockState(new BlockPos(i + 6, j + 19, k + 9), leaves);
		world.setBlockState(new BlockPos(i + 7, j + 8, k + 7), log);
		world.setBlockState(new BlockPos(i + 7, j + 9, k + 7), log);
		world.setBlockState(new BlockPos(i + 7, j + 9, k + 8), leaves);
		world.setBlockState(new BlockPos(i + 7, j + 9, k + 9), leaves);
		world.setBlockState(new BlockPos(i + 7, j + 9, k + 10), leaves);
		world.setBlockState(new BlockPos(i + 7, j + 9, k + 11), leaves);
		world.setBlockState(new BlockPos(i + 7, j + 10, k + 5), log);
		world.setBlockState(new BlockPos(i + 7, j + 10, k + 9), leaves);
		world.setBlockState(new BlockPos(i + 7, j + 11, k + 5), log);
		world.setBlockState(new BlockPos(i + 7, j + 12, k + 3), leaves);
		world.setBlockState(new BlockPos(i + 7, j + 12, k + 4), leaves);
		world.setBlockState(new BlockPos(i + 7, j + 12, k + 5), leaves);
		world.setBlockState(new BlockPos(i + 7, j + 13, k + 4), leaves);
		world.setBlockState(new BlockPos(i + 7, j + 14, k + 8), leaves);
		world.setBlockState(new BlockPos(i + 7, j + 14, k + 9), leaves);
		world.setBlockState(new BlockPos(i + 7, j + 14, k + 10), leaves);
		world.setBlockState(new BlockPos(i + 7, j + 14, k + 11), leaves);
		world.setBlockState(new BlockPos(i + 7, j + 14, k + 12), leaves);
		world.setBlockState(new BlockPos(i + 7, j + 15, k + 10), leaves);
		world.setBlockState(new BlockPos(i + 7, j + 17, k + 2), leaves);
		world.setBlockState(new BlockPos(i + 7, j + 17, k + 3), leaves);
		world.setBlockState(new BlockPos(i + 7, j + 17, k + 4), leaves);
		world.setBlockState(new BlockPos(i + 7, j + 17, k + 5), leaves);
		world.setBlockState(new BlockPos(i + 7, j + 17, k + 6), leaves);
		world.setBlockState(new BlockPos(i + 7, j + 17, k + 7), leaves);
		world.setBlockState(new BlockPos(i + 7, j + 17, k + 8), leaves);
		world.setBlockState(new BlockPos(i + 7, j + 17, k + 9), leaves);
		world.setBlockState(new BlockPos(i + 7, j + 17, k + 10), leaves);
		world.setBlockState(new BlockPos(i + 7, j + 18, k + 3), leaves);
		world.setBlockState(new BlockPos(i + 7, j + 18, k + 4), leaves);
		world.setBlockState(new BlockPos(i + 7, j + 18, k + 5), leaves);
		world.setBlockState(new BlockPos(i + 7, j + 18, k + 6), leaves);
		world.setBlockState(new BlockPos(i + 7, j + 18, k + 7), leaves);
		world.setBlockState(new BlockPos(i + 7, j + 18, k + 8), leaves);
		world.setBlockState(new BlockPos(i + 7, j + 18, k + 9), leaves);
		world.setBlockState(new BlockPos(i + 7, j + 19, k + 4), leaves);
		world.setBlockState(new BlockPos(i + 7, j + 19, k + 5), leaves);
		world.setBlockState(new BlockPos(i + 7, j + 19, k + 6), leaves);
		world.setBlockState(new BlockPos(i + 7, j + 19, k + 7), leaves);
		world.setBlockState(new BlockPos(i + 7, j + 19, k + 8), leaves);
		world.setBlockState(new BlockPos(i + 8, j + 9, k + 7), leaves);
		world.setBlockState(new BlockPos(i + 8, j + 9, k + 8), log);
		world.setBlockState(new BlockPos(i + 8, j + 9, k + 9), leaves);
		world.setBlockState(new BlockPos(i + 8, j + 9, k + 10), leaves);
		world.setBlockState(new BlockPos(i + 8, j + 9, k + 11), leaves);
		world.setBlockState(new BlockPos(i + 8, j + 10, k + 8), leaves);
		world.setBlockState(new BlockPos(i + 8, j + 10, k + 9), leaves);
		world.setBlockState(new BlockPos(i + 8, j + 10, k + 10), leaves);
		world.setBlockState(new BlockPos(i + 8, j + 11, k + 5), log);
		world.setBlockState(new BlockPos(i + 8, j + 11, k + 9), leaves);
		world.setBlockState(new BlockPos(i + 8, j + 12, k + 2), leaves);
		world.setBlockState(new BlockPos(i + 8, j + 12, k + 3), leaves);
		world.setBlockState(new BlockPos(i + 8, j + 12, k + 4), log);
		world.setBlockState(new BlockPos(i + 8, j + 12, k + 5), leaves);
		world.setBlockState(new BlockPos(i + 8, j + 12, k + 6), leaves);
		world.setBlockState(new BlockPos(i + 8, j + 13, k + 3), leaves);
		world.setBlockState(new BlockPos(i + 8, j + 13, k + 4), leaves);
		world.setBlockState(new BlockPos(i + 8, j + 13, k + 5), leaves);
		world.setBlockState(new BlockPos(i + 8, j + 14, k + 10), leaves);
		world.setBlockState(new BlockPos(i + 8, j + 17, k + 1), leaves);
		world.setBlockState(new BlockPos(i + 8, j + 17, k + 2), leaves);
		world.setBlockState(new BlockPos(i + 8, j + 17, k + 3), leaves);
		world.setBlockState(new BlockPos(i + 8, j + 17, k + 4), leaves);
		world.setBlockState(new BlockPos(i + 8, j + 17, k + 5), leaves);
		world.setBlockState(new BlockPos(i + 8, j + 17, k + 6), leaves);
		world.setBlockState(new BlockPos(i + 8, j + 17, k + 7), leaves);
		world.setBlockState(new BlockPos(i + 8, j + 17, k + 8), leaves);
		world.setBlockState(new BlockPos(i + 8, j + 17, k + 9), leaves);
		world.setBlockState(new BlockPos(i + 8, j + 17, k + 10), leaves);
		world.setBlockState(new BlockPos(i + 8, j + 18, k + 4), leaves);
		world.setBlockState(new BlockPos(i + 8, j + 18, k + 5), leaves);
		world.setBlockState(new BlockPos(i + 8, j + 18, k + 6), leaves);
		world.setBlockState(new BlockPos(i + 8, j + 18, k + 7), leaves);
		world.setBlockState(new BlockPos(i + 8, j + 18, k + 8), leaves);
		world.setBlockState(new BlockPos(i + 8, j + 18, k + 9), leaves);
		world.setBlockState(new BlockPos(i + 8, j + 19, k + 4), leaves);
		world.setBlockState(new BlockPos(i + 8, j + 19, k + 5), leaves);
		world.setBlockState(new BlockPos(i + 8, j + 19, k + 6), leaves);
		world.setBlockState(new BlockPos(i + 8, j + 19, k + 7), leaves);
		world.setBlockState(new BlockPos(i + 8, j + 19, k + 8), leaves);
		world.setBlockState(new BlockPos(i + 9, j + 9, k + 6), leaves);
		world.setBlockState(new BlockPos(i + 9, j + 9, k + 7), leaves);
		world.setBlockState(new BlockPos(i + 9, j + 9, k + 8), leaves);
		world.setBlockState(new BlockPos(i + 9, j + 9, k + 9), leaves);
		world.setBlockState(new BlockPos(i + 9, j + 9, k + 10), leaves);
		world.setBlockState(new BlockPos(i + 9, j + 9, k + 11), leaves);
		world.setBlockState(new BlockPos(i + 9, j + 9, k + 12), leaves);
		world.setBlockState(new BlockPos(i + 9, j + 10, k + 7), leaves);
		world.setBlockState(new BlockPos(i + 9, j + 10, k + 8), leaves);
		world.setBlockState(new BlockPos(i + 9, j + 10, k + 9), log);
		world.setBlockState(new BlockPos(i + 9, j + 10, k + 10), leaves);
		world.setBlockState(new BlockPos(i + 9, j + 10, k + 11), leaves);
		world.setBlockState(new BlockPos(i + 9, j + 11, k + 8), leaves);
		world.setBlockState(new BlockPos(i + 9, j + 11, k + 9), leaves);
		world.setBlockState(new BlockPos(i + 9, j + 11, k + 10), leaves);
		world.setBlockState(new BlockPos(i + 9, j + 12, k + 3), leaves);
		world.setBlockState(new BlockPos(i + 9, j + 12, k + 4), leaves);
		world.setBlockState(new BlockPos(i + 9, j + 12, k + 5), leaves);
		world.setBlockState(new BlockPos(i + 9, j + 13, k + 4), leaves);
		world.setBlockState(new BlockPos(i + 9, j + 17, k + 2), leaves);
		world.setBlockState(new BlockPos(i + 9, j + 17, k + 4), leaves);
		world.setBlockState(new BlockPos(i + 9, j + 17, k + 5), leaves);
		world.setBlockState(new BlockPos(i + 9, j + 17, k + 6), leaves);
		world.setBlockState(new BlockPos(i + 9, j + 17, k + 7), leaves);
		world.setBlockState(new BlockPos(i + 9, j + 17, k + 8), leaves);
		world.setBlockState(new BlockPos(i + 9, j + 17, k + 9), leaves);
		world.setBlockState(new BlockPos(i + 9, j + 17, k + 10), leaves);
		world.setBlockState(new BlockPos(i + 9, j + 18, k + 3), leaves);
		world.setBlockState(new BlockPos(i + 9, j + 18, k + 5), leaves);
		world.setBlockState(new BlockPos(i + 9, j + 18, k + 6), leaves);
		world.setBlockState(new BlockPos(i + 9, j + 18, k + 7), leaves);
		world.setBlockState(new BlockPos(i + 9, j + 18, k + 8), leaves);
		world.setBlockState(new BlockPos(i + 9, j + 19, k + 6), leaves);
		world.setBlockState(new BlockPos(i + 10, j + 9, k + 7), leaves);
		world.setBlockState(new BlockPos(i + 10, j + 9, k + 8), leaves);
		world.setBlockState(new BlockPos(i + 10, j + 9, k + 9), leaves);
		world.setBlockState(new BlockPos(i + 10, j + 9, k + 10), leaves);
		world.setBlockState(new BlockPos(i + 10, j + 9, k + 11), leaves);
		world.setBlockState(new BlockPos(i + 10, j + 10, k + 8), leaves);
		world.setBlockState(new BlockPos(i + 10, j + 10, k + 9), leaves);
		world.setBlockState(new BlockPos(i + 10, j + 10, k + 10), leaves);
		world.setBlockState(new BlockPos(i + 10, j + 11, k + 9), leaves);
		world.setBlockState(new BlockPos(i + 10, j + 12, k + 4), leaves);
		world.setBlockState(new BlockPos(i + 10, j + 17, k + 3), leaves);
		world.setBlockState(new BlockPos(i + 10, j + 17, k + 4), leaves);
		world.setBlockState(new BlockPos(i + 10, j + 17, k + 5), leaves);
		world.setBlockState(new BlockPos(i + 10, j + 17, k + 6), leaves);
		world.setBlockState(new BlockPos(i + 10, j + 17, k + 7), leaves);
		world.setBlockState(new BlockPos(i + 10, j + 17, k + 8), leaves);
		world.setBlockState(new BlockPos(i + 10, j + 17, k + 9), leaves);
		world.setBlockState(new BlockPos(i + 11, j + 9, k + 7), leaves);
		world.setBlockState(new BlockPos(i + 11, j + 9, k + 8), leaves);
		world.setBlockState(new BlockPos(i + 11, j + 9, k + 9), leaves);
		world.setBlockState(new BlockPos(i + 11, j + 9, k + 10), leaves);
		world.setBlockState(new BlockPos(i + 11, j + 10, k + 9), leaves);
		world.setBlockState(new BlockPos(i + 12, j + 9, k + 9), leaves);
		world.setBlockState(new BlockPos(i + 0, j + 14, k + 8), JourneyBlocks.terraniaVine.getStateFromMeta(8));
		world.setBlockState(new BlockPos(i + 0, j + 15, k + 8), JourneyBlocks.terraniaVine.getStateFromMeta(8));
		world.setBlockState(new BlockPos(i + 0, j + 16, k + 8), JourneyBlocks.terraniaVine.getStateFromMeta(8));
		world.setBlockState(new BlockPos(i + 0, j + 17, k + 3), JourneyBlocks.terraniaVine.getStateFromMeta(8));
		world.setBlockState(new BlockPos(i + 0, j + 17, k + 8), JourneyBlocks.terraniaVine.getStateFromMeta(8));
		world.setBlockState(new BlockPos(i + 1, j + 11, k + 10), JourneyBlocks.terraniaVine.getStateFromMeta(8));
		world.setBlockState(new BlockPos(i + 1, j + 12, k + 10), JourneyBlocks.terraniaVine.getStateFromMeta(8));
		world.setBlockState(new BlockPos(i + 1, j + 13, k + 10), JourneyBlocks.terraniaVine.getStateFromMeta(8));
		world.setBlockState(new BlockPos(i + 1, j + 14, k + 1), JourneyBlocks.terraniaVine.getStateFromMeta(8));
		world.setBlockState(new BlockPos(i + 1, j + 14, k + 10), JourneyBlocks.terraniaVine.getStateFromMeta(8));
		world.setBlockState(new BlockPos(i + 1, j + 15, k + 1), JourneyBlocks.terraniaVine.getStateFromMeta(8));
		world.setBlockState(new BlockPos(i + 1, j + 16, k + 1), JourneyBlocks.terraniaVine.getStateFromMeta(8));
		world.setBlockState(new BlockPos(i + 2, j + 11, k + 11), JourneyBlocks.terraniaVine.getStateFromMeta(4));
		world.setBlockState(new BlockPos(i + 2, j + 12, k + 11), JourneyBlocks.terraniaVine.getStateFromMeta(4));
		world.setBlockState(new BlockPos(i + 2, j + 13, k + 11), JourneyBlocks.terraniaVine.getStateFromMeta(4));
		world.setBlockState(new BlockPos(i + 2, j + 14, k + 11), JourneyBlocks.terraniaVine.getStateFromMeta(4));
		world.setBlockState(new BlockPos(i + 3, j + 12, k + 13), JourneyBlocks.terraniaVine.getStateFromMeta(4));
		world.setBlockState(new BlockPos(i + 3, j + 13, k + 13), JourneyBlocks.terraniaVine.getStateFromMeta(4));
		world.setBlockState(new BlockPos(i + 3, j + 14, k + 13), JourneyBlocks.terraniaVine.getStateFromMeta(4));
		world.setBlockState(new BlockPos(i + 4, j + 1, k + 5), JourneyBlocks.terraniaVine.getStateFromMeta(8));
		world.setBlockState(new BlockPos(i + 4, j + 1, k + 6), JourneyBlocks.terraniaVine.getStateFromMeta(8));
		world.setBlockState(new BlockPos(i + 4, j + 2, k + 5), JourneyBlocks.terraniaVine.getStateFromMeta(8));
		world.setBlockState(new BlockPos(i + 4, j + 2, k + 6), JourneyBlocks.terraniaVine.getStateFromMeta(8));
		world.setBlockState(new BlockPos(i + 4, j + 4, k + 5), JourneyBlocks.terraniaVine.getStateFromMeta(8));
		world.setBlockState(new BlockPos(i + 4, j + 4, k + 6), JourneyBlocks.terraniaVine.getStateFromMeta(8));
		world.setBlockState(new BlockPos(i + 4, j + 5, k + 6), JourneyBlocks.terraniaVine.getStateFromMeta(8));
		world.setBlockState(new BlockPos(i + 4, j + 6, k + 5), JourneyBlocks.terraniaVine.getStateFromMeta(8));
		world.setBlockState(new BlockPos(i + 4, j + 7, k + 6), JourneyBlocks.terraniaVine.getStateFromMeta(8));
		world.setBlockState(new BlockPos(i + 4, j + 8, k + 6), JourneyBlocks.terraniaVine.getStateFromMeta(8));
		world.setBlockState(new BlockPos(i + 4, j + 9, k + 5), JourneyBlocks.terraniaVine.getStateFromMeta(8));
		world.setBlockState(new BlockPos(i + 4, j + 9, k + 6), JourneyBlocks.terraniaVine.getStateFromMeta(8));
		world.setBlockState(new BlockPos(i + 4, j + 10, k + 5), JourneyBlocks.terraniaVine.getStateFromMeta(8));
		world.setBlockState(new BlockPos(i + 4, j + 11, k + 5), JourneyBlocks.terraniaVine.getStateFromMeta(8));
		world.setBlockState(new BlockPos(i + 4, j + 12, k + 5), JourneyBlocks.terraniaVine.getStateFromMeta(8));
		world.setBlockState(new BlockPos(i + 4, j + 13, k + 5), JourneyBlocks.terraniaVine.getStateFromMeta(8));
		world.setBlockState(new BlockPos(i + 4, j + 13, k + 6), JourneyBlocks.terraniaVine.getStateFromMeta(8));
		world.setBlockState(new BlockPos(i + 4, j + 14, k + 5), JourneyBlocks.terraniaVine.getStateFromMeta(8));
		world.setBlockState(new BlockPos(i + 4, j + 15, k + 5), JourneyBlocks.terraniaVine.getStateFromMeta(8));
		world.setBlockState(new BlockPos(i + 4, j + 15, k + 6), JourneyBlocks.terraniaVine.getStateFromMeta(8));
		world.setBlockState(new BlockPos(i + 4, j + 16, k + 6), JourneyBlocks.terraniaVine.getStateFromMeta(8));
		world.setBlockState(new BlockPos(i + 5, j + 1, k + 4), JourneyBlocks.terraniaVine.getStateFromMeta(1));
		world.setBlockState(new BlockPos(i + 5, j + 1, k + 7), JourneyBlocks.terraniaVine.getStateFromMeta(4));
		world.setBlockState(new BlockPos(i + 5, j + 2, k + 4), JourneyBlocks.terraniaVine.getStateFromMeta(1));
		world.setBlockState(new BlockPos(i + 5, j + 3, k + 4), JourneyBlocks.terraniaVine.getStateFromMeta(1));
		world.setBlockState(new BlockPos(i + 5, j + 3, k + 7), JourneyBlocks.terraniaVine.getStateFromMeta(4));
		world.setBlockState(new BlockPos(i + 5, j + 4, k + 4), JourneyBlocks.terraniaVine.getStateFromMeta(1));
		world.setBlockState(new BlockPos(i + 5, j + 4, k + 7), JourneyBlocks.terraniaVine.getStateFromMeta(4));
		world.setBlockState(new BlockPos(i + 5, j + 5, k + 4), JourneyBlocks.terraniaVine.getStateFromMeta(1));
		world.setBlockState(new BlockPos(i + 5, j + 7, k + 7), JourneyBlocks.terraniaVine.getStateFromMeta(4));
		world.setBlockState(new BlockPos(i + 5, j + 7, k + 9), JourneyBlocks.terraniaVine.getStateFromMeta(8));
		world.setBlockState(new BlockPos(i + 5, j + 8, k + 9), JourneyBlocks.terraniaVine.getStateFromMeta(8));
		world.setBlockState(new BlockPos(i + 5, j + 9, k + 4), JourneyBlocks.terraniaVine.getStateFromMeta(1));
		world.setBlockState(new BlockPos(i + 5, j + 9, k + 7), JourneyBlocks.terraniaVine.getStateFromMeta(4));
		world.setBlockState(new BlockPos(i + 5, j + 9, k + 9), JourneyBlocks.terraniaVine.getStateFromMeta(8));
		world.setBlockState(new BlockPos(i + 5, j + 10, k + 4), JourneyBlocks.terraniaVine.getStateFromMeta(1));
		world.setBlockState(new BlockPos(i + 5, j + 10, k + 7), JourneyBlocks.terraniaVine.getStateFromMeta(4));
		world.setBlockState(new BlockPos(i + 5, j + 10, k + 14), JourneyBlocks.terraniaVine.getStateFromMeta(4));
		world.setBlockState(new BlockPos(i + 5, j + 11, k + 14), JourneyBlocks.terraniaVine.getStateFromMeta(4));
		world.setBlockState(new BlockPos(i + 5, j + 12, k + 4), JourneyBlocks.terraniaVine.getStateFromMeta(1));
		world.setBlockState(new BlockPos(i + 5, j + 12, k + 7), JourneyBlocks.terraniaVine.getStateFromMeta(4));
		world.setBlockState(new BlockPos(i + 5, j + 12, k + 14), JourneyBlocks.terraniaVine.getStateFromMeta(4));
		world.setBlockState(new BlockPos(i + 5, j + 13, k + 4), JourneyBlocks.terraniaVine.getStateFromMeta(1));
		world.setBlockState(new BlockPos(i + 5, j + 13, k + 14), JourneyBlocks.terraniaVine.getStateFromMeta(4));
		world.setBlockState(new BlockPos(i + 5, j + 14, k + 4), JourneyBlocks.terraniaVine.getStateFromMeta(1));
		world.setBlockState(new BlockPos(i + 5, j + 14, k + 14), JourneyBlocks.terraniaVine.getStateFromMeta(4));
		world.setBlockState(new BlockPos(i + 5, j + 15, k + 7), JourneyBlocks.terraniaVine.getStateFromMeta(4));
		world.setBlockState(new BlockPos(i + 5, j + 16, k + 4), JourneyBlocks.terraniaVine.getStateFromMeta(1));
		world.setBlockState(new BlockPos(i + 6, j + 1, k + 4), JourneyBlocks.terraniaVine.getStateFromMeta(1));
		world.setBlockState(new BlockPos(i + 6, j + 1, k + 7), JourneyBlocks.terraniaVine.getStateFromMeta(4));
		world.setBlockState(new BlockPos(i + 6, j + 2, k + 4), JourneyBlocks.terraniaVine.getStateFromMeta(1));
		world.setBlockState(new BlockPos(i + 6, j + 2, k + 7), JourneyBlocks.terraniaVine.getStateFromMeta(4));
		world.setBlockState(new BlockPos(i + 6, j + 3, k + 4), JourneyBlocks.terraniaVine.getStateFromMeta(1));
		world.setBlockState(new BlockPos(i + 6, j + 3, k + 7), JourneyBlocks.terraniaVine.getStateFromMeta(4));
		world.setBlockState(new BlockPos(i + 6, j + 4, k + 4), JourneyBlocks.terraniaVine.getStateFromMeta(1));
		world.setBlockState(new BlockPos(i + 6, j + 4, k + 7), JourneyBlocks.terraniaVine.getStateFromMeta(4));
		world.setBlockState(new BlockPos(i + 6, j + 5, k + 4), JourneyBlocks.terraniaVine.getStateFromMeta(1));
		world.setBlockState(new BlockPos(i + 6, j + 5, k + 7), JourneyBlocks.terraniaVine.getStateFromMeta(4));
		world.setBlockState(new BlockPos(i + 6, j + 6, k + 4), JourneyBlocks.terraniaVine.getStateFromMeta(1));
		world.setBlockState(new BlockPos(i + 6, j + 6, k + 7), JourneyBlocks.terraniaVine.getStateFromMeta(4));
		world.setBlockState(new BlockPos(i + 6, j + 7, k + 4), JourneyBlocks.terraniaVine.getStateFromMeta(1));
		world.setBlockState(new BlockPos(i + 6, j + 7, k + 7), JourneyBlocks.terraniaVine.getStateFromMeta(4));
		world.setBlockState(new BlockPos(i + 6, j + 8, k + 4), JourneyBlocks.terraniaVine.getStateFromMeta(1));
		world.setBlockState(new BlockPos(i + 6, j + 9, k + 4), JourneyBlocks.terraniaVine.getStateFromMeta(1));
		world.setBlockState(new BlockPos(i + 6, j + 9, k + 7), JourneyBlocks.terraniaVine.getStateFromMeta(4));
		world.setBlockState(new BlockPos(i + 6, j + 10, k + 4), JourneyBlocks.terraniaVine.getStateFromMeta(1));
		world.setBlockState(new BlockPos(i + 6, j + 13, k + 4), JourneyBlocks.terraniaVine.getStateFromMeta(1));
		world.setBlockState(new BlockPos(i + 6, j + 14, k + 4), JourneyBlocks.terraniaVine.getStateFromMeta(1));
		world.setBlockState(new BlockPos(i + 6, j + 15, k + 4), JourneyBlocks.terraniaVine.getStateFromMeta(1));
		world.setBlockState(new BlockPos(i + 6, j + 16, k + 4), JourneyBlocks.terraniaVine.getStateFromMeta(1));
		world.setBlockState(new BlockPos(i + 6, j + 16, k + 7), JourneyBlocks.terraniaVine.getStateFromMeta(4));
		world.setBlockState(new BlockPos(i + 7, j + 1, k + 5), JourneyBlocks.terraniaVine.getStateFromMeta(2));
		world.setBlockState(new BlockPos(i + 7, j + 1, k + 6), JourneyBlocks.terraniaVine.getStateFromMeta(2));
		world.setBlockState(new BlockPos(i + 7, j + 2, k + 5), JourneyBlocks.terraniaVine.getStateFromMeta(2));
		world.setBlockState(new BlockPos(i + 7, j + 3, k + 5), JourneyBlocks.terraniaVine.getStateFromMeta(2));
		world.setBlockState(new BlockPos(i + 7, j + 3, k + 6), JourneyBlocks.terraniaVine.getStateFromMeta(2));
		world.setBlockState(new BlockPos(i + 7, j + 4, k + 5), JourneyBlocks.terraniaVine.getStateFromMeta(2));
		world.setBlockState(new BlockPos(i + 7, j + 4, k + 6), JourneyBlocks.terraniaVine.getStateFromMeta(2));
		world.setBlockState(new BlockPos(i + 7, j + 5, k + 5), JourneyBlocks.terraniaVine.getStateFromMeta(2));
		world.setBlockState(new BlockPos(i + 7, j + 5, k + 6), JourneyBlocks.terraniaVine.getStateFromMeta(2));
		world.setBlockState(new BlockPos(i + 7, j + 6, k + 5), JourneyBlocks.terraniaVine.getStateFromMeta(2));
		world.setBlockState(new BlockPos(i + 7, j + 6, k + 6), JourneyBlocks.terraniaVine.getStateFromMeta(2));
		world.setBlockState(new BlockPos(i + 7, j + 9, k + 5), JourneyBlocks.terraniaVine.getStateFromMeta(2));
		world.setBlockState(new BlockPos(i + 7, j + 9, k + 6), JourneyBlocks.terraniaVine.getStateFromMeta(2));
		world.setBlockState(new BlockPos(i + 7, j + 14, k + 5), JourneyBlocks.terraniaVine.getStateFromMeta(2));
		world.setBlockState(new BlockPos(i + 7, j + 14, k + 6), JourneyBlocks.terraniaVine.getStateFromMeta(2));
		world.setBlockState(new BlockPos(i + 7, j + 15, k + 5), JourneyBlocks.terraniaVine.getStateFromMeta(2));
		world.setBlockState(new BlockPos(i + 7, j + 15, k + 6), JourneyBlocks.terraniaVine.getStateFromMeta(2));
		world.setBlockState(new BlockPos(i + 7, j + 16, k + 6), JourneyBlocks.terraniaVine.getStateFromMeta(2));
		world.setBlockState(new BlockPos(i + 9, j + 4, k + 13), JourneyBlocks.terraniaVine.getStateFromMeta(4));
		world.setBlockState(new BlockPos(i + 9, j + 5, k + 13), JourneyBlocks.terraniaVine.getStateFromMeta(4));
		world.setBlockState(new BlockPos(i + 9, j + 6, k + 13), JourneyBlocks.terraniaVine.getStateFromMeta(4));
		world.setBlockState(new BlockPos(i + 9, j + 7, k + 5), JourneyBlocks.terraniaVine.getStateFromMeta(1));
		world.setBlockState(new BlockPos(i + 9, j + 7, k + 13), JourneyBlocks.terraniaVine.getStateFromMeta(4));
		world.setBlockState(new BlockPos(i + 9, j + 8, k + 5), JourneyBlocks.terraniaVine.getStateFromMeta(1));
		world.setBlockState(new BlockPos(i + 9, j + 8, k + 13), JourneyBlocks.terraniaVine.getStateFromMeta(4));
		world.setBlockState(new BlockPos(i + 9, j + 9, k + 5), JourneyBlocks.terraniaVine.getStateFromMeta(1));
		world.setBlockState(new BlockPos(i + 9, j + 9, k + 13), JourneyBlocks.terraniaVine.getStateFromMeta(4));
		world.setBlockState(new BlockPos(i + 11, j + 8, k + 6), JourneyBlocks.terraniaVine.getStateFromMeta(1));
		world.setBlockState(new BlockPos(i + 11, j + 9, k + 6), JourneyBlocks.terraniaVine.getStateFromMeta(1));
		world.setBlockState(new BlockPos(i + 12, j + 8, k + 7), JourneyBlocks.terraniaVine.getStateFromMeta(2));
		world.setBlockState(new BlockPos(i + 12, j + 9, k + 7), JourneyBlocks.terraniaVine.getStateFromMeta(2));
		world.setBlockState(new BlockPos(i + 13, j + 6, k + 9), JourneyBlocks.terraniaVine.getStateFromMeta(2));
		world.setBlockState(new BlockPos(i + 13, j + 7, k + 9), JourneyBlocks.terraniaVine.getStateFromMeta(2));
		world.setBlockState(new BlockPos(i + 13, j + 8, k + 9), JourneyBlocks.terraniaVine.getStateFromMeta(2));
		world.setBlockState(new BlockPos(i + 13, j + 9, k + 9), JourneyBlocks.terraniaVine.getStateFromMeta(2));

		return true;
	}
}