package net.journey.dimension.depths.gen;

import java.util.Random;

import net.journey.JourneyBlocks;
import net.journey.entity.mob.depths.npc.EntityStaringGuardian;
import net.minecraft.util.math.BlockPos;
import net.minecraft.world.World;
import net.minecraft.world.gen.feature.WorldGenerator;

public class WorldGenGuardianTower extends WorldGenerator {
	
	@Override
	public boolean generate(World world, Random rand, BlockPos pos) {
		int i = pos.getX(), j = pos.getY(), k = pos.getZ();
		i-=5;
		k-=5;
		world.setBlockState(new BlockPos(i + 0, j + 6, k + 3), JourneyBlocks.darkFloor.getDefaultState());
		world.setBlockState(new BlockPos(i + 0, j + 6, k + 4), JourneyBlocks.darkFloor.getDefaultState());
		world.setBlockState(new BlockPos(i + 0, j + 6, k + 5), JourneyBlocks.darkFloor.getDefaultState());
		world.setBlockState(new BlockPos(i + 0, j + 6, k + 6), JourneyBlocks.darkFloor.getDefaultState());
		world.setBlockState(new BlockPos(i + 0, j + 7, k + 4), JourneyBlocks.darkBrick.getDefaultState());
		world.setBlockState(new BlockPos(i + 0, j + 7, k + 5), JourneyBlocks.darkBrick.getDefaultState());
		world.setBlockState(new BlockPos(i + 1, j + 6, k + 2), JourneyBlocks.darkFloor.getDefaultState());
		world.setBlockState(new BlockPos(i + 1, j + 6, k + 3), JourneyBlocks.darkFloor.getDefaultState());
		world.setBlockState(new BlockPos(i + 1, j + 6, k + 4), JourneyBlocks.darkFloor.getDefaultState());
		world.setBlockState(new BlockPos(i + 1, j + 6, k + 5), JourneyBlocks.darkFloor.getDefaultState());
		world.setBlockState(new BlockPos(i + 1, j + 6, k + 6), JourneyBlocks.darkFloor.getDefaultState());
		world.setBlockState(new BlockPos(i + 1, j + 6, k + 7), JourneyBlocks.darkFloor.getDefaultState());
		world.setBlockState(new BlockPos(i + 1, j + 7, k + 2), JourneyBlocks.darkBrick.getDefaultState());
		world.setBlockState(new BlockPos(i + 1, j + 7, k + 7), JourneyBlocks.darkBrick.getDefaultState());
		world.setBlockState(new BlockPos(i + 2, j + 0, k + 3), JourneyBlocks.darkShingle.getDefaultState());
		world.setBlockState(new BlockPos(i + 2, j + 0, k + 5), JourneyBlocks.depthsGrass.getDefaultState());
		world.setBlockState(new BlockPos(i + 2, j + 0, k + 6), JourneyBlocks.darkShingle.getDefaultState());
		world.setBlockState(new BlockPos(i + 2, j + 0, k + 7), JourneyBlocks.depthsGrass.getDefaultState());
		world.setBlockState(new BlockPos(i + 2, j + 1, k + 3), JourneyBlocks.depthsGrass.getDefaultState());
		world.setBlockState(new BlockPos(i + 2, j + 1, k + 6), JourneyBlocks.depthsGrass.getDefaultState());
		world.setBlockState(new BlockPos(i + 2, j + 6, k + 1), JourneyBlocks.darkFloor.getDefaultState());
		world.setBlockState(new BlockPos(i + 2, j + 6, k + 2), JourneyBlocks.darkFloor.getDefaultState());
		world.setBlockState(new BlockPos(i + 2, j + 6, k + 3), JourneyBlocks.darkFloor.getDefaultState());
		world.setBlockState(new BlockPos(i + 2, j + 6, k + 4), JourneyBlocks.darkFloor.getDefaultState());
		world.setBlockState(new BlockPos(i + 2, j + 6, k + 5), JourneyBlocks.darkFloor.getDefaultState());
		world.setBlockState(new BlockPos(i + 2, j + 6, k + 6), JourneyBlocks.darkFloor.getDefaultState());
		world.setBlockState(new BlockPos(i + 2, j + 6, k + 7), JourneyBlocks.darkFloor.getDefaultState());
		world.setBlockState(new BlockPos(i + 2, j + 6, k + 8), JourneyBlocks.darkFloor.getDefaultState());
		world.setBlockState(new BlockPos(i + 2, j + 7, k + 1), JourneyBlocks.darkBrick.getDefaultState());
		world.setBlockState(new BlockPos(i + 2, j + 7, k + 8), JourneyBlocks.darkBrick.getDefaultState());
		world.setBlockState(new BlockPos(i + 3, j + 0, k + 2), JourneyBlocks.depthsGrass.getDefaultState());
		world.setBlockState(new BlockPos(i + 3, j + 0, k + 3), JourneyBlocks.darkBrick.getDefaultState());
		world.setBlockState(new BlockPos(i + 3, j + 0, k + 4), JourneyBlocks.darkShingle.getDefaultState());
		world.setBlockState(new BlockPos(i + 3, j + 0, k + 5), JourneyBlocks.darkShingle.getDefaultState());
		world.setBlockState(new BlockPos(i + 3, j + 0, k + 6), JourneyBlocks.darkBrick.getDefaultState());
		world.setBlockState(new BlockPos(i + 3, j + 0, k + 7), JourneyBlocks.darkShingle.getDefaultState());
		world.setBlockState(new BlockPos(i + 3, j + 1, k + 3), JourneyBlocks.darkBrick.getDefaultState());
		world.setBlockState(new BlockPos(i + 3, j + 1, k + 4), JourneyBlocks.darkShingle.getDefaultState());
		world.setBlockState(new BlockPos(i + 3, j + 1, k + 5), JourneyBlocks.darkShingle.getDefaultState());
		world.setBlockState(new BlockPos(i + 3, j + 1, k + 6), JourneyBlocks.darkBrick.getDefaultState());
		world.setBlockState(new BlockPos(i + 3, j + 1, k + 7), JourneyBlocks.depthsGrass.getDefaultState());
		world.setBlockState(new BlockPos(i + 3, j + 2, k + 3), JourneyBlocks.darkBrick.getDefaultState());
		world.setBlockState(new BlockPos(i + 3, j + 2, k + 4), JourneyBlocks.darkShingle.getDefaultState());
		world.setBlockState(new BlockPos(i + 3, j + 2, k + 5), JourneyBlocks.darkShingle.getDefaultState());
		world.setBlockState(new BlockPos(i + 3, j + 2, k + 6), JourneyBlocks.darkBrick.getDefaultState());
		world.setBlockState(new BlockPos(i + 3, j + 3, k + 3), JourneyBlocks.darkBrick.getDefaultState());
		world.setBlockState(new BlockPos(i + 3, j + 3, k + 4), JourneyBlocks.darkShingle.getDefaultState());
		world.setBlockState(new BlockPos(i + 3, j + 3, k + 5), JourneyBlocks.darkShingle.getDefaultState());
		world.setBlockState(new BlockPos(i + 3, j + 3, k + 6), JourneyBlocks.darkBrick.getDefaultState());
		world.setBlockState(new BlockPos(i + 3, j + 4, k + 3), JourneyBlocks.darkBrick.getDefaultState());
		world.setBlockState(new BlockPos(i + 3, j + 4, k + 4), JourneyBlocks.darkShingle.getDefaultState());
		world.setBlockState(new BlockPos(i + 3, j + 4, k + 5), JourneyBlocks.darkShingle.getDefaultState());
		world.setBlockState(new BlockPos(i + 3, j + 4, k + 6), JourneyBlocks.darkBrick.getDefaultState());
		world.setBlockState(new BlockPos(i + 3, j + 5, k + 3), JourneyBlocks.darkBrick.getDefaultState());
		world.setBlockState(new BlockPos(i + 3, j + 5, k + 4), JourneyBlocks.darkShingle.getDefaultState());
		world.setBlockState(new BlockPos(i + 3, j + 5, k + 5), JourneyBlocks.darkShingle.getDefaultState());
		world.setBlockState(new BlockPos(i + 3, j + 5, k + 6), JourneyBlocks.darkBrick.getDefaultState());
		world.setBlockState(new BlockPos(i + 3, j + 6, k + 0), JourneyBlocks.darkFloor.getDefaultState());
		world.setBlockState(new BlockPos(i + 3, j + 6, k + 1), JourneyBlocks.darkFloor.getDefaultState());
		world.setBlockState(new BlockPos(i + 3, j + 6, k + 2), JourneyBlocks.darkFloor.getDefaultState());
		world.setBlockState(new BlockPos(i + 3, j + 6, k + 3), JourneyBlocks.darkFloor.getDefaultState());
		world.setBlockState(new BlockPos(i + 3, j + 6, k + 4), JourneyBlocks.darkFloor.getDefaultState());
		world.setBlockState(new BlockPos(i + 3, j + 6, k + 5), JourneyBlocks.darkFloor.getDefaultState());
		world.setBlockState(new BlockPos(i + 3, j + 6, k + 6), JourneyBlocks.darkFloor.getDefaultState());
		world.setBlockState(new BlockPos(i + 3, j + 6, k + 7), JourneyBlocks.darkFloor.getDefaultState());
		world.setBlockState(new BlockPos(i + 3, j + 6, k + 8), JourneyBlocks.darkFloor.getDefaultState());
		world.setBlockState(new BlockPos(i + 3, j + 6, k + 9), JourneyBlocks.darkFloor.getDefaultState());
		world.setBlockState(new BlockPos(i + 4, j + 0, k + 3), JourneyBlocks.darkShingle.getDefaultState());
		world.setBlockState(new BlockPos(i + 4, j + 0, k + 6), JourneyBlocks.darkShingle.getDefaultState());
		world.setBlockState(new BlockPos(i + 4, j + 0, k + 7), JourneyBlocks.depthsGrass.getDefaultState());
		world.setBlockState(new BlockPos(i + 4, j + 1, k + 3), JourneyBlocks.darkShingle.getDefaultState());
		world.setBlockState(new BlockPos(i + 4, j + 1, k + 6), JourneyBlocks.darkShingle.getDefaultState());
		world.setBlockState(new BlockPos(i + 4, j + 2, k + 3), JourneyBlocks.darkShingle.getDefaultState());
		world.setBlockState(new BlockPos(i + 4, j + 2, k + 6), JourneyBlocks.darkShingle.getDefaultState());
		world.setBlockState(new BlockPos(i + 4, j + 3, k + 3), JourneyBlocks.darkShingle.getDefaultState());
		world.setBlockState(new BlockPos(i + 4, j + 3, k + 6), JourneyBlocks.darkShingle.getDefaultState());
		world.setBlockState(new BlockPos(i + 4, j + 4, k + 3), JourneyBlocks.darkShingle.getDefaultState());
		world.setBlockState(new BlockPos(i + 4, j + 4, k + 6), JourneyBlocks.darkShingle.getDefaultState());
		world.setBlockState(new BlockPos(i + 4, j + 5, k + 3), JourneyBlocks.darkShingle.getDefaultState());
		world.setBlockState(new BlockPos(i + 4, j + 5, k + 6), JourneyBlocks.darkShingle.getDefaultState());
		world.setBlockState(new BlockPos(i + 4, j + 6, k + 0), JourneyBlocks.darkFloor.getDefaultState());
		world.setBlockState(new BlockPos(i + 4, j + 6, k + 1), JourneyBlocks.darkFloor.getDefaultState());
		world.setBlockState(new BlockPos(i + 4, j + 6, k + 2), JourneyBlocks.darkFloor.getDefaultState());
		world.setBlockState(new BlockPos(i + 4, j + 6, k + 3), JourneyBlocks.darkFloor.getDefaultState());
		world.setBlockState(new BlockPos(i + 4, j + 6, k + 4), JourneyBlocks.darkShingle.getDefaultState());
		world.setBlockState(new BlockPos(i + 4, j + 6, k + 5), JourneyBlocks.darkShingle.getDefaultState());
		world.setBlockState(new BlockPos(i + 4, j + 6, k + 6), JourneyBlocks.darkFloor.getDefaultState());
		world.setBlockState(new BlockPos(i + 4, j + 6, k + 7), JourneyBlocks.darkFloor.getDefaultState());
		world.setBlockState(new BlockPos(i + 4, j + 6, k + 8), JourneyBlocks.darkFloor.getDefaultState());
		world.setBlockState(new BlockPos(i + 4, j + 6, k + 9), JourneyBlocks.darkFloor.getDefaultState());
		world.setBlockState(new BlockPos(i + 4, j + 7, k + 0), JourneyBlocks.darkBrick.getDefaultState());
		world.setBlockState(new BlockPos(i + 4, j + 7, k + 9), JourneyBlocks.darkBrick.getDefaultState());
		world.setBlockState(new BlockPos(i + 5, j + 0, k + 2), JourneyBlocks.darkShingle.getDefaultState());
		world.setBlockState(new BlockPos(i + 5, j + 0, k + 3), JourneyBlocks.darkShingle.getDefaultState());
		world.setBlockState(new BlockPos(i + 5, j + 0, k + 6), JourneyBlocks.darkShingle.getDefaultState());
		world.setBlockState(new BlockPos(i + 5, j + 0, k + 7), JourneyBlocks.depthsGrass.getDefaultState());
		world.setBlockState(new BlockPos(i + 5, j + 1, k + 2), JourneyBlocks.depthsGrass.getDefaultState());
		world.setBlockState(new BlockPos(i + 5, j + 1, k + 3), JourneyBlocks.darkShingle.getDefaultState());
		world.setBlockState(new BlockPos(i + 5, j + 1, k + 6), JourneyBlocks.darkShingle.getDefaultState());
		world.setBlockState(new BlockPos(i + 5, j + 2, k + 3), JourneyBlocks.darkShingle.getDefaultState());
		world.setBlockState(new BlockPos(i + 5, j + 2, k + 6), JourneyBlocks.darkShingle.getDefaultState());
		world.setBlockState(new BlockPos(i + 5, j + 3, k + 3), JourneyBlocks.darkShingle.getDefaultState());
		world.setBlockState(new BlockPos(i + 5, j + 3, k + 6), JourneyBlocks.darkShingle.getDefaultState());
		world.setBlockState(new BlockPos(i + 5, j + 4, k + 3), JourneyBlocks.darkShingle.getDefaultState());
		world.setBlockState(new BlockPos(i + 5, j + 4, k + 6), JourneyBlocks.darkShingle.getDefaultState());
		world.setBlockState(new BlockPos(i + 5, j + 5, k + 3), JourneyBlocks.darkShingle.getDefaultState());
		world.setBlockState(new BlockPos(i + 5, j + 5, k + 6), JourneyBlocks.darkShingle.getDefaultState());
		world.setBlockState(new BlockPos(i + 5, j + 6, k + 0), JourneyBlocks.darkFloor.getDefaultState());
		world.setBlockState(new BlockPos(i + 5, j + 6, k + 1), JourneyBlocks.darkFloor.getDefaultState());
		world.setBlockState(new BlockPos(i + 5, j + 6, k + 2), JourneyBlocks.darkFloor.getDefaultState());
		world.setBlockState(new BlockPos(i + 5, j + 6, k + 3), JourneyBlocks.darkFloor.getDefaultState());
		world.setBlockState(new BlockPos(i + 5, j + 6, k + 4), JourneyBlocks.darkShingle.getDefaultState());
		world.setBlockState(new BlockPos(i + 5, j + 6, k + 5), JourneyBlocks.darkShingle.getDefaultState());
		world.setBlockState(new BlockPos(i + 5, j + 6, k + 6), JourneyBlocks.darkFloor.getDefaultState());
		world.setBlockState(new BlockPos(i + 5, j + 6, k + 7), JourneyBlocks.darkFloor.getDefaultState());
		world.setBlockState(new BlockPos(i + 5, j + 6, k + 8), JourneyBlocks.darkFloor.getDefaultState());
		world.setBlockState(new BlockPos(i + 5, j + 6, k + 9), JourneyBlocks.darkFloor.getDefaultState());
		world.setBlockState(new BlockPos(i + 5, j + 7, k + 0), JourneyBlocks.darkBrick.getDefaultState());
		world.setBlockState(new BlockPos(i + 5, j + 7, k + 9), JourneyBlocks.darkBrick.getDefaultState());
		world.setBlockState(new BlockPos(i + 6, j + 0, k + 2), JourneyBlocks.depthsGrass.getDefaultState());
		world.setBlockState(new BlockPos(i + 6, j + 0, k + 3), JourneyBlocks.darkBrick.getDefaultState());
		world.setBlockState(new BlockPos(i + 6, j + 0, k + 4), JourneyBlocks.darkShingle.getDefaultState());
		world.setBlockState(new BlockPos(i + 6, j + 0, k + 5), JourneyBlocks.darkShingle.getDefaultState());
		world.setBlockState(new BlockPos(i + 6, j + 0, k + 6), JourneyBlocks.darkBrick.getDefaultState());
		world.setBlockState(new BlockPos(i + 6, j + 0, k + 7), JourneyBlocks.darkShingle.getDefaultState());
		world.setBlockState(new BlockPos(i + 6, j + 0, k + 8), JourneyBlocks.depthsGrass.getDefaultState());
		world.setBlockState(new BlockPos(i + 6, j + 1, k + 3), JourneyBlocks.darkBrick.getDefaultState());
		world.setBlockState(new BlockPos(i + 6, j + 1, k + 4), JourneyBlocks.darkShingle.getDefaultState());
		world.setBlockState(new BlockPos(i + 6, j + 1, k + 5), JourneyBlocks.darkShingle.getDefaultState());
		world.setBlockState(new BlockPos(i + 6, j + 1, k + 6), JourneyBlocks.darkBrick.getDefaultState());
		world.setBlockState(new BlockPos(i + 6, j + 1, k + 7), JourneyBlocks.depthsGrass.getDefaultState());
		world.setBlockState(new BlockPos(i + 6, j + 2, k + 3), JourneyBlocks.darkBrick.getDefaultState());
		world.setBlockState(new BlockPos(i + 6, j + 2, k + 4), JourneyBlocks.darkShingle.getDefaultState());
		world.setBlockState(new BlockPos(i + 6, j + 2, k + 5), JourneyBlocks.darkShingle.getDefaultState());
		world.setBlockState(new BlockPos(i + 6, j + 2, k + 6), JourneyBlocks.darkBrick.getDefaultState());
		world.setBlockState(new BlockPos(i + 6, j + 3, k + 3), JourneyBlocks.darkBrick.getDefaultState());
		world.setBlockState(new BlockPos(i + 6, j + 3, k + 4), JourneyBlocks.darkShingle.getDefaultState());
		world.setBlockState(new BlockPos(i + 6, j + 3, k + 5), JourneyBlocks.darkShingle.getDefaultState());
		world.setBlockState(new BlockPos(i + 6, j + 3, k + 6), JourneyBlocks.darkBrick.getDefaultState());
		world.setBlockState(new BlockPos(i + 6, j + 4, k + 3), JourneyBlocks.darkBrick.getDefaultState());
		world.setBlockState(new BlockPos(i + 6, j + 4, k + 4), JourneyBlocks.darkShingle.getDefaultState());
		world.setBlockState(new BlockPos(i + 6, j + 4, k + 5), JourneyBlocks.darkShingle.getDefaultState());
		world.setBlockState(new BlockPos(i + 6, j + 4, k + 6), JourneyBlocks.darkBrick.getDefaultState());
		world.setBlockState(new BlockPos(i + 6, j + 5, k + 3), JourneyBlocks.darkBrick.getDefaultState());
		world.setBlockState(new BlockPos(i + 6, j + 5, k + 4), JourneyBlocks.darkShingle.getDefaultState());
		world.setBlockState(new BlockPos(i + 6, j + 5, k + 5), JourneyBlocks.darkShingle.getDefaultState());
		world.setBlockState(new BlockPos(i + 6, j + 5, k + 6), JourneyBlocks.darkBrick.getDefaultState());
		world.setBlockState(new BlockPos(i + 6, j + 6, k + 0), JourneyBlocks.darkFloor.getDefaultState());
		world.setBlockState(new BlockPos(i + 6, j + 6, k + 1), JourneyBlocks.darkFloor.getDefaultState());
		world.setBlockState(new BlockPos(i + 6, j + 6, k + 2), JourneyBlocks.darkFloor.getDefaultState());
		world.setBlockState(new BlockPos(i + 6, j + 6, k + 3), JourneyBlocks.darkFloor.getDefaultState());
		world.setBlockState(new BlockPos(i + 6, j + 6, k + 4), JourneyBlocks.darkFloor.getDefaultState());
		world.setBlockState(new BlockPos(i + 6, j + 6, k + 5), JourneyBlocks.darkFloor.getDefaultState());
		world.setBlockState(new BlockPos(i + 6, j + 6, k + 6), JourneyBlocks.darkFloor.getDefaultState());
		world.setBlockState(new BlockPos(i + 6, j + 6, k + 7), JourneyBlocks.darkFloor.getDefaultState());
		world.setBlockState(new BlockPos(i + 6, j + 6, k + 8), JourneyBlocks.darkFloor.getDefaultState());
		world.setBlockState(new BlockPos(i + 6, j + 6, k + 9), JourneyBlocks.darkFloor.getDefaultState());
		world.setBlockState(new BlockPos(i + 7, j + 0, k + 4), JourneyBlocks.depthsGrass.getDefaultState());
		world.setBlockState(new BlockPos(i + 7, j + 0, k + 6), JourneyBlocks.depthsGrass.getDefaultState());
		world.setBlockState(new BlockPos(i + 7, j + 6, k + 1), JourneyBlocks.darkFloor.getDefaultState());
		world.setBlockState(new BlockPos(i + 7, j + 6, k + 2), JourneyBlocks.darkFloor.getDefaultState());
		world.setBlockState(new BlockPos(i + 7, j + 6, k + 3), JourneyBlocks.darkFloor.getDefaultState());
		world.setBlockState(new BlockPos(i + 7, j + 6, k + 4), JourneyBlocks.darkFloor.getDefaultState());
		world.setBlockState(new BlockPos(i + 7, j + 6, k + 5), JourneyBlocks.darkFloor.getDefaultState());
		world.setBlockState(new BlockPos(i + 7, j + 6, k + 6), JourneyBlocks.darkFloor.getDefaultState());
		world.setBlockState(new BlockPos(i + 7, j + 6, k + 7), JourneyBlocks.darkFloor.getDefaultState());
		world.setBlockState(new BlockPos(i + 7, j + 6, k + 8), JourneyBlocks.darkFloor.getDefaultState());
		world.setBlockState(new BlockPos(i + 7, j + 7, k + 1), JourneyBlocks.darkBrick.getDefaultState());
		world.setBlockState(new BlockPos(i + 7, j + 7, k + 8), JourneyBlocks.darkBrick.getDefaultState());
		world.setBlockState(new BlockPos(i + 8, j + 6, k + 2), JourneyBlocks.darkFloor.getDefaultState());
		world.setBlockState(new BlockPos(i + 8, j + 6, k + 3), JourneyBlocks.darkFloor.getDefaultState());
		world.setBlockState(new BlockPos(i + 8, j + 6, k + 4), JourneyBlocks.darkFloor.getDefaultState());
		world.setBlockState(new BlockPos(i + 8, j + 6, k + 5), JourneyBlocks.darkFloor.getDefaultState());
		world.setBlockState(new BlockPos(i + 8, j + 6, k + 6), JourneyBlocks.darkFloor.getDefaultState());
		world.setBlockState(new BlockPos(i + 8, j + 6, k + 7), JourneyBlocks.darkFloor.getDefaultState());
		world.setBlockState(new BlockPos(i + 8, j + 7, k + 2), JourneyBlocks.darkBrick.getDefaultState());
		world.setBlockState(new BlockPos(i + 8, j + 7, k + 7), JourneyBlocks.darkBrick.getDefaultState());
		world.setBlockState(new BlockPos(i + 9, j + 6, k + 3), JourneyBlocks.darkFloor.getDefaultState());
		world.setBlockState(new BlockPos(i + 9, j + 6, k + 4), JourneyBlocks.darkFloor.getDefaultState());
		world.setBlockState(new BlockPos(i + 9, j + 6, k + 5), JourneyBlocks.darkFloor.getDefaultState());
		world.setBlockState(new BlockPos(i + 9, j + 6, k + 6), JourneyBlocks.darkFloor.getDefaultState());
		world.setBlockState(new BlockPos(i + 9, j + 7, k + 4), JourneyBlocks.darkBrick.getDefaultState());
		world.setBlockState(new BlockPos(i + 9, j + 7, k + 5), JourneyBlocks.darkBrick.getDefaultState());

		if(!world.isRemote) {
			EntityStaringGuardian smith = new EntityStaringGuardian(world);
			smith.setLocationAndAngles(i + 6, j + 7, k + 4, 0.0F, 0.0F);
			world.spawnEntity(smith);
		}
		return false;
	}
}