package net.journey.dimension.euca.gen;

import java.util.Random;

import net.journey.JourneyBlocks;
import net.journey.blocks.tileentity.TileEntityJourneyChest;
import net.journey.entity.mob.euca.npc.EntityAlloyMender;
import net.minecraft.init.Blocks;
import net.minecraft.util.math.BlockPos;
import net.minecraft.world.World;
import net.minecraft.world.gen.feature.WorldGenerator;

public class WorldGenSmeltery extends WorldGenerator {
	
	
	/*private static WeightedRandomChestContent[] loot = {
		new WeightedRandomChestContent(JourneyItems.metalDisk, 0, 1, 5, 1), 
		new WeightedRandomChestContent(JourneyItems.golderDust, 0, 1, 10, 5), 
		new WeightedRandomChestContent(JourneyItems.goldClump, 0, 1, 5, 10)};*/
	

	public boolean locationIsValidSpawn(World w, int x, int y, int z) {
		for(int i = 0; i < 11; i++) {
			for(int l = 0; l < 11; l++) {
				if(w.getBlockState(new BlockPos(x + i, y, z + l)) != JourneyBlocks.eucaGrass) {
					return false;
				}
			}
		}
		return true;
	}
	
	@Override
	public boolean generate(World w, Random r, BlockPos pos) {
		int x = pos.getX(), y = pos.getY() - 1, z = pos.getZ();
		if(locationIsValidSpawn(w, x, y, z)) return true;
		
		w.setBlockState(new BlockPos(x + 0, y + 5, z + 1), JourneyBlocks.eucaBricks.getDefaultState());
		w.setBlockState(new BlockPos(x + 0, y + 5, z + 2), JourneyBlocks.eucaBricks.getDefaultState());
		w.setBlockState(new BlockPos(x + 0, y + 5, z + 3), JourneyBlocks.eucaBricks.getDefaultState());
		w.setBlockState(new BlockPos(x + 0, y + 5, z + 4), JourneyBlocks.eucaBricks.getDefaultState());
		w.setBlockState(new BlockPos(x + 0, y + 5, z + 5), JourneyBlocks.eucaBricks.getDefaultState());
		w.setBlockState(new BlockPos(x + 0, y + 5, z + 6), JourneyBlocks.eucaBricks.getDefaultState());
		w.setBlockState(new BlockPos(x + 0, y + 5, z + 7), JourneyBlocks.eucaBricks.getDefaultState());
		w.setBlockState(new BlockPos(x + 0, y + 5, z + 8), JourneyBlocks.eucaBricks.getDefaultState());
		w.setBlockState(new BlockPos(x + 0, y + 5, z + 9), JourneyBlocks.eucaBricks.getDefaultState());
		w.setBlockState(new BlockPos(x + 0, y + 5, z + 10), JourneyBlocks.eucaBricks.getDefaultState());
		w.setBlockState(new BlockPos(x + 0, y + 5, z + 11), JourneyBlocks.eucaBricks.getDefaultState());
		w.setBlockState(new BlockPos(x + 1, y + 0, z + 2), JourneyBlocks.eucaBricks.getDefaultState());
		w.setBlockState(new BlockPos(x + 1, y + 0, z + 3), JourneyBlocks.eucaBricks.getDefaultState());
		w.setBlockState(new BlockPos(x + 1, y + 0, z + 4), JourneyBlocks.eucaBricks.getDefaultState());
		w.setBlockState(new BlockPos(x + 1, y + 0, z + 5), JourneyBlocks.eucaBricks.getDefaultState());
		w.setBlockState(new BlockPos(x + 1, y + 0, z + 6), JourneyBlocks.eucaBricks.getDefaultState());
		w.setBlockState(new BlockPos(x + 1, y + 0, z + 7), JourneyBlocks.eucaBricks.getDefaultState());
		w.setBlockState(new BlockPos(x + 1, y + 0, z + 8), JourneyBlocks.eucaBricks.getDefaultState());
		w.setBlockState(new BlockPos(x + 1, y + 0, z + 9), JourneyBlocks.eucaBricks.getDefaultState());
		w.setBlockState(new BlockPos(x + 1, y + 0, z + 10), JourneyBlocks.eucaBricks.getDefaultState());
		w.setBlockState(new BlockPos(x + 1, y + 1, z + 2), JourneyBlocks.eucaBricks.getDefaultState());
		w.setBlockState(new BlockPos(x + 1, y + 1, z + 3), JourneyBlocks.eucaBricks.getDefaultState());
		w.setBlockState(new BlockPos(x + 1, y + 1, z + 4), JourneyBlocks.eucaBricks.getDefaultState());
		w.setBlockState(new BlockPos(x + 1, y + 1, z + 5), JourneyBlocks.eucaBricks.getDefaultState());
		w.setBlockState(new BlockPos(x + 1, y + 1, z + 6), JourneyBlocks.eucaBricks.getDefaultState());
		w.setBlockState(new BlockPos(x + 1, y + 1, z + 7), JourneyBlocks.eucaBricks.getDefaultState());
		w.setBlockState(new BlockPos(x + 1, y + 1, z + 8), JourneyBlocks.eucaBricks.getDefaultState());
		w.setBlockState(new BlockPos(x + 1, y + 1, z + 9), JourneyBlocks.eucaBricks.getDefaultState());
		w.setBlockState(new BlockPos(x + 1, y + 1, z + 10), JourneyBlocks.eucaBricks.getDefaultState());
		w.setBlockState(new BlockPos(x + 1, y + 2, z + 2), JourneyBlocks.eucaBricks.getDefaultState());
		w.setBlockState(new BlockPos(x + 1, y + 2, z + 3), JourneyBlocks.eucaBricks.getDefaultState());
		w.setBlockState(new BlockPos(x + 1, y + 2, z + 4), Blocks.STAINED_GLASS_PANE.getStateFromMeta(1));
		w.setBlockState(new BlockPos(x + 1, y + 2, z + 5), Blocks.STAINED_GLASS_PANE.getStateFromMeta(1));
		w.setBlockState(new BlockPos(x + 1, y + 2, z + 6), JourneyBlocks.eucaBricks.getDefaultState());
		w.setBlockState(new BlockPos(x + 1, y + 2, z + 7), Blocks.STAINED_GLASS_PANE.getStateFromMeta(1));
		w.setBlockState(new BlockPos(x + 1, y + 2, z + 8), Blocks.STAINED_GLASS_PANE.getStateFromMeta(1));
		w.setBlockState(new BlockPos(x + 1, y + 2, z + 9), JourneyBlocks.eucaBricks.getDefaultState());
		w.setBlockState(new BlockPos(x + 1, y + 2, z + 10), JourneyBlocks.eucaBricks.getDefaultState());
		w.setBlockState(new BlockPos(x + 1, y + 3, z + 2), JourneyBlocks.eucaBricks.getDefaultState());
		w.setBlockState(new BlockPos(x + 1, y + 3, z + 3), JourneyBlocks.eucaBricks.getDefaultState());
		w.setBlockState(new BlockPos(x + 1, y + 3, z + 4), Blocks.STAINED_GLASS_PANE.getStateFromMeta(1));
		w.setBlockState(new BlockPos(x + 1, y + 3, z + 5), Blocks.STAINED_GLASS_PANE.getStateFromMeta(1));
		w.setBlockState(new BlockPos(x + 1, y + 3, z + 6), JourneyBlocks.eucaBricks.getDefaultState());
		w.setBlockState(new BlockPos(x + 1, y + 3, z + 7), Blocks.STAINED_GLASS_PANE.getStateFromMeta(1));
		w.setBlockState(new BlockPos(x + 1, y + 3, z + 8), Blocks.STAINED_GLASS_PANE.getStateFromMeta(1));
		w.setBlockState(new BlockPos(x + 1, y + 3, z + 9), JourneyBlocks.eucaBricks.getDefaultState());
		w.setBlockState(new BlockPos(x + 1, y + 3, z + 10), JourneyBlocks.eucaBricks.getDefaultState());
		w.setBlockState(new BlockPos(x + 1, y + 4, z + 2), JourneyBlocks.eucaBricks.getDefaultState());
		w.setBlockState(new BlockPos(x + 1, y + 4, z + 3), JourneyBlocks.eucaBricks.getDefaultState());
		w.setBlockState(new BlockPos(x + 1, y + 4, z + 4), JourneyBlocks.eucaBricks.getDefaultState());
		w.setBlockState(new BlockPos(x + 1, y + 4, z + 5), JourneyBlocks.eucaBricks.getDefaultState());
		w.setBlockState(new BlockPos(x + 1, y + 4, z + 6), JourneyBlocks.eucaBricks.getDefaultState());
		w.setBlockState(new BlockPos(x + 1, y + 4, z + 7), JourneyBlocks.eucaBricks.getDefaultState());
		w.setBlockState(new BlockPos(x + 1, y + 4, z + 8), JourneyBlocks.eucaBricks.getDefaultState());
		w.setBlockState(new BlockPos(x + 1, y + 4, z + 9), JourneyBlocks.eucaBricks.getDefaultState());
		w.setBlockState(new BlockPos(x + 1, y + 4, z + 10), JourneyBlocks.eucaBricks.getDefaultState());
		w.setBlockState(new BlockPos(x + 1, y + 5, z + 2), JourneyBlocks.eucaBricks.getDefaultState());
		w.setBlockState(new BlockPos(x + 1, y + 5, z + 3), JourneyBlocks.eucaBricks.getDefaultState());
		w.setBlockState(new BlockPos(x + 1, y + 5, z + 4), JourneyBlocks.eucaBricks.getDefaultState());
		w.setBlockState(new BlockPos(x + 1, y + 5, z + 5), JourneyBlocks.eucaBricks.getDefaultState());
		w.setBlockState(new BlockPos(x + 1, y + 5, z + 6), JourneyBlocks.eucaBricks.getDefaultState());
		w.setBlockState(new BlockPos(x + 1, y + 5, z + 7), JourneyBlocks.eucaBricks.getDefaultState());
		w.setBlockState(new BlockPos(x + 1, y + 5, z + 8), JourneyBlocks.eucaBricks.getDefaultState());
		w.setBlockState(new BlockPos(x + 1, y + 5, z + 9), JourneyBlocks.eucaBricks.getDefaultState());
		w.setBlockState(new BlockPos(x + 1, y + 5, z + 10), JourneyBlocks.eucaBricks.getDefaultState());
		w.setBlockState(new BlockPos(x + 1, y + 6, z + 1), JourneyBlocks.eucaBricks.getDefaultState());
		w.setBlockState(new BlockPos(x + 1, y + 6, z + 2), JourneyBlocks.eucaBricks.getDefaultState());
		w.setBlockState(new BlockPos(x + 1, y + 6, z + 3), JourneyBlocks.eucaBricks.getDefaultState());
		w.setBlockState(new BlockPos(x + 1, y + 6, z + 4), JourneyBlocks.eucaBricks.getDefaultState());
		w.setBlockState(new BlockPos(x + 1, y + 6, z + 5), JourneyBlocks.eucaBricks.getDefaultState());
		w.setBlockState(new BlockPos(x + 1, y + 6, z + 6), JourneyBlocks.eucaBricks.getDefaultState());
		w.setBlockState(new BlockPos(x + 1, y + 6, z + 7), JourneyBlocks.eucaBricks.getDefaultState());
		w.setBlockState(new BlockPos(x + 1, y + 6, z + 8), JourneyBlocks.eucaBricks.getDefaultState());
		w.setBlockState(new BlockPos(x + 1, y + 6, z + 9), JourneyBlocks.eucaBricks.getDefaultState());
		w.setBlockState(new BlockPos(x + 1, y + 6, z + 10), JourneyBlocks.eucaBricks.getDefaultState());
		w.setBlockState(new BlockPos(x + 1, y + 6, z + 11), JourneyBlocks.eucaBricks.getDefaultState());
		w.setBlockState(new BlockPos(x + 2, y + 0, z + 2), JourneyBlocks.eucaBricks.getDefaultState());
		w.setBlockState(new BlockPos(x + 2, y + 0, z + 3), JourneyBlocks.goldEucaPlank.getDefaultState());
		w.setBlockState(new BlockPos(x + 2, y + 0, z + 4), JourneyBlocks.goldEucaPlank.getDefaultState());
		w.setBlockState(new BlockPos(x + 2, y + 0, z + 5), JourneyBlocks.goldEucaPlank.getDefaultState());
		w.setBlockState(new BlockPos(x + 2, y + 0, z + 6), JourneyBlocks.goldEucaPlank.getDefaultState());
		w.setBlockState(new BlockPos(x + 2, y + 0, z + 7), JourneyBlocks.goldEucaPlank.getDefaultState());
		w.setBlockState(new BlockPos(x + 2, y + 0, z + 8), JourneyBlocks.goldEucaPlank.getDefaultState());
		w.setBlockState(new BlockPos(x + 2, y + 0, z + 9), JourneyBlocks.goldEucaPlank.getDefaultState());
		w.setBlockState(new BlockPos(x + 2, y + 0, z + 10), JourneyBlocks.eucaBricks.getDefaultState());
		w.setBlockState(new BlockPos(x + 2, y + 1, z + 2), JourneyBlocks.eucaBricks.getDefaultState());
		w.setBlockState(new BlockPos(x + 2, y + 1, z + 5), JourneyBlocks.eucaChest.getStateFromMeta(3));
		
		TileEntityJourneyChest te = (TileEntityJourneyChest)w.getTileEntity(new BlockPos(x + 2, y + 1, z + 5));
		if(te != null) {
			//WeightedRandomChestContent.generateChestContents(r, Lists.newArrayList(loot), te, 4);
		}
		
		w.setBlockState(new BlockPos(x + 2, y + 1, z + 6), JourneyBlocks.eucaChest.getStateFromMeta(3));
		w.setBlockState(new BlockPos(x + 2, y + 1, z + 8), JourneyBlocks.eucaBricks.getDefaultState());
		w.setBlockState(new BlockPos(x + 2, y + 1, z + 9), JourneyBlocks.eucaChest.getStateFromMeta(3));
		
		TileEntityJourneyChest te2 = (TileEntityJourneyChest)w.getTileEntity(new BlockPos(x + 2, y + 1, z + 9));
		if(te2 != null) {
			//WeightedRandomChestContent.generateChestContents(r, Lists.newArrayList(loot), te2, 12);
		}
		
		w.setBlockState(new BlockPos(x + 2, y + 1, z + 10), JourneyBlocks.eucaBricks.getDefaultState());
		w.setBlockState(new BlockPos(x + 2, y + 2, z + 2), JourneyBlocks.eucaBricks.getDefaultState());
		w.setBlockState(new BlockPos(x + 2, y + 2, z + 10), JourneyBlocks.eucaBricks.getDefaultState());
		w.setBlockState(new BlockPos(x + 2, y + 3, z + 2), JourneyBlocks.eucaBricks.getDefaultState());
		w.setBlockState(new BlockPos(x + 2, y + 3, z + 8), JourneyBlocks.eucaBricks.getDefaultState());
		w.setBlockState(new BlockPos(x + 2, y + 3, z + 10), JourneyBlocks.eucaBricks.getDefaultState());
		w.setBlockState(new BlockPos(x + 2, y + 4, z + 2), JourneyBlocks.eucaBricks.getDefaultState());
		w.setBlockState(new BlockPos(x + 2, y + 4, z + 8), JourneyBlocks.eucaBricks.getDefaultState());
		w.setBlockState(new BlockPos(x + 2, y + 4, z + 10), JourneyBlocks.eucaBricks.getDefaultState());
		w.setBlockState(new BlockPos(x + 2, y + 5, z + 2), JourneyBlocks.eucaBricks.getDefaultState());
		w.setBlockState(new BlockPos(x + 2, y + 5, z + 3), JourneyBlocks.eucaBricks.getDefaultState());
		w.setBlockState(new BlockPos(x + 2, y + 5, z + 4), JourneyBlocks.eucaBricks.getDefaultState());
		w.setBlockState(new BlockPos(x + 2, y + 5, z + 5), JourneyBlocks.eucaBricks.getDefaultState());
		w.setBlockState(new BlockPos(x + 2, y + 5, z + 6), JourneyBlocks.eucaBricks.getDefaultState());
		w.setBlockState(new BlockPos(x + 2, y + 5, z + 7), JourneyBlocks.eucaBricks.getDefaultState());
		w.setBlockState(new BlockPos(x + 2, y + 5, z + 8), JourneyBlocks.eucaBricks.getDefaultState());
		w.setBlockState(new BlockPos(x + 2, y + 5, z + 9), JourneyBlocks.eucaBricks.getDefaultState());
		w.setBlockState(new BlockPos(x + 2, y + 5, z + 10), JourneyBlocks.eucaBricks.getDefaultState());
		w.setBlockState(new BlockPos(x + 2, y + 6, z + 2), JourneyBlocks.eucaBricks.getDefaultState());
		w.setBlockState(new BlockPos(x + 2, y + 6, z + 3), JourneyBlocks.eucaBricks.getDefaultState());
		w.setBlockState(new BlockPos(x + 2, y + 6, z + 4), JourneyBlocks.eucaBricks.getDefaultState());
		w.setBlockState(new BlockPos(x + 2, y + 6, z + 5), JourneyBlocks.eucaBricks.getDefaultState());
		w.setBlockState(new BlockPos(x + 2, y + 6, z + 6), JourneyBlocks.eucaBricks.getDefaultState());
		w.setBlockState(new BlockPos(x + 2, y + 6, z + 7), JourneyBlocks.eucaBricks.getDefaultState());
		w.setBlockState(new BlockPos(x + 2, y + 6, z + 8), JourneyBlocks.eucaBricks.getDefaultState());
		w.setBlockState(new BlockPos(x + 2, y + 6, z + 9), JourneyBlocks.eucaBricks.getDefaultState());
		w.setBlockState(new BlockPos(x + 2, y + 6, z + 10), JourneyBlocks.eucaBricks.getDefaultState());
		w.setBlockState(new BlockPos(x + 2, y + 7, z + 0), JourneyBlocks.eucaBricks.getDefaultState());
		w.setBlockState(new BlockPos(x + 2, y + 7, z + 1), JourneyBlocks.eucaBricks.getDefaultState());
		w.setBlockState(new BlockPos(x + 2, y + 7, z + 2), JourneyBlocks.eucaBricks.getDefaultState());
		w.setBlockState(new BlockPos(x + 2, y + 7, z + 3), JourneyBlocks.eucaBricks.getDefaultState());
		w.setBlockState(new BlockPos(x + 2, y + 7, z + 4), JourneyBlocks.eucaBricks.getDefaultState());
		w.setBlockState(new BlockPos(x + 2, y + 7, z + 5), JourneyBlocks.eucaBricks.getDefaultState());
		w.setBlockState(new BlockPos(x + 2, y + 7, z + 6), JourneyBlocks.eucaBricks.getDefaultState());
		w.setBlockState(new BlockPos(x + 2, y + 7, z + 7), JourneyBlocks.eucaBricks.getDefaultState());
		w.setBlockState(new BlockPos(x + 2, y + 7, z + 8), JourneyBlocks.eucaBricks.getDefaultState());
		w.setBlockState(new BlockPos(x + 2, y + 7, z + 9), JourneyBlocks.eucaBricks.getDefaultState());
		w.setBlockState(new BlockPos(x + 2, y + 7, z + 10), JourneyBlocks.eucaBricks.getDefaultState());
		w.setBlockState(new BlockPos(x + 2, y + 7, z + 11), JourneyBlocks.eucaBricks.getDefaultState());
		w.setBlockState(new BlockPos(x + 2, y + 7, z + 12), JourneyBlocks.eucaBricks.getDefaultState());
		w.setBlockState(new BlockPos(x + 3, y + 0, z + 2), JourneyBlocks.eucaBricks.getDefaultState());
		w.setBlockState(new BlockPos(x + 3, y + 0, z + 3), JourneyBlocks.goldEucaPlank.getDefaultState());
		w.setBlockState(new BlockPos(x + 3, y + 0, z + 4), JourneyBlocks.goldEucaPlank.getDefaultState());
		w.setBlockState(new BlockPos(x + 3, y + 0, z + 5), JourneyBlocks.goldEucaPlank.getDefaultState());
		w.setBlockState(new BlockPos(x + 3, y + 0, z + 6), JourneyBlocks.goldEucaPlank.getDefaultState());
		w.setBlockState(new BlockPos(x + 3, y + 0, z + 7), JourneyBlocks.goldEucaPlank.getDefaultState());
		w.setBlockState(new BlockPos(x + 3, y + 0, z + 8), JourneyBlocks.goldEucaPlank.getDefaultState());
		w.setBlockState(new BlockPos(x + 3, y + 0, z + 9), JourneyBlocks.goldEucaPlank.getDefaultState());
		w.setBlockState(new BlockPos(x + 3, y + 0, z + 10), JourneyBlocks.eucaBricks.getDefaultState());
		w.setBlockState(new BlockPos(x + 3, y + 1, z + 2), JourneyBlocks.eucaBricks.getDefaultState());
		w.setBlockState(new BlockPos(x + 3, y + 1, z + 9), JourneyBlocks.eucaBricks.getDefaultState());
		w.setBlockState(new BlockPos(x + 3, y + 1, z + 10), JourneyBlocks.eucaBricks.getDefaultState());
		w.setBlockState(new BlockPos(x + 3, y + 2, z + 2), JourneyBlocks.eucaBricks.getStateFromMeta(1));
		w.setBlockState(new BlockPos(x + 3, y + 2, z + 10), JourneyBlocks.eucaBricks.getStateFromMeta(1));
		w.setBlockState(new BlockPos(x + 3, y + 3, z + 2), JourneyBlocks.eucaBricks.getStateFromMeta(1));
		w.setBlockState(new BlockPos(x + 3, y + 3, z + 9), JourneyBlocks.eucaBricks.getDefaultState());
		w.setBlockState(new BlockPos(x + 3, y + 3, z + 10), JourneyBlocks.eucaBricks.getStateFromMeta(1));
		w.setBlockState(new BlockPos(x + 3, y + 4, z + 2), JourneyBlocks.eucaBricks.getDefaultState());
		w.setBlockState(new BlockPos(x + 3, y + 4, z + 9), JourneyBlocks.eucaBricks.getDefaultState());
		w.setBlockState(new BlockPos(x + 3, y + 4, z + 10), JourneyBlocks.eucaBricks.getDefaultState());
		w.setBlockState(new BlockPos(x + 3, y + 5, z + 2), JourneyBlocks.eucaBricks.getDefaultState());
		w.setBlockState(new BlockPos(x + 3, y + 5, z + 3), JourneyBlocks.eucaBricks.getDefaultState());
		w.setBlockState(new BlockPos(x + 3, y + 5, z + 4), JourneyBlocks.eucaBricks.getDefaultState());
		w.setBlockState(new BlockPos(x + 3, y + 5, z + 5), JourneyBlocks.eucaBricks.getDefaultState());
		w.setBlockState(new BlockPos(x + 3, y + 5, z + 6), JourneyBlocks.eucaBricks.getDefaultState());
		w.setBlockState(new BlockPos(x + 3, y + 5, z + 7), JourneyBlocks.eucaBricks.getDefaultState());
		w.setBlockState(new BlockPos(x + 3, y + 5, z + 8), JourneyBlocks.eucaBricks.getDefaultState());
		w.setBlockState(new BlockPos(x + 3, y + 5, z + 9), JourneyBlocks.eucaBricks.getDefaultState());
		w.setBlockState(new BlockPos(x + 3, y + 5, z + 10), JourneyBlocks.eucaBricks.getDefaultState());
		w.setBlockState(new BlockPos(x + 3, y + 6, z + 2), JourneyBlocks.eucaBricks.getDefaultState());
		w.setBlockState(new BlockPos(x + 3, y + 6, z + 3), JourneyBlocks.eucaBricks.getDefaultState());
		w.setBlockState(new BlockPos(x + 3, y + 6, z + 4), JourneyBlocks.eucaBricks.getDefaultState());
		w.setBlockState(new BlockPos(x + 3, y + 6, z + 5), JourneyBlocks.eucaBricks.getDefaultState());
		w.setBlockState(new BlockPos(x + 3, y + 6, z + 6), JourneyBlocks.eucaBricks.getDefaultState());
		w.setBlockState(new BlockPos(x + 3, y + 6, z + 7), JourneyBlocks.eucaBricks.getDefaultState());
		w.setBlockState(new BlockPos(x + 3, y + 6, z + 8), JourneyBlocks.eucaBricks.getDefaultState());
		w.setBlockState(new BlockPos(x + 3, y + 6, z + 9), JourneyBlocks.eucaBricks.getDefaultState());
		w.setBlockState(new BlockPos(x + 3, y + 6, z + 10), JourneyBlocks.eucaBricks.getDefaultState());
		w.setBlockState(new BlockPos(x + 3, y + 7, z + 2), JourneyBlocks.eucaBricks.getDefaultState());
		w.setBlockState(new BlockPos(x + 3, y + 7, z + 3), JourneyBlocks.eucaBricks.getDefaultState());
		w.setBlockState(new BlockPos(x + 3, y + 7, z + 4), JourneyBlocks.eucaBricks.getDefaultState());
		w.setBlockState(new BlockPos(x + 3, y + 7, z + 5), JourneyBlocks.eucaBricks.getDefaultState());
		w.setBlockState(new BlockPos(x + 3, y + 7, z + 6), JourneyBlocks.eucaBricks.getDefaultState());
		w.setBlockState(new BlockPos(x + 3, y + 7, z + 7), JourneyBlocks.eucaBricks.getDefaultState());
		w.setBlockState(new BlockPos(x + 3, y + 7, z + 8), JourneyBlocks.eucaBricks.getDefaultState());
		w.setBlockState(new BlockPos(x + 3, y + 7, z + 9), JourneyBlocks.eucaBricks.getDefaultState());
		w.setBlockState(new BlockPos(x + 3, y + 7, z + 10), JourneyBlocks.eucaBricks.getDefaultState());
		w.setBlockState(new BlockPos(x + 3, y + 8, z + 0), JourneyBlocks.eucaBricks.getDefaultState());
		w.setBlockState(new BlockPos(x + 3, y + 8, z + 1), JourneyBlocks.eucaBricks.getDefaultState());
		w.setBlockState(new BlockPos(x + 3, y + 8, z + 2), JourneyBlocks.eucaBricks.getDefaultState());
		w.setBlockState(new BlockPos(x + 3, y + 8, z + 3), JourneyBlocks.eucaBricks.getDefaultState());
		w.setBlockState(new BlockPos(x + 3, y + 8, z + 4), JourneyBlocks.eucaBricks.getDefaultState());
		w.setBlockState(new BlockPos(x + 3, y + 8, z + 5), JourneyBlocks.eucaBricks.getDefaultState());
		w.setBlockState(new BlockPos(x + 3, y + 8, z + 6), JourneyBlocks.eucaBricks.getDefaultState());
		w.setBlockState(new BlockPos(x + 3, y + 8, z + 7), JourneyBlocks.eucaBricks.getDefaultState());
		w.setBlockState(new BlockPos(x + 3, y + 8, z + 8), JourneyBlocks.eucaBricks.getDefaultState());
		w.setBlockState(new BlockPos(x + 3, y + 8, z + 9), JourneyBlocks.eucaBricks.getDefaultState());
		w.setBlockState(new BlockPos(x + 3, y + 8, z + 10), JourneyBlocks.eucaBricks.getDefaultState());
		w.setBlockState(new BlockPos(x + 3, y + 8, z + 11), JourneyBlocks.eucaBricks.getDefaultState());
		w.setBlockState(new BlockPos(x + 3, y + 8, z + 12), JourneyBlocks.eucaBricks.getDefaultState());
		w.setBlockState(new BlockPos(x + 4, y + 0, z + 2), JourneyBlocks.eucaBricks.getDefaultState());
		w.setBlockState(new BlockPos(x + 4, y + 0, z + 3), JourneyBlocks.goldEucaPlank.getDefaultState());
		w.setBlockState(new BlockPos(x + 4, y + 0, z + 4), JourneyBlocks.goldEucaPlank.getDefaultState());
		w.setBlockState(new BlockPos(x + 4, y + 0, z + 5), JourneyBlocks.goldEucaPlank.getDefaultState());
		w.setBlockState(new BlockPos(x + 4, y + 0, z + 6), JourneyBlocks.goldEucaPlank.getDefaultState());
		w.setBlockState(new BlockPos(x + 4, y + 0, z + 7), JourneyBlocks.goldEucaPlank.getDefaultState());
		w.setBlockState(new BlockPos(x + 4, y + 0, z + 8), JourneyBlocks.goldEucaPlank.getDefaultState());
		w.setBlockState(new BlockPos(x + 4, y + 0, z + 9), JourneyBlocks.goldEucaPlank.getDefaultState());
		w.setBlockState(new BlockPos(x + 4, y + 0, z + 10), JourneyBlocks.eucaBricks.getDefaultState());
		w.setBlockState(new BlockPos(x + 4, y + 1, z + 2), JourneyBlocks.eucaBricks.getDefaultState());
		w.setBlockState(new BlockPos(x + 4, y + 1, z + 10), JourneyBlocks.eucaBricks.getDefaultState());
		w.setBlockState(new BlockPos(x + 4, y + 2, z + 2), Blocks.STAINED_GLASS_PANE.getStateFromMeta(1));
		w.setBlockState(new BlockPos(x + 4, y + 2, z + 10), Blocks.STAINED_GLASS_PANE.getStateFromMeta(1));
		w.setBlockState(new BlockPos(x + 4, y + 3, z + 2), Blocks.STAINED_GLASS_PANE.getStateFromMeta(1));
		w.setBlockState(new BlockPos(x + 4, y + 3, z + 10), Blocks.STAINED_GLASS_PANE.getStateFromMeta(1));
		w.setBlockState(new BlockPos(x + 4, y + 4, z + 2), JourneyBlocks.eucaBricks.getDefaultState());
		w.setBlockState(new BlockPos(x + 4, y + 4, z + 10), JourneyBlocks.eucaBricks.getDefaultState());
		w.setBlockState(new BlockPos(x + 4, y + 5, z + 2), JourneyBlocks.eucaBricks.getDefaultState());
		w.setBlockState(new BlockPos(x + 4, y + 5, z + 3), JourneyBlocks.eucaBricks.getDefaultState());
		w.setBlockState(new BlockPos(x + 4, y + 5, z + 4), JourneyBlocks.eucaBricks.getDefaultState());
		w.setBlockState(new BlockPos(x + 4, y + 5, z + 5), JourneyBlocks.eucaBricks.getDefaultState());
		w.setBlockState(new BlockPos(x + 4, y + 5, z + 6), JourneyBlocks.eucaBricks.getDefaultState());
		w.setBlockState(new BlockPos(x + 4, y + 5, z + 7), JourneyBlocks.eucaBricks.getDefaultState());
		w.setBlockState(new BlockPos(x + 4, y + 5, z + 8), JourneyBlocks.eucaBricks.getDefaultState());
		w.setBlockState(new BlockPos(x + 4, y + 5, z + 9), JourneyBlocks.eucaBricks.getDefaultState());
		w.setBlockState(new BlockPos(x + 4, y + 5, z + 10), JourneyBlocks.eucaBricks.getDefaultState());
		w.setBlockState(new BlockPos(x + 4, y + 6, z + 2), JourneyBlocks.eucaBricks.getDefaultState());
		w.setBlockState(new BlockPos(x + 4, y + 6, z + 3), JourneyBlocks.eucaBricks.getDefaultState());
		w.setBlockState(new BlockPos(x + 4, y + 6, z + 4), JourneyBlocks.eucaBricks.getDefaultState());
		w.setBlockState(new BlockPos(x + 4, y + 6, z + 5), JourneyBlocks.eucaBricks.getDefaultState());
		w.setBlockState(new BlockPos(x + 4, y + 6, z + 6), JourneyBlocks.eucaBricks.getDefaultState());
		w.setBlockState(new BlockPos(x + 4, y + 6, z + 7), JourneyBlocks.eucaBricks.getDefaultState());
		w.setBlockState(new BlockPos(x + 4, y + 6, z + 8), JourneyBlocks.eucaBricks.getDefaultState());
		w.setBlockState(new BlockPos(x + 4, y + 6, z + 9), JourneyBlocks.eucaBricks.getDefaultState());
		w.setBlockState(new BlockPos(x + 4, y + 6, z + 10), JourneyBlocks.eucaBricks.getDefaultState());
		w.setBlockState(new BlockPos(x + 4, y + 7, z + 2), JourneyBlocks.eucaBricks.getDefaultState());
		w.setBlockState(new BlockPos(x + 4, y + 7, z + 3), JourneyBlocks.eucaBricks.getDefaultState());
		w.setBlockState(new BlockPos(x + 4, y + 7, z + 4), JourneyBlocks.eucaBricks.getDefaultState());
		w.setBlockState(new BlockPos(x + 4, y + 7, z + 5), JourneyBlocks.eucaBricks.getDefaultState());
		w.setBlockState(new BlockPos(x + 4, y + 7, z + 6), JourneyBlocks.eucaBricks.getDefaultState());
		w.setBlockState(new BlockPos(x + 4, y + 7, z + 7), JourneyBlocks.eucaBricks.getDefaultState());
		w.setBlockState(new BlockPos(x + 4, y + 7, z + 8), JourneyBlocks.eucaBricks.getDefaultState());
		w.setBlockState(new BlockPos(x + 4, y + 7, z + 9), JourneyBlocks.eucaBricks.getDefaultState());
		w.setBlockState(new BlockPos(x + 4, y + 7, z + 10), JourneyBlocks.eucaBricks.getDefaultState());
		w.setBlockState(new BlockPos(x + 4, y + 8, z + 0), JourneyBlocks.eucaBricks.getDefaultState());
		w.setBlockState(new BlockPos(x + 4, y + 8, z + 1), JourneyBlocks.eucaBricks.getDefaultState());
		w.setBlockState(new BlockPos(x + 4, y + 8, z + 2), JourneyBlocks.eucaBricks.getDefaultState());
		w.setBlockState(new BlockPos(x + 4, y + 8, z + 3), JourneyBlocks.eucaBricks.getDefaultState());
		w.setBlockState(new BlockPos(x + 4, y + 8, z + 4), JourneyBlocks.eucaBricks.getDefaultState());
		w.setBlockState(new BlockPos(x + 4, y + 8, z + 5), JourneyBlocks.eucaBricks.getDefaultState());
		w.setBlockState(new BlockPos(x + 4, y + 8, z + 6), JourneyBlocks.eucaBricks.getDefaultState());
		w.setBlockState(new BlockPos(x + 4, y + 8, z + 7), JourneyBlocks.eucaBricks.getDefaultState());
		w.setBlockState(new BlockPos(x + 4, y + 8, z + 8), JourneyBlocks.eucaBricks.getDefaultState());
		w.setBlockState(new BlockPos(x + 4, y + 8, z + 9), JourneyBlocks.eucaBricks.getDefaultState());
		w.setBlockState(new BlockPos(x + 4, y + 8, z + 10), JourneyBlocks.eucaBricks.getDefaultState());
		w.setBlockState(new BlockPos(x + 4, y + 8, z + 11), JourneyBlocks.eucaBricks.getDefaultState());
		w.setBlockState(new BlockPos(x + 4, y + 8, z + 12), JourneyBlocks.eucaBricks.getDefaultState());
		w.setBlockState(new BlockPos(x + 5, y + 0, z + 2), JourneyBlocks.eucaBricks.getDefaultState());
		w.setBlockState(new BlockPos(x + 5, y + 0, z + 3), JourneyBlocks.goldEucaPlank.getDefaultState());
		w.setBlockState(new BlockPos(x + 5, y + 0, z + 4), JourneyBlocks.goldEucaPlank.getDefaultState());
		w.setBlockState(new BlockPos(x + 5, y + 0, z + 5), JourneyBlocks.goldEucaPlank.getDefaultState());
		w.setBlockState(new BlockPos(x + 5, y + 0, z + 6), JourneyBlocks.goldEucaPlank.getDefaultState());
		w.setBlockState(new BlockPos(x + 5, y + 0, z + 7), JourneyBlocks.goldEucaPlank.getDefaultState());
		w.setBlockState(new BlockPos(x + 5, y + 0, z + 8), JourneyBlocks.goldEucaPlank.getDefaultState());
		w.setBlockState(new BlockPos(x + 5, y + 0, z + 9), JourneyBlocks.goldEucaPlank.getDefaultState());
		w.setBlockState(new BlockPos(x + 5, y + 0, z + 10), JourneyBlocks.eucaBricks.getDefaultState());
		w.setBlockState(new BlockPos(x + 5, y + 1, z + 2), JourneyBlocks.eucaBricks.getDefaultState());
		w.setBlockState(new BlockPos(x + 5, y + 1, z + 10), JourneyBlocks.eucaBricks.getDefaultState());
		w.setBlockState(new BlockPos(x + 5, y + 2, z + 2), JourneyBlocks.eucaBricks.getDefaultState());
		w.setBlockState(new BlockPos(x + 5, y + 2, z + 10), JourneyBlocks.eucaBricks.getDefaultState());
		w.setBlockState(new BlockPos(x + 5, y + 3, z + 2), JourneyBlocks.eucaBricks.getDefaultState());
		w.setBlockState(new BlockPos(x + 5, y + 3, z + 10), JourneyBlocks.eucaBricks.getDefaultState());
		w.setBlockState(new BlockPos(x + 5, y + 4, z + 2), JourneyBlocks.eucaBricks.getDefaultState());
		w.setBlockState(new BlockPos(x + 5, y + 4, z + 3), JourneyBlocks.eucaBricks.getDefaultState());
		w.setBlockState(new BlockPos(x + 5, y + 4, z + 4), JourneyBlocks.eucaBricks.getDefaultState());
		w.setBlockState(new BlockPos(x + 5, y + 4, z + 5), JourneyBlocks.eucaBricks.getDefaultState());
		w.setBlockState(new BlockPos(x + 5, y + 4, z + 6), JourneyBlocks.eucaBricks.getDefaultState());
		w.setBlockState(new BlockPos(x + 5, y + 4, z + 7), JourneyBlocks.eucaBricks.getDefaultState());
		w.setBlockState(new BlockPos(x + 5, y + 4, z + 8), JourneyBlocks.eucaBricks.getDefaultState());
		w.setBlockState(new BlockPos(x + 5, y + 4, z + 9), JourneyBlocks.eucaBricks.getDefaultState());
		w.setBlockState(new BlockPos(x + 5, y + 4, z + 10), JourneyBlocks.eucaBricks.getDefaultState());
		w.setBlockState(new BlockPos(x + 5, y + 5, z + 2), JourneyBlocks.eucaBricks.getDefaultState());
		w.setBlockState(new BlockPos(x + 5, y + 5, z + 3), JourneyBlocks.eucaBricks.getDefaultState());
		w.setBlockState(new BlockPos(x + 5, y + 5, z + 4), JourneyBlocks.eucaBricks.getDefaultState());
		w.setBlockState(new BlockPos(x + 5, y + 5, z + 5), JourneyBlocks.eucaBricks.getDefaultState());
		w.setBlockState(new BlockPos(x + 5, y + 5, z + 6), JourneyBlocks.eucaBricks.getDefaultState());
		w.setBlockState(new BlockPos(x + 5, y + 5, z + 7), JourneyBlocks.eucaBricks.getDefaultState());
		w.setBlockState(new BlockPos(x + 5, y + 5, z + 8), JourneyBlocks.eucaBricks.getDefaultState());
		w.setBlockState(new BlockPos(x + 5, y + 5, z + 9), JourneyBlocks.eucaBricks.getDefaultState());
		w.setBlockState(new BlockPos(x + 5, y + 5, z + 10), JourneyBlocks.eucaBricks.getDefaultState());
		w.setBlockState(new BlockPos(x + 5, y + 6, z + 2), JourneyBlocks.eucaBricks.getDefaultState());
		w.setBlockState(new BlockPos(x + 5, y + 6, z + 3), JourneyBlocks.eucaBricks.getDefaultState());
		w.setBlockState(new BlockPos(x + 5, y + 6, z + 4), JourneyBlocks.eucaBricks.getDefaultState());
		w.setBlockState(new BlockPos(x + 5, y + 6, z + 5), JourneyBlocks.eucaBricks.getDefaultState());
		w.setBlockState(new BlockPos(x + 5, y + 6, z + 6), JourneyBlocks.eucaBricks.getDefaultState());
		w.setBlockState(new BlockPos(x + 5, y + 6, z + 7), JourneyBlocks.eucaBricks.getDefaultState());
		w.setBlockState(new BlockPos(x + 5, y + 6, z + 8), JourneyBlocks.eucaBricks.getDefaultState());
		w.setBlockState(new BlockPos(x + 5, y + 6, z + 9), JourneyBlocks.eucaBricks.getDefaultState());
		w.setBlockState(new BlockPos(x + 5, y + 6, z + 10), JourneyBlocks.eucaBricks.getDefaultState());
		w.setBlockState(new BlockPos(x + 5, y + 7, z + 0), JourneyBlocks.eucaBricks.getDefaultState());
		w.setBlockState(new BlockPos(x + 5, y + 7, z + 1), JourneyBlocks.eucaBricks.getDefaultState());
		w.setBlockState(new BlockPos(x + 5, y + 7, z + 2), JourneyBlocks.eucaBricks.getDefaultState());
		w.setBlockState(new BlockPos(x + 5, y + 7, z + 3), JourneyBlocks.eucaBricks.getDefaultState());
		w.setBlockState(new BlockPos(x + 5, y + 7, z + 4), JourneyBlocks.eucaBricks.getDefaultState());
		w.setBlockState(new BlockPos(x + 5, y + 7, z + 5), JourneyBlocks.eucaBricks.getDefaultState());
		w.setBlockState(new BlockPos(x + 5, y + 7, z + 6), JourneyBlocks.eucaBricks.getDefaultState());
		w.setBlockState(new BlockPos(x + 5, y + 7, z + 7), JourneyBlocks.eucaBricks.getDefaultState());
		w.setBlockState(new BlockPos(x + 5, y + 7, z + 8), JourneyBlocks.eucaBricks.getDefaultState());
		w.setBlockState(new BlockPos(x + 5, y + 7, z + 9), JourneyBlocks.eucaBricks.getDefaultState());
		w.setBlockState(new BlockPos(x + 5, y + 7, z + 10), JourneyBlocks.eucaBricks.getDefaultState());
		w.setBlockState(new BlockPos(x + 5, y + 7, z + 11), JourneyBlocks.eucaBricks.getDefaultState());
		w.setBlockState(new BlockPos(x + 5, y + 7, z + 12), JourneyBlocks.eucaBricks.getDefaultState());
		w.setBlockState(new BlockPos(x + 6, y + 0, z + 2), JourneyBlocks.eucaBricks.getDefaultState());
		w.setBlockState(new BlockPos(x + 6, y + 0, z + 3), JourneyBlocks.goldEucaPlank.getDefaultState());
		w.setBlockState(new BlockPos(x + 6, y + 0, z + 4), JourneyBlocks.eucaBricks.getDefaultState());
		w.setBlockState(new BlockPos(x + 6, y + 0, z + 5), JourneyBlocks.eucaBricks.getDefaultState());
		w.setBlockState(new BlockPos(x + 6, y + 0, z + 6), JourneyBlocks.eucaBricks.getDefaultState());
		w.setBlockState(new BlockPos(x + 6, y + 0, z + 7), JourneyBlocks.eucaBricks.getDefaultState());
		w.setBlockState(new BlockPos(x + 6, y + 0, z + 8), JourneyBlocks.eucaBricks.getDefaultState());
		w.setBlockState(new BlockPos(x + 6, y + 0, z + 9), JourneyBlocks.eucaBricks.getDefaultState());
		w.setBlockState(new BlockPos(x + 6, y + 0, z + 10), JourneyBlocks.eucaBricks.getDefaultState());
		w.setBlockState(new BlockPos(x + 6, y + 1, z + 2), JourneyBlocks.eucaBricks.getDefaultState());
		w.setBlockState(new BlockPos(x + 6, y + 1, z + 4), JourneyBlocks.eucaBricks.getDefaultState());
		w.setBlockState(new BlockPos(x + 6, y + 1, z + 5), JourneyBlocks.eucaBricks.getDefaultState());
		w.setBlockState(new BlockPos(x + 6, y + 1, z + 6), JourneyBlocks.eucaBricks.getDefaultState());
		w.setBlockState(new BlockPos(x + 6, y + 1, z + 7), JourneyBlocks.eucaBricks.getDefaultState());
		w.setBlockState(new BlockPos(x + 6, y + 1, z + 8), JourneyBlocks.eucaBricks.getDefaultState());
		w.setBlockState(new BlockPos(x + 6, y + 1, z + 9), JourneyBlocks.eucaBricks.getDefaultState());
		w.setBlockState(new BlockPos(x + 6, y + 1, z + 10), JourneyBlocks.eucaBricks.getDefaultState());
		w.setBlockState(new BlockPos(x + 6, y + 2, z + 2), JourneyBlocks.eucaBricks.getDefaultState());
		w.setBlockState(new BlockPos(x + 6, y + 2, z + 4), JourneyBlocks.eucaBricks.getDefaultState());
		w.setBlockState(new BlockPos(x + 6, y + 2, z + 5), JourneyBlocks.eucaBricks.getDefaultState());
		w.setBlockState(new BlockPos(x + 6, y + 2, z + 6), Blocks.STAINED_GLASS_PANE.getStateFromMeta(1));
		w.setBlockState(new BlockPos(x + 6, y + 2, z + 7), Blocks.STAINED_GLASS_PANE.getStateFromMeta(1));
		w.setBlockState(new BlockPos(x + 6, y + 2, z + 8), Blocks.STAINED_GLASS_PANE.getStateFromMeta(1));
		w.setBlockState(new BlockPos(x + 6, y + 2, z + 9), JourneyBlocks.eucaBricks.getDefaultState());
		w.setBlockState(new BlockPos(x + 6, y + 2, z + 10), JourneyBlocks.eucaBricks.getDefaultState());
		w.setBlockState(new BlockPos(x + 6, y + 3, z + 2), JourneyBlocks.eucaBricks.getDefaultState());
		w.setBlockState(new BlockPos(x + 6, y + 3, z + 3), JourneyBlocks.eucaBricks.getDefaultState());
		w.setBlockState(new BlockPos(x + 6, y + 3, z + 4), JourneyBlocks.eucaBricks.getDefaultState());
		w.setBlockState(new BlockPos(x + 6, y + 3, z + 5), JourneyBlocks.eucaBricks.getDefaultState());
		w.setBlockState(new BlockPos(x + 6, y + 3, z + 6), Blocks.STAINED_GLASS_PANE.getStateFromMeta(1));
		w.setBlockState(new BlockPos(x + 6, y + 3, z + 7), Blocks.STAINED_GLASS_PANE.getStateFromMeta(1));
		w.setBlockState(new BlockPos(x + 6, y + 3, z + 8), Blocks.STAINED_GLASS_PANE.getStateFromMeta(1));
		w.setBlockState(new BlockPos(x + 6, y + 3, z + 9), JourneyBlocks.eucaBricks.getDefaultState());
		w.setBlockState(new BlockPos(x + 6, y + 3, z + 10), JourneyBlocks.eucaBricks.getDefaultState());
		w.setBlockState(new BlockPos(x + 6, y + 4, z + 2), JourneyBlocks.eucaBricks.getDefaultState());
		w.setBlockState(new BlockPos(x + 6, y + 4, z + 3), JourneyBlocks.eucaBricks.getDefaultState());
		w.setBlockState(new BlockPos(x + 6, y + 4, z + 4), JourneyBlocks.eucaBricks.getDefaultState());
		w.setBlockState(new BlockPos(x + 6, y + 4, z + 5), JourneyBlocks.eucaBricks.getDefaultState());
		w.setBlockState(new BlockPos(x + 6, y + 4, z + 6), JourneyBlocks.eucaBricks.getDefaultState());
		w.setBlockState(new BlockPos(x + 6, y + 4, z + 7), JourneyBlocks.eucaBricks.getDefaultState());
		w.setBlockState(new BlockPos(x + 6, y + 4, z + 8), JourneyBlocks.eucaBricks.getDefaultState());
		w.setBlockState(new BlockPos(x + 6, y + 4, z + 9), JourneyBlocks.eucaBricks.getDefaultState());
		w.setBlockState(new BlockPos(x + 6, y + 4, z + 10), JourneyBlocks.eucaBricks.getDefaultState());
		w.setBlockState(new BlockPos(x + 6, y + 5, z + 2), JourneyBlocks.eucaBricks.getDefaultState());
		w.setBlockState(new BlockPos(x + 6, y + 5, z + 3), JourneyBlocks.eucaBricks.getDefaultState());
		w.setBlockState(new BlockPos(x + 6, y + 5, z + 4), JourneyBlocks.eucaBricks.getDefaultState());
		w.setBlockState(new BlockPos(x + 6, y + 5, z + 5), JourneyBlocks.eucaBricks.getDefaultState());
		w.setBlockState(new BlockPos(x + 6, y + 5, z + 6), JourneyBlocks.eucaBricks.getDefaultState());
		w.setBlockState(new BlockPos(x + 6, y + 5, z + 7), JourneyBlocks.eucaBricks.getDefaultState());
		w.setBlockState(new BlockPos(x + 6, y + 5, z + 8), JourneyBlocks.eucaBricks.getDefaultState());
		w.setBlockState(new BlockPos(x + 6, y + 5, z + 9), JourneyBlocks.eucaBricks.getDefaultState());
		w.setBlockState(new BlockPos(x + 6, y + 5, z + 10), JourneyBlocks.eucaBricks.getDefaultState());
		w.setBlockState(new BlockPos(x + 6, y + 6, z + 1), JourneyBlocks.eucaBricks.getDefaultState());
		w.setBlockState(new BlockPos(x + 6, y + 6, z + 2), JourneyBlocks.eucaBricks.getDefaultState());
		w.setBlockState(new BlockPos(x + 6, y + 6, z + 3), JourneyBlocks.eucaBricks.getDefaultState());
		w.setBlockState(new BlockPos(x + 6, y + 6, z + 4), JourneyBlocks.eucaBricks.getDefaultState());
		w.setBlockState(new BlockPos(x + 6, y + 6, z + 5), JourneyBlocks.eucaBricks.getDefaultState());
		w.setBlockState(new BlockPos(x + 6, y + 6, z + 6), JourneyBlocks.eucaBricks.getDefaultState());
		w.setBlockState(new BlockPos(x + 6, y + 6, z + 7), JourneyBlocks.eucaBricks.getDefaultState());
		w.setBlockState(new BlockPos(x + 6, y + 6, z + 8), JourneyBlocks.eucaBricks.getDefaultState());
		w.setBlockState(new BlockPos(x + 6, y + 6, z + 9), JourneyBlocks.eucaBricks.getDefaultState());
		w.setBlockState(new BlockPos(x + 6, y + 6, z + 10), JourneyBlocks.eucaBricks.getDefaultState());
		w.setBlockState(new BlockPos(x + 6, y + 6, z + 11), JourneyBlocks.eucaBricks.getDefaultState());
		w.setBlockState(new BlockPos(x + 7, y + 5, z + 1), JourneyBlocks.eucaBricks.getDefaultState());
		w.setBlockState(new BlockPos(x + 7, y + 5, z + 2), JourneyBlocks.eucaBricks.getDefaultState());
		w.setBlockState(new BlockPos(x + 7, y + 5, z + 3), JourneyBlocks.eucaBricks.getDefaultState());
		w.setBlockState(new BlockPos(x + 7, y + 5, z + 4), JourneyBlocks.eucaBricks.getDefaultState());
		w.setBlockState(new BlockPos(x + 7, y + 5, z + 5), JourneyBlocks.eucaBricks.getDefaultState());
		w.setBlockState(new BlockPos(x + 7, y + 5, z + 6), JourneyBlocks.eucaBricks.getDefaultState());
		w.setBlockState(new BlockPos(x + 7, y + 5, z + 7), JourneyBlocks.eucaBricks.getDefaultState());
		w.setBlockState(new BlockPos(x + 7, y + 5, z + 8), JourneyBlocks.eucaBricks.getDefaultState());
		w.setBlockState(new BlockPos(x + 7, y + 5, z + 9), JourneyBlocks.eucaBricks.getDefaultState());
		w.setBlockState(new BlockPos(x + 7, y + 5, z + 10), JourneyBlocks.eucaBricks.getDefaultState());
		w.setBlockState(new BlockPos(x + 7, y + 5, z + 11), JourneyBlocks.eucaBricks.getDefaultState());

		if(!w.isRemote) {
			EntityAlloyMender smith = new EntityAlloyMender(w);
			smith.setLocationAndAngles(x + 4, y + 2, z + 4, 0.0F, 0.0F);
			w.spawnEntity(smith);
		}
		return false;
	}
}