package net.journey.dimension.cloudia.zone;

import net.journey.dimension.cloudia.CloudiaChunkPrimer;
import net.journey.init.blocks.JourneyBlocks;
import net.journey.init.common.JourneyCrops;
import net.minecraft.block.BlockStairs;
import net.minecraft.init.Blocks;
import net.minecraft.util.EnumFacing;

import java.util.Random;

public class CloudiaHouse1 extends CloudiaZoneBase {

    /*First layer only*/
    @Override
    public boolean generate(CloudiaChunkPrimer worldIn, Random rand, int i, int j, int k) {
        this.setBlock(worldIn, i + 0, j + 0, k + 6, JourneyBlocks.cloudiaRock.getDefaultState());
        this.setBlock(worldIn, i + 0, j + 0, k + 7, JourneyBlocks.cloudiaRock.getDefaultState());
        this.setBlock(worldIn, i + 0, j + 0, k + 8, JourneyBlocks.cloudiaRock.getDefaultState());
        this.setBlock(worldIn, i + 0, j + 0, k + 9, JourneyBlocks.cloudiaRock.getDefaultState());
        this.setBlock(worldIn, i + 0, j + 1, k + 6, JourneyBlocks.cloudiaTile.getDefaultState());
        this.setBlock(worldIn, i + 0, j + 1, k + 9, JourneyBlocks.cloudiaTile.getDefaultState());
        this.setBlock(worldIn, i + 0, j + 2, k + 6, JourneyBlocks.cloudiaWall.getDefaultState());
        this.setBlock(worldIn, i + 0, j + 2, k + 9, JourneyBlocks.cloudiaWall.getDefaultState());
        this.setBlock(worldIn, i + 0, j + 3, k + 6, JourneyBlocks.cloudiaLamp.getDefaultState());
        this.setBlock(worldIn, i + 0, j + 3, k + 9, JourneyBlocks.cloudiaLamp.getDefaultState());
        this.setBlock(worldIn, i + 1, j + 0, k + 6, JourneyBlocks.cloudiaRock.getDefaultState());
        this.setBlock(worldIn, i + 1, j + 0, k + 7, JourneyBlocks.cloudiaRock.getDefaultState());
        this.setBlock(worldIn, i + 1, j + 0, k + 8, JourneyBlocks.cloudiaRock.getDefaultState());
        this.setBlock(worldIn, i + 1, j + 0, k + 9, JourneyBlocks.cloudiaRock.getDefaultState());
        this.setBlock(worldIn, i + 2, j + 0, k + 2, JourneyBlocks.cloudiaRock.getDefaultState());
        this.setBlock(worldIn, i + 2, j + 0, k + 3, JourneyBlocks.cloudiaRock.getDefaultState());
        this.setBlock(worldIn, i + 2, j + 0, k + 4, JourneyBlocks.cloudiaRock.getDefaultState());
        this.setBlock(worldIn, i + 2, j + 0, k + 5, JourneyBlocks.cloudiaRock.getDefaultState());
        this.setBlock(worldIn, i + 2, j + 0, k + 6, JourneyBlocks.cloudiaRock.getDefaultState());
        this.setBlock(worldIn, i + 2, j + 0, k + 7, JourneyBlocks.cloudiaRock.getDefaultState());
        this.setBlock(worldIn, i + 2, j + 0, k + 8, JourneyBlocks.cloudiaRock.getDefaultState());
        this.setBlock(worldIn, i + 2, j + 0, k + 9, JourneyBlocks.cloudiaRock.getDefaultState());
        this.setBlock(worldIn, i + 2, j + 0, k + 10, JourneyBlocks.cloudiaRock.getDefaultState());
        this.setBlock(worldIn, i + 2, j + 0, k + 11, JourneyBlocks.cloudiaRock.getDefaultState());
        this.setBlock(worldIn, i + 2, j + 0, k + 12, JourneyBlocks.cloudiaRock.getDefaultState());
        this.setBlock(worldIn, i + 2, j + 0, k + 13, JourneyBlocks.cloudiaRock.getDefaultState());
        this.setBlock(worldIn, i + 2, j + 4, k + 5, JourneyBlocks.cloudiaTileStairs.getDefaultState().withProperty(BlockStairs.FACING, EnumFacing.SOUTH));
        this.setBlock(worldIn, i + 2, j + 4, k + 6, JourneyBlocks.cloudiaTileStairs.getDefaultState().withProperty(BlockStairs.FACING, EnumFacing.EAST));
        this.setBlock(worldIn, i + 2, j + 4, k + 7, JourneyBlocks.cloudiaTileStairs.getDefaultState().withProperty(BlockStairs.FACING, EnumFacing.EAST));
        this.setBlock(worldIn, i + 2, j + 4, k + 8, JourneyBlocks.cloudiaTileStairs.getDefaultState().withProperty(BlockStairs.FACING, EnumFacing.EAST));
        this.setBlock(worldIn, i + 2, j + 4, k + 9, JourneyBlocks.cloudiaTileStairs.getDefaultState().withProperty(BlockStairs.FACING, EnumFacing.EAST));
        this.setBlock(worldIn, i + 2, j + 4, k + 10, JourneyBlocks.cloudiaTileStairs.getDefaultState().withProperty(BlockStairs.FACING, EnumFacing.EAST));
        this.setBlock(worldIn, i + 3, j + 0, k + 2, JourneyBlocks.cloudiaRock.getDefaultState());
        this.setBlock(worldIn, i + 3, j + 0, k + 3, JourneyBlocks.cloudiaDirt);
        this.setBlock(worldIn, i + 3, j + 0, k + 4, JourneyBlocks.cloudiaDirt);
        this.setBlock(worldIn, i + 3, j + 0, k + 5, JourneyBlocks.cloudiaDirt);
        this.setBlock(worldIn, i + 3, j + 0, k + 6, JourneyBlocks.cloudiaPlanks.getDefaultState());
        this.setBlock(worldIn, i + 3, j + 0, k + 7, JourneyBlocks.cloudiaPlanks.getDefaultState());
        this.setBlock(worldIn, i + 3, j + 0, k + 8, JourneyBlocks.cloudiaPlanks.getDefaultState());
        this.setBlock(worldIn, i + 3, j + 0, k + 9, JourneyBlocks.cloudiaPlanks.getDefaultState());
        this.setBlock(worldIn, i + 3, j + 0, k + 10, JourneyBlocks.cloudiaDirt);
        this.setBlock(worldIn, i + 3, j + 0, k + 11, JourneyBlocks.cloudiaDirt);
        this.setBlock(worldIn, i + 3, j + 0, k + 12, JourneyBlocks.cloudiaDirt);
        this.setBlock(worldIn, i + 3, j + 0, k + 13, JourneyBlocks.cloudiaRock.getDefaultState());
        this.setBlock(worldIn, i + 3, j + 1, k + 3, JourneyCrops.airRootMelon);
        this.setBlock(worldIn, i + 3, j + 1, k + 4, JourneyCrops.airRootMelon);
        this.setBlock(worldIn, i + 3, j + 1, k + 5, JourneyCrops.airRootMelon);
        this.setBlock(worldIn, i + 3, j + 1, k + 6, JourneyBlocks.cloudiaPillar);
        this.setBlock(worldIn, i + 3, j + 1, k + 9, JourneyBlocks.cloudiaPillar);
        this.setBlock(worldIn, i + 3, j + 1, k + 10, JourneyCrops.airRootMelon);
        this.setBlock(worldIn, i + 3, j + 1, k + 11, JourneyCrops.airRootMelon);
        this.setBlock(worldIn, i + 3, j + 1, k + 12, JourneyCrops.airRootMelon);
        this.setBlock(worldIn, i + 3, j + 2, k + 6, JourneyBlocks.cloudiaPillar);
        this.setBlock(worldIn, i + 3, j + 2, k + 9, JourneyBlocks.cloudiaPillar);
        this.setBlock(worldIn, i + 3, j + 3, k + 6, JourneyBlocks.cloudiaPillar);
        this.setBlock(worldIn, i + 3, j + 3, k + 9, JourneyBlocks.cloudiaPillar);
        this.setBlock(worldIn, i + 3, j + 4, k + 5, JourneyBlocks.cloudiaTileStairs.getDefaultState().withProperty(BlockStairs.FACING, EnumFacing.SOUTH));
        this.setBlock(worldIn, i + 3, j + 4, k + 6, JourneyBlocks.cloudiaPlanks.getDefaultState());
        this.setBlock(worldIn, i + 3, j + 4, k + 7, JourneyBlocks.cloudiaPlanks.getDefaultState());
        this.setBlock(worldIn, i + 3, j + 4, k + 8, JourneyBlocks.cloudiaPlanks.getDefaultState());
        this.setBlock(worldIn, i + 3, j + 4, k + 9, JourneyBlocks.cloudiaPlanks.getDefaultState());
        this.setBlock(worldIn, i + 3, j + 4, k + 10, JourneyBlocks.cloudiaTileStairs.getDefaultState().withProperty(BlockStairs.FACING, EnumFacing.NORTH));
        this.setBlock(worldIn, i + 3, j + 5, k + 6, JourneyBlocks.cloudiaTileStairs.getDefaultState().withProperty(BlockStairs.FACING, EnumFacing.SOUTH));
        this.setBlock(worldIn, i + 3, j + 5, k + 7, JourneyBlocks.cloudiaTileStairs.getDefaultState().withProperty(BlockStairs.FACING, EnumFacing.EAST));
        this.setBlock(worldIn, i + 3, j + 5, k + 8, JourneyBlocks.cloudiaTileStairs.getDefaultState().withProperty(BlockStairs.FACING, EnumFacing.EAST));
        this.setBlock(worldIn, i + 3, j + 5, k + 9, JourneyBlocks.cloudiaTileStairs.getDefaultState().withProperty(BlockStairs.FACING, EnumFacing.EAST));
        this.setBlock(worldIn, i + 4, j + 0, k + 2, JourneyBlocks.cloudiaRock.getDefaultState());
        this.setBlock(worldIn, i + 4, j + 0, k + 3, JourneyBlocks.cloudiaDirt);
        //this.setBlock(worldIn, i + 4, j + 0, k + 4, Blocks.WATER.getDefaultState());
        this.setBlock(worldIn, i + 4, j + 0, k + 5, JourneyBlocks.cloudiaDirt);
        this.setBlock(worldIn, i + 4, j + 0, k + 6, JourneyBlocks.cloudiaPlanks.getDefaultState());
        this.setBlock(worldIn, i + 4, j + 0, k + 7, JourneyBlocks.cloudiaPlanks.getDefaultState());
        this.setBlock(worldIn, i + 4, j + 0, k + 8, JourneyBlocks.cloudiaPlanks.getDefaultState());
        this.setBlock(worldIn, i + 4, j + 0, k + 9, JourneyBlocks.cloudiaPlanks.getDefaultState());
        this.setBlock(worldIn, i + 4, j + 0, k + 10, JourneyBlocks.cloudiaDirt);
        //this.setBlock(worldIn, i + 4, j + 0, k + 11, Blocks.WATER.getDefaultState());
        this.setBlock(worldIn, i + 4, j + 0, k + 12, JourneyBlocks.cloudiaDirt);
        this.setBlock(worldIn, i + 4, j + 0, k + 13, JourneyBlocks.cloudiaRock.getDefaultState());
        this.setBlock(worldIn, i + 4, j + 1, k + 3, JourneyCrops.airRootMelon);
        this.setBlock(worldIn, i + 4, j + 1, k + 5, JourneyCrops.airRootMelon);
        this.setBlock(worldIn, i + 4, j + 1, k + 6, JourneyBlocks.cloudiaTile.getDefaultState());
        this.setBlock(worldIn, i + 4, j + 1, k + 9, JourneyBlocks.cloudiaTile.getDefaultState());
        this.setBlock(worldIn, i + 4, j + 1, k + 10, JourneyCrops.airRootMelon);
        this.setBlock(worldIn, i + 4, j + 1, k + 12, JourneyCrops.airRootMelon);
        this.setBlock(worldIn, i + 4, j + 2, k + 6, JourneyBlocks.cloudiaTile.getDefaultState());
        this.setBlock(worldIn, i + 4, j + 2, k + 9, JourneyBlocks.cloudiaTile.getDefaultState());
        this.setBlock(worldIn, i + 4, j + 3, k + 6, JourneyBlocks.cloudiaTile.getDefaultState());
        this.setBlock(worldIn, i + 4, j + 3, k + 9, JourneyBlocks.cloudiaTile.getDefaultState());
        this.setBlock(worldIn, i + 4, j + 4, k + 5, JourneyBlocks.cloudiaTileStairs.getDefaultState().withProperty(BlockStairs.FACING, EnumFacing.SOUTH));
        this.setBlock(worldIn, i + 4, j + 4, k + 6, JourneyBlocks.cloudiaPlanks.getDefaultState());
        this.setBlock(worldIn, i + 4, j + 4, k + 7, JourneyBlocks.cloudiaPlanks.getDefaultState());
        this.setBlock(worldIn, i + 4, j + 4, k + 8, JourneyBlocks.cloudiaPlanks.getDefaultState());
        this.setBlock(worldIn, i + 4, j + 4, k + 9, JourneyBlocks.cloudiaPlanks.getDefaultState());
        this.setBlock(worldIn, i + 4, j + 4, k + 10, JourneyBlocks.cloudiaTileStairs.getDefaultState().withProperty(BlockStairs.FACING, EnumFacing.NORTH));
        this.setBlock(worldIn, i + 4, j + 5, k + 6, JourneyBlocks.cloudiaTileStairs.getDefaultState().withProperty(BlockStairs.FACING, EnumFacing.SOUTH));
        this.setBlock(worldIn, i + 4, j + 5, k + 7, JourneyBlocks.cloudiaCobblestone.getDefaultState());
        this.setBlock(worldIn, i + 4, j + 5, k + 8, JourneyBlocks.cloudiaCobblestone.getDefaultState());
        this.setBlock(worldIn, i + 4, j + 5, k + 9, JourneyBlocks.cloudiaTileStairs.getDefaultState().withProperty(BlockStairs.FACING, EnumFacing.NORTH));
        this.setBlock(worldIn, i + 4, j + 6, k + 7, JourneyBlocks.cloudiaTileStairs.getDefaultState().withProperty(BlockStairs.FACING, EnumFacing.SOUTH));
        this.setBlock(worldIn, i + 4, j + 6, k + 8, JourneyBlocks.cloudiaTileStairs.getDefaultState().withProperty(BlockStairs.FACING, EnumFacing.EAST));
        this.setBlock(worldIn, i + 5, j + 0, k + 2, JourneyBlocks.cloudiaRock.getDefaultState());
        this.setBlock(worldIn, i + 5, j + 0, k + 3, JourneyBlocks.cloudiaDirt);
        this.setBlock(worldIn, i + 5, j + 0, k + 4, JourneyBlocks.cloudiaDirt);
        this.setBlock(worldIn, i + 5, j + 0, k + 5, JourneyBlocks.cloudiaDirt);
        this.setBlock(worldIn, i + 5, j + 0, k + 6, JourneyBlocks.cloudiaPlanks.getDefaultState());
        this.setBlock(worldIn, i + 5, j + 0, k + 7, JourneyBlocks.cloudiaPlanks.getDefaultState());
        this.setBlock(worldIn, i + 5, j + 0, k + 8, JourneyBlocks.cloudiaPlanks.getDefaultState());
        this.setBlock(worldIn, i + 5, j + 0, k + 9, JourneyBlocks.cloudiaPlanks.getDefaultState());
        this.setBlock(worldIn, i + 5, j + 0, k + 10, JourneyBlocks.cloudiaDirt);
        this.setBlock(worldIn, i + 5, j + 0, k + 11, JourneyBlocks.cloudiaDirt);
        this.setBlock(worldIn, i + 5, j + 0, k + 12, JourneyBlocks.cloudiaDirt);
        this.setBlock(worldIn, i + 5, j + 0, k + 13, JourneyBlocks.cloudiaRock.getDefaultState());
        this.setBlock(worldIn, i + 5, j + 1, k + 3, JourneyCrops.airRootMelon);
        this.setBlock(worldIn, i + 5, j + 1, k + 4, JourneyCrops.airRootMelon);
        this.setBlock(worldIn, i + 5, j + 1, k + 5, JourneyCrops.airRootMelon);
        this.setBlock(worldIn, i + 5, j + 1, k + 6, JourneyBlocks.cloudiaTile.getDefaultState());
        this.setBlock(worldIn, i + 5, j + 1, k + 9, JourneyBlocks.cloudiaTile.getDefaultState());
        this.setBlock(worldIn, i + 5, j + 1, k + 10, JourneyCrops.airRootMelon);
        this.setBlock(worldIn, i + 5, j + 1, k + 11, JourneyCrops.airRootMelon);
        this.setBlock(worldIn, i + 5, j + 1, k + 12, JourneyCrops.airRootMelon);
        this.setBlock(worldIn, i + 5, j + 2, k + 6, JourneyBlocks.cloudiaTile.getDefaultState());
        this.setBlock(worldIn, i + 5, j + 2, k + 9, JourneyBlocks.cloudiaTile.getDefaultState());
        this.setBlock(worldIn, i + 5, j + 3, k + 6, JourneyBlocks.cloudiaTile.getDefaultState());
        this.setBlock(worldIn, i + 5, j + 3, k + 9, JourneyBlocks.cloudiaTile.getDefaultState());
        this.setBlock(worldIn, i + 5, j + 4, k + 2, JourneyBlocks.cloudiaTileStairs.getDefaultState().withProperty(BlockStairs.FACING, EnumFacing.EAST));
        this.setBlock(worldIn, i + 5, j + 4, k + 3, JourneyBlocks.cloudiaTileStairs.getDefaultState().withProperty(BlockStairs.FACING, EnumFacing.EAST));
        this.setBlock(worldIn, i + 5, j + 4, k + 4, JourneyBlocks.cloudiaTileStairs.getDefaultState().withProperty(BlockStairs.FACING, EnumFacing.EAST));
        this.setBlock(worldIn, i + 5, j + 4, k + 5, JourneyBlocks.cloudiaTileStairs.getDefaultState().withProperty(BlockStairs.FACING, EnumFacing.EAST));
        this.setBlock(worldIn, i + 5, j + 4, k + 6, JourneyBlocks.cloudiaPlanks.getDefaultState());
        this.setBlock(worldIn, i + 5, j + 4, k + 7, JourneyBlocks.cloudiaPlanks.getDefaultState());
        this.setBlock(worldIn, i + 5, j + 4, k + 8, JourneyBlocks.cloudiaPlanks.getDefaultState());
        this.setBlock(worldIn, i + 5, j + 4, k + 9, JourneyBlocks.cloudiaPlanks.getDefaultState());
        this.setBlock(worldIn, i + 5, j + 4, k + 10, JourneyBlocks.cloudiaTileStairs.getDefaultState().withProperty(BlockStairs.FACING, EnumFacing.EAST));
        this.setBlock(worldIn, i + 5, j + 4, k + 11, JourneyBlocks.cloudiaTileStairs.getDefaultState().withProperty(BlockStairs.FACING, EnumFacing.EAST));
        this.setBlock(worldIn, i + 5, j + 4, k + 12, JourneyBlocks.cloudiaTileStairs.getDefaultState().withProperty(BlockStairs.FACING, EnumFacing.EAST));
        this.setBlock(worldIn, i + 5, j + 4, k + 13, JourneyBlocks.cloudiaTileStairs.getDefaultState().withProperty(BlockStairs.FACING, EnumFacing.EAST));
        this.setBlock(worldIn, i + 5, j + 5, k + 5, JourneyBlocks.cloudiaTileStairs.getDefaultState().withProperty(BlockStairs.FACING, EnumFacing.SOUTH));
        this.setBlock(worldIn, i + 5, j + 5, k + 6, JourneyBlocks.cloudiaTileStairs.getDefaultState().withProperty(BlockStairs.FACING, EnumFacing.EAST));
        this.setBlock(worldIn, i + 5, j + 5, k + 7, JourneyBlocks.cloudiaCobblestone.getDefaultState());
        this.setBlock(worldIn, i + 5, j + 5, k + 8, JourneyBlocks.cloudiaCobblestone.getDefaultState());
        this.setBlock(worldIn, i + 5, j + 5, k + 9, JourneyBlocks.cloudiaTileStairs.getDefaultState().withProperty(BlockStairs.FACING, EnumFacing.EAST));
        this.setBlock(worldIn, i + 5, j + 5, k + 10, JourneyBlocks.cloudiaTileStairs.getDefaultState().withProperty(BlockStairs.FACING, EnumFacing.NORTH));
        this.setBlock(worldIn, i + 5, j + 6, k + 7, JourneyBlocks.cloudiaTileStairs.getDefaultState().withProperty(BlockStairs.FACING, EnumFacing.SOUTH));
        this.setBlock(worldIn, i + 5, j + 6, k + 8, JourneyBlocks.cloudiaTileStairs.getDefaultState().withProperty(BlockStairs.FACING, EnumFacing.NORTH));
        this.setBlock(worldIn, i + 5, j + 11, k + 5, JourneyBlocks.cloudiaTileStairs.getDefaultState().withProperty(BlockStairs.FACING, EnumFacing.EAST));
        this.setBlock(worldIn, i + 5, j + 11, k + 6, JourneyBlocks.cloudiaTileStairs.getDefaultState().withProperty(BlockStairs.FACING, EnumFacing.EAST));
        this.setBlock(worldIn, i + 5, j + 11, k + 7, JourneyBlocks.cloudiaTileStairs.getDefaultState().withProperty(BlockStairs.FACING, EnumFacing.EAST));
        this.setBlock(worldIn, i + 5, j + 11, k + 8, JourneyBlocks.cloudiaTileStairs.getDefaultState().withProperty(BlockStairs.FACING, EnumFacing.EAST));
        this.setBlock(worldIn, i + 5, j + 11, k + 9, JourneyBlocks.cloudiaTileStairs.getDefaultState().withProperty(BlockStairs.FACING, EnumFacing.EAST));
        this.setBlock(worldIn, i + 5, j + 11, k + 10, JourneyBlocks.cloudiaTileStairs.getDefaultState().withProperty(BlockStairs.FACING, EnumFacing.NORTH));
        this.setBlock(worldIn, i + 6, j + 0, k + 0, JourneyBlocks.cloudiaRock.getDefaultState());
        this.setBlock(worldIn, i + 6, j + 0, k + 1, JourneyBlocks.cloudiaRock.getDefaultState());
        this.setBlock(worldIn, i + 6, j + 0, k + 2, JourneyBlocks.cloudiaRock.getDefaultState());
        this.setBlock(worldIn, i + 6, j + 0, k + 3, JourneyBlocks.cloudiaPlanks.getDefaultState());
        this.setBlock(worldIn, i + 6, j + 0, k + 4, JourneyBlocks.cloudiaPlanks.getDefaultState());
        this.setBlock(worldIn, i + 6, j + 0, k + 5, JourneyBlocks.cloudiaPlanks.getDefaultState());
        this.setBlock(worldIn, i + 6, j + 0, k + 6, JourneyBlocks.cloudiaPlanks.getDefaultState());
        this.setBlock(worldIn, i + 6, j + 0, k + 7, JourneyBlocks.cloudiaPlanks.getDefaultState());
        this.setBlock(worldIn, i + 6, j + 0, k + 8, JourneyBlocks.cloudiaPlanks.getDefaultState());
        this.setBlock(worldIn, i + 6, j + 0, k + 9, JourneyBlocks.cloudiaPlanks.getDefaultState());
        this.setBlock(worldIn, i + 6, j + 0, k + 10, JourneyBlocks.cloudiaPlanks.getDefaultState());
        this.setBlock(worldIn, i + 6, j + 0, k + 11, JourneyBlocks.cloudiaPlanks.getDefaultState());
        this.setBlock(worldIn, i + 6, j + 0, k + 12, JourneyBlocks.cloudiaPlanks.getDefaultState());
        this.setBlock(worldIn, i + 6, j + 0, k + 13, JourneyBlocks.cloudiaRock.getDefaultState());
        this.setBlock(worldIn, i + 6, j + 0, k + 14, JourneyBlocks.cloudiaRock.getDefaultState());
        this.setBlock(worldIn, i + 6, j + 0, k + 15, JourneyBlocks.cloudiaRock.getDefaultState());
        this.setBlock(worldIn, i + 6, j + 1, k + 0, JourneyBlocks.cloudiaTile.getDefaultState());
        this.setBlock(worldIn, i + 6, j + 1, k + 1, Blocks.AIR.getDefaultState());
        this.setBlock(worldIn, i + 6, j + 1, k + 2, Blocks.AIR.getDefaultState());
        this.setBlock(worldIn, i + 6, j + 1, k + 3, JourneyBlocks.cloudiaPillar);
        this.setBlock(worldIn, i + 6, j + 1, k + 4, JourneyBlocks.cloudiaTile.getDefaultState());
        this.setBlock(worldIn, i + 6, j + 1, k + 5, JourneyBlocks.cloudiaTile.getDefaultState());
        this.setBlock(worldIn, i + 6, j + 1, k + 6, Blocks.AIR.getDefaultState());
        this.setBlock(worldIn, i + 6, j + 1, k + 7, Blocks.AIR.getDefaultState());
        this.setBlock(worldIn, i + 6, j + 1, k + 8, Blocks.AIR.getDefaultState());
        this.setBlock(worldIn, i + 6, j + 1, k + 9, Blocks.AIR.getDefaultState());
        this.setBlock(worldIn, i + 6, j + 1, k + 10, JourneyBlocks.cloudiaTile.getDefaultState());
        this.setBlock(worldIn, i + 6, j + 1, k + 11, JourneyBlocks.cloudiaTile.getDefaultState());
        this.setBlock(worldIn, i + 6, j + 1, k + 12, JourneyBlocks.cloudiaPillar);
        this.setBlock(worldIn, i + 6, j + 1, k + 13, Blocks.AIR.getDefaultState());
        this.setBlock(worldIn, i + 6, j + 1, k + 14, Blocks.AIR.getDefaultState());
        this.setBlock(worldIn, i + 6, j + 1, k + 15, JourneyBlocks.cloudiaTile.getDefaultState());
        this.setBlock(worldIn, i + 6, j + 2, k + 0, JourneyBlocks.cloudiaWall.getDefaultState());
        this.setBlock(worldIn, i + 6, j + 2, k + 1, Blocks.AIR.getDefaultState());
        this.setBlock(worldIn, i + 6, j + 2, k + 2, Blocks.AIR.getDefaultState());
        this.setBlock(worldIn, i + 6, j + 2, k + 3, JourneyBlocks.cloudiaPillar);
        this.setBlock(worldIn, i + 6, j + 2, k + 4, JourneyBlocks.cloudiaTile.getDefaultState());
        this.setBlock(worldIn, i + 6, j + 2, k + 5, JourneyBlocks.cloudiaTile.getDefaultState());
        this.setBlock(worldIn, i + 6, j + 2, k + 6, Blocks.AIR.getDefaultState());
        this.setBlock(worldIn, i + 6, j + 2, k + 7, Blocks.AIR.getDefaultState());
        this.setBlock(worldIn, i + 6, j + 2, k + 8, Blocks.AIR.getDefaultState());
        this.setBlock(worldIn, i + 6, j + 2, k + 9, Blocks.AIR.getDefaultState());
        this.setBlock(worldIn, i + 6, j + 2, k + 10, JourneyBlocks.cloudiaTile.getDefaultState());
        this.setBlock(worldIn, i + 6, j + 2, k + 11, JourneyBlocks.cloudiaTile.getDefaultState());
        this.setBlock(worldIn, i + 6, j + 2, k + 12, JourneyBlocks.cloudiaPillar);
        this.setBlock(worldIn, i + 6, j + 2, k + 13, Blocks.AIR.getDefaultState());
        this.setBlock(worldIn, i + 6, j + 2, k + 14, Blocks.AIR.getDefaultState());
        this.setBlock(worldIn, i + 6, j + 2, k + 15, JourneyBlocks.cloudiaWall.getDefaultState());
        this.setBlock(worldIn, i + 6, j + 3, k + 0, JourneyBlocks.cloudiaLamp.getDefaultState());
        this.setBlock(worldIn, i + 6, j + 3, k + 1, Blocks.AIR.getDefaultState());
        this.setBlock(worldIn, i + 6, j + 3, k + 2, Blocks.AIR.getDefaultState());
        this.setBlock(worldIn, i + 6, j + 3, k + 3, JourneyBlocks.cloudiaPillar);
        this.setBlock(worldIn, i + 6, j + 3, k + 4, JourneyBlocks.cloudiaTile.getDefaultState());
        this.setBlock(worldIn, i + 6, j + 3, k + 5, JourneyBlocks.cloudiaTile.getDefaultState());
        this.setBlock(worldIn, i + 6, j + 3, k + 6, Blocks.AIR.getDefaultState());
        this.setBlock(worldIn, i + 6, j + 3, k + 7, Blocks.AIR.getDefaultState());
        this.setBlock(worldIn, i + 6, j + 3, k + 8, Blocks.AIR.getDefaultState());
        this.setBlock(worldIn, i + 6, j + 3, k + 9, Blocks.AIR.getDefaultState());
        this.setBlock(worldIn, i + 6, j + 3, k + 10, JourneyBlocks.cloudiaTile.getDefaultState());
        this.setBlock(worldIn, i + 6, j + 3, k + 11, JourneyBlocks.cloudiaTile.getDefaultState());
        this.setBlock(worldIn, i + 6, j + 3, k + 12, JourneyBlocks.cloudiaPillar);
        this.setBlock(worldIn, i + 6, j + 3, k + 13, Blocks.AIR.getDefaultState());
        this.setBlock(worldIn, i + 6, j + 3, k + 14, Blocks.AIR.getDefaultState());
        this.setBlock(worldIn, i + 6, j + 3, k + 15, JourneyBlocks.cloudiaLamp.getDefaultState());
        this.setBlock(worldIn, i + 6, j + 4, k + 0, Blocks.AIR.getDefaultState());
        this.setBlock(worldIn, i + 6, j + 4, k + 1, Blocks.AIR.getDefaultState());
        this.setBlock(worldIn, i + 6, j + 4, k + 2, JourneyBlocks.cloudiaTileStairs.getDefaultState().withProperty(BlockStairs.FACING, EnumFacing.SOUTH));
        this.setBlock(worldIn, i + 6, j + 4, k + 3, JourneyBlocks.cloudiaPlanks.getDefaultState());
        this.setBlock(worldIn, i + 6, j + 4, k + 4, JourneyBlocks.cloudiaPlanks.getDefaultState());
        this.setBlock(worldIn, i + 6, j + 4, k + 5, JourneyBlocks.cloudiaPlanks.getDefaultState());
        this.setBlock(worldIn, i + 6, j + 4, k + 6, JourneyBlocks.cloudiaPlanks.getDefaultState());
        this.setBlock(worldIn, i + 6, j + 4, k + 7, JourneyBlocks.cloudiaPlanks.getDefaultState());
        this.setBlock(worldIn, i + 6, j + 4, k + 8, JourneyBlocks.cloudiaPlanks.getDefaultState());
        this.setBlock(worldIn, i + 6, j + 4, k + 9, JourneyBlocks.cloudiaPlanks.getDefaultState());
        this.setBlock(worldIn, i + 6, j + 4, k + 10, JourneyBlocks.cloudiaPlanks.getDefaultState());
        this.setBlock(worldIn, i + 6, j + 4, k + 11, JourneyBlocks.cloudiaPlanks.getDefaultState());
        this.setBlock(worldIn, i + 6, j + 4, k + 12, JourneyBlocks.cloudiaPlanks.getDefaultState());
        this.setBlock(worldIn, i + 6, j + 4, k + 13, JourneyBlocks.cloudiaTileStairs.getDefaultState().withProperty(BlockStairs.FACING, EnumFacing.NORTH));
        this.setBlock(worldIn, i + 6, j + 4, k + 14, Blocks.AIR.getDefaultState());
        this.setBlock(worldIn, i + 6, j + 4, k + 15, Blocks.AIR.getDefaultState());
        this.setBlock(worldIn, i + 6, j + 5, k + 0, Blocks.AIR.getDefaultState());
        this.setBlock(worldIn, i + 6, j + 5, k + 1, Blocks.AIR.getDefaultState());
        this.setBlock(worldIn, i + 6, j + 5, k + 2, Blocks.AIR.getDefaultState());
        this.setBlock(worldIn, i + 6, j + 5, k + 3, Blocks.AIR.getDefaultState());
        this.setBlock(worldIn, i + 6, j + 5, k + 4, Blocks.AIR.getDefaultState());
        this.setBlock(worldIn, i + 6, j + 5, k + 5, JourneyBlocks.cloudiaTileStairs.getDefaultState().withProperty(BlockStairs.FACING, EnumFacing.SOUTH));
        this.setBlock(worldIn, i + 6, j + 5, k + 6, JourneyBlocks.cloudiaPillar);
        this.setBlock(worldIn, i + 6, j + 5, k + 7, JourneyBlocks.cloudiaCobblestone.getDefaultState());
        this.setBlock(worldIn, i + 6, j + 5, k + 8, JourneyBlocks.cloudiaCobblestone.getDefaultState());
        this.setBlock(worldIn, i + 6, j + 5, k + 9, JourneyBlocks.cloudiaPillar);
        this.setBlock(worldIn, i + 6, j + 5, k + 10, JourneyBlocks.cloudiaTileStairs.getDefaultState().withProperty(BlockStairs.FACING, EnumFacing.NORTH));
        this.setBlock(worldIn, i + 6, j + 5, k + 11, Blocks.AIR.getDefaultState());
        this.setBlock(worldIn, i + 6, j + 5, k + 12, Blocks.AIR.getDefaultState());
        this.setBlock(worldIn, i + 6, j + 5, k + 13, Blocks.AIR.getDefaultState());
        this.setBlock(worldIn, i + 6, j + 5, k + 14, Blocks.AIR.getDefaultState());
        this.setBlock(worldIn, i + 6, j + 5, k + 15, Blocks.AIR.getDefaultState());
        this.setBlock(worldIn, i + 6, j + 6, k + 0, Blocks.AIR.getDefaultState());
        this.setBlock(worldIn, i + 6, j + 6, k + 1, Blocks.AIR.getDefaultState());
        this.setBlock(worldIn, i + 6, j + 6, k + 2, Blocks.AIR.getDefaultState());
        this.setBlock(worldIn, i + 6, j + 6, k + 3, Blocks.AIR.getDefaultState());
        this.setBlock(worldIn, i + 6, j + 6, k + 4, Blocks.AIR.getDefaultState());
        this.setBlock(worldIn, i + 6, j + 6, k + 5, Blocks.AIR.getDefaultState());
        this.setBlock(worldIn, i + 6, j + 6, k + 6, JourneyBlocks.cloudiaPillar);
        this.setBlock(worldIn, i + 6, j + 6, k + 7, JourneyBlocks.cloudiaTile.getDefaultState());
        this.setBlock(worldIn, i + 6, j + 6, k + 8, JourneyBlocks.cloudiaTile.getDefaultState());
        this.setBlock(worldIn, i + 6, j + 6, k + 9, JourneyBlocks.cloudiaPillar);
        this.setBlock(worldIn, i + 6, j + 6, k + 10, Blocks.AIR.getDefaultState());
        this.setBlock(worldIn, i + 6, j + 6, k + 11, Blocks.AIR.getDefaultState());
        this.setBlock(worldIn, i + 6, j + 6, k + 12, Blocks.AIR.getDefaultState());
        this.setBlock(worldIn, i + 6, j + 6, k + 13, Blocks.AIR.getDefaultState());
        this.setBlock(worldIn, i + 6, j + 6, k + 14, Blocks.AIR.getDefaultState());
        this.setBlock(worldIn, i + 6, j + 6, k + 15, Blocks.AIR.getDefaultState());
        this.setBlock(worldIn, i + 6, j + 7, k + 0, Blocks.AIR.getDefaultState());
        this.setBlock(worldIn, i + 6, j + 7, k + 1, Blocks.AIR.getDefaultState());
        this.setBlock(worldIn, i + 6, j + 7, k + 2, Blocks.AIR.getDefaultState());
        this.setBlock(worldIn, i + 6, j + 7, k + 3, Blocks.AIR.getDefaultState());
        this.setBlock(worldIn, i + 6, j + 7, k + 4, Blocks.AIR.getDefaultState());
        this.setBlock(worldIn, i + 6, j + 7, k + 5, Blocks.AIR.getDefaultState());
        this.setBlock(worldIn, i + 6, j + 7, k + 6, JourneyBlocks.cloudiaPillar);
        this.setBlock(worldIn, i + 6, j + 7, k + 7, JourneyBlocks.cloudiaBrickStairs.getDefaultState().withProperty(BlockStairs.FACING, EnumFacing.EAST));
        this.setBlock(worldIn, i + 6, j + 7, k + 8, JourneyBlocks.cloudiaBrickStairs.getDefaultState().withProperty(BlockStairs.FACING, EnumFacing.EAST));
        this.setBlock(worldIn, i + 6, j + 7, k + 9, JourneyBlocks.cloudiaPillar);
        this.setBlock(worldIn, i + 6, j + 7, k + 10, Blocks.AIR.getDefaultState());
        this.setBlock(worldIn, i + 6, j + 7, k + 11, Blocks.AIR.getDefaultState());
        this.setBlock(worldIn, i + 6, j + 7, k + 12, Blocks.AIR.getDefaultState());
        this.setBlock(worldIn, i + 6, j + 7, k + 13, Blocks.AIR.getDefaultState());
        this.setBlock(worldIn, i + 6, j + 7, k + 14, Blocks.AIR.getDefaultState());
        this.setBlock(worldIn, i + 6, j + 7, k + 15, Blocks.AIR.getDefaultState());
        this.setBlock(worldIn, i + 6, j + 8, k + 0, Blocks.AIR.getDefaultState());
        this.setBlock(worldIn, i + 6, j + 8, k + 1, Blocks.AIR.getDefaultState());
        this.setBlock(worldIn, i + 6, j + 8, k + 2, Blocks.AIR.getDefaultState());
        this.setBlock(worldIn, i + 6, j + 8, k + 3, Blocks.AIR.getDefaultState());
        this.setBlock(worldIn, i + 6, j + 8, k + 4, Blocks.AIR.getDefaultState());
        this.setBlock(worldIn, i + 6, j + 8, k + 5, Blocks.AIR.getDefaultState());
        this.setBlock(worldIn, i + 6, j + 8, k + 6, JourneyBlocks.cloudiaPillar);
        this.setBlock(worldIn, i + 6, j + 8, k + 7, Blocks.AIR.getDefaultState());
        this.setBlock(worldIn, i + 6, j + 8, k + 8, Blocks.AIR.getDefaultState());
        this.setBlock(worldIn, i + 6, j + 8, k + 9, JourneyBlocks.cloudiaPillar);
        this.setBlock(worldIn, i + 6, j + 8, k + 10, Blocks.AIR.getDefaultState());
        this.setBlock(worldIn, i + 6, j + 8, k + 11, Blocks.AIR.getDefaultState());
        this.setBlock(worldIn, i + 6, j + 8, k + 12, Blocks.AIR.getDefaultState());
        this.setBlock(worldIn, i + 6, j + 8, k + 13, Blocks.AIR.getDefaultState());
        this.setBlock(worldIn, i + 6, j + 8, k + 14, Blocks.AIR.getDefaultState());
        this.setBlock(worldIn, i + 6, j + 8, k + 15, Blocks.AIR.getDefaultState());
        this.setBlock(worldIn, i + 6, j + 9, k + 0, Blocks.AIR.getDefaultState());
        this.setBlock(worldIn, i + 6, j + 9, k + 1, Blocks.AIR.getDefaultState());
        this.setBlock(worldIn, i + 6, j + 9, k + 2, Blocks.AIR.getDefaultState());
        this.setBlock(worldIn, i + 6, j + 9, k + 3, Blocks.AIR.getDefaultState());
        this.setBlock(worldIn, i + 6, j + 9, k + 4, Blocks.AIR.getDefaultState());
        this.setBlock(worldIn, i + 6, j + 9, k + 5, Blocks.AIR.getDefaultState());
        this.setBlock(worldIn, i + 6, j + 9, k + 6, JourneyBlocks.cloudiaPillar);
        this.setBlock(worldIn, i + 6, j + 9, k + 7, Blocks.AIR.getDefaultState());
        this.setBlock(worldIn, i + 6, j + 9, k + 8, Blocks.AIR.getDefaultState());
        this.setBlock(worldIn, i + 6, j + 9, k + 9, JourneyBlocks.cloudiaPillar);
        this.setBlock(worldIn, i + 6, j + 9, k + 10, Blocks.AIR.getDefaultState());
        this.setBlock(worldIn, i + 6, j + 9, k + 11, Blocks.AIR.getDefaultState());
        this.setBlock(worldIn, i + 6, j + 9, k + 12, Blocks.AIR.getDefaultState());
        this.setBlock(worldIn, i + 6, j + 9, k + 13, Blocks.AIR.getDefaultState());
        this.setBlock(worldIn, i + 6, j + 9, k + 14, Blocks.AIR.getDefaultState());
        this.setBlock(worldIn, i + 6, j + 9, k + 15, Blocks.AIR.getDefaultState());
        this.setBlock(worldIn, i + 6, j + 10, k + 0, Blocks.AIR.getDefaultState());
        this.setBlock(worldIn, i + 6, j + 10, k + 1, Blocks.AIR.getDefaultState());
        this.setBlock(worldIn, i + 6, j + 10, k + 2, Blocks.AIR.getDefaultState());
        this.setBlock(worldIn, i + 6, j + 10, k + 3, Blocks.AIR.getDefaultState());
        this.setBlock(worldIn, i + 6, j + 10, k + 4, Blocks.AIR.getDefaultState());
        this.setBlock(worldIn, i + 6, j + 10, k + 5, Blocks.AIR.getDefaultState());
        this.setBlock(worldIn, i + 6, j + 10, k + 6, JourneyBlocks.cloudiaPillar);
        this.setBlock(worldIn, i + 6, j + 10, k + 7, JourneyBlocks.cloudiaTile.getDefaultState());
        this.setBlock(worldIn, i + 6, j + 10, k + 8, JourneyBlocks.cloudiaTile.getDefaultState());
        this.setBlock(worldIn, i + 6, j + 10, k + 9, JourneyBlocks.cloudiaPillar);
        this.setBlock(worldIn, i + 6, j + 10, k + 10, Blocks.AIR.getDefaultState());
        this.setBlock(worldIn, i + 6, j + 10, k + 11, Blocks.AIR.getDefaultState());
        this.setBlock(worldIn, i + 6, j + 10, k + 12, Blocks.AIR.getDefaultState());
        this.setBlock(worldIn, i + 6, j + 10, k + 13, Blocks.AIR.getDefaultState());
        this.setBlock(worldIn, i + 6, j + 10, k + 14, Blocks.AIR.getDefaultState());
        this.setBlock(worldIn, i + 6, j + 10, k + 15, Blocks.AIR.getDefaultState());
        this.setBlock(worldIn, i + 6, j + 11, k + 0, Blocks.AIR.getDefaultState());
        this.setBlock(worldIn, i + 6, j + 11, k + 1, Blocks.AIR.getDefaultState());
        this.setBlock(worldIn, i + 6, j + 11, k + 2, Blocks.AIR.getDefaultState());
        this.setBlock(worldIn, i + 6, j + 11, k + 3, Blocks.AIR.getDefaultState());
        this.setBlock(worldIn, i + 6, j + 11, k + 4, Blocks.AIR.getDefaultState());
        this.setBlock(worldIn, i + 6, j + 11, k + 5, JourneyBlocks.cloudiaTileStairs.getDefaultState().withProperty(BlockStairs.FACING, EnumFacing.SOUTH));
        this.setBlock(worldIn, i + 6, j + 11, k + 6, JourneyBlocks.cloudiaPlanks.getDefaultState());
        this.setBlock(worldIn, i + 6, j + 11, k + 7, JourneyBlocks.cloudiaPlanks.getDefaultState());
        this.setBlock(worldIn, i + 6, j + 11, k + 8, JourneyBlocks.cloudiaPlanks.getDefaultState());
        this.setBlock(worldIn, i + 6, j + 11, k + 9, JourneyBlocks.cloudiaPlanks.getDefaultState());
        this.setBlock(worldIn, i + 6, j + 11, k + 10, JourneyBlocks.cloudiaTileStairs.getDefaultState().withProperty(BlockStairs.FACING, EnumFacing.NORTH));
        this.setBlock(worldIn, i + 6, j + 11, k + 11, Blocks.AIR.getDefaultState());
        this.setBlock(worldIn, i + 6, j + 11, k + 12, Blocks.AIR.getDefaultState());
        this.setBlock(worldIn, i + 6, j + 11, k + 13, Blocks.AIR.getDefaultState());
        this.setBlock(worldIn, i + 6, j + 11, k + 14, Blocks.AIR.getDefaultState());
        this.setBlock(worldIn, i + 6, j + 11, k + 15, Blocks.AIR.getDefaultState());
        this.setBlock(worldIn, i + 6, j + 12, k + 0, Blocks.AIR.getDefaultState());
        this.setBlock(worldIn, i + 6, j + 12, k + 1, Blocks.AIR.getDefaultState());
        this.setBlock(worldIn, i + 6, j + 12, k + 2, Blocks.AIR.getDefaultState());
        this.setBlock(worldIn, i + 6, j + 12, k + 3, Blocks.AIR.getDefaultState());
        this.setBlock(worldIn, i + 6, j + 12, k + 4, Blocks.AIR.getDefaultState());
        this.setBlock(worldIn, i + 6, j + 12, k + 5, Blocks.AIR.getDefaultState());
        this.setBlock(worldIn, i + 6, j + 12, k + 6, JourneyBlocks.cloudiaTileStairs.getDefaultState().withProperty(BlockStairs.FACING, EnumFacing.EAST));
        this.setBlock(worldIn, i + 6, j + 12, k + 7, JourneyBlocks.cloudiaTileStairs.getDefaultState().withProperty(BlockStairs.FACING, EnumFacing.EAST));
        this.setBlock(worldIn, i + 6, j + 12, k + 8, JourneyBlocks.cloudiaTileStairs.getDefaultState().withProperty(BlockStairs.FACING, EnumFacing.EAST));
        this.setBlock(worldIn, i + 6, j + 12, k + 9, JourneyBlocks.cloudiaTileStairs.getDefaultState().withProperty(BlockStairs.FACING, EnumFacing.NORTH));
        this.setBlock(worldIn, i + 7, j + 0, k + 0, JourneyBlocks.cloudiaRock.getDefaultState());
        this.setBlock(worldIn, i + 7, j + 0, k + 1, JourneyBlocks.cloudiaRock.getDefaultState());
        this.setBlock(worldIn, i + 7, j + 0, k + 2, JourneyBlocks.cloudiaRock.getDefaultState());
        this.setBlock(worldIn, i + 7, j + 0, k + 3, JourneyBlocks.cloudiaPlanks.getDefaultState());
        this.setBlock(worldIn, i + 7, j + 0, k + 4, JourneyBlocks.cloudiaPlanks.getDefaultState());
        this.setBlock(worldIn, i + 7, j + 0, k + 5, JourneyBlocks.cloudiaPlanks.getDefaultState());
        this.setBlock(worldIn, i + 7, j + 0, k + 6, JourneyBlocks.cloudiaPlanks.getDefaultState());
        this.setBlock(worldIn, i + 7, j + 0, k + 7, JourneyBlocks.cloudiaCobblestone.getDefaultState());
        this.setBlock(worldIn, i + 7, j + 0, k + 8, JourneyBlocks.cloudiaCobblestone.getDefaultState());
        this.setBlock(worldIn, i + 7, j + 0, k + 9, JourneyBlocks.cloudiaPlanks.getDefaultState());
        this.setBlock(worldIn, i + 7, j + 0, k + 10, JourneyBlocks.cloudiaPlanks.getDefaultState());
        this.setBlock(worldIn, i + 7, j + 0, k + 11, JourneyBlocks.cloudiaPlanks.getDefaultState());
        this.setBlock(worldIn, i + 7, j + 0, k + 12, JourneyBlocks.cloudiaPlanks.getDefaultState());
        this.setBlock(worldIn, i + 7, j + 0, k + 13, JourneyBlocks.cloudiaRock.getDefaultState());
        this.setBlock(worldIn, i + 7, j + 0, k + 14, JourneyBlocks.cloudiaRock.getDefaultState());
        this.setBlock(worldIn, i + 7, j + 0, k + 15, JourneyBlocks.cloudiaRock.getDefaultState());
        this.setBlock(worldIn, i + 7, j + 3, k + 3, JourneyBlocks.cloudiaTile.getDefaultState());
        this.setBlock(worldIn, i + 7, j + 3, k + 4, Blocks.AIR.getDefaultState());
        this.setBlock(worldIn, i + 7, j + 3, k + 5, Blocks.AIR.getDefaultState());
        this.setBlock(worldIn, i + 7, j + 3, k + 6, Blocks.AIR.getDefaultState());
        this.setBlock(worldIn, i + 7, j + 3, k + 7, Blocks.AIR.getDefaultState());
        this.setBlock(worldIn, i + 7, j + 3, k + 8, Blocks.AIR.getDefaultState());
        this.setBlock(worldIn, i + 7, j + 3, k + 9, Blocks.AIR.getDefaultState());
        this.setBlock(worldIn, i + 7, j + 3, k + 10, Blocks.AIR.getDefaultState());
        this.setBlock(worldIn, i + 7, j + 3, k + 11, Blocks.AIR.getDefaultState());
        this.setBlock(worldIn, i + 7, j + 3, k + 12, JourneyBlocks.cloudiaTile.getDefaultState());
        this.setBlock(worldIn, i + 7, j + 3, k + 13, Blocks.AIR.getDefaultState());
        this.setBlock(worldIn, i + 7, j + 3, k + 14, Blocks.AIR.getDefaultState());
        this.setBlock(worldIn, i + 7, j + 3, k + 15, Blocks.AIR.getDefaultState());
        this.setBlock(worldIn, i + 7, j + 4, k + 0, Blocks.AIR.getDefaultState());
        this.setBlock(worldIn, i + 7, j + 4, k + 1, Blocks.AIR.getDefaultState());
        this.setBlock(worldIn, i + 7, j + 4, k + 2, JourneyBlocks.cloudiaTileStairs.getDefaultState().withProperty(BlockStairs.FACING, EnumFacing.SOUTH));
        this.setBlock(worldIn, i + 7, j + 4, k + 3, JourneyBlocks.cloudiaPlanks.getDefaultState());
        this.setBlock(worldIn, i + 7, j + 4, k + 4, JourneyBlocks.cloudiaPlanks.getDefaultState());
        this.setBlock(worldIn, i + 7, j + 4, k + 5, JourneyBlocks.cloudiaPlanks.getDefaultState());
        this.setBlock(worldIn, i + 7, j + 4, k + 6, JourneyBlocks.cloudiaPlanks.getDefaultState());
        this.setBlock(worldIn, i + 7, j + 4, k + 7, JourneyBlocks.cloudiaPlanks.getDefaultState());
        this.setBlock(worldIn, i + 7, j + 4, k + 8, JourneyBlocks.cloudiaPlanks.getDefaultState());
        this.setBlock(worldIn, i + 7, j + 4, k + 9, JourneyBlocks.cloudiaPlanks.getDefaultState());
        this.setBlock(worldIn, i + 7, j + 4, k + 10, JourneyBlocks.cloudiaPlanks.getDefaultState());
        this.setBlock(worldIn, i + 7, j + 4, k + 11, JourneyBlocks.cloudiaPlanks.getDefaultState());
        this.setBlock(worldIn, i + 7, j + 4, k + 12, JourneyBlocks.cloudiaPlanks.getDefaultState());
        this.setBlock(worldIn, i + 7, j + 4, k + 13, JourneyBlocks.cloudiaTileStairs.getDefaultState().withProperty(BlockStairs.FACING, EnumFacing.NORTH));
        this.setBlock(worldIn, i + 7, j + 4, k + 14, Blocks.AIR.getDefaultState());
        this.setBlock(worldIn, i + 7, j + 4, k + 15, Blocks.AIR.getDefaultState());
        this.setBlock(worldIn, i + 7, j + 5, k + 0, Blocks.AIR.getDefaultState());
        this.setBlock(worldIn, i + 7, j + 5, k + 1, Blocks.AIR.getDefaultState());
        this.setBlock(worldIn, i + 7, j + 5, k + 2, Blocks.AIR.getDefaultState());
        this.setBlock(worldIn, i + 7, j + 5, k + 3, Blocks.AIR.getDefaultState());
        this.setBlock(worldIn, i + 7, j + 5, k + 4, Blocks.AIR.getDefaultState());
        this.setBlock(worldIn, i + 7, j + 5, k + 5, JourneyBlocks.cloudiaTileStairs.getDefaultState().withProperty(BlockStairs.FACING, EnumFacing.SOUTH));
        this.setBlock(worldIn, i + 7, j + 5, k + 6, JourneyBlocks.cloudiaCobblestone.getDefaultState());
        this.setBlock(worldIn, i + 7, j + 5, k + 7, Blocks.AIR.getDefaultState());
        this.setBlock(worldIn, i + 7, j + 5, k + 8, Blocks.AIR.getDefaultState());
        this.setBlock(worldIn, i + 7, j + 5, k + 9, JourneyBlocks.cloudiaCobblestone.getDefaultState());
        this.setBlock(worldIn, i + 7, j + 5, k + 10, JourneyBlocks.cloudiaTileStairs.getDefaultState().withProperty(BlockStairs.FACING, EnumFacing.NORTH));
        this.setBlock(worldIn, i + 7, j + 5, k + 11, Blocks.AIR.getDefaultState());
        this.setBlock(worldIn, i + 7, j + 5, k + 12, Blocks.AIR.getDefaultState());
        this.setBlock(worldIn, i + 7, j + 5, k + 13, Blocks.AIR.getDefaultState());
        this.setBlock(worldIn, i + 7, j + 5, k + 14, Blocks.AIR.getDefaultState());
        this.setBlock(worldIn, i + 7, j + 5, k + 15, Blocks.AIR.getDefaultState());
        this.setBlock(worldIn, i + 7, j + 6, k + 0, Blocks.AIR.getDefaultState());
        this.setBlock(worldIn, i + 7, j + 6, k + 1, Blocks.AIR.getDefaultState());
        this.setBlock(worldIn, i + 7, j + 6, k + 2, Blocks.AIR.getDefaultState());
        this.setBlock(worldIn, i + 7, j + 6, k + 3, Blocks.AIR.getDefaultState());
        this.setBlock(worldIn, i + 7, j + 6, k + 4, Blocks.AIR.getDefaultState());
        this.setBlock(worldIn, i + 7, j + 6, k + 5, Blocks.AIR.getDefaultState());
        this.setBlock(worldIn, i + 7, j + 6, k + 6, JourneyBlocks.cloudiaTile.getDefaultState());
        this.setBlock(worldIn, i + 7, j + 6, k + 7, JourneyBlocks.cloudiaLamp.getDefaultState());
        this.setBlock(worldIn, i + 7, j + 6, k + 8, JourneyBlocks.cloudiaLamp.getDefaultState());
        this.setBlock(worldIn, i + 7, j + 6, k + 9, JourneyBlocks.cloudiaTile.getDefaultState());
        this.setBlock(worldIn, i + 7, j + 6, k + 10, Blocks.AIR.getDefaultState());
        this.setBlock(worldIn, i + 7, j + 6, k + 11, Blocks.AIR.getDefaultState());
        this.setBlock(worldIn, i + 7, j + 6, k + 12, Blocks.AIR.getDefaultState());
        this.setBlock(worldIn, i + 7, j + 6, k + 13, Blocks.AIR.getDefaultState());
        this.setBlock(worldIn, i + 7, j + 6, k + 14, Blocks.AIR.getDefaultState());
        this.setBlock(worldIn, i + 7, j + 6, k + 15, Blocks.AIR.getDefaultState());
        this.setBlock(worldIn, i + 7, j + 7, k + 0, Blocks.AIR.getDefaultState());
        this.setBlock(worldIn, i + 7, j + 7, k + 1, Blocks.AIR.getDefaultState());
        this.setBlock(worldIn, i + 7, j + 7, k + 2, Blocks.AIR.getDefaultState());
        this.setBlock(worldIn, i + 7, j + 7, k + 3, Blocks.AIR.getDefaultState());
        this.setBlock(worldIn, i + 7, j + 7, k + 4, Blocks.AIR.getDefaultState());
        this.setBlock(worldIn, i + 7, j + 7, k + 5, Blocks.AIR.getDefaultState());
        this.setBlock(worldIn, i + 7, j + 7, k + 6, JourneyBlocks.cloudiaBrickStairs.getDefaultState().withProperty(BlockStairs.FACING, EnumFacing.SOUTH));
        this.setBlock(worldIn, i + 7, j + 7, k + 7, Blocks.AIR.getDefaultState());
        this.setBlock(worldIn, i + 7, j + 7, k + 8, Blocks.AIR.getDefaultState());
        this.setBlock(worldIn, i + 7, j + 7, k + 9, JourneyBlocks.cloudiaBrickStairs.getDefaultState().withProperty(BlockStairs.FACING, EnumFacing.NORTH));
        this.setBlock(worldIn, i + 7, j + 10, k + 6, JourneyBlocks.cloudiaTile.getDefaultState());
        this.setBlock(worldIn, i + 7, j + 10, k + 7, Blocks.AIR.getDefaultState());
        this.setBlock(worldIn, i + 7, j + 10, k + 8, Blocks.AIR.getDefaultState());
        this.setBlock(worldIn, i + 7, j + 10, k + 9, JourneyBlocks.cloudiaTile.getDefaultState());
        this.setBlock(worldIn, i + 7, j + 10, k + 10, Blocks.AIR.getDefaultState());
        this.setBlock(worldIn, i + 7, j + 10, k + 11, Blocks.AIR.getDefaultState());
        this.setBlock(worldIn, i + 7, j + 10, k + 12, Blocks.AIR.getDefaultState());
        this.setBlock(worldIn, i + 7, j + 10, k + 13, Blocks.AIR.getDefaultState());
        this.setBlock(worldIn, i + 7, j + 10, k + 14, Blocks.AIR.getDefaultState());
        this.setBlock(worldIn, i + 7, j + 10, k + 15, Blocks.AIR.getDefaultState());
        this.setBlock(worldIn, i + 7, j + 11, k + 0, Blocks.AIR.getDefaultState());
        this.setBlock(worldIn, i + 7, j + 11, k + 1, Blocks.AIR.getDefaultState());
        this.setBlock(worldIn, i + 7, j + 11, k + 2, Blocks.AIR.getDefaultState());
        this.setBlock(worldIn, i + 7, j + 11, k + 3, Blocks.AIR.getDefaultState());
        this.setBlock(worldIn, i + 7, j + 11, k + 4, Blocks.AIR.getDefaultState());
        this.setBlock(worldIn, i + 7, j + 11, k + 5, JourneyBlocks.cloudiaTileStairs.getDefaultState().withProperty(BlockStairs.FACING, EnumFacing.SOUTH));
        this.setBlock(worldIn, i + 7, j + 11, k + 6, JourneyBlocks.cloudiaPlanks.getDefaultState());
        this.setBlock(worldIn, i + 7, j + 11, k + 7, JourneyBlocks.cloudiaPlanks.getDefaultState());
        this.setBlock(worldIn, i + 7, j + 11, k + 8, JourneyBlocks.cloudiaPlanks.getDefaultState());
        this.setBlock(worldIn, i + 7, j + 11, k + 9, JourneyBlocks.cloudiaPlanks.getDefaultState());
        this.setBlock(worldIn, i + 7, j + 11, k + 10, JourneyBlocks.cloudiaTileStairs.getDefaultState().withProperty(BlockStairs.FACING, EnumFacing.NORTH));
        this.setBlock(worldIn, i + 7, j + 11, k + 11, Blocks.AIR.getDefaultState());
        this.setBlock(worldIn, i + 7, j + 11, k + 12, Blocks.AIR.getDefaultState());
        this.setBlock(worldIn, i + 7, j + 11, k + 13, Blocks.AIR.getDefaultState());
        this.setBlock(worldIn, i + 7, j + 11, k + 14, Blocks.AIR.getDefaultState());
        this.setBlock(worldIn, i + 7, j + 11, k + 15, Blocks.AIR.getDefaultState());
        this.setBlock(worldIn, i + 7, j + 12, k + 0, Blocks.AIR.getDefaultState());
        this.setBlock(worldIn, i + 7, j + 12, k + 1, Blocks.AIR.getDefaultState());
        this.setBlock(worldIn, i + 7, j + 12, k + 2, Blocks.AIR.getDefaultState());
        this.setBlock(worldIn, i + 7, j + 12, k + 3, Blocks.AIR.getDefaultState());
        this.setBlock(worldIn, i + 7, j + 12, k + 4, Blocks.AIR.getDefaultState());
        this.setBlock(worldIn, i + 7, j + 12, k + 5, Blocks.AIR.getDefaultState());
        this.setBlock(worldIn, i + 7, j + 12, k + 6, JourneyBlocks.cloudiaTileStairs.getDefaultState().withProperty(BlockStairs.FACING, EnumFacing.SOUTH));
        this.setBlock(worldIn, i + 7, j + 12, k + 7, JourneyBlocks.cloudiaPlanks.getDefaultState());
        this.setBlock(worldIn, i + 7, j + 12, k + 8, JourneyBlocks.cloudiaPlanks.getDefaultState());
        this.setBlock(worldIn, i + 7, j + 12, k + 9, JourneyBlocks.cloudiaTileStairs.getDefaultState().withProperty(BlockStairs.FACING, EnumFacing.NORTH));
        this.setBlock(worldIn, i + 7, j + 13, k + 7, JourneyBlocks.cloudiaTileStairs.getDefaultState().withProperty(BlockStairs.FACING, EnumFacing.EAST));
        this.setBlock(worldIn, i + 7, j + 13, k + 8, JourneyBlocks.cloudiaTileStairs.getDefaultState().withProperty(BlockStairs.FACING, EnumFacing.NORTH));
        this.setBlock(worldIn, i + 7, j + 13, k + 9, Blocks.AIR.getDefaultState());
        this.setBlock(worldIn, i + 7, j + 13, k + 10, Blocks.AIR.getDefaultState());
        this.setBlock(worldIn, i + 7, j + 13, k + 11, Blocks.AIR.getDefaultState());
        this.setBlock(worldIn, i + 7, j + 13, k + 12, Blocks.AIR.getDefaultState());
        this.setBlock(worldIn, i + 7, j + 13, k + 13, Blocks.AIR.getDefaultState());
        this.setBlock(worldIn, i + 7, j + 13, k + 14, Blocks.AIR.getDefaultState());
        this.setBlock(worldIn, i + 7, j + 13, k + 15, Blocks.AIR.getDefaultState());
        this.setBlock(worldIn, i + 8, j + 0, k + 0, JourneyBlocks.cloudiaRock.getDefaultState());
        this.setBlock(worldIn, i + 8, j + 0, k + 1, JourneyBlocks.cloudiaRock.getDefaultState());
        this.setBlock(worldIn, i + 8, j + 0, k + 2, JourneyBlocks.cloudiaRock.getDefaultState());
        this.setBlock(worldIn, i + 8, j + 0, k + 3, JourneyBlocks.cloudiaPlanks.getDefaultState());
        this.setBlock(worldIn, i + 8, j + 0, k + 4, JourneyBlocks.cloudiaPlanks.getDefaultState());
        this.setBlock(worldIn, i + 8, j + 0, k + 5, JourneyBlocks.cloudiaPlanks.getDefaultState());
        this.setBlock(worldIn, i + 8, j + 0, k + 6, JourneyBlocks.cloudiaPlanks.getDefaultState());
        this.setBlock(worldIn, i + 8, j + 0, k + 7, JourneyBlocks.cloudiaCobblestone.getDefaultState());
        this.setBlock(worldIn, i + 8, j + 0, k + 8, JourneyBlocks.cloudiaCobblestone.getDefaultState());
        this.setBlock(worldIn, i + 8, j + 0, k + 9, JourneyBlocks.cloudiaPlanks.getDefaultState());
        this.setBlock(worldIn, i + 8, j + 0, k + 10, JourneyBlocks.cloudiaPlanks.getDefaultState());
        this.setBlock(worldIn, i + 8, j + 0, k + 11, JourneyBlocks.cloudiaPlanks.getDefaultState());
        this.setBlock(worldIn, i + 8, j + 0, k + 12, JourneyBlocks.cloudiaPlanks.getDefaultState());
        this.setBlock(worldIn, i + 8, j + 0, k + 13, JourneyBlocks.cloudiaRock.getDefaultState());
        this.setBlock(worldIn, i + 8, j + 0, k + 14, JourneyBlocks.cloudiaRock.getDefaultState());
        this.setBlock(worldIn, i + 8, j + 0, k + 15, JourneyBlocks.cloudiaRock.getDefaultState());
        this.setBlock(worldIn, i + 8, j + 3, k + 3, JourneyBlocks.cloudiaTile.getDefaultState());
        this.setBlock(worldIn, i + 8, j + 3, k + 4, Blocks.AIR.getDefaultState());
        this.setBlock(worldIn, i + 8, j + 3, k + 5, Blocks.AIR.getDefaultState());
        this.setBlock(worldIn, i + 8, j + 3, k + 6, Blocks.AIR.getDefaultState());
        this.setBlock(worldIn, i + 8, j + 3, k + 7, Blocks.AIR.getDefaultState());
        this.setBlock(worldIn, i + 8, j + 3, k + 8, Blocks.AIR.getDefaultState());
        this.setBlock(worldIn, i + 8, j + 3, k + 9, Blocks.AIR.getDefaultState());
        this.setBlock(worldIn, i + 8, j + 3, k + 10, Blocks.AIR.getDefaultState());
        this.setBlock(worldIn, i + 8, j + 3, k + 11, Blocks.AIR.getDefaultState());
        this.setBlock(worldIn, i + 8, j + 3, k + 12, JourneyBlocks.cloudiaTile.getDefaultState());
        this.setBlock(worldIn, i + 8, j + 3, k + 13, Blocks.AIR.getDefaultState());
        this.setBlock(worldIn, i + 8, j + 3, k + 14, Blocks.AIR.getDefaultState());
        this.setBlock(worldIn, i + 8, j + 3, k + 15, Blocks.AIR.getDefaultState());
        this.setBlock(worldIn, i + 8, j + 4, k + 0, Blocks.AIR.getDefaultState());
        this.setBlock(worldIn, i + 8, j + 4, k + 1, Blocks.AIR.getDefaultState());
        this.setBlock(worldIn, i + 8, j + 4, k + 2, JourneyBlocks.cloudiaTileStairs.getDefaultState().withProperty(BlockStairs.FACING, EnumFacing.SOUTH));
        this.setBlock(worldIn, i + 8, j + 4, k + 3, JourneyBlocks.cloudiaPlanks.getDefaultState());
        this.setBlock(worldIn, i + 8, j + 4, k + 4, JourneyBlocks.cloudiaPlanks.getDefaultState());
        this.setBlock(worldIn, i + 8, j + 4, k + 5, JourneyBlocks.cloudiaPlanks.getDefaultState());
        this.setBlock(worldIn, i + 8, j + 4, k + 6, JourneyBlocks.cloudiaPlanks.getDefaultState());
        this.setBlock(worldIn, i + 8, j + 4, k + 7, JourneyBlocks.cloudiaPlanks.getDefaultState());
        this.setBlock(worldIn, i + 8, j + 4, k + 8, JourneyBlocks.cloudiaPlanks.getDefaultState());
        this.setBlock(worldIn, i + 8, j + 4, k + 9, JourneyBlocks.cloudiaPlanks.getDefaultState());
        this.setBlock(worldIn, i + 8, j + 4, k + 10, JourneyBlocks.cloudiaPlanks.getDefaultState());
        this.setBlock(worldIn, i + 8, j + 4, k + 11, JourneyBlocks.cloudiaPlanks.getDefaultState());
        this.setBlock(worldIn, i + 8, j + 4, k + 12, JourneyBlocks.cloudiaPlanks.getDefaultState());
        this.setBlock(worldIn, i + 8, j + 4, k + 13, JourneyBlocks.cloudiaTileStairs.getDefaultState().withProperty(BlockStairs.FACING, EnumFacing.NORTH));
        this.setBlock(worldIn, i + 8, j + 4, k + 14, Blocks.AIR.getDefaultState());
        this.setBlock(worldIn, i + 8, j + 4, k + 15, Blocks.AIR.getDefaultState());
        this.setBlock(worldIn, i + 8, j + 5, k + 0, Blocks.AIR.getDefaultState());
        this.setBlock(worldIn, i + 8, j + 5, k + 1, Blocks.AIR.getDefaultState());
        this.setBlock(worldIn, i + 8, j + 5, k + 2, Blocks.AIR.getDefaultState());
        this.setBlock(worldIn, i + 8, j + 5, k + 3, Blocks.AIR.getDefaultState());
        this.setBlock(worldIn, i + 8, j + 5, k + 4, Blocks.AIR.getDefaultState());
        this.setBlock(worldIn, i + 8, j + 5, k + 5, JourneyBlocks.cloudiaTileStairs.getDefaultState().withProperty(BlockStairs.FACING, EnumFacing.SOUTH));
        this.setBlock(worldIn, i + 8, j + 5, k + 6, JourneyBlocks.cloudiaCobblestone.getDefaultState());
        this.setBlock(worldIn, i + 8, j + 5, k + 7, Blocks.AIR.getDefaultState());
        this.setBlock(worldIn, i + 8, j + 5, k + 8, Blocks.AIR.getDefaultState());
        this.setBlock(worldIn, i + 8, j + 5, k + 9, JourneyBlocks.cloudiaCobblestone.getDefaultState());
        this.setBlock(worldIn, i + 8, j + 5, k + 10, JourneyBlocks.cloudiaTileStairs.getDefaultState().withProperty(BlockStairs.FACING, EnumFacing.NORTH));
        this.setBlock(worldIn, i + 8, j + 6, k + 6, JourneyBlocks.cloudiaTile.getDefaultState());
        this.setBlock(worldIn, i + 8, j + 6, k + 7, JourneyBlocks.cloudiaLamp.getDefaultState());
        this.setBlock(worldIn, i + 8, j + 6, k + 8, JourneyBlocks.cloudiaLamp.getDefaultState());
        this.setBlock(worldIn, i + 8, j + 6, k + 9, JourneyBlocks.cloudiaTile.getDefaultState());
        this.setBlock(worldIn, i + 8, j + 7, k + 6, JourneyBlocks.cloudiaBrickStairs.getDefaultState().withProperty(BlockStairs.FACING, EnumFacing.SOUTH));
        this.setBlock(worldIn, i + 8, j + 7, k + 7, Blocks.AIR.getDefaultState());
        this.setBlock(worldIn, i + 8, j + 7, k + 8, Blocks.AIR.getDefaultState());
        this.setBlock(worldIn, i + 8, j + 7, k + 9, JourneyBlocks.cloudiaBrickStairs.getDefaultState().withProperty(BlockStairs.FACING, EnumFacing.NORTH));
        this.setBlock(worldIn, i + 8, j + 10, k + 6, JourneyBlocks.cloudiaTile.getDefaultState());
        this.setBlock(worldIn, i + 8, j + 10, k + 7, Blocks.AIR.getDefaultState());
        this.setBlock(worldIn, i + 8, j + 10, k + 8, Blocks.AIR.getDefaultState());
        this.setBlock(worldIn, i + 8, j + 10, k + 9, JourneyBlocks.cloudiaTile.getDefaultState());
        this.setBlock(worldIn, i + 8, j + 10, k + 10, Blocks.AIR.getDefaultState());
        this.setBlock(worldIn, i + 8, j + 10, k + 11, Blocks.AIR.getDefaultState());
        this.setBlock(worldIn, i + 8, j + 10, k + 12, Blocks.AIR.getDefaultState());
        this.setBlock(worldIn, i + 8, j + 10, k + 13, Blocks.AIR.getDefaultState());
        this.setBlock(worldIn, i + 8, j + 10, k + 14, Blocks.AIR.getDefaultState());
        this.setBlock(worldIn, i + 8, j + 10, k + 15, Blocks.AIR.getDefaultState());
        this.setBlock(worldIn, i + 8, j + 11, k + 0, Blocks.AIR.getDefaultState());
        this.setBlock(worldIn, i + 8, j + 11, k + 1, Blocks.AIR.getDefaultState());
        this.setBlock(worldIn, i + 8, j + 11, k + 2, Blocks.AIR.getDefaultState());
        this.setBlock(worldIn, i + 8, j + 11, k + 3, Blocks.AIR.getDefaultState());
        this.setBlock(worldIn, i + 8, j + 11, k + 4, Blocks.AIR.getDefaultState());
        this.setBlock(worldIn, i + 8, j + 11, k + 5, JourneyBlocks.cloudiaTileStairs.getDefaultState().withProperty(BlockStairs.FACING, EnumFacing.SOUTH));
        this.setBlock(worldIn, i + 8, j + 11, k + 6, JourneyBlocks.cloudiaPlanks.getDefaultState());
        this.setBlock(worldIn, i + 8, j + 11, k + 7, JourneyBlocks.cloudiaPlanks.getDefaultState());
        this.setBlock(worldIn, i + 8, j + 11, k + 8, JourneyBlocks.cloudiaPlanks.getDefaultState());
        this.setBlock(worldIn, i + 8, j + 11, k + 9, JourneyBlocks.cloudiaPlanks.getDefaultState());
        this.setBlock(worldIn, i + 8, j + 11, k + 10, JourneyBlocks.cloudiaTileStairs.getDefaultState().withProperty(BlockStairs.FACING, EnumFacing.NORTH));
        this.setBlock(worldIn, i + 8, j + 11, k + 11, Blocks.AIR.getDefaultState());
        this.setBlock(worldIn, i + 8, j + 11, k + 12, Blocks.AIR.getDefaultState());
        this.setBlock(worldIn, i + 8, j + 11, k + 13, Blocks.AIR.getDefaultState());
        this.setBlock(worldIn, i + 8, j + 11, k + 14, Blocks.AIR.getDefaultState());
        this.setBlock(worldIn, i + 8, j + 11, k + 15, Blocks.AIR.getDefaultState());
        this.setBlock(worldIn, i + 8, j + 12, k + 0, Blocks.AIR.getDefaultState());
        this.setBlock(worldIn, i + 8, j + 12, k + 1, Blocks.AIR.getDefaultState());
        this.setBlock(worldIn, i + 8, j + 12, k + 2, Blocks.AIR.getDefaultState());
        this.setBlock(worldIn, i + 8, j + 12, k + 3, Blocks.AIR.getDefaultState());
        this.setBlock(worldIn, i + 8, j + 12, k + 4, Blocks.AIR.getDefaultState());
        this.setBlock(worldIn, i + 8, j + 12, k + 5, Blocks.AIR.getDefaultState());
        this.setBlock(worldIn, i + 8, j + 12, k + 6, JourneyBlocks.cloudiaTileStairs.getDefaultState().withProperty(BlockStairs.FACING, EnumFacing.SOUTH));
        this.setBlock(worldIn, i + 8, j + 12, k + 7, JourneyBlocks.cloudiaPlanks.getDefaultState());
        this.setBlock(worldIn, i + 8, j + 12, k + 8, JourneyBlocks.cloudiaPlanks.getDefaultState());
        this.setBlock(worldIn, i + 8, j + 12, k + 9, JourneyBlocks.cloudiaTileStairs.getDefaultState().withProperty(BlockStairs.FACING, EnumFacing.NORTH));
        this.setBlock(worldIn, i + 8, j + 12, k + 10, Blocks.AIR.getDefaultState());
        this.setBlock(worldIn, i + 8, j + 12, k + 11, Blocks.AIR.getDefaultState());
        this.setBlock(worldIn, i + 8, j + 12, k + 12, Blocks.AIR.getDefaultState());
        this.setBlock(worldIn, i + 8, j + 12, k + 13, Blocks.AIR.getDefaultState());
        this.setBlock(worldIn, i + 8, j + 12, k + 14, Blocks.AIR.getDefaultState());
        this.setBlock(worldIn, i + 8, j + 12, k + 15, Blocks.AIR.getDefaultState());
        this.setBlock(worldIn, i + 8, j + 13, k + 0, Blocks.AIR.getDefaultState());
        this.setBlock(worldIn, i + 8, j + 13, k + 1, Blocks.AIR.getDefaultState());
        this.setBlock(worldIn, i + 8, j + 13, k + 2, Blocks.AIR.getDefaultState());
        this.setBlock(worldIn, i + 8, j + 13, k + 3, Blocks.AIR.getDefaultState());
        this.setBlock(worldIn, i + 8, j + 13, k + 4, Blocks.AIR.getDefaultState());
        this.setBlock(worldIn, i + 8, j + 13, k + 5, Blocks.AIR.getDefaultState());
        this.setBlock(worldIn, i + 8, j + 13, k + 6, Blocks.AIR.getDefaultState());
        this.setBlock(worldIn, i + 8, j + 13, k + 7, JourneyBlocks.cloudiaTileStairs.getDefaultState().withProperty(BlockStairs.FACING, EnumFacing.SOUTH));
        this.setBlock(worldIn, i + 8, j + 13, k + 8, JourneyBlocks.cloudiaTileStairs.getDefaultState().withProperty(BlockStairs.FACING, EnumFacing.WEST));
        this.setBlock(worldIn, i + 8, j + 13, k + 9, Blocks.AIR.getDefaultState());
        this.setBlock(worldIn, i + 8, j + 13, k + 10, Blocks.AIR.getDefaultState());
        this.setBlock(worldIn, i + 8, j + 13, k + 11, Blocks.AIR.getDefaultState());
        this.setBlock(worldIn, i + 8, j + 13, k + 12, Blocks.AIR.getDefaultState());
        this.setBlock(worldIn, i + 8, j + 13, k + 13, Blocks.AIR.getDefaultState());
        this.setBlock(worldIn, i + 8, j + 13, k + 14, Blocks.AIR.getDefaultState());
        this.setBlock(worldIn, i + 8, j + 13, k + 15, Blocks.AIR.getDefaultState());
        this.setBlock(worldIn, i + 9, j + 0, k + 0, JourneyBlocks.cloudiaRock.getDefaultState());
        this.setBlock(worldIn, i + 9, j + 0, k + 1, JourneyBlocks.cloudiaRock.getDefaultState());
        this.setBlock(worldIn, i + 9, j + 0, k + 2, JourneyBlocks.cloudiaRock.getDefaultState());
        this.setBlock(worldIn, i + 9, j + 0, k + 3, JourneyBlocks.cloudiaPlanks.getDefaultState());
        this.setBlock(worldIn, i + 9, j + 0, k + 4, JourneyBlocks.cloudiaPlanks.getDefaultState());
        this.setBlock(worldIn, i + 9, j + 0, k + 5, JourneyBlocks.cloudiaPlanks.getDefaultState());
        this.setBlock(worldIn, i + 9, j + 0, k + 6, JourneyBlocks.cloudiaPlanks.getDefaultState());
        this.setBlock(worldIn, i + 9, j + 0, k + 7, JourneyBlocks.cloudiaPlanks.getDefaultState());
        this.setBlock(worldIn, i + 9, j + 0, k + 8, JourneyBlocks.cloudiaPlanks.getDefaultState());
        this.setBlock(worldIn, i + 9, j + 0, k + 9, JourneyBlocks.cloudiaPlanks.getDefaultState());
        this.setBlock(worldIn, i + 9, j + 0, k + 10, JourneyBlocks.cloudiaPlanks.getDefaultState());
        this.setBlock(worldIn, i + 9, j + 0, k + 11, JourneyBlocks.cloudiaPlanks.getDefaultState());
        this.setBlock(worldIn, i + 9, j + 0, k + 12, JourneyBlocks.cloudiaPlanks.getDefaultState());
        this.setBlock(worldIn, i + 9, j + 0, k + 13, JourneyBlocks.cloudiaRock.getDefaultState());
        this.setBlock(worldIn, i + 9, j + 0, k + 14, JourneyBlocks.cloudiaRock.getDefaultState());
        this.setBlock(worldIn, i + 9, j + 0, k + 15, JourneyBlocks.cloudiaRock.getDefaultState());
        this.setBlock(worldIn, i + 9, j + 1, k + 0, JourneyBlocks.cloudiaTile.getDefaultState());
        this.setBlock(worldIn, i + 9, j + 1, k + 1, Blocks.AIR.getDefaultState());
        this.setBlock(worldIn, i + 9, j + 1, k + 2, Blocks.AIR.getDefaultState());
        this.setBlock(worldIn, i + 9, j + 1, k + 3, JourneyBlocks.cloudiaPillar);
        this.setBlock(worldIn, i + 9, j + 1, k + 4, JourneyBlocks.cloudiaTile.getDefaultState());
        this.setBlock(worldIn, i + 9, j + 1, k + 5, JourneyBlocks.cloudiaTile.getDefaultState());
        this.setBlock(worldIn, i + 9, j + 1, k + 6, Blocks.AIR.getDefaultState());
        this.setBlock(worldIn, i + 9, j + 1, k + 7, Blocks.AIR.getDefaultState());
        this.setBlock(worldIn, i + 9, j + 1, k + 8, Blocks.AIR.getDefaultState());
        this.setBlock(worldIn, i + 9, j + 1, k + 9, Blocks.AIR.getDefaultState());
        this.setBlock(worldIn, i + 9, j + 1, k + 10, JourneyBlocks.cloudiaTile.getDefaultState());
        this.setBlock(worldIn, i + 9, j + 1, k + 11, JourneyBlocks.cloudiaTile.getDefaultState());
        this.setBlock(worldIn, i + 9, j + 1, k + 12, JourneyBlocks.cloudiaPillar);
        this.setBlock(worldIn, i + 9, j + 1, k + 13, Blocks.AIR.getDefaultState());
        this.setBlock(worldIn, i + 9, j + 1, k + 14, Blocks.AIR.getDefaultState());
        this.setBlock(worldIn, i + 9, j + 1, k + 15, JourneyBlocks.cloudiaTile.getDefaultState());
        this.setBlock(worldIn, i + 9, j + 2, k + 0, JourneyBlocks.cloudiaWall.getDefaultState());
        this.setBlock(worldIn, i + 9, j + 2, k + 1, Blocks.AIR.getDefaultState());
        this.setBlock(worldIn, i + 9, j + 2, k + 2, Blocks.AIR.getDefaultState());
        this.setBlock(worldIn, i + 9, j + 2, k + 3, JourneyBlocks.cloudiaPillar);
        this.setBlock(worldIn, i + 9, j + 2, k + 4, JourneyBlocks.cloudiaTile.getDefaultState());
        this.setBlock(worldIn, i + 9, j + 2, k + 5, JourneyBlocks.cloudiaTile.getDefaultState());
        this.setBlock(worldIn, i + 9, j + 2, k + 6, Blocks.AIR.getDefaultState());
        this.setBlock(worldIn, i + 9, j + 2, k + 7, Blocks.AIR.getDefaultState());
        this.setBlock(worldIn, i + 9, j + 2, k + 8, Blocks.AIR.getDefaultState());
        this.setBlock(worldIn, i + 9, j + 2, k + 9, Blocks.AIR.getDefaultState());
        this.setBlock(worldIn, i + 9, j + 2, k + 10, JourneyBlocks.cloudiaTile.getDefaultState());
        this.setBlock(worldIn, i + 9, j + 2, k + 11, JourneyBlocks.cloudiaTile.getDefaultState());
        this.setBlock(worldIn, i + 9, j + 2, k + 12, JourneyBlocks.cloudiaPillar);
        this.setBlock(worldIn, i + 9, j + 2, k + 13, Blocks.AIR.getDefaultState());
        this.setBlock(worldIn, i + 9, j + 2, k + 14, Blocks.AIR.getDefaultState());
        this.setBlock(worldIn, i + 9, j + 2, k + 15, JourneyBlocks.cloudiaWall.getDefaultState());
        this.setBlock(worldIn, i + 9, j + 3, k + 0, JourneyBlocks.cloudiaLamp.getDefaultState());
        this.setBlock(worldIn, i + 9, j + 3, k + 1, Blocks.AIR.getDefaultState());
        this.setBlock(worldIn, i + 9, j + 3, k + 2, Blocks.AIR.getDefaultState());
        this.setBlock(worldIn, i + 9, j + 3, k + 3, JourneyBlocks.cloudiaPillar);
        this.setBlock(worldIn, i + 9, j + 3, k + 4, JourneyBlocks.cloudiaTile.getDefaultState());
        this.setBlock(worldIn, i + 9, j + 3, k + 5, JourneyBlocks.cloudiaTile.getDefaultState());
        this.setBlock(worldIn, i + 9, j + 3, k + 6, Blocks.AIR.getDefaultState());
        this.setBlock(worldIn, i + 9, j + 3, k + 7, Blocks.AIR.getDefaultState());
        this.setBlock(worldIn, i + 9, j + 3, k + 8, Blocks.AIR.getDefaultState());
        this.setBlock(worldIn, i + 9, j + 3, k + 9, Blocks.AIR.getDefaultState());
        this.setBlock(worldIn, i + 9, j + 3, k + 10, JourneyBlocks.cloudiaTile.getDefaultState());
        this.setBlock(worldIn, i + 9, j + 3, k + 11, JourneyBlocks.cloudiaTile.getDefaultState());
        this.setBlock(worldIn, i + 9, j + 3, k + 12, JourneyBlocks.cloudiaPillar);
        this.setBlock(worldIn, i + 9, j + 3, k + 13, Blocks.AIR.getDefaultState());
        this.setBlock(worldIn, i + 9, j + 3, k + 14, Blocks.AIR.getDefaultState());
        this.setBlock(worldIn, i + 9, j + 3, k + 15, JourneyBlocks.cloudiaLamp.getDefaultState());
        this.setBlock(worldIn, i + 9, j + 4, k + 0, Blocks.AIR.getDefaultState());
        this.setBlock(worldIn, i + 9, j + 4, k + 1, Blocks.AIR.getDefaultState());
        this.setBlock(worldIn, i + 9, j + 4, k + 2, JourneyBlocks.cloudiaTileStairs.getDefaultState().withProperty(BlockStairs.FACING, EnumFacing.SOUTH));
        this.setBlock(worldIn, i + 9, j + 4, k + 3, JourneyBlocks.cloudiaPlanks.getDefaultState());
        this.setBlock(worldIn, i + 9, j + 4, k + 4, JourneyBlocks.cloudiaPlanks.getDefaultState());
        this.setBlock(worldIn, i + 9, j + 4, k + 5, JourneyBlocks.cloudiaPlanks.getDefaultState());
        this.setBlock(worldIn, i + 9, j + 4, k + 6, JourneyBlocks.cloudiaPlanks.getDefaultState());
        this.setBlock(worldIn, i + 9, j + 4, k + 7, JourneyBlocks.cloudiaPlanks.getDefaultState());
        this.setBlock(worldIn, i + 9, j + 4, k + 8, JourneyBlocks.cloudiaPlanks.getDefaultState());
        this.setBlock(worldIn, i + 9, j + 4, k + 9, JourneyBlocks.cloudiaPlanks.getDefaultState());
        this.setBlock(worldIn, i + 9, j + 4, k + 10, JourneyBlocks.cloudiaPlanks.getDefaultState());
        this.setBlock(worldIn, i + 9, j + 4, k + 11, JourneyBlocks.cloudiaPlanks.getDefaultState());
        this.setBlock(worldIn, i + 9, j + 4, k + 12, JourneyBlocks.cloudiaPlanks.getDefaultState());
        this.setBlock(worldIn, i + 9, j + 4, k + 13, JourneyBlocks.cloudiaTileStairs.getDefaultState().withProperty(BlockStairs.FACING, EnumFacing.NORTH));
        this.setBlock(worldIn, i + 9, j + 4, k + 14, Blocks.AIR.getDefaultState());
        this.setBlock(worldIn, i + 9, j + 4, k + 15, Blocks.AIR.getDefaultState());
        this.setBlock(worldIn, i + 9, j + 5, k + 0, Blocks.AIR.getDefaultState());
        this.setBlock(worldIn, i + 9, j + 5, k + 1, Blocks.AIR.getDefaultState());
        this.setBlock(worldIn, i + 9, j + 5, k + 2, Blocks.AIR.getDefaultState());
        this.setBlock(worldIn, i + 9, j + 5, k + 3, Blocks.AIR.getDefaultState());
        this.setBlock(worldIn, i + 9, j + 5, k + 4, Blocks.AIR.getDefaultState());
        this.setBlock(worldIn, i + 9, j + 5, k + 5, JourneyBlocks.cloudiaTileStairs.getDefaultState().withProperty(BlockStairs.FACING, EnumFacing.SOUTH));
        this.setBlock(worldIn, i + 9, j + 5, k + 6, JourneyBlocks.cloudiaPillar);
        this.setBlock(worldIn, i + 9, j + 5, k + 7, JourneyBlocks.cloudiaCobblestone.getDefaultState());
        this.setBlock(worldIn, i + 9, j + 5, k + 8, JourneyBlocks.cloudiaCobblestone.getDefaultState());
        this.setBlock(worldIn, i + 9, j + 5, k + 9, JourneyBlocks.cloudiaPillar);
        this.setBlock(worldIn, i + 9, j + 5, k + 10, JourneyBlocks.cloudiaTileStairs.getDefaultState().withProperty(BlockStairs.FACING, EnumFacing.NORTH));
        this.setBlock(worldIn, i + 9, j + 5, k + 11, Blocks.AIR.getDefaultState());
        this.setBlock(worldIn, i + 9, j + 5, k + 12, Blocks.AIR.getDefaultState());
        this.setBlock(worldIn, i + 9, j + 5, k + 13, Blocks.AIR.getDefaultState());
        this.setBlock(worldIn, i + 9, j + 5, k + 14, Blocks.AIR.getDefaultState());
        this.setBlock(worldIn, i + 9, j + 5, k + 15, Blocks.AIR.getDefaultState());
        this.setBlock(worldIn, i + 9, j + 6, k + 0, Blocks.AIR.getDefaultState());
        this.setBlock(worldIn, i + 9, j + 6, k + 1, Blocks.AIR.getDefaultState());
        this.setBlock(worldIn, i + 9, j + 6, k + 2, Blocks.AIR.getDefaultState());
        this.setBlock(worldIn, i + 9, j + 6, k + 3, Blocks.AIR.getDefaultState());
        this.setBlock(worldIn, i + 9, j + 6, k + 4, Blocks.AIR.getDefaultState());
        this.setBlock(worldIn, i + 9, j + 6, k + 5, Blocks.AIR.getDefaultState());
        this.setBlock(worldIn, i + 9, j + 6, k + 6, JourneyBlocks.cloudiaPillar);
        this.setBlock(worldIn, i + 9, j + 6, k + 7, JourneyBlocks.cloudiaTile.getDefaultState());
        this.setBlock(worldIn, i + 9, j + 6, k + 8, JourneyBlocks.cloudiaTile.getDefaultState());
        this.setBlock(worldIn, i + 9, j + 6, k + 9, JourneyBlocks.cloudiaPillar);
        this.setBlock(worldIn, i + 9, j + 6, k + 10, Blocks.AIR.getDefaultState());
        this.setBlock(worldIn, i + 9, j + 6, k + 11, Blocks.AIR.getDefaultState());
        this.setBlock(worldIn, i + 9, j + 6, k + 12, Blocks.AIR.getDefaultState());
        this.setBlock(worldIn, i + 9, j + 6, k + 13, Blocks.AIR.getDefaultState());
        this.setBlock(worldIn, i + 9, j + 6, k + 14, Blocks.AIR.getDefaultState());
        this.setBlock(worldIn, i + 9, j + 6, k + 15, Blocks.AIR.getDefaultState());
        this.setBlock(worldIn, i + 9, j + 7, k + 0, Blocks.AIR.getDefaultState());
        this.setBlock(worldIn, i + 9, j + 7, k + 1, Blocks.AIR.getDefaultState());
        this.setBlock(worldIn, i + 9, j + 7, k + 2, Blocks.AIR.getDefaultState());
        this.setBlock(worldIn, i + 9, j + 7, k + 3, Blocks.AIR.getDefaultState());
        this.setBlock(worldIn, i + 9, j + 7, k + 4, Blocks.AIR.getDefaultState());
        this.setBlock(worldIn, i + 9, j + 7, k + 5, Blocks.AIR.getDefaultState());
        this.setBlock(worldIn, i + 9, j + 7, k + 6, JourneyBlocks.cloudiaPillar);
        this.setBlock(worldIn, i + 9, j + 7, k + 7, JourneyBlocks.cloudiaBrickStairs.getDefaultState().withProperty(BlockStairs.FACING, EnumFacing.WEST));
        this.setBlock(worldIn, i + 9, j + 7, k + 8, JourneyBlocks.cloudiaBrickStairs.getDefaultState().withProperty(BlockStairs.FACING, EnumFacing.WEST));
        this.setBlock(worldIn, i + 9, j + 7, k + 9, JourneyBlocks.cloudiaPillar);
        this.setBlock(worldIn, i + 9, j + 7, k + 10, Blocks.AIR.getDefaultState());
        this.setBlock(worldIn, i + 9, j + 7, k + 11, Blocks.AIR.getDefaultState());
        this.setBlock(worldIn, i + 9, j + 7, k + 12, Blocks.AIR.getDefaultState());
        this.setBlock(worldIn, i + 9, j + 7, k + 13, Blocks.AIR.getDefaultState());
        this.setBlock(worldIn, i + 9, j + 7, k + 14, Blocks.AIR.getDefaultState());
        this.setBlock(worldIn, i + 9, j + 7, k + 15, Blocks.AIR.getDefaultState());
        this.setBlock(worldIn, i + 9, j + 8, k + 0, Blocks.AIR.getDefaultState());
        this.setBlock(worldIn, i + 9, j + 8, k + 1, Blocks.AIR.getDefaultState());
        this.setBlock(worldIn, i + 9, j + 8, k + 2, Blocks.AIR.getDefaultState());
        this.setBlock(worldIn, i + 9, j + 8, k + 3, Blocks.AIR.getDefaultState());
        this.setBlock(worldIn, i + 9, j + 8, k + 4, Blocks.AIR.getDefaultState());
        this.setBlock(worldIn, i + 9, j + 8, k + 5, Blocks.AIR.getDefaultState());
        this.setBlock(worldIn, i + 9, j + 8, k + 6, JourneyBlocks.cloudiaPillar);
        this.setBlock(worldIn, i + 9, j + 8, k + 7, Blocks.AIR.getDefaultState());
        this.setBlock(worldIn, i + 9, j + 8, k + 8, Blocks.AIR.getDefaultState());
        this.setBlock(worldIn, i + 9, j + 8, k + 9, JourneyBlocks.cloudiaPillar);
        this.setBlock(worldIn, i + 9, j + 8, k + 10, Blocks.AIR.getDefaultState());
        this.setBlock(worldIn, i + 9, j + 8, k + 11, Blocks.AIR.getDefaultState());
        this.setBlock(worldIn, i + 9, j + 8, k + 12, Blocks.AIR.getDefaultState());
        this.setBlock(worldIn, i + 9, j + 8, k + 13, Blocks.AIR.getDefaultState());
        this.setBlock(worldIn, i + 9, j + 8, k + 14, Blocks.AIR.getDefaultState());
        this.setBlock(worldIn, i + 9, j + 8, k + 15, Blocks.AIR.getDefaultState());
        this.setBlock(worldIn, i + 9, j + 9, k + 0, Blocks.AIR.getDefaultState());
        this.setBlock(worldIn, i + 9, j + 9, k + 1, Blocks.AIR.getDefaultState());
        this.setBlock(worldIn, i + 9, j + 9, k + 2, Blocks.AIR.getDefaultState());
        this.setBlock(worldIn, i + 9, j + 9, k + 3, Blocks.AIR.getDefaultState());
        this.setBlock(worldIn, i + 9, j + 9, k + 4, Blocks.AIR.getDefaultState());
        this.setBlock(worldIn, i + 9, j + 9, k + 5, Blocks.AIR.getDefaultState());
        this.setBlock(worldIn, i + 9, j + 9, k + 6, JourneyBlocks.cloudiaPillar);
        this.setBlock(worldIn, i + 9, j + 9, k + 7, Blocks.AIR.getDefaultState());
        this.setBlock(worldIn, i + 9, j + 9, k + 8, Blocks.AIR.getDefaultState());
        this.setBlock(worldIn, i + 9, j + 9, k + 9, JourneyBlocks.cloudiaPillar);
        this.setBlock(worldIn, i + 9, j + 9, k + 10, Blocks.AIR.getDefaultState());
        this.setBlock(worldIn, i + 9, j + 9, k + 11, Blocks.AIR.getDefaultState());
        this.setBlock(worldIn, i + 9, j + 9, k + 12, Blocks.AIR.getDefaultState());
        this.setBlock(worldIn, i + 9, j + 9, k + 13, Blocks.AIR.getDefaultState());
        this.setBlock(worldIn, i + 9, j + 9, k + 14, Blocks.AIR.getDefaultState());
        this.setBlock(worldIn, i + 9, j + 9, k + 15, Blocks.AIR.getDefaultState());
        this.setBlock(worldIn, i + 9, j + 10, k + 0, Blocks.AIR.getDefaultState());
        this.setBlock(worldIn, i + 9, j + 10, k + 1, Blocks.AIR.getDefaultState());
        this.setBlock(worldIn, i + 9, j + 10, k + 2, Blocks.AIR.getDefaultState());
        this.setBlock(worldIn, i + 9, j + 10, k + 3, Blocks.AIR.getDefaultState());
        this.setBlock(worldIn, i + 9, j + 10, k + 4, Blocks.AIR.getDefaultState());
        this.setBlock(worldIn, i + 9, j + 10, k + 5, Blocks.AIR.getDefaultState());
        this.setBlock(worldIn, i + 9, j + 10, k + 6, JourneyBlocks.cloudiaPillar);
        this.setBlock(worldIn, i + 9, j + 10, k + 7, JourneyBlocks.cloudiaTile.getDefaultState());
        this.setBlock(worldIn, i + 9, j + 10, k + 8, JourneyBlocks.cloudiaTile.getDefaultState());
        this.setBlock(worldIn, i + 9, j + 10, k + 9, JourneyBlocks.cloudiaPillar);
        this.setBlock(worldIn, i + 9, j + 10, k + 10, Blocks.AIR.getDefaultState());
        this.setBlock(worldIn, i + 9, j + 10, k + 11, Blocks.AIR.getDefaultState());
        this.setBlock(worldIn, i + 9, j + 10, k + 12, Blocks.AIR.getDefaultState());
        this.setBlock(worldIn, i + 9, j + 10, k + 13, Blocks.AIR.getDefaultState());
        this.setBlock(worldIn, i + 9, j + 10, k + 14, Blocks.AIR.getDefaultState());
        this.setBlock(worldIn, i + 9, j + 10, k + 15, Blocks.AIR.getDefaultState());
        this.setBlock(worldIn, i + 9, j + 11, k + 0, Blocks.AIR.getDefaultState());
        this.setBlock(worldIn, i + 9, j + 11, k + 1, Blocks.AIR.getDefaultState());
        this.setBlock(worldIn, i + 9, j + 11, k + 2, Blocks.AIR.getDefaultState());
        this.setBlock(worldIn, i + 9, j + 11, k + 3, Blocks.AIR.getDefaultState());
        this.setBlock(worldIn, i + 9, j + 11, k + 4, Blocks.AIR.getDefaultState());
        this.setBlock(worldIn, i + 9, j + 11, k + 5, JourneyBlocks.cloudiaTileStairs.getDefaultState().withProperty(BlockStairs.FACING, EnumFacing.SOUTH));
        this.setBlock(worldIn, i + 9, j + 11, k + 6, JourneyBlocks.cloudiaPlanks.getDefaultState());
        this.setBlock(worldIn, i + 9, j + 11, k + 7, JourneyBlocks.cloudiaPlanks.getDefaultState());
        this.setBlock(worldIn, i + 9, j + 11, k + 8, JourneyBlocks.cloudiaPlanks.getDefaultState());
        this.setBlock(worldIn, i + 9, j + 11, k + 9, JourneyBlocks.cloudiaPlanks.getDefaultState());
        this.setBlock(worldIn, i + 9, j + 11, k + 10, JourneyBlocks.cloudiaTileStairs.getDefaultState().withProperty(BlockStairs.FACING, EnumFacing.NORTH));
        this.setBlock(worldIn, i + 9, j + 11, k + 11, Blocks.AIR.getDefaultState());
        this.setBlock(worldIn, i + 9, j + 11, k + 12, Blocks.AIR.getDefaultState());
        this.setBlock(worldIn, i + 9, j + 11, k + 13, Blocks.AIR.getDefaultState());
        this.setBlock(worldIn, i + 9, j + 11, k + 14, Blocks.AIR.getDefaultState());
        this.setBlock(worldIn, i + 9, j + 11, k + 15, Blocks.AIR.getDefaultState());
        this.setBlock(worldIn, i + 9, j + 12, k + 0, Blocks.AIR.getDefaultState());
        this.setBlock(worldIn, i + 9, j + 12, k + 1, Blocks.AIR.getDefaultState());
        this.setBlock(worldIn, i + 9, j + 12, k + 2, Blocks.AIR.getDefaultState());
        this.setBlock(worldIn, i + 9, j + 12, k + 3, Blocks.AIR.getDefaultState());
        this.setBlock(worldIn, i + 9, j + 12, k + 4, Blocks.AIR.getDefaultState());
        this.setBlock(worldIn, i + 9, j + 12, k + 5, Blocks.AIR.getDefaultState());
        this.setBlock(worldIn, i + 9, j + 12, k + 6, JourneyBlocks.cloudiaTileStairs.getDefaultState().withProperty(BlockStairs.FACING, EnumFacing.WEST));
        this.setBlock(worldIn, i + 9, j + 12, k + 7, JourneyBlocks.cloudiaTileStairs.getDefaultState().withProperty(BlockStairs.FACING, EnumFacing.WEST));
        this.setBlock(worldIn, i + 9, j + 12, k + 8, JourneyBlocks.cloudiaTileStairs.getDefaultState().withProperty(BlockStairs.FACING, EnumFacing.WEST));
        this.setBlock(worldIn, i + 9, j + 12, k + 9, JourneyBlocks.cloudiaTileStairs.getDefaultState().withProperty(BlockStairs.FACING, EnumFacing.WEST));
        this.setBlock(worldIn, i + 10, j + 0, k + 2, JourneyBlocks.cloudiaRock.getDefaultState());
        this.setBlock(worldIn, i + 10, j + 0, k + 3, JourneyBlocks.cloudiaDirt);
        this.setBlock(worldIn, i + 10, j + 0, k + 4, JourneyBlocks.cloudiaDirt);
        this.setBlock(worldIn, i + 10, j + 0, k + 5, JourneyBlocks.cloudiaDirt);
        this.setBlock(worldIn, i + 10, j + 0, k + 6, JourneyBlocks.cloudiaPlanks.getDefaultState());
        this.setBlock(worldIn, i + 10, j + 0, k + 7, JourneyBlocks.cloudiaPlanks.getDefaultState());
        this.setBlock(worldIn, i + 10, j + 0, k + 8, JourneyBlocks.cloudiaPlanks.getDefaultState());
        this.setBlock(worldIn, i + 10, j + 0, k + 9, JourneyBlocks.cloudiaPlanks.getDefaultState());
        this.setBlock(worldIn, i + 10, j + 0, k + 10, JourneyBlocks.cloudiaDirt);
        this.setBlock(worldIn, i + 10, j + 0, k + 11, JourneyBlocks.cloudiaDirt);
        this.setBlock(worldIn, i + 10, j + 0, k + 12, JourneyBlocks.cloudiaDirt);
        this.setBlock(worldIn, i + 10, j + 0, k + 13, JourneyBlocks.cloudiaRock.getDefaultState());
        this.setBlock(worldIn, i + 10, j + 0, k + 14, Blocks.AIR.getDefaultState());
        this.setBlock(worldIn, i + 10, j + 0, k + 15, Blocks.AIR.getDefaultState());
        this.setBlock(worldIn, i + 10, j + 1, k + 0, Blocks.AIR.getDefaultState());
        this.setBlock(worldIn, i + 10, j + 1, k + 1, Blocks.AIR.getDefaultState());
        this.setBlock(worldIn, i + 10, j + 1, k + 2, Blocks.AIR.getDefaultState());
        this.setBlock(worldIn, i + 10, j + 1, k + 3, JourneyCrops.airRootMelon);
        this.setBlock(worldIn, i + 10, j + 1, k + 4, JourneyCrops.airRootMelon);
        this.setBlock(worldIn, i + 10, j + 1, k + 5, JourneyCrops.airRootMelon);
        this.setBlock(worldIn, i + 10, j + 1, k + 6, JourneyBlocks.cloudiaTile.getDefaultState());
        this.setBlock(worldIn, i + 10, j + 1, k + 7, Blocks.AIR.getDefaultState());
        this.setBlock(worldIn, i + 10, j + 1, k + 8, Blocks.AIR.getDefaultState());
        this.setBlock(worldIn, i + 10, j + 1, k + 9, JourneyBlocks.cloudiaTile.getDefaultState());
        this.setBlock(worldIn, i + 10, j + 1, k + 10, JourneyCrops.airRootMelon);
        this.setBlock(worldIn, i + 10, j + 1, k + 11, JourneyCrops.airRootMelon);
        this.setBlock(worldIn, i + 10, j + 1, k + 12, JourneyCrops.airRootMelon);
        this.setBlock(worldIn, i + 10, j + 2, k + 6, JourneyBlocks.cloudiaTile.getDefaultState());
        this.setBlock(worldIn, i + 10, j + 2, k + 7, Blocks.AIR.getDefaultState());
        this.setBlock(worldIn, i + 10, j + 2, k + 8, Blocks.AIR.getDefaultState());
        this.setBlock(worldIn, i + 10, j + 2, k + 9, JourneyBlocks.cloudiaTile.getDefaultState());
        this.setBlock(worldIn, i + 10, j + 3, k + 6, JourneyBlocks.cloudiaTile.getDefaultState());
        this.setBlock(worldIn, i + 10, j + 3, k + 7, Blocks.AIR.getDefaultState());
        this.setBlock(worldIn, i + 10, j + 3, k + 8, Blocks.AIR.getDefaultState());
        this.setBlock(worldIn, i + 10, j + 3, k + 9, JourneyBlocks.cloudiaTile.getDefaultState());
        this.setBlock(worldIn, i + 10, j + 3, k + 10, Blocks.AIR.getDefaultState());
        this.setBlock(worldIn, i + 10, j + 3, k + 11, Blocks.AIR.getDefaultState());
        this.setBlock(worldIn, i + 10, j + 3, k + 12, Blocks.AIR.getDefaultState());
        this.setBlock(worldIn, i + 10, j + 3, k + 13, Blocks.AIR.getDefaultState());
        this.setBlock(worldIn, i + 10, j + 3, k + 14, Blocks.AIR.getDefaultState());
        this.setBlock(worldIn, i + 10, j + 3, k + 15, Blocks.AIR.getDefaultState());
        this.setBlock(worldIn, i + 10, j + 4, k + 0, Blocks.AIR.getDefaultState());
        this.setBlock(worldIn, i + 10, j + 4, k + 1, Blocks.AIR.getDefaultState());
        this.setBlock(worldIn, i + 10, j + 4, k + 2, JourneyBlocks.cloudiaTileStairs.getDefaultState().withProperty(BlockStairs.FACING, EnumFacing.WEST));
        this.setBlock(worldIn, i + 10, j + 4, k + 3, JourneyBlocks.cloudiaTileStairs.getDefaultState().withProperty(BlockStairs.FACING, EnumFacing.WEST));
        this.setBlock(worldIn, i + 10, j + 4, k + 4, JourneyBlocks.cloudiaTileStairs.getDefaultState().withProperty(BlockStairs.FACING, EnumFacing.WEST));
        this.setBlock(worldIn, i + 10, j + 4, k + 5, JourneyBlocks.cloudiaTileStairs.getDefaultState().withProperty(BlockStairs.FACING, EnumFacing.WEST));
        this.setBlock(worldIn, i + 10, j + 4, k + 6, JourneyBlocks.cloudiaPlanks.getDefaultState());
        this.setBlock(worldIn, i + 10, j + 4, k + 7, JourneyBlocks.cloudiaPlanks.getDefaultState());
        this.setBlock(worldIn, i + 10, j + 4, k + 8, JourneyBlocks.cloudiaPlanks.getDefaultState());
        this.setBlock(worldIn, i + 10, j + 4, k + 9, JourneyBlocks.cloudiaPlanks.getDefaultState());
        this.setBlock(worldIn, i + 10, j + 4, k + 10, JourneyBlocks.cloudiaTileStairs.getDefaultState().withProperty(BlockStairs.FACING, EnumFacing.NORTH));
        this.setBlock(worldIn, i + 10, j + 4, k + 11, JourneyBlocks.cloudiaTileStairs.getDefaultState().withProperty(BlockStairs.FACING, EnumFacing.WEST));
        this.setBlock(worldIn, i + 10, j + 4, k + 12, JourneyBlocks.cloudiaTileStairs.getDefaultState().withProperty(BlockStairs.FACING, EnumFacing.WEST));
        this.setBlock(worldIn, i + 10, j + 4, k + 13, JourneyBlocks.cloudiaTileStairs.getDefaultState().withProperty(BlockStairs.FACING, EnumFacing.WEST));
        this.setBlock(worldIn, i + 10, j + 4, k + 14, Blocks.AIR.getDefaultState());
        this.setBlock(worldIn, i + 10, j + 4, k + 15, Blocks.AIR.getDefaultState());
        this.setBlock(worldIn, i + 10, j + 5, k + 0, Blocks.AIR.getDefaultState());
        this.setBlock(worldIn, i + 10, j + 5, k + 1, Blocks.AIR.getDefaultState());
        this.setBlock(worldIn, i + 10, j + 5, k + 2, Blocks.AIR.getDefaultState());
        this.setBlock(worldIn, i + 10, j + 5, k + 3, Blocks.AIR.getDefaultState());
        this.setBlock(worldIn, i + 10, j + 5, k + 4, Blocks.AIR.getDefaultState());
        this.setBlock(worldIn, i + 10, j + 5, k + 5, JourneyBlocks.cloudiaTileStairs.getDefaultState().withProperty(BlockStairs.FACING, EnumFacing.WEST));
        this.setBlock(worldIn, i + 10, j + 5, k + 6, JourneyBlocks.cloudiaTileStairs.getDefaultState().withProperty(BlockStairs.FACING, EnumFacing.WEST));
        this.setBlock(worldIn, i + 10, j + 5, k + 7, JourneyBlocks.cloudiaCobblestone.getDefaultState());
        this.setBlock(worldIn, i + 10, j + 5, k + 8, JourneyBlocks.cloudiaCobblestone.getDefaultState());
        this.setBlock(worldIn, i + 10, j + 5, k + 9, JourneyBlocks.cloudiaTileStairs.getDefaultState().withProperty(BlockStairs.FACING, EnumFacing.WEST));
        this.setBlock(worldIn, i + 10, j + 5, k + 10, JourneyBlocks.cloudiaTileStairs.getDefaultState().withProperty(BlockStairs.FACING, EnumFacing.NORTH));
        this.setBlock(worldIn, i + 10, j + 5, k + 11, Blocks.AIR.getDefaultState());
        this.setBlock(worldIn, i + 10, j + 5, k + 12, Blocks.AIR.getDefaultState());
        this.setBlock(worldIn, i + 10, j + 5, k + 13, Blocks.AIR.getDefaultState());
        this.setBlock(worldIn, i + 10, j + 5, k + 14, Blocks.AIR.getDefaultState());
        this.setBlock(worldIn, i + 10, j + 5, k + 15, Blocks.AIR.getDefaultState());
        this.setBlock(worldIn, i + 10, j + 6, k + 0, Blocks.AIR.getDefaultState());
        this.setBlock(worldIn, i + 10, j + 6, k + 1, Blocks.AIR.getDefaultState());
        this.setBlock(worldIn, i + 10, j + 6, k + 2, Blocks.AIR.getDefaultState());
        this.setBlock(worldIn, i + 10, j + 6, k + 3, Blocks.AIR.getDefaultState());
        this.setBlock(worldIn, i + 10, j + 6, k + 4, Blocks.AIR.getDefaultState());
        this.setBlock(worldIn, i + 10, j + 6, k + 5, Blocks.AIR.getDefaultState());
        this.setBlock(worldIn, i + 10, j + 6, k + 6, Blocks.AIR.getDefaultState());
        this.setBlock(worldIn, i + 10, j + 6, k + 7, JourneyBlocks.cloudiaTileStairs.getDefaultState().withProperty(BlockStairs.FACING, EnumFacing.SOUTH));
        this.setBlock(worldIn, i + 10, j + 6, k + 8, JourneyBlocks.cloudiaTileStairs.getDefaultState().withProperty(BlockStairs.FACING, EnumFacing.NORTH));
        this.setBlock(worldIn, i + 10, j + 11, k + 5, JourneyBlocks.cloudiaTileStairs.getDefaultState().withProperty(BlockStairs.FACING, EnumFacing.WEST));
        this.setBlock(worldIn, i + 10, j + 11, k + 6, JourneyBlocks.cloudiaTileStairs.getDefaultState().withProperty(BlockStairs.FACING, EnumFacing.WEST));
        this.setBlock(worldIn, i + 10, j + 11, k + 7, JourneyBlocks.cloudiaTileStairs.getDefaultState().withProperty(BlockStairs.FACING, EnumFacing.WEST));
        this.setBlock(worldIn, i + 10, j + 11, k + 8, JourneyBlocks.cloudiaTileStairs.getDefaultState().withProperty(BlockStairs.FACING, EnumFacing.WEST));
        this.setBlock(worldIn, i + 10, j + 11, k + 9, JourneyBlocks.cloudiaTileStairs.getDefaultState().withProperty(BlockStairs.FACING, EnumFacing.WEST));
        this.setBlock(worldIn, i + 10, j + 11, k + 10, JourneyBlocks.cloudiaTileStairs.getDefaultState().withProperty(BlockStairs.FACING, EnumFacing.WEST));
        this.setBlock(worldIn, i + 11, j + 0, k + 2, JourneyBlocks.cloudiaRock.getDefaultState());
        this.setBlock(worldIn, i + 11, j + 0, k + 3, JourneyBlocks.cloudiaDirt);
        //this.setBlock(worldIn, i + 11, j + 0, k + 4, Blocks.WATER.getDefaultState());
        this.setBlock(worldIn, i + 11, j + 0, k + 5, JourneyBlocks.cloudiaDirt);
        this.setBlock(worldIn, i + 11, j + 0, k + 6, JourneyBlocks.cloudiaPlanks.getDefaultState());
        this.setBlock(worldIn, i + 11, j + 0, k + 7, JourneyBlocks.cloudiaPlanks.getDefaultState());
        this.setBlock(worldIn, i + 11, j + 0, k + 8, JourneyBlocks.cloudiaPlanks.getDefaultState());
        this.setBlock(worldIn, i + 11, j + 0, k + 9, JourneyBlocks.cloudiaPlanks.getDefaultState());
        this.setBlock(worldIn, i + 11, j + 0, k + 10, JourneyBlocks.cloudiaDirt);
        //this.setBlock(worldIn, i + 11, j + 0, k + 11, Blocks.WATER.getDefaultState());
        this.setBlock(worldIn, i + 11, j + 0, k + 12, JourneyBlocks.cloudiaDirt);
        this.setBlock(worldIn, i + 11, j + 0, k + 13, JourneyBlocks.cloudiaRock.getDefaultState());
        this.setBlock(worldIn, i + 11, j + 0, k + 14, Blocks.AIR.getDefaultState());
        this.setBlock(worldIn, i + 11, j + 0, k + 15, Blocks.AIR.getDefaultState());
        this.setBlock(worldIn, i + 11, j + 1, k + 0, Blocks.AIR.getDefaultState());
        this.setBlock(worldIn, i + 11, j + 1, k + 1, Blocks.AIR.getDefaultState());
        this.setBlock(worldIn, i + 11, j + 1, k + 2, Blocks.AIR.getDefaultState());
        this.setBlock(worldIn, i + 11, j + 1, k + 3, JourneyCrops.airRootMelon);
        this.setBlock(worldIn, i + 11, j + 1, k + 4, Blocks.AIR.getDefaultState());
        this.setBlock(worldIn, i + 11, j + 1, k + 5, JourneyCrops.airRootMelon);
        this.setBlock(worldIn, i + 11, j + 1, k + 6, JourneyBlocks.cloudiaTile.getDefaultState());
        this.setBlock(worldIn, i + 11, j + 1, k + 7, Blocks.AIR.getDefaultState());
        this.setBlock(worldIn, i + 11, j + 1, k + 8, Blocks.AIR.getDefaultState());
        this.setBlock(worldIn, i + 11, j + 1, k + 9, JourneyBlocks.cloudiaTile.getDefaultState());
        this.setBlock(worldIn, i + 11, j + 1, k + 10, JourneyCrops.airRootMelon);
        this.setBlock(worldIn, i + 11, j + 1, k + 11, Blocks.AIR.getDefaultState());
        this.setBlock(worldIn, i + 11, j + 1, k + 12, JourneyCrops.airRootMelon);
        this.setBlock(worldIn, i + 11, j + 1, k + 13, Blocks.AIR.getDefaultState());
        this.setBlock(worldIn, i + 11, j + 1, k + 14, Blocks.AIR.getDefaultState());
        this.setBlock(worldIn, i + 11, j + 1, k + 15, Blocks.AIR.getDefaultState());
        this.setBlock(worldIn, i + 11, j + 2, k + 0, Blocks.AIR.getDefaultState());
        this.setBlock(worldIn, i + 11, j + 2, k + 1, Blocks.AIR.getDefaultState());
        this.setBlock(worldIn, i + 11, j + 2, k + 2, Blocks.AIR.getDefaultState());
        this.setBlock(worldIn, i + 11, j + 2, k + 3, Blocks.AIR.getDefaultState());
        this.setBlock(worldIn, i + 11, j + 2, k + 4, Blocks.AIR.getDefaultState());
        this.setBlock(worldIn, i + 11, j + 2, k + 5, Blocks.AIR.getDefaultState());
        this.setBlock(worldIn, i + 11, j + 2, k + 6, JourneyBlocks.cloudiaTile.getDefaultState());
        this.setBlock(worldIn, i + 11, j + 2, k + 7, Blocks.AIR.getDefaultState());
        this.setBlock(worldIn, i + 11, j + 2, k + 8, Blocks.AIR.getDefaultState());
        this.setBlock(worldIn, i + 11, j + 2, k + 9, JourneyBlocks.cloudiaTile.getDefaultState());
        this.setBlock(worldIn, i + 11, j + 2, k + 10, Blocks.AIR.getDefaultState());
        this.setBlock(worldIn, i + 11, j + 2, k + 11, Blocks.AIR.getDefaultState());
        this.setBlock(worldIn, i + 11, j + 2, k + 12, Blocks.AIR.getDefaultState());
        this.setBlock(worldIn, i + 11, j + 2, k + 13, Blocks.AIR.getDefaultState());
        this.setBlock(worldIn, i + 11, j + 2, k + 14, Blocks.AIR.getDefaultState());
        this.setBlock(worldIn, i + 11, j + 2, k + 15, Blocks.AIR.getDefaultState());
        this.setBlock(worldIn, i + 11, j + 3, k + 0, Blocks.AIR.getDefaultState());
        this.setBlock(worldIn, i + 11, j + 3, k + 1, Blocks.AIR.getDefaultState());
        this.setBlock(worldIn, i + 11, j + 3, k + 2, Blocks.AIR.getDefaultState());
        this.setBlock(worldIn, i + 11, j + 3, k + 3, Blocks.AIR.getDefaultState());
        this.setBlock(worldIn, i + 11, j + 3, k + 4, Blocks.AIR.getDefaultState());
        this.setBlock(worldIn, i + 11, j + 3, k + 5, Blocks.AIR.getDefaultState());
        this.setBlock(worldIn, i + 11, j + 3, k + 6, JourneyBlocks.cloudiaTile.getDefaultState());
        this.setBlock(worldIn, i + 11, j + 3, k + 7, Blocks.AIR.getDefaultState());
        this.setBlock(worldIn, i + 11, j + 3, k + 8, Blocks.AIR.getDefaultState());
        this.setBlock(worldIn, i + 11, j + 3, k + 9, JourneyBlocks.cloudiaTile.getDefaultState());
        this.setBlock(worldIn, i + 11, j + 3, k + 10, Blocks.AIR.getDefaultState());
        this.setBlock(worldIn, i + 11, j + 3, k + 11, Blocks.AIR.getDefaultState());
        this.setBlock(worldIn, i + 11, j + 3, k + 12, Blocks.AIR.getDefaultState());
        this.setBlock(worldIn, i + 11, j + 3, k + 13, Blocks.AIR.getDefaultState());
        this.setBlock(worldIn, i + 11, j + 3, k + 14, Blocks.AIR.getDefaultState());
        this.setBlock(worldIn, i + 11, j + 3, k + 15, Blocks.AIR.getDefaultState());
        this.setBlock(worldIn, i + 11, j + 4, k + 0, Blocks.AIR.getDefaultState());
        this.setBlock(worldIn, i + 11, j + 4, k + 1, Blocks.AIR.getDefaultState());
        this.setBlock(worldIn, i + 11, j + 4, k + 2, Blocks.AIR.getDefaultState());
        this.setBlock(worldIn, i + 11, j + 4, k + 3, Blocks.AIR.getDefaultState());
        this.setBlock(worldIn, i + 11, j + 4, k + 4, Blocks.AIR.getDefaultState());
        this.setBlock(worldIn, i + 11, j + 4, k + 5, JourneyBlocks.cloudiaTileStairs.getDefaultState().withProperty(BlockStairs.FACING, EnumFacing.SOUTH));
        this.setBlock(worldIn, i + 11, j + 4, k + 6, JourneyBlocks.cloudiaPlanks.getDefaultState());
        this.setBlock(worldIn, i + 11, j + 4, k + 7, JourneyBlocks.cloudiaPlanks.getDefaultState());
        this.setBlock(worldIn, i + 11, j + 4, k + 8, JourneyBlocks.cloudiaPlanks.getDefaultState());
        this.setBlock(worldIn, i + 11, j + 4, k + 9, JourneyBlocks.cloudiaPlanks.getDefaultState());
        this.setBlock(worldIn, i + 11, j + 4, k + 10, JourneyBlocks.cloudiaTileStairs.getDefaultState().withProperty(BlockStairs.FACING, EnumFacing.NORTH));
        this.setBlock(worldIn, i + 11, j + 4, k + 11, Blocks.AIR.getDefaultState());
        this.setBlock(worldIn, i + 11, j + 4, k + 12, Blocks.AIR.getDefaultState());
        this.setBlock(worldIn, i + 11, j + 4, k + 13, Blocks.AIR.getDefaultState());
        this.setBlock(worldIn, i + 11, j + 4, k + 14, Blocks.AIR.getDefaultState());
        this.setBlock(worldIn, i + 11, j + 4, k + 15, Blocks.AIR.getDefaultState());
        this.setBlock(worldIn, i + 11, j + 5, k + 0, Blocks.AIR.getDefaultState());
        this.setBlock(worldIn, i + 11, j + 5, k + 1, Blocks.AIR.getDefaultState());
        this.setBlock(worldIn, i + 11, j + 5, k + 2, Blocks.AIR.getDefaultState());
        this.setBlock(worldIn, i + 11, j + 5, k + 3, Blocks.AIR.getDefaultState());
        this.setBlock(worldIn, i + 11, j + 5, k + 4, Blocks.AIR.getDefaultState());
        this.setBlock(worldIn, i + 11, j + 5, k + 5, Blocks.AIR.getDefaultState());
        this.setBlock(worldIn, i + 11, j + 5, k + 6, JourneyBlocks.cloudiaTileStairs.getDefaultState().withProperty(BlockStairs.FACING, EnumFacing.SOUTH));
        this.setBlock(worldIn, i + 11, j + 5, k + 7, JourneyBlocks.cloudiaCobblestone.getDefaultState());
        this.setBlock(worldIn, i + 11, j + 5, k + 8, JourneyBlocks.cloudiaCobblestone.getDefaultState());
        this.setBlock(worldIn, i + 11, j + 5, k + 9, JourneyBlocks.cloudiaTileStairs.getDefaultState().withProperty(BlockStairs.FACING, EnumFacing.NORTH));
        this.setBlock(worldIn, i + 11, j + 6, k + 7, JourneyBlocks.cloudiaTileStairs.getDefaultState().withProperty(BlockStairs.FACING, EnumFacing.WEST));
        this.setBlock(worldIn, i + 11, j + 6, k + 8, JourneyBlocks.cloudiaTileStairs.getDefaultState().withProperty(BlockStairs.FACING, EnumFacing.NORTH));
        this.setBlock(worldIn, i + 12, j + 0, k + 2, JourneyBlocks.cloudiaRock.getDefaultState());
        this.setBlock(worldIn, i + 12, j + 0, k + 3, JourneyBlocks.cloudiaDirt);
        this.setBlock(worldIn, i + 12, j + 0, k + 4, JourneyBlocks.cloudiaDirt);
        this.setBlock(worldIn, i + 12, j + 0, k + 5, JourneyBlocks.cloudiaDirt);
        this.setBlock(worldIn, i + 12, j + 0, k + 6, JourneyBlocks.cloudiaPlanks.getDefaultState());
        this.setBlock(worldIn, i + 12, j + 0, k + 7, JourneyBlocks.cloudiaPlanks.getDefaultState());
        this.setBlock(worldIn, i + 12, j + 0, k + 8, JourneyBlocks.cloudiaPlanks.getDefaultState());
        this.setBlock(worldIn, i + 12, j + 0, k + 9, JourneyBlocks.cloudiaPlanks.getDefaultState());
        this.setBlock(worldIn, i + 12, j + 0, k + 10, JourneyBlocks.cloudiaDirt);
        this.setBlock(worldIn, i + 12, j + 0, k + 11, JourneyBlocks.cloudiaDirt);
        this.setBlock(worldIn, i + 12, j + 0, k + 12, JourneyBlocks.cloudiaDirt);
        this.setBlock(worldIn, i + 12, j + 0, k + 13, JourneyBlocks.cloudiaRock.getDefaultState());
        this.setBlock(worldIn, i + 12, j + 0, k + 14, Blocks.AIR.getDefaultState());
        this.setBlock(worldIn, i + 12, j + 0, k + 15, Blocks.AIR.getDefaultState());
        this.setBlock(worldIn, i + 12, j + 1, k + 0, Blocks.AIR.getDefaultState());
        this.setBlock(worldIn, i + 12, j + 1, k + 1, Blocks.AIR.getDefaultState());
        this.setBlock(worldIn, i + 12, j + 1, k + 2, Blocks.AIR.getDefaultState());
        this.setBlock(worldIn, i + 12, j + 1, k + 3, JourneyCrops.airRootMelon);
        this.setBlock(worldIn, i + 12, j + 1, k + 4, JourneyCrops.airRootMelon);
        this.setBlock(worldIn, i + 12, j + 1, k + 5, JourneyCrops.airRootMelon);
        this.setBlock(worldIn, i + 12, j + 1, k + 6, JourneyBlocks.cloudiaPillar);
        this.setBlock(worldIn, i + 12, j + 1, k + 7, Blocks.AIR.getDefaultState());
        this.setBlock(worldIn, i + 12, j + 1, k + 8, Blocks.AIR.getDefaultState());
        this.setBlock(worldIn, i + 12, j + 1, k + 9, JourneyBlocks.cloudiaPillar);
        this.setBlock(worldIn, i + 12, j + 1, k + 10, JourneyCrops.airRootMelon);
        this.setBlock(worldIn, i + 12, j + 1, k + 11, JourneyCrops.airRootMelon);
        this.setBlock(worldIn, i + 12, j + 1, k + 12, JourneyCrops.airRootMelon);
        this.setBlock(worldIn, i + 12, j + 2, k + 6, JourneyBlocks.cloudiaPillar);
        this.setBlock(worldIn, i + 12, j + 2, k + 9, JourneyBlocks.cloudiaPillar);
        this.setBlock(worldIn, i + 12, j + 3, k + 6, JourneyBlocks.cloudiaPillar);
        this.setBlock(worldIn, i + 12, j + 3, k + 7, JourneyBlocks.cloudiaTile.getDefaultState());
        this.setBlock(worldIn, i + 12, j + 3, k + 8, JourneyBlocks.cloudiaTile.getDefaultState());
        this.setBlock(worldIn, i + 12, j + 3, k + 9, JourneyBlocks.cloudiaPillar);
        this.setBlock(worldIn, i + 12, j + 4, k + 5, JourneyBlocks.cloudiaTileStairs.getDefaultState().withProperty(BlockStairs.FACING, EnumFacing.SOUTH));
        this.setBlock(worldIn, i + 12, j + 4, k + 6, JourneyBlocks.cloudiaPlanks.getDefaultState());
        this.setBlock(worldIn, i + 12, j + 4, k + 7, JourneyBlocks.cloudiaPlanks.getDefaultState());
        this.setBlock(worldIn, i + 12, j + 4, k + 8, JourneyBlocks.cloudiaPlanks.getDefaultState());
        this.setBlock(worldIn, i + 12, j + 4, k + 9, JourneyBlocks.cloudiaPlanks.getDefaultState());
        this.setBlock(worldIn, i + 12, j + 4, k + 10, JourneyBlocks.cloudiaTileStairs.getDefaultState().withProperty(BlockStairs.FACING, EnumFacing.NORTH));
        this.setBlock(worldIn, i + 12, j + 5, k + 6, JourneyBlocks.cloudiaTileStairs.getDefaultState().withProperty(BlockStairs.FACING, EnumFacing.SOUTH));
        this.setBlock(worldIn, i + 12, j + 5, k + 7, JourneyBlocks.cloudiaTileStairs.getDefaultState().withProperty(BlockStairs.FACING, EnumFacing.WEST));
        this.setBlock(worldIn, i + 12, j + 5, k + 8, JourneyBlocks.cloudiaTileStairs.getDefaultState().withProperty(BlockStairs.FACING, EnumFacing.WEST));
