package net.journey.dimension.corba.village.pieces;

import java.util.List;
import java.util.Random;

import net.journey.dimension.corba.village.StructureCorbaVillagePieces;
import net.journey.init.blocks.JourneyBlocks;
import net.journey.util.RandHelper;
import net.minecraft.block.BlockStairs;
import net.minecraft.block.state.IBlockState;
import net.minecraft.init.Blocks;
import net.minecraft.util.EnumFacing;
import net.minecraft.world.World;
import net.minecraft.world.gen.structure.StructureBoundingBox;
import net.minecraft.world.gen.structure.StructureComponent;

public class CorbaVillageHouse1 extends StructureCorbaVillagePieces.Village {
	
		public CorbaVillageHouse1() {}

		public CorbaVillageHouse1(StructureCorbaVillagePieces.Start start, int type, Random rand, StructureBoundingBox boundingBox, EnumFacing facing) {
			super(start, type);
			this.setCoordBaseMode(facing);
			this.boundingBox = boundingBox;
		}

		public static CorbaVillageHouse1 createPiece(StructureCorbaVillagePieces.Start start, List<StructureComponent> component, Random rand, int x, int y, int z, EnumFacing facing, int var1) {
			StructureBoundingBox structureboundingbox = StructureBoundingBox.getComponentToAddBoundingBox(x, y, z, 0, 0, 0, 16, 16, 16, facing);
			return canVillageGoDeeper(structureboundingbox) && StructureComponent.findIntersecting(component, structureboundingbox) == null ? new CorbaVillageHouse1(start, var1, rand, structureboundingbox, facing) : null;
		}
		
		public IBlockState chooseRandomBrick() {
			return RandHelper.chooseEqual(new Random(), JourneyBlocks.corbaCrackedBricks.getDefaultState(), JourneyBlocks.corbaBricks.getDefaultState(), JourneyBlocks.corbaDarkBricks.getDefaultState(), JourneyBlocks.corbaLightBricks.getDefaultState());
		}
		
		@Override
		public boolean addComponentParts(World worldIn, Random randomIn, StructureBoundingBox structureBoundingBoxIn) {
			EnumFacing south = EnumFacing.SOUTH;
			EnumFacing north = EnumFacing.NORTH;
			
			int i = 0;
			int j = 0;
			int k = 0;
			if (this.averageGroundLvl < 0) {
				this.averageGroundLvl = this.getAverageGroundLevel(worldIn, structureBoundingBoxIn);

				if (this.averageGroundLvl < 0) {
					return true;
				}

				this.boundingBox.offset(0, this.averageGroundLvl - this.boundingBox.maxY + 16 - 1, 0);
			}

			this.setBlockState(worldIn, structureBoundingBoxIn, i + 0, j + 4, k + 0, JourneyBlocks.corbaPlankStairs.getDefaultState().withProperty(BlockStairs.FACING, north));

			this.setBlockState(worldIn, structureBoundingBoxIn, i + 0, j + 4, k + 10, JourneyBlocks.corbaPlankStairs.getDefaultState().withProperty(BlockStairs.FACING, south));
			this.setBlockState(worldIn, structureBoundingBoxIn, i + 0, j + 5, k + 0, Blocks.AIR.getDefaultState());
			this.setBlockState(worldIn, structureBoundingBoxIn, i + 0, j + 5, k + 1, JourneyBlocks.corbaPlankStairs.getDefaultState().withProperty(BlockStairs.FACING, north));

			this.setBlockState(worldIn, structureBoundingBoxIn, i + 0, j + 5, k + 9, JourneyBlocks.corbaPlankStairs.getDefaultState().withProperty(BlockStairs.FACING, south));
			this.setBlockState(worldIn, structureBoundingBoxIn, i + 0, j + 5, k + 10, Blocks.AIR.getDefaultState());
			this.setBlockState(worldIn, structureBoundingBoxIn, i + 0, j + 6, k + 0, Blocks.AIR.getDefaultState());
			this.setBlockState(worldIn, structureBoundingBoxIn, i + 0, j + 6, k + 1, Blocks.AIR.getDefaultState());
			this.setBlockState(worldIn, structureBoundingBoxIn, i + 0, j + 6, k + 2, JourneyBlocks.corbaPlankStairs.getDefaultState().withProperty(BlockStairs.FACING, north));
			this.setBlockState(worldIn, structureBoundingBoxIn, i + 0, j + 6, k + 3, Blocks.AIR.getDefaultState());
			this.setBlockState(worldIn, structureBoundingBoxIn, i + 0, j + 6, k + 4, Blocks.AIR.getDefaultState());
			this.setBlockState(worldIn, structureBoundingBoxIn, i + 0, j + 6, k + 5, Blocks.AIR.getDefaultState());
			this.setBlockState(worldIn, structureBoundingBoxIn, i + 0, j + 6, k + 6, Blocks.AIR.getDefaultState());
			this.setBlockState(worldIn, structureBoundingBoxIn, i + 0, j + 6, k + 7, Blocks.AIR.getDefaultState());
			this.setBlockState(worldIn, structureBoundingBoxIn, i + 0, j + 6, k + 8, JourneyBlocks.corbaPlankStairs.getDefaultState().withProperty(BlockStairs.FACING, south));
			this.setBlockState(worldIn, structureBoundingBoxIn, i + 0, j + 6, k + 9, Blocks.AIR.getDefaultState());
			this.setBlockState(worldIn, structureBoundingBoxIn, i + 0, j + 6, k + 10, Blocks.AIR.getDefaultState());
			this.setBlockState(worldIn, structureBoundingBoxIn, i + 0, j + 7, k + 0, Blocks.AIR.getDefaultState());
			this.setBlockState(worldIn, structureBoundingBoxIn, i + 0, j + 7, k + 1, Blocks.AIR.getDefaultState());
			this.setBlockState(worldIn, structureBoundingBoxIn, i + 0, j + 7, k + 2, Blocks.AIR.getDefaultState());
			this.setBlockState(worldIn, structureBoundingBoxIn, i + 0, j + 7, k + 3, JourneyBlocks.corbaPlankStairs.getDefaultState().withProperty(BlockStairs.FACING, north));
			this.setBlockState(worldIn, structureBoundingBoxIn, i + 0, j + 7, k + 4, Blocks.AIR.getDefaultState());
			this.setBlockState(worldIn, structureBoundingBoxIn, i + 0, j + 7, k + 5, Blocks.AIR.getDefaultState());
			this.setBlockState(worldIn, structureBoundingBoxIn, i + 0, j + 7, k + 6, Blocks.AIR.getDefaultState());
			this.setBlockState(worldIn, structureBoundingBoxIn, i + 0, j + 7, k + 7, JourneyBlocks.corbaPlankStairs.getDefaultState().withProperty(BlockStairs.FACING, south));
			this.setBlockState(worldIn, structureBoundingBoxIn, i + 0, j + 7, k + 8, Blocks.AIR.getDefaultState());
			this.setBlockState(worldIn, structureBoundingBoxIn, i + 0, j + 7, k + 9, Blocks.AIR.getDefaultState());
			this.setBlockState(worldIn, structureBoundingBoxIn, i + 0, j + 7, k + 10, Blocks.AIR.getDefaultState());
			this.setBlockState(worldIn, structureBoundingBoxIn, i + 0, j + 8, k + 0, Blocks.AIR.getDefaultState());
			this.setBlockState(worldIn, structureBoundingBoxIn, i + 0, j + 8, k + 1, Blocks.AIR.getDefaultState());
			this.setBlockState(worldIn, structureBoundingBoxIn, i + 0, j + 8, k + 2, Blocks.AIR.getDefaultState());
			this.setBlockState(worldIn, structureBoundingBoxIn, i + 0, j + 8, k + 3, Blocks.AIR.getDefaultState());
			this.setBlockState(worldIn, structureBoundingBoxIn, i + 0, j + 8, k + 4, JourneyBlocks.corbaPlankStairs.getDefaultState().withProperty(BlockStairs.FACING, north));
			this.setBlockState(worldIn, structureBoundingBoxIn, i + 0, j + 8, k + 5, Blocks.AIR.getDefaultState());
			this.setBlockState(worldIn, structureBoundingBoxIn, i + 0, j + 8, k + 6, JourneyBlocks.corbaPlankStairs.getDefaultState().withProperty(BlockStairs.FACING, south));
			this.setBlockState(worldIn, structureBoundingBoxIn, i + 0, j + 8, k + 7, Blocks.AIR.getDefaultState());
			this.setBlockState(worldIn, structureBoundingBoxIn, i + 0, j + 8, k + 8, Blocks.AIR.getDefaultState());
			this.setBlockState(worldIn, structureBoundingBoxIn, i + 0, j + 8, k + 9, Blocks.AIR.getDefaultState());
			this.setBlockState(worldIn, structureBoundingBoxIn, i + 0, j + 8, k + 10, Blocks.AIR.getDefaultState());
			this.setBlockState(worldIn, structureBoundingBoxIn, i + 0, j + 9, k + 0, Blocks.AIR.getDefaultState());
			this.setBlockState(worldIn, structureBoundingBoxIn, i + 0, j + 9, k + 1, Blocks.AIR.getDefaultState());
			this.setBlockState(worldIn, structureBoundingBoxIn, i + 0, j + 9, k + 2, Blocks.AIR.getDefaultState());
			this.setBlockState(worldIn, structureBoundingBoxIn, i + 0, j + 9, k + 3, Blocks.AIR.getDefaultState());
			this.setBlockState(worldIn, structureBoundingBoxIn, i + 0, j + 9, k + 4, Blocks.AIR.getDefaultState());
			this.setBlockState(worldIn, structureBoundingBoxIn, i + 0, j + 9, k + 5, JourneyBlocks.corbaPlank.getDefaultState());
			this.setBlockState(worldIn, structureBoundingBoxIn, i + 0, j + 9, k + 6, Blocks.AIR.getDefaultState());
			this.setBlockState(worldIn, structureBoundingBoxIn, i + 0, j + 9, k + 7, Blocks.AIR.getDefaultState());
			this.setBlockState(worldIn, structureBoundingBoxIn, i + 0, j + 9, k + 8, Blocks.AIR.getDefaultState());
			this.setBlockState(worldIn, structureBoundingBoxIn, i + 0, j + 9, k + 9, Blocks.AIR.getDefaultState());
			this.setBlockState(worldIn, structureBoundingBoxIn, i + 0, j + 9, k + 10, Blocks.AIR.getDefaultState());
			this.setBlockState(worldIn, structureBoundingBoxIn, i + 1, j + 0, k + 0, JourneyBlocks.corbaCobblestone.getDefaultState());
			this.setBlockState(worldIn, structureBoundingBoxIn, i + 1, j + 0, k + 1, JourneyBlocks.corbaCobblestone.getDefaultState());
			this.setBlockState(worldIn, structureBoundingBoxIn, i + 1, j + 0, k + 2, JourneyBlocks.corbaCobblestone.getDefaultState());
			this.setBlockState(worldIn, structureBoundingBoxIn, i + 1, j + 0, k + 3, JourneyBlocks.corbaCobblestone.getDefaultState());
			this.setBlockState(worldIn, structureBoundingBoxIn, i + 1, j + 0, k + 4, JourneyBlocks.corbaCobblestone.getDefaultState());
			this.setBlockState(worldIn, structureBoundingBoxIn, i + 1, j + 0, k + 5, JourneyBlocks.corbaCobblestone.getDefaultState());
			this.setBlockState(worldIn, structureBoundingBoxIn, i + 1, j + 0, k + 6, JourneyBlocks.corbaCobblestone.getDefaultState());
			this.setBlockState(worldIn, structureBoundingBoxIn, i + 1, j + 0, k + 7, JourneyBlocks.corbaCobblestone.getDefaultState());
			this.setBlockState(worldIn, structureBoundingBoxIn, i + 1, j + 0, k + 8, JourneyBlocks.corbaCobblestone.getDefaultState());
			this.setBlockState(worldIn, structureBoundingBoxIn, i + 1, j + 0, k + 9, JourneyBlocks.corbaCobblestone.getDefaultState());
			this.setBlockState(worldIn, structureBoundingBoxIn, i + 1, j + 0, k + 10, JourneyBlocks.corbaCobblestone.getDefaultState());
			this.setBlockState(worldIn, structureBoundingBoxIn, i + 1, j + 1, k + 0, JourneyBlocks.corbaWall.getDefaultState());
			this.setBlockState(worldIn, structureBoundingBoxIn, i + 1, j + 1, k + 1, JourneyBlocks.corbaWall.getDefaultState());
			this.setBlockState(worldIn, structureBoundingBoxIn, i + 1, j + 1, k + 2, Blocks.AIR.getDefaultState());
			this.setBlockState(worldIn, structureBoundingBoxIn, i + 1, j + 1, k + 3, Blocks.AIR.getDefaultState());
			this.setBlockState(worldIn, structureBoundingBoxIn, i + 1, j + 1, k + 4, Blocks.AIR.getDefaultState());
			this.setBlockState(worldIn, structureBoundingBoxIn, i + 1, j + 1, k + 5, Blocks.AIR.getDefaultState());
			this.setBlockState(worldIn, structureBoundingBoxIn, i + 1, j + 1, k + 6, Blocks.AIR.getDefaultState());
			this.setBlockState(worldIn, structureBoundingBoxIn, i + 1, j + 1, k + 7, Blocks.AIR.getDefaultState());
			this.setBlockState(worldIn, structureBoundingBoxIn, i + 1, j + 1, k + 8, Blocks.AIR.getDefaultState());
			this.setBlockState(worldIn, structureBoundingBoxIn, i + 1, j + 1, k + 9, JourneyBlocks.corbaWall.getDefaultState());
			this.setBlockState(worldIn, structureBoundingBoxIn, i + 1, j + 1, k + 10, JourneyBlocks.corbaWall.getDefaultState());
			this.setBlockState(worldIn, structureBoundingBoxIn, i + 1, j + 2, k + 0, Blocks.AIR.getDefaultState());
			this.setBlockState(worldIn, structureBoundingBoxIn, i + 1, j + 2, k + 1, Blocks.AIR.getDefaultState());
			this.setBlockState(worldIn, structureBoundingBoxIn, i + 1, j + 2, k + 2, Blocks.AIR.getDefaultState());
			this.setBlockState(worldIn, structureBoundingBoxIn, i + 1, j + 2, k + 3, Blocks.AIR.getDefaultState());
			this.setBlockState(worldIn, structureBoundingBoxIn, i + 1, j + 2, k + 4, Blocks.AIR.getDefaultState());
			this.setBlockState(worldIn, structureBoundingBoxIn, i + 1, j + 2, k + 5, Blocks.AIR.getDefaultState());
			this.setBlockState(worldIn, structureBoundingBoxIn, i + 1, j + 2, k + 6, Blocks.AIR.getDefaultState());
			this.setBlockState(worldIn, structureBoundingBoxIn, i + 1, j + 2, k + 7, Blocks.AIR.getDefaultState());
			this.setBlockState(worldIn, structureBoundingBoxIn, i + 1, j + 2, k + 8, Blocks.AIR.getDefaultState());
			this.setBlockState(worldIn, structureBoundingBoxIn, i + 1, j + 2, k + 9, Blocks.AIR.getDefaultState());
			this.setBlockState(worldIn, structureBoundingBoxIn, i + 1, j + 2, k + 10, Blocks.AIR.getDefaultState());
			this.setBlockState(worldIn, structureBoundingBoxIn, i + 1, j + 3, k + 0, Blocks.AIR.getDefaultState());
			this.setBlockState(worldIn, structureBoundingBoxIn, i + 1, j + 3, k + 1, Blocks.AIR.getDefaultState());
			this.setBlockState(worldIn, structureBoundingBoxIn, i + 1, j + 3, k + 2, Blocks.AIR.getDefaultState());
			this.setBlockState(worldIn, structureBoundingBoxIn, i + 1, j + 3, k + 3, Blocks.AIR.getDefaultState());
			this.setBlockState(worldIn, structureBoundingBoxIn, i + 1, j + 3, k + 4, Blocks.AIR.getDefaultState());
			this.setBlockState(worldIn, structureBoundingBoxIn, i + 1, j + 3, k + 5, Blocks.AIR.getDefaultState());
			this.setBlockState(worldIn, structureBoundingBoxIn, i + 1, j + 3, k + 6, Blocks.AIR.getDefaultState());
			this.setBlockState(worldIn, structureBoundingBoxIn, i + 1, j + 3, k + 7, Blocks.AIR.getDefaultState());
			this.setBlockState(worldIn, structureBoundingBoxIn, i + 1, j + 3, k + 8, Blocks.AIR.getDefaultState());
			this.setBlockState(worldIn, structureBoundingBoxIn, i + 1, j + 3, k + 9, Blocks.AIR.getDefaultState());
			this.setBlockState(worldIn, structureBoundingBoxIn, i + 1, j + 3, k + 10, Blocks.AIR.getDefaultState());
			this.setBlockState(worldIn, structureBoundingBoxIn, i + 1, j + 4, k + 0, JourneyBlocks.corbaPlankStairs.getDefaultState().withProperty(BlockStairs.FACING, north));
			this.setBlockState(worldIn, structureBoundingBoxIn, i + 1, j + 4, k + 1, JourneyBlocks.corbaLog.getDefaultState());
			this.setBlockState(worldIn, structureBoundingBoxIn, i + 1, j + 4, k + 2, JourneyBlocks.corbaPlankStairs.getDefaultState().withProperty(BlockStairs.FACING, EnumFacing.EAST));
			this.setBlockState(worldIn, structureBoundingBoxIn, i + 1, j + 4, k + 3, JourneyBlocks.corbaPlankStairs.getDefaultState().withProperty(BlockStairs.FACING, EnumFacing.EAST));
			this.setBlockState(worldIn, structureBoundingBoxIn, i + 1, j + 4, k + 4, JourneyBlocks.corbaPlankStairs.getDefaultState().withProperty(BlockStairs.FACING, EnumFacing.EAST));
			this.setBlockState(worldIn, structureBoundingBoxIn, i + 1, j + 4, k + 5, JourneyBlocks.corbaPlankStairs.getDefaultState().withProperty(BlockStairs.FACING, EnumFacing.EAST));
			this.setBlockState(worldIn, structureBoundingBoxIn, i + 1, j + 4, k + 6, JourneyBlocks.corbaPlankStairs.getDefaultState().withProperty(BlockStairs.FACING, EnumFacing.EAST));
			this.setBlockState(worldIn, structureBoundingBoxIn, i + 1, j + 4, k + 7, JourneyBlocks.corbaPlankStairs.getDefaultState().withProperty(BlockStairs.FACING, EnumFacing.EAST));
			this.setBlockState(worldIn, structureBoundingBoxIn, i + 1, j + 4, k + 8, JourneyBlocks.corbaPlankStairs.getDefaultState().withProperty(BlockStairs.FACING, EnumFacing.EAST));
			this.setBlockState(worldIn, structureBoundingBoxIn, i + 1, j + 4, k + 9, JourneyBlocks.corbaLog.getDefaultState());
			this.setBlockState(worldIn, structureBoundingBoxIn, i + 1, j + 4, k + 10, JourneyBlocks.corbaPlankStairs.getDefaultState().withProperty(BlockStairs.FACING, south));
			this.setBlockState(worldIn, structureBoundingBoxIn, i + 1, j + 5, k + 0, Blocks.AIR.getDefaultState());
			this.setBlockState(worldIn, structureBoundingBoxIn, i + 1, j + 5, k + 1, JourneyBlocks.corbaPlankStairs.getDefaultState().withProperty(BlockStairs.FACING, north));
			this.setBlockState(worldIn, structureBoundingBoxIn, i + 1, j + 5, k + 2, JourneyBlocks.corbaLog.getDefaultState());
			this.setBlockState(worldIn, structureBoundingBoxIn, i + 1, j + 5, k + 3, Blocks.AIR.getDefaultState());
			this.setBlockState(worldIn, structureBoundingBoxIn, i + 1, j + 5, k + 4, Blocks.AIR.getDefaultState());
			this.setBlockState(worldIn, structureBoundingBoxIn, i + 1, j + 5, k + 5, Blocks.AIR.getDefaultState());
			this.setBlockState(worldIn, structureBoundingBoxIn, i + 1, j + 5, k + 6, Blocks.AIR.getDefaultState());
			this.setBlockState(worldIn, structureBoundingBoxIn, i + 1, j + 5, k + 7, Blocks.AIR.getDefaultState());
			this.setBlockState(worldIn, structureBoundingBoxIn, i + 1, j + 5, k + 8, JourneyBlocks.corbaLog.getDefaultState());
			this.setBlockState(worldIn, structureBoundingBoxIn, i + 1, j + 5, k + 9, JourneyBlocks.corbaPlankStairs.getDefaultState().withProperty(BlockStairs.FACING, south));
			this.setBlockState(worldIn, structureBoundingBoxIn, i + 1, j + 5, k + 10, Blocks.AIR.getDefaultState());
			this.setBlockState(worldIn, structureBoundingBoxIn, i + 1, j + 6, k + 0, Blocks.AIR.getDefaultState());
			this.setBlockState(worldIn, structureBoundingBoxIn, i + 1, j + 6, k + 1, Blocks.AIR.getDefaultState());
			this.setBlockState(worldIn, structureBoundingBoxIn, i + 1, j + 6, k + 2, JourneyBlocks.corbaPlankStairs.getDefaultState().withProperty(BlockStairs.FACING, north));
			this.setBlockState(worldIn, structureBoundingBoxIn, i + 1, j + 6, k + 3, JourneyBlocks.corbaLog.getDefaultState());
			this.setBlockState(worldIn, structureBoundingBoxIn, i + 1, j + 6, k + 4, Blocks.AIR.getDefaultState());
			this.setBlockState(worldIn, structureBoundingBoxIn, i + 1, j + 6, k + 5, Blocks.AIR.getDefaultState());
			this.setBlockState(worldIn, structureBoundingBoxIn, i + 1, j + 6, k + 6, Blocks.AIR.getDefaultState());
			this.setBlockState(worldIn, structureBoundingBoxIn, i + 1, j + 6, k + 7, JourneyBlocks.corbaLog.getDefaultState());
			this.setBlockState(worldIn, structureBoundingBoxIn, i + 1, j + 6, k + 8, JourneyBlocks.corbaPlankStairs.getDefaultState().withProperty(BlockStairs.FACING, south));
			this.setBlockState(worldIn, structureBoundingBoxIn, i + 1, j + 6, k + 9, Blocks.AIR.getDefaultState());
			this.setBlockState(worldIn, structureBoundingBoxIn, i + 1, j + 6, k + 10, Blocks.AIR.getDefaultState());
			this.setBlockState(worldIn, structureBoundingBoxIn, i + 1, j + 7, k + 0, Blocks.AIR.getDefaultState());
			this.setBlockState(worldIn, structureBoundingBoxIn, i + 1, j + 7, k + 1, Blocks.AIR.getDefaultState());
			this.setBlockState(worldIn, structureBoundingBoxIn, i + 1, j + 7, k + 2, Blocks.AIR.getDefaultState());
			this.setBlockState(worldIn, structureBoundingBoxIn, i + 1, j + 7, k + 3, JourneyBlocks.corbaPlankStairs.getDefaultState().withProperty(BlockStairs.FACING, north));
			this.setBlockState(worldIn, structureBoundingBoxIn, i + 1, j + 7, k + 4, JourneyBlocks.corbaLog.getDefaultState());
			this.setBlockState(worldIn, structureBoundingBoxIn, i + 1, j + 7, k + 5, Blocks.AIR.getDefaultState());
			this.setBlockState(worldIn, structureBoundingBoxIn, i + 1, j + 7, k + 6, JourneyBlocks.corbaLog.getDefaultState());
			this.setBlockState(worldIn, structureBoundingBoxIn, i + 1, j + 7, k + 7, JourneyBlocks.corbaPlankStairs.getDefaultState().withProperty(BlockStairs.FACING, south));
			this.setBlockState(worldIn, structureBoundingBoxIn, i + 1, j + 7, k + 8, Blocks.AIR.getDefaultState());
			this.setBlockState(worldIn, structureBoundingBoxIn, i + 1, j + 7, k + 9, Blocks.AIR.getDefaultState());
			this.setBlockState(worldIn, structureBoundingBoxIn, i + 1, j + 7, k + 10, Blocks.AIR.getDefaultState());
			this.setBlockState(worldIn, structureBoundingBoxIn, i + 1, j + 8, k + 0, Blocks.AIR.getDefaultState());
			this.setBlockState(worldIn, structureBoundingBoxIn, i + 1, j + 8, k + 1, Blocks.AIR.getDefaultState());
			this.setBlockState(worldIn, structureBoundingBoxIn, i + 1, j + 8, k + 2, Blocks.AIR.getDefaultState());
			this.setBlockState(worldIn, structureBoundingBoxIn, i + 1, j + 8, k + 3, Blocks.AIR.getDefaultState());
			this.setBlockState(worldIn, structureBoundingBoxIn, i + 1, j + 8, k + 4, JourneyBlocks.corbaPlankStairs.getDefaultState().withProperty(BlockStairs.FACING, north));
			this.setBlockState(worldIn, structureBoundingBoxIn, i + 1, j + 8, k + 5, JourneyBlocks.corbaLog.getDefaultState());
			this.setBlockState(worldIn, structureBoundingBoxIn, i + 1, j + 8, k + 6, JourneyBlocks.corbaPlankStairs.getDefaultState().withProperty(BlockStairs.FACING, south));
			this.setBlockState(worldIn, structureBoundingBoxIn, i + 1, j + 8, k + 7, Blocks.AIR.getDefaultState());
			this.setBlockState(worldIn, structureBoundingBoxIn, i + 1, j + 8, k + 8, Blocks.AIR.getDefaultState());
			this.setBlockState(worldIn, structureBoundingBoxIn, i + 1, j + 8, k + 9, Blocks.AIR.getDefaultState());
			this.setBlockState(worldIn, structureBoundingBoxIn, i + 1, j + 8, k + 10, Blocks.AIR.getDefaultState());
			this.setBlockState(worldIn, structureBoundingBoxIn, i + 1, j + 9, k + 0, Blocks.AIR.getDefaultState());
			this.setBlockState(worldIn, structureBoundingBoxIn, i + 1, j + 9, k + 1, Blocks.AIR.getDefaultState());
			this.setBlockState(worldIn, structureBoundingBoxIn, i + 1, j + 9, k + 2, Blocks.AIR.getDefaultState());
			this.setBlockState(worldIn, structureBoundingBoxIn, i + 1, j + 9, k + 3, Blocks.AIR.getDefaultState());
			this.setBlockState(worldIn, structureBoundingBoxIn, i + 1, j + 9, k + 4, Blocks.AIR.getDefaultState());
			this.setBlockState(worldIn, structureBoundingBoxIn, i + 1, j + 9, k + 5, JourneyBlocks.corbaPlank.getDefaultState());
			this.setBlockState(worldIn, structureBoundingBoxIn, i + 1, j + 9, k + 6, Blocks.AIR.getDefaultState());
			this.setBlockState(worldIn, structureBoundingBoxIn, i + 1, j + 9, k + 7, Blocks.AIR.getDefaultState());
			this.setBlockState(worldIn, structureBoundingBoxIn, i + 1, j + 9, k + 8, Blocks.AIR.getDefaultState());
			this.setBlockState(worldIn, structureBoundingBoxIn, i + 1, j + 9, k + 9, Blocks.AIR.getDefaultState());
			this.setBlockState(worldIn, structureBoundingBoxIn, i + 1, j + 9, k + 10, Blocks.AIR.getDefaultState());
			this.setBlockState(worldIn, structureBoundingBoxIn, i + 2, j + 0, k + 0, JourneyBlocks.corbaCobblestone.getDefaultState());
			this.setBlockState(worldIn, structureBoundingBoxIn, i + 2, j + 0, k + 1, JourneyBlocks.corbaCobblestone.getDefaultState());
			this.setBlockState(worldIn, structureBoundingBoxIn, i + 2, j + 0, k + 2, JourneyBlocks.corbaCobblestone.getDefaultState());
			this.setBlockState(worldIn, structureBoundingBoxIn, i + 2, j + 0, k + 3, JourneyBlocks.corbaCobblestone.getDefaultState());
			this.setBlockState(worldIn, structureBoundingBoxIn, i + 2, j + 0, k + 4, JourneyBlocks.corbaCobblestone.getDefaultState());
			this.setBlockState(worldIn, structureBoundingBoxIn, i + 2, j + 0, k + 5, JourneyBlocks.corbaCobblestone.getDefaultState());
			this.setBlockState(worldIn, structureBoundingBoxIn, i + 2, j + 0, k + 6, JourneyBlocks.corbaCobblestone.getDefaultState());
			this.setBlockState(worldIn, structureBoundingBoxIn, i + 2, j + 0, k + 7, JourneyBlocks.corbaCobblestone.getDefaultState());
			this.setBlockState(worldIn, structureBoundingBoxIn, i + 2, j + 0, k + 8, JourneyBlocks.corbaCobblestone.getDefaultState());
			this.setBlockState(worldIn, structureBoundingBoxIn, i + 2, j + 0, k + 9, JourneyBlocks.corbaCobblestone.getDefaultState());
			this.setBlockState(worldIn, structureBoundingBoxIn, i + 2, j + 0, k + 10, JourneyBlocks.corbaCobblestone.getDefaultState());
			this.setBlockState(worldIn, structureBoundingBoxIn, i + 2, j + 1, k + 0, JourneyBlocks.corbaWall.getDefaultState());
			this.setBlockState(worldIn, structureBoundingBoxIn, i + 2, j + 1, k + 1, JourneyBlocks.corbaLog.getDefaultState());
			this.setBlockState(worldIn, structureBoundingBoxIn, i + 2, j + 1, k + 2, JourneyBlocks.corbaPost.getDefaultState());
			this.setBlockState(worldIn, structureBoundingBoxIn, i + 2, j + 1, k + 3, JourneyBlocks.corbaPost.getDefaultState());
			this.setBlockState(worldIn, structureBoundingBoxIn, i + 2, j + 1, k + 4, JourneyBlocks.corbaPlank.getDefaultState());
			this.setBlockState(worldIn, structureBoundingBoxIn, i + 2, j + 1, k + 5, JourneyBlocks.corbaPost.getDefaultState());
			this.setBlockState(worldIn, structureBoundingBoxIn, i + 2, j + 1, k + 6, JourneyBlocks.corbaPlank.getDefaultState());
			this.setBlockState(worldIn, structureBoundingBoxIn, i + 2, j + 1, k + 7, JourneyBlocks.corbaPost.getDefaultState());
			this.setBlockState(worldIn, structureBoundingBoxIn, i + 2, j + 1, k + 8, JourneyBlocks.corbaPost.getDefaultState());
			this.setBlockState(worldIn, structureBoundingBoxIn, i + 2, j + 1, k + 9, JourneyBlocks.corbaLog.getDefaultState());
			this.setBlockState(worldIn, structureBoundingBoxIn, i + 2, j + 1, k + 10, JourneyBlocks.corbaWall.getDefaultState());
			this.setBlockState(worldIn, structureBoundingBoxIn, i + 2, j + 2, k + 0, Blocks.AIR.getDefaultState());
			this.setBlockState(worldIn, structureBoundingBoxIn, i + 2, j + 2, k + 1, JourneyBlocks.corbaLog.getDefaultState());
			this.setBlockState(worldIn, structureBoundingBoxIn, i + 2, j + 2, k + 2, JourneyBlocks.corbaPost.getDefaultState());
			this.setBlockState(worldIn, structureBoundingBoxIn, i + 2, j + 2, k + 3, JourneyBlocks.corbaPost.getDefaultState());
			this.setBlockState(worldIn, structureBoundingBoxIn, i + 2, j + 2, k + 4, JourneyBlocks.corbaPlank.getDefaultState());
			this.setBlockState(worldIn, structureBoundingBoxIn, i + 2, j + 2, k + 5, JourneyBlocks.corbaPost.getDefaultState());
			this.setBlockState(worldIn, structureBoundingBoxIn, i + 2, j + 2, k + 6, JourneyBlocks.corbaPlank.getDefaultState());
			this.setBlockState(worldIn, structureBoundingBoxIn, i + 2, j + 2, k + 7, JourneyBlocks.corbaPost.getDefaultState());
			this.setBlockState(worldIn, structureBoundingBoxIn, i + 2, j + 2, k + 8, JourneyBlocks.corbaPost.getDefaultState());
			this.setBlockState(worldIn, structureBoundingBoxIn, i + 2, j + 2, k + 9, JourneyBlocks.corbaLog.getDefaultState());
			this.setBlockState(worldIn, structureBoundingBoxIn, i + 2, j + 2, k + 10, Blocks.AIR.getDefaultState());
			this.setBlockState(worldIn, structureBoundingBoxIn, i + 2, j + 3, k + 0, Blocks.AIR.getDefaultState());
			this.setBlockState(worldIn, structureBoundingBoxIn, i + 2, j + 3, k + 1, JourneyBlocks.corbaLog.getDefaultState());
			this.setBlockState(worldIn, structureBoundingBoxIn, i + 2, j + 3, k + 2, JourneyBlocks.corbaPost.getDefaultState());
			this.setBlockState(worldIn, structureBoundingBoxIn, i + 2, j + 3, k + 3, JourneyBlocks.corbaPost.getDefaultState());
			this.setBlockState(worldIn, structureBoundingBoxIn, i + 2, j + 3, k + 4, JourneyBlocks.corbaPlank.getDefaultState());
			this.setBlockState(worldIn, structureBoundingBoxIn, i + 2, j + 3, k + 5, JourneyBlocks.corbaPost.getDefaultState());
			this.setBlockState(worldIn, structureBoundingBoxIn, i + 2, j + 3, k + 6, JourneyBlocks.corbaPlank.getDefaultState());
			this.setBlockState(worldIn, structureBoundingBoxIn, i + 2, j + 3, k + 7, JourneyBlocks.corbaPost.getDefaultState());
			this.setBlockState(worldIn, structureBoundingBoxIn, i + 2, j + 3, k + 8, JourneyBlocks.corbaPost.getDefaultState());
			this.setBlockState(worldIn, structureBoundingBoxIn, i + 2, j + 3, k + 9, JourneyBlocks.corbaLog.getDefaultState());
			this.setBlockState(worldIn, structureBoundingBoxIn, i + 2, j + 3, k + 10, Blocks.AIR.getDefaultState());
			this.setBlockState(worldIn, structureBoundingBoxIn, i + 2, j + 4, k + 0, JourneyBlocks.corbaPlankStairs.getDefaultState().withProperty(BlockStairs.FACING, north));
			this.setBlockState(worldIn, structureBoundingBoxIn, i + 2, j + 4, k + 1, JourneyBlocks.corbaLog.getDefaultState());
			this.setBlockState(worldIn, structureBoundingBoxIn, i + 2, j + 4, k + 2, JourneyBlocks.corbaPlank.getDefaultState());
			this.setBlockState(worldIn, structureBoundingBoxIn, i + 2, j + 4, k + 3, JourneyBlocks.corbaPlank.getDefaultState());
			this.setBlockState(worldIn, structureBoundingBoxIn, i + 2, j + 4, k + 4, JourneyBlocks.corbaPlank.getDefaultState());
			this.setBlockState(worldIn, structureBoundingBoxIn, i + 2, j + 4, k + 5, JourneyBlocks.corbaPlank.getDefaultState());
			this.setBlockState(worldIn, structureBoundingBoxIn, i + 2, j + 4, k + 6, JourneyBlocks.corbaPlank.getDefaultState());
			this.setBlockState(worldIn, structureBoundingBoxIn, i + 2, j + 4, k + 7, JourneyBlocks.corbaPlank.getDefaultState());
			this.setBlockState(worldIn, structureBoundingBoxIn, i + 2, j + 4, k + 8, JourneyBlocks.corbaPlank.getDefaultState());
			this.setBlockState(worldIn, structureBoundingBoxIn, i + 2, j + 4, k + 9, JourneyBlocks.corbaLog.getDefaultState());
			this.setBlockState(worldIn, structureBoundingBoxIn, i + 2, j + 4, k + 10, JourneyBlocks.corbaPlankStairs.getDefaultState().withProperty(BlockStairs.FACING, south));
			this.setBlockState(worldIn, structureBoundingBoxIn, i + 2, j + 5, k + 0, Blocks.AIR.getDefaultState());
			this.setBlockState(worldIn, structureBoundingBoxIn, i + 2, j + 5, k + 1, JourneyBlocks.corbaPlankStairs.getDefaultState().withProperty(BlockStairs.FACING, north));
			this.setBlockState(worldIn, structureBoundingBoxIn, i + 2, j + 5, k + 2, JourneyBlocks.corbaLog.getDefaultState());
			this.setBlockState(worldIn, structureBoundingBoxIn, i + 2, j + 5, k + 3, JourneyBlocks.corbaPost.getDefaultState());
			this.setBlockState(worldIn, structureBoundingBoxIn, i + 2, j + 5, k + 4, JourneyBlocks.corbaPlank.getDefaultState());
			this.setBlockState(worldIn, structureBoundingBoxIn, i + 2, j + 5, k + 5, JourneyBlocks.corbaPost.getDefaultState());
			this.setBlockState(worldIn, structureBoundingBoxIn, i + 2, j + 5, k + 6, JourneyBlocks.corbaPlank.getDefaultState());
			this.setBlockState(worldIn, structureBoundingBoxIn, i + 2, j + 5, k + 7, JourneyBlocks.corbaPost.getDefaultState());
			this.setBlockState(worldIn, structureBoundingBoxIn, i + 2, j + 5, k + 8, JourneyBlocks.corbaLog.getDefaultState());
			this.setBlockState(worldIn, structureBoundingBoxIn, i + 2, j + 5, k + 9, JourneyBlocks.corbaPlankStairs.getDefaultState().withProperty(BlockStairs.FACING, south));
			this.setBlockState(worldIn, structureBoundingBoxIn, i + 2, j + 5, k + 10, Blocks.AIR.getDefaultState());
			this.setBlockState(worldIn, structureBoundingBoxIn, i + 2, j + 6, k + 0, Blocks.AIR.getDefaultState());
			this.setBlockState(worldIn, structureBoundingBoxIn, i + 2, j + 6, k + 1, Blocks.AIR.getDefaultState());
			this.setBlockState(worldIn, structureBoundingBoxIn, i + 2, j + 6, k + 2, JourneyBlocks.corbaPlankStairs.getDefaultState().withProperty(BlockStairs.FACING, north));
			this.setBlockState(worldIn, structureBoundingBoxIn, i + 2, j + 6, k + 3, JourneyBlocks.corbaLog.getDefaultState());
			this.setBlockState(worldIn, structureBoundingBoxIn, i + 2, j + 6, k + 4, JourneyBlocks.corbaPlank.getDefaultState());
			this.setBlockState(worldIn, structureBoundingBoxIn, i + 2, j + 6, k + 5, JourneyBlocks.corbaPost.getDefaultState());
			this.setBlockState(worldIn, structureBoundingBoxIn, i + 2, j + 6, k + 6, JourneyBlocks.corbaPlank.getDefaultState());
			this.setBlockState(worldIn, structureBoundingBoxIn, i + 2, j + 6, k + 7, JourneyBlocks.corbaLog.getDefaultState());
			this.setBlockState(worldIn, structureBoundingBoxIn, i + 2, j + 6, k + 8, JourneyBlocks.corbaPlankStairs.getDefaultState().withProperty(BlockStairs.FACING, south));
			this.setBlockState(worldIn, structureBoundingBoxIn, i + 2, j + 6, k + 9, Blocks.AIR.getDefaultState());
			this.setBlockState(worldIn, structureBoundingBoxIn, i + 2, j + 6, k + 10, Blocks.AIR.getDefaultState());
			this.setBlockState(worldIn, structureBoundingBoxIn, i + 2, j + 7, k + 0, Blocks.AIR.getDefaultState());
			this.setBlockState(worldIn, structureBoundingBoxIn, i + 2, j + 7, k + 1, Blocks.AIR.getDefaultState());
			this.setBlockState(worldIn, structureBoundingBoxIn, i + 2, j + 7, k + 2, Blocks.AIR.getDefaultState());
			this.setBlockState(worldIn, structureBoundingBoxIn, i + 2, j + 7, k + 3, JourneyBlocks.corbaPlankStairs.getDefaultState().withProperty(BlockStairs.FACING, north));
			this.setBlockState(worldIn, structureBoundingBoxIn, i + 2, j + 7, k + 4, JourneyBlocks.corbaLog.getDefaultState());
			this.setBlockState(worldIn, structureBoundingBoxIn, i + 2, j + 7, k + 5, JourneyBlocks.corbaPost.getDefaultState());
			this.setBlockState(worldIn, structureBoundingBoxIn, i + 2, j + 7, k + 6, JourneyBlocks.corbaLog.getDefaultState());
			this.setBlockState(worldIn, structureBoundingBoxIn, i + 2, j + 7, k + 7, JourneyBlocks.corbaPlankStairs.getDefaultState().withProperty(BlockStairs.FACING, south));
			this.setBlockState(worldIn, structureBoundingBoxIn, i + 2, j + 7, k + 8, Blocks.AIR.getDefaultState());
			this.setBlockState(worldIn, structureBoundingBoxIn, i + 2, j + 7, k + 9, Blocks.AIR.getDefaultState());
			this.setBlockState(worldIn, structureBoundingBoxIn, i + 2, j + 7, k + 10, Blocks.AIR.getDefaultState());
			this.setBlockState(worldIn, structureBoundingBoxIn, i + 2, j + 8, k + 0, Blocks.AIR.getDefaultState());
			this.setBlockState(worldIn, structureBoundingBoxIn, i + 2, j + 8, k + 1, Blocks.AIR.getDefaultState());
			this.setBlockState(worldIn, structureBoundingBoxIn, i + 2, j + 8, k + 2, Blocks.AIR.getDefaultState());
			this.setBlockState(worldIn, structureBoundingBoxIn, i + 2, j + 8, k + 3, Blocks.AIR.getDefaultState());
			this.setBlockState(worldIn, structureBoundingBoxIn, i + 2, j + 8, k + 4, JourneyBlocks.corbaPlankStairs.getDefaultState().withProperty(BlockStairs.FACING, north));
			this.setBlockState(worldIn, structureBoundingBoxIn, i + 2, j + 8, k + 5, JourneyBlocks.corbaLog.getDefaultState());
			this.setBlockState(worldIn, structureBoundingBoxIn, i + 2, j + 8, k + 6, JourneyBlocks.corbaPlankStairs.getDefaultState().withProperty(BlockStairs.FACING, south));
			this.setBlockState(worldIn, structureBoundingBoxIn, i + 2, j + 8, k + 7, Blocks.AIR.getDefaultState());
			this.setBlockState(worldIn, structureBoundingBoxIn, i + 2, j + 8, k + 8, Blocks.AIR.getDefaultState());
			this.setBlockState(worldIn, structureBoundingBoxIn, i + 2, j + 8, k + 9, Blocks.AIR.getDefaultState());
			this.setBlockState(worldIn, structureBoundingBoxIn, i + 2, j + 8, k + 10, Blocks.AIR.getDefaultState());
			this.setBlockState(worldIn, structureBoundingBoxIn, i + 2, j + 9, k + 0, Blocks.AIR.getDefaultState());
			this.setBlockState(worldIn, structureBoundingBoxIn, i + 2, j + 9, k + 1, Blocks.AIR.getDefaultState());
			this.setBlockState(worldIn, structureBoundingBoxIn, i + 2, j + 9, k + 2, Blocks.AIR.getDefaultState());
			this.setBlockState(worldIn, structureBoundingBoxIn, i + 2, j + 9, k + 3, Blocks.AIR.getDefaultState());
			this.setBlockState(worldIn, structureBoundingBoxIn, i + 2, j + 9, k + 4, Blocks.AIR.getDefaultState());
			this.setBlockState(worldIn, structureBoundingBoxIn, i + 2, j + 9, k + 5, JourneyBlocks.corbaPlank.getDefaultState());
			this.setBlockState(worldIn, structureBoundingBoxIn, i + 2, j + 9, k + 6, Blocks.AIR.getDefaultState());
			this.setBlockState(worldIn, structureBoundingBoxIn, i + 2, j + 9, k + 7, Blocks.AIR.getDefaultState());
			this.setBlockState(worldIn, structureBoundingBoxIn, i + 2, j + 9, k + 8, Blocks.AIR.getDefaultState());
			this.setBlockState(worldIn, structureBoundingBoxIn, i + 2, j + 9, k + 9, Blocks.AIR.getDefaultState());
			this.setBlockState(worldIn, structureBoundingBoxIn, i + 2, j + 9, k + 10, Blocks.AIR.getDefaultState());
			this.setBlockState(worldIn, structureBoundingBoxIn, i + 3, j + 0, k + 0, JourneyBlocks.corbaCobblestone.getDefaultState());
			this.setBlockState(worldIn, structureBoundingBoxIn, i + 3, j + 0, k + 1, JourneyBlocks.corbaCobblestone.getDefaultState());
			this.setBlockState(worldIn, structureBoundingBoxIn, i + 3, j + 0, k + 2, JourneyBlocks.corbaCobblestone.getDefaultState());
			this.setBlockState(worldIn, structureBoundingBoxIn, i + 3, j + 0, k + 3, JourneyBlocks.corbaCobblestone.getDefaultState());
			this.setBlockState(worldIn, structureBoundingBoxIn, i + 3, j + 0, k + 4, JourneyBlocks.corbaCobblestone.getDefaultState());
			this.setBlockState(worldIn, structureBoundingBoxIn, i + 3, j + 0, k + 5, JourneyBlocks.corbaCobblestone.getDefaultState());
			this.setBlockState(worldIn, structureBoundingBoxIn, i + 3, j + 0, k + 6, JourneyBlocks.corbaCobblestone.getDefaultState());
			this.setBlockState(worldIn, structureBoundingBoxIn, i + 3, j + 0, k + 7, JourneyBlocks.corbaCobblestone.getDefaultState());
			this.setBlockState(worldIn, structureBoundingBoxIn, i + 3, j + 0, k + 8, JourneyBlocks.corbaCobblestone.getDefaultState());
			this.setBlockState(worldIn, structureBoundingBoxIn, i + 3, j + 0, k + 9, JourneyBlocks.corbaCobblestone.getDefaultState());
			this.setBlockState(worldIn, structureBoundingBoxIn, i + 3, j + 0, k + 10, JourneyBlocks.corbaCobblestone.getDefaultState());
			this.setBlockState(worldIn, structureBoundingBoxIn, i + 3, j + 1, k + 0, Blocks.AIR.getDefaultState());
			this.setBlockState(worldIn, structureBoundingBoxIn, i + 3, j + 1, k + 1, JourneyBlocks.corbaPlank.getDefaultState());
			this.setBlockState(worldIn, structureBoundingBoxIn, i + 3, j + 1, k + 2, JourneyBlocks.corbaPlankStairs.getDefaultState().withProperty(BlockStairs.FACING, south));
			this.setBlockState(worldIn, structureBoundingBoxIn, i + 3, j + 1, k + 3, Blocks.AIR.getDefaultState());
			this.setBlockState(worldIn, structureBoundingBoxIn, i + 3, j + 1, k + 4, (IBlockState)Blocks.BRICK_STAIRS.getDefaultState().withProperty(BlockStairs.FACING, EnumFacing.WEST));
			this.setBlockState(worldIn, structureBoundingBoxIn, i + 3, j + 1, k + 6, Blocks.BOOKSHELF.getDefaultState());
			this.setBlockState(worldIn, structureBoundingBoxIn, i + 3, j + 1, k + 7, Blocks.AIR.getDefaultState());
			this.setBlockState(worldIn, structureBoundingBoxIn, i + 3, j + 1, k + 8, JourneyBlocks.corbaPlankStairs.getDefaultState().withProperty(BlockStairs.FACING, north));
			this.setBlockState(worldIn, structureBoundingBoxIn, i + 3, j + 1, k + 9, JourneyBlocks.corbaPlank.getDefaultState());
			this.setBlockState(worldIn, structureBoundingBoxIn, i + 3, j + 1, k + 10, Blocks.AIR.getDefaultState());
			this.setBlockState(worldIn, structureBoundingBoxIn, i + 3, j + 2, k + 0, Blocks.AIR.getDefaultState());
			this.setBlockState(worldIn, structureBoundingBoxIn, i + 3, j + 2, k + 1, JourneyBlocks.corbaPlank.getDefaultState());
			this.setBlockState(worldIn, structureBoundingBoxIn, i + 3, j + 2, k + 2, Blocks.AIR.getDefaultState());
			this.setBlockState(worldIn, structureBoundingBoxIn, i + 3, j + 2, k + 3, Blocks.AIR.getDefaultState());
			this.setBlockState(worldIn, structureBoundingBoxIn, i + 3, j + 2, k + 4, Blocks.AIR.getDefaultState());
			this.setBlockState(worldIn, structureBoundingBoxIn, i + 3, j + 2, k + 5, Blocks.AIR.getDefaultState());
			this.setBlockState(worldIn, structureBoundingBoxIn, i + 3, j + 2, k + 6, Blocks.AIR.getDefaultState());
			this.setBlockState(worldIn, structureBoundingBoxIn, i + 3, j + 2, k + 7, Blocks.AIR.getDefaultState());
			this.setBlockState(worldIn, structureBoundingBoxIn, i + 3, j + 2, k + 8, Blocks.AIR.getDefaultState());
			this.setBlockState(worldIn, structureBoundingBoxIn, i + 3, j + 2, k + 9, JourneyBlocks.corbaPlank.getDefaultState());
			this.setBlockState(worldIn, structureBoundingBoxIn, i + 3, j + 2, k + 10, Blocks.AIR.getDefaultState());
			this.setBlockState(worldIn, structureBoundingBoxIn, i + 3, j + 3, k + 0, Blocks.AIR.getDefaultState());
			this.setBlockState(worldIn, structureBoundingBoxIn, i + 3, j + 3, k + 1, JourneyBlocks.corbaPlank.getDefaultState());
			this.setBlockState(worldIn, structureBoundingBoxIn, i + 3, j + 3, k + 2, Blocks.AIR.getDefaultState());
			this.setBlockState(worldIn, structureBoundingBoxIn, i + 3, j + 3, k + 3, Blocks.AIR.getDefaultState());
			this.setBlockState(worldIn, structureBoundingBoxIn, i + 3, j + 3, k + 4, Blocks.AIR.getDefaultState());
			this.setBlockState(worldIn, structureBoundingBoxIn, i + 3, j + 3, k + 5, Blocks.AIR.getDefaultState());
			this.setBlockState(worldIn, structureBoundingBoxIn, i + 3, j + 3, k + 6, Blocks.AIR.getDefaultState());
			this.setBlockState(worldIn, structureBoundingBoxIn, i + 3, j + 3, k + 7, Blocks.AIR.getDefaultState());
			this.setBlockState(worldIn, structureBoundingBoxIn, i + 3, j + 3, k + 8, Blocks.AIR.getDefaultState());
			this.setBlockState(worldIn, structureBoundingBoxIn, i + 3, j + 3, k + 9, JourneyBlocks.corbaPlank.getDefaultState());
			this.setBlockState(worldIn, structureBoundingBoxIn, i + 3, j + 3, k + 10, Blocks.AIR.getDefaultState());
			this.setBlockState(worldIn, structureBoundingBoxIn, i + 3, j + 4, k + 0, JourneyBlocks.corbaPlankStairs.getDefaultState().withProperty(BlockStairs.FACING, north));
			this.setBlockState(worldIn, structureBoundingBoxIn, i + 3, j + 4, k + 1, JourneyBlocks.corbaLog.getDefaultState());
			this.setBlockState(worldIn, structureBoundingBoxIn, i + 3, j + 4, k + 2, Blocks.AIR.getDefaultState());
			this.setBlockState(worldIn, structureBoundingBoxIn, i + 3, j + 4, k + 3, Blocks.AIR.getDefaultState());
			this.setBlockState(worldIn, structureBoundingBoxIn, i + 3, j + 4, k + 4, Blocks.AIR.getDefaultState());
			this.setBlockState(worldIn, structureBoundingBoxIn, i + 3, j + 4, k + 5, Blocks.TORCH.getDefaultState());
			this.setBlockState(worldIn, structureBoundingBoxIn, i + 3, j + 4, k + 6, Blocks.AIR.getDefaultState());
			this.setBlockState(worldIn, structureBoundingBoxIn, i + 3, j + 4, k + 7, Blocks.AIR.getDefaultState());
			this.setBlockState(worldIn, structureBoundingBoxIn, i + 3, j + 4, k + 8, Blocks.AIR.getDefaultState());
			this.setBlockState(worldIn, structureBoundingBoxIn, i + 3, j + 4, k + 9, JourneyBlocks.corbaLog.getDefaultState());
			this.setBlockState(worldIn, structureBoundingBoxIn, i + 3, j + 4, k + 10, JourneyBlocks.corbaPlankStairs.getDefaultState().withProperty(BlockStairs.FACING, south));
			this.setBlockState(worldIn, structureBoundingBoxIn, i + 3, j + 5, k + 0, Blocks.AIR.getDefaultState());
			this.setBlockState(worldIn, structureBoundingBoxIn, i + 3, j + 5, k + 1, JourneyBlocks.corbaPlankStairs.getDefaultState().withProperty(BlockStairs.FACING, north));
			this.setBlockState(worldIn, structureBoundingBoxIn, i + 3, j + 5, k + 2, JourneyBlocks.corbaLog.getDefaultState());
			this.setBlockState(worldIn, structureBoundingBoxIn, i + 3, j + 5, k + 3, Blocks.AIR.getDefaultState());
			this.setBlockState(worldIn, structureBoundingBoxIn, i + 3, j + 5, k + 4, Blocks.AIR.getDefaultState());
			this.setBlockState(worldIn, structureBoundingBoxIn, i + 3, j + 5, k + 5, Blocks.AIR.getDefaultState());
			this.setBlockState(worldIn, structureBoundingBoxIn, i + 3, j + 5, k + 6, Blocks.AIR.getDefaultState());
			this.setBlockState(worldIn, structureBoundingBoxIn, i + 3, j + 5, k + 7, Blocks.AIR.getDefaultState());
			this.setBlockState(worldIn, structureBoundingBoxIn, i + 3, j + 5, k + 8, JourneyBlocks.corbaLog.getDefaultState());
			this.setBlockState(worldIn, structureBoundingBoxIn, i + 3, j + 5, k + 9, JourneyBlocks.corbaPlankStairs.getDefaultState().withProperty(BlockStairs.FACING, south));
			this.setBlockState(worldIn, structureBoundingBoxIn, i + 3, j + 5, k + 10, Blocks.AIR.getDefaultState());
			this.setBlockState(worldIn, structureBoundingBoxIn, i + 3, j + 6, k + 0, Blocks.AIR.getDefaultState());
			this.setBlockState(worldIn, structureBoundingBoxIn, i + 3, j + 6, k + 1, Blocks.AIR.getDefaultState());
			this.setBlockState(worldIn, structureBoundingBoxIn, i + 3, j + 6, k + 2, JourneyBlocks.corbaPlankStairs.getDefaultState().withProperty(BlockStairs.FACING, north));
			this.setBlockState(worldIn, structureBoundingBoxIn, i + 3, j + 6, k + 3, JourneyBlocks.corbaLog.getDefaultState());
			this.setBlockState(worldIn, structureBoundingBoxIn, i + 3, j + 6, k + 4, Blocks.AIR.getDefaultState());
			this.setBlockState(worldIn, structureBoundingBoxIn, i + 3, j + 6, k + 5, Blocks.AIR.getDefaultState());
			this.setBlockState(worldIn, structureBoundingBoxIn, i + 3, j + 6, k + 6, Blocks.AIR.getDefaultState());
			this.setBlockState(worldIn, structureBoundingBoxIn, i + 3, j + 6, k + 7, JourneyBlocks.corbaLog.getDefaultState());
			this.setBlockState(worldIn, structureBoundingBoxIn, i + 3, j + 6, k + 8, JourneyBlocks.corbaPlankStairs.getDefaultState().withProperty(BlockStairs.FACING, south));
			this.setBlockState(worldIn, structureBoundingBoxIn, i + 3, j + 6, k + 9, Blocks.AIR.getDefaultState());
			this.setBlockState(worldIn, structureBoundingBoxIn, i + 3, j + 6, k + 10, Blocks.AIR.getDefaultState());
			this.setBlockState(worldIn, structureBoundingBoxIn, i + 3, j + 7, k + 0, Blocks.AIR.getDefaultState());
			this.setBlockState(worldIn, structureBoundingBoxIn, i + 3, j + 7, k + 1, Blocks.AIR.getDefaultState());
			this.setBlockState(worldIn, structureBoundingBoxIn, i + 3, j + 7, k + 2, Blocks.AIR.getDefaultState());
			this.setBlockState(worldIn, structureBoundingBoxIn, i + 3, j + 7, k + 3, JourneyBlocks.corbaPlankStairs.getDefaultState().withProperty(BlockStairs.FACING, north));
			this.setBlockState(worldIn, structureBoundingBoxIn, i + 3, j + 7, k + 4, JourneyBlocks.corbaLog.getDefaultState());
			this.setBlockState(worldIn, structureBoundingBoxIn, i + 3, j + 7, k + 5, Blocks.AIR.getDefaultState());
			this.setBlockState(worldIn, structureBoundingBoxIn, i + 3, j + 7, k + 6, JourneyBlocks.corbaLog.getDefaultState());
			this.setBlockState(worldIn, structureBoundingBoxIn, i + 3, j + 7, k + 7, JourneyBlocks.corbaPlankStairs.getDefaultState().withProperty(BlockStairs.FACING, south));
			this.setBlockState(worldIn, structureBoundingBoxIn, i + 3, j + 7, k + 8, Blocks.AIR.getDefaultState());
			this.setBlockState(worldIn, structureBoundingBoxIn, i + 3, j + 7, k + 9, Blocks.AIR.getDefaultState());
			this.setBlockState(worldIn, structureBoundingBoxIn, i + 3, j + 7, k + 10, Blocks.AIR.getDefaultState());
			this.setBlockState(worldIn, structureBoundingBoxIn, i + 3, j + 8, k + 0, Blocks.AIR.getDefaultState());
			this.setBlockState(worldIn, structureBoundingBoxIn, i + 3, j + 8, k + 1, Blocks.AIR.getDefaultState());
			this.setBlockState(worldIn, structureBoundingBoxIn, i + 3, j + 8, k + 2, Blocks.AIR.getDefaultState());
			this.setBlockState(worldIn, structureBoundingBoxIn, i + 3, j + 8, k + 3, Blocks.AIR.getDefaultState());
			this.setBlockState(worldIn, structureBoundingBoxIn, i + 3, j + 8, k + 4, JourneyBlocks.corbaPlankStairs.getDefaultState().withProperty(BlockStairs.FACING, north));
			this.setBlockState(worldIn, structureBoundingBoxIn, i + 3, j + 8, k + 5, JourneyBlocks.corbaLog.getDefaultState());
			this.setBlockState(worldIn, structureBoundingBoxIn, i + 3, j + 8, k + 6, JourneyBlocks.corbaPlankStairs.getDefaultState().withProperty(BlockStairs.FACING, south));
			this.setBlockState(worldIn, structureBoundingBoxIn, i + 3, j + 8, k + 7, Blocks.AIR.getDefaultState());
			this.setBlockState(worldIn, structureBoundingBoxIn, i + 3, j + 8, k + 8, Blocks.AIR.getDefaultState());
			this.setBlockState(worldIn, structureBoundingBoxIn, i + 3, j + 8, k + 9, Blocks.AIR.getDefaultState());
			this.setBlockState(worldIn, structureBoundingBoxIn, i + 3, j + 8, k + 10, Blocks.AIR.getDefaultState());
			this.setBlockState(worldIn, structureBoundingBoxIn, i + 3, j + 9, k + 0, Blocks.AIR.getDefaultState());
			this.setBlockState(worldIn, structureBoundingBoxIn, i + 3, j + 9, k + 1, Blocks.AIR.getDefaultState());
			this.setBlockState(worldIn, structureBoundingBoxIn, i + 3, j + 9, k + 2, Blocks.AIR.getDefaultState());
			this.setBlockState(worldIn, structureBoundingBoxIn, i + 3, j + 9, k + 3, Blocks.AIR.getDefaultState());
			this.setBlockState(worldIn, structureBoundingBoxIn, i + 3, j + 9, k + 4, Blocks.AIR.getDefaultState());
			this.setBlockState(worldIn, structureBoundingBoxIn, i + 3, j + 9, k + 5, JourneyBlocks.corbaPlank.getDefaultState());
			this.setBlockState(worldIn, structureBoundingBoxIn, i + 3, j + 9, k + 6, Blocks.AIR.getDefaultState());
			this.setBlockState(worldIn, structureBoundingBoxIn, i + 3, j + 9, k + 7, Blocks.AIR.getDefaultState());
			this.setBlockState(worldIn, structureBoundingBoxIn, i + 3, j + 9, k + 8, Blocks.AIR.getDefaultState());
			this.setBlockState(worldIn, structureBoundingBoxIn, i + 3, j + 9, k + 9, Blocks.AIR.getDefaultState());
			this.setBlockState(worldIn, structureBoundingBoxIn, i + 3, j + 9, k + 10, Blocks.AIR.getDefaultState());
			this.setBlockState(worldIn, structureBoundingBoxIn, i + 4, j + 0, k + 0, JourneyBlocks.corbaCobblestone.getDefaultState());
			this.setBlockState(worldIn, structureBoundingBoxIn, i + 4, j + 0, k + 1, JourneyBlocks.corbaCobblestone.getDefaultState());
			this.setBlockState(worldIn, structureBoundingBoxIn, i + 4, j + 0, k + 2, JourneyBlocks.corbaCobblestone.getDefaultState());
			this.setBlockState(worldIn, structureBoundingBoxIn, i + 4, j + 0, k + 3, JourneyBlocks.corbaCobblestone.getDefaultState());
			this.setBlockState(worldIn, structureBoundingBoxIn, i + 4, j + 0, k + 4, JourneyBlocks.corbaCobblestone.getDefaultState());
			this.setBlockState(worldIn, structureBoundingBoxIn, i + 4, j + 0, k + 5, JourneyBlocks.corbaCobblestone.getDefaultState());
			this.setBlockState(worldIn, structureBoundingBoxIn, i + 4, j + 0, k + 6, JourneyBlocks.corbaCobblestone.getDefaultState());
			this.setBlockState(worldIn, structureBoundingBoxIn, i + 4, j + 0, k + 7, JourneyBlocks.corbaCobblestone.getDefaultState());
			this.setBlockState(worldIn, structureBoundingBoxIn, i + 4, j + 0, k + 8, JourneyBlocks.corbaCobblestone.getDefaultState());
			this.setBlockState(worldIn, structureBoundingBoxIn, i + 4, j + 0, k + 9, JourneyBlocks.corbaCobblestone.getDefaultState());
			this.setBlockState(worldIn, structureBoundingBoxIn, i + 4, j + 0, k + 10, JourneyBlocks.corbaCobblestone.getDefaultState());
			this.setBlockState(worldIn, structureBoundingBoxIn, i + 4, j + 1, k + 0, Blocks.AIR.getDefaultState());
			this.setBlockState(worldIn, structureBoundingBoxIn, i + 4, j + 1, k + 1, JourneyBlocks.corbaPost.getDefaultState());
			this.setBlockState(worldIn, structureBoundingBoxIn, i + 4, j + 1, k + 2, Blocks.AIR.getDefaultState());
			this.setBlockState(worldIn, structureBoundingBoxIn, i + 4, j + 1, k + 3, Blocks.AIR.getDefaultState());
			this.setBlockState(worldIn, structureBoundingBoxIn, i + 4, j + 1, k + 4, Blocks.AIR.getDefaultState());
			this.setBlockState(worldIn, structureBoundingBoxIn, i + 4, j + 1, k + 5, Blocks.BED.getDefaultState());
			this.setBlockState(worldIn, structureBoundingBoxIn, i + 4, j + 1, k + 6, Blocks.AIR.getDefaultState());
			this.setBlockState(worldIn, structureBoundingBoxIn, i + 4, j + 1, k + 7, Blocks.AIR.getDefaultState());
			this.setBlockState(worldIn, structureBoundingBoxIn, i + 4, j + 1, k + 8, Blocks.AIR.getDefaultState());
			this.setBlockState(worldIn, structureBoundingBoxIn, i + 4, j + 1, k + 9, JourneyBlocks.corbaPost.getDefaultState());
			this.setBlockState(worldIn, structureBoundingBoxIn, i + 4, j + 1, k + 10, Blocks.AIR.getDefaultState());
			this.setBlockState(worldIn, structureBoundingBoxIn, i + 4, j + 2, k + 0, Blocks.AIR.getDefaultState());
			this.setBlockState(worldIn, structureBoundingBoxIn, i + 4, j + 2, k + 1, JourneyBlocks.corbaPost.getDefaultState());
			this.setBlockState(worldIn, structureBoundingBoxIn, i + 4, j + 2, k + 2, Blocks.AIR.getDefaultState());
			this.setBlockState(worldIn, structureBoundingBoxIn, i + 4, j + 2, k + 3, Blocks.AIR.getDefaultState());
			this.setBlockState(worldIn, structureBoundingBoxIn, i + 4, j + 2, k + 4, Blocks.AIR.getDefaultState());
			this.setBlockState(worldIn, structureBoundingBoxIn, i + 4, j + 2, k + 5, Blocks.AIR.getDefaultState());
			this.setBlockState(worldIn, structureBoundingBoxIn, i + 4, j + 2, k + 6, Blocks.AIR.getDefaultState());
			this.setBlockState(worldIn, structureBoundingBoxIn, i + 4, j + 2, k + 7, Blocks.AIR.getDefaultState());
			this.setBlockState(worldIn, structureBoundingBoxIn, i + 4, j + 2, k + 8, Blocks.AIR.getDefaultState());
			this.setBlockState(worldIn, structureBoundingBoxIn, i + 4, j + 2, k + 9, JourneyBlocks.corbaPost.getDefaultState());
			this.setBlockState(worldIn, structureBoundingBoxIn, i + 4, j + 2, k + 10, Blocks.AIR.getDefaultState());
			this.setBlockState(worldIn, structureBoundingBoxIn, i + 4, j + 3, k + 0, Blocks.AIR.getDefaultState());
			this.setBlockState(worldIn, structureBoundingBoxIn, i + 4, j + 3, k + 1, JourneyBlocks.corbaPost.getDefaultState());
			this.setBlockState(worldIn, structureBoundingBoxIn, i + 4, j + 3, k + 2, Blocks.AIR.getDefaultState());
			this.setBlockState(worldIn, structureBoundingBoxIn, i + 4, j + 3, k + 3, Blocks.AIR.getDefaultState());
			this.setBlockState(worldIn, structureBoundingBoxIn, i + 4, j + 3, k + 4, Blocks.AIR.getDefaultState());
			this.setBlockState(worldIn, structureBoundingBoxIn, i + 4, j + 3, k + 5, Blocks.AIR.getDefaultState());
			this.setBlockState(worldIn, structureBoundingBoxIn, i + 4, j + 3, k + 6, Blocks.AIR.getDefaultState());
			this.setBlockState(worldIn, structureBoundingBoxIn, i + 4, j + 3, k + 7, Blocks.AIR.getDefaultState());
			this.setBlockState(worldIn, structureBoundingBoxIn, i + 4, j + 3, k + 8, Blocks.AIR.getDefaultState());
			this.setBlockState(worldIn, structureBoundingBoxIn, i + 4, j + 3, k + 9, JourneyBlocks.corbaPost.getDefaultState());
			this.setBlockState(worldIn, structureBoundingBoxIn, i + 4, j + 3, k + 10, Blocks.AIR.getDefaultState());
			this.setBlockState(worldIn, structureBoundingBoxIn, i + 4, j + 4, k + 0, JourneyBlocks.corbaPlankStairs.getDefaultState().withProperty(BlockStairs.FACING, north));
			this.setBlockState(worldIn, structureBoundingBoxIn, i + 4, j + 4, k + 1, JourneyBlocks.corbaLog.getDefaultState());
			this.setBlockState(worldIn, structureBoundingBoxIn, i + 4, j + 4, k + 2, Blocks.AIR.getDefaultState());
			this.setBlockState(worldIn, structureBoundingBoxIn, i + 4, j + 4, k + 3, Blocks.AIR.getDefaultState());
			this.setBlockState(worldIn, structureBoundingBoxIn, i + 4, j + 4, k + 4, Blocks.AIR.getDefaultState());
			this.setBlockState(worldIn, structureBoundingBoxIn, i + 4, j + 4, k + 5, Blocks.AIR.getDefaultState());
			this.setBlockState(worldIn, structureBoundingBoxIn, i + 4, j + 4, k + 6, Blocks.AIR.getDefaultState());
			this.setBlockState(worldIn, structureBoundingBoxIn, i + 4, j + 4, k + 7, Blocks.AIR.getDefaultState());
			this.setBlockState(worldIn, structureBoundingBoxIn, i + 4, j + 4, k + 8, Blocks.AIR.getDefaultState());
			this.setBlockState(worldIn, structureBoundingBoxIn, i + 4, j + 4, k + 9, JourneyBlocks.corbaLog.getDefaultState());
			this.setBlockState(worldIn, structureBoundingBoxIn, i + 4, j + 4, k + 10, JourneyBlocks.corbaPlankStairs.getDefaultState().withProperty(BlockStairs.FACING, south));
			this.setBlockState(worldIn, structureBoundingBoxIn, i + 4, j + 5, k + 0, Blocks.AIR.getDefaultState());
			this.setBlockState(worldIn, structureBoundingBoxIn, i + 4, j + 5, k + 1, JourneyBlocks.corbaPlankStairs.getDefaultState().withProperty(BlockStairs.FACING, north));
			this.setBlockState(worldIn, structureBoundingBoxIn, i + 4, j + 5, k + 2, JourneyBlocks.corbaLog.getDefaultState());
			this.setBlockState(worldIn, structureBoundingBoxIn, i + 4, j + 5, k + 3, Blocks.AIR.getDefaultState());
			this.setBlockState(worldIn, structureBoundingBoxIn, i + 4, j + 5, k + 4, Blocks.AIR.getDefaultState());
			this.setBlockState(worldIn, structureBoundingBoxIn, i + 4, j + 5, k + 5, Blocks.AIR.getDefaultState());
			this.setBlockState(worldIn, structureBoundingBoxIn, i + 4, j + 5, k + 6, Blocks.AIR.getDefaultState());
			this.setBlockState(worldIn, structureBoundingBoxIn, i + 4, j + 5, k + 7, Blocks.AIR.getDefaultState());
			this.setBlockState(worldIn, structureBoundingBoxIn, i + 4, j + 5, k + 8, JourneyBlocks.corbaLog.getDefaultState());
			this.setBlockState(worldIn, structureBoundingBoxIn, i + 4, j + 5, k + 9, JourneyBlocks.corbaPlankStairs.getDefaultState().withProperty(BlockStairs.FACING, south));
			this.setBlockState(worldIn, structureBoundingBoxIn, i + 4, j + 5, k + 10, Blocks.AIR.getDefaultState());
			this.setBlockState(worldIn, structureBoundingBoxIn, i + 4, j + 6, k + 0, Blocks.AIR.getDefaultState());
			this.setBlockState(worldIn, structureBoundingBoxIn, i + 4, j + 6, k + 1, Blocks.AIR.getDefaultState());
			this.setBlockState(worldIn, structureBoundingBoxIn, i + 4, j + 6, k + 2, JourneyBlocks.corbaPlankStairs.getDefaultState().withProperty(BlockStairs.FACING, north));
			this.setBlockState(worldIn, structureBoundingBoxIn, i + 4, j + 6, k + 3, JourneyBlocks.corbaLog.getDefaultState());
			this.setBlockState(worldIn, structureBoundingBoxIn, i + 4, j + 6, k + 4, Blocks.AIR.getDefaultState());
			this.setBlockState(worldIn, structureBoundingBoxIn, i + 4, j + 6, k + 5, Blocks.AIR.getDefaultState());
			this.setBlockState(worldIn, structureBoundingBoxIn, i + 4, j + 6, k + 6, Blocks.AIR.getDefaultState());
			this.setBlockState(worldIn, structureBoundingBoxIn, i + 4, j + 6, k + 7, JourneyBlocks.corbaLog.getDefaultState());
			this.setBlockState(worldIn, structureBoundingBoxIn, i + 4, j + 6, k + 8, JourneyBlocks.corbaPlankStairs.getDefaultState().withProperty(BlockStairs.FACING, south));
			this.setBlockState(worldIn, structureBoundingBoxIn, i + 4, j + 6, k + 9, Blocks.AIR.getDefaultState());
			this.setBlockState(worldIn, structureBoundingBoxIn, i + 4, j + 6, k + 10, Blocks.AIR.getDefaultState());
			this.setBlockState(worldIn, structureBoundingBoxIn, i + 4, j + 7, k + 0, Blocks.AIR.getDefaultState());
			this.setBlockState(worldIn, structureBoundingBoxIn, i + 4, j + 7, k + 1, Blocks.AIR.getDefaultState());
			this.setBlockState(worldIn, structureBoundingBoxIn, i + 4, j + 7, k + 2, Blocks.AIR.getDefaultState());
			this.setBlockState(worldIn, structureBoundingBoxIn, i + 4, j + 7, k + 3, JourneyBlocks.corbaPlankStairs.getDefaultState().withProperty(BlockStairs.FACING, north));
			this.setBlockState(worldIn, structureBoundingBoxIn, i + 4, j + 7, k + 4, JourneyBlocks.corbaLog.getDefaultState());
			this.setBlockState(worldIn, structureBoundingBoxIn, i + 4, j + 7, k + 5, Blocks.AIR.getDefaultState());
			this.setBlockState(worldIn, structureBoundingBoxIn, i + 4, j + 7, k + 6, JourneyBlocks.corbaLog.getDefaultState());
			this.setBlockState(worldIn, structureBoundingBoxIn, i + 4, j + 7, k + 7, JourneyBlocks.corbaPlankStairs.getDefaultState().withProperty(BlockStairs.FACING, south));
			this.setBlockState(worldIn, structureBoundingBoxIn, i + 4, j + 7, k + 8, Blocks.AIR.getDefaultState());
			this.setBlockState(worldIn, structureBoundingBoxIn, i + 4, j + 7, k + 9, Blocks.AIR.getDefaultState());
			this.setBlockState(worldIn, structureBoundingBoxIn, i + 4, j + 7, k + 10, Blocks.AIR.getDefaultState());
			this.setBlockState(worldIn, structureBoundingBoxIn, i + 4, j + 8, k + 0, Blocks.AIR.getDefaultState());
			this.setBlockState(worldIn, structureBoundingBoxIn, i + 4, j + 8, k + 1, Blocks.AIR.getDefaultState());
			this.setBlockState(worldIn, structureBoundingBoxIn, i + 4, j + 8, k + 2, Blocks.AIR.getDefaultState());
			this.setBlockState(worldIn, structureBoundingBoxIn, i + 4, j + 8, k + 3, Blocks.AIR.getDefaultState());
			this.setBlockState(worldIn, structureBoundingBoxIn, i + 4, j + 8, k + 4, JourneyBlocks.corbaPlankStairs.getDefaultState().withProperty(BlockStairs.FACING, north));
			this.setBlockState(worldIn, structureBoundingBoxIn, i + 4, j + 8, k + 5, JourneyBlocks.corbaLog.getDefaultState());
			this.setBlockState(worldIn, structureBoundingBoxIn, i + 4, j + 8, k + 6, JourneyBlocks.corbaPlankStairs.getDefaultState().withProperty(BlockStairs.FACING, south));
			this.setBlockState(worldIn, structureBoundingBoxIn, i + 4, j + 8, k + 7, Blocks.AIR.getDefaultState());
			this.setBlockState(worldIn, structureBoundingBoxIn, i + 4, j + 8, k + 8, Blocks.AIR.getDefaultState());
			this.setBlockState(worldIn, structureBoundingBoxIn, i + 4, j + 8, k + 9, Blocks.AIR.getDefaultState());
			this.setBlockState(worldIn, structureBoundingBoxIn, i + 4, j + 8, k + 10, Blocks.AIR.getDefaultState());
			this.setBlockState(worldIn, structureBoundingBoxIn, i + 4, j + 9, k + 0, Blocks.AIR.getDefaultState());
			this.setBlockState(worldIn, structureBoundingBoxIn, i + 4, j + 9, k + 1, Blocks.AIR.getDefaultState());
			this.setBlockState(worldIn, structureBoundingBoxIn, i + 4, j + 9, k + 2, Blocks.AIR.getDefaultState());
			this.setBlockState(worldIn, structureBoundingBoxIn, i + 4, j + 9, k + 3, Blocks.AIR.getDefaultState());
			this.setBlockState(worldIn, structureBoundingBoxIn, i + 4, j + 9, k + 4, Blocks.AIR.getDefaultState());
			this.setBlockState(worldIn, structureBoundingBoxIn, i + 4, j + 9, k + 5, JourneyBlocks.corbaPlank.getDefaultState());
			this.setBlockState(worldIn, structureBoundingBoxIn, i + 4, j + 9, k + 6, Blocks.AIR.getDefaultState());
			this.setBlockState(worldIn, structureBoundingBoxIn, i + 4, j + 9, k + 7, Blocks.AIR.getDefaultState());
			this.setBlockState(worldIn, structureBoundingBoxIn, i + 4, j + 9, k + 8, Blocks.AIR.getDefaultState());
			this.setBlockState(worldIn, structureBoundingBoxIn, i + 4, j + 9, k + 9, Blocks.AIR.getDefaultState());
			this.setBlockState(worldIn, structureBoundingBoxIn, i + 4, j + 9, k + 10, Blocks.AIR.getDefaultState());
			this.setBlockState(worldIn, structureBoundingBoxIn, i + 5, j + 0, k + 0, JourneyBlocks.corbaCobblestone.getDefaultState());
			this.setBlockState(worldIn, structureBoundingBoxIn, i + 5, j + 0, k + 1, JourneyBlocks.corbaCobblestone.getDefaultState());
			this.setBlockState(worldIn, structureBoundingBoxIn, i + 5, j + 0, k + 2, JourneyBlocks.corbaCobblestone.getDefaultState());
			this.setBlockState(worldIn, structureBoundingBoxIn, i + 5, j + 0, k + 3, JourneyBlocks.corbaCobblestone.getDefaultState());
			this.setBlockState(worldIn, structureBoundingBoxIn, i + 5, j + 0, k + 4, JourneyBlocks.corbaCobblestone.getDefaultState());
			this.setBlockState(worldIn, structureBoundingBoxIn, i + 5, j + 0, k + 5, JourneyBlocks.corbaCobblestone.getDefaultState());
			this.setBlockState(worldIn, structureBoundingBoxIn, i + 5, j + 0, k + 6, JourneyBlocks.corbaCobblestone.getDefaultState());
			this.setBlockState(worldIn, structureBoundingBoxIn, i + 5, j + 0, k + 7, JourneyBlocks.corbaCobblestone.getDefaultState());
			this.setBlockState(worldIn, structureBoundingBoxIn, i + 5, j + 0, k + 8, JourneyBlocks.corbaCobblestone.getDefaultState());
			this.setBlockState(worldIn, structureBoundingBoxIn, i + 5, j + 0, k + 9, JourneyBlocks.corbaCobblestone.getDefaultState());
			this.setBlockState(worldIn, structureBoundingBoxIn, i + 5, j + 0, k + 10, JourneyBlocks.corbaCobblestone.getDefaultState());
			this.setBlockState(worldIn, structureBoundingBoxIn, i + 5, j + 1, k + 0, Blocks.AIR.getDefaultState());
			this.setBlockState(worldIn, structureBoundingBoxIn, i + 5, j + 1, k + 1, JourneyBlocks.corbaPost.getDefaultState());
			this.setBlockState(worldIn, structureBoundingBoxIn, i + 5, j + 1, k + 2, Blocks.AIR.getDefaultState());
			this.setBlockState(worldIn, structureBoundingBoxIn, i + 5, j + 1, k + 3, Blocks.AIR.getDefaultState());
			this.setBlockState(worldIn, structureBoundingBoxIn, i + 5, j + 1, k + 4, Blocks.AIR.getDefaultState());
			this.setBlockState(worldIn, structureBoundingBoxIn, i + 5, j + 1, k + 5, Blocks.AIR.getDefaultState());
			this.setBlockState(worldIn, structureBoundingBoxIn, i + 5, j + 1, k + 6, Blocks.AIR.getDefaultState());
			this.setBlockState(worldIn, structureBoundingBoxIn, i + 5, j + 1, k + 7, Blocks.AIR.getDefaultState());
			this.setBlockState(worldIn, structureBoundingBoxIn, i + 5, j + 1, k + 8, Blocks.AIR.getDefaultState());
			this.setBlockState(worldIn, structureBoundingBoxIn, i + 5, j + 1, k + 9, JourneyBlocks.corbaPost.getDefaultState());
			this.setBlockState(worldIn, structureBoundingBoxIn, i + 5, j + 1, k + 10, Blocks.AIR.getDefaultState());
			this.setBlockState(worldIn, structureBoundingBoxIn, i + 5, j + 2, k + 0, Blocks.AIR.getDefaultState());
			this.setBlockState(worldIn, structureBoundingBoxIn, i + 5, j + 2, k + 1, JourneyBlocks.corbaPost.getDefaultState());
			this.setBlockState(worldIn, structureBoundingBoxIn, i + 5, j + 2, k + 2, Blocks.AIR.getDefaultState());
			this.setBlockState(worldIn, structureBoundingBoxIn, i + 5, j + 2, k + 3, Blocks.AIR.getDefaultState());
			this.setBlockState(worldIn, structureBoundingBoxIn, i + 5, j + 2, k + 4, Blocks.AIR.getDefaultState());
			this.setBlockState(worldIn, structureBoundingBoxIn, i + 5, j + 2, k + 5, Blocks.AIR.getDefaultState());
			this.setBlockState(worldIn, structureBoundingBoxIn, i + 5, j + 2, k + 6, Blocks.AIR.getDefaultState());
			this.setBlockState(worldIn, structureBoundingBoxIn, i + 5, j + 2, k + 7, Blocks.AIR.getDefaultState());
			this.setBlockState(worldIn, structureBoundingBoxIn, i + 5, j + 2, k + 8, Blocks.AIR.getDefaultState());
			this.setBlockState(worldIn, structureBoundingBoxIn, i + 5, j + 2, k + 9, JourneyBlocks.corbaPost.getDefaultState());
			this.setBlockState(worldIn, structureBoundingBoxIn, i + 5, j + 2, k + 10, Blocks.AIR.getDefaultState());
			this.setBlockState(worldIn, structureBoundingBoxIn, i + 5, j + 3, k + 0, Blocks.AIR.getDefaultState());
			this.setBlockState(worldIn, structureBoundingBoxIn, i + 5, j + 3, k + 1, JourneyBlocks.corbaPost.getDefaultState());
			this.setBlockState(worldIn, structureBoundingBoxIn, i + 5, j + 3, k + 2, Blocks.AIR.getDefaultState());
			this.setBlockState(worldIn, structureBoundingBoxIn, i + 5, j + 3, k + 3, Blocks.AIR.getDefaultState());
			this.setBlockState(worldIn, structureBoundingBoxIn, i + 5, j + 3, k + 4, Blocks.AIR.getDefaultState());
			this.setBlockState(worldIn, structureBoundingBoxIn, i + 5, j + 3, k + 5, Blocks.AIR.getDefaultState());
			this.setBlockState(worldIn, structureBoundingBoxIn, i + 5, j + 3, k + 6, Blocks.AIR.getDefaultState());
			this.setBlockState(worldIn, structureBoundingBoxIn, i + 5, j + 3, k + 7, Blocks.AIR.getDefaultState());
			this.setBlockState(worldIn, structureBoundingBoxIn, i + 5, j + 3, k + 8, Blocks.AIR.getDefaultState());
			this.setBlockState(worldIn, structureBoundingBoxIn, i + 5, j + 3, k + 9, JourneyBlocks.corbaPost.getDefaultState());
			this.setBlockState(worldIn, structureBoundingBoxIn, i + 5, j + 3, k + 10, Blocks.AIR.getDefaultState());
			this.setBlockState(worldIn, structureBoundingBoxIn, i + 5, j + 4, k + 0, JourneyBlocks.corbaPlankStairs.getDefaultState().withProperty(BlockStairs.FACING, north));
			this.setBlockState(worldIn, structureBoundingBoxIn, i + 5, j + 4, k + 1, JourneyBlocks.corbaLog.getDefaultState());
			this.setBlockState(worldIn, structureBoundingBoxIn, i + 5, j + 4, k + 2, Blocks.AIR.getDefaultState());
			this.setBlockState(worldIn, structureBoundingBoxIn, i + 5, j + 4, k + 3, Blocks.AIR.getDefaultState());
			this.setBlockState(worldIn, structureBoundingBoxIn, i + 5, j + 4, k + 4, Blocks.AIR.getDefaultState());
			this.setBlockState(worldIn, structureBoundingBoxIn, i + 5, j + 4, k + 5, Blocks.AIR.getDefaultState());
			this.setBlockState(worldIn, structureBoundingBoxIn, i + 5, j + 4, k + 6, Blocks.AIR.getDefaultState());
			this.setBlockState(worldIn, structureBoundingBoxIn, i + 5, j + 4, k + 7, Blocks.AIR.getDefaultState());
			this.setBlockState(worldIn, structureBoundingBoxIn, i + 5, j + 4, k + 8, Blocks.AIR.getDefaultState());
			this.setBlockState(worldIn, structureBoundingBoxIn, i + 5, j + 4, k + 9, JourneyBlocks.corbaLog.getDefaultState());
			this.setBlockState(worldIn, structureBoundingBoxIn, i + 5, j + 4, k + 10, JourneyBlocks.corbaPlankStairs.getDefaultState().withProperty(BlockStairs.FACING, south));
			this.setBlockState(worldIn, structureBoundingBoxIn, i + 5, j + 5, k + 0, Blocks.AIR.getDefaultState());
			this.setBlockState(worldIn, structureBoundingBoxIn, i + 5, j + 5, k + 1, JourneyBlocks.corbaPlankStairs.getDefaultState().withProperty(BlockStairs.FACING, north));
			this.setBlockState(worldIn, structureBoundingBoxIn, i + 5, j + 5, k + 2, JourneyBlocks.corbaLog.getDefaultState());
			this.setBlockState(worldIn, structureBoundingBoxIn, i + 5, j + 5, k + 3, Blocks.AIR.getDefaultState());
			this.setBlockState(worldIn, structureBoundingBoxIn, i + 5, j + 5, k + 4, Blocks.AIR.getDefaultState());
			this.setBlockState(worldIn, structureBoundingBoxIn, i + 5, j + 5, k + 5, Blocks.AIR.getDefaultState());
			this.setBlockState(worldIn, structureBoundingBoxIn, i + 5, j + 5, k + 6, Blocks.AIR.getDefaultState());
			this.setBlockState(worldIn, structureBoundingBoxIn, i + 5, j + 5, k + 7, Blocks.AIR.getDefaultState());
			this.setBlockState(worldIn, structureBoundingBoxIn, i + 5, j + 5, k + 8, JourneyBlocks.corbaLog.getDefaultState());
			this.setBlockState(worldIn, structureBoundingBoxIn, i + 5, j + 5, k + 9, JourneyBlocks.corbaPlankStairs.getDefaultState().withProperty(BlockStairs.FACING, south));
			this.setBlockState(worldIn, structureBoundingBoxIn, i + 5, j + 5, k + 10, Blocks.AIR.getDefaultState());
			this.setBlockState(worldIn, structureBoundingBoxIn, i + 5, j + 6, k + 0, Blocks.AIR.getDefaultState());
			this.setBlockState(worldIn, structureBoundingBoxIn, i + 5, j + 6, k + 1, Blocks.AIR.getDefaultState());
			this.setBlockState(worldIn, structureBoundingBoxIn, i + 5, j + 6, k + 2, JourneyBlocks.corbaPlankStairs.getDefaultState().withProperty(BlockStairs.FACING, north));
			this.setBlockState(worldIn, structureBoundingBoxIn, i + 5, j + 6, k + 3, JourneyBlocks.corbaLog.getDefaultState());
			this.setBlockState(worldIn, structureBoundingBoxIn, i + 5, j + 6, k + 4, Blocks.AIR.getDefaultState());
			this.setBlockState(worldIn, structureBoundingBoxIn, i + 5, j + 6, k + 5, Blocks.AIR.getDefaultState());
			this.setBlockState(worldIn, structureBoundingBoxIn, i + 5, j + 6, k + 6, Blocks.AIR.getDefaultState());
			this.setBlockState(worldIn, structureBoundingBoxIn, i + 5, j + 6, k + 7, JourneyBlocks.corbaLog.getDefaultState());
			this.setBlockState(worldIn, structureBoundingBoxIn, i + 5, j + 6, k + 8, JourneyBlocks.corbaPlankStairs.getDefaultState().withProperty(BlockStairs.FACING, south));
			this.setBlockState(worldIn, structureBoundingBoxIn, i + 5, j + 6, k + 9, Blocks.AIR.getDefaultState());
			this.setBlockState(worldIn, structureBoundingBoxIn, i + 5, j + 6, k + 10, Blocks.AIR.getDefaultState());
			this.setBlockState(worldIn, structureBoundingBoxIn, i + 5, j + 7, k + 0, Blocks.AIR.getDefaultState());
			this.setBlockState(worldIn, structureBoundingBoxIn, i + 5, j + 7, k + 1, Blocks.AIR.getDefaultState());
			this.setBlockState(worldIn, structureBoundingBoxIn, i + 5, j + 7, k + 2, Blocks.AIR.getDefaultState());
			this.setBlockState(worldIn, structureBoundingBoxIn, i + 5, j + 7, k + 3, JourneyBlocks.corbaPlankStairs.getDefaultState().withProperty(BlockStairs.FACING, north));
			this.setBlockState(worldIn, structureBoundingBoxIn, i + 5, j + 7, k + 4, JourneyBlocks.corbaLog.getDefaultState());
			this.setBlockState(worldIn, structureBoundingBoxIn, i + 5, j + 7, k + 5, Blocks.AIR.getDefaultState());
			this.setBlockState(worldIn, structureBoundingBoxIn, i + 5, j + 7, k + 6, JourneyBlocks.corbaLog.getDefaultState());
			this.setBlockState(worldIn, structureBoundingBoxIn, i + 5, j + 7, k + 7, JourneyBlocks.corbaPlankStairs.getDefaultState().withProperty(BlockStairs.FACING, south));
			this.setBlockState(worldIn, structureBoundingBoxIn, i + 5, j + 7, k + 8, Blocks.AIR.getDefaultState());
			this.setBlockState(worldIn, structureBoundingBoxIn, i + 5, j + 7, k + 9, Blocks.AIR.getDefaultState());
			this.setBlockState(worldIn, structureBoundingBoxIn, i + 5, j + 7, k + 10, Blocks.AIR.getDefaultState());
			this.setBlockState(worldIn, structureBoundingBoxIn, i + 5, j + 8, k + 0, Blocks.AIR.getDefaultState());
			this.setBlockState(worldIn, structureBoundingBoxIn, i + 5, j + 8, k + 1, Blocks.AIR.getDefaultState());
			this.setBlockState(worldIn, structureBoundingBoxIn, i + 5, j + 8, k + 2, Blocks.AIR.getDefaultState());
			this.setBlockState(worldIn, structureBoundingBoxIn, i + 5, j + 8, k + 3, Blocks.AIR.getDefaultState());
			this.setBlockState(worldIn, structureBoundingBoxIn, i + 5, j + 8, k + 4, JourneyBlocks.corbaPlankStairs.getDefaultState().withProperty(BlockStairs.FACING, north));
			this.setBlockState(worldIn, structureBoundingBoxIn, i + 5, j + 8, k + 5, JourneyBlocks.corbaLog.getDefaultState());
			this.setBlockState(worldIn, structureBoundingBoxIn, i + 5, j + 8, k + 6, JourneyBlocks.corbaPlankStairs.getDefaultState().withProperty(BlockStairs.FACING, south));
			this.setBlockState(worldIn, structureBoundingBoxIn, i + 5, j + 8, k + 7, Blocks.AIR.getDefaultState());
			this.setBlockState(worldIn, structureBoundingBoxIn, i + 5, j + 8, k + 8, Blocks.AIR.getDefaultState());
			this.setBlockState(worldIn, structureBoundingBoxIn, i + 5, j + 8, k + 9, Blocks.AIR.getDefaultState());
			this.setBlockState(worldIn, structureBoundingBoxIn, i + 5, j + 8, k + 10, Blocks.AIR.getDefaultState());
			this.setBlockState(worldIn, structureBoundingBoxIn, i + 5, j + 9, k + 0, Blocks.AIR.getDefaultState());
			this.setBlockState(worldIn, structureBoundingBoxIn, i + 5, j + 9, k + 1, Blocks.AIR.getDefaultState());
			this.setBlockState(worldIn, structureBoundingBoxIn, i + 5, j + 9, k + 2, Blocks.AIR.getDefaultState());
			this.setBlockState(worldIn, structureBoundingBoxIn, i + 5, j + 9, k + 3, Blocks.AIR.getDefaultState());
			this.setBlockState(worldIn, structureBoundingBoxIn, i + 5, j + 9, k + 4, Blocks.AIR.getDefaultState());
			this.setBlockState(worldIn, structureBoundingBoxIn, i + 5, j + 9, k + 5, JourneyBlocks.corbaPlank.getDefaultState());
			this.setBlockState(worldIn, structureBoundingBoxIn, i + 5, j + 9, k + 6, Blocks.AIR.getDefaultState());
			this.setBlockState(worldIn, structureBoundingBoxIn, i + 5, j + 9, k + 7, Blocks.AIR.getDefaultState());
			this.setBlockState(worldIn, structureBoundingBoxIn, i + 5, j + 9, k + 8, Blocks.AIR.getDefaultState());
			this.setBlockState(worldIn, structureBoundingBoxIn, i + 5, j + 9, k + 9, Blocks.AIR.getDefaultState());
			this.setBlockState(worldIn, structureBoundingBoxIn, i + 5, j + 9, k + 10, Blocks.AIR.getDefaultState());
			this.setBlockState(worldIn, structureBoundingBoxIn, i + 6, j + 0, k + 0, JourneyBlocks.corbaCobblestone.getDefaultState());
			this.setBlockState(worldIn, structureBoundingBoxIn, i + 6, j + 0, k + 1, JourneyBlocks.corbaCobblestone.getDefaultState());
			this.setBlockState(worldIn, structureBoundingBoxIn, i + 6, j + 0, k + 2, JourneyBlocks.corbaCobblestone.getDefaultState());
			this.setBlockState(worldIn, structureBoundingBoxIn, i + 6, j + 0, k + 3, JourneyBlocks.corbaCobblestone.getDefaultState());
			this.setBlockState(worldIn, structureBoundingBoxIn, i + 6, j + 0, k + 4, JourneyBlocks.corbaCobblestone.getDefaultState());
			this.setBlockState(worldIn, structureBoundingBoxIn, i + 6, j + 0, k + 5, JourneyBlocks.corbaCobblestone.getDefaultState());
			this.setBlockState(worldIn, structureBoundingBoxIn, i + 6, j + 0, k + 6, JourneyBlocks.corbaCobblestone.getDefaultState());
			this.setBlockState(worldIn, structureBoundingBoxIn, i + 6, j + 0, k + 7, JourneyBlocks.corbaCobblestone.getDefaultState());
			this.setBlockState(worldIn, structureBoundingBoxIn, i + 6, j + 0, k + 8, JourneyBlocks.corbaCobblestone.getDefaultState());
			this.setBlockState(worldIn, structureBoundingBoxIn, i + 6, j + 0, k + 9, JourneyBlocks.corbaCobblestone.getDefaultState());
			this.setBlockState(worldIn, structureBoundingBoxIn, i + 6, j + 0, k + 10, JourneyBlocks.corbaCobblestone.getDefaultState());
			this.setBlockState(worldIn, structureBoundingBoxIn, i + 6, j + 1, k + 0, Blocks.AIR.getDefaultState());
			this.setBlockState(worldIn, structureBoundingBoxIn, i + 6, j + 1, k + 1, JourneyBlocks.corbaPlank.getDefaultState());
			this.setBlockState(worldIn, structureBoundingBoxIn, i + 6, j + 1, k + 2, JourneyBlocks.corbaPlankStairs.getDefaultState().withProperty(BlockStairs.FACING, south));
			this.setBlockState(worldIn, structureBoundingBoxIn, i + 6, j + 1, k + 3, Blocks.AIR.getDefaultState());
			this.setBlockState(worldIn, structureBoundingBoxIn, i + 6, j + 1, k + 4, Blocks.AIR.getDefaultState());
			this.setBlockState(worldIn, structureBoundingBoxIn, i + 6, j + 1, k + 5, Blocks.AIR.getDefaultState());
			this.setBlockState(worldIn, structureBoundingBoxIn, i + 6, j + 1, k + 6, Blocks.AIR.getDefaultState());
			this.setBlockState(worldIn, structureBoundingBoxIn, i + 6, j + 1, k + 7, Blocks.AIR.getDefaultState());
			this.setBlockState(worldIn, structureBoundingBoxIn, i + 6, j + 1, k + 8, JourneyBlocks.corbaPlankStairs.getDefaultState().withProperty(BlockStairs.FACING, north));
			this.setBlockState(worldIn, structureBoundingBoxIn, i + 6, j + 1, k + 9, JourneyBlocks.corbaPlank.getDefaultState());
			this.setBlockState(worldIn, structureBoundingBoxIn, i + 6, j + 1, k + 10, Blocks.AIR.getDefaultState());
			this.setBlockState(worldIn, structureBoundingBoxIn, i + 6, j + 2, k + 0, Blocks.AIR.getDefaultState());
			this.setBlockState(worldIn, structureBoundingBoxIn, i + 6, j + 2, k + 1, JourneyBlocks.corbaPlank.getDefaultState());
			this.setBlockState(worldIn, structureBoundingBoxIn, i + 6, j + 2, k + 2, Blocks.AIR.getDefaultState());
			this.setBlockState(worldIn, structureBoundingBoxIn, i + 6, j + 2, k + 3, Blocks.AIR.getDefaultState());
			this.setBlockState(worldIn, structureBoundingBoxIn, i + 6, j + 2, k + 4, Blocks.AIR.getDefaultState());
			this.setBlockState(worldIn, structureBoundingBoxIn, i + 6, j + 2, k + 5, Blocks.AIR.getDefaultState());
			this.setBlockState(worldIn, structureBoundingBoxIn, i + 6, j + 2, k + 6, Blocks.AIR.getDefaultState());
			this.setBlockState(worldIn, structureBoundingBoxIn, i + 6, j + 2, k + 7, Blocks.AIR.getDefaultState());
			this.setBlockState(worldIn, structureBoundingBoxIn, i + 6, j + 2, k + 8, Blocks.AIR.getDefaultState());
			this.setBlockState(worldIn, structureBoundingBoxIn, i + 6, j + 2, k + 9, JourneyBlocks.corbaPlank.getDefaultState());
			this.setBlockState(worldIn, structureBoundingBoxIn, i + 6, j + 2, k + 10, Blocks.AIR.getDefaultState());
			this.setBlockState(worldIn, structureBoundingBoxIn, i + 6, j + 3, k + 0, Blocks.AIR.getDefaultState());
			this.setBlockState(worldIn, structureBoundingBoxIn, i + 6, j + 3, k + 1, JourneyBlocks.corbaPlank.getDefaultState());
			this.setBlockState(worldIn, structureBoundingBoxIn, i + 6, j + 3, k + 2, Blocks.AIR.getDefaultState());
			this.setBlockState(worldIn, structureBoundingBoxIn, i + 6, j + 3, k + 3, Blocks.AIR.getDefaultState());
			this.setBlockState(worldIn, structureBoundingBoxIn, i + 6, j + 3, k + 4, Blocks.AIR.getDefaultState());
			this.setBlockState(worldIn, structureBoundingBoxIn, i + 6, j + 3, k + 5, Blocks.AIR.getDefaultState());
			this.setBlockState(worldIn, structureBoundingBoxIn, i + 6, j + 3, k + 6, Blocks.AIR.getDefaultState());
			this.setBlockState(worldIn, structureBoundingBoxIn, i + 6, j + 3, k + 7, Blocks.AIR.getDefaultState());
			this.setBlockState(worldIn, structureBoundingBoxIn, i + 6, j + 3, k + 8, Blocks.AIR.getDefaultState());
			this.setBlockState(worldIn, structureBoundingBoxIn, i + 6, j + 3, k + 9, JourneyBlocks.corbaPlank.getDefaultState());
			this.setBlockState(worldIn, structureBoundingBoxIn, i + 6, j + 3, k + 10, Blocks.AIR.getDefaultState());
			this.setBlockState(worldIn, structureBoundingBoxIn, i + 6, j + 4, k + 0, JourneyBlocks.corbaPlankStairs.getDefaultState().withProperty(BlockStairs.FACING, north));
			this.setBlockState(worldIn, structureBoundingBoxIn, i + 6, j + 4, k + 1, JourneyBlocks.corbaLog.getDefaultState());
			this.setBlockState(worldIn, structureBoundingBoxIn, i + 6, j + 4, k + 2, Blocks.AIR.getDefaultState());
			this.setBlockState(worldIn, structureBoundingBoxIn, i + 6, j + 4, k + 3, Blocks.AIR.getDefaultState());
			this.setBlockState(worldIn, structureBoundingBoxIn, i + 6, j + 4, k + 4, Blocks.AIR.getDefaultState());
			this.setBlockState(worldIn, structureBoundingBoxIn, i + 6, j + 4, k + 5, Blocks.AIR.getDefaultState());
			this.setBlockState(worldIn, structureBoundingBoxIn, i + 6, j + 4, k + 6, Blocks.AIR.getDefaultState());
			this.setBlockState(worldIn, structureBoundingBoxIn, i + 6, j + 4, k + 7, Blocks.AIR.getDefaultState());
			this.setBlockState(worldIn, structureBoundingBoxIn, i + 6, j + 4, k + 8, Blocks.AIR.getDefaultState());
			this.setBlockState(worldIn, structureBoundingBoxIn, i + 6, j + 4, k + 9, JourneyBlocks.corbaLog.getDefaultState());
			this.setBlockState(worldIn, structureBoundingBoxIn, i + 6, j + 4, k + 10, JourneyBlocks.corbaPlankStairs.getDefaultState().withProperty(BlockStairs.FACING, south));
			this.setBlockState(worldIn, structureBoundingBoxIn, i + 6, j + 5, k + 0, Blocks.AIR.getDefaultState());
			this.setBlockState(worldIn, structureBoundingBoxIn, i + 6, j + 5, k + 1, JourneyBlocks.corbaPlankStairs.getDefaultState().withProperty(BlockStairs.FACING, north));
			this.setBlockState(worldIn, structureBoundingBoxIn, i + 6, j + 5, k + 2, JourneyBlocks.corbaLog.getDefaultState());
			this.setBlockState(worldIn, structureBoundingBoxIn, i + 6, j + 5, k + 3, Blocks.AIR.getDefaultState());
			this.setBlockState(worldIn, structureBoundingBoxIn, i + 6, j + 5, k + 4, Blocks.AIR.getDefaultState());
			this.setBlockState(worldIn, structureBoundingBoxIn, i + 6, j + 5, k + 5, Blocks.AIR.getDefaultState());
			this.setBlockState(worldIn, structureBoundingBoxIn, i + 6, j + 5, k + 6, Blocks.AIR.getDefaultState());
			this.setBlockState(worldIn, structureBoundingBoxIn, i + 6, j + 5, k + 7, Blocks.AIR.getDefaultState());
			this.setBlockState(worldIn, structureBoundingBoxIn, i + 6, j + 5, k + 8, JourneyBlocks.corbaLog.getDefaultState());
			this.setBlockState(worldIn, structureBoundingBoxIn, i + 6, j + 5, k + 9, JourneyBlocks.corbaPlankStairs.getDefaultState().withProperty(BlockStairs.FACING, south));
			this.setBlockState(worldIn, structureBoundingBoxIn, i + 6, j + 5, k + 10, Blocks.AIR.getDefaultState());
			this.setBlockState(worldIn, structureBoundingBoxIn, i + 6, j + 6, k + 0, Blocks.AIR.getDefaultState());
			this.setBlockState(worldIn, structureBoundingBoxIn, i + 6, j + 6, k + 1, Blocks.AIR.getDefaultState());
			this.setBlockState(worldIn, structureBoundingBoxIn, i + 6, j + 6, k + 2, JourneyBlocks.corbaPlankStairs.getDefaultState().withProperty(BlockStairs.FACING, north));
			this.setBlockState(worldIn, structureBoundingBoxIn, i + 6, j + 6, k + 3, JourneyBlocks.corbaLog.getDefaultState());
			this.setBlockState(worldIn, structureBoundingBoxIn, i + 6, j + 6, k + 4, Blocks.AIR.getDefaultState());
			this.setBlockState(worldIn, structureBoundingBoxIn, i + 6, j + 6, k + 5, Blocks.AIR.getDefaultState());
			this.setBlockState(worldIn, structureBoundingBoxIn, i + 6, j + 6, k + 6, Blocks.AIR.getDefaultState());
			this.setBlockState(worldIn, structureBoundingBoxIn, i + 6, j + 6, k + 7, JourneyBlocks.corbaLog.getDefaultState());
			this.setBlockState(worldIn, structureBoundingBoxIn, i + 6, j + 6, k + 8, JourneyBlocks.corbaPlankStairs.getDefaultState().withProperty(BlockStairs.FACING, south));
			this.setBlockState(worldIn, structureBoundingBoxIn, i + 6, j + 6, k + 9, Blocks.AIR.getDefaultState());
			this.setBlockState(worldIn, structureBoundingBoxIn, i + 6, j + 6, k + 10, Blocks.AIR.getDefaultState());
			this.setBlockState(worldIn, structureBoundingBoxIn, i + 6, j + 7, k + 0, Blocks.AIR.getDefaultState());
			this.setBlockState(worldIn, structureBoundingBoxIn, i + 6, j + 7, k + 1, Blocks.AIR.getDefaultState());
			this.setBlockState(worldIn, structureBoundingBoxIn, i + 6, j + 7, k + 2, Blocks.AIR.getDefaultState());
			this.setBlockState(worldIn, structureBoundingBoxIn, i + 6, j + 7, k + 3, JourneyBlocks.corbaPlankStairs.getDefaultState().withProperty(BlockStairs.FACING, north));
			this.setBlockState(worldIn, structureBoundingBoxIn, i + 6, j + 7, k + 4, JourneyBlocks.corbaLog.getDefaultState());
			this.setBlockState(worldIn, structureBoundingBoxIn, i + 6, j + 7, k + 5, Blocks.AIR.getDefaultState());
			this.setBlockState(worldIn, structureBoundingBoxIn, i + 6, j + 7, k + 6, JourneyBlocks.corbaLog.getDefaultState());
			this.setBlockState(worldIn, structureBoundingBoxIn, i + 6, j + 7, k + 7, JourneyBlocks.corbaPlankStairs.getDefaultState().withProperty(BlockStairs.FACING, south));
			this.setBlockState(worldIn, structureBoundingBoxIn, i + 6, j + 7, k + 8, Blocks.AIR.getDefaultState());
			this.setBlockState(worldIn, structureBoundingBoxIn, i + 6, j + 7, k + 9, Blocks.AIR.getDefaultState());
			this.setBlockState(worldIn, structureBoundingBoxIn, i + 6, j + 7, k + 10, Blocks.AIR.getDefaultState());
			this.setBlockState(worldIn, structureBoundingBoxIn, i + 6, j + 8, k + 0, Blocks.AIR.getDefaultState());
			this.setBlockState(worldIn, structureBoundingBoxIn, i + 6, j + 8, k + 1, Blocks.AIR.getDefaultState());
			this.setBlockState(worldIn, structureBoundingBoxIn, i + 6, j + 8, k + 2, Blocks.AIR.getDefaultState());
			this.setBlockState(worldIn, structureBoundingBoxIn, i + 6, j + 8, k + 3, Blocks.AIR.getDefaultState());
			this.setBlockState(worldIn, structureBoundingBoxIn, i + 6, j + 8, k + 4, JourneyBlocks.corbaPlankStairs.getDefaultState().withProperty(BlockStairs.FACING, north));
			this.setBlockState(worldIn, structureBoundingBoxIn, i + 6, j + 8, k + 5, JourneyBlocks.corbaLog.getDefaultState());
			this.setBlockState(worldIn, structureBoundingBoxIn, i + 6, j + 8, k + 6, JourneyBlocks.corbaPlankStairs.getDefaultState().withProperty(BlockStairs.FACING, south));
			this.setBlockState(worldIn, structureBoundingBoxIn, i + 6, j + 8, k + 7, Blocks.AIR.getDefaultState());
			this.setBlockState(worldIn, structureBoundingBoxIn, i + 6, j + 8, k + 8, Blocks.AIR.getDefaultState());
			this.setBlockState(worldIn, structureBoundingBoxIn, i + 6, j + 8, k + 9, Blocks.AIR.getDefaultState());
			this.setBlockState(worldIn, structureBoundingBoxIn, i + 6, j + 8, k + 10, Blocks.AIR.getDefaultState());
			this.setBlockState(worldIn, structureBoundingBoxIn, i + 6, j + 9, k + 0, Blocks.AIR.getDefaultState());
			this.setBlockState(worldIn, structureBoundingBoxIn, i + 6, j + 9, k + 1, Blocks.AIR.getDefaultState());
			this.setBlockState(worldIn, structureBoundingBoxIn, i + 6, j + 9, k + 2, Blocks.AIR.getDefaultState());
			this.setBlockState(worldIn, structureBoundingBoxIn, i + 6, j + 9, k + 3, Blocks.AIR.getDefaultState());
			this.setBlockState(worldIn, structureBoundingBoxIn, i + 6, j + 9, k + 4, Blocks.AIR.getDefaultState());
			this.setBlockState(worldIn, structureBoundingBoxIn, i + 6, j + 9, k + 5, JourneyBlocks.corbaPlank.getDefaultState());
			this.setBlockState(worldIn, structureBoundingBoxIn, i + 6, j + 9, k + 6, Blocks.AIR.getDefaultState());
			this.setBlockState(worldIn, structureBoundingBoxIn, i + 6, j + 9, k + 7, Blocks.AIR.getDefaultState());
			this.setBlockState(worldIn, structureBoundingBoxIn, i + 6, j + 9, k + 8, Blocks.AIR.getDefaultState());
			this.setBlockState(worldIn, structureBoundingBoxIn, i + 6, j + 9, k + 9, Blocks.AIR.getDefaultState());
			this.setBlockState(worldIn, structureBoundingBoxIn, i + 6, j + 9, k + 10, Blocks.AIR.getDefaultState());
			this.setBlockState(worldIn, structureBoundingBoxIn, i + 7, j + 0, k + 0, JourneyBlocks.corbaCobblestone.getDefaultState());
			this.setBlockState(worldIn, structureBoundingBoxIn, i + 7, j + 0, k + 1, JourneyBlocks.corbaCobblestone.getDefaultState());
			this.setBlockState(worldIn, structureBoundingBoxIn, i + 7, j + 0, k + 2, JourneyBlocks.corbaCobblestone.getDefaultState());
			this.setBlockState(worldIn, structureBoundingBoxIn, i + 7, j + 0, k + 3, JourneyBlocks.corbaCobblestone.getDefaultState());
			this.setBlockState(worldIn, structureBoundingBoxIn, i + 7, j + 0, k + 4, JourneyBlocks.corbaCobblestone.getDefaultState());
			this.setBlockState(worldIn, structureBoundingBoxIn, i + 7, j + 0, k + 5, JourneyBlocks.corbaCobblestone.getDefaultState());
			this.setBlockState(worldIn, structureBoundingBoxIn, i + 7, j + 0, k + 6, JourneyBlocks.corbaCobblestone.getDefaultState());
			this.setBlockState(worldIn, structureBoundingBoxIn, i + 7, j + 0, k + 7, JourneyBlocks.corbaCobblestone.getDefaultState());
			this.setBlockState(worldIn, structureBoundingBoxIn, i + 7, j + 0, k + 8, JourneyBlocks.corbaCobblestone.getDefaultState());
			this.setBlockState(worldIn, structureBoundingBoxIn, i + 7, j + 0, k + 9, JourneyBlocks.corbaCobblestone.getDefaultState());
			this.setBlockState(worldIn, structureBoundingBoxIn, i + 7, j + 0, k + 10, JourneyBlocks.corbaCobblestone.getDefaultState());
			this.setBlockState(worldIn, structureBoundingBoxIn, i + 7, j + 1, k + 0, Blocks.AIR.getDefaultState());
			this.setBlockState(worldIn, structureBoundingBoxIn, i + 7, j + 1, k + 1, JourneyBlocks.corbaPost.getDefaultState());
			this.setBlockState(worldIn, structureBoundingBoxIn, i + 7, j + 1, k + 2, (IBlockState)Blocks.BRICK_STAIRS.getDefaultState().withProperty(BlockStairs.FACING, south));
			this.setBlockState(worldIn, structureBoundingBoxIn, i + 7, j + 1, k + 3, Blocks.AIR.getDefaultState());
			this.setBlockState(worldIn, structureBoundingBoxIn, i + 7, j + 1, k + 4, Blocks.AIR.getDefaultState());
			this.setBlockState(worldIn, structureBoundingBoxIn, i + 7, j + 1, k + 5, Blocks.AIR.getDefaultState());
			this.setBlockState(worldIn, structureBoundingBoxIn, i + 7, j + 1, k + 6, Blocks.AIR.getDefaultState());
			this.setBlockState(worldIn, structureBoundingBoxIn, i + 7, j + 1, k + 7, Blocks.AIR.getDefaultState());
			this.setBlockState(worldIn, structureBoundingBoxIn, i + 7, j + 1, k + 8, Blocks.CRAFTING_TABLE.getDefaultState());
			this.setBlockState(worldIn, structureBoundingBoxIn, i + 7, j + 1, k + 9, JourneyBlocks.corbaPost.getDefaultState());
			this.setBlockState(worldIn, structureBoundingBoxIn, i + 7, j + 1, k + 10, Blocks.AIR.getDefaultState());
			this.setBlockState(worldIn, structureBoundingBoxIn, i + 7, j + 2, k + 0, Blocks.AIR.getDefaultState());
			this.setBlockState(worldIn, structureBoundingBoxIn, i + 7, j + 2, k + 1, JourneyBlocks.corbaPost.getDefaultState());
			this.setBlockState(worldIn, structureBoundingBoxIn, i + 7, j + 2, k + 2, Blocks.AIR.getDefaultState());
			this.setBlockState(worldIn, structureBoundingBoxIn, i + 7, j + 2, k + 3, Blocks.AIR.getDefaultState());
			this.setBlockState(worldIn, structureBoundingBoxIn, i + 7, j + 2, k + 4, Blocks.AIR.getDefaultState());
			this.setBlockState(worldIn, structureBoundingBoxIn, i + 7, j + 2, k + 5, Blocks.AIR.getDefaultState());
			this.setBlockState(worldIn, structureBoundingBoxIn, i + 7, j + 2, k + 6, Blocks.AIR.getDefaultState());
			this.setBlockState(worldIn, structureBoundingBoxIn, i + 7, j + 2, k + 7, Blocks.AIR.getDefaultState());
			this.setBlockState(worldIn, structureBoundingBoxIn, i + 7, j + 2, k + 8, Blocks.AIR.getDefaultState());
			this.setBlockState(worldIn, structureBoundingBoxIn, i + 7, j + 2, k + 9, JourneyBlocks.corbaPost.getDefaultState());
			this.setBlockState(worldIn, structureBoundingBoxIn, i + 7, j + 2, k + 10, Blocks.AIR.getDefaultState());
			this.setBlockState(worldIn, structureBoundingBoxIn, i + 7, j + 3, k + 0, Blocks.AIR.getDefaultState());
			this.setBlockState(worldIn, structureBoundingBoxIn, i + 7, j + 3, k + 1, JourneyBlocks.corbaPost.getDefaultState());
			this.setBlockState(worldIn, structureBoundingBoxIn, i + 7, j + 3, k + 2, Blocks.AIR.getDefaultState());
			this.setBlockState(worldIn, structureBoundingBoxIn, i + 7, j + 3, k + 3, Blocks.AIR.getDefaultState());
			this.setBlockState(worldIn, structureBoundingBoxIn, i + 7, j + 3, k + 4, Blocks.AIR.getDefaultState());
			this.setBlockState(worldIn, structureBoundingBoxIn, i + 7, j + 3, k + 5, Blocks.AIR.getDefaultState());
			this.setBlockState(worldIn, structureBoundingBoxIn, i + 7, j + 3, k + 6, Blocks.AIR.getDefaultState());
			this.setBlockState(worldIn, structureBoundingBoxIn, i + 7, j + 3, k + 7, Blocks.AIR.getDefaultState());
			this.setBlockState(worldIn, structureBoundingBoxIn, i + 7, j + 3, k + 8, Blocks.AIR.getDefaultState());
			this.setBlockState(worldIn, structureBoundingBoxIn, i + 7, j + 3, k + 9, JourneyBlocks.corbaPost.getDefaultState());
			this.setBlockState(worldIn, structureBoundingBoxIn, i + 7, j + 3, k + 10, Blocks.AIR.getDefaultState());
			this.setBlockState(worldIn, structureBoundingBoxIn, i + 7, j + 4, k + 0, JourneyBlocks.corbaPlankStairs.getDefaultState().withProperty(BlockStairs.FACING, north));
			this.setBlockState(worldIn, structureBoundingBoxIn, i + 7, j + 4, k + 1, JourneyBlocks.corbaLog.getDefaultState());
			this.setBlockState(worldIn, structureBoundingBoxIn, i + 7, j + 4, k + 2, Blocks.AIR.getDefaultState());
			this.setBlockState(worldIn, structureBoundingBoxIn, i + 7, j + 4, k + 3, Blocks.AIR.getDefaultState());
			this.setBlockState(worldIn, structureBoundingBoxIn, i + 7, j + 4, k + 4, Blocks.AIR.getDefaultState());
			this.setBlockState(worldIn, structureBoundingBoxIn, i + 7, j + 4, k + 5, Blocks.AIR.getDefaultState());
			this.setBlockState(worldIn, structureBoundingBoxIn, i + 7, j + 4, k + 6, Blocks.AIR.getDefaultState());
			this.setBlockState(worldIn, structureBoundingBoxIn, i + 7, j + 4, k + 7, Blocks.AIR.getDefaultState());
			this.setBlockState(worldIn, structureBoundingBoxIn, i + 7, j + 4, k + 8, Blocks.AIR.getDefaultState());
			this.setBlockState(worldIn, structureBoundingBoxIn, i + 7, j + 4, k + 9, JourneyBlocks.corbaLog.getDefaultState());
			this.setBlockState(worldIn, structureBoundingBoxIn, i + 7, j + 4, k + 10, JourneyBlocks.corbaPlankStairs.getDefaultState().withProperty(BlockStairs.FACING, south));
			this.setBlockState(worldIn, structureBoundingBoxIn, i + 7, j + 5, k + 0, Blocks.AIR.getDefaultState());
			this.setBlockState(worldIn, structureBoundingBoxIn, i + 7, j + 5, k + 1, JourneyBlocks.corbaPlankStairs.getDefaultState().withProperty(BlockStairs.FACING, north));
			this.setBlockState(worldIn, structureBoundingBoxIn, i + 7, j + 5, k + 2, JourneyBlocks.corbaLog.getDefaultState());
			this.setBlockState(worldIn, structureBoundingBoxIn, i + 7, j + 5, k + 3, Blocks.AIR.getDefaultState());
			this.setBlockState(worldIn, structureBoundingBoxIn, i + 7, j + 5, k + 4, Blocks.AIR.getDefaultState());
			this.setBlockState(worldIn, structureBoundingBoxIn, i + 7, j + 5, k + 5, Blocks.AIR.getDefaultState());
			this.setBlockState(worldIn, structureBoundingBoxIn, i + 7, j + 5, k + 6, Blocks.AIR.getDefaultState());
			this.setBlockState(worldIn, structureBoundingBoxIn, i + 7, j + 5, k + 7, Blocks.AIR.getDefaultState());
			this.setBlockState(worldIn, structureBoundingBoxIn, i + 7, j + 5, k + 8, JourneyBlocks.corbaLog.getDefaultState());
			this.setBlockState(worldIn, structureBoundingBoxIn, i + 7, j + 5, k + 9, JourneyBlocks.corbaPlankStairs.getDefaultState().withProperty(BlockStairs.FACING, south));
			this.setBlockState(worldIn, structureBoundingBoxIn, i + 7, j + 5, k + 10, Blocks.AIR.getDefaultState());
			this.setBlockState(worldIn, structureBoundingBoxIn, i + 7, j + 6, k + 0, Blocks.AIR.getDefaultState());
			this.setBlockState(worldIn, structureBoundingBoxIn, i + 7, j + 6, k + 1, Blocks.AIR.getDefaultState());
			this.setBlockState(worldIn, structureBoundingBoxIn, i + 7, j + 6, k + 2, JourneyBlocks.corbaPlankStairs.getDefaultState().withProperty(BlockStairs.FACING, north));
			this.setBlockState(worldIn, structureBoundingBoxIn, i + 7, j + 6, k + 3, JourneyBlocks.corbaLog.getDefaultState());
			this.setBlockState(worldIn, structureBoundingBoxIn, i + 7, j + 6, k + 4, Blocks.AIR.getDefaultState());
			this.setBlockState(worldIn, structureBoundingBoxIn, i + 7, j + 6, k + 5, Blocks.AIR.getDefaultState());
			this.setBlockState(worldIn, structureBoundingBoxIn, i + 7, j + 6, k + 6, Blocks.AIR.getDefaultState());
			this.setBlockState(worldIn, structureBoundingBoxIn, i + 7, j + 6, k + 7, JourneyBlocks.corbaLog.getDefaultState());
			this.setBlockState(worldIn, structureBoundingBoxIn, i + 7, j + 6, k + 8, JourneyBlocks.corbaPlankStairs.getDefaultState().withProperty(BlockStairs.FACING, south));
			this.setBlockState(worldIn, structureBoundingBoxIn, i + 7, j + 6, k + 9, Blocks.AIR.getDefaultState());
			this.setBlockState(worldIn, structureBoundingBoxIn, i + 7, j + 6, k + 10, Blocks.AIR.getDefaultState());
			this.setBlockState(worldIn, structureBoundingBoxIn, i + 7, j + 7, k + 0, Blocks.AIR.getDefaultState());
			this.setBlockState(worldIn, structureBoundingBoxIn, i + 7, j + 7, k + 1, Blocks.AIR.getDefaultState());
			this.setBlockState(worldIn, structureBoundingBoxIn, i + 7, j + 7, k + 2, Blocks.AIR.getDefaultState());
			this.setBlockState(worldIn, structureBoundingBoxIn, i + 7, j + 7, k + 3, JourneyBlocks.corbaPlankStairs.getDefaultState().withProperty(BlockStairs.FACING, north));
			this.setBlockState(worldIn, structureBoundingBoxIn, i + 7, j + 7, k + 4, JourneyBlocks.corbaLog.getDefaultState());
			this.setBlockState(worldIn, structureBoundingBoxIn, i + 7, j + 7, k + 5, Blocks.AIR.getDefaultState());
			this.setBlockState(worldIn, structureBoundingBoxIn, i + 7, j + 7, k + 6, JourneyBlocks.corbaLog.getDefaultState());
			this.setBlockState(worldIn, structureBoundingBoxIn, i + 7, j + 7, k + 7, JourneyBlocks.corbaPlankStairs.getDefaultState().withProperty(BlockStairs.FACING, south));
			this.setBlockState(worldIn, structureBoundingBoxIn, i + 7, j + 7, k + 8, Blocks.AIR.getDefaultState());
			this.setBlockState(worldIn, structureBoundingBoxIn, i + 7, j + 7, k + 9, Blocks.AIR.getDefaultState());
			this.setBlockState(worldIn, structureBoundingBoxIn, i + 7, j + 7, k + 10, Blocks.AIR.getDefaultState());
			this.setBlockState(worldIn, structureBoundingBoxIn, i + 7, j + 8, k + 0, Blocks.AIR.getDefaultState());
			this.setBlockState(worldIn, structureBoundingBoxIn, i + 7, j + 8, k + 1, Blocks.AIR.getDefaultState());
			this.setBlockState(worldIn, structureBoundingBoxIn, i + 7, j + 8, k + 2, Blocks.AIR.getDefaultState());
			this.setBlockState(worldIn, structureBoundingBoxIn, i + 7, j + 8, k + 3, Blocks.AIR.getDefaultState());
			this.setBlockState(worldIn, structureBoundingBoxIn, i + 7, j + 8, k + 4, JourneyBlocks.corbaPlankStairs.getDefaultState().withProperty(BlockStairs.FACING, north));
			this.setBlockState(worldIn, structureBoundingBoxIn, i + 7, j + 8, k + 5, JourneyBlocks.corbaLog.getDefaultState());
			this.setBlockState(worldIn, structureBoundingBoxIn, i + 7, j + 8, k + 6, JourneyBlocks.corbaPlankStairs.getDefaultState().withProperty(BlockStairs.FACING, south));
			this.setBlockState(worldIn, structureBoundingBoxIn, i + 7, j + 8, k + 7, Blocks.AIR.getDefaultState());
			this.setBlockState(worldIn, structureBoundingBoxIn, i + 7, j + 8, k + 8, Blocks.AIR.getDefaultState());
			this.setBlockState(worldIn, structureBoundingBoxIn, i + 7, j + 8, k + 9, Blocks.AIR.getDefaultState());
			this.setBlockState(worldIn, structureBoundingBoxIn, i + 7, j + 8, k + 10, Blocks.AIR.getDefaultState());
			this.setBlockState(worldIn, structureBoundingBoxIn, i + 7, j + 9, k + 0, Blocks.AIR.getDefaultState());
			this.setBlockState(worldIn, structureBoundingBoxIn, i + 7, j + 9, k + 1, Blocks.AIR.getDefaultState());
			this.setBlockState(worldIn, structureBoundingBoxIn, i + 7, j + 9, k + 2, Blocks.AIR.getDefaultState());
			this.setBlockState(worldIn, structureBoundingBoxIn, i + 7, j + 9, k + 3, Blocks.AIR.getDefaultState());
			this.setBlockState(worldIn, structureBoundingBoxIn, i + 7, j + 9, k + 4, Blocks.AIR.getDefaultState());
			this.setBlockState(worldIn, structureBoundingBoxIn, i + 7, j + 9, k + 5, JourneyBlocks.corbaPlank.getDefaultState());
			this.setBlockState(worldIn, structureBoundingBoxIn, i + 7, j + 9, k + 6, Blocks.AIR.getDefaultState());
			this.setBlockState(worldIn, structureBoundingBoxIn, i + 7, j + 9, k + 7, Blocks.AIR.getDefaultState());
			this.setBlockState(worldIn, structureBoundingBoxIn, i + 7, j + 9, k + 8, Blocks.AIR.getDefaultState());
			this.setBlockState(worldIn, structureBoundingBoxIn, i + 7, j + 9, k + 9, Blocks.AIR.getDefaultState());
			this.setBlockState(worldIn, structureBoundingBoxIn, i + 7, j + 9, k + 10, Blocks.AIR.getDefaultState());
			this.setBlockState(worldIn, structureBoundingBoxIn, i + 8, j + 0, k + 0, JourneyBlocks.corbaCobblestone.getDefaultState());
			this.setBlockState(worldIn, structureBoundingBoxIn, i + 8, j + 0, k + 1, JourneyBlocks.corbaCobblestone.getDefaultState());
			this.setBlockState(worldIn, structureBoundingBoxIn, i + 8, j + 0, k + 2, JourneyBlocks.corbaCobblestone.getDefaultState());
			this.setBlockState(worldIn, structureBoundingBoxIn, i + 8, j + 0, k + 3, JourneyBlocks.corbaCobblestone.getDefaultState());
			this.setBlockState(worldIn, structureBoundingBoxIn, i + 8, j + 0, k + 4, JourneyBlocks.corbaCobblestone.getDefaultState());
			this.setBlockState(worldIn, structureBoundingBoxIn, i + 8, j + 0, k + 5, JourneyBlocks.corbaCobblestone.getDefaultState());
