package net.journey.dimension.corba.gen;

import java.util.Random;

import net.journey.JourneyBlocks;
import net.journey.entity.mob.corba.npc.EntityRedTordo;
import net.journey.entity.mob.corba.npc.EntityTordo;
import net.journey.util.enums.EnumTypeLogs;
import net.minecraft.util.math.BlockPos;
import net.minecraft.world.World;
import net.minecraft.world.gen.feature.WorldGenerator;
import net.slayer.api.block.BlockModLog;

public class WorldGenCorbaVillage extends WorldGenerator {
	
	public boolean locationIsValidSpawn(World w, int x, int y, int z) {
		for(int i = 0; i < 11; i++) {
			for(int l = 0; l < 11; l++) {
				if(w.getBlockState(new BlockPos(x + i, y, z + l)) != JourneyBlocks.corbaGrass) {
					return false;
				}
			}
		}
		return true;
	}
	
	@Override
	public boolean generate(World w, Random r, BlockPos pos) {
		int i = pos.getX(), j = pos.getY() - 1, k = pos.getZ();
		if(locationIsValidSpawn(w, i, j, k)) return true;

		w.setBlockState(new BlockPos(i + 0, j + 1, k + 4), JourneyBlocks.logs.getDefaultState().withProperty(BlockModLog.VARIANT, EnumTypeLogs.EnumType.CORBA_LOG));
		w.setBlockState(new BlockPos(i + 0, j + 1, k + 5), JourneyBlocks.corbaPlank.getDefaultState());
		w.setBlockState(new BlockPos(i + 0, j + 1, k + 7), JourneyBlocks.corbaPlank.getDefaultState());
		w.setBlockState(new BlockPos(i + 0, j + 1, k + 8), JourneyBlocks.logs.getDefaultState().withProperty(BlockModLog.VARIANT, EnumTypeLogs.EnumType.CORBA_LOG));
		w.setBlockState(new BlockPos(i + 0, j + 2, k + 4), JourneyBlocks.logs.getDefaultState().withProperty(BlockModLog.VARIANT, EnumTypeLogs.EnumType.CORBA_LOG));
		w.setBlockState(new BlockPos(i + 0, j + 2, k + 5), JourneyBlocks.corbaPlank.getDefaultState());
		w.setBlockState(new BlockPos(i + 0, j + 2, k + 7), JourneyBlocks.corbaPlank.getDefaultState());
		w.setBlockState(new BlockPos(i + 0, j + 2, k + 8), JourneyBlocks.logs.getDefaultState().withProperty(BlockModLog.VARIANT, EnumTypeLogs.EnumType.CORBA_LOG));
		w.setBlockState(new BlockPos(i + 0, j + 3, k + 4), JourneyBlocks.logs.getDefaultState().withProperty(BlockModLog.VARIANT, EnumTypeLogs.EnumType.CORBA_LOG));
		w.setBlockState(new BlockPos(i + 0, j + 3, k + 5), JourneyBlocks.corbaPlank.getDefaultState());
		w.setBlockState(new BlockPos(i + 0, j + 3, k + 6), JourneyBlocks.corbaPlank.getDefaultState());
		w.setBlockState(new BlockPos(i + 0, j + 3, k + 7), JourneyBlocks.corbaPlank.getDefaultState());
		w.setBlockState(new BlockPos(i + 0, j + 3, k + 8), JourneyBlocks.logs.getDefaultState().withProperty(BlockModLog.VARIANT, EnumTypeLogs.EnumType.CORBA_LOG));
		w.setBlockState(new BlockPos(i + 0, j + 4, k + 5), JourneyBlocks.logs.getDefaultState().withProperty(BlockModLog.VARIANT, EnumTypeLogs.EnumType.CORBA_LOG));
		w.setBlockState(new BlockPos(i + 0, j + 4, k + 6), JourneyBlocks.logs.getDefaultState().withProperty(BlockModLog.VARIANT, EnumTypeLogs.EnumType.CORBA_LOG));
		w.setBlockState(new BlockPos(i + 0, j + 4, k + 7), JourneyBlocks.logs.getDefaultState().withProperty(BlockModLog.VARIANT, EnumTypeLogs.EnumType.CORBA_LOG));
		w.setBlockState(new BlockPos(i + 0, j + 5, k + 5), JourneyBlocks.corbaPost.getDefaultState());
		w.setBlockState(new BlockPos(i + 0, j + 5, k + 6), JourneyBlocks.corbaPost.getDefaultState());
		w.setBlockState(new BlockPos(i + 0, j + 5, k + 7), JourneyBlocks.corbaPost.getDefaultState());
		w.setBlockState(new BlockPos(i + 1, j + 0, k + 5), JourneyBlocks.corbaPlank.getDefaultState());
		w.setBlockState(new BlockPos(i + 1, j + 0, k + 6), JourneyBlocks.corbaPlank.getDefaultState());
		w.setBlockState(new BlockPos(i + 1, j + 0, k + 7), JourneyBlocks.corbaPlank.getDefaultState());
		w.setBlockState(new BlockPos(i + 1, j + 1, k + 4), JourneyBlocks.corbaPlank.getDefaultState());
		w.setBlockState(new BlockPos(i + 1, j + 1, k + 8), JourneyBlocks.corbaPlank.getDefaultState());
		w.setBlockState(new BlockPos(i + 1, j + 2, k + 4), JourneyBlocks.corbaPlank.getDefaultState());
		w.setBlockState(new BlockPos(i + 1, j + 2, k + 8), JourneyBlocks.corbaPlank.getDefaultState());
		w.setBlockState(new BlockPos(i + 1, j + 3, k + 4), JourneyBlocks.corbaPlank.getDefaultState());
		w.setBlockState(new BlockPos(i + 1, j + 3, k + 8), JourneyBlocks.corbaPlank.getDefaultState());
		w.setBlockState(new BlockPos(i + 1, j + 4, k + 4), JourneyBlocks.logs.getDefaultState().withProperty(BlockModLog.VARIANT, EnumTypeLogs.EnumType.CORBA_LOG));
		w.setBlockState(new BlockPos(i + 1, j + 4, k + 5), JourneyBlocks.corbaPlank.getDefaultState());
		w.setBlockState(new BlockPos(i + 1, j + 4, k + 6), JourneyBlocks.corbaPlank.getDefaultState());
		w.setBlockState(new BlockPos(i + 1, j + 4, k + 7), JourneyBlocks.corbaPlank.getDefaultState());
		w.setBlockState(new BlockPos(i + 1, j + 4, k + 8), JourneyBlocks.logs.getDefaultState().withProperty(BlockModLog.VARIANT, EnumTypeLogs.EnumType.CORBA_LOG));
		w.setBlockState(new BlockPos(i + 1, j + 5, k + 4), JourneyBlocks.corbaPost.getDefaultState());
		w.setBlockState(new BlockPos(i + 1, j + 5, k + 5), JourneyBlocks.corbaPost.getDefaultState());
		w.setBlockState(new BlockPos(i + 1, j + 5, k + 7), JourneyBlocks.corbaPost.getDefaultState());
		w.setBlockState(new BlockPos(i + 1, j + 5, k + 8), JourneyBlocks.corbaPost.getDefaultState());
		w.setBlockState(new BlockPos(i + 2, j + 0, k + 4), JourneyBlocks.corbaPlank.getDefaultState());
		w.setBlockState(new BlockPos(i + 2, j + 0, k + 5), JourneyBlocks.corbaPlank.getDefaultState());
		w.setBlockState(new BlockPos(i + 2, j + 0, k + 6), JourneyBlocks.corbaPlank.getDefaultState());
		w.setBlockState(new BlockPos(i + 2, j + 0, k + 7), JourneyBlocks.corbaPlank.getDefaultState());
		w.setBlockState(new BlockPos(i + 2, j + 0, k + 8), JourneyBlocks.corbaPlank.getDefaultState());
		w.setBlockState(new BlockPos(i + 2, j + 3, k + 4), JourneyBlocks.corbaPlank.getDefaultState());
		w.setBlockState(new BlockPos(i + 2, j + 3, k + 6), JourneyBlocks.corbaLamp.getDefaultState());
		w.setBlockState(new BlockPos(i + 2, j + 3, k + 8), JourneyBlocks.corbaPlank.getDefaultState());
		w.setBlockState(new BlockPos(i + 2, j + 4, k + 4), JourneyBlocks.logs.getDefaultState().withProperty(BlockModLog.VARIANT, EnumTypeLogs.EnumType.CORBA_LOG));
		w.setBlockState(new BlockPos(i + 2, j + 4, k + 5), JourneyBlocks.corbaPlank.getDefaultState());
		w.setBlockState(new BlockPos(i + 2, j + 4, k + 6), JourneyBlocks.corbaPlank.getDefaultState());
		w.setBlockState(new BlockPos(i + 2, j + 4, k + 7), JourneyBlocks.corbaPlank.getDefaultState());
		w.setBlockState(new BlockPos(i + 2, j + 4, k + 8), JourneyBlocks.logs.getDefaultState().withProperty(BlockModLog.VARIANT, EnumTypeLogs.EnumType.CORBA_LOG));
		w.setBlockState(new BlockPos(i + 2, j + 5, k + 4), JourneyBlocks.corbaPost.getDefaultState());
		w.setBlockState(new BlockPos(i + 2, j + 5, k + 8), JourneyBlocks.corbaPost.getDefaultState());
		w.setBlockState(new BlockPos(i + 3, j + 0, k + 5), JourneyBlocks.corbaPlank.getDefaultState());
		w.setBlockState(new BlockPos(i + 3, j + 0, k + 6), JourneyBlocks.corbaPlank.getDefaultState());
		w.setBlockState(new BlockPos(i + 3, j + 0, k + 7), JourneyBlocks.corbaPlank.getDefaultState());
		w.setBlockState(new BlockPos(i + 3, j + 1, k + 4), JourneyBlocks.corbaPlank.getDefaultState());
		w.setBlockState(new BlockPos(i + 3, j + 1, k + 8), JourneyBlocks.corbaPlank.getDefaultState());
		w.setBlockState(new BlockPos(i + 3, j + 2, k + 4), JourneyBlocks.corbaPlank.getDefaultState());
		w.setBlockState(new BlockPos(i + 3, j + 2, k + 8), JourneyBlocks.corbaPlank.getDefaultState());
		w.setBlockState(new BlockPos(i + 3, j + 3, k + 4), JourneyBlocks.corbaPlank.getDefaultState());
		w.setBlockState(new BlockPos(i + 3, j + 3, k + 8), JourneyBlocks.corbaPlank.getDefaultState());
		w.setBlockState(new BlockPos(i + 3, j + 4, k + 4), JourneyBlocks.logs.getDefaultState().withProperty(BlockModLog.VARIANT, EnumTypeLogs.EnumType.CORBA_LOG));
		w.setBlockState(new BlockPos(i + 3, j + 4, k + 5), JourneyBlocks.corbaPlank.getDefaultState());
		w.setBlockState(new BlockPos(i + 3, j + 4, k + 6), JourneyBlocks.corbaPlank.getDefaultState());
		w.setBlockState(new BlockPos(i + 3, j + 4, k + 7), JourneyBlocks.corbaPlank.getDefaultState());
		w.setBlockState(new BlockPos(i + 3, j + 4, k + 8), JourneyBlocks.logs.getDefaultState().withProperty(BlockModLog.VARIANT, EnumTypeLogs.EnumType.CORBA_LOG));
		w.setBlockState(new BlockPos(i + 3, j + 5, k + 4), JourneyBlocks.corbaPost.getDefaultState());
		w.setBlockState(new BlockPos(i + 3, j + 5, k + 5), JourneyBlocks.corbaPost.getDefaultState());
		w.setBlockState(new BlockPos(i + 3, j + 5, k + 7), JourneyBlocks.corbaPost.getDefaultState());
		w.setBlockState(new BlockPos(i + 3, j + 5, k + 8), JourneyBlocks.corbaPost.getDefaultState());
		w.setBlockState(new BlockPos(i + 4, j + 0, k + 6), JourneyBlocks.corbaPlank.getDefaultState());
		w.setBlockState(new BlockPos(i + 4, j + 1, k + 4), JourneyBlocks.logs.getDefaultState().withProperty(BlockModLog.VARIANT, EnumTypeLogs.EnumType.CORBA_LOG));
		w.setBlockState(new BlockPos(i + 4, j + 1, k + 5), JourneyBlocks.corbaPlank.getDefaultState());
		w.setBlockState(new BlockPos(i + 4, j + 1, k + 7), JourneyBlocks.corbaPlank.getDefaultState());
		w.setBlockState(new BlockPos(i + 4, j + 1, k + 8), JourneyBlocks.logs.getDefaultState().withProperty(BlockModLog.VARIANT, EnumTypeLogs.EnumType.CORBA_LOG));
		w.setBlockState(new BlockPos(i + 4, j + 2, k + 4), JourneyBlocks.logs.getDefaultState().withProperty(BlockModLog.VARIANT, EnumTypeLogs.EnumType.CORBA_LOG));
		w.setBlockState(new BlockPos(i + 4, j + 2, k + 5), JourneyBlocks.corbaPlank.getDefaultState());
		w.setBlockState(new BlockPos(i + 4, j + 2, k + 7), JourneyBlocks.corbaPlank.getDefaultState());
		w.setBlockState(new BlockPos(i + 4, j + 2, k + 8), JourneyBlocks.logs.getDefaultState().withProperty(BlockModLog.VARIANT, EnumTypeLogs.EnumType.CORBA_LOG));
		w.setBlockState(new BlockPos(i + 4, j + 3, k + 4), JourneyBlocks.logs.getDefaultState().withProperty(BlockModLog.VARIANT, EnumTypeLogs.EnumType.CORBA_LOG));
		w.setBlockState(new BlockPos(i + 4, j + 3, k + 5), JourneyBlocks.corbaPlank.getDefaultState());
		w.setBlockState(new BlockPos(i + 4, j + 3, k + 6), JourneyBlocks.corbaPlank.getDefaultState());
		w.setBlockState(new BlockPos(i + 4, j + 3, k + 7), JourneyBlocks.corbaPlank.getDefaultState());
		w.setBlockState(new BlockPos(i + 4, j + 3, k + 8), JourneyBlocks.logs.getDefaultState().withProperty(BlockModLog.VARIANT, EnumTypeLogs.EnumType.CORBA_LOG));
		w.setBlockState(new BlockPos(i + 4, j + 4, k + 5), JourneyBlocks.logs.getDefaultState().withProperty(BlockModLog.VARIANT, EnumTypeLogs.EnumType.CORBA_LOG));
		w.setBlockState(new BlockPos(i + 4, j + 4, k + 6), JourneyBlocks.logs.getDefaultState().withProperty(BlockModLog.VARIANT, EnumTypeLogs.EnumType.CORBA_LOG));
		w.setBlockState(new BlockPos(i + 4, j + 4, k + 7), JourneyBlocks.logs.getDefaultState().withProperty(BlockModLog.VARIANT, EnumTypeLogs.EnumType.CORBA_LOG));
		w.setBlockState(new BlockPos(i + 4, j + 5, k + 5), JourneyBlocks.corbaPost.getDefaultState());
		w.setBlockState(new BlockPos(i + 4, j + 5, k + 6), JourneyBlocks.corbaPost.getDefaultState());
		w.setBlockState(new BlockPos(i + 4, j + 5, k + 7), JourneyBlocks.corbaPost.getDefaultState());
		w.setBlockState(new BlockPos(i + 5, j + 0, k + 5), JourneyBlocks.corbaPlank.getDefaultState());
		w.setBlockState(new BlockPos(i + 5, j + 0, k + 6), JourneyBlocks.corbaPlank.getDefaultState());
		w.setBlockState(new BlockPos(i + 5, j + 0, k + 7), JourneyBlocks.corbaPlank.getDefaultState());
		w.setBlockState(new BlockPos(i + 5, j + 1, k + 5), JourneyBlocks.corbaPost.getDefaultState());
		w.setBlockState(new BlockPos(i + 5, j + 1, k + 7), JourneyBlocks.corbaPost.getDefaultState());
		w.setBlockState(new BlockPos(i + 6, j + 0, k + 6), JourneyBlocks.corbaPlank.getDefaultState());
		w.setBlockState(new BlockPos(i + 6, j + 1, k + 5), JourneyBlocks.logs.getDefaultState().withProperty(BlockModLog.VARIANT, EnumTypeLogs.EnumType.CORBA_LOG));
		w.setBlockState(new BlockPos(i + 6, j + 1, k + 7), JourneyBlocks.logs.getDefaultState().withProperty(BlockModLog.VARIANT, EnumTypeLogs.EnumType.CORBA_LOG));
		w.setBlockState(new BlockPos(i + 6, j + 2, k + 5), JourneyBlocks.logs.getDefaultState().withProperty(BlockModLog.VARIANT, EnumTypeLogs.EnumType.CORBA_LOG));
		w.setBlockState(new BlockPos(i + 6, j + 2, k + 7), JourneyBlocks.logs.getDefaultState().withProperty(BlockModLog.VARIANT, EnumTypeLogs.EnumType.CORBA_LOG));
		w.setBlockState(new BlockPos(i + 6, j + 3, k + 5), JourneyBlocks.logs.getDefaultState().withProperty(BlockModLog.VARIANT, EnumTypeLogs.EnumType.CORBA_LOG));
		w.setBlockState(new BlockPos(i + 6, j + 3, k + 7), JourneyBlocks.logs.getDefaultState().withProperty(BlockModLog.VARIANT, EnumTypeLogs.EnumType.CORBA_LOG));
		w.setBlockState(new BlockPos(i + 6, j + 4, k + 6), JourneyBlocks.logs.getDefaultState().withProperty(BlockModLog.VARIANT, EnumTypeLogs.EnumType.CORBA_LOG));
		w.setBlockState(new BlockPos(i + 7, j + 0, k + 5), JourneyBlocks.corbaPlank.getDefaultState());
		w.setBlockState(new BlockPos(i + 7, j + 0, k + 6), JourneyBlocks.corbaPlank.getDefaultState());
		w.setBlockState(new BlockPos(i + 7, j + 1, k + 7), JourneyBlocks.corbaPlank.getDefaultState());
		w.setBlockState(new BlockPos(i + 7, j + 3, k + 5), JourneyBlocks.corbaPlank.getDefaultState());
		w.setBlockState(new BlockPos(i + 7, j + 3, k + 7), JourneyBlocks.corbaPlank.getDefaultState());
		w.setBlockState(new BlockPos(i + 7, j + 4, k + 6), JourneyBlocks.corbaPlank.getDefaultState());
		w.setBlockState(new BlockPos(i + 8, j + 0, k + 6), JourneyBlocks.corbaPlank.getDefaultState());
		w.setBlockState(new BlockPos(i + 8, j + 1, k + 5), JourneyBlocks.logs.getDefaultState().withProperty(BlockModLog.VARIANT, EnumTypeLogs.EnumType.CORBA_LOG));
		w.setBlockState(new BlockPos(i + 8, j + 1, k + 7), JourneyBlocks.logs.getDefaultState().withProperty(BlockModLog.VARIANT, EnumTypeLogs.EnumType.CORBA_LOG));
		w.setBlockState(new BlockPos(i + 8, j + 2, k + 5), JourneyBlocks.logs.getDefaultState().withProperty(BlockModLog.VARIANT, EnumTypeLogs.EnumType.CORBA_LOG));
		w.setBlockState(new BlockPos(i + 8, j + 2, k + 7), JourneyBlocks.logs.getDefaultState().withProperty(BlockModLog.VARIANT, EnumTypeLogs.EnumType.CORBA_LOG));
		w.setBlockState(new BlockPos(i + 8, j + 3, k + 5), JourneyBlocks.logs.getDefaultState().withProperty(BlockModLog.VARIANT, EnumTypeLogs.EnumType.CORBA_LOG));
		w.setBlockState(new BlockPos(i + 8, j + 3, k + 7), JourneyBlocks.logs.getDefaultState().withProperty(BlockModLog.VARIANT, EnumTypeLogs.EnumType.CORBA_LOG));
		w.setBlockState(new BlockPos(i + 8, j + 4, k + 6), JourneyBlocks.logs.getDefaultState().withProperty(BlockModLog.VARIANT, EnumTypeLogs.EnumType.CORBA_LOG));
		w.setBlockState(new BlockPos(i + 9, j + 0, k + 5), JourneyBlocks.corbaPlank.getDefaultState());
		w.setBlockState(new BlockPos(i + 9, j + 0, k + 6), JourneyBlocks.corbaPlank.getDefaultState());
		w.setBlockState(new BlockPos(i + 9, j + 0, k + 7), JourneyBlocks.corbaPlank.getDefaultState());
		w.setBlockState(new BlockPos(i + 9, j + 1, k + 5), JourneyBlocks.corbaPost.getDefaultState());
		w.setBlockState(new BlockPos(i + 9, j + 1, k + 7), JourneyBlocks.corbaPost.getDefaultState());
		w.setBlockState(new BlockPos(i + 10, j + 0, k + 5), JourneyBlocks.corbaPlank.getDefaultState());
		w.setBlockState(new BlockPos(i + 10, j + 0, k + 6), JourneyBlocks.corbaPlank.getDefaultState());
		w.setBlockState(new BlockPos(i + 10, j + 0, k + 7), JourneyBlocks.corbaPlank.getDefaultState());
		w.setBlockState(new BlockPos(i + 10, j + 1, k + 4), JourneyBlocks.logs.getDefaultState().withProperty(BlockModLog.VARIANT, EnumTypeLogs.EnumType.CORBA_LOG));
		w.setBlockState(new BlockPos(i + 10, j + 1, k + 5), JourneyBlocks.logs.getDefaultState().withProperty(BlockModLog.VARIANT, EnumTypeLogs.EnumType.CORBA_LOG));
		w.setBlockState(new BlockPos(i + 10, j + 1, k + 7), JourneyBlocks.logs.getDefaultState().withProperty(BlockModLog.VARIANT, EnumTypeLogs.EnumType.CORBA_LOG));
		w.setBlockState(new BlockPos(i + 10, j + 1, k + 8), JourneyBlocks.logs.getDefaultState().withProperty(BlockModLog.VARIANT, EnumTypeLogs.EnumType.CORBA_LOG));
		w.setBlockState(new BlockPos(i + 10, j + 2, k + 4), JourneyBlocks.logs.getDefaultState().withProperty(BlockModLog.VARIANT, EnumTypeLogs.EnumType.CORBA_LOG));
		w.setBlockState(new BlockPos(i + 10, j + 2, k + 8), JourneyBlocks.logs.getDefaultState().withProperty(BlockModLog.VARIANT, EnumTypeLogs.EnumType.CORBA_LOG));
		w.setBlockState(new BlockPos(i + 10, j + 6, k + 3), JourneyBlocks.logs.getDefaultState().withProperty(BlockModLog.VARIANT, EnumTypeLogs.EnumType.CORBA_LOG));
		w.setBlockState(new BlockPos(i + 10, j + 6, k + 4), JourneyBlocks.logs.getDefaultState().withProperty(BlockModLog.VARIANT, EnumTypeLogs.EnumType.CORBA_LOG));
		w.setBlockState(new BlockPos(i + 10, j + 6, k + 5), JourneyBlocks.logs.getDefaultState().withProperty(BlockModLog.VARIANT, EnumTypeLogs.EnumType.CORBA_LOG));
		w.setBlockState(new BlockPos(i + 10, j + 6, k + 6), JourneyBlocks.logs.getDefaultState().withProperty(BlockModLog.VARIANT, EnumTypeLogs.EnumType.CORBA_LOG));
		w.setBlockState(new BlockPos(i + 10, j + 6, k + 7), JourneyBlocks.logs.getDefaultState().withProperty(BlockModLog.VARIANT, EnumTypeLogs.EnumType.CORBA_LOG));
		w.setBlockState(new BlockPos(i + 10, j + 6, k + 8), JourneyBlocks.logs.getDefaultState().withProperty(BlockModLog.VARIANT, EnumTypeLogs.EnumType.CORBA_LOG));
		w.setBlockState(new BlockPos(i + 11, j + 1, k + 3), JourneyBlocks.logs.getDefaultState().withProperty(BlockModLog.VARIANT, EnumTypeLogs.EnumType.CORBA_LOG));
		w.setBlockState(new BlockPos(i + 11, j + 1, k + 4), JourneyBlocks.logs.getDefaultState().withProperty(BlockModLog.VARIANT, EnumTypeLogs.EnumType.CORBA_LOG));
		w.setBlockState(new BlockPos(i + 11, j + 1, k + 5), JourneyBlocks.corbaPlank.getDefaultState());
		w.setBlockState(new BlockPos(i + 11, j + 1, k + 6), JourneyBlocks.corbaPlank.getDefaultState());
		w.setBlockState(new BlockPos(i + 11, j + 1, k + 7), JourneyBlocks.corbaPlank.getDefaultState());
		w.setBlockState(new BlockPos(i + 11, j + 1, k + 8), JourneyBlocks.logs.getDefaultState().withProperty(BlockModLog.VARIANT, EnumTypeLogs.EnumType.CORBA_LOG));
		w.setBlockState(new BlockPos(i + 11, j + 1, k + 9), JourneyBlocks.logs.getDefaultState().withProperty(BlockModLog.VARIANT, EnumTypeLogs.EnumType.CORBA_LOG));
		w.setBlockState(new BlockPos(i + 11, j + 2, k + 3), JourneyBlocks.logs.getDefaultState().withProperty(BlockModLog.VARIANT, EnumTypeLogs.EnumType.CORBA_LOG));
		w.setBlockState(new BlockPos(i + 11, j + 2, k + 4), JourneyBlocks.logs.getDefaultState().withProperty(BlockModLog.VARIANT, EnumTypeLogs.EnumType.CORBA_LOG));
		w.setBlockState(new BlockPos(i + 11, j + 2, k + 5), JourneyBlocks.corbaPlank.getDefaultState());
		w.setBlockState(new BlockPos(i + 11, j + 2, k + 6), JourneyBlocks.logs.getDefaultState().withProperty(BlockModLog.VARIANT, EnumTypeLogs.EnumType.CORBA_LOG));
		w.setBlockState(new BlockPos(i + 11, j + 2, k + 7), JourneyBlocks.corbaPlank.getDefaultState());
		w.setBlockState(new BlockPos(i + 11, j + 2, k + 8), JourneyBlocks.logs.getDefaultState().withProperty(BlockModLog.VARIANT, EnumTypeLogs.EnumType.CORBA_LOG));
		w.setBlockState(new BlockPos(i + 11, j + 2, k + 9), JourneyBlocks.logs.getDefaultState().withProperty(BlockModLog.VARIANT, EnumTypeLogs.EnumType.CORBA_LOG));
		w.setBlockState(new BlockPos(i + 11, j + 3, k + 4), JourneyBlocks.logs.getDefaultState().withProperty(BlockModLog.VARIANT, EnumTypeLogs.EnumType.CORBA_LOG));
		w.setBlockState(new BlockPos(i + 11, j + 3, k + 5), JourneyBlocks.corbaPlank.getDefaultState());
		w.setBlockState(new BlockPos(i + 11, j + 3, k + 7), JourneyBlocks.corbaPlank.getDefaultState());
		w.setBlockState(new BlockPos(i + 11, j + 3, k + 8), JourneyBlocks.logs.getDefaultState().withProperty(BlockModLog.VARIANT, EnumTypeLogs.EnumType.CORBA_LOG));
		w.setBlockState(new BlockPos(i + 11, j + 4, k + 4), JourneyBlocks.logs.getDefaultState().withProperty(BlockModLog.VARIANT, EnumTypeLogs.EnumType.CORBA_LOG));
		w.setBlockState(new BlockPos(i + 11, j + 4, k + 5), JourneyBlocks.corbaPlank.getDefaultState());
		w.setBlockState(new BlockPos(i + 11, j + 4, k + 7), JourneyBlocks.corbaPlank.getDefaultState());
		w.setBlockState(new BlockPos(i + 11, j + 4, k + 8), JourneyBlocks.logs.getDefaultState().withProperty(BlockModLog.VARIANT, EnumTypeLogs.EnumType.CORBA_LOG));
		w.setBlockState(new BlockPos(i + 11, j + 5, k + 4), JourneyBlocks.logs.getDefaultState().withProperty(BlockModLog.VARIANT, EnumTypeLogs.EnumType.CORBA_LOG));
		w.setBlockState(new BlockPos(i + 11, j + 5, k + 5), JourneyBlocks.corbaPlank.getDefaultState());
		w.setBlockState(new BlockPos(i + 11, j + 5, k + 6), JourneyBlocks.logs.getDefaultState().withProperty(BlockModLog.VARIANT, EnumTypeLogs.EnumType.CORBA_LOG));
		w.setBlockState(new BlockPos(i + 11, j + 5, k + 7), JourneyBlocks.corbaPlank.getDefaultState());
		w.setBlockState(new BlockPos(i + 11, j + 5, k + 8), JourneyBlocks.logs.getDefaultState().withProperty(BlockModLog.VARIANT, EnumTypeLogs.EnumType.CORBA_LOG));
		w.setBlockState(new BlockPos(i + 11, j + 6, k + 2), JourneyBlocks.logs.getDefaultState().withProperty(BlockModLog.VARIANT, EnumTypeLogs.EnumType.CORBA_LOG));
		w.setBlockState(new BlockPos(i + 11, j + 6, k + 3), JourneyBlocks.logs.getDefaultState().withProperty(BlockModLog.VARIANT, EnumTypeLogs.EnumType.CORBA_LOG));
		w.setBlockState(new BlockPos(i + 11, j + 6, k + 4), JourneyBlocks.logs.getDefaultState().withProperty(BlockModLog.VARIANT, EnumTypeLogs.EnumType.CORBA_LOG));
		w.setBlockState(new BlockPos(i + 11, j + 6, k + 5), JourneyBlocks.corbaPlank.getDefaultState());
		w.setBlockState(new BlockPos(i + 11, j + 6, k + 6), JourneyBlocks.corbaPlank.getDefaultState());
		w.setBlockState(new BlockPos(i + 11, j + 6, k + 7), JourneyBlocks.corbaPlank.getDefaultState());
		w.setBlockState(new BlockPos(i + 11, j + 6, k + 8), JourneyBlocks.logs.getDefaultState().withProperty(BlockModLog.VARIANT, EnumTypeLogs.EnumType.CORBA_LOG));
		w.setBlockState(new BlockPos(i + 11, j + 6, k + 9), JourneyBlocks.logs.getDefaultState().withProperty(BlockModLog.VARIANT, EnumTypeLogs.EnumType.CORBA_LOG));
		w.setBlockState(new BlockPos(i + 11, j + 7, k + 3), JourneyBlocks.corbaPlank.getDefaultState());
		w.setBlockState(new BlockPos(i + 11, j + 7, k + 4), JourneyBlocks.corbaPlank.getDefaultState());
		w.setBlockState(new BlockPos(i + 11, j + 7, k + 5), JourneyBlocks.corbaPlank.getDefaultState());
		w.setBlockState(new BlockPos(i + 11, j + 7, k + 6), JourneyBlocks.corbaPlank.getDefaultState());
		w.setBlockState(new BlockPos(i + 11, j + 7, k + 7), JourneyBlocks.corbaPlank.getDefaultState());
		w.setBlockState(new BlockPos(i + 11, j + 7, k + 8), JourneyBlocks.corbaPlank.getDefaultState());
		w.setBlockState(new BlockPos(i + 12, j + 0, k + 5), JourneyBlocks.corbaPlank.getDefaultState());
		w.setBlockState(new BlockPos(i + 12, j + 0, k + 6), JourneyBlocks.corbaPlank.getDefaultState());
		w.setBlockState(new BlockPos(i + 12, j + 0, k + 7), JourneyBlocks.corbaPlank.getDefaultState());
		w.setBlockState(new BlockPos(i + 12, j + 1, k + 4), JourneyBlocks.corbaPlank.getDefaultState());
		w.setBlockState(new BlockPos(i + 12, j + 1, k + 8), JourneyBlocks.corbaPlank.getDefaultState());
		w.setBlockState(new BlockPos(i + 12, j + 2, k + 4), JourneyBlocks.corbaPlank.getDefaultState());
		w.setBlockState(new BlockPos(i + 12, j + 2, k + 8), JourneyBlocks.corbaPlank.getDefaultState());
		w.setBlockState(new BlockPos(i + 12, j + 5, k + 4), JourneyBlocks.corbaPlank.getDefaultState());
		w.setBlockState(new BlockPos(i + 12, j + 5, k + 8), JourneyBlocks.corbaPlank.getDefaultState());
		w.setBlockState(new BlockPos(i + 12, j + 6, k + 4), JourneyBlocks.corbaPlank.getDefaultState());
		w.setBlockState(new BlockPos(i + 12, j + 6, k + 8), JourneyBlocks.corbaPlank.getDefaultState());
		w.setBlockState(new BlockPos(i + 12, j + 7, k + 2), JourneyBlocks.logs.getDefaultState().withProperty(BlockModLog.VARIANT, EnumTypeLogs.EnumType.CORBA_LOG));
		w.setBlockState(new BlockPos(i + 12, j + 7, k + 3), JourneyBlocks.logs.getDefaultState().withProperty(BlockModLog.VARIANT, EnumTypeLogs.EnumType.CORBA_LOG));
		w.setBlockState(new BlockPos(i + 12, j + 7, k + 4), JourneyBlocks.logs.getDefaultState().withProperty(BlockModLog.VARIANT, EnumTypeLogs.EnumType.CORBA_LOG));
		w.setBlockState(new BlockPos(i + 12, j + 7, k + 8), JourneyBlocks.logs.getDefaultState().withProperty(BlockModLog.VARIANT, EnumTypeLogs.EnumType.CORBA_LOG));
		w.setBlockState(new BlockPos(i + 12, j + 7, k + 9), JourneyBlocks.logs.getDefaultState().withProperty(BlockModLog.VARIANT, EnumTypeLogs.EnumType.CORBA_LOG));
		w.setBlockState(new BlockPos(i + 12, j + 8, k + 3), JourneyBlocks.corbaPlank.getDefaultState());
		w.setBlockState(new BlockPos(i + 12, j + 8, k + 4), JourneyBlocks.corbaPlank.getDefaultState());
		w.setBlockState(new BlockPos(i + 12, j + 8, k + 5), JourneyBlocks.corbaPlank.getDefaultState());
		w.setBlockState(new BlockPos(i + 12, j + 8, k + 6), JourneyBlocks.corbaPlank.getDefaultState());
		w.setBlockState(new BlockPos(i + 12, j + 8, k + 7), JourneyBlocks.corbaPlank.getDefaultState());
		w.setBlockState(new BlockPos(i + 12, j + 8, k + 8), JourneyBlocks.corbaPlank.getDefaultState());
		w.setBlockState(new BlockPos(i + 13, j + 0, k + 4), JourneyBlocks.corbaPlank.getDefaultState());
		w.setBlockState(new BlockPos(i + 13, j + 0, k + 5), JourneyBlocks.corbaPlank.getDefaultState());
		w.setBlockState(new BlockPos(i + 13, j + 0, k + 6), JourneyBlocks.corbaPlank.getDefaultState());
		w.setBlockState(new BlockPos(i + 13, j + 0, k + 7), JourneyBlocks.corbaPlank.getDefaultState());
		w.setBlockState(new BlockPos(i + 13, j + 1, k + 4), JourneyBlocks.logs.getDefaultState().withProperty(BlockModLog.VARIANT, EnumTypeLogs.EnumType.CORBA_LOG));
		w.setBlockState(new BlockPos(i + 13, j + 1, k + 8), JourneyBlocks.logs.getDefaultState().withProperty(BlockModLog.VARIANT, EnumTypeLogs.EnumType.CORBA_LOG));
		w.setBlockState(new BlockPos(i + 13, j + 2, k + 4), JourneyBlocks.logs.getDefaultState().withProperty(BlockModLog.VARIANT, EnumTypeLogs.EnumType.CORBA_LOG));
		w.setBlockState(new BlockPos(i + 13, j + 2, k + 8), JourneyBlocks.logs.getDefaultState().withProperty(BlockModLog.VARIANT, EnumTypeLogs.EnumType.CORBA_LOG));
		w.setBlockState(new BlockPos(i + 13, j + 3, k + 4), JourneyBlocks.logs.getDefaultState().withProperty(BlockModLog.VARIANT, EnumTypeLogs.EnumType.CORBA_LOG));
		w.setBlockState(new BlockPos(i + 13, j + 3, k + 8), JourneyBlocks.logs.getDefaultState().withProperty(BlockModLog.VARIANT, EnumTypeLogs.EnumType.CORBA_LOG));
		w.setBlockState(new BlockPos(i + 13, j + 4, k + 4), JourneyBlocks.logs.getDefaultState().withProperty(BlockModLog.VARIANT, EnumTypeLogs.EnumType.CORBA_LOG));
		w.setBlockState(new BlockPos(i + 13, j + 4, k + 8), JourneyBlocks.logs.getDefaultState().withProperty(BlockModLog.VARIANT, EnumTypeLogs.EnumType.CORBA_LOG));
		w.setBlockState(new BlockPos(i + 13, j + 5, k + 4), JourneyBlocks.logs.getDefaultState().withProperty(BlockModLog.VARIANT, EnumTypeLogs.EnumType.CORBA_LOG));
		w.setBlockState(new BlockPos(i + 13, j + 5, k + 8), JourneyBlocks.logs.getDefaultState().withProperty(BlockModLog.VARIANT, EnumTypeLogs.EnumType.CORBA_LOG));
		w.setBlockState(new BlockPos(i + 13, j + 6, k + 4), JourneyBlocks.logs.getDefaultState().withProperty(BlockModLog.VARIANT, EnumTypeLogs.EnumType.CORBA_LOG));
		w.setBlockState(new BlockPos(i + 13, j + 6, k + 8), JourneyBlocks.logs.getDefaultState().withProperty(BlockModLog.VARIANT, EnumTypeLogs.EnumType.CORBA_LOG));
		w.setBlockState(new BlockPos(i + 13, j + 7, k + 1), JourneyBlocks.logs.getDefaultState().withProperty(BlockModLog.VARIANT, EnumTypeLogs.EnumType.CORBA_LOG));
		w.setBlockState(new BlockPos(i + 13, j + 7, k + 2), JourneyBlocks.logs.getDefaultState().withProperty(BlockModLog.VARIANT, EnumTypeLogs.EnumType.CORBA_LOG));
		w.setBlockState(new BlockPos(i + 13, j + 7, k + 3), JourneyBlocks.logs.getDefaultState().withProperty(BlockModLog.VARIANT, EnumTypeLogs.EnumType.CORBA_LOG));
		w.setBlockState(new BlockPos(i + 13, j + 7, k + 4), JourneyBlocks.logs.getDefaultState().withProperty(BlockModLog.VARIANT, EnumTypeLogs.EnumType.CORBA_LOG));
		w.setBlockState(new BlockPos(i + 13, j + 7, k + 8), JourneyBlocks.logs.getDefaultState().withProperty(BlockModLog.VARIANT, EnumTypeLogs.EnumType.CORBA_LOG));
		w.setBlockState(new BlockPos(i + 13, j + 7, k + 9), JourneyBlocks.logs.getDefaultState().withProperty(BlockModLog.VARIANT, EnumTypeLogs.EnumType.CORBA_LOG));
		w.setBlockState(new BlockPos(i + 13, j + 8, k + 2), JourneyBlocks.corbaPlank.getDefaultState());
		w.setBlockState(new BlockPos(i + 13, j + 8, k + 3), JourneyBlocks.corbaPlank.getDefaultState());
		w.setBlockState(new BlockPos(i + 13, j + 8, k + 4), JourneyBlocks.corbaPlank.getDefaultState());
		w.setBlockState(new BlockPos(i + 13, j + 8, k + 5), JourneyBlocks.corbaPlank.getDefaultState());
		w.setBlockState(new BlockPos(i + 13, j + 8, k + 6), JourneyBlocks.corbaPlank.getDefaultState());
		w.setBlockState(new BlockPos(i + 13, j + 8, k + 7), JourneyBlocks.corbaPlank.getDefaultState());
		w.setBlockState(new BlockPos(i + 13, j + 8, k + 8), JourneyBlocks.corbaPlank.getDefaultState());
		w.setBlockState(new BlockPos(i + 13, j + 8, k + 9), JourneyBlocks.corbaPlank.getDefaultState());
		w.setBlockState(new BlockPos(i + 14, j + 0, k + 4), JourneyBlocks.corbaPlank.getDefaultState());
		w.setBlockState(new BlockPos(i + 14, j + 0, k + 5), JourneyBlocks.corbaPlank.getDefaultState());
		w.setBlockState(new BlockPos(i + 14, j + 0, k + 6), JourneyBlocks.corbaPlank.getDefaultState());
		w.setBlockState(new BlockPos(i + 14, j + 0, k + 7), JourneyBlocks.corbaPlank.getDefaultState());
		w.setBlockState(new BlockPos(i + 14, j + 1, k + 8), JourneyBlocks.logs.getDefaultState().withProperty(BlockModLog.VARIANT, EnumTypeLogs.EnumType.CORBA_LOG));
		w.setBlockState(new BlockPos(i + 14, j + 2, k + 8), JourneyBlocks.corbaPlank.getDefaultState());
		w.setBlockState(new BlockPos(i + 14, j + 4, k + 4), JourneyBlocks.corbaPlank.getDefaultState());
		w.setBlockState(new BlockPos(i + 14, j + 5, k + 4), JourneyBlocks.corbaPlank.getDefaultState());
		w.setBlockState(new BlockPos(i + 14, j + 5, k + 6), JourneyBlocks.corbaLamp.getDefaultState());
		w.setBlockState(new BlockPos(i + 14, j + 5, k + 8), JourneyBlocks.logs.getDefaultState().withProperty(BlockModLog.VARIANT, EnumTypeLogs.EnumType.CORBA_LOG));
		w.setBlockState(new BlockPos(i + 14, j + 6, k + 4), JourneyBlocks.logs.getDefaultState().withProperty(BlockModLog.VARIANT, EnumTypeLogs.EnumType.CORBA_LOG));
		w.setBlockState(new BlockPos(i + 14, j + 6, k + 6), JourneyBlocks.corbaPost.getDefaultState());
		w.setBlockState(new BlockPos(i + 14, j + 6, k + 8), JourneyBlocks.logs.getDefaultState().withProperty(BlockModLog.VARIANT, EnumTypeLogs.EnumType.CORBA_LOG));
		w.setBlockState(new BlockPos(i + 14, j + 7, k + 4), JourneyBlocks.logs.getDefaultState().withProperty(BlockModLog.VARIANT, EnumTypeLogs.EnumType.CORBA_LOG));
		w.setBlockState(new BlockPos(i + 14, j + 7, k + 6), JourneyBlocks.corbaPost.getDefaultState());
		w.setBlockState(new BlockPos(i + 14, j + 7, k + 8), JourneyBlocks.logs.getDefaultState().withProperty(BlockModLog.VARIANT, EnumTypeLogs.EnumType.CORBA_LOG));
		w.setBlockState(new BlockPos(i + 14, j + 8, k + 0), JourneyBlocks.logs.getDefaultState().withProperty(BlockModLog.VARIANT, EnumTypeLogs.EnumType.CORBA_LOG));
		w.setBlockState(new BlockPos(i + 14, j + 8, k + 1), JourneyBlocks.logs.getDefaultState().withProperty(BlockModLog.VARIANT, EnumTypeLogs.EnumType.CORBA_LOG));
		w.setBlockState(new BlockPos(i + 14, j + 8, k + 2), JourneyBlocks.logs.getDefaultState().withProperty(BlockModLog.VARIANT, EnumTypeLogs.EnumType.CORBA_LOG));
		w.setBlockState(new BlockPos(i + 14, j + 8, k + 3), JourneyBlocks.logs.getDefaultState().withProperty(BlockModLog.VARIANT, EnumTypeLogs.EnumType.CORBA_LOG));
		w.setBlockState(new BlockPos(i + 14, j + 8, k + 4), JourneyBlocks.logs.getDefaultState().withProperty(BlockModLog.VARIANT, EnumTypeLogs.EnumType.CORBA_LOG));
		w.setBlockState(new BlockPos(i + 14, j + 8, k + 6), JourneyBlocks.corbaPost.getDefaultState());
		w.setBlockState(new BlockPos(i + 14, j + 8, k + 8), JourneyBlocks.logs.getDefaultState().withProperty(BlockModLog.VARIANT, EnumTypeLogs.EnumType.CORBA_LOG));
		w.setBlockState(new BlockPos(i + 14, j + 8, k + 9), JourneyBlocks.logs.getDefaultState().withProperty(BlockModLog.VARIANT, EnumTypeLogs.EnumType.CORBA_LOG));
		w.setBlockState(new BlockPos(i + 14, j + 9, k + 1), JourneyBlocks.corbaPlank.getDefaultState());
		w.setBlockState(new BlockPos(i + 14, j + 9, k + 2), JourneyBlocks.corbaPlank.getDefaultState());
		w.setBlockState(new BlockPos(i + 14, j + 9, k + 3), JourneyBlocks.corbaPlank.getDefaultState());
		w.setBlockState(new BlockPos(i + 14, j + 9, k + 4), JourneyBlocks.corbaPlank.getDefaultState());
		w.setBlockState(new BlockPos(i + 14, j + 9, k + 5), JourneyBlocks.corbaPlank.getDefaultState());
		w.setBlockState(new BlockPos(i + 14, j + 9, k + 6), JourneyBlocks.corbaPlank.getDefaultState());
		w.setBlockState(new BlockPos(i + 14, j + 9, k + 7), JourneyBlocks.corbaPlank.getDefaultState());
		w.setBlockState(new BlockPos(i + 14, j + 9, k + 8), JourneyBlocks.corbaPlank.getDefaultState());
		w.setBlockState(new BlockPos(i + 14, j + 9, k + 9), JourneyBlocks.corbaPlank.getDefaultState());
		w.setBlockState(new BlockPos(i + 15, j + 0, k + 4), JourneyBlocks.corbaPlank.getDefaultState());
		w.setBlockState(new BlockPos(i + 15, j + 0, k + 5), JourneyBlocks.corbaPlank.getDefaultState());
		w.setBlockState(new BlockPos(i + 15, j + 0, k + 6), JourneyBlocks.corbaPlank.getDefaultState());
		w.setBlockState(new BlockPos(i + 15, j + 0, k + 7), JourneyBlocks.corbaPlank.getDefaultState());
		w.setBlockState(new BlockPos(i + 15, j + 1, k + 4), JourneyBlocks.logs.getDefaultState().withProperty(BlockModLog.VARIANT, EnumTypeLogs.EnumType.CORBA_LOG));
		w.setBlockState(new BlockPos(i + 15, j + 1, k + 8), JourneyBlocks.logs.getDefaultState().withProperty(BlockModLog.VARIANT, EnumTypeLogs.EnumType.CORBA_LOG));
		w.setBlockState(new BlockPos(i + 15, j + 2, k + 4), JourneyBlocks.logs.getDefaultState().withProperty(BlockModLog.VARIANT, EnumTypeLogs.EnumType.CORBA_LOG));
		w.setBlockState(new BlockPos(i + 15, j + 2, k + 8), JourneyBlocks.logs.getDefaultState().withProperty(BlockModLog.VARIANT, EnumTypeLogs.EnumType.CORBA_LOG));
		w.setBlockState(new BlockPos(i + 15, j + 3, k + 4), JourneyBlocks.logs.getDefaultState().withProperty(BlockModLog.VARIANT, EnumTypeLogs.EnumType.CORBA_LOG));
		w.setBlockState(new BlockPos(i + 15, j + 3, k + 8), JourneyBlocks.logs.getDefaultState().withProperty(BlockModLog.VARIANT, EnumTypeLogs.EnumType.CORBA_LOG));
		w.setBlockState(new BlockPos(i + 15, j + 4, k + 4), JourneyBlocks.logs.getDefaultState().withProperty(BlockModLog.VARIANT, EnumTypeLogs.EnumType.CORBA_LOG));
		w.setBlockState(new BlockPos(i + 15, j + 4, k + 8), JourneyBlocks.logs.getDefaultState().withProperty(BlockModLog.VARIANT, EnumTypeLogs.EnumType.CORBA_LOG));
		w.setBlockState(new BlockPos(i + 15, j + 5, k + 4), JourneyBlocks.logs.getDefaultState().withProperty(BlockModLog.VARIANT, EnumTypeLogs.EnumType.CORBA_LOG));
		w.setBlockState(new BlockPos(i + 15, j + 5, k + 8), JourneyBlocks.logs.getDefaultState().withProperty(BlockModLog.VARIANT, EnumTypeLogs.EnumType.CORBA_LOG));
		w.setBlockState(new BlockPos(i + 15, j + 6, k + 4), JourneyBlocks.logs.getDefaultState().withProperty(BlockModLog.VARIANT, EnumTypeLogs.EnumType.CORBA_LOG));
		w.setBlockState(new BlockPos(i + 15, j + 6, k + 8), JourneyBlocks.logs.getDefaultState().withProperty(BlockModLog.VARIANT, EnumTypeLogs.EnumType.CORBA_LOG));
		w.setBlockState(new BlockPos(i + 15, j + 7, k + 1), JourneyBlocks.logs.getDefaultState().withProperty(BlockModLog.VARIANT, EnumTypeLogs.EnumType.CORBA_LOG));
		w.setBlockState(new BlockPos(i + 15, j + 7, k + 2), JourneyBlocks.logs.getDefaultState().withProperty(BlockModLog.VARIANT, EnumTypeLogs.EnumType.CORBA_LOG));
		w.setBlockState(new BlockPos(i + 15, j + 7, k + 3), JourneyBlocks.logs.getDefaultState().withProperty(BlockModLog.VARIANT, EnumTypeLogs.EnumType.CORBA_LOG));
		w.setBlockState(new BlockPos(i + 15, j + 7, k + 4), JourneyBlocks.logs.getDefaultState().withProperty(BlockModLog.VARIANT, EnumTypeLogs.EnumType.CORBA_LOG));
		w.setBlockState(new BlockPos(i + 15, j + 7, k + 8), JourneyBlocks.logs.getDefaultState().withProperty(BlockModLog.VARIANT, EnumTypeLogs.EnumType.CORBA_LOG));
		w.setBlockState(new BlockPos(i + 15, j + 7, k + 9), JourneyBlocks.logs.getDefaultState().withProperty(BlockModLog.VARIANT, EnumTypeLogs.EnumType.CORBA_LOG));
		w.setBlockState(new BlockPos(i + 15, j + 8, k + 2), JourneyBlocks.corbaPlank.getDefaultState());
		w.setBlockState(new BlockPos(i + 15, j + 8, k + 3), JourneyBlocks.corbaPlank.getDefaultState());
		w.setBlockState(new BlockPos(i + 15, j + 8, k + 4), JourneyBlocks.corbaPlank.getDefaultState());
		w.setBlockState(new BlockPos(i + 15, j + 8, k + 5), JourneyBlocks.corbaPlank.getDefaultState());
		w.setBlockState(new BlockPos(i + 15, j + 8, k + 6), JourneyBlocks.corbaPlank.getDefaultState());
		w.setBlockState(new BlockPos(i + 15, j + 8, k + 7), JourneyBlocks.corbaPlank.getDefaultState());
		w.setBlockState(new BlockPos(i + 15, j + 8, k + 8), JourneyBlocks.corbaPlank.getDefaultState());
		w.setBlockState(new BlockPos(i + 15, j + 8, k + 9), JourneyBlocks.corbaPlank.getDefaultState());
		w.setBlockState(new BlockPos(i + 16, j + 0, k + 5), JourneyBlocks.corbaPlank.getDefaultState());
		w.setBlockState(new BlockPos(i + 16, j + 0, k + 6), JourneyBlocks.corbaPlank.getDefaultState());
		w.setBlockState(new BlockPos(i + 16, j + 0, k + 7), JourneyBlocks.corbaPlank.getDefaultState());
		w.setBlockState(new BlockPos(i + 16, j + 1, k + 4), JourneyBlocks.corbaPlank.getDefaultState());
		w.setBlockState(new BlockPos(i + 16, j + 1, k + 8), JourneyBlocks.corbaPlank.getDefaultState());
		w.setBlockState(new BlockPos(i + 16, j + 2, k + 4), JourneyBlocks.corbaPlank.getDefaultState());
		w.setBlockState(new BlockPos(i + 16, j + 2, k + 8), JourneyBlocks.corbaPlank.getDefaultState());
		w.setBlockState(new BlockPos(i + 16, j + 5, k + 4), JourneyBlocks.corbaPlank.getDefaultState());
		w.setBlockState(new BlockPos(i + 16, j + 5, k + 8), JourneyBlocks.corbaPlank.getDefaultState());
		w.setBlockState(new BlockPos(i + 16, j + 6, k + 4), JourneyBlocks.corbaPlank.getDefaultState());
		w.setBlockState(new BlockPos(i + 16, j + 6, k + 8), JourneyBlocks.corbaPlank.getDefaultState());
		w.setBlockState(new BlockPos(i + 16, j + 7, k + 2), JourneyBlocks.logs.getDefaultState().withProperty(BlockModLog.VARIANT, EnumTypeLogs.EnumType.CORBA_LOG));
		w.setBlockState(new BlockPos(i + 16, j + 7, k + 3), JourneyBlocks.logs.getDefaultState().withProperty(BlockModLog.VARIANT, EnumTypeLogs.EnumType.CORBA_LOG));
		w.setBlockState(new BlockPos(i + 16, j + 7, k + 4), JourneyBlocks.logs.getDefaultState().withProperty(BlockModLog.VARIANT, EnumTypeLogs.EnumType.CORBA_LOG));
		w.setBlockState(new BlockPos(i + 16, j + 7, k + 8), JourneyBlocks.logs.getDefaultState().withProperty(BlockModLog.VARIANT, EnumTypeLogs.EnumType.CORBA_LOG));
		w.setBlockState(new BlockPos(i + 16, j + 7, k + 9), JourneyBlocks.logs.getDefaultState().withProperty(BlockModLog.VARIANT, EnumTypeLogs.EnumType.CORBA_LOG));
		w.setBlockState(new BlockPos(i + 16, j + 8, k + 3), JourneyBlocks.corbaPlank.getDefaultState());
		w.setBlockState(new BlockPos(i + 16, j + 8, k + 4), JourneyBlocks.corbaPlank.getDefaultState());
		w.setBlockState(new BlockPos(i + 16, j + 8, k + 5), JourneyBlocks.corbaPlank.getDefaultState());
		w.setBlockState(new BlockPos(i + 16, j + 8, k + 6), JourneyBlocks.corbaPlank.getDefaultState());
		w.setBlockState(new BlockPos(i + 16, j + 8, k + 7), JourneyBlocks.corbaPlank.getDefaultState());
		w.setBlockState(new BlockPos(i + 16, j + 8, k + 8), JourneyBlocks.corbaPlank.getDefaultState());
		w.setBlockState(new BlockPos(i + 17, j + 1, k + 3), JourneyBlocks.logs.getDefaultState().withProperty(BlockModLog.VARIANT, EnumTypeLogs.EnumType.CORBA_LOG));
		w.setBlockState(new BlockPos(i + 17, j + 1, k + 4), JourneyBlocks.logs.getDefaultState().withProperty(BlockModLog.VARIANT, EnumTypeLogs.EnumType.CORBA_LOG));
		w.setBlockState(new BlockPos(i + 17, j + 1, k + 5), JourneyBlocks.corbaPlank.getDefaultState());
		w.setBlockState(new BlockPos(i + 17, j + 1, k + 6), JourneyBlocks.corbaPlank.getDefaultState());
		w.setBlockState(new BlockPos(i + 17, j + 1, k + 7), JourneyBlocks.corbaPlank.getDefaultState());
		w.setBlockState(new BlockPos(i + 17, j + 1, k + 8), JourneyBlocks.logs.getDefaultState().withProperty(BlockModLog.VARIANT, EnumTypeLogs.EnumType.CORBA_LOG));
		w.setBlockState(new BlockPos(i + 17, j + 1, k + 9), JourneyBlocks.logs.getDefaultState().withProperty(BlockModLog.VARIANT, EnumTypeLogs.EnumType.CORBA_LOG));
		w.setBlockState(new BlockPos(i + 17, j + 2, k + 3), JourneyBlocks.logs.getDefaultState().withProperty(BlockModLog.VARIANT, EnumTypeLogs.EnumType.CORBA_LOG));
		w.setBlockState(new BlockPos(i + 17, j + 2, k + 4), JourneyBlocks.logs.getDefaultState().withProperty(BlockModLog.VARIANT, EnumTypeLogs.EnumType.CORBA_LOG));
		w.setBlockState(new BlockPos(i + 17, j + 2, k + 5), JourneyBlocks.corbaPlank.getDefaultState());
		w.setBlockState(new BlockPos(i + 17, j + 2, k + 6), JourneyBlocks.logs.getDefaultState().withProperty(BlockModLog.VARIANT, EnumTypeLogs.EnumType.CORBA_LOG));
		w.setBlockState(new BlockPos(i + 17, j + 2, k + 7), JourneyBlocks.corbaPlank.getDefaultState());
		w.setBlockState(new BlockPos(i + 17, j + 2, k + 8), JourneyBlocks.logs.getDefaultState().withProperty(BlockModLog.VARIANT, EnumTypeLogs.EnumType.CORBA_LOG));
		w.setBlockState(new BlockPos(i + 17, j + 2, k + 9), JourneyBlocks.logs.getDefaultState().withProperty(BlockModLog.VARIANT, EnumTypeLogs.EnumType.CORBA_LOG));
		w.setBlockState(new BlockPos(i + 17, j + 3, k + 4), JourneyBlocks.logs.getDefaultState().withProperty(BlockModLog.VARIANT, EnumTypeLogs.EnumType.CORBA_LOG));
		w.setBlockState(new BlockPos(i + 17, j + 3, k + 5), JourneyBlocks.corbaPlank.getDefaultState());
		w.setBlockState(new BlockPos(i + 17, j + 3, k + 7), JourneyBlocks.corbaPlank.getDefaultState());
		w.setBlockState(new BlockPos(i + 17, j + 3, k + 8), JourneyBlocks.logs.getDefaultState().withProperty(BlockModLog.VARIANT, EnumTypeLogs.EnumType.CORBA_LOG));
		w.setBlockState(new BlockPos(i + 17, j + 4, k + 4), JourneyBlocks.logs.getDefaultState().withProperty(BlockModLog.VARIANT, EnumTypeLogs.EnumType.CORBA_LOG));
		w.setBlockState(new BlockPos(i + 17, j + 4, k + 5), JourneyBlocks.corbaPlank.getDefaultState());
		w.setBlockState(new BlockPos(i + 17, j + 4, k + 7), JourneyBlocks.corbaPlank.getDefaultState());
		w.setBlockState(new BlockPos(i + 17, j + 4, k + 8), JourneyBlocks.logs.getDefaultState().withProperty(BlockModLog.VARIANT, EnumTypeLogs.EnumType.CORBA_LOG));
		w.setBlockState(new BlockPos(i + 17, j + 5, k + 4), JourneyBlocks.logs.getDefaultState().withProperty(BlockModLog.VARIANT, EnumTypeLogs.EnumType.CORBA_LOG));
		w.setBlockState(new BlockPos(i + 17, j + 5, k + 5), JourneyBlocks.corbaPlank.getDefaultState());
		w.setBlockState(new BlockPos(i + 17, j + 5, k + 6), JourneyBlocks.logs.getDefaultState().withProperty(BlockModLog.VARIANT, EnumTypeLogs.EnumType.CORBA_LOG));
		w.setBlockState(new BlockPos(i + 17, j + 5, k + 7), JourneyBlocks.corbaPlank.getDefaultState());
		w.setBlockState(new BlockPos(i + 17, j + 5, k + 8), JourneyBlocks.logs.getDefaultState().withProperty(BlockModLog.VARIANT, EnumTypeLogs.EnumType.CORBA_LOG));
		w.setBlockState(new BlockPos(i + 17, j + 6, k + 2), JourneyBlocks.logs.getDefaultState().withProperty(BlockModLog.VARIANT, EnumTypeLogs.EnumType.CORBA_LOG));
		w.setBlockState(new BlockPos(i + 17, j + 6, k + 3), JourneyBlocks.logs.getDefaultState().withProperty(BlockModLog.VARIANT, EnumTypeLogs.EnumType.CORBA_LOG));
		w.setBlockState(new BlockPos(i + 17, j + 6, k + 4), JourneyBlocks.logs.getDefaultState().withProperty(BlockModLog.VARIANT, EnumTypeLogs.EnumType.CORBA_LOG));
		w.setBlockState(new BlockPos(i + 17, j + 6, k + 5), JourneyBlocks.corbaPlank.getDefaultState());
		w.setBlockState(new BlockPos(i + 17, j + 6, k + 6), JourneyBlocks.corbaPlank.getDefaultState());
		w.setBlockState(new BlockPos(i + 17, j + 6, k + 7), JourneyBlocks.corbaPlank.getDefaultState());
		w.setBlockState(new BlockPos(i + 17, j + 6, k + 8), JourneyBlocks.logs.getDefaultState().withProperty(BlockModLog.VARIANT, EnumTypeLogs.EnumType.CORBA_LOG));
		w.setBlockState(new BlockPos(i + 17, j + 6, k + 9), JourneyBlocks.logs.getDefaultState().withProperty(BlockModLog.VARIANT, EnumTypeLogs.EnumType.CORBA_LOG));
		w.setBlockState(new BlockPos(i + 17, j + 7, k + 3), JourneyBlocks.corbaPlank.getDefaultState());
		w.setBlockState(new BlockPos(i + 17, j + 7, k + 4), JourneyBlocks.corbaPlank.getDefaultState());
		w.setBlockState(new BlockPos(i + 17, j + 7, k + 5), JourneyBlocks.corbaPlank.getDefaultState());
		w.setBlockState(new BlockPos(i + 17, j + 7, k + 6), JourneyBlocks.corbaPlank.getDefaultState());
		w.setBlockState(new BlockPos(i + 17, j + 7, k + 7), JourneyBlocks.corbaPlank.getDefaultState());
		w.setBlockState(new BlockPos(i + 17, j + 7, k + 8), JourneyBlocks.corbaPlank.getDefaultState());
		w.setBlockState(new BlockPos(i + 18, j + 1, k + 4), JourneyBlocks.logs.getDefaultState().withProperty(BlockModLog.VARIANT, EnumTypeLogs.EnumType.CORBA_LOG));
		w.setBlockState(new BlockPos(i + 18, j + 1, k + 5), JourneyBlocks.logs.getDefaultState().withProperty(BlockModLog.VARIANT, EnumTypeLogs.EnumType.CORBA_LOG));
		w.setBlockState(new BlockPos(i + 18, j + 1, k + 7), JourneyBlocks.logs.getDefaultState().withProperty(BlockModLog.VARIANT, EnumTypeLogs.EnumType.CORBA_LOG));
		w.setBlockState(new BlockPos(i + 18, j + 1, k + 8), JourneyBlocks.logs.getDefaultState().withProperty(BlockModLog.VARIANT, EnumTypeLogs.EnumType.CORBA_LOG));
		w.setBlockState(new BlockPos(i + 18, j + 2, k + 4), JourneyBlocks.logs.getDefaultState().withProperty(BlockModLog.VARIANT, EnumTypeLogs.EnumType.CORBA_LOG));
		w.setBlockState(new BlockPos(i + 18, j + 2, k + 8), JourneyBlocks.logs.getDefaultState().withProperty(BlockModLog.VARIANT, EnumTypeLogs.EnumType.CORBA_LOG));
		w.setBlockState(new BlockPos(i + 18, j + 6, k + 3), JourneyBlocks.logs.getDefaultState().withProperty(BlockModLog.VARIANT, EnumTypeLogs.EnumType.CORBA_LOG));
		w.setBlockState(new BlockPos(i + 18, j + 6, k + 4), JourneyBlocks.logs.getDefaultState().withProperty(BlockModLog.VARIANT, EnumTypeLogs.EnumType.CORBA_LOG));
		w.setBlockState(new BlockPos(i + 18, j + 6, k + 5), JourneyBlocks.logs.getDefaultState().withProperty(BlockModLog.VARIANT, EnumTypeLogs.EnumType.CORBA_LOG));
		w.setBlockState(new BlockPos(i + 18, j + 6, k + 6), JourneyBlocks.logs.getDefaultState().withProperty(BlockModLog.VARIANT, EnumTypeLogs.EnumType.CORBA_LOG));
		w.setBlockState(new BlockPos(i + 18, j + 6, k + 7), JourneyBlocks.logs.getDefaultState().withProperty(BlockModLog.VARIANT, EnumTypeLogs.EnumType.CORBA_LOG));
		w.setBlockState(new BlockPos(i + 18, j + 6, k + 8), JourneyBlocks.logs.getDefaultState().withProperty(BlockModLog.VARIANT, EnumTypeLogs.EnumType.CORBA_LOG));
		w.setBlockState(new BlockPos(i + 19, j + 0, k + 5), JourneyBlocks.corbaPlank.getDefaultState());
		w.setBlockState(new BlockPos(i + 19, j + 0, k + 6), JourneyBlocks.corbaPlank.getDefaultState());
		w.setBlockState(new BlockPos(i + 19, j + 0, k + 7), JourneyBlocks.corbaPlank.getDefaultState());
		w.setBlockState(new BlockPos(i + 19, j + 1, k + 5), JourneyBlocks.corbaPost.getDefaultState());
		w.setBlockState(new BlockPos(i + 19, j + 1, k + 7), JourneyBlocks.corbaPost.getDefaultState());
		w.setBlockState(new BlockPos(i + 20, j + 0, k + 6), JourneyBlocks.corbaPlank.getDefaultState());
		w.setBlockState(new BlockPos(i + 20, j + 1, k + 5), JourneyBlocks.logs.getDefaultState().withProperty(BlockModLog.VARIANT, EnumTypeLogs.EnumType.CORBA_LOG));
		w.setBlockState(new BlockPos(i + 20, j + 1, k + 7), JourneyBlocks.logs.getDefaultState().withProperty(BlockModLog.VARIANT, EnumTypeLogs.EnumType.CORBA_LOG));
		w.setBlockState(new BlockPos(i + 20, j + 2, k + 5), JourneyBlocks.logs.getDefaultState().withProperty(BlockModLog.VARIANT, EnumTypeLogs.EnumType.CORBA_LOG));
		w.setBlockState(new BlockPos(i + 20, j + 2, k + 7), JourneyBlocks.logs.getDefaultState().withProperty(BlockModLog.VARIANT, EnumTypeLogs.EnumType.CORBA_LOG));
		w.setBlockState(new BlockPos(i + 20, j + 3, k + 5), JourneyBlocks.logs.getDefaultState().withProperty(BlockModLog.VARIANT, EnumTypeLogs.EnumType.CORBA_LOG));
		w.setBlockState(new BlockPos(i + 20, j + 3, k + 7), JourneyBlocks.logs.getDefaultState().withProperty(BlockModLog.VARIANT, EnumTypeLogs.EnumType.CORBA_LOG));
		w.setBlockState(new BlockPos(i + 20, j + 4, k + 6), JourneyBlocks.logs.getDefaultState().withProperty(BlockModLog.VARIANT, EnumTypeLogs.EnumType.CORBA_LOG));
		w.setBlockState(new BlockPos(i + 21, j + 0, k + 5), JourneyBlocks.corbaPlank.getDefaultState());
		w.setBlockState(new BlockPos(i + 21, j + 0, k + 6), JourneyBlocks.corbaPlank.getDefaultState());
		w.setBlockState(new BlockPos(i + 21, j + 0, k + 7), JourneyBlocks.corbaPlank.getDefaultState());
		w.setBlockState(new BlockPos(i + 21, j + 1, k + 7), JourneyBlocks.corbaPlank.getDefaultState());
		w.setBlockState(new BlockPos(i + 21, j + 3, k + 5), JourneyBlocks.corbaPlank.getDefaultState());
		w.setBlockState(new BlockPos(i + 21, j + 3, k + 7), JourneyBlocks.corbaPlank.getDefaultState());
		w.setBlockState(new BlockPos(i + 21, j + 4, k + 6), JourneyBlocks.corbaPlank.getDefaultState());
		w.setBlockState(new BlockPos(i + 22, j + 0, k + 6), JourneyBlocks.corbaPlank.getDefaultState());
		w.setBlockState(new BlockPos(i + 22, j + 1, k + 5), JourneyBlocks.logs.getDefaultState().withProperty(BlockModLog.VARIANT, EnumTypeLogs.EnumType.CORBA_LOG));
		w.setBlockState(new BlockPos(i + 22, j + 1, k + 7), JourneyBlocks.logs.getDefaultState().withProperty(BlockModLog.VARIANT, EnumTypeLogs.EnumType.CORBA_LOG));
		w.setBlockState(new BlockPos(i + 22, j + 2, k + 5), JourneyBlocks.logs.getDefaultState().withProperty(BlockModLog.VARIANT, EnumTypeLogs.EnumType.CORBA_LOG));
		w.setBlockState(new BlockPos(i + 22, j + 2, k + 7), JourneyBlocks.logs.getDefaultState().withProperty(BlockModLog.VARIANT, EnumTypeLogs.EnumType.CORBA_LOG));
		w.setBlockState(new BlockPos(i + 22, j + 3, k + 5), JourneyBlocks.logs.getDefaultState().withProperty(BlockModLog.VARIANT, EnumTypeLogs.EnumType.CORBA_LOG));
		w.setBlockState(new BlockPos(i + 22, j + 3, k + 7), JourneyBlocks.logs.getDefaultState().withProperty(BlockModLog.VARIANT, EnumTypeLogs.EnumType.CORBA_LOG));
		w.setBlockState(new BlockPos(i + 22, j + 4, k + 6), JourneyBlocks.logs.getDefaultState().withProperty(BlockModLog.VARIANT, EnumTypeLogs.EnumType.CORBA_LOG));
		w.setBlockState(new BlockPos(i + 23, j + 0, k + 5), JourneyBlocks.corbaPlank.getDefaultState());
		w.setBlockState(new BlockPos(i + 23, j + 0, k + 6), JourneyBlocks.corbaPlank.getDefaultState());
		w.setBlockState(new BlockPos(i + 23, j + 0, k + 7), JourneyBlocks.corbaPlank.getDefaultState());
		w.setBlockState(new BlockPos(i + 23, j + 1, k + 5), JourneyBlocks.corbaPost.getDefaultState());
		w.setBlockState(new BlockPos(i + 23, j + 1, k + 7), JourneyBlocks.corbaPost.getDefaultState());
		w.setBlockState(new BlockPos(i + 24, j + 0, k + 6), JourneyBlocks.corbaPlank.getDefaultState());
		w.setBlockState(new BlockPos(i + 24, j + 0, k + 8), JourneyBlocks.corbaPlank.getDefaultState());
		w.setBlockState(new BlockPos(i + 24, j + 1, k + 4), JourneyBlocks.logs.getDefaultState().withProperty(BlockModLog.VARIANT, EnumTypeLogs.EnumType.CORBA_LOG));
		w.setBlockState(new BlockPos(i + 24, j + 1, k + 5), JourneyBlocks.corbaPlank.getDefaultState());
		w.setBlockState(new BlockPos(i + 24, j + 1, k + 7), JourneyBlocks.corbaPlank.getDefaultState());
		w.setBlockState(new BlockPos(i + 24, j + 1, k + 8), JourneyBlocks.logs.getDefaultState().withProperty(BlockModLog.VARIANT, EnumTypeLogs.EnumType.CORBA_LOG));
		w.setBlockState(new BlockPos(i + 24, j + 2, k + 4), JourneyBlocks.logs.getDefaultState().withProperty(BlockModLog.VARIANT, EnumTypeLogs.EnumType.CORBA_LOG));
		w.setBlockState(new BlockPos(i + 24, j + 2, k + 5), JourneyBlocks.corbaPlank.getDefaultState());
		w.setBlockState(new BlockPos(i + 24, j + 2, k + 7), JourneyBlocks.corbaPlank.getDefaultState());
		w.setBlockState(new BlockPos(i + 24, j + 2, k + 8), JourneyBlocks.logs.getDefaultState().withProperty(BlockModLog.VARIANT, EnumTypeLogs.EnumType.CORBA_LOG));
		w.setBlockState(new BlockPos(i + 24, j + 3, k + 4), JourneyBlocks.logs.getDefaultState().withProperty(BlockModLog.VARIANT, EnumTypeLogs.EnumType.CORBA_LOG));
		w.setBlockState(new BlockPos(i + 24, j + 3, k + 5), JourneyBlocks.corbaPlank.getDefaultState());
		w.setBlockState(new BlockPos(i + 24, j + 3, k + 6), JourneyBlocks.corbaPlank.getDefaultState());
		w.setBlockState(new BlockPos(i + 24, j + 3, k + 7), JourneyBlocks.corbaPlank.getDefaultState());
		w.setBlockState(new BlockPos(i + 24, j + 3, k + 8), JourneyBlocks.logs.getDefaultState().withProperty(BlockModLog.VARIANT, EnumTypeLogs.EnumType.CORBA_LOG));
		w.setBlockState(new BlockPos(i + 24, j + 4, k + 5), JourneyBlocks.logs.getDefaultState().withProperty(BlockModLog.VARIANT, EnumTypeLogs.EnumType.CORBA_LOG));
		w.setBlockState(new BlockPos(i + 24, j + 4, k + 6), JourneyBlocks.logs.getDefaultState().withProperty(BlockModLog.VARIANT, EnumTypeLogs.EnumType.CORBA_LOG));
		w.setBlockState(new BlockPos(i + 24, j + 4, k + 7), JourneyBlocks.logs.getDefaultState().withProperty(BlockModLog.VARIANT, EnumTypeLogs.EnumType.CORBA_LOG));
		w.setBlockState(new BlockPos(i + 24, j + 5, k + 5), JourneyBlocks.corbaPost.getDefaultState());
		w.setBlockState(new BlockPos(i + 24, j + 5, k + 6), JourneyBlocks.corbaPost.getDefaultState());
		w.setBlockState(new BlockPos(i + 24, j + 5, k + 7), JourneyBlocks.corbaPost.getDefaultState());
		w.setBlockState(new BlockPos(i + 25, j + 0, k + 5), JourneyBlocks.corbaPlank.getDefaultState());
		w.setBlockState(new BlockPos(i + 25, j + 0, k + 6), JourneyBlocks.corbaPlank.getDefaultState());
		w.setBlockState(new BlockPos(i + 25, j + 0, k + 7), JourneyBlocks.corbaPlank.getDefaultState());
		w.setBlockState(new BlockPos(i + 25, j + 0, k + 8), JourneyBlocks.corbaPlank.getDefaultState());
		w.setBlockState(new BlockPos(i + 25, j + 1, k + 4), JourneyBlocks.corbaPlank.getDefaultState());
		w.setBlockState(new BlockPos(i + 25, j + 1, k + 8), JourneyBlocks.corbaPlank.getDefaultState());
		w.setBlockState(new BlockPos(i + 25, j + 2, k + 4), JourneyBlocks.corbaPlank.getDefaultState());
		w.setBlockState(new BlockPos(i + 25, j + 2, k + 8), JourneyBlocks.corbaPlank.getDefaultState());
		w.setBlockState(new BlockPos(i + 25, j + 3, k + 4), JourneyBlocks.corbaPlank.getDefaultState());
		w.setBlockState(new BlockPos(i + 25, j + 3, k + 8), JourneyBlocks.corbaPlank.getDefaultState());
		w.setBlockState(new BlockPos(i + 25, j + 4, k + 4), JourneyBlocks.logs.getDefaultState().withProperty(BlockModLog.VARIANT, EnumTypeLogs.EnumType.CORBA_LOG));
		w.setBlockState(new BlockPos(i + 25, j + 4, k + 5), JourneyBlocks.corbaPlank.getDefaultState());
		w.setBlockState(new BlockPos(i + 25, j + 4, k + 6), JourneyBlocks.corbaPlank.getDefaultState());
		w.setBlockState(new BlockPos(i + 25, j + 4, k + 7), JourneyBlocks.corbaPlank.getDefaultState());
		w.setBlockState(new BlockPos(i + 25, j + 4, k + 8), JourneyBlocks.logs.getDefaultState().withProperty(BlockModLog.VARIANT, EnumTypeLogs.EnumType.CORBA_LOG));
		w.setBlockState(new BlockPos(i + 25, j + 5, k + 4), JourneyBlocks.corbaPost.getDefaultState());
		w.setBlockState(new BlockPos(i + 25, j + 5, k + 5), JourneyBlocks.corbaPost.getDefaultState());
		w.setBlockState(new BlockPos(i + 25, j + 5, k + 7), JourneyBlocks.corbaPost.getDefaultState());
		w.setBlockState(new BlockPos(i + 25, j + 5, k + 8), JourneyBlocks.corbaPost.getDefaultState());
		w.setBlockState(new BlockPos(i + 26, j + 0, k + 4), JourneyBlocks.corbaPlank.getDefaultState());
		w.setBlockState(new BlockPos(i + 26, j + 0, k + 5), JourneyBlocks.corbaPlank.getDefaultState());
		w.setBlockState(new BlockPos(i + 26, j + 0, k + 6), JourneyBlocks.corbaPlank.getDefaultState());
		w.setBlockState(new BlockPos(i + 26, j + 0, k + 7), JourneyBlocks.corbaPlank.getDefaultState());
		w.setBlockState(new BlockPos(i + 26, j + 0, k + 8), JourneyBlocks.corbaPlank.getDefaultState());
		w.setBlockState(new BlockPos(i + 26, j + 3, k + 4), JourneyBlocks.corbaPlank.getDefaultState());
		w.setBlockState(new BlockPos(i + 26, j + 3, k + 6), JourneyBlocks.corbaLamp.getDefaultState());
		w.setBlockState(new BlockPos(i + 26, j + 3, k + 8), JourneyBlocks.corbaPlank.getDefaultState());
		w.setBlockState(new BlockPos(i + 26, j + 4, k + 4), JourneyBlocks.logs.getDefaultState().withProperty(BlockModLog.VARIANT, EnumTypeLogs.EnumType.CORBA_LOG));
		w.setBlockState(new BlockPos(i + 26, j + 4, k + 5), JourneyBlocks.corbaPlank.getDefaultState());
		w.setBlockState(new BlockPos(i + 26, j + 4, k + 6), JourneyBlocks.corbaPlank.getDefaultState());
		w.setBlockState(new BlockPos(i + 26, j + 4, k + 7), JourneyBlocks.corbaPlank.getDefaultState());
		w.setBlockState(new BlockPos(i + 26, j + 4, k + 8), JourneyBlocks.logs.getDefaultState().withProperty(BlockModLog.VARIANT, EnumTypeLogs.EnumType.CORBA_LOG));
		w.setBlockState(new BlockPos(i + 26, j + 5, k + 4), JourneyBlocks.corbaPost.getDefaultState());
		w.setBlockState(new BlockPos(i + 26, j + 5, k + 8), JourneyBlocks.corbaPost.getDefaultState());
		w.setBlockState(new BlockPos(i + 27, j + 0, k + 5), JourneyBlocks.corbaPlank.getDefaultState());
		w.setBlockState(new BlockPos(i + 27, j + 0, k + 6), JourneyBlocks.corbaPlank.getDefaultState());
		w.setBlockState(new BlockPos(i + 27, j + 0, k + 7), JourneyBlocks.corbaPlank.getDefaultState());
		w.setBlockState(new BlockPos(i + 27, j + 1, k + 4), JourneyBlocks.corbaPlank.getDefaultState());
		w.setBlockState(new BlockPos(i + 27, j + 1, k + 8), JourneyBlocks.corbaPlank.getDefaultState());
		w.setBlockState(new BlockPos(i + 27, j + 2, k + 4), JourneyBlocks.corbaPlank.getDefaultState());
		w.setBlockState(new BlockPos(i + 27, j + 2, k + 8), JourneyBlocks.corbaPlank.getDefaultState());
		w.setBlockState(new BlockPos(i + 27, j + 3, k + 4), JourneyBlocks.corbaPlank.getDefaultState());
		w.setBlockState(new BlockPos(i + 27, j + 3, k + 8), JourneyBlocks.corbaPlank.getDefaultState());
		w.setBlockState(new BlockPos(i + 27, j + 4, k + 4), JourneyBlocks.logs.getDefaultState().withProperty(BlockModLog.VARIANT, EnumTypeLogs.EnumType.CORBA_LOG));
		w.setBlockState(new BlockPos(i + 27, j + 4, k + 5), JourneyBlocks.corbaPlank.getDefaultState());
		w.setBlockState(new BlockPos(i + 27, j + 4, k + 6), JourneyBlocks.corbaPlank.getDefaultState());
		w.setBlockState(new BlockPos(i + 27, j + 4, k + 7), JourneyBlocks.corbaPlank.getDefaultState());
		w.setBlockState(new BlockPos(i + 27, j + 4, k + 8), JourneyBlocks.logs.getDefaultState().withProperty(BlockModLog.VARIANT, EnumTypeLogs.EnumType.CORBA_LOG));
		w.setBlockState(new BlockPos(i + 27, j + 5, k + 4), JourneyBlocks.corbaPost.getDefaultState());
		w.setBlockState(new BlockPos(i + 27, j + 5, k + 5), JourneyBlocks.corbaPost.getDefaultState());
		w.setBlockState(new BlockPos(i + 27, j + 5, k + 7), JourneyBlocks.corbaPost.getDefaultState());
		w.setBlockState(new BlockPos(i + 27, j + 5, k + 8), JourneyBlocks.corbaPost.getDefaultState());
		w.setBlockState(new BlockPos(i + 28, j + 0, k + 6), JourneyBlocks.corbaPlank.getDefaultState());
		w.setBlockState(new BlockPos(i + 28, j + 1, k + 4), JourneyBlocks.logs.getDefaultState().withProperty(BlockModLog.VARIANT, EnumTypeLogs.EnumType.CORBA_LOG));
		w.setBlockState(new BlockPos(i + 28, j + 1, k + 5), JourneyBlocks.corbaPlank.getDefaultState());
		w.setBlockState(new BlockPos(i + 28, j + 1, k + 7), JourneyBlocks.corbaPlank.getDefaultState());
		w.setBlockState(new BlockPos(i + 28, j + 1, k + 8), JourneyBlocks.logs.getDefaultState().withProperty(BlockModLog.VARIANT, EnumTypeLogs.EnumType.CORBA_LOG));
		w.setBlockState(new BlockPos(i + 28, j + 2, k + 4), JourneyBlocks.logs.getDefaultState().withProperty(BlockModLog.VARIANT, EnumTypeLogs.EnumType.CORBA_LOG));
		w.setBlockState(new BlockPos(i + 28, j + 2, k + 5), JourneyBlocks.corbaPlank.getDefaultState());
		w.setBlockState(new BlockPos(i + 28, j + 2, k + 7), JourneyBlocks.corbaPlank.getDefaultState());
		w.setBlockState(new BlockPos(i + 28, j + 2, k + 8), JourneyBlocks.logs.getDefaultState().withProperty(BlockModLog.VARIANT, EnumTypeLogs.EnumType.CORBA_LOG));
		w.setBlockState(new BlockPos(i + 28, j + 3, k + 4), JourneyBlocks.logs.getDefaultState().withProperty(BlockModLog.VARIANT, EnumTypeLogs.EnumType.CORBA_LOG));
		w.setBlockState(new BlockPos(i + 28, j + 3, k + 5), JourneyBlocks.corbaPlank.getDefaultState());
		w.setBlockState(new BlockPos(i + 28, j + 3, k + 6), JourneyBlocks.corbaPlank.getDefaultState());
		w.setBlockState(new BlockPos(i + 28, j + 3, k + 7), JourneyBlocks.corbaPlank.getDefaultState());
		w.setBlockState(new BlockPos(i + 28, j + 3, k + 8), JourneyBlocks.logs.getDefaultState().withProperty(BlockModLog.VARIANT, EnumTypeLogs.EnumType.CORBA_LOG));
		w.setBlockState(new BlockPos(i + 28, j + 4, k + 5), JourneyBlocks.logs.getDefaultState().withProperty(BlockModLog.VARIANT, EnumTypeLogs.EnumType.CORBA_LOG));
		w.setBlockState(new BlockPos(i + 28, j + 4, k + 6), JourneyBlocks.logs.getDefaultState().withProperty(BlockModLog.VARIANT, EnumTypeLogs.EnumType.CORBA_LOG));
		w.setBlockState(new BlockPos(i + 28, j + 4, k + 7), JourneyBlocks.logs.getDefaultState().withProperty(BlockModLog.VARIANT, EnumTypeLogs.EnumType.CORBA_LOG));
		w.setBlockState(new BlockPos(i + 28, j + 5, k + 5), JourneyBlocks.corbaPost.getDefaultState());
		w.setBlockState(new BlockPos(i + 28, j + 5, k + 6), JourneyBlocks.corbaPost.getDefaultState());
		w.setBlockState(new BlockPos(i + 28, j + 5, k + 7), JourneyBlocks.corbaPost.getDefaultState());

		if(!w.isRemote) {
			EntityTordo smith = new EntityTordo(w);
				smith.setLocationAndAngles(i + 15, j + 3, k + 5, 0.0F, 0.0F);
				w.spawnEntity(smith);
			EntityRedTordo smith1 = new EntityRedTordo(w);
				smith1.setLocationAndAngles(i + 14, j + 3, k + 6, 0.0F, 0.0F);
				w.spawnEntity(smith1);
		}
		return false;
	}
}